<?xml version="1.0" ?>
<!-- =================================================================================== -->
<!-- |    This document was autogenerated by xacro from pleurobot-gazebo.xacro         | -->
<!-- |    EDITING THIS FILE BY HAND IS NOT RECOMMENDED                                 | -->
<!-- =================================================================================== -->
<robot name="pleurobot" xmlns:xacro="http://www.ros.org/wiki/xacro">
  <gazebo>
    <!-- ros_control plugin -->
    <plugin filename="libgazebo_ros_control.so" name="gazebo_ros_control">
      <robotNamespace>/pleurobot</robotNamespace>
      <robotSimType>gazebo_ros_control/DefaultRobotHWSim</robotSimType>
    </plugin>
    <!-- GPS plugin -->
    <plugin filename="libhector_gazebo_ros_gps.so" name="pleurobot_gps_sim">
      <alwaysOn>true</alwaysOn>
      <updateRate>4.0</updateRate>
      <bodyName>base_link</bodyName>
      <topicName>gps</topicName>
      <!-- <velocityTopicName>gps_velocity</velocityTopicName> -->
      <drift>5.0 5.0 5.0</drift>
      <gaussianNoise>0.1 0.1 0.1</gaussianNoise>
      <velocityDrift>0 0 0</velocityDrift>
      <velocityGaussianNoise>0.1 0.1 0.1</velocityGaussianNoise>
    </plugin>
    <!-- Groundtruth plugin -->
    <plugin filename="libgazebo_ros_p3d.so" name="pleurobot_groundtruth_sim">
      <alwaysOn>true</alwaysOn>
      <updateRate>100.0</updateRate>
      <bodyName>base_link</bodyName>
      <topicName>groundtruth</topicName>
      <gaussianNoise>0.0</gaussianNoise>
      <frameName>map</frameName>
      <xyzOffsets>0 0 0</xyzOffsets>
      <rpyOffsets>0 0 0</rpyOffsets>
    </plugin>
    <!-- IMU plugin -->
    <plugin filename="libhector_gazebo_ros_imu.so" name="pleurobot_imu_sim">
      <alwaysOn>true</alwaysOn>
      <updateRate>100.0</updateRate>
      <bodyName>base_link</bodyName>
      <frameID>pleurobot_link1</frameID>
      <topicName>pleurobot/IMU</topicName>
      <xyzOffset>0.0 0.0 0.0</xyzOffset>
      <rpyOffset>0.0 0.0 0.0</rpyOffset>
      <gaussianNoise>0</gaussianNoise>
      <accelDrift>0.5 0.5 0.5</accelDrift>
      <accelGaussianNoise>0.35 0.35 0.3</accelGaussianNoise>
      <rateDrift>0.0 0.0 0.0</rateDrift>
      <rateGaussianNoise>0.00 0.00 0.00</rateGaussianNoise>
      <headingDrift>0.0</headingDrift>
      <headingGaussianNoise>0.00</headingGaussianNoise>
    </plugin>
  </gazebo>
  <!-- Head -->
  <gazebo reference="Head">
    <material>Gazebo/Grey</material>
  </gazebo>
  <!-- Base -->
  <gazebo reference="base_link">
    <material>Gazebo/Grey</material>
  </gazebo>
  <!-- Link1 -->
  <gazebo reference="link1">
    <mu1>0.2</mu1>
    <mu2>0.2</mu2>
    <material>Gazebo/Grey</material>
  </gazebo>
  <!-- Link2 -->
  <gazebo reference="link2">
    <mu1>0.2</mu1>
    <mu2>0.2</mu2>
    <material>Gazebo/Grey</material>
  </gazebo>
  <!-- Link3 -->
  <gazebo reference="link3">
    <mu1>0.2</mu1>
    <mu2>0.2</mu2>
    <material>Gazebo/Grey</material>
  </gazebo>
  <!-- Link4 -->
  <gazebo reference="link4">
    <mu1>0.2</mu1>
    <mu2>0.2</mu2>
    <material>Gazebo/Grey</material>
  </gazebo>
  <!-- Link5 -->
  <gazebo reference="link5">
    <mu1>0.2</mu1>
    <mu2>0.2</mu2>
    <material>Gazebo/Grey</material>
  </gazebo>
  <!-- Link6 -->
  <gazebo reference="link6">
    <mu1>0.2</mu1>
    <mu2>0.2</mu2>
    <material>Gazebo/Grey</material>
  </gazebo>
  <!-- Link7 -->
  <gazebo reference="link7">
    <mu1>0.2</mu1>
    <mu2>0.2</mu2>
    <material>Gazebo/Grey</material>
  </gazebo>
  <!-- Link8 -->
  <gazebo reference="link8">
    <mu1>0.2</mu1>
    <mu2>0.2</mu2>
    <material>Gazebo/Grey</material>
  </gazebo>
  <!-- Link9 -->
  <gazebo reference="link9">
    <mu1>0.2</mu1>
    <mu2>0.2</mu2>
    <material>Gazebo/Grey</material>
  </gazebo>
  <!-- Link10 -->
  <gazebo reference="link10">
    <mu1>0.2</mu1>
    <mu2>0.2</mu2>
    <material>Gazebo/Grey</material>
  </gazebo>
  <!-- Link11 -->
  <gazebo reference="link11">
    <mu1>0.2</mu1>
    <mu2>0.2</mu2>
    <material>Gazebo/Grey</material>
  </gazebo>
  <!-- Link12 -->
  <gazebo reference="link12">
    <mu1>0.2</mu1>
    <mu2>0.2</mu2>
    <material>Gazebo/Grey</material>
  </gazebo>
  <!-- Link13 -->
  <gazebo reference="link13">
    <mu1>0.2</mu1>
    <mu2>0.2</mu2>
    <material>Gazebo/Grey</material>
  </gazebo>
  <!-- Link14 -->
  <gazebo reference="link14">
    <mu1>0.2</mu1>
    <mu2>0.2</mu2>
    <material>Gazebo/Grey</material>
  </gazebo>
  <!-- Link15 -->
  <gazebo reference="link15">
    <mu1>0.2</mu1>
    <mu2>0.2</mu2>
    <material>Gazebo/Grey</material>
  </gazebo>
  <!-- Link16 -->
  <gazebo reference="link16">
    <mu1>0.2</mu1>
    <mu2>0.2</mu2>
    <material>Gazebo/Grey</material>
  </gazebo>
  <!-- Link17 -->
  <gazebo reference="link17">
    <mu1>0.2</mu1>
    <mu2>0.2</mu2>
    <material>Gazebo/Grey</material>
  </gazebo>
  <!-- Link18 -->
  <gazebo reference="link18">
    <mu1>0.2</mu1>
    <mu2>0.2</mu2>
    <material>Gazebo/Grey</material>
  </gazebo>
  <!-- Link19 -->
  <gazebo reference="link19">
    <mu1>0.2</mu1>
    <mu2>0.2</mu2>
    <material>Gazebo/Grey</material>
  </gazebo>
  <!-- Link20 -->
  <gazebo reference="link20">
    <mu1>0.2</mu1>
    <mu2>0.2</mu2>
    <material>Gazebo/Grey</material>
  </gazebo>
  <!-- Link21 -->
  <gazebo reference="link21">
    <mu1>0.2</mu1>
    <mu2>0.2</mu2>
    <material>Gazebo/Grey</material>
  </gazebo>
  <!-- Link22 -->
  <gazebo reference="link22">
    <mu1>0.2</mu1>
    <mu2>0.2</mu2>
    <material>Gazebo/Grey</material>
  </gazebo>
  <!-- Link23 -->
  <gazebo reference="link23">
    <mu1>0.2</mu1>
    <mu2>0.2</mu2>
    <material>Gazebo/Grey</material>
  </gazebo>
  <!-- Link24 -->
  <gazebo reference="link24">
    <mu1>0.2</mu1>
    <mu2>0.2</mu2>
    <material>Gazebo/Grey</material>
  </gazebo>
  <!-- Link25 -->
  <gazebo reference="link25">
    <mu1>0.2</mu1>
    <mu2>0.2</mu2>
    <material>Gazebo/Grey</material>
  </gazebo>
  <!-- Link26 -->
  <gazebo reference="link26">
    <mu1>0.2</mu1>
    <mu2>0.2</mu2>
    <material>Gazebo/Grey</material>
  </gazebo>
  <!-- Link27 -->
  <gazebo reference="link27">
    <mu1>0.2</mu1>
    <mu2>0.2</mu2>
    <material>Gazebo/Grey</material>
  </gazebo>
  <!-- TailBone -->
  <gazebo reference="link_tailbone">
    <mu1>0.2</mu1>
    <mu2>0.2</mu2>
    <material>Gazebo/Grey</material>
  </gazebo>
  <!-- Tail -->
  <gazebo reference="link_tail">
    <mu1>0.2</mu1>
    <mu2>0.2</mu2>
    <material>Gazebo/Grey</material>
  </gazebo>
  <!-- camera_link -->
  <gazebo reference="camera_link">
    <mu1>0.2</mu1>
    <mu2>0.2</mu2>
  </gazebo>
  <!-- camera -->
  <!-- Microsoft Kinect / ASUS Xtion PRO Live for simulation -->
  <gazebo reference="camera_link">
    <sensor name="camera" type="depth">
      <always_on>true</always_on>
      <update_rate>20.0</update_rate>
      <camera>
        <horizontal_fov>1.0471975512</horizontal_fov>
        <image>
          <format>R8G8B8</format>
          <width>640</width>
          <height>480</height>
        </image>
        <clip>
          <near>0.05</near>
          <far>8.0</far>
        </clip>
      </camera>
      <plugin filename="libgazebo_ros_openni_kinect.so" name="kinect_camera_controller">
        <cameraName>camera</cameraName>
        <alwaysOn>true</alwaysOn>
        <updateRate>10</updateRate>
        <imageTopicName>rgb/image_raw</imageTopicName>
        <depthImageTopicName>depth/image_raw</depthImageTopicName>
        <pointCloudTopicName>depth/points</pointCloudTopicName>
        <cameraInfoTopicName>rgb/camera_info</cameraInfoTopicName>
        <depthImageCameraInfoTopicName>depth/camera_info</depthImageCameraInfoTopicName>
        <frameName>camera_depth_optical_frame</frameName>
        <baseline>0.1</baseline>
        <distortion_k1>0.0</distortion_k1>
        <distortion_k2>0.0</distortion_k2>
        <distortion_k3>0.0</distortion_k3>
        <distortion_t1>0.0</distortion_t1>
        <distortion_t2>0.0</distortion_t2>
        <pointCloudCutoff>0.4</pointCloudCutoff>
      </plugin>
    </sensor>
  </gazebo>
  <!-- HEAD -->
  <transmission name="Head_Transmission">
    <type>transmission_interface/SimpleTransmission</type>
    <joint name="jHead">
      <hardwareInterface>EffortJointInterface</hardwareInterface>
    </joint>
    <actuator name="Head_Motor">
      <hardwareInterface>EffortJointInterface</hardwareInterface>
      <mechanicalReduction>1</mechanicalReduction>
    </actuator>
  </transmission>
  <!-- Front Body -->
  <transmission name="BodyFront2_Transmission">
    <type>transmission_interface/SimpleTransmission</type>
    <joint name="j2">
      <hardwareInterface>EffortJointInterface</hardwareInterface>
    </joint>
    <actuator name="BodyFront2_Motor">
      <hardwareInterface>EffortJointInterface</hardwareInterface>
      <mechanicalReduction>1</mechanicalReduction>
    </actuator>
  </transmission>
  <transmission name="BodyFront3_Transmission">
    <type>transmission_interface/SimpleTransmission</type>
    <joint name="j3">
      <hardwareInterface>EffortJointInterface</hardwareInterface>
    </joint>
    <actuator name="BodyFront3_Motor">
      <hardwareInterface>EffortJointInterface</hardwareInterface>
      <mechanicalReduction>1</mechanicalReduction>
    </actuator>
  </transmission>
  <transmission name="BodyFront4_Transmission">
    <type>transmission_interface/SimpleTransmission</type>
    <joint name="j4">
      <hardwareInterface>EffortJointInterface</hardwareInterface>
    </joint>
    <actuator name="BodyFront4_Motor">
      <hardwareInterface>EffortJointInterface</hardwareInterface>
      <mechanicalReduction>1</mechanicalReduction>
    </actuator>
  </transmission>
  <transmission name="BodyFront5_Transmission">
    <type>transmission_interface/SimpleTransmission</type>
    <joint name="j5">
      <hardwareInterface>EffortJointInterface</hardwareInterface>
    </joint>
    <actuator name="BodyFront5_Motor">
      <hardwareInterface>EffortJointInterface</hardwareInterface>
      <mechanicalReduction>1</mechanicalReduction>
    </actuator>
  </transmission>
  <transmission name="BodyFront6_Transmission">
    <type>transmission_interface/SimpleTransmission</type>
    <joint name="j6">
      <hardwareInterface>EffortJointInterface</hardwareInterface>
    </joint>
    <actuator name="BodyFront6_Motor">
      <hardwareInterface>EffortJointInterface</hardwareInterface>
      <mechanicalReduction>1</mechanicalReduction>
    </actuator>
  </transmission>
  <!-- Back Body -->
  <transmission name="BodyBack7_Transmission">
    <type>transmission_interface/SimpleTransmission</type>
    <joint name="j7">
      <hardwareInterface>EffortJointInterface</hardwareInterface>
    </joint>
    <actuator name="BodyBack7_Motor">
      <hardwareInterface>EffortJointInterface</hardwareInterface>
      <mechanicalReduction>1</mechanicalReduction>
    </actuator>
  </transmission>
  <transmission name="BodyBack8_Transmission">
    <type>transmission_interface/SimpleTransmission</type>
    <joint name="j8">
      <hardwareInterface>EffortJointInterface</hardwareInterface>
    </joint>
    <actuator name="BodyBack8_Motor">
      <hardwareInterface>EffortJointInterface</hardwareInterface>
      <mechanicalReduction>1</mechanicalReduction>
    </actuator>
  </transmission>
  <transmission name="BodyBack9_Transmission">
    <type>transmission_interface/SimpleTransmission</type>
    <joint name="j9">
      <hardwareInterface>EffortJointInterface</hardwareInterface>
    </joint>
    <actuator name="BodyBack9_Motor">
      <hardwareInterface>EffortJointInterface</hardwareInterface>
      <mechanicalReduction>1</mechanicalReduction>
    </actuator>
  </transmission>
  <transmission name="BodyBack10_Transmission">
    <type>transmission_interface/SimpleTransmission</type>
    <joint name="j10">
      <hardwareInterface>EffortJointInterface</hardwareInterface>
    </joint>
    <actuator name="BodyBack10_Motor">
      <hardwareInterface>EffortJointInterface</hardwareInterface>
      <mechanicalReduction>1</mechanicalReduction>
    </actuator>
  </transmission>
  <transmission name="BodyBack11_Transmission">
    <type>transmission_interface/SimpleTransmission</type>
    <joint name="j11">
      <hardwareInterface>EffortJointInterface</hardwareInterface>
    </joint>
    <actuator name="BodyBack11_Motor">
      <hardwareInterface>EffortJointInterface</hardwareInterface>
      <mechanicalReduction>1</mechanicalReduction>
    </actuator>
  </transmission>
  <!-- LEG-leftFront -->
  <transmission name="ForearmLeft1_Transmission">
    <type>transmission_interface/SimpleTransmission</type>
    <joint name="ForearmLeft_Yaw">
      <hardwareInterface>EffortJointInterface</hardwareInterface>
    </joint>
    <actuator name="ForearmLeft1_Motor">
      <hardwareInterface>EffortJointInterface</hardwareInterface>
      <mechanicalReduction>1</mechanicalReduction>
    </actuator>
  </transmission>
  <transmission name="ForearmLeft2_Transmission">
    <type>transmission_interface/SimpleTransmission</type>
    <joint name="ForearmLeft_Pitch">
      <hardwareInterface>EffortJointInterface</hardwareInterface>
    </joint>
    <actuator name="ForearmLeft2_Motor">
      <hardwareInterface>EffortJointInterface</hardwareInterface>
      <mechanicalReduction>1</mechanicalReduction>
    </actuator>
  </transmission>
  <transmission name="ForearmLeft3_Transmission">
    <type>transmission_interface/SimpleTransmission</type>
    <joint name="ForearmLeft_Roll">
      <hardwareInterface>EffortJointInterface</hardwareInterface>
    </joint>
    <actuator name="ForearmLeft3_Motor">
      <hardwareInterface>EffortJointInterface</hardwareInterface>
      <mechanicalReduction>1</mechanicalReduction>
    </actuator>
  </transmission>
  <transmission name="ForearmLeft4_Transmission">
    <type>transmission_interface/SimpleTransmission</type>
    <joint name="ForearmLeft_Elbow">
      <hardwareInterface>EffortJointInterface</hardwareInterface>
    </joint>
    <actuator name="ForearmLeft4_Motor">
      <hardwareInterface>EffortJointInterface</hardwareInterface>
      <mechanicalReduction>1</mechanicalReduction>
    </actuator>
  </transmission>
  <!-- LEG-rightFront -->
  <transmission name="ForearmRight1_Transmission">
    <type>transmission_interface/SimpleTransmission</type>
    <joint name="ForearmRight_Yaw">
      <hardwareInterface>EffortJointInterface</hardwareInterface>
    </joint>
    <actuator name="ForearmRight1_Motor">
      <hardwareInterface>EffortJointInterface</hardwareInterface>
      <mechanicalReduction>1</mechanicalReduction>
    </actuator>
  </transmission>
  <transmission name="ForearmRight2_Transmission">
    <type>transmission_interface/SimpleTransmission</type>
    <joint name="ForearmRight_Pitch">
      <hardwareInterface>EffortJointInterface</hardwareInterface>
    </joint>
    <actuator name="ForearmRight2_Motor">
      <hardwareInterface>EffortJointInterface</hardwareInterface>
      <mechanicalReduction>1</mechanicalReduction>
    </actuator>
  </transmission>
  <transmission name="ForearmRight3_Transmission">
    <type>transmission_interface/SimpleTransmission</type>
    <joint name="ForearmRight_Roll">
      <hardwareInterface>EffortJointInterface</hardwareInterface>
    </joint>
    <actuator name="ForearmRight3_Motor">
      <hardwareInterface>EffortJointInterface</hardwareInterface>
      <mechanicalReduction>1</mechanicalReduction>
    </actuator>
  </transmission>
  <transmission name="ForearmRight4_Transmission">
    <type>transmission_interface/SimpleTransmission</type>
    <joint name="ForearmRight_Elbow">
      <hardwareInterface>EffortJointInterface</hardwareInterface>
    </joint>
    <actuator name="ForearmRight4_Motor">
      <hardwareInterface>EffortJointInterface</hardwareInterface>
      <mechanicalReduction>1</mechanicalReduction>
    </actuator>
  </transmission>
  <!-- LEG-leftBack -->
  <transmission name="HindLimbLeft1_Transmission">
    <type>transmission_interface/SimpleTransmission</type>
    <joint name="HindLimbLeft_Yaw">
      <hardwareInterface>EffortJointInterface</hardwareInterface>
    </joint>
    <actuator name="HindLimbLeft1_Motor">
      <hardwareInterface>EffortJointInterface</hardwareInterface>
      <mechanicalReduction>1</mechanicalReduction>
    </actuator>
  </transmission>
  <transmission name="HindLimbLeft2_Transmission">
    <type>transmission_interface/SimpleTransmission</type>
    <joint name="HindLimbLeft_Pitch">
      <hardwareInterface>EffortJointInterface</hardwareInterface>
    </joint>
    <actuator name="HindLimbLeft2_Motor">
      <hardwareInterface>EffortJointInterface</hardwareInterface>
      <mechanicalReduction>1</mechanicalReduction>
    </actuator>
  </transmission>
  <transmission name="HindLimbLeft3_Transmission">
    <type>transmission_interface/SimpleTransmission</type>
    <joint name="HindLimbLeft_Roll">
      <hardwareInterface>EffortJointInterface</hardwareInterface>
    </joint>
    <actuator name="HindLimbLeft3_Motor">
      <hardwareInterface>EffortJointInterface</hardwareInterface>
      <mechanicalReduction>1</mechanicalReduction>
    </actuator>
  </transmission>
  <transmission name="HindLimbLeft4_Transmission">
    <type>transmission_interface/SimpleTransmission</type>
    <joint name="HindLimbLeft_Elbow">
      <hardwareInterface>EffortJointInterface</hardwareInterface>
    </joint>
    <actuator name="HindLimbLeft4_Motor">
      <hardwareInterface>EffortJointInterface</hardwareInterface>
      <mechanicalReduction>1</mechanicalReduction>
    </actuator>
  </transmission>
  <!-- LEG-rightBack -->
  <transmission name="HindLimbRight1_Transmission">
    <type>transmission_interface/SimpleTransmission</type>
    <joint name="HindLimbRight_Yaw">
      <hardwareInterface>EffortJointInterface</hardwareInterface>
    </joint>
    <actuator name="HindLimbRight1_Motor">
      <hardwareInterface>EffortJointInterface</hardwareInterface>
      <mechanicalReduction>1</mechanicalReduction>
    </actuator>
  </transmission>
  <transmission name="HindLimbRight2_Transmission">
    <type>transmission_interface/SimpleTransmission</type>
    <joint name="HindLimbRight_Pitch">
      <hardwareInterface>EffortJointInterface</hardwareInterface>
    </joint>
    <actuator name="HindLimbRight2_Motor">
      <hardwareInterface>EffortJointInterface</hardwareInterface>
      <mechanicalReduction>1</mechanicalReduction>
    </actuator>
  </transmission>
  <transmission name="HindLimbRight3_Transmission">
    <type>transmission_interface/SimpleTransmission</type>
    <joint name="HindLimbRight_Roll">
      <hardwareInterface>EffortJointInterface</hardwareInterface>
    </joint>
    <actuator name="HindLimbRight3_Motor">
      <hardwareInterface>EffortJointInterface</hardwareInterface>
      <mechanicalReduction>1</mechanicalReduction>
    </actuator>
  </transmission>
  <transmission name="HindLimbRight4_Transmission">
    <type>transmission_interface/SimpleTransmission</type>
    <joint name="HindLimbRight_Elbow">
      <hardwareInterface>EffortJointInterface</hardwareInterface>
    </joint>
    <actuator name="HindLimbRight4_Motor">
      <hardwareInterface>EffortJointInterface</hardwareInterface>
      <mechanicalReduction>1</mechanicalReduction>
    </actuator>
  </transmission>
  <material name="black">
    <color rgba="0.0 0.0 0.0 1.0"/>
  </material>
  <material name="blue">
    <color rgba="0.0 0.0 1.0 0.2"/>
  </material>
  <material name="green">
    <color rgba="0.0 0.8 0.0 1.0"/>
  </material>
  <material name="grey">
    <color rgba="0.2 0.2 0.2 1.0"/>
  </material>
  <material name="orange">
    <color rgba="1.0 0.423529411765 0.0392156862745 1.0"/>
  </material>
  <material name="brown">
    <color rgba="0.870588235294 0.811764705882 0.764705882353 1.0"/>
  </material>
  <material name="red">
    <color rgba="0.8 0.0 0.0 1.0"/>
  </material>
  <material name="white">
    <color rgba="1.0 1.0 1.0 1.0"/>
  </material>
  <material name="lightgrey">
    <color rgba="0.7 0.7 0.7 1.0"/>
  </material>
  <link name="Head">
    <visual>
      <origin rpy="3.1416 0 -1.5708 " xyz="-0.6 0.615 0.515"/>
      <geometry>
        <mesh filename="meshes/head.STL" scale=".0015 .0015 .0015"/>
      </geometry>
    </visual>
    <collision>
      <origin rpy="3.1416 0 -1.5708 " xyz="-0.6 0.615 0.515"/>
      <geometry>
        <mesh filename="meshes/head.STL" scale=".0015 .0015 .0015"/>
      </geometry>
    </collision>
    <inertial>
      <mass value="0.53597"/>
      <origin rpy="0 0 0 " xyz="0 0 -0.315"/>
      <inertia ixx="0.025492" ixy="0" ixz="0" iyy="0.032502" iyz="-3.26672e-18" izz="0.01779"/>
    </inertial>
  </link>
  <joint name="jHead" type="revolute">
    <parent link="link1"/>
    <child link="Head"/>
    <origin rpy="0 0 0 " xyz="0.1 0 0"/>
    <axis xyz="0 0 1"/>
    <limit effort="19.7336" lower="-0.6981" upper="0.6981" velocity="3.2"/>
  </joint>
  <link name="base_link">
    <inertial>
      <origin rpy="0 0 0" xyz="0 0 0"/>
      <mass value="1e-6"/>
      <inertia ixx="1e-12" ixy="0.0" ixz="0.0" iyy="1e-12" iyz="0.0" izz="1e-12"/>
    </inertial>
  </link> <!-- in pybullet, the inertia need to be specified even for dummy links, otherwise it will put an identity inertia and a mass of 1 by default -->
  <joint name="base_link_fixedjoint" type="fixed">
    <parent link="base_link"/>
    <child link="link1"/>
    <origin rpy="3.1416 0 0 " xyz="0 0 0.16"/>
    <axis xyz="0 0 0"/>
  </joint>
  <link name="link1">
    <visual>
      <origin rpy="3.1416 0 -1.5708 " xyz="-0.5 0.612 0.515"/>
      <geometry>
        <mesh filename="meshes/link1.STL" scale=".0015 .0015 .0015"/>
      </geometry>
    </visual>
    <collision>
      <origin rpy="3.1416 0 -1.5708 " xyz="-0.5 0.612 0.515"/>
      <geometry>
        <mesh filename="meshes/link1.STL" scale=".0015 .0015 .0015"/>
      </geometry>
    </collision>
    <inertial>
      <mass value="0.85"/>
      <origin rpy="0 0 0" xyz="0 0 0"/>
      <inertia ixx="0.025492" ixy="0" ixz="0" iyy="0.032502" iyz="-3.26672e-18" izz="0.01779"/>
    </inertial>
  </link>
  <joint name="j2" type="revolute">
    <parent link="link1"/>
    <child link="link2"/>
    <origin rpy="0 0 0 " xyz="-0.095 -0.0015 0.001"/>
    <axis xyz="0 0 1"/>
    <limit effort="19.7336" lower="-0.6981" upper="0.6981" velocity="3.2"/>
  </joint>
  <link name="link2">
    <visual>
      <origin rpy="3.1416 0 -1.5708 " xyz="-0.405 0.6135 0.516"/>
      <geometry>
        <mesh filename="meshes/link2.STL" scale=".0015 .0015 .0015"/>
      </geometry>
    </visual>
    <collision>
      <origin rpy="3.1416 0 -1.5708 " xyz="-0.405 0.6135 0.516"/>
      <geometry>
        <mesh filename="meshes/link2.STL" scale=".0015 .0015 .0015"/>
      </geometry>
    </collision>
    <inertial>
      <mass value="0.3619"/>
      <origin rpy="0 0 0" xyz="0 0 0"/>
      <inertia ixx="0.025492" ixy="0" ixz="0" iyy="0.032502" iyz="-3.26672e-18" izz="0.01779"/>
    </inertial>
  </link>
  <joint name="j3" type="revolute">
    <parent link="link2"/>
    <child link="link3"/>
    <origin rpy="0 0 0 " xyz="-0.17 0 0"/>
    <axis xyz="0 0 1"/>
    <limit effort="19.7336" lower="-0.6981" upper="0.6981" velocity="3.2"/>
  </joint>
  <link name="link3">
    <visual>
      <origin rpy="3.1416 0 -1.5708 " xyz="-0.235 0.6135 0.515"/>
      <geometry>
        <mesh filename="meshes/link3.STL" scale=".0015 .0015 .0015"/>
      </geometry>
    </visual>
    <collision>
      <origin rpy="3.1416 0 -1.5708 " xyz="-0.235 0.6135 0.515"/>
      <geometry>
        <mesh filename="meshes/link3.STL" scale=".0015 .0015 .0015"/>
      </geometry>
    </collision>
    <inertial>
      <mass value="0.3429"/>
      <origin rpy="0 0 0" xyz="0 0 0"/>
      <inertia ixx="0.025492" ixy="0" ixz="0" iyy="0.032502" iyz="-3.26672e-18" izz="0.01779"/>
    </inertial>
  </link>
  <joint name="j4" type="revolute">
    <parent link="link3"/>
    <child link="link4"/>
    <origin rpy="0 0 0 " xyz="-0.145 0 -0.0001"/>
    <axis xyz="0 0 1"/>
    <limit effort="19.7336" lower="-0.6981" upper="0.6981" velocity="3.2"/>
  </joint>
  <link name="link4">
    <visual>
      <origin rpy="3.1416 0 -1.5708 " xyz="-0.09 0.6135 0.515"/>
      <geometry>
        <mesh filename="meshes/link4.STL" scale=".0015 .0015 .0015"/>
      </geometry>
    </visual>
    <collision>
      <origin rpy="3.1416 0 -1.5708 " xyz="-0.09 0.6135 0.515"/>
      <geometry>
        <mesh filename="meshes/link4.STL" scale=".0015 .0015 .0015"/>
      </geometry>
    </collision>
    <inertial>
      <mass value="0.3329"/>
      <origin rpy="0 0 0" xyz="0 0 0"/>
      <inertia ixx="0.025492" ixy="0" ixz="0" iyy="0.032502" iyz="-3.26672e-18" izz="0.01779"/>
    </inertial>
  </link>
  <joint name="j5" type="revolute">
    <parent link="link4"/>
    <child link="link5"/>
    <origin rpy="0 0 0 " xyz="-0.13 0 0"/>
    <axis xyz="0 0 1"/>
    <limit effort="19.7336" lower="-0.6981" upper="0.6981" velocity="3.2"/>
  </joint>
  <link name="link5">
    <visual>
      <origin rpy="3.1416 0 -1.5708 " xyz="0.04 0.6135 0.515"/>
      <geometry>
        <mesh filename="meshes/link5.STL" scale=".0015 .0015 .0015"/>
      </geometry>
    </visual>
    <collision>
      <origin rpy="3.1416 0 -1.5708 " xyz="0.04 0.6135 0.515"/>
      <geometry>
        <mesh filename="meshes/link5.STL" scale=".0015 .0015 .0015"/>
      </geometry>
    </collision>
    <inertial>
      <mass value="0.3319"/>
      <origin rpy="0 0 0" xyz="0 0 0"/>
      <inertia ixx="0.025492" ixy="0" ixz="0" iyy="0.032502" iyz="-3.26672e-18" izz="0.01779"/>
    </inertial>
  </link>
  <link name="link12">
    <visual>
      <origin rpy="0 0 1.5708 " xyz="-0.5025 -0.735 -0.428"/>
      <geometry>
        <mesh filename="meshes/link12.STL" scale=".0015 .0015 .0015"/>
      </geometry>
    </visual>
    <collision>
      <origin rpy="0 0 1.5708 " xyz="-0.5025 -0.735 -0.428"/>
      <geometry>
        <mesh filename="meshes/link12.STL" scale=".0015 .0015 .0015"/>
      </geometry>
    </collision>
    <inertial>
      <mass value="0.159"/>
      <origin rpy="0 0 0" xyz="0 0 0"/>
      <inertia ixx="0.025492" ixy="0" ixz="0" iyy="0.032502" iyz="-3.26672e-18" izz="0.01779"/>
    </inertial>
  </link>
  <joint name="ForearmLeft_Yaw" type="revolute">
    <parent link="link1"/>
    <child link="link12"/>
    <origin rpy="0 0 0 " xyz="0.0025 -0.12 0.095"/>
    <axis xyz="0 0 1"/>
    <limit effort="19.7336" lower="-1.5708" upper="1.5708" velocity="2.2"/>
  </joint>
  <link name="link13">
    <visual>
      <origin rpy="3.1416 0 3.1416" xyz="0.737 0.5025 0.425"/>
      <geometry>
        <mesh filename="meshes/link13.STL" scale=".0015 .0015 .0015"/>
      </geometry>
    </visual>
    <collision>
      <origin rpy="3.1416 0 3.1416" xyz="0.737 0.5025 0.425"/>
      <geometry>
        <mesh filename="meshes/link13.STL" scale=".0015 .0015 .0015"/>
      </geometry>
    </collision>
    <inertial>
      <mass value="0.33101"/>
      <origin rpy="0 0 0" xyz="0 0 0"/>
      <inertia ixx="0.025492" ixy="0" ixz="0" iyy="0.032502" iyz="-3.26672e-18" izz="0.01779"/>
    </inertial>
  </link>
  <joint name="ForearmLeft_Pitch" type="revolute">
    <parent link="link12"/>
    <child link="link13"/>
    <origin rpy="0 0 1.5708 " xyz="0 0 -0.004"/>
    <axis xyz="0 1 0"/>
    <limit effort="19.7336" lower="-1.5708" upper="1.5708" velocity="2.2"/>
  </joint>
  <link name="link14">
    <visual>
      <origin rpy="0 0 0" xyz="-0.927 0.5025 -0.424"/>
      <geometry>
        <mesh filename="meshes/link14.STL" scale=".0015 .0015 .0015"/>
      </geometry>
    </visual>
    <collision>
      <origin rpy="0 0 0" xyz="-0.927 0.5025 -0.424"/>
      <geometry>
        <mesh filename="meshes/link14.STL" scale=".0015 .0015 .0015"/>
      </geometry>
    </collision>
    <inertial>
      <mass value="0.2674"/>
      <origin rpy="0 0 0" xyz="0 0 0"/>
      <inertia ixx="0.025492" ixy="0" ixz="0" iyy="0.032502" iyz="-3.26672e-18" izz="0.01779"/>
    </inertial>
  </link>
  <joint name="ForearmLeft_Roll" type="revolute">
    <parent link="link13"/>
    <child link="link14"/>
    <origin rpy="1.5708 0 3.1416" xyz="-0.19 0 0.003"/>
    <axis xyz="1 0 0"/>
    <limit effort="19.7336" lower="-1.5708" upper="1.5708" velocity="2.2"/>
  </joint>
  <link name="link15">
    <visual>
      <origin rpy="0 0 0" xyz="-0.951 0.5025 -0.426"/>
      <geometry>
        <mesh filename="meshes/link15.STL" scale=".0015 .0015 .0015"/>
      </geometry>
    </visual>
    <collision>
      <origin rpy="0 0 0" xyz="-0.951 0.5025 -0.426"/>
      <geometry>
        <mesh filename="meshes/link15.STL" scale=".0015 .0015 .0015"/>
      </geometry>
    </collision>
    <inertial>
      <mass value="0.11213"/>
      <origin rpy="0 0 0" xyz="0 0 0"/>
      <inertia ixx="0.025492" ixy="0" ixz="0" iyy="0.032502" iyz="-3.26672e-18" izz="0.01779"/>
    </inertial>
  </link>
  <joint name="ForearmLeft_Elbow" type="revolute">
    <parent link="link14"/>
    <child link="link15"/>
    <origin rpy="0 0 0 " xyz="0.025 0 0"/>
    <axis xyz="0 1 0"/>
    <limit effort="19.7336" lower="-1.5708" upper="1.5708" velocity="2.2"/>
  </joint>
  <link name="link16">
    <visual>
      <origin rpy="0 0 1.5708 " xyz="-0.503 -0.492 -0.428"/>
      <geometry>
        <mesh filename="meshes/link16.STL" scale=".0015 .0015 .0015"/>
      </geometry>
    </visual>
    <collision>
      <origin rpy="0 0 1.5708 " xyz="-0.503 -0.492 -0.428"/>
      <geometry>
        <mesh filename="meshes/link16.STL" scale=".0015 .0015 .0015"/>
      </geometry>
    </collision>
    <inertial>
      <mass value="0.125"/>
      <origin rpy="0 0 0" xyz="0 0 0"/>
      <inertia ixx="0.025492" ixy="0" ixz="0" iyy="0.032502" iyz="-3.26672e-18" izz="0.01779"/>
    </inertial>
  </link>
  <joint name="ForearmRight_Yaw" type="revolute">
    <parent link="link1"/>
    <child link="link16"/>
    <origin rpy="0 0 0" xyz="0.003 0.123 0.095"/>
    <axis xyz="0 0 1"/>
    <limit effort="19.7336" lower="-1.5708" upper="1.5708" velocity="3.2"/>
  </joint>
  <link name="link17">
    <visual>
      <origin rpy="3.1416 0 3.1416" xyz="0.493 0.503 0.424"/>
      <geometry>
        <mesh filename="meshes/link17.STL" scale=".0015 .0015 .0015"/>
      </geometry>
    </visual>
    <collision>
      <origin rpy="3.1416 0 3.1416" xyz="0.493 0.503 0.424"/>
      <geometry>
        <mesh filename="meshes/link17.STL" scale=".0015 .0015 .0015"/>
      </geometry>
    </collision>
    <inertial>
      <mass value="0.18191"/>
      <origin rpy="0 0 0" xyz="0 0 0"/>
      <inertia ixx="0.025492" ixy="0" ixz="0" iyy="0.032502" iyz="-3.26672e-18" izz="0.01779"/>
    </inertial>
  </link>
  <joint name="ForearmRight_Pitch" type="revolute">
    <parent link="link16"/>
    <child link="link17"/>
    <origin rpy="0 0 1.5708 " xyz="0 0 0"/>
    <axis xyz="0 1 0"/>
    <limit effort="19.7336" lower="-1.5708" upper="1.5708" velocity="3.2"/>
  </joint>
  <link name="link18">
    <visual>
      <origin rpy="0 0 -3.1416" xyz="0.305 -0.503 -0.424"/>
      <geometry>
        <mesh filename="meshes/link18.STL" scale=".0015 .0015 .0015"/>
      </geometry>
    </visual>
    <collision>
      <origin rpy="0 0 -3.1416" xyz="0.305 -0.503 -0.424"/>
      <geometry>
        <mesh filename="meshes/link18.STL" scale=".0015 .0015 .0015"/>
      </geometry>
    </collision>
    <inertial>
      <mass value="0.2674"/>
      <origin rpy="0 0 0" xyz="0 0 0"/>
      <inertia ixx="0.025492" ixy="0" ixz="0" iyy="0.032502" iyz="-3.26672e-18" izz="0.01779"/>
    </inertial>
  </link>
  <joint name="ForearmRight_Roll" type="revolute">
    <parent link="link17"/>
    <child link="link18"/>
    <origin rpy="-1.5708 0 0 " xyz="0.188 0 0"/>
    <axis xyz="1 0 0"/>
    <limit effort="19.7336" lower="-1.5708" upper="1.5708" velocity="3.2"/>
  </joint>
  <link name="link19">
    <visual>
      <origin rpy="0 0 0" xyz="-0.275 0.503 -0.425"/>
      <geometry>
        <mesh filename="meshes/link19.STL" scale=".0015 .0015 .0015"/>
      </geometry>
    </visual>
    <collision>
      <origin rpy="0 0 0" xyz="-0.275 0.503 -0.425"/>
      <geometry>
        <mesh filename="meshes/link19.STL" scale=".0015 .0015 .0015"/>
      </geometry>
    </collision>
    <inertial>
      <mass value="0.11213"/>
      <origin rpy="0 0 0" xyz="0 0 0"/>
      <inertia ixx="0.025492" ixy="0" ixz="0" iyy="0.032502" iyz="-3.26672e-18" izz="0.01779"/>
    </inertial>
  </link>
  <joint name="ForearmRight_Elbow" type="revolute">
    <parent link="link18"/>
    <child link="link19"/>
    <origin rpy="0 0 3.1416 " xyz="0.03 0 0"/>
    <axis xyz="0 1 0"/>
    <limit effort="19.7336" lower="-1.5708" upper="1.5708" velocity="3.2"/>
  </joint>
  <joint name="j6" type="revolute">
    <parent link="link5"/>
    <child link="link6"/>
    <origin rpy="0 0 0 " xyz="-0.133 0 0"/>
    <axis xyz="0 0 1"/>
    <limit effort="19.7336" lower="-0.6981" upper="0.6981" velocity="3.2"/>
  </joint>
  <link name="link6">
    <visual>
      <origin rpy="3.1416 0 -1.5708 " xyz="0.173 0.6135 0.515"/>
      <geometry>
        <mesh filename="meshes/link6.STL" scale=".0015 .0015 .0015"/>
      </geometry>
    </visual>
    <collision>
      <origin rpy="3.1416 0 -1.5708 " xyz="0.173 0.6135 0.515"/>
      <geometry>
        <mesh filename="meshes/link6.STL" scale=".0015 .0015 .0015"/>
      </geometry>
    </collision>
    <inertial>
      <mass value="0.67"/>
      <origin rpy="0 0 0" xyz="0 0 0"/>
      <inertia ixx="0.025492" ixy="0" ixz="0" iyy="0.032502" iyz="-3.26672e-18" izz="0.01779"/>
    </inertial>
  </link>
  <joint name="j_tailBone" type="revolute">
    <parent link="link6"/>
    <child link="link_tailBone"/>
    <origin rpy="0 0 0 " xyz="-0.16 0 0"/>
    <axis xyz="0 1 0"/>
    <limit effort="19.7336" lower="-0.2" upper="0.2" velocity="1.2"/>
  </joint>
  <link name="link_tailBone">
    <visual>
      <origin rpy="3.1416 0 -1.58 " xyz="0.338 0.61 0.515"/>
      <geometry>
        <mesh filename="meshes/tailbone.STL" scale=".0015 .0015 .0015"/>
      </geometry>
    </visual>
    <collision>
      <origin rpy="3.1416 0 -1.58 " xyz="0.338 0.61 0.515"/>
      <geometry>
        <mesh filename="meshes/tailbone.STL" scale=".0015 .0015 .0015"/>
      </geometry>
    </collision>
    <inertial>
      <mass value="0.1299"/>
      <origin rpy="0 0 0" xyz="0 0 0"/>
      <inertia ixx="0.025492" ixy="0" ixz="0" iyy="0.032502" iyz="-3.26672e-18" izz="0.01779"/>
    </inertial>
  </link>
  <joint name="j7" type="revolute">
    <parent link="link_tailBone"/>
    <child link="link7"/>
    <origin rpy="0 0 0 " xyz="-0.05 0 0"/>
    <axis xyz="0 0 1"/>
    <limit effort="19.7336" lower="-0.6981" upper="0.6981" velocity="3.2"/>
  </joint>
  <link name="link7">
    <visual>
      <origin rpy="3.1416 0 -1.5708 " xyz="0.382 0.6135 0.521"/>
      <geometry>
        <mesh filename="meshes/link7.STL" scale=".0015 .0015 .0015"/>
      </geometry>
    </visual>
    <collision>
      <origin rpy="3.1416 0 -1.5708 " xyz="0.382 0.6135 0.521"/>
      <geometry>
        <mesh filename="meshes/link7.STL" scale=".0015 .0015 .0015"/>
      </geometry>
    </collision>
    <inertial>
      <mass value="0.3241"/>
      <origin rpy="0 0 0" xyz="0 0 0"/>
      <inertia ixx="0.025492" ixy="0" ixz="0" iyy="0.032502" iyz="-3.26672e-18" izz="0.01779"/>
    </inertial>
  </link>
  <joint name="j8" type="revolute">
    <parent link="link7"/>
    <child link="link8"/>
    <origin rpy="0 0 0 " xyz="-0.128 0 0"/>
    <axis xyz="0 0 1"/>
    <limit effort="19.7336" lower="-0.6981" upper="0.6981" velocity="3.2"/>
  </joint>
  <link name="link8">
    <visual>
      <origin rpy="0 0 1.5708 " xyz="0.5094 -0.6135 -0.5145"/>
      <geometry>
        <mesh filename="meshes/link8.STL" scale=".0015 .0015 .0015"/>
      </geometry>
    </visual>
    <collision>
      <origin rpy="0 0 1.5708 " xyz="0.5094 -0.6135 -0.5145"/>
      <geometry>
        <mesh filename="meshes/link8.STL" scale=".0015 .0015 .0015"/>
      </geometry>
    </collision>
    <inertial>
      <mass value="0.3993"/>
      <origin rpy="0 0 0" xyz="0 0 0"/>
      <inertia ixx="0.025492" ixy="0" ixz="0" iyy="0.032502" iyz="-3.26672e-18" izz="0.01779"/>
    </inertial>
  </link>
  <joint name="j9" type="revolute">
    <parent link="link8"/>
    <child link="link9"/>
    <origin rpy="0 0 0 " xyz="-0.11 0 0"/>
    <axis xyz="0 0 1"/>
    <limit effort="19.7336" lower="-0.6981" upper="0.6981" velocity="3.2"/>
  </joint>
  <link name="link9">
    <visual>
      <origin rpy="0 0 1.5708 " xyz="0.618 -0.613 -0.5145"/>
      <geometry>
        <mesh filename="meshes/link9.STL" scale=".0015 .0015 .0015"/>
      </geometry>
    </visual>
    <collision>
      <origin rpy="0 0 1.5708 " xyz="0.618 -0.613 -0.5145"/>
      <geometry>
        <mesh filename="meshes/link9.STL" scale=".0015 .0015 .0015"/>
      </geometry>
    </collision>
    <inertial>
      <mass value="0.3089"/>
      <origin rpy="0 0 0" xyz="0 0 0"/>
      <inertia ixx="0.025492" ixy="0" ixz="0" iyy="0.032502" iyz="-3.26672e-18" izz="0.01779"/>
    </inertial>
  </link>
  <joint name="j10" type="revolute">
    <parent link="link9"/>
    <child link="link10"/>
    <origin rpy="0 0 0 " xyz="-0.115 0 0"/>
    <axis xyz="0 0 1"/>
    <limit effort="19.7336" lower="-0.6981" upper="0.6981" velocity="3.2"/>
  </joint>
  <link name="link10">
    <visual>
      <origin rpy="0 0 1.5708 " xyz="0.732 -0.613 -0.5145"/>
      <geometry>
        <mesh filename="meshes/link10.STL" scale=".0015 .0015 .0015"/>
      </geometry>
    </visual>
    <collision>
      <origin rpy="0 0 1.5708 " xyz="0.732 -0.613 -0.5145"/>
      <geometry>
        <mesh filename="meshes/link10.STL" scale=".0015 .0015 .0015"/>
      </geometry>
    </collision>
    <inertial>
      <mass value="0.327"/>
      <origin rpy="0 0 0" xyz="0 0 0"/>
      <inertia ixx="0.025492" ixy="0" ixz="0" iyy="0.032502" iyz="-3.26672e-18" izz="0.01779"/>
    </inertial>
  </link>
  <joint name="j11" type="revolute">
    <parent link="link10"/>
    <child link="link11"/>
    <origin rpy="0 0 0 " xyz="-0.14 0 0"/>
    <axis xyz="0 0 1"/>
    <limit effort="19.7336" lower="-0.6981" upper="0.6981" velocity="3.2"/>
  </joint>
  <link name="link11">
    <visual>
      <origin rpy="0 0 1.5708 " xyz="0.871 -0.613 -0.5145"/>
      <geometry>
        <mesh filename="meshes/link11.STL" scale=".0015 .0015 .0015"/>
      </geometry>
    </visual>
    <collision>
      <origin rpy="0 0 1.5708 " xyz="0.871 -0.613 -0.5145"/>
      <geometry>
        <mesh filename="meshes/link11.STL" scale=".0015 .0015 .0015"/>
      </geometry>
    </collision>
    <inertial>
      <mass value="0.3161"/>
      <origin rpy="0 0 0" xyz="0 0 0"/>
      <inertia ixx="0.025492" ixy="0" ixz="0" iyy="0.032502" iyz="-3.26672e-18" izz="0.01779"/>
    </inertial>
  </link>
  <link name="link20">
    <visual>
      <origin rpy="0 0 -1.5708 " xyz="-0.275 0.687 -0.4465"/>
      <geometry>
        <mesh filename="meshes/link20.STL" scale=".0015 .0015 .0015"/>
      </geometry>
    </visual>
    <collision>
      <origin rpy="0 0 -1.5708 " xyz="-0.275 0.687 -0.4465"/>
      <geometry>
        <mesh filename="meshes/link20.STL" scale=".0015 .0015 .0015"/>
      </geometry>
    </collision>
    <inertial>
      <mass value="0.1244"/>
      <origin rpy="0 0 0" xyz="0 0 0"/>
      <inertia ixx="0.025492" ixy="0" ixz="0" iyy="0.032502" iyz="-3.26672e-18" izz="0.01779"/>
    </inertial>
  </link>
  <joint name="HindLimbLeft_Yaw" type="revolute">
    <parent link="link6"/>
    <child link="link20"/>
    <origin rpy="0 0 0 " xyz="-0.102 -0.073 0.07"/>
    <axis xyz="0 0 1"/>
    <limit effort="19.7336" lower="-1.5708" upper="1.5708" velocity="2.2"/>
  </joint>
  <link name="link21">
    <visual>
      <origin rpy="3.1416 0 3.1416 " xyz="0.685 -0.275 0.445"/>
      <geometry>
        <mesh filename="meshes/link21.STL" scale=".0015 .0015 .0015"/>
      </geometry>
    </visual>
    <collision>
      <origin rpy="3.1416 0 3.1416 " xyz="0.685 -0.275 0.445"/>
      <geometry>
        <mesh filename="meshes/link21.STL" scale=".0015 .0015 .0015"/>
      </geometry>
    </collision>
    <inertial>
      <mass value="0.25582"/>
      <origin rpy="0 0 0" xyz="0 0 0"/>
      <inertia ixx="0.025492" ixy="0" ixz="0" iyy="0.032502" iyz="-3.26672e-18" izz="0.01779"/>
    </inertial>
  </link>
  <joint name="HindLimbLeft_Pitch" type="revolute">
    <parent link="link20"/>
    <child link="link21"/>
    <origin rpy="3.1416 3.1416 -1.5708 " xyz="0 0 0"/>
    <axis xyz="0 1 0"/>
    <limit effort="19.7336" lower="-1.5708" upper="1.5708" velocity="2.2"/>
  </joint>
  <link name="link22">
    <visual>
      <origin rpy="0 0 0" xyz="-0.855 -0.275 -0.445"/>
      <geometry>
        <mesh filename="meshes/link22.STL" scale=".0015 .0015 .0015"/>
      </geometry>
    </visual>
    <collision>
      <origin rpy="0 0 0" xyz="-0.855 -0.275 -0.445"/>
      <geometry>
        <mesh filename="meshes/link22.STL" scale=".0015 .0015 .0015"/>
      </geometry>
    </collision>
    <inertial>
      <mass value="0.2776"/>
      <origin rpy="0 0 0" xyz="0 0 0"/>
      <inertia ixx="0.025492" ixy="0" ixz="0" iyy="0.032502" iyz="-3.26672e-18" izz="0.01779"/>
    </inertial>
  </link>
  <joint name="HindLimbLeft_Roll" type="revolute">
    <parent link="link21"/>
    <child link="link22"/>
    <origin rpy="3.1416 0 3.1416 " xyz="-0.168 0 0"/>
    <axis xyz="1 0 0"/>
    <limit effort="19.7336" lower="-1.5708" upper="1.5708" velocity="2.2"/>
  </joint>
  <link name="link23">
    <visual>
      <origin rpy="0 0 0" xyz="-0.876 -0.272 -0.445"/>
      <geometry>
        <mesh filename="meshes/link23.STL" scale=".0015 .0015 .0015"/>
      </geometry>
    </visual>
    <collision>
      <origin rpy="0 0 0" xyz="-0.876 -0.272 -0.445"/>
      <geometry>
        <mesh filename="meshes/link23.STL" scale=".0015 .0015 .0015"/>
      </geometry>
    </collision>
    <inertial>
      <mass value="0.26"/>
      <origin rpy="0 0 0" xyz="0 0 0"/>
      <inertia ixx="0.025492" ixy="0" ixz="0" iyy="0.032502" iyz="-3.26672e-18" izz="0.01779"/>
    </inertial>
  </link>
  <joint name="HindLimbLeft_Elbow" type="revolute">
    <parent link="link22"/>
    <child link="link23"/>
    <origin rpy="0 -1.5708 0 " xyz="0.022 -0.003 0"/>
    <axis xyz="0 1 0"/>
    <limit effort="19.7336" lower="-2.61" upper="2.61" velocity="2.2"/>
  </joint>
  <link name="link24">
    <visual>
      <origin rpy="3.1416 0 -1.5708 " xyz="0.275 0.54 0.4465"/>
      <geometry>
        <mesh filename="meshes/link24.STL" scale=".0015 .0015 .0015"/>
      </geometry>
    </visual>
    <collision>
      <origin rpy="3.1416 0 -1.5708 " xyz="0.275 0.54 0.4465"/>
      <geometry>
        <mesh filename="meshes/link24.STL" scale=".0015 .0015 .0015"/>
      </geometry>
    </collision>
    <inertial>
      <mass value="0.1244"/>
      <origin rpy="0 0 0" xyz="0 0 0"/>
      <inertia ixx="0.025492" ixy="0" ixz="0" iyy="0.032502" iyz="-3.26672e-18" izz="0.01779"/>
    </inertial>
  </link>
  <joint name="HindLimbRight_Yaw" type="revolute">
    <parent link="link6"/>
    <child link="link24"/>
    <origin rpy="0 0 0 " xyz="-0.102 0.0735 0.07"/>
    <axis xyz="0 0 1"/>
    <limit effort="19.7336" lower="-1.5708" upper="1.5708" velocity="2.2"/>
  </joint>
  <link name="link25">
    <visual>
      <origin rpy="0 3.1416 0 " xyz="0.542 -0.275 0.445"/>
      <geometry>
        <mesh filename="meshes/link25.STL" scale=".0015 .0015 .0015"/>
      </geometry>
    </visual>
    <collision>
      <origin rpy="0 3.1416 0 " xyz="0.542 -0.275 0.445"/>
      <geometry>
        <mesh filename="meshes/link25.STL" scale=".0015 .0015 .0015"/>
      </geometry>
    </collision>
    <inertial>
      <mass value="0.14236"/>
      <origin rpy="0 0 0" xyz="0 0 0"/>
      <inertia ixx="0.025492" ixy="0" ixz="0" iyy="0.032502" iyz="-3.26672e-18" izz="0.01779"/>
    </inertial>
  </link>
  <joint name="HindLimbRight_Pitch" type="revolute">
    <parent link="link24"/>
    <child link="link25"/>
    <origin rpy="0 0 1.5708 " xyz="0 0 0"/>
    <axis xyz="0 1 0"/>
    <limit effort="19.7336" lower="-1.5708" upper="1.5708" velocity="2.2"/>
  </joint>
  <link name="link26">
    <visual>
      <origin rpy="0 0 3.1416" xyz="0.37 0.275 -0.444"/>
      <geometry>
        <mesh filename="meshes/link26.STL" scale=".0015 .0015 .0015"/>
      </geometry>
    </visual>
    <collision>
      <origin rpy="0 0 3.1416" xyz="0.37 0.275 -0.444"/>
      <geometry>
        <mesh filename="meshes/link26.STL" scale=".0015 .0015 .0015"/>
      </geometry>
    </collision>
    <inertial>
      <mass value="0.0416"/>
      <origin rpy="0 0 0" xyz="0 0 0"/>
      <inertia ixx="0.025492" ixy="0" ixz="0" iyy="0.032502" iyz="-3.26672e-18" izz="0.01779"/>
    </inertial>
  </link>
  <joint name="HindLimbRight_Roll" type="revolute">
    <parent link="link25"/>
    <child link="link26"/>
    <origin rpy="3.1416 0 0 " xyz="0.17 0 0.001"/>
    <axis xyz="1 0 0"/>
    <limit effort="19.7336" lower="-1.5708" upper="1.5708" velocity="2.2"/>
  </joint>
  <link name="link27">
    <visual>
      <origin rpy="0 0 0" xyz="-0.35 -0.2753 -0.448"/>
      <geometry>
        <mesh filename="meshes/link27.STL" scale=".0015 .0015 .0015"/>
      </geometry>
    </visual>
    <collision>
      <origin rpy="0 0 0" xyz="-0.35 -0.2753 -0.448"/>
      <geometry>
        <mesh filename="meshes/link27.STL" scale=".0015 .0015 .0015"/>
      </geometry>
    </collision>
    <inertial>
      <mass value="0.16"/>
      <origin rpy="0 0 0" xyz="0 0 0"/>
      <inertia ixx="0.025492" ixy="0" ixz="0" iyy="0.032502" iyz="-3.26672e-18" izz="0.01779"/>
    </inertial>
  </link>
  <joint name="HindLimbRight_Elbow" type="revolute">
    <parent link="link26"/>
    <child link="link27"/>
    <origin rpy="0 1.5708 3.1416 " xyz="0.02 0 0"/>
    <axis xyz="0 1 0"/>
    <limit effort="19.7336" lower="-2.61" upper="2.61" velocity="2.2"/>
  </joint>
  <joint name="j_tail" type="revolute">
    <parent link="link11"/>
    <child link="link_tail"/>
    <origin rpy="0 0 0 " xyz="-0.1 0 0"/>
    <axis xyz="0 1 0"/>
    <limit effort="19.7336" lower="-0.2" upper="0.2" velocity="1.2"/>
  </joint>
  <link name="link_tail">
    <visual>
      <origin rpy="0 0 1.5708 " xyz="0.97 -0.6125 -0.51"/>
      <geometry>
        <mesh filename="meshes/tail.STL" scale=".0015 .0015 .0015"/>
      </geometry>
    </visual>
    <collision>
      <origin rpy="0 0 1.5708 " xyz="0.97 -0.6125 -0.51"/>
      <geometry>
        <mesh filename="meshes/tail.STL" scale=".0015 .0015 .0015"/>
      </geometry>
    </collision>
    <inertial>
      <mass value="0.19391"/>
      <origin rpy="0 0 0" xyz="0 0 0"/>
      <inertia ixx="0.025492" ixy="0" ixz="0" iyy="0.032502" iyz="-3.26672e-18" izz="0.01779"/>
    </inertial>
  </link>
  <!-- Camera -->
  <joint name="camera_rgb_joint" type="fixed">
    <origin rpy="0 0 0" xyz="-0.087 -0.0125 0.116"/>
    <parent link="Head"/>
    <child link="camera_rgb_frame"/>
  </joint>
  <link name="camera_rgb_frame">
    <inertial>
      <origin rpy="0 0 0" xyz="0 0 0"/>
      <mass value="0"/>
      <inertia ixx="0.0" ixy="0.0" ixz="0.0" iyy="0.0" iyz="0.0" izz="0.0"/>
    </inertial>
  </link> <!-- in pybullet, the inertia need to be specified even for dummy links, otherwise it will put an identity inertia and a mass of 1 by default -->
  <joint name="camera_rgb_optical_joint" type="fixed">
    <origin rpy="-1.5707963268 0 -1.5707963268" xyz="0 0 0"/>
    <parent link="camera_rgb_frame"/>
    <child link="camera_rgb_optical_frame"/>
  </joint>
  <link name="camera_rgb_optical_frame">
    <inertial>
      <origin rpy="0 0 0" xyz="0 0 0"/>
      <mass value="0"/>
      <inertia ixx="0.0" ixy="0.0" ixz="0.0" iyy="0.0" iyz="0.0" izz="0.0"/>
    </inertial>
  </link> <!-- in pybullet, the inertia need to be specified even for dummy links, otherwise it will put an identity inertia and a mass of 1 by default -->
  <link name="camera_link">
    <collision>
      <origin rpy="0 0 1.5707963268" xyz="0 0 0"/>
      <geometry>
        <mesh filename="meshes/sensors/kinect.dae"/>
      </geometry>
    </collision>
    <visual>
      <origin rpy="0 0 1.5707963268" xyz="0 0 0"/>
      <geometry>
        <mesh filename="meshes/sensors/kinect.dae"/>
      </geometry>
      <material name="green"/>
    </visual>
    <inertial>
      <mass value="0.564"/>
      <origin xyz="0 0 0"/>
      <inertia ixx="0.003881243" ixy="0.0" ixz="0.0" iyy="0.000498940" iyz="0.0" izz="0.003879257"/>
    </inertial>
  </link>
  <joint name="camera_joint" type="fixed">
    <axis xyz="0 0 1"/>
    <origin rpy="0 0 0" xyz="0 0 0.1"/>
    <parent link="Head"/>
    <child link="camera_link"/>
  </joint>
  <!-- The fixed joints & links below are usually published by static_transformers launched by the OpenNi launch 
         files. However, for Gazebo simulation we need them, so we add them here. (Hence, don't publish them additionally!) -->
  <joint name="camera_depth_joint" type="fixed">
    <origin rpy="0 0 0" xyz="0 0.025 0"/>
    <parent link="camera_rgb_frame"/>
    <child link="camera_depth_frame"/>
  </joint>
  <link name="camera_depth_frame">
    <inertial>
      <origin rpy="0 0 0" xyz="0 0 0"/>
      <mass value="0"/>
      <inertia ixx="0.0" ixy="0.0" ixz="0.0" iyy="0.0" iyz="0.0" izz="0.0"/>
    </inertial>
  </link> <!-- in pybullet, the inertia need to be specified even for dummy links, otherwise it will put an identity inertia and a mass of 1 by default -->
  <joint name="camera_depth_optical_joint" type="fixed">
    <origin rpy="-1.5707963268 0 -1.5707963268" xyz="0 0 0"/>
    <parent link="camera_depth_frame"/>
    <child link="camera_depth_optical_frame"/>
  </joint>
  <link name="camera_depth_optical_frame">
    <inertial>
      <origin rpy="0 0 0" xyz="0 0 0"/>
      <mass value="0"/>
      <inertia ixx="0.0" ixy="0.0" ixz="0.0" iyy="0.0" iyz="0.0" izz="0.0"/>
    </inertial>
  </link> <!-- in pybullet, the inertia need to be specified even for dummy links, otherwise it will put an identity inertia and a mass of 1 by default -->
  <!-- Asus xtion pro live -->
  <!--xacro:include filename="$(find pleurobot_ros_pkg)/urdf/sensors/xtion.urdf.xacro"/-->
</robot>

