<?xml version="1.0" ?>
<!-- =================================================================================== -->
<!-- |    This document was autogenerated by xacro from huboplus.xacro                 | -->
<!-- |    EDITING THIS FILE BY HAND IS NOT RECOMMENDED                                 | -->
<!-- =================================================================================== -->
<robot name="huboplus" xmlns:xacro="http://www.ros.org/wiki/xacro">
  <link name="Body_Torso">
    <inertial>
      <mass value="7.50334"/>
      <inertia ixx="0.102019" ixy="2.45462e-05" ixz="0.00713022" iyy="0.0832724" iyz="-0.00131733" izz="0.086493"/>
      <origin xyz="0 0 0"/>
    </inertial>
    <visual>
      <geometry>
        <mesh filename="meshes/Body_Torso_vis.dae"/>
      </geometry>
      <material name="random">
        <color rgba="0.866667 0.866667 0.866667 1"/>
      </material>
    </visual>
    <collision>
      <geometry>
        <mesh filename="meshes/Body_Torso.stl"/>
      </geometry>
    </collision>
  </link>
  <!-- Robots should have necks, dammit! -->
  <link name="Body_Neck">
    <collision>
        <geometry>
        <mesh filename="meshes/Body_Neck.stl"/>
      </geometry>
    </collision>
    <visual>
      <geometry>
        <mesh filename="meshes/Body_Neck.stl"/>
      </geometry>
      <material name="random">
        <color rgba="0.866667 0.866667 0.866667 1"/>
      </material>
    </visual>
    <!-- and they should have an inertia, dammit! Because we do not know the value, we put something small. -->
    <inertial>
      <mass value="0.000001"/>
      <inertia ixx="1e-12" ixy="0" ixz="0" iyy="1e-12" iyz="0" izz="1e-12"/>
      <origin xyz="0 0 0"/>
    </inertial>
  </link>
  <link name="Body_Head_Empty">
    <inertial>
      <mass value="0.000001"/>
      <inertia ixx="1e-12" ixy="0" ixz="0" iyy="1e-12" iyz="0" izz="1e-12"/>
      <origin xyz="0 0 0"/>
    </inertial>
  </link> 
  <link name="Body_Head">
    <inertial>
      <mass value="0.374251"/>
      <inertia ixx="0.00164033" ixy="-1.08171e-07" ixz="-9.53978e-05" iyy="0.00153943" iyz="1.25376e-06" izz="0.00190393"/>
      <origin xyz="0.0106886 -3.00864e-05 0.032123"/>
    </inertial>
    <visual>
      <geometry>
        <mesh filename="meshes/Body_Head.stl"/>
      </geometry>
      <material name="random">
        <color rgba="0.866667 0.866667 0.866667 1"/>
      </material>
    </visual>
    <collision>
      <geometry>
        <mesh filename="meshes/Body_Head.stl"/>
      </geometry>
    </collision>
  </link>
  <link name="Body_LSP">
    <inertial>
      <mass value="0.646655"/>
      <inertia ixx="0.000893731" ixy="-0.000156484" ixz="4.98007e-07" iyy="0.00093016" iyz="1.57095e-07" izz="0.00124323"/>
      <origin xyz="0.0167207 0.0570407 9.91873e-06"/>
    </inertial>
    <visual>
      <geometry>
        <mesh filename="meshes/Body_LSP_vis.dae"/>
      </geometry>
      <material name="random">
        <color rgba="0.866667 0.866667 0.866667 1"/>
      </material>
    </visual>
    <collision>
      <geometry>
        <mesh filename="meshes/Body_LSP.stl"/>
      </geometry>
    </collision>
  </link>
  <link name="Body_LSR">
    <inertial>
      <mass value="0.413368"/>
      <inertia ixx="0.000269283" ixy="4.52571e-07" ixz="3.23662e-06" iyy="0.00037679" iyz="9.93935e-07" izz="0.000360355"/>
      <origin xyz="-0.036208 -8.31243e-05 -0.00126685"/>
    </inertial>
    <visual>
      <geometry>
        <mesh filename="meshes/Body_LSR_vis.dae"/>
      </geometry>
      <material name="random">
        <color rgba="0.866667 0.866667 0.866667 1"/>
      </material>
    </visual>
    <collision>
      <geometry>
        <mesh filename="meshes/Body_LSR.stl"/>
      </geometry>
    </collision>
  </link>
  <link name="Body_LSY">
    <inertial>
      <mass value="1.15461"/>
      <inertia ixx="0.00365479" ixy="2.05436e-06" ixz="0.000418448" iyy="0.00364731" iyz="-3.09648e-05" izz="0.00060633"/>
      <origin xyz="0.00456121 3.10576e-05 -0.0907824"/>
    </inertial>
    <visual>
      <geometry>
        <mesh filename="meshes/Body_LSY_vis.dae"/>
      </geometry>
      <material name="random">
        <color rgba="0.866667 0.866667 0.866667 1"/>
      </material>
    </visual>
    <collision>
      <geometry>
        <mesh filename="meshes/Body_LSY.stl"/>
      </geometry>
    </collision>
  </link>
  <link name="Body_LEB">
    <inertial>
      <mass value="0.44094"/>
      <inertia ixx="0.0005027" ixy="3.64587e-06" ixz="-1.41388e-05" iyy="0.00049415" iyz="7.65528e-06" izz="0.000131786"/>
      <origin xyz="-0.0217349 0.0178314 -0.0610873"/>
    </inertial>
    <visual>
      <geometry>
        <mesh filename="meshes/Body_LEB.stl"/>
      </geometry>
      <material name="random">
        <color rgba="0.866667 0.866667 0.866667 1"/>
      </material>
    </visual>
    <collision>
      <geometry>
        <mesh filename="meshes/Body_LEB.stl"/>
      </geometry>
    </collision>
  </link>
  <link name="Body_LWY">
    <inertial>
      <mass value="0.537738"/>
      <inertia ixx="0.00063457" ixy="-4.62486e-07" ixz="6.20682e-06" iyy="0.000563918" iyz="3.54044e-05" izz="0.000305422"/>
      <origin xyz="-0.00122019 0.000635233 -0.0238043"/>
    </inertial>
    <visual>
      <geometry>
        <mesh filename="meshes/Body_LWY_vis.dae"/>
      </geometry>
      <material name="random">
        <color rgba="0.866667 0.866667 0.866667 1"/>
      </material>
    </visual>
    <collision>
      <geometry>
        <mesh filename="meshes/Body_LWY.stl"/>
      </geometry>
    </collision>
  </link>
  <link name="Body_LWP">
    <inertial>
      <mass value="0.164393"/>
      <inertia ixx="9.74327e-05" ixy="-5.22155e-07" ixz="-1.17317e-06" iyy="0.000144494" iyz="9.4927e-06" izz="0.000122681"/>
      <origin xyz="-0.000258199 0.011442 -0.0461472"/>
    </inertial>
    <visual>
      <geometry>
        <mesh filename="meshes/Body_LWP_vis.dae"/>
      </geometry>
      <material name="random">
        <color rgba="0.866667 0.866667 0.866667 1"/>
      </material>
    </visual>
    <collision>
      <geometry>
        <mesh filename="meshes/Body_LWP.stl"/>
      </geometry>
    </collision>
  </link>
  <link name="leftThumbProximal">
    <inertial>
      <mass value="0.096"/>
      <inertia ixx="2.304e-06" ixy="0" ixz="0" iyy="8.96e-06" iyz="6.85949e-15" izz="9.216e-06"/>
      <origin xyz="0.024 0 0"/>
    </inertial>
    <visual>
      <geometry>
        <mesh filename="meshes/proximal.stl"/>
      </geometry>
      <material name="random">
        <color rgba="0.866667 0.866667 0.866667 1"/>
      </material>
    </visual>
    <collision>
      <geometry>
        <mesh filename="meshes/proximal.stl"/>
      </geometry>
    </collision>
  </link>
  <link name="leftThumbMedial">
    <inertial>
      <mass value="0.048"/>
      <inertia ixx="1.152e-06" ixy="0" ixz="0" iyy="2.59e-06" iyz="3.42975e-15" izz="2.718e-06"/>
      <origin xyz="0.0165 0 0"/>
    </inertial>
    <visual>
      <geometry>
        <mesh filename="meshes/medial_distal.stl"/>
      </geometry>
      <material name="random">
        <color rgba="0.866667 0.866667 0.866667 1"/>
      </material>
    </visual>
    <collision>
      <geometry>
        <mesh filename="meshes/medial_distal.stl"/>
      </geometry>
    </collision>
  </link>
  <link name="leftThumbDistal">
    <inertial>
      <mass value="0.08"/>
      <inertia ixx="1.92e-06" ixy="0" ixz="0" iyy="3.82667e-06" iyz="5.71624e-15" izz="4.04e-06"/>
      <origin xyz="0.015 0 0"/>
    </inertial>
    <visual>
      <geometry>
        <mesh filename="meshes/medial_distal.stl"/>
      </geometry>
      <material name="random">
        <color rgba="0.866667 0.866667 0.866667 1"/>
      </material>
    </visual>
    <collision>
      <geometry>
        <mesh filename="meshes/medial_distal.stl"/>
      </geometry>
    </collision>
  </link>
  <link name="leftPinkyProximal">
    <inertial>
      <mass value="0.096"/>
      <inertia ixx="2.304e-06" ixy="0" ixz="0" iyy="8.96e-06" iyz="6.85949e-15" izz="9.216e-06"/>
      <origin xyz="0.024 0 0"/>
    </inertial>
    <visual>
      <geometry>
        <mesh filename="meshes/proximal.stl"/>
      </geometry>
      <material name="random">
        <color rgba="0.866667 0.866667 0.866667 1"/>
      </material>
    </visual>
    <collision>
      <geometry>
        <mesh filename="meshes/proximal.stl"/>
      </geometry>
    </collision>
  </link>
  <link name="leftPinkyMedial">
    <inertial>
      <mass value="0.048"/>
      <inertia ixx="1.152e-06" ixy="0" ixz="0" iyy="2.59e-06" iyz="3.42975e-15" izz="2.718e-06"/>
      <origin xyz="0.0165 0 0"/>
    </inertial>
    <visual>
      <geometry>
        <mesh filename="meshes/medial_distal.stl"/>
      </geometry>
      <material name="random">
        <color rgba="0.866667 0.866667 0.866667 1"/>
      </material>
    </visual>
    <collision>
      <geometry>
        <mesh filename="meshes/medial_distal.stl"/>
      </geometry>
    </collision>
  </link>
  <link name="leftPinkyDistal">
    <inertial>
      <mass value="0.08"/>
      <inertia ixx="1.92e-06" ixy="0" ixz="0" iyy="3.82667e-06" iyz="5.71624e-15" izz="4.04e-06"/>
      <origin xyz="0.015 0 0"/>
    </inertial>
    <visual>
      <geometry>
        <mesh filename="meshes/medial_distal.stl"/>
      </geometry>
      <material name="random">
        <color rgba="0.866667 0.866667 0.866667 1"/>
      </material>
    </visual>
    <collision>
      <geometry>
        <mesh filename="meshes/medial_distal.stl"/>
      </geometry>
    </collision>
  </link>
  <link name="leftRingProximal">
    <inertial>
      <mass value="0.096"/>
      <inertia ixx="2.304e-06" ixy="0" ixz="0" iyy="8.96e-06" iyz="6.85949e-15" izz="9.216e-06"/>
      <origin xyz="0.024 0 0"/>
    </inertial>
    <visual>
      <geometry>
        <mesh filename="meshes/proximal.stl"/>
      </geometry>
      <material name="random">
        <color rgba="0.866667 0.866667 0.866667 1"/>
      </material>
    </visual>
    <collision>
      <geometry>
        <mesh filename="meshes/proximal.stl"/>
      </geometry>
    </collision>
  </link>
  <link name="leftRingMedial">
    <inertial>
      <mass value="0.048"/>
      <inertia ixx="1.152e-06" ixy="0" ixz="0" iyy="2.59e-06" iyz="3.42975e-15" izz="2.718e-06"/>
      <origin xyz="0.0165 0 0"/>
    </inertial>
    <visual>
      <geometry>
        <mesh filename="meshes/medial_distal.stl"/>
      </geometry>
      <material name="random">
        <color rgba="0.866667 0.866667 0.866667 1"/>
      </material>
    </visual>
    <collision>
      <geometry>
        <mesh filename="meshes/medial_distal.stl"/>
      </geometry>
    </collision>
  </link>
  <link name="leftRingDistal">
    <inertial>
      <mass value="0.08"/>
      <inertia ixx="1.92e-06" ixy="0" ixz="0" iyy="3.82667e-06" iyz="5.71624e-15" izz="4.04e-06"/>
      <origin xyz="0.015 0 0"/>
    </inertial>
    <visual>
      <geometry>
        <mesh filename="meshes/medial_distal.stl"/>
      </geometry>
      <material name="random">
        <color rgba="0.866667 0.866667 0.866667 1"/>
      </material>
    </visual>
    <collision>
      <geometry>
        <mesh filename="meshes/medial_distal.stl"/>
      </geometry>
    </collision>
  </link>
  <link name="leftMiddleProximal">
    <inertial>
      <mass value="0.096"/>
      <inertia ixx="2.304e-06" ixy="0" ixz="0" iyy="8.96e-06" iyz="6.85949e-15" izz="9.216e-06"/>
      <origin xyz="0.024 0 0"/>
    </inertial>
    <visual>
      <geometry>
        <mesh filename="meshes/proximal.stl"/>
      </geometry>
      <material name="random">
        <color rgba="0.866667 0.866667 0.866667 1"/>
      </material>
    </visual>
    <collision>
      <geometry>
        <mesh filename="meshes/proximal.stl"/>
      </geometry>
    </collision>
  </link>
  <link name="leftMiddleMedial">
    <inertial>
      <mass value="0.048"/>
      <inertia ixx="1.152e-06" ixy="0" ixz="0" iyy="2.59e-06" iyz="3.42975e-15" izz="2.718e-06"/>
      <origin xyz="0.0165 0 0"/>
    </inertial>
    <visual>
      <geometry>
        <mesh filename="meshes/medial_distal.stl"/>
      </geometry>
      <material name="random">
        <color rgba="0.866667 0.866667 0.866667 1"/>
      </material>
    </visual>
    <collision>
      <geometry>
        <mesh filename="meshes/medial_distal.stl"/>
      </geometry>
    </collision>
  </link>
  <link name="leftMiddleDistal">
    <inertial>
      <mass value="0.08"/>
      <inertia ixx="1.92e-06" ixy="0" ixz="0" iyy="3.82667e-06" iyz="5.71624e-15" izz="4.04e-06"/>
      <origin xyz="0.015 0 0"/>
    </inertial>
    <visual>
      <geometry>
        <mesh filename="meshes/medial_distal.stl"/>
      </geometry>
      <material name="random">
        <color rgba="0.866667 0.866667 0.866667 1"/>
      </material>
    </visual>
    <collision>
      <geometry>
        <mesh filename="meshes/medial_distal.stl"/>
      </geometry>
    </collision>
  </link>
  <link name="leftIndexProximal">
    <inertial>
      <mass value="0.096"/>
      <inertia ixx="2.304e-06" ixy="0" ixz="0" iyy="8.96e-06" iyz="6.85949e-15" izz="9.216e-06"/>
      <origin xyz="0.024 0 0"/>
    </inertial>
    <visual>
      <geometry>
        <mesh filename="meshes/proximal.stl"/>
      </geometry>
      <material name="random">
        <color rgba="0.866667 0.866667 0.866667 1"/>
      </material>
    </visual>
    <collision>
      <geometry>
        <mesh filename="meshes/proximal.stl"/>
      </geometry>
    </collision>
  </link>
  <link name="leftIndexMedial">
    <inertial>
      <mass value="0.048"/>
      <inertia ixx="1.152e-06" ixy="0" ixz="0" iyy="2.59e-06" iyz="3.42975e-15" izz="2.718e-06"/>
      <origin xyz="0.0165 0 0"/>
    </inertial>
    <visual>
      <geometry>
        <mesh filename="meshes/medial_distal.stl"/>
      </geometry>
      <material name="random">
        <color rgba="0.866667 0.866667 0.866667 1"/>
      </material>
    </visual>
    <collision>
      <geometry>
        <mesh filename="meshes/medial_distal.stl"/>
      </geometry>
    </collision>
  </link>
  <link name="leftIndexDistal">
    <inertial>
      <mass value="0.08"/>
      <inertia ixx="1.92e-06" ixy="0" ixz="0" iyy="3.82667e-06" iyz="5.71624e-15" izz="4.04e-06"/>
      <origin xyz="0.015 0 0"/>
    </inertial>
    <visual>
      <geometry>
        <mesh filename="meshes/medial_distal.stl"/>
      </geometry>
      <material name="random">
        <color rgba="0.866667 0.866667 0.866667 1"/>
      </material>
    </visual>
    <collision>
      <geometry>
        <mesh filename="meshes/medial_distal.stl"/>
      </geometry>
    </collision>
  </link>
  <link name="Body_RSP">
    <inertial>
      <mass value="0.646655"/>
      <inertia ixx="0.000893731" ixy="0.000156484" ixz="4.98007e-07" iyy="0.00093016" iyz="-1.57095e-07" izz="0.00124323"/>
      <origin xyz="0.0167207 -0.0570407 9.91873e-06"/>
    </inertial>
    <visual>
      <geometry>
        <mesh filename="meshes/Body_RSP_vis.dae"/>
      </geometry>
      <material name="random">
        <color rgba="0.866667 0.866667 0.866667 1"/>
      </material>
    </visual>
    <collision>
      <geometry>
        <mesh filename="meshes/Body_RSP.stl"/>
      </geometry>
    </collision>
  </link>
  <link name="Body_RSR">
    <inertial>
      <mass value="0.413368"/>
      <inertia ixx="0.000269283" ixy="-4.52571e-07" ixz="3.23662e-06" iyy="0.00037679" iyz="-9.93935e-07" izz="0.000360355"/>
      <origin xyz="-0.036208 8.31243e-05 -0.00126685"/>
    </inertial>
    <visual>
      <geometry>
        <mesh filename="meshes/Body_RSR_vis.dae"/>
      </geometry>
      <material name="random">
        <color rgba="0.866667 0.866667 0.866667 1"/>
      </material>
    </visual>
    <collision>
      <geometry>
        <mesh filename="meshes/Body_RSR.stl"/>
      </geometry>
    </collision>
  </link>
  <link name="Body_RSY">
    <inertial>
      <mass value="1.15461"/>
      <inertia ixx="0.00365479" ixy="-2.05436e-06" ixz="0.000418448" iyy="0.00364731" iyz="3.09648e-05" izz="0.00060633"/>
      <origin xyz="0.00456121 -3.10576e-05 -0.0907824"/>
    </inertial>
    <visual>
      <geometry>
        <mesh filename="meshes/Body_RSY_vis.dae"/>
      </geometry>
      <material name="random">
        <color rgba="0.866667 0.866667 0.866667 1"/>
      </material>
    </visual>
    <collision>
      <geometry>
        <mesh filename="meshes/Body_RSY.stl"/>
      </geometry>
    </collision>
  </link>
  <link name="Body_REB">
    <inertial>
      <mass value="0.44094"/>
      <inertia ixx="0.0005027" ixy="-3.64587e-06" ixz="-1.41388e-05" iyy="0.00049415" iyz="-7.65528e-06" izz="0.000131786"/>
      <origin xyz="-0.0217349 -0.0178314 -0.0610873"/>
    </inertial>
    <visual>
      <geometry>
        <mesh filename="meshes/Body_REB_vis.dae"/>
      </geometry>
      <material name="random">
        <color rgba="0.866667 0.866667 0.866667 1"/>
      </material>
    </visual>
    <collision>
      <geometry>
        <mesh filename="meshes/Body_REB.stl"/>
      </geometry>
    </collision>
  </link>
  <link name="Body_RWY">
    <inertial>
      <mass value="0.537738"/>
      <inertia ixx="0.00063457" ixy="4.62486e-07" ixz="6.20682e-06" iyy="0.000563918" iyz="-3.54044e-05" izz="0.000305422"/>
      <origin xyz="-0.00122019 -0.000635233 -0.0238043"/>
    </inertial>
    <visual>
      <geometry>
        <mesh filename="meshes/Body_RWY_vis.dae"/>
      </geometry>
      <material name="random">
        <color rgba="0.866667 0.866667 0.866667 1"/>
      </material>
    </visual>
    <collision>
      <geometry>
        <mesh filename="meshes/Body_RWY.stl"/>
      </geometry>
    </collision>
  </link>
  <link name="Body_RWP">
    <inertial>
      <mass value="0.164393"/>
      <inertia ixx="9.74327e-05" ixy="5.22155e-07" ixz="-1.17317e-06" iyy="0.000144494" iyz="-9.4927e-06" izz="0.000122681"/>
      <origin xyz="-0.000258199 -0.011442 -0.0461472"/>
    </inertial>
    <visual>
      <geometry>
        <mesh filename="meshes/Body_RWP_vis.dae"/>
      </geometry>
      <material name="random">
        <color rgba="0.866667 0.866667 0.866667 1"/>
      </material>
    </visual>
    <collision>
      <geometry>
        <mesh filename="meshes/Body_RWP.stl"/>
      </geometry>
    </collision>
  </link>
  <link name="rightThumbProximal">
    <inertial>
      <mass value="0.096"/>
      <inertia ixx="2.304e-06" ixy="0" ixz="0" iyy="8.96e-06" iyz="6.85949e-15" izz="9.216e-06"/>
      <origin xyz="0.024 0 0"/>
    </inertial>
    <visual>
      <geometry>
        <mesh filename="meshes/proximal.stl"/>
      </geometry>
      <material name="random">
        <color rgba="0.866667 0.866667 0.866667 1"/>
      </material>
    </visual>
    <collision>
      <geometry>
        <mesh filename="meshes/proximal.stl"/>
      </geometry>
    </collision>
  </link>
  <link name="rightThumbMedial">
    <inertial>
      <mass value="0.048"/>
      <inertia ixx="1.152e-06" ixy="0" ixz="0" iyy="2.59e-06" iyz="3.42975e-15" izz="2.718e-06"/>
      <origin xyz="0.0165 0 0"/>
    </inertial>
    <visual>
      <geometry>
        <mesh filename="meshes/medial_distal.stl"/>
      </geometry>
      <material name="random">
        <color rgba="0.866667 0.866667 0.866667 1"/>
      </material>
    </visual>
    <collision>
      <geometry>
        <mesh filename="meshes/medial_distal.stl"/>
      </geometry>
    </collision>
  </link>
  <link name="rightThumbDistal">
    <inertial>
      <mass value="0.08"/>
      <inertia ixx="1.92e-06" ixy="0" ixz="0" iyy="3.82667e-06" iyz="5.71624e-15" izz="4.04e-06"/>
      <origin xyz="0.015 0 0"/>
    </inertial>
    <visual>
      <geometry>
        <mesh filename="meshes/medial_distal.stl"/>
      </geometry>
      <material name="random">
        <color rgba="0.866667 0.866667 0.866667 1"/>
      </material>
    </visual>
    <collision>
      <geometry>
        <mesh filename="meshes/medial_distal.stl"/>
      </geometry>
    </collision>
  </link>
  <link name="rightPinkyProximal">
    <inertial>
      <mass value="0.096"/>
      <inertia ixx="2.304e-06" ixy="0" ixz="0" iyy="8.96e-06" iyz="6.85949e-15" izz="9.216e-06"/>
      <origin xyz="0.024 0 0"/>
    </inertial>
    <visual>
      <geometry>
        <mesh filename="meshes/proximal.stl"/>
      </geometry>
      <material name="random">
        <color rgba="0.866667 0.866667 0.866667 1"/>
      </material>
    </visual>
    <collision>
      <geometry>
        <mesh filename="meshes/proximal.stl"/>
      </geometry>
    </collision>
  </link>
  <link name="rightPinkyMedial">
    <inertial>
      <mass value="0.048"/>
      <inertia ixx="1.152e-06" ixy="0" ixz="0" iyy="2.59e-06" iyz="3.42975e-15" izz="2.718e-06"/>
      <origin xyz="0.0165 0 0"/>
    </inertial>
    <visual>
      <geometry>
        <mesh filename="meshes/medial_distal.stl"/>
      </geometry>
      <material name="random">
        <color rgba="0.866667 0.866667 0.866667 1"/>
      </material>
    </visual>
    <collision>
      <geometry>
        <mesh filename="meshes/medial_distal.stl"/>
      </geometry>
    </collision>
  </link>
  <link name="rightPinkyDistal">
    <inertial>
      <mass value="0.08"/>
      <inertia ixx="1.92e-06" ixy="0" ixz="0" iyy="3.82667e-06" iyz="5.71624e-15" izz="4.04e-06"/>
      <origin xyz="0.015 0 0"/>
    </inertial>
    <visual>
      <geometry>
        <mesh filename="meshes/medial_distal.stl"/>
      </geometry>
      <material name="random">
        <color rgba="0.866667 0.866667 0.866667 1"/>
      </material>
    </visual>
    <collision>
      <geometry>
        <mesh filename="meshes/medial_distal.stl"/>
      </geometry>
    </collision>
  </link>
  <link name="rightRingProximal">
    <inertial>
      <mass value="0.096"/>
      <inertia ixx="2.304e-06" ixy="0" ixz="0" iyy="8.96e-06" iyz="6.85949e-15" izz="9.216e-06"/>
      <origin xyz="0.024 0 0"/>
    </inertial>
    <visual>
      <geometry>
        <mesh filename="meshes/proximal.stl"/>
      </geometry>
      <material name="random">
        <color rgba="0.866667 0.866667 0.866667 1"/>
      </material>
    </visual>
    <collision>
      <geometry>
        <mesh filename="meshes/proximal.stl"/>
      </geometry>
    </collision>
  </link>
  <link name="rightRingMedial">
    <inertial>
      <mass value="0.048"/>
      <inertia ixx="1.152e-06" ixy="0" ixz="0" iyy="2.59e-06" iyz="3.42975e-15" izz="2.718e-06"/>
      <origin xyz="0.0165 0 0"/>
    </inertial>
    <visual>
      <geometry>
        <mesh filename="meshes/medial_distal.stl"/>
      </geometry>
      <material name="random">
        <color rgba="0.866667 0.866667 0.866667 1"/>
      </material>
    </visual>
    <collision>
      <geometry>
        <mesh filename="meshes/medial_distal.stl"/>
      </geometry>
    </collision>
  </link>
  <link name="rightRingDistal">
    <inertial>
      <mass value="0.08"/>
      <inertia ixx="1.92e-06" ixy="0" ixz="0" iyy="3.82667e-06" iyz="5.71624e-15" izz="4.04e-06"/>
      <origin xyz="0.015 0 0"/>
    </inertial>
    <visual>
      <geometry>
        <mesh filename="meshes/medial_distal.stl"/>
      </geometry>
      <material name="random">
        <color rgba="0.866667 0.866667 0.866667 1"/>
      </material>
    </visual>
    <collision>
      <geometry>
        <mesh filename="meshes/medial_distal.stl"/>
      </geometry>
    </collision>
  </link>
  <link name="rightMiddleProximal">
    <inertial>
      <mass value="0.096"/>
      <inertia ixx="2.304e-06" ixy="0" ixz="0" iyy="8.96e-06" iyz="6.85949e-15" izz="9.216e-06"/>
      <origin xyz="0.024 0 0"/>
    </inertial>
    <visual>
      <geometry>
        <mesh filename="meshes/proximal.stl"/>
      </geometry>
      <material name="random">
        <color rgba="0.866667 0.866667 0.866667 1"/>
      </material>
    </visual>
    <collision>
      <geometry>
        <mesh filename="meshes/proximal.stl"/>
      </geometry>
    </collision>
  </link>
  <link name="rightMiddleMedial">
    <inertial>
      <mass value="0.048"/>
      <inertia ixx="1.152e-06" ixy="0" ixz="0" iyy="2.59e-06" iyz="3.42975e-15" izz="2.718e-06"/>
      <origin xyz="0.0165 0 0"/>
    </inertial>
    <visual>
      <geometry>
        <mesh filename="meshes/medial_distal.stl"/>
      </geometry>
      <material name="random">
        <color rgba="0.866667 0.866667 0.866667 1"/>
      </material>
    </visual>
    <collision>
      <geometry>
        <mesh filename="meshes/medial_distal.stl"/>
      </geometry>
    </collision>
  </link>
  <link name="rightMiddleDistal">
    <inertial>
      <mass value="0.08"/>
      <inertia ixx="1.92e-06" ixy="0" ixz="0" iyy="3.82667e-06" iyz="5.71624e-15" izz="4.04e-06"/>
      <origin xyz="0.015 0 0"/>
    </inertial>
    <visual>
      <geometry>
        <mesh filename="meshes/medial_distal.stl"/>
      </geometry>
      <material name="random">
        <color rgba="0.866667 0.866667 0.866667 1"/>
      </material>
    </visual>
    <collision>
      <geometry>
        <mesh filename="meshes/medial_distal.stl"/>
      </geometry>
    </collision>
  </link>
  <link name="rightIndexProximal">
    <inertial>
      <mass value="0.096"/>
      <inertia ixx="2.304e-06" ixy="0" ixz="0" iyy="8.96e-06" iyz="6.85949e-15" izz="9.216e-06"/>
      <origin xyz="0.024 0 0"/>
    </inertial>
    <visual>
      <geometry>
        <mesh filename="meshes/proximal.stl"/>
      </geometry>
      <material name="random">
        <color rgba="0.866667 0.866667 0.866667 1"/>
      </material>
    </visual>
    <collision>
      <geometry>
        <mesh filename="meshes/proximal.stl"/>
      </geometry>
    </collision>
  </link>
  <link name="rightIndexMedial">
    <inertial>
      <mass value="0.048"/>
      <inertia ixx="1.152e-06" ixy="0" ixz="0" iyy="2.59e-06" iyz="3.42975e-15" izz="2.718e-06"/>
      <origin xyz="0.0165 0 0"/>
    </inertial>
    <visual>
      <geometry>
        <mesh filename="meshes/medial_distal.stl"/>
      </geometry>
      <material name="random">
        <color rgba="0.866667 0.866667 0.866667 1"/>
      </material>
    </visual>
    <collision>
      <geometry>
        <mesh filename="meshes/medial_distal.stl"/>
      </geometry>
    </collision>
  </link>
  <link name="rightIndexDistal">
    <inertial>
      <mass value="0.08"/>
      <inertia ixx="1.92e-06" ixy="0" ixz="0" iyy="3.82667e-06" iyz="5.71624e-15" izz="4.04e-06"/>
      <origin xyz="0.015 0 0"/>
    </inertial>
    <visual>
      <geometry>
        <mesh filename="meshes/medial_distal.stl"/>
      </geometry>
      <material name="random">
        <color rgba="0.866667 0.866667 0.866667 1"/>
      </material>
    </visual>
    <collision>
      <geometry>
        <mesh filename="meshes/medial_distal.stl"/>
      </geometry>
    </collision>
  </link>
  <link name="Body_Hip">
    <inertial>
      <mass value="3.41719"/>
      <inertia ixx="0.0180349" ixy="3.17531e-05" ixz="-0.000513489" iyy="0.00912382" iyz="-6.90617e-05" izz="0.0220514"/>
      <origin xyz="-0.0138504 7.80652e-06 -0.0354613"/>
    </inertial>
    <visual>
      <geometry>
        <mesh filename="meshes/Body_Hip_vis.dae"/>
      </geometry>
      <material name="random">
        <color rgba="0.866667 0.866667 0.866667 1"/>
      </material>
    </visual>
    <collision>
      <geometry>
        <mesh filename="meshes/Body_Hip.stl"/>
      </geometry>
    </collision>
  </link>
  <link name="Body_LHY">
    <inertial>
      <mass value="0.826125"/>
      <inertia ixx="0.00151818" ixy="2.13586e-06" ixz="0.000434128" iyy="0.00286333" iyz="-1.57525e-07" izz="0.00211437"/>
      <origin xyz="0.0347065 3.748e-05 -0.0726153"/>
    </inertial>
    <visual>
      <geometry>
        <mesh filename="meshes/Body_LHY.stl"/>
      </geometry>
      <material name="random">
        <color rgba="0.866667 0.866667 0.866667 1"/>
      </material>
    </visual>
    <collision>
      <geometry>
        <mesh filename="meshes/Body_LHY.stl"/>
      </geometry>
    </collision>
  </link>
  <link name="Body_LHR">
    <inertial>
      <mass value="1.93266"/>
      <inertia ixx="0.00403487" ixy="7.9452e-05" ixz="-0.000125343" iyy="0.00332707" iyz="-0.000551964" izz="0.00317173"/>
      <origin xyz="-0.0497479 0.0125311 -0.0156437"/>
    </inertial>
    <visual>
      <geometry>
        <mesh filename="meshes/Body_LHR.stl"/>
      </geometry>
      <material name="random">
        <color rgba="0.866667 0.866667 0.866667 1"/>
      </material>
    </visual>
    <collision>
      <geometry>
        <mesh filename="meshes/Body_LHR.stl"/>
      </geometry>
    </collision>
  </link>
  <link name="Body_LHP">
    <inertial>
      <mass value="2.8201"/>
      <inertia ixx="0.0295102" ixy="0.000184399" ixz="-0.000370291" iyy="0.0273771" iyz="0.00065658" izz="0.00838035"/>
      <origin xyz="0.0195049 -0.0595775 -0.175202"/>
    </inertial>
    <visual>
      <geometry>
        <mesh filename="meshes/Body_LHP.stl"/>
      </geometry>
      <material name="random">
        <color rgba="0.866667 0.866667 0.866667 1"/>
      </material>
    </visual>
    <collision>
      <geometry>
        <mesh filename="meshes/Body_LHP.stl"/>
      </geometry>
    </collision>
  </link>
  <link name="Body_LKN">
    <inertial>
      <mass value="1.80912"/>
      <inertia ixx="0.0232156" ixy="0.000251648" ixz="-0.00129343" iyy="0.0208342" iyz="0.00278068" izz="0.0059204"/>
      <origin xyz="0.0128254 -0.00727567 -0.171431"/>
    </inertial>
    <visual>
      <geometry>
        <mesh filename="meshes/Body_LKN_vis.dae"/>
      </geometry>
      <material name="random">
        <color rgba="0.866667 0.866667 0.866667 1"/>
      </material>
    </visual>
    <collision>
      <geometry>
        <mesh filename="meshes/Body_LKN.stl"/>
      </geometry>
    </collision>
  </link>
  <link name="Body_LAP">
    <inertial>
      <mass value="1.63501"/>
      <inertia ixx="0.00231659" ixy="1.87402e-05" ixz="0.000369899" iyy="0.00330411" iyz="6.38153e-05" izz="0.00279495"/>
      <origin xyz="0.0198702 -0.0459693 0.0115069"/>
    </inertial>
    <visual>
      <geometry>
        <mesh filename="meshes/Body_LAP.stl"/>
      </geometry>
      <material name="random">
        <color rgba="0.866667 0.866667 0.866667 1"/>
      </material>
    </visual>
    <collision>
      <geometry>
        <mesh filename="meshes/Body_LAP.stl"/>
      </geometry>
    </collision>
  </link>
  <link name="Body_LAR">
    <inertial>
      <mass value="1.20318"/>
      <inertia ixx="0.00295183" ixy="3.23211e-05" ixz="0.000141769" iyy="0.00524792" iyz="5.95404e-05" izz="0.00516817"/>
      <origin xyz="-0.0515094 0.00216398 -0.0693881"/>
    </inertial>
    <visual>
      <geometry>
        <mesh filename="meshes/Body_LAR.stl"/>
      </geometry>
      <material name="random">
        <color rgba="0.866667 0.866667 0.866667 1"/>
      </material>
    </visual>
    <collision>
      <geometry>
        <mesh filename="meshes/Body_LAR.stl"/>
      </geometry>
    </collision>
  </link>
  <link name="Body_RHY">
    <inertial>
      <mass value="0.826125"/>
      <inertia ixx="0.00151818" ixy="-2.13586e-06" ixz="0.000434128" iyy="0.00286333" iyz="1.57525e-07" izz="0.00211437"/>
      <origin xyz="0.0347065 -3.748e-05 -0.0726153"/>
    </inertial>
    <visual>
      <geometry>
        <mesh filename="meshes/Body_RHY_vis.dae"/>
      </geometry>
      <material name="random">
        <color rgba="0.866667 0.866667 0.866667 1"/>
      </material>
    </visual>
    <collision>
      <geometry>
        <mesh filename="meshes/Body_RHY.stl"/>
      </geometry>
    </collision>
  </link>
  <link name="Body_RHR">
    <inertial>
      <mass value="1.93266"/>
      <inertia ixx="0.00403487" ixy="-7.9452e-05" ixz="-0.000125343" iyy="0.00332707" iyz="0.000551964" izz="0.00317173"/>
      <origin xyz="-0.0497479 -0.0125311 -0.0156437"/>
    </inertial>
    <visual>
      <geometry>
        <mesh filename="meshes/Body_RHR_vis.dae"/>
      </geometry>
      <material name="random">
        <color rgba="0.866667 0.866667 0.866667 1"/>
      </material>
    </visual>
    <collision>
      <geometry>
        <mesh filename="meshes/Body_RHR.stl"/>
      </geometry>
    </collision>
  </link>
  <link name="Body_RHP">
    <inertial>
      <mass value="2.8201"/>
      <inertia ixx="0.0295102" ixy="-0.000184399" ixz="-0.000370291" iyy="0.0273771" iyz="-0.00065658" izz="0.00838035"/>
      <origin xyz="0.0195049 0.0595775 -0.175202"/>
    </inertial>
    <visual>
      <geometry>
        <mesh filename="meshes/Body_RHP_vis.dae"/>
      </geometry>
      <material name="random">
        <color rgba="0.866667 0.866667 0.866667 1"/>
      </material>
    </visual>
    <collision>
      <geometry>
        <mesh filename="meshes/Body_RHP.stl"/>
      </geometry>
    </collision>
  </link>
  <link name="Body_RKN">
    <inertial>
      <mass value="1.80912"/>
      <inertia ixx="0.0232156" ixy="-0.000251648" ixz="-0.00129343" iyy="0.0208342" iyz="-0.00278068" izz="0.0059204"/>
      <origin xyz="0.0128254 0.00727567 -0.171431"/>
    </inertial>
    <visual>
      <geometry>
        <mesh filename="meshes/Body_RKN_vis.dae"/>
      </geometry>
      <material name="random">
        <color rgba="0.866667 0.866667 0.866667 1"/>
      </material>
    </visual>
    <collision>
      <geometry>
        <mesh filename="meshes/Body_RKN.stl"/>
      </geometry>
    </collision>
  </link>
  <link name="Body_RAP">
    <inertial>
      <mass value="1.63501"/>
      <inertia ixx="0.00231659" ixy="-1.87402e-05" ixz="0.000369899" iyy="0.00330411" iyz="-6.38153e-05" izz="0.00279495"/>
      <origin xyz="0.0198702 0.0459693 0.0115069"/>
    </inertial>
    <visual>
      <geometry>
        <mesh filename="meshes/Body_RAP_vis.dae"/>
      </geometry>
      <material name="random">
        <color rgba="0.866667 0.866667 0.866667 1"/>
      </material>
    </visual>
    <collision>
      <geometry>
        <mesh filename="meshes/Body_RAP.stl"/>
      </geometry>
    </collision>
  </link>
  <link name="Body_RAR">
    <inertial>
      <mass value="1.20318"/>
      <inertia ixx="0.00295183" ixy="-3.23211e-05" ixz="0.000141769" iyy="0.00524792" iyz="-5.95404e-05" izz="0.00516817"/>
      <origin xyz="-0.0515094 -0.00216398 -0.0693881"/>
    </inertial>
    <visual>
      <geometry>
        <mesh filename="meshes/Body_RAR_vis.dae"/>
      </geometry>
      <material name="random">
        <color rgba="0.866667 0.866667 0.866667 1"/>
      </material>
    </visual>
    <collision>
      <geometry>
        <mesh filename="meshes/Body_RAR.stl"/>
      </geometry>
    </collision>
  </link>
  <joint name="NKY" type="revolute">
    <origin rpy="0 -0 0" xyz="0.0137246 0.0 0.1092625"/>
    <parent link="Body_Torso"/>
    <child link="Body_Neck"/>
    <axis xyz="0 0 1"/>
    <limit effort="10.0" lower="-1.5" upper="1.5" velocity="1.0"/>
  </joint>
  <joint name="HNP" type="revolute">
    <origin rpy="0 -0 0" xyz="-0.0014665 0.0024526 0.0876725"/>
    <parent link="Body_Neck"/>
    <child link="Body_Head_Empty"/>
    <axis xyz="0 1 0"/>
    <limit effort="10.0" lower="-0.523599" upper="0.523599" velocity="1.0"/>
  </joint>
  <joint name="HNR" type="revolute">
    <origin rpy="0 -0 0" xyz="0 0 0"/>
    <parent link="Body_Head_Empty"/>
    <child link="Body_Head"/>
    <axis xyz="1 0 0"/>
    <limit effort="10.0" lower="-0.523599" upper="0.523599" velocity="1.0"/>
  </joint>
  <joint name="LSP" type="revolute">
    <origin rpy="0 -0 0" xyz="0.0122581 0.143973 0.0486356"/>
    <parent link="Body_Torso"/>
    <child link="Body_LSP"/>
    <axis xyz="0 1 0"/>
    <limit effort="10.0" lower="-3.14158" upper="3.14158" velocity="1.0"/>
  </joint>
  <joint name="LSR" type="revolute">
    <origin rpy="0 -0 0" xyz="0.0269 0.072 0"/>
    <parent link="Body_LSP"/>
    <child link="Body_LSR"/>
    <axis xyz="1 0 0"/>
    <limit effort="10.0" lower="0" upper="3.14158" velocity="1.0"/>
  </joint>
  <joint name="LSY" type="revolute">
    <origin rpy="0 -0 0" xyz="-0.0269 -0.000166249 -0.0245"/>
    <parent link="Body_LSR"/>
    <child link="Body_LSY"/>
    <axis xyz="0 0 1"/>
    <limit effort="10.0" lower="-3.14158" upper="3.14158" velocity="1.0"/>
  </joint>
  <joint name="LEB" type="revolute">
    <origin rpy="0 -0 0" xyz="0.0219936 -0.018 -0.157505"/>
    <parent link="Body_LSY"/>
    <child link="Body_LEB"/>
    <axis xyz="0 1 0"/>
    <limit effort="10.0" lower="-2.49582" upper="0.0698132" velocity="1.0"/>
  </joint>
  <joint name="LWY" type="revolute">
    <origin rpy="0 -0 0" xyz="-0.0219906 0.018 -0.111408"/>
    <parent link="Body_LEB"/>
    <child link="Body_LWY"/>
    <axis xyz="0 0 1"/>
    <limit effort="10.0" lower="-3.14158" upper="3.14158" velocity="1.0"/>
  </joint>
  <joint name="LWP" type="revolute">
    <origin rpy="0 -0 0" xyz="1.72973e-06 -0.00872953 -0.05255"/>
    <parent link="Body_LWY"/>
    <child link="Body_LWP"/>
    <axis xyz="0 1 0"/>
    <limit effort="10.0" lower="-1.64061" upper="1.01229" velocity="1.0"/>
  </joint>
  <joint name="leftThumbKnuckle1" type="revolute">
    <origin rpy="1.5708 -0.785398 -1.5708" xyz="0.0208959 0.00192069 -0.060952"/>
    <parent link="Body_LWP"/>
    <child link="leftThumbProximal"/>
    <axis xyz="0 0 -1"/>
    <limit effort="10.0" lower="-3.14" upper="3.14" velocity="1.0"/>
  </joint>
  <joint name="leftThumbKnuckle2" type="revolute">
    <origin rpy="0 -0 0" xyz="0.032 0 0"/>
    <parent link="leftThumbProximal"/>
    <child link="leftThumbMedial"/>
    <axis xyz="0 0 -1"/>
    <limit effort="10.0" lower="-3.14" upper="3.14" velocity="1.0"/>
  </joint>
  <joint name="leftThumbKnuckle3" type="revolute">
    <origin rpy="0 -0 0" xyz="0.022 0 0"/>
    <parent link="leftThumbMedial"/>
    <child link="leftThumbDistal"/>
    <axis xyz="0 0 -1"/>
    <limit effort="10.0" lower="-3.14" upper="3.14" velocity="1.0"/>
  </joint>
  <joint name="leftPinkyKnuckle1" type="revolute">
    <origin rpy="1.5708 0.785398 1.5708" xyz="-0.0281041 0.0298617 -0.088883"/>
    <parent link="Body_LWP"/>
    <child link="leftPinkyProximal"/>
    <axis xyz="0 0 -1"/>
    <limit effort="10.0" lower="-3.14" upper="3.14" velocity="1.0"/>
  </joint>
  <joint name="leftPinkyKnuckle2" type="revolute">
    <origin rpy="0 -0 0" xyz="0.032 0 0"/>
    <parent link="leftPinkyProximal"/>
    <child link="leftPinkyMedial"/>
    <axis xyz="0 0 -1"/>
    <limit effort="10.0" lower="-3.14" upper="3.14" velocity="1.0"/>
  </joint>
  <joint name="leftPinkyKnuckle3" type="revolute">
    <origin rpy="0 -0 0" xyz="0.022 0 0"/>
    <parent link="leftPinkyMedial"/>
    <child link="leftPinkyDistal"/>
    <axis xyz="0 0 -1"/>
    <limit effort="10.0" lower="-3.14" upper="3.14" velocity="1.0"/>
  </joint>
  <joint name="leftRingKnuckle1" type="revolute">
    <origin rpy="1.5708 0.785398 1.5708" xyz="-0.00910415 0.0298617 -0.088883"/>
    <parent link="Body_LWP"/>
    <child link="leftRingProximal"/>
    <axis xyz="0 0 -1"/>
    <limit effort="10.0" lower="-3.14" upper="3.14" velocity="1.0"/>
  </joint>
  <joint name="leftRingKnuckle2" type="revolute">
    <origin rpy="0 -0 0" xyz="0.032 0 0"/>
    <parent link="leftRingProximal"/>
    <child link="leftRingMedial"/>
    <axis xyz="0 0 -1"/>
    <limit effort="10.0" lower="-3.14" upper="3.14" velocity="1.0"/>
  </joint>
  <joint name="leftRingKnuckle3" type="revolute">
    <origin rpy="0 -0 0" xyz="0.022 0 0"/>
    <parent link="leftRingMedial"/>
    <child link="leftRingDistal"/>
    <axis xyz="0 0 -1"/>
    <limit effort="10.0" lower="-3.14" upper="3.14" velocity="1.0"/>
  </joint>
  <joint name="leftMiddleKnuckle1" type="revolute">
    <origin rpy="1.5708 0.785398 1.5708" xyz="0.00993585 0.0298617 -0.088883"/>
    <parent link="Body_LWP"/>
    <child link="leftMiddleProximal"/>
    <axis xyz="0 0 -1"/>
    <limit effort="10.0" lower="-3.14" upper="3.14" velocity="1.0"/>
  </joint>
  <joint name="leftMiddleKnuckle2" type="revolute">
    <origin rpy="0 -0 0" xyz="0.032 0 0"/>
    <parent link="leftMiddleProximal"/>
    <child link="leftMiddleMedial"/>
    <axis xyz="0 0 -1"/>
    <limit effort="10.0" lower="-3.14" upper="3.14" velocity="1.0"/>
  </joint>
  <joint name="leftMiddleKnuckle3" type="revolute">
    <origin rpy="0 -0 0" xyz="0.022 0 0"/>
    <parent link="leftMiddleMedial"/>
    <child link="leftMiddleDistal"/>
    <axis xyz="0 0 -1"/>
    <limit effort="10.0" lower="-3.14" upper="3.14" velocity="1.0"/>
  </joint>
  <joint name="leftIndexKnuckle1" type="revolute">
    <origin rpy="1.5708 0.785398 1.5708" xyz="0.0289159 0.0298617 -0.088883"/>
    <parent link="Body_LWP"/>
    <child link="leftIndexProximal"/>
    <axis xyz="0 0 -1"/>
    <limit effort="10.0" lower="-3.14" upper="3.14" velocity="1.0"/>
  </joint>
  <joint name="leftIndexKnuckle2" type="revolute">
    <origin rpy="0 -0 0" xyz="0.032 0 0"/>
    <parent link="leftIndexProximal"/>
    <child link="leftIndexMedial"/>
    <axis xyz="0 0 -1"/>
    <limit effort="10.0" lower="-3.14" upper="3.14" velocity="1.0"/>
  </joint>
  <joint name="leftIndexKnuckle3" type="revolute">
    <origin rpy="0 -0 0" xyz="0.022 0 0"/>
    <parent link="leftIndexMedial"/>
    <child link="leftIndexDistal"/>
    <axis xyz="0 0 -1"/>
    <limit effort="10.0" lower="-3.14" upper="3.14" velocity="1.0"/>
  </joint>
  <joint name="RSP" type="revolute">
    <origin rpy="0 -0 0" xyz="0.0122581 -0.139027 0.0486356"/>
    <parent link="Body_Torso"/>
    <child link="Body_RSP"/>
    <axis xyz="0 1 0"/>
    <limit effort="10.0" lower="-3.14158" upper="3.14158" velocity="1.0"/>
  </joint>
  <joint name="RSR" type="revolute">
    <origin rpy="0 -0 0" xyz="0.0269 -0.072 0"/>
    <parent link="Body_RSP"/>
    <child link="Body_RSR"/>
    <axis xyz="1 0 0"/>
    <limit effort="10.0" lower="-3.14158" upper="0" velocity="1.0"/>
  </joint>
  <joint name="RSY" type="revolute">
    <origin rpy="0 -0 0" xyz="-0.0269 0 -0.0245"/>
    <parent link="Body_RSR"/>
    <child link="Body_RSY"/>
    <axis xyz="0 0 1"/>
    <limit effort="10.0" lower="-3.14158" upper="3.14158" velocity="1.0"/>
  </joint>
  <joint name="REB" type="revolute">
    <origin rpy="0 -0 0" xyz="0.0219936 0.018 -0.157505"/>
    <parent link="Body_RSY"/>
    <child link="Body_REB"/>
    <axis xyz="0 1 0"/>
    <limit effort="10.0" lower="-2.49582" upper="0.0698132" velocity="1.0"/>
  </joint>
  <joint name="RWY" type="revolute">
    <origin rpy="0 -0 0" xyz="-0.0219906 -0.018 -0.111408"/>
    <parent link="Body_REB"/>
    <child link="Body_RWY"/>
    <axis xyz="0 0 1"/>
    <limit effort="10.0" lower="-3.14158" upper="3.14158" velocity="1.0"/>
  </joint>
  <joint name="RWP" type="revolute">
    <origin rpy="0 -0 0" xyz="1.72973e-06 0.01 -0.05255"/>
    <parent link="Body_RWY"/>
    <child link="Body_RWP"/>
    <axis xyz="0 1 0"/>
    <limit effort="10.0" lower="-1.64061" upper="1.01229" velocity="1.0"/>
  </joint>
  <joint name="rightThumbKnuckle1" type="revolute">
    <origin rpy="1.5708 -0.785398 1.5708" xyz="0.0208959 -0.00192069 -0.060952"/>
    <parent link="Body_RWP"/>
    <child link="rightThumbProximal"/>
    <axis xyz="0 0 -1"/>
    <limit effort="10.0" lower="0" upper="1.57" velocity="1.0"/>
  </joint>
  <joint name="rightThumbKnuckle2" type="revolute">
    <origin rpy="0 -0 0" xyz="0.032 0 0"/>
    <parent link="rightThumbProximal"/>
    <child link="rightThumbMedial"/>
    <axis xyz="0 0 -1"/>
    <limit effort="10.0" lower="0" upper="1.57" velocity="1.0"/>
  </joint>
  <joint name="rightThumbKnuckle3" type="revolute">
    <origin rpy="0 -0 0" xyz="0.022 0 0"/>
    <parent link="rightThumbMedial"/>
    <child link="rightThumbDistal"/>
    <axis xyz="0 0 -1"/>
    <limit effort="10.0" lower="0" upper="1.57" velocity="1.0"/>
  </joint>
  <joint name="rightPinkyKnuckle1" type="revolute">
    <origin rpy="1.5708 0.785398 -1.5708" xyz="-0.0281041 -0.0298617 -0.088883"/>
    <parent link="Body_RWP"/>
    <child link="rightPinkyProximal"/>
    <axis xyz="0 0 -1"/>
    <limit effort="10.0" lower="0" upper="1.57" velocity="1.0"/>
  </joint>
  <joint name="rightPinkyKnuckle2" type="revolute">
    <origin rpy="0 -0 0" xyz="0.032 0 0"/>
    <parent link="rightPinkyProximal"/>
    <child link="rightPinkyMedial"/>
    <axis xyz="0 0 -1"/>
    <limit effort="10.0" lower="0" upper="1.57" velocity="1.0"/>
  </joint>
  <joint name="rightPinkyKnuckle3" type="revolute">
    <origin rpy="0 -0 0" xyz="0.022 0 0"/>
    <parent link="rightPinkyMedial"/>
    <child link="rightPinkyDistal"/>
    <axis xyz="0 0 -1"/>
    <limit effort="10.0" lower="0" upper="1.57" velocity="1.0"/>
  </joint>
  <joint name="rightRingKnuckle1" type="revolute">
    <origin rpy="1.5708 0.785398 -1.5708" xyz="-0.00910415 -0.0298617 -0.088883"/>
    <parent link="Body_RWP"/>
    <child link="rightRingProximal"/>
    <axis xyz="0 0 -1"/>
    <limit effort="10.0" lower="0" upper="1.57" velocity="1.0"/>
  </joint>
  <joint name="rightRingKnuckle2" type="revolute">
    <origin rpy="0 -0 0" xyz="0.032 0 0"/>
    <parent link="rightRingProximal"/>
    <child link="rightRingMedial"/>
    <axis xyz="0 0 -1"/>
    <limit effort="10.0" lower="0" upper="1.57" velocity="1.0"/>
  </joint>
  <joint name="rightRingKnuckle3" type="revolute">
    <origin rpy="0 -0 0" xyz="0.022 0 0"/>
    <parent link="rightRingMedial"/>
    <child link="rightRingDistal"/>
    <axis xyz="0 0 -1"/>
    <limit effort="10.0" lower="0" upper="1.57" velocity="1.0"/>
  </joint>
  <joint name="rightMiddleKnuckle1" type="revolute">
    <origin rpy="1.5708 0.785398 -1.5708" xyz="0.00993585 -0.0298617 -0.088883"/>
    <parent link="Body_RWP"/>
    <child link="rightMiddleProximal"/>
    <axis xyz="0 0 -1"/>
    <limit effort="10.0" lower="0" upper="1.57" velocity="1.0"/>
  </joint>
  <joint name="rightMiddleKnuckle2" type="revolute">
    <origin rpy="0 -0 0" xyz="0.032 0 0"/>
    <parent link="rightMiddleProximal"/>
    <child link="rightMiddleMedial"/>
    <axis xyz="0 0 -1"/>
    <limit effort="10.0" lower="0" upper="1.57" velocity="1.0"/>
  </joint>
  <joint name="rightMiddleKnuckle3" type="revolute">
    <origin rpy="0 -0 0" xyz="0.022 0 0"/>
    <parent link="rightMiddleMedial"/>
    <child link="rightMiddleDistal"/>
    <axis xyz="0 0 -1"/>
    <limit effort="10.0" lower="0" upper="1.57" velocity="1.0"/>
  </joint>
  <joint name="rightIndexKnuckle1" type="revolute">
    <origin rpy="1.5708 0.785398 -1.5708" xyz="0.0289159 -0.0298617 -0.088883"/>
    <parent link="Body_RWP"/>
    <child link="rightIndexProximal"/>
    <axis xyz="0 0 -1"/>
    <limit effort="10.0" lower="0" upper="1.57" velocity="1.0"/>
  </joint>
  <joint name="rightIndexKnuckle2" type="revolute">
    <origin rpy="0 -0 0" xyz="0.032 0 0"/>
    <parent link="rightIndexProximal"/>
    <child link="rightIndexMedial"/>
    <axis xyz="0 0 -1"/>
    <limit effort="10.0" lower="0" upper="1.57" velocity="1.0"/>
  </joint>
  <joint name="rightIndexKnuckle3" type="revolute">
    <origin rpy="0 -0 0" xyz="0.022 0 0"/>
    <parent link="rightIndexMedial"/>
    <child link="rightIndexDistal"/>
    <axis xyz="0 0 -1"/>
    <limit effort="10.0" lower="0" upper="1.57" velocity="1.0"/>
  </joint>
  <joint name="WST" type="revolute">
    <origin rpy="0 -0 0" xyz="0.0122662 0.00245974 -0.15262"/>
    <parent link="Body_Torso"/>
    <child link="Body_Hip"/>
    <axis xyz="0 0 -1"/>
    <limit effort="10.0" lower="-3.14158" upper="3.14158" velocity="1.0"/>
  </joint>
  <joint name="LHY" type="revolute">
    <origin rpy="0 -0 0" xyz="0.000125136 0.0885155 -0.0764689"/>
    <parent link="Body_Hip"/>
    <child link="Body_LHY"/>
    <axis xyz="0 0 1"/>
    <limit effort="10.0" lower="-1.5708" upper="1.5708" velocity="1.0"/>
  </joint>
  <joint name="LHR" type="revolute">
    <origin rpy="0 -0 0" xyz="0.0520001 1.50498e-06 -0.091004"/>
    <parent link="Body_LHY"/>
    <child link="Body_LHR"/>
    <axis xyz="1 0 0"/>
    <limit effort="10.0" lower="-0.488692" upper="0.488692" velocity="1.0"/>
  </joint>
  <joint name="LHP" type="revolute">
    <origin rpy="0 -0 0" xyz="-0.0529074 0.0655748 9.99159e-05"/>
    <parent link="Body_LHR"/>
    <child link="Body_LHP"/>
    <axis xyz="0 1 0"/>
    <limit effort="10.0" lower="-1.48353" upper="1.6057" velocity="1.0"/>
  </joint>
  <joint name="LKN" type="revolute">
    <origin rpy="0 -0 0" xyz="0.000766364 -0.0445011 -0.280007"/>
    <parent link="Body_LHP"/>
    <child link="Body_LKN"/>
    <axis xyz="0 1 0"/>
    <limit effort="10.0" lower="-0.0698132" upper="2.60054" velocity="1.0"/>
  </joint>
  <joint name="LAP" type="revolute">
    <origin rpy="0 -0 0" xyz="7.20248e-06 0.0247555 -0.279942"/>
    <parent link="Body_LKN"/>
    <child link="Body_LAP"/>
    <axis xyz="0 1 0"/>
    <limit effort="10.0" lower="-1.29154" upper="1.69297" velocity="1.0"/>
  </joint>
  <joint name="LAR" type="revolute">
    <origin rpy="0 -0 0" xyz="0.0711787 -0.0466006 -1.04e-10"/>
    <parent link="Body_LAP"/>
    <child link="Body_LAR"/>
    <axis xyz="1 0 0"/>
    <limit effort="10.0" lower="-0.191986" upper="0.191986" velocity="1.0"/>
  </joint>
  <joint name="RHY" type="revolute">
    <origin rpy="0 -0 0" xyz="0.000125136 -0.0884999 -0.0764689"/>
    <parent link="Body_Hip"/>
    <child link="Body_RHY"/>
    <axis xyz="0 0 1"/>
    <limit effort="10.0" lower="-1.5708" upper="1.5708" velocity="1.0"/>
  </joint>
  <joint name="RHR" type="revolute">
    <origin rpy="0 -0 0" xyz="0.0520001 7.3455e-05 -0.091004"/>
    <parent link="Body_RHY"/>
    <child link="Body_RHR"/>
    <axis xyz="1 0 0"/>
    <limit effort="10.0" lower="-0.488692" upper="0.488692" velocity="1.0"/>
  </joint>
  <joint name="RHP" type="revolute">
    <origin rpy="0 -0 0" xyz="-0.0529074 -0.0655748 9.99159e-05"/>
    <parent link="Body_RHR"/>
    <child link="Body_RHP"/>
    <axis xyz="0 1 0"/>
    <limit effort="10.0" lower="-1.48353" upper="1.6057" velocity="1.0"/>
  </joint>
  <joint name="RKN" type="revolute">
    <origin rpy="0 -0 0" xyz="0.000766364 0.0445011 -0.280007"/>
    <parent link="Body_RHP"/>
    <child link="Body_RKN"/>
    <axis xyz="0 1 0"/>
    <limit effort="10.0" lower="-0.0698132" upper="2.60054" velocity="1.0"/>
  </joint>
  <joint name="RAP" type="revolute">
    <origin rpy="0 -0 0" xyz="7.20248e-06 -0.0247555 -0.279942"/>
    <parent link="Body_RKN"/>
    <child link="Body_RAP"/>
    <axis xyz="0 1 0"/>
    <limit effort="10.0" lower="-1.29154" upper="1.69297" velocity="1.0"/>
  </joint>
  <joint name="RAR" type="revolute">
    <origin rpy="0 -0 0" xyz="0.0711787 0.0466006 -1.04e-10"/>
    <parent link="Body_RAP"/>
    <child link="Body_RAR"/>
    <axis xyz="1 0 0"/>
    <limit effort="10.0" lower="-0.191986" upper="0.191986" velocity="1.0"/>
  </joint>
  <gazebo>
    <!-- robot model offset -->
    <pose>0 0 1 0 0 0</pose>
  </gazebo>
  <transmission name="LHY_trans" type="pr2_mechanism_model/SimpleTransmission">
    <actuator name="LHY_motor" />
    <joint name="LHY" />
    <mechanicalReduction>1</mechanicalReduction>
    <motorTorqueConstant>1</motorTorqueConstant>
  </transmission>
  <transmission name="LHR_trans" type="pr2_mechanism_model/SimpleTransmission">
    <actuator name="LHR_motor" />
    <joint name="LHR" />
    <mechanicalReduction>1</mechanicalReduction>
    <motorTorqueConstant>1</motorTorqueConstant>
  </transmission>
  <transmission name="LHP_trans" type="pr2_mechanism_model/SimpleTransmission">
    <actuator name="LHP_motor" />
    <joint name="LHP" />
    <mechanicalReduction>1</mechanicalReduction>
    <motorTorqueConstant>1</motorTorqueConstant>
  </transmission>
  <transmission name="LKN_trans" type="pr2_mechanism_model/SimpleTransmission">
    <actuator name="LKN_motor" />
    <joint name="LKN" />
    <mechanicalReduction>1</mechanicalReduction>
    <motorTorqueConstant>1</motorTorqueConstant>
  </transmission>
  <transmission name="LAP_trans" type="pr2_mechanism_model/SimpleTransmission">
    <actuator name="LAP_motor" />
    <joint name="LAP" />
    <mechanicalReduction>1</mechanicalReduction>
    <motorTorqueConstant>1</motorTorqueConstant>
  </transmission>
  <transmission name="LAR_trans" type="pr2_mechanism_model/SimpleTransmission">
    <actuator name="LAR_motor" />
    <joint name="LAR" />
    <mechanicalReduction>1</mechanicalReduction>
    <motorTorqueConstant>1</motorTorqueConstant>
  </transmission>
  <transmission name="RHY_trans" type="pr2_mechanism_model/SimpleTransmission">
    <actuator name="RHY_motor" />
    <joint name="RHY" />
    <mechanicalReduction>1</mechanicalReduction>
    <motorTorqueConstant>1</motorTorqueConstant>
  </transmission>
<transmission name="RHR_trans" type="pr2_mechanism_model/SimpleTransmission">
    <actuator name="RHR_motor" />
    <joint name="RHR" />
    <mechanicalReduction>1</mechanicalReduction>
    <motorTorqueConstant>1</motorTorqueConstant>
  </transmission>
  <transmission name="RHP_trans" type="pr2_mechanism_model/SimpleTransmission">
    <actuator name="RHP_motor" />
    <joint name="RHP" />
    <mechanicalReduction>1</mechanicalReduction>
    <motorTorqueConstant>1</motorTorqueConstant>
  </transmission>
  <transmission name="RKN_trans" type="pr2_mechanism_model/SimpleTransmission">
    <actuator name="RKN_motor" />
    <joint name="RKN" />
    <mechanicalReduction>1</mechanicalReduction>
    <motorTorqueConstant>1</motorTorqueConstant>
  </transmission>
  <transmission name="RAP_trans" type="pr2_mechanism_model/SimpleTransmission">
    <actuator name="RAP_motor" />
    <joint name="RAP" />
    <mechanicalReduction>1</mechanicalReduction>
    <motorTorqueConstant>1</motorTorqueConstant>
  </transmission>
  <transmission name="RAR_trans" type="pr2_mechanism_model/SimpleTransmission">
    <actuator name="RAR_motor" />
    <joint name="RAR" />
    <mechanicalReduction>1</mechanicalReduction>
    <motorTorqueConstant>1</motorTorqueConstant>
  </transmission>
  <gazebo>
<!--    <plugin name="pid_joints" filename="libpid_joints.so" />  -->
    <plugin name="hubo_stand" filename="/usr/share/drcsim-1.3/models/hubo/plugins/libhubo_stand.so" /> 
<!--    <plugin name="hubo_all" filename="libhubo_all.so" /> -->

  </gazebo>
</robot>

