<?xml version="1.0" ?>
<!-- =================================================================================== -->
<!-- |    This document was autogenerated by xacro from cubli.xacro                    | -->
<!-- |    EDITING THIS FILE BY HAND IS NOT RECOMMENDED                                 | -->
<!-- =================================================================================== -->
<!-- Revolute-Revolute Manipulator -->
<robot name="cubli" xmlns:xacro="http://www.ros.org/wiki/xacro">
    <!-- Space btw top of beam and the each joint -->


    <material name="black">
        <color rgba="0.0 0.0 0.0 1.0"/>
    </material>
    <material name="blue">
        <color rgba="0.0 0.0 0.8 1.0"/>
    </material>
    <material name="green">
        <color rgba="0.0 0.8 0.0 1.0"/>
    </material>
    <material name="grey">
        <color rgba="0.2 0.2 0.2 1.0"/>
    </material>
    <material name="orange">
        <color rgba="1.0 0.423529411765 0.0392156862745 1.0"/>
    </material>
    <material name="brown">
        <color rgba="0.870588235294 0.811764705882 0.764705882353 1.0"/>
    </material>
    <material name="red">
        <color rgba="0.8 0.0 0.0 1.0"/>
    </material>
    <material name="white">
        <color rgba="1.0 1.0 1.0 1.0"/>
    </material>

    <link name="cube">
        <inertial>
            <origin rpy="0 0 0" xyz="0 0 0"/>
            <mass value="1.0"/>
            <inertia ixx="0.166667" ixy="0.0" ixz="0.0" iyy="0.166667" iyz="0.0" izz="0.166667"/>
        </inertial>
        <visual>
            <origin rpy="0 0 0" xyz="0 0 0"/>
            <geometry>
                <box size="1.0 1.0 1.0"/>
            </geometry>
            <material name="white"/>
        </visual>
        <collision>
            <origin rpy="0 0 0" xyz="0 0 0"/>
            <geometry>
                <box size="1.0 1.0 1.0"/>
            </geometry>
        </collision>
    </link>
    <link name="wheel_x">
        <inertial>
            <origin rpy="0 0 0" xyz="0 0 0"/>
            <mass value="1.0"/>
            <inertia ixx="0.04020833333333334" ixy="0.0" ixz="0.0" iyy="0.04020833333333334" iyz="0.0" izz="0.08"/>
        </inertial>
        <visual>
            <origin rpy="0 0 0" xyz="0 0 0"/>
            <geometry>
                <cylinder length="0.05" radius="0.4"/>
            </geometry>
            <material name="red"/>
        </visual>
        <collision>
            <origin xyz="0 0 0" rpy="0 0 0"/>
            <geometry>
                <cylinder length="0.05" radius="0.4"/>
            </geometry>
        </collision>
    </link>
    <link name="wheel_y">
        <inertial>
            <origin rpy="0 0 0" xyz="0 0 0"/>
            <mass value="1.0"/>
            <inertia ixx="0.04020833333333334" ixy="0.0" ixz="0.0" iyy="0.04020833333333334" iyz="0.0" izz="0.08"/>
        </inertial>
        <visual>
            <origin rpy="0 0 0" xyz="0 0 0"/>
            <geometry>
                <cylinder length="0.05" radius="0.4"/>
            </geometry>
            <material name="green"/>
        </visual>
        <collision>
            <origin xyz="0 0 0" rpy="0 0 0"/>
            <geometry>
                <cylinder length="0.05" radius="0.4"/>
            </geometry>
        </collision>
    </link>
    <link name="wheel_z">
        <inertial>
            <origin rpy="0 0 0" xyz="0 0 0"/>
            <mass value="1.0"/>
            <inertia ixx="0.04020833333333334" ixy="0.0" ixz="0.0" iyy="0.04020833333333334" iyz="0.0" izz="0.08"/>
        </inertial>
        <visual>
            <origin rpy="0 0 0" xyz="0 0 0"/>
            <geometry>
                <cylinder length="0.05" radius="0.4"/>
            </geometry>
            <material name="blue"/>
        </visual>
        <collision>
            <origin xyz="0 0 0" rpy="0 0 0"/>
            <geometry>
                <cylinder length="0.05" radius="0.4"/>
            </geometry>
        </collision>
    </link>
    <joint name="joint_x" type="continuous">
        <parent link="cube"/>
        <child link="wheel_x"/>
        <origin rpy="0 1.57079632679 0" xyz="0.475 0 0"/>
        <axis xyz="0 0 1"/>
        <dynamics damping="0.7"/>
    </joint>
    <joint name="joint_y" type="continuous">
        <parent link="cube"/>
        <child link="wheel_y"/>
        <origin rpy="-1.57079632679 0 0" xyz="0 0.475 0"/>
        <axis xyz="0 0 1"/>
        <dynamics damping="0.7"/>
    </joint>
    <joint name="joint_z" type="continuous">
        <parent link="cube"/>
        <child link="wheel_z"/>
        <origin rpy="0 0 0" xyz="0 0 0.475"/>
        <axis xyz="0 0 1"/>
        <dynamics damping="0.7"/>
    </joint>

</robot>

