<?xml version="1.0" ?>
<!-- =================================================================================== -->
<!-- |    This document was autogenerated by xacro from snake.xacro                    | -->
<!-- |    EDITING THIS FILE BY HAND IS NOT RECOMMENDED                                 | -->
<!-- =================================================================================== -->
<robot name="snake" xmlns:xacro="http://www.ros.org/wiki/xacro">
  <!--link name="kdl_dummy_root"/>
  <joint name="kdl_dummy_root_to_base" type="fixed">
    <parent link="kdl_dummy_root"/>
    <child link="base"/>
    <origin rpy="0 -1.57079632679 0" xyz="0 0 0"/>
  </joint-->
  <!-- base body -->
  <!--link name="base"/>
  <!-- leg outputs on the base -->
  <!--joint name="head__OUTPUT_INTERFACE" type="fixed">
    <parent link="base"/>
    <child link="SA001__MoJo__INPUT_INTERFACE"/>
    <!-- <origin xyz="${width/2} ${leg_y_offset} ${height/2}" rpy="-${PI/2} 0 -${PI/2}"/> -->
  <!--/joint>
  <!-- ros_control plugin -->
  <gazebo>
    <plugin filename="libgazebo_ros_control.so" name="gazebo_ros_control">
      <robotNamespace>/snake</robotNamespace>
      <!-- <robotSimType>gazebo_ros_control/DefaultRobotHWSim</robotSimType> -->
    </plugin>
  </gazebo>
  <gazebo reference="SA001__MoJo__OUTPUT_BODY">
    <mu1>0.9</mu1>
    <mu2>0.9</mu2>
    <material>Gazebo/Red</material>
    <static>false</static>
    <selfCollide>true</selfCollide>
  </gazebo>
  <gazebo reference="SA001__MoJo__INPUT_INTERFACE">
    <mu1>0.9</mu1>
    <mu2>0.9</mu2>
    <material>Gazebo/Red</material>
    <static>false</static>
    <selfCollide>true</selfCollide>
  </gazebo>
  <gazebo reference="SA001__MoJo__INPUT_INTERFACE__COLLAR">
    <mu1>0.9</mu1>
    <mu2>0.9</mu2>
    <material>Gazebo/Black</material>
    <static>false</static>
    <selfCollide>true</selfCollide>
  </gazebo>
  <gazebo reference="SA002__MoJo__OUTPUT_BODY">
    <mu1>0.9</mu1>
    <mu2>0.9</mu2>
    <material>Gazebo/Red</material>
    <static>false</static>
    <selfCollide>true</selfCollide>
  </gazebo>
  <gazebo reference="SA002__MoJo__INPUT_INTERFACE">
    <mu1>0.9</mu1>
    <mu2>0.9</mu2>
    <material>Gazebo/Red</material>
    <static>false</static>
    <selfCollide>true</selfCollide>
  </gazebo>
  <gazebo reference="SA002__MoJo__INPUT_INTERFACE__COLLAR">
    <mu1>0.9</mu1>
    <mu2>0.9</mu2>
    <material>Gazebo/Black</material>
    <static>false</static>
    <selfCollide>true</selfCollide>
  </gazebo>
  <gazebo reference="SA003__MoJo__OUTPUT_BODY">
    <mu1>0.9</mu1>
    <mu2>0.9</mu2>
    <material>Gazebo/Red</material>
    <static>false</static>
    <selfCollide>true</selfCollide>
  </gazebo>
  <gazebo reference="SA003__MoJo__INPUT_INTERFACE">
    <mu1>0.9</mu1>
    <mu2>0.9</mu2>
    <material>Gazebo/Red</material>
    <static>false</static>
    <selfCollide>true</selfCollide>
  </gazebo>
  <gazebo reference="SA003__MoJo__INPUT_INTERFACE__COLLAR">
    <mu1>0.9</mu1>
    <mu2>0.9</mu2>
    <material>Gazebo/Black</material>
    <static>false</static>
    <selfCollide>true</selfCollide>
  </gazebo>
  <gazebo reference="SA004__MoJo__OUTPUT_BODY">
    <mu1>0.9</mu1>
    <mu2>0.9</mu2>
    <material>Gazebo/Red</material>
    <static>false</static>
    <selfCollide>true</selfCollide>
  </gazebo>
  <gazebo reference="SA004__MoJo__INPUT_INTERFACE">
    <mu1>0.9</mu1>
    <mu2>0.9</mu2>
    <material>Gazebo/Red</material>
    <static>false</static>
    <selfCollide>true</selfCollide>
  </gazebo>
  <gazebo reference="SA004__MoJo__INPUT_INTERFACE__COLLAR">
    <mu1>0.9</mu1>
    <mu2>0.9</mu2>
    <material>Gazebo/Black</material>
    <static>false</static>
    <selfCollide>true</selfCollide>
  </gazebo>
  <gazebo reference="SA005__MoJo__OUTPUT_BODY">
    <mu1>0.9</mu1>
    <mu2>0.9</mu2>
    <material>Gazebo/Red</material>
    <static>false</static>
    <selfCollide>true</selfCollide>
  </gazebo>
  <gazebo reference="SA005__MoJo__INPUT_INTERFACE">
    <mu1>0.9</mu1>
    <mu2>0.9</mu2>
    <material>Gazebo/Red</material>
    <static>false</static>
    <selfCollide>true</selfCollide>
  </gazebo>
  <gazebo reference="SA005__MoJo__INPUT_INTERFACE__COLLAR">
    <mu1>0.9</mu1>
    <mu2>0.9</mu2>
    <material>Gazebo/Black</material>
    <static>false</static>
    <selfCollide>true</selfCollide>
  </gazebo>
  <gazebo reference="SA006__MoJo__OUTPUT_BODY">
    <mu1>0.9</mu1>
    <mu2>0.9</mu2>
    <material>Gazebo/Red</material>
    <static>false</static>
    <selfCollide>true</selfCollide>
  </gazebo>
  <gazebo reference="SA006__MoJo__INPUT_INTERFACE">
    <mu1>0.9</mu1>
    <mu2>0.9</mu2>
    <material>Gazebo/Red</material>
    <static>false</static>
    <selfCollide>true</selfCollide>
  </gazebo>
  <gazebo reference="SA006__MoJo__INPUT_INTERFACE__COLLAR">
    <mu1>0.9</mu1>
    <mu2>0.9</mu2>
    <material>Gazebo/Black</material>
    <static>false</static>
    <selfCollide>true</selfCollide>
  </gazebo>
  <gazebo reference="SA007__MoJo__OUTPUT_BODY">
    <mu1>0.9</mu1>
    <mu2>0.9</mu2>
    <material>Gazebo/Red</material>
    <static>false</static>
    <selfCollide>true</selfCollide>
  </gazebo>
  <gazebo reference="SA007__MoJo__INPUT_INTERFACE">
    <mu1>0.9</mu1>
    <mu2>0.9</mu2>
    <material>Gazebo/Red</material>
    <static>false</static>
    <selfCollide>true</selfCollide>
  </gazebo>
  <gazebo reference="SA007__MoJo__INPUT_INTERFACE__COLLAR">
    <mu1>0.9</mu1>
    <mu2>0.9</mu2>
    <material>Gazebo/Black</material>
    <static>false</static>
    <selfCollide>true</selfCollide>
  </gazebo>
  <gazebo reference="SA008__MoJo__OUTPUT_BODY">
    <mu1>0.9</mu1>
    <mu2>0.9</mu2>
    <material>Gazebo/Red</material>
    <static>false</static>
    <selfCollide>true</selfCollide>
  </gazebo>
  <gazebo reference="SA008__MoJo__INPUT_INTERFACE">
    <mu1>0.9</mu1>
    <mu2>0.9</mu2>
    <material>Gazebo/Red</material>
    <static>false</static>
    <selfCollide>true</selfCollide>
  </gazebo>
  <gazebo reference="SA008__MoJo__INPUT_INTERFACE__COLLAR">
    <mu1>0.9</mu1>
    <mu2>0.9</mu2>
    <material>Gazebo/Black</material>
    <static>false</static>
    <selfCollide>true</selfCollide>
  </gazebo>
  <gazebo reference="SA009__MoJo__OUTPUT_BODY">
    <mu1>0.9</mu1>
    <mu2>0.9</mu2>
    <material>Gazebo/Red</material>
    <static>false</static>
    <selfCollide>true</selfCollide>
  </gazebo>
  <gazebo reference="SA009__MoJo__INPUT_INTERFACE">
    <mu1>0.9</mu1>
    <mu2>0.9</mu2>
    <material>Gazebo/Red</material>
    <static>false</static>
    <selfCollide>true</selfCollide>
  </gazebo>
  <gazebo reference="SA009__MoJo__INPUT_INTERFACE__COLLAR">
    <mu1>0.9</mu1>
    <mu2>0.9</mu2>
    <material>Gazebo/Black</material>
    <static>false</static>
    <selfCollide>true</selfCollide>
  </gazebo>
  <gazebo reference="SA010__MoJo__OUTPUT_BODY">
    <mu1>0.9</mu1>
    <mu2>0.9</mu2>
    <material>Gazebo/Red</material>
    <static>false</static>
    <selfCollide>true</selfCollide>
  </gazebo>
  <gazebo reference="SA010__MoJo__INPUT_INTERFACE">
    <mu1>0.9</mu1>
    <mu2>0.9</mu2>
    <material>Gazebo/Red</material>
    <static>false</static>
    <selfCollide>true</selfCollide>
  </gazebo>
  <gazebo reference="SA010__MoJo__INPUT_INTERFACE__COLLAR">
    <mu1>0.9</mu1>
    <mu2>0.9</mu2>
    <material>Gazebo/Black</material>
    <static>false</static>
    <selfCollide>true</selfCollide>
  </gazebo>
  <gazebo reference="SA011__MoJo__OUTPUT_BODY">
    <mu1>0.9</mu1>
    <mu2>0.9</mu2>
    <material>Gazebo/Red</material>
    <static>false</static>
    <selfCollide>true</selfCollide>
  </gazebo>
  <gazebo reference="SA011__MoJo__INPUT_INTERFACE">
    <mu1>0.9</mu1>
    <mu2>0.9</mu2>
    <material>Gazebo/Red</material>
    <static>false</static>
    <selfCollide>true</selfCollide>
  </gazebo>
  <gazebo reference="SA011__MoJo__INPUT_INTERFACE__COLLAR">
    <mu1>0.9</mu1>
    <mu2>0.9</mu2>
    <material>Gazebo/Black</material>
    <static>false</static>
    <selfCollide>true</selfCollide>
  </gazebo>
  <gazebo reference="SA012__MoJo__OUTPUT_BODY">
    <mu1>0.9</mu1>
    <mu2>0.9</mu2>
    <material>Gazebo/Red</material>
    <static>false</static>
    <selfCollide>true</selfCollide>
  </gazebo>
  <gazebo reference="SA012__MoJo__INPUT_INTERFACE">
    <mu1>0.9</mu1>
    <mu2>0.9</mu2>
    <material>Gazebo/Red</material>
    <static>false</static>
    <selfCollide>true</selfCollide>
  </gazebo>
  <gazebo reference="SA012__MoJo__INPUT_INTERFACE__COLLAR">
    <mu1>0.9</mu1>
    <mu2>0.9</mu2>
    <material>Gazebo/Black</material>
    <static>false</static>
    <selfCollide>true</selfCollide>
  </gazebo>
  <gazebo reference="SA013__MoJo__OUTPUT_BODY">
    <mu1>0.9</mu1>
    <mu2>0.9</mu2>
    <material>Gazebo/Red</material>
    <static>false</static>
    <selfCollide>true</selfCollide>
  </gazebo>
  <gazebo reference="SA013__MoJo__INPUT_INTERFACE">
    <mu1>0.9</mu1>
    <mu2>0.9</mu2>
    <material>Gazebo/Red</material>
    <static>false</static>
    <selfCollide>true</selfCollide>
  </gazebo>
  <gazebo reference="SA013__MoJo__INPUT_INTERFACE__COLLAR">
    <mu1>0.9</mu1>
    <mu2>0.9</mu2>
    <material>Gazebo/Black</material>
    <static>false</static>
    <selfCollide>true</selfCollide>
  </gazebo>
  <gazebo reference="SA014__MoJo__OUTPUT_BODY">
    <mu1>0.9</mu1>
    <mu2>0.9</mu2>
    <material>Gazebo/Red</material>
    <static>false</static>
    <selfCollide>true</selfCollide>
  </gazebo>
  <gazebo reference="SA014__MoJo__INPUT_INTERFACE">
    <mu1>0.9</mu1>
    <mu2>0.9</mu2>
    <material>Gazebo/Red</material>
    <static>false</static>
    <selfCollide>true</selfCollide>
  </gazebo>
  <gazebo reference="SA014__MoJo__INPUT_INTERFACE__COLLAR">
    <mu1>0.9</mu1>
    <mu2>0.9</mu2>
    <material>Gazebo/Black</material>
    <static>false</static>
    <selfCollide>true</selfCollide>
  </gazebo>
  <gazebo reference="SA015__MoJo__OUTPUT_BODY">
    <mu1>0.9</mu1>
    <mu2>0.9</mu2>
    <material>Gazebo/Red</material>
    <static>false</static>
    <selfCollide>true</selfCollide>
  </gazebo>
  <gazebo reference="SA015__MoJo__INPUT_INTERFACE">
    <mu1>0.9</mu1>
    <mu2>0.9</mu2>
    <material>Gazebo/Red</material>
    <static>false</static>
    <selfCollide>true</selfCollide>
  </gazebo>
  <gazebo reference="SA015__MoJo__INPUT_INTERFACE__COLLAR">
    <mu1>0.9</mu1>
    <mu2>0.9</mu2>
    <material>Gazebo/Black</material>
    <static>false</static>
    <selfCollide>true</selfCollide>
  </gazebo>
  <gazebo reference="SA016__MoJo__OUTPUT_BODY">
    <mu1>0.9</mu1>
    <mu2>0.9</mu2>
    <material>Gazebo/Red</material>
    <static>false</static>
    <selfCollide>true</selfCollide>
  </gazebo>
  <gazebo reference="SA016__MoJo__INPUT_INTERFACE">
    <mu1>0.9</mu1>
    <mu2>0.9</mu2>
    <material>Gazebo/Red</material>
    <static>false</static>
    <selfCollide>true</selfCollide>
  </gazebo>
  <gazebo reference="SA016__MoJo__INPUT_INTERFACE__COLLAR">
    <mu1>0.9</mu1>
    <mu2>0.9</mu2>
    <material>Gazebo/Black</material>
    <static>false</static>
    <selfCollide>true</selfCollide>
  </gazebo>
  <link name="SA001__MoJo__INPUT_INTERFACE">
    <visual>
      <origin rpy="1.57075 0 0" xyz="0 0 0.035"/>
      <geometry>
        <mesh filename="meshes/rotary_input.stl"/>
      </geometry>
      <material name="red">
        <color rgba=".82 0.06 0.06 1"/>
      </material>
    </visual>
    <collision>
      <origin rpy="0 0 0" xyz="0 0 0.0183"/>
      <geometry>
        <cylinder length="0.033" radius="0.026"/>
      </geometry>
    </collision>
    <inertial>
      <origin rpy="0 0 0" xyz="0 0 0.0366"/>
      <mass value="0.103"/>
      <inertia ixx="5.4796e-05" ixy="0" ixz="0" iyy="5.4796e-05" iyz="0" izz="3.4814e-05"/>
    </inertial>
  </link>
  <link name="SA001__MoJo__INPUT_INTERFACE__COLLAR">
    <visual>
      <origin rpy="0 0 0" xyz="0 0 0.005"/>
      <geometry>
        <cylinder length="0.01" radius="0.026"/>
      </geometry>
      <material name="black">
        <color rgba="0 0 0 1"/>
      </material>
    </visual>
    <inertial>
      <origin rpy="0 0 0" xyz="0 0 0"/>
      <mass value="0"/>
      <inertia ixx="0.0" ixy="0.0" ixz="0.0" iyy="0.0" iyz="0.0" izz="0.0"/>
    </inertial>
  </link> <!-- in pybullet, the inertia need to be specified even for dummy links, otherwise it will put an identity inertia and a mass of 1 by default -->
  <joint name="SA001__MoJo__INPUT_INTERFACE__COLLAR_JOINT" type="fixed">
    <parent link="SA001__MoJo__INPUT_INTERFACE"/>
    <child link="SA001__MoJo__INPUT_INTERFACE__COLLAR"/>
  </joint>
  <joint name="SA001__MoJo" type="revolute">
    <parent link="SA001__MoJo__INPUT_INTERFACE"/>
    <child link="SA001__MoJo__OUTPUT_BODY"/>
    <origin rpy="0 0 0" xyz="0 0 0.0366"/>
    <axis xyz="0 1 0"/>
    <dynamics damping=".1" friction="0.2"/>
    <limit effort="7.0" lower="-1.57" upper="1.57" velocity="2.208932"/>
  </joint>
  <transmission name="SA001__MoJo_trans">
    <type>transmission_interface/SimpleTransmission</type>
    <joint name="SA001__MoJo">
      <hardwareInterface>EffortJointInterface</hardwareInterface>
    </joint>
    <actuator name="SA001__MoJo_motor">
      <hardwareInterface>EffortJointInterface</hardwareInterface>
      <mechanicalReduction>300</mechanicalReduction>
    </actuator>
  </transmission>
  <link name="SA001__MoJo__OUTPUT_BODY">
    <visual>
      <origin rpy="1.57075 0 0" xyz="0 0 0"/>
      <geometry>
        <mesh filename="meshes/rotary_output.stl"/>
        <!-- <cylinder radius=".0025" length=".1" /> -->
      </geometry>
      <material name="red">
        <color rgba=".82 0.06 0.06 1"/>
      </material>
    </visual>
    <collision>
      <origin rpy="0 0 0" xyz="0 0 0.0183"/>
      <geometry>
        <cylinder length="0.033" radius="0.026"/>
      </geometry>
    </collision>
    <inertial>
      <origin rpy="0 0 0" xyz="0 0 0"/>
      <mass value="0.103"/>
      <inertia ixx="5.4796e-05" ixy="0" ixz="0" iyy="5.4796e-05" iyz="0" izz="3.4814e-05"/>
    </inertial>
  </link>
  <joint name="SA001__MoJo__OUTPUT_INTERFACE" type="fixed">
    <parent link="SA001__MoJo__OUTPUT_BODY"/>
    <child link="SA002__MoJo__INPUT_INTERFACE"/>
    <origin rpy="0 0 -1.57075" xyz="0 0 0.0273"/>
  </joint>
  <link name="SA002__MoJo__INPUT_INTERFACE">
    <visual>
      <origin rpy="1.57075 0 0" xyz="0 0 0.035"/>
      <geometry>
        <mesh filename="meshes/rotary_input.stl"/>
      </geometry>
      <material name="red">
        <color rgba=".82 0.06 0.06 1"/>
      </material>
    </visual>
    <collision>
      <origin rpy="0 0 0" xyz="0 0 0.0183"/>
      <geometry>
        <cylinder length="0.033" radius="0.026"/>
      </geometry>
    </collision>
    <inertial>
      <origin rpy="0 0 0" xyz="0 0 0.0366"/>
      <mass value="0.103"/>
      <inertia ixx="5.4796e-05" ixy="0" ixz="0" iyy="5.4796e-05" iyz="0" izz="3.4814e-05"/>
    </inertial>
  </link>
  <link name="SA002__MoJo__INPUT_INTERFACE__COLLAR">
    <visual>
      <origin rpy="0 0 0" xyz="0 0 0.005"/>
      <geometry>
        <cylinder length="0.01" radius="0.026"/>
      </geometry>
      <material name="black">
        <color rgba="0 0 0 1"/>
      </material>
    </visual>
    <inertial>
      <origin rpy="0 0 0" xyz="0 0 0"/>
      <mass value="0"/>
      <inertia ixx="0.0" ixy="0.0" ixz="0.0" iyy="0.0" iyz="0.0" izz="0.0"/>
    </inertial>
  </link> <!-- in pybullet, the inertia need to be specified even for dummy links, otherwise it will put an identity inertia and a mass of 1 by default -->
  <joint name="SA002__MoJo__INPUT_INTERFACE__COLLAR_JOINT" type="fixed">
    <parent link="SA002__MoJo__INPUT_INTERFACE"/>
    <child link="SA002__MoJo__INPUT_INTERFACE__COLLAR"/>
  </joint>
  <joint name="SA002__MoJo" type="revolute">
    <parent link="SA002__MoJo__INPUT_INTERFACE"/>
    <child link="SA002__MoJo__OUTPUT_BODY"/>
    <origin rpy="0 0 0" xyz="0 0 0.0366"/>
    <axis xyz="0 1 0"/>
    <dynamics damping=".1" friction="0.2"/>
    <limit effort="7.0" lower="-1.57" upper="1.57" velocity="2.208932"/>
  </joint>
  <transmission name="SA002__MoJo_trans">
    <type>transmission_interface/SimpleTransmission</type>
    <joint name="SA002__MoJo">
      <hardwareInterface>EffortJointInterface</hardwareInterface>
    </joint>
    <actuator name="SA002__MoJo_motor">
      <hardwareInterface>EffortJointInterface</hardwareInterface>
      <mechanicalReduction>300</mechanicalReduction>
    </actuator>
  </transmission>
  <link name="SA002__MoJo__OUTPUT_BODY">
    <visual>
      <origin rpy="1.57075 0 0" xyz="0 0 0"/>
      <geometry>
        <mesh filename="meshes/rotary_output.stl"/>
        <!-- <cylinder radius=".0025" length=".1" /> -->
      </geometry>
      <material name="red">
        <color rgba=".82 0.06 0.06 1"/>
      </material>
    </visual>
    <collision>
      <origin rpy="0 0 0" xyz="0 0 0.0183"/>
      <geometry>
        <cylinder length="0.033" radius="0.026"/>
      </geometry>
    </collision>
    <inertial>
      <origin rpy="0 0 0" xyz="0 0 0"/>
      <mass value="0.103"/>
      <inertia ixx="5.4796e-05" ixy="0" ixz="0" iyy="5.4796e-05" iyz="0" izz="3.4814e-05"/>
    </inertial>
  </link>
  <joint name="SA002__MoJo__OUTPUT_INTERFACE" type="fixed">
    <parent link="SA002__MoJo__OUTPUT_BODY"/>
    <child link="SA003__MoJo__INPUT_INTERFACE"/>
    <origin rpy="0 0 -1.57075" xyz="0 0 0.0273"/>
  </joint>
  <link name="SA003__MoJo__INPUT_INTERFACE">
    <visual>
      <origin rpy="1.57075 0 0" xyz="0 0 0.035"/>
      <geometry>
        <mesh filename="meshes/rotary_input.stl"/>
      </geometry>
      <material name="red">
        <color rgba=".82 0.06 0.06 1"/>
      </material>
    </visual>
    <collision>
      <origin rpy="0 0 0" xyz="0 0 0.0183"/>
      <geometry>
        <cylinder length="0.033" radius="0.026"/>
      </geometry>
    </collision>
    <inertial>
      <origin rpy="0 0 0" xyz="0 0 0.0366"/>
      <mass value="0.103"/>
      <inertia ixx="5.4796e-05" ixy="0" ixz="0" iyy="5.4796e-05" iyz="0" izz="3.4814e-05"/>
    </inertial>
  </link>
  <link name="SA003__MoJo__INPUT_INTERFACE__COLLAR">
    <visual>
      <origin rpy="0 0 0" xyz="0 0 0.005"/>
      <geometry>
        <cylinder length="0.01" radius="0.026"/>
      </geometry>
      <material name="black">
        <color rgba="0 0 0 1"/>
      </material>
    </visual>
    <inertial>
      <origin rpy="0 0 0" xyz="0 0 0"/>
      <mass value="0"/>
      <inertia ixx="0.0" ixy="0.0" ixz="0.0" iyy="0.0" iyz="0.0" izz="0.0"/>
    </inertial>
  </link> <!-- in pybullet, the inertia need to be specified even for dummy links, otherwise it will put an identity inertia and a mass of 1 by default -->
  <joint name="SA003__MoJo__INPUT_INTERFACE__COLLAR_JOINT" type="fixed">
    <parent link="SA003__MoJo__INPUT_INTERFACE"/>
    <child link="SA003__MoJo__INPUT_INTERFACE__COLLAR"/>
  </joint>
  <joint name="SA003__MoJo" type="revolute">
    <parent link="SA003__MoJo__INPUT_INTERFACE"/>
    <child link="SA003__MoJo__OUTPUT_BODY"/>
    <origin rpy="0 0 0" xyz="0 0 0.0366"/>
    <axis xyz="0 1 0"/>
    <dynamics damping=".1" friction="0.2"/>
    <limit effort="7.0" lower="-1.57" upper="1.57" velocity="2.208932"/>
  </joint>
  <transmission name="SA003__MoJo_trans">
    <type>transmission_interface/SimpleTransmission</type>
    <joint name="SA003__MoJo">
      <hardwareInterface>EffortJointInterface</hardwareInterface>
    </joint>
    <actuator name="SA003__MoJo_motor">
      <hardwareInterface>EffortJointInterface</hardwareInterface>
      <mechanicalReduction>300</mechanicalReduction>
    </actuator>
  </transmission>
  <link name="SA003__MoJo__OUTPUT_BODY">
    <visual>
      <origin rpy="1.57075 0 0" xyz="0 0 0"/>
      <geometry>
        <mesh filename="meshes/rotary_output.stl"/>
        <!-- <cylinder radius=".0025" length=".1" /> -->
      </geometry>
      <material name="red">
        <color rgba=".82 0.06 0.06 1"/>
      </material>
    </visual>
    <collision>
      <origin rpy="0 0 0" xyz="0 0 0.0183"/>
      <geometry>
        <cylinder length="0.033" radius="0.026"/>
      </geometry>
    </collision>
    <inertial>
      <origin rpy="0 0 0" xyz="0 0 0"/>
      <mass value="0.103"/>
      <inertia ixx="5.4796e-05" ixy="0" ixz="0" iyy="5.4796e-05" iyz="0" izz="3.4814e-05"/>
    </inertial>
  </link>
  <joint name="SA003__MoJo__OUTPUT_INTERFACE" type="fixed">
    <parent link="SA003__MoJo__OUTPUT_BODY"/>
    <child link="SA004__MoJo__INPUT_INTERFACE"/>
    <origin rpy="0 0 -1.57075" xyz="0 0 0.0273"/>
  </joint>
  <link name="SA004__MoJo__INPUT_INTERFACE">
    <visual>
      <origin rpy="1.57075 0 0" xyz="0 0 0.035"/>
      <geometry>
        <mesh filename="meshes/rotary_input.stl"/>
      </geometry>
      <material name="red">
        <color rgba=".82 0.06 0.06 1"/>
      </material>
    </visual>
    <collision>
      <origin rpy="0 0 0" xyz="0 0 0.0183"/>
      <geometry>
        <cylinder length="0.033" radius="0.026"/>
      </geometry>
    </collision>
    <inertial>
      <origin rpy="0 0 0" xyz="0 0 0.0366"/>
      <mass value="0.103"/>
      <inertia ixx="5.4796e-05" ixy="0" ixz="0" iyy="5.4796e-05" iyz="0" izz="3.4814e-05"/>
    </inertial>
  </link>
  <link name="SA004__MoJo__INPUT_INTERFACE__COLLAR">
    <visual>
      <origin rpy="0 0 0" xyz="0 0 0.005"/>
      <geometry>
        <cylinder length="0.01" radius="0.026"/>
      </geometry>
      <material name="black">
        <color rgba="0 0 0 1"/>
      </material>
    </visual>
    <inertial>
      <origin rpy="0 0 0" xyz="0 0 0"/>
      <mass value="0"/>
      <inertia ixx="0.0" ixy="0.0" ixz="0.0" iyy="0.0" iyz="0.0" izz="0.0"/>
    </inertial>
  </link> <!-- in pybullet, the inertia need to be specified even for dummy links, otherwise it will put an identity inertia and a mass of 1 by default -->
  <joint name="SA004__MoJo__INPUT_INTERFACE__COLLAR_JOINT" type="fixed">
    <parent link="SA004__MoJo__INPUT_INTERFACE"/>
    <child link="SA004__MoJo__INPUT_INTERFACE__COLLAR"/>
  </joint>
  <joint name="SA004__MoJo" type="revolute">
    <parent link="SA004__MoJo__INPUT_INTERFACE"/>
    <child link="SA004__MoJo__OUTPUT_BODY"/>
    <origin rpy="0 0 0" xyz="0 0 0.0366"/>
    <axis xyz="0 1 0"/>
    <dynamics damping=".1" friction="0.2"/>
    <limit effort="7.0" lower="-1.57" upper="1.57" velocity="2.208932"/>
  </joint>
  <transmission name="SA004__MoJo_trans">
    <type>transmission_interface/SimpleTransmission</type>
    <joint name="SA004__MoJo">
      <hardwareInterface>EffortJointInterface</hardwareInterface>
    </joint>
    <actuator name="SA004__MoJo_motor">
      <hardwareInterface>EffortJointInterface</hardwareInterface>
      <mechanicalReduction>300</mechanicalReduction>
    </actuator>
  </transmission>
  <link name="SA004__MoJo__OUTPUT_BODY">
    <visual>
      <origin rpy="1.57075 0 0" xyz="0 0 0"/>
      <geometry>
        <mesh filename="meshes/rotary_output.stl"/>
        <!-- <cylinder radius=".0025" length=".1" /> -->
      </geometry>
      <material name="red">
        <color rgba=".82 0.06 0.06 1"/>
      </material>
    </visual>
    <collision>
      <origin rpy="0 0 0" xyz="0 0 0.0183"/>
      <geometry>
        <cylinder length="0.033" radius="0.026"/>
      </geometry>
    </collision>
    <inertial>
      <origin rpy="0 0 0" xyz="0 0 0"/>
      <mass value="0.103"/>
      <inertia ixx="5.4796e-05" ixy="0" ixz="0" iyy="5.4796e-05" iyz="0" izz="3.4814e-05"/>
    </inertial>
  </link>
  <joint name="SA004__MoJo__OUTPUT_INTERFACE" type="fixed">
    <parent link="SA004__MoJo__OUTPUT_BODY"/>
    <child link="SA005__MoJo__INPUT_INTERFACE"/>
    <origin rpy="0 0 -1.57075" xyz="0 0 0.0273"/>
  </joint>
  <link name="SA005__MoJo__INPUT_INTERFACE">
    <visual>
      <origin rpy="1.57075 0 0" xyz="0 0 0.035"/>
      <geometry>
        <mesh filename="meshes/rotary_input.stl"/>
      </geometry>
      <material name="red">
        <color rgba=".82 0.06 0.06 1"/>
      </material>
    </visual>
    <collision>
      <origin rpy="0 0 0" xyz="0 0 0.0183"/>
      <geometry>
        <cylinder length="0.033" radius="0.026"/>
      </geometry>
    </collision>
    <inertial>
      <origin rpy="0 0 0" xyz="0 0 0.0366"/>
      <mass value="0.103"/>
      <inertia ixx="5.4796e-05" ixy="0" ixz="0" iyy="5.4796e-05" iyz="0" izz="3.4814e-05"/>
    </inertial>
  </link>
  <link name="SA005__MoJo__INPUT_INTERFACE__COLLAR">
    <visual>
      <origin rpy="0 0 0" xyz="0 0 0.005"/>
      <geometry>
        <cylinder length="0.01" radius="0.026"/>
      </geometry>
      <material name="black">
        <color rgba="0 0 0 1"/>
      </material>
    </visual>
    <inertial>
      <origin rpy="0 0 0" xyz="0 0 0"/>
      <mass value="0"/>
      <inertia ixx="0.0" ixy="0.0" ixz="0.0" iyy="0.0" iyz="0.0" izz="0.0"/>
    </inertial>
  </link> <!-- in pybullet, the inertia need to be specified even for dummy links, otherwise it will put an identity inertia and a mass of 1 by default -->
  <joint name="SA005__MoJo__INPUT_INTERFACE__COLLAR_JOINT" type="fixed">
    <parent link="SA005__MoJo__INPUT_INTERFACE"/>
    <child link="SA005__MoJo__INPUT_INTERFACE__COLLAR"/>
  </joint>
  <joint name="SA005__MoJo" type="revolute">
    <parent link="SA005__MoJo__INPUT_INTERFACE"/>
    <child link="SA005__MoJo__OUTPUT_BODY"/>
    <origin rpy="0 0 0" xyz="0 0 0.0366"/>
    <axis xyz="0 1 0"/>
    <dynamics damping=".1" friction="0.2"/>
    <limit effort="7.0" lower="-1.57" upper="1.57" velocity="2.208932"/>
  </joint>
  <transmission name="SA005__MoJo_trans">
    <type>transmission_interface/SimpleTransmission</type>
    <joint name="SA005__MoJo">
      <hardwareInterface>EffortJointInterface</hardwareInterface>
    </joint>
    <actuator name="SA005__MoJo_motor">
      <hardwareInterface>EffortJointInterface</hardwareInterface>
      <mechanicalReduction>300</mechanicalReduction>
    </actuator>
  </transmission>
  <link name="SA005__MoJo__OUTPUT_BODY">
    <visual>
      <origin rpy="1.57075 0 0" xyz="0 0 0"/>
      <geometry>
        <mesh filename="meshes/rotary_output.stl"/>
        <!-- <cylinder radius=".0025" length=".1" /> -->
      </geometry>
      <material name="red">
        <color rgba=".82 0.06 0.06 1"/>
      </material>
    </visual>
    <collision>
      <origin rpy="0 0 0" xyz="0 0 0.0183"/>
      <geometry>
        <cylinder length="0.033" radius="0.026"/>
      </geometry>
    </collision>
    <inertial>
      <origin rpy="0 0 0" xyz="0 0 0"/>
      <mass value="0.103"/>
      <inertia ixx="5.4796e-05" ixy="0" ixz="0" iyy="5.4796e-05" iyz="0" izz="3.4814e-05"/>
    </inertial>
  </link>
  <joint name="SA005__MoJo__OUTPUT_INTERFACE" type="fixed">
    <parent link="SA005__MoJo__OUTPUT_BODY"/>
    <child link="SA006__MoJo__INPUT_INTERFACE"/>
    <origin rpy="0 0 -1.57075" xyz="0 0 0.0273"/>
  </joint>
  <link name="SA006__MoJo__INPUT_INTERFACE">
    <visual>
      <origin rpy="1.57075 0 0" xyz="0 0 0.035"/>
      <geometry>
        <mesh filename="meshes/rotary_input.stl"/>
      </geometry>
      <material name="red">
        <color rgba=".82 0.06 0.06 1"/>
      </material>
    </visual>
    <collision>
      <origin rpy="0 0 0" xyz="0 0 0.0183"/>
      <geometry>
        <cylinder length="0.033" radius="0.026"/>
      </geometry>
    </collision>
    <inertial>
      <origin rpy="0 0 0" xyz="0 0 0.0366"/>
      <mass value="0.103"/>
      <inertia ixx="5.4796e-05" ixy="0" ixz="0" iyy="5.4796e-05" iyz="0" izz="3.4814e-05"/>
    </inertial>
  </link>
  <link name="SA006__MoJo__INPUT_INTERFACE__COLLAR">
    <visual>
      <origin rpy="0 0 0" xyz="0 0 0.005"/>
      <geometry>
        <cylinder length="0.01" radius="0.026"/>
      </geometry>
      <material name="black">
        <color rgba="0 0 0 1"/>
      </material>
    </visual>
    <inertial>
      <origin rpy="0 0 0" xyz="0 0 0"/>
      <mass value="0"/>
      <inertia ixx="0.0" ixy="0.0" ixz="0.0" iyy="0.0" iyz="0.0" izz="0.0"/>
    </inertial>
  </link> <!-- in pybullet, the inertia need to be specified even for dummy links, otherwise it will put an identity inertia and a mass of 1 by default -->
  <joint name="SA006__MoJo__INPUT_INTERFACE__COLLAR_JOINT" type="fixed">
    <parent link="SA006__MoJo__INPUT_INTERFACE"/>
    <child link="SA006__MoJo__INPUT_INTERFACE__COLLAR"/>
  </joint>
  <joint name="SA006__MoJo" type="revolute">
    <parent link="SA006__MoJo__INPUT_INTERFACE"/>
    <child link="SA006__MoJo__OUTPUT_BODY"/>
    <origin rpy="0 0 0" xyz="0 0 0.0366"/>
    <axis xyz="0 1 0"/>
    <dynamics damping=".1" friction="0.2"/>
    <limit effort="7.0" lower="-1.57" upper="1.57" velocity="2.208932"/>
  </joint>
  <transmission name="SA006__MoJo_trans">
    <type>transmission_interface/SimpleTransmission</type>
    <joint name="SA006__MoJo">
      <hardwareInterface>EffortJointInterface</hardwareInterface>
    </joint>
    <actuator name="SA006__MoJo_motor">
      <hardwareInterface>EffortJointInterface</hardwareInterface>
      <mechanicalReduction>300</mechanicalReduction>
    </actuator>
  </transmission>
  <link name="SA006__MoJo__OUTPUT_BODY">
    <visual>
      <origin rpy="1.57075 0 0" xyz="0 0 0"/>
      <geometry>
        <mesh filename="meshes/rotary_output.stl"/>
        <!-- <cylinder radius=".0025" length=".1" /> -->
      </geometry>
      <material name="red">
        <color rgba=".82 0.06 0.06 1"/>
      </material>
    </visual>
    <collision>
      <origin rpy="0 0 0" xyz="0 0 0.0183"/>
      <geometry>
        <cylinder length="0.033" radius="0.026"/>
      </geometry>
    </collision>
    <inertial>
      <origin rpy="0 0 0" xyz="0 0 0"/>
      <mass value="0.103"/>
      <inertia ixx="5.4796e-05" ixy="0" ixz="0" iyy="5.4796e-05" iyz="0" izz="3.4814e-05"/>
    </inertial>
  </link>
  <joint name="SA006__MoJo__OUTPUT_INTERFACE" type="fixed">
    <parent link="SA006__MoJo__OUTPUT_BODY"/>
    <child link="SA007__MoJo__INPUT_INTERFACE"/>
    <origin rpy="0 0 -1.57075" xyz="0 0 0.0273"/>
  </joint>
  <link name="SA007__MoJo__INPUT_INTERFACE">
    <visual>
      <origin rpy="1.57075 0 0" xyz="0 0 0.035"/>
      <geometry>
        <mesh filename="meshes/rotary_input.stl"/>
      </geometry>
      <material name="red">
        <color rgba=".82 0.06 0.06 1"/>
      </material>
    </visual>
    <collision>
      <origin rpy="0 0 0" xyz="0 0 0.0183"/>
      <geometry>
        <cylinder length="0.033" radius="0.026"/>
      </geometry>
    </collision>
    <inertial>
      <origin rpy="0 0 0" xyz="0 0 0.0366"/>
      <mass value="0.103"/>
      <inertia ixx="5.4796e-05" ixy="0" ixz="0" iyy="5.4796e-05" iyz="0" izz="3.4814e-05"/>
    </inertial>
  </link>
  <link name="SA007__MoJo__INPUT_INTERFACE__COLLAR">
    <visual>
      <origin rpy="0 0 0" xyz="0 0 0.005"/>
      <geometry>
        <cylinder length="0.01" radius="0.026"/>
      </geometry>
      <material name="black">
        <color rgba="0 0 0 1"/>
      </material>
    </visual>
    <inertial>
      <origin rpy="0 0 0" xyz="0 0 0"/>
      <mass value="0"/>
      <inertia ixx="0.0" ixy="0.0" ixz="0.0" iyy="0.0" iyz="0.0" izz="0.0"/>
    </inertial>
  </link> <!-- in pybullet, the inertia need to be specified even for dummy links, otherwise it will put an identity inertia and a mass of 1 by default -->
  <joint name="SA007__MoJo__INPUT_INTERFACE__COLLAR_JOINT" type="fixed">
    <parent link="SA007__MoJo__INPUT_INTERFACE"/>
    <child link="SA007__MoJo__INPUT_INTERFACE__COLLAR"/>
  </joint>
  <joint name="SA007__MoJo" type="revolute">
    <parent link="SA007__MoJo__INPUT_INTERFACE"/>
    <child link="SA007__MoJo__OUTPUT_BODY"/>
    <origin rpy="0 0 0" xyz="0 0 0.0366"/>
    <axis xyz="0 1 0"/>
    <dynamics damping=".1" friction="0.2"/>
    <limit effort="7.0" lower="-1.57" upper="1.57" velocity="2.208932"/>
  </joint>
  <transmission name="SA007__MoJo_trans">
    <type>transmission_interface/SimpleTransmission</type>
    <joint name="SA007__MoJo">
      <hardwareInterface>EffortJointInterface</hardwareInterface>
    </joint>
    <actuator name="SA007__MoJo_motor">
      <hardwareInterface>EffortJointInterface</hardwareInterface>
      <mechanicalReduction>300</mechanicalReduction>
    </actuator>
  </transmission>
  <link name="SA007__MoJo__OUTPUT_BODY">
    <visual>
      <origin rpy="1.57075 0 0" xyz="0 0 0"/>
      <geometry>
        <mesh filename="meshes/rotary_output.stl"/>
        <!-- <cylinder radius=".0025" length=".1" /> -->
      </geometry>
      <material name="red">
        <color rgba=".82 0.06 0.06 1"/>
      </material>
    </visual>
    <collision>
      <origin rpy="0 0 0" xyz="0 0 0.0183"/>
      <geometry>
        <cylinder length="0.033" radius="0.026"/>
      </geometry>
    </collision>
    <inertial>
      <origin rpy="0 0 0" xyz="0 0 0"/>
      <mass value="0.103"/>
      <inertia ixx="5.4796e-05" ixy="0" ixz="0" iyy="5.4796e-05" iyz="0" izz="3.4814e-05"/>
    </inertial>
  </link>
  <joint name="SA007__MoJo__OUTPUT_INTERFACE" type="fixed">
    <parent link="SA007__MoJo__OUTPUT_BODY"/>
    <child link="SA008__MoJo__INPUT_INTERFACE"/>
    <origin rpy="0 0 -1.57075" xyz="0 0 0.0273"/>
  </joint>
  <link name="SA008__MoJo__INPUT_INTERFACE">
    <visual>
      <origin rpy="1.57075 0 0" xyz="0 0 0.035"/>
      <geometry>
        <mesh filename="meshes/rotary_input.stl"/>
      </geometry>
      <material name="red">
        <color rgba=".82 0.06 0.06 1"/>
      </material>
    </visual>
    <collision>
      <origin rpy="0 0 0" xyz="0 0 0.0183"/>
      <geometry>
        <cylinder length="0.033" radius="0.026"/>
      </geometry>
    </collision>
    <inertial>
      <origin rpy="0 0 0" xyz="0 0 0.0366"/>
      <mass value="0.103"/>
      <inertia ixx="5.4796e-05" ixy="0" ixz="0" iyy="5.4796e-05" iyz="0" izz="3.4814e-05"/>
    </inertial>
  </link>
  <link name="SA008__MoJo__INPUT_INTERFACE__COLLAR">
    <visual>
      <origin rpy="0 0 0" xyz="0 0 0.005"/>
      <geometry>
        <cylinder length="0.01" radius="0.026"/>
      </geometry>
      <material name="black">
        <color rgba="0 0 0 1"/>
      </material>
    </visual>
    <inertial>
      <origin rpy="0 0 0" xyz="0 0 0"/>
      <mass value="0"/>
      <inertia ixx="0.0" ixy="0.0" ixz="0.0" iyy="0.0" iyz="0.0" izz="0.0"/>
    </inertial>
  </link> <!-- in pybullet, the inertia need to be specified even for dummy links, otherwise it will put an identity inertia and a mass of 1 by default -->
  <joint name="SA008__MoJo__INPUT_INTERFACE__COLLAR_JOINT" type="fixed">
    <parent link="SA008__MoJo__INPUT_INTERFACE"/>
    <child link="SA008__MoJo__INPUT_INTERFACE__COLLAR"/>
  </joint>
  <joint name="SA008__MoJo" type="revolute">
    <parent link="SA008__MoJo__INPUT_INTERFACE"/>
    <child link="SA008__MoJo__OUTPUT_BODY"/>
    <origin rpy="0 0 0" xyz="0 0 0.0366"/>
    <axis xyz="0 1 0"/>
    <dynamics damping=".1" friction="0.2"/>
    <limit effort="7.0" lower="-1.57" upper="1.57" velocity="2.208932"/>
  </joint>
  <transmission name="SA008__MoJo_trans">
    <type>transmission_interface/SimpleTransmission</type>
    <joint name="SA008__MoJo">
      <hardwareInterface>EffortJointInterface</hardwareInterface>
    </joint>
    <actuator name="SA008__MoJo_motor">
      <hardwareInterface>EffortJointInterface</hardwareInterface>
      <mechanicalReduction>300</mechanicalReduction>
    </actuator>
  </transmission>
  <link name="SA008__MoJo__OUTPUT_BODY">
    <visual>
      <origin rpy="1.57075 0 0" xyz="0 0 0"/>
      <geometry>
        <mesh filename="meshes/rotary_output.stl"/>
        <!-- <cylinder radius=".0025" length=".1" /> -->
      </geometry>
      <material name="red">
        <color rgba=".82 0.06 0.06 1"/>
      </material>
    </visual>
    <collision>
      <origin rpy="0 0 0" xyz="0 0 0.0183"/>
      <geometry>
        <cylinder length="0.033" radius="0.026"/>
      </geometry>
    </collision>
    <inertial>
      <origin rpy="0 0 0" xyz="0 0 0"/>
      <mass value="0.103"/>
      <inertia ixx="5.4796e-05" ixy="0" ixz="0" iyy="5.4796e-05" iyz="0" izz="3.4814e-05"/>
    </inertial>
  </link>
  <joint name="SA008__MoJo__OUTPUT_INTERFACE" type="fixed">
    <parent link="SA008__MoJo__OUTPUT_BODY"/>
    <child link="SA009__MoJo__INPUT_INTERFACE"/>
    <origin rpy="0 0 -1.57075" xyz="0 0 0.0273"/>
  </joint>
  <link name="SA009__MoJo__INPUT_INTERFACE">
    <visual>
      <origin rpy="1.57075 0 0" xyz="0 0 0.035"/>
      <geometry>
        <mesh filename="meshes/rotary_input.stl"/>
      </geometry>
      <material name="red">
        <color rgba=".82 0.06 0.06 1"/>
      </material>
    </visual>
    <collision>
      <origin rpy="0 0 0" xyz="0 0 0.0183"/>
      <geometry>
        <cylinder length="0.033" radius="0.026"/>
      </geometry>
    </collision>
    <inertial>
      <origin rpy="0 0 0" xyz="0 0 0.0366"/>
      <mass value="0.103"/>
      <inertia ixx="5.4796e-05" ixy="0" ixz="0" iyy="5.4796e-05" iyz="0" izz="3.4814e-05"/>
    </inertial>
  </link>
  <link name="SA009__MoJo__INPUT_INTERFACE__COLLAR">
    <visual>
      <origin rpy="0 0 0" xyz="0 0 0.005"/>
      <geometry>
        <cylinder length="0.01" radius="0.026"/>
      </geometry>
      <material name="black">
        <color rgba="0 0 0 1"/>
      </material>
    </visual>
    <inertial>
      <origin rpy="0 0 0" xyz="0 0 0"/>
      <mass value="0"/>
      <inertia ixx="0.0" ixy="0.0" ixz="0.0" iyy="0.0" iyz="0.0" izz="0.0"/>
    </inertial>
  </link> <!-- in pybullet, the inertia need to be specified even for dummy links, otherwise it will put an identity inertia and a mass of 1 by default -->
  <joint name="SA009__MoJo__INPUT_INTERFACE__COLLAR_JOINT" type="fixed">
    <parent link="SA009__MoJo__INPUT_INTERFACE"/>
    <child link="SA009__MoJo__INPUT_INTERFACE__COLLAR"/>
  </joint>
  <joint name="SA009__MoJo" type="revolute">
    <parent link="SA009__MoJo__INPUT_INTERFACE"/>
    <child link="SA009__MoJo__OUTPUT_BODY"/>
    <origin rpy="0 0 0" xyz="0 0 0.0366"/>
    <axis xyz="0 1 0"/>
    <dynamics damping=".1" friction="0.2"/>
    <limit effort="7.0" lower="-1.57" upper="1.57" velocity="2.208932"/>
  </joint>
  <transmission name="SA009__MoJo_trans">
    <type>transmission_interface/SimpleTransmission</type>
    <joint name="SA009__MoJo">
      <hardwareInterface>EffortJointInterface</hardwareInterface>
    </joint>
    <actuator name="SA009__MoJo_motor">
      <hardwareInterface>EffortJointInterface</hardwareInterface>
      <mechanicalReduction>300</mechanicalReduction>
    </actuator>
  </transmission>
  <link name="SA009__MoJo__OUTPUT_BODY">
    <visual>
      <origin rpy="1.57075 0 0" xyz="0 0 0"/>
      <geometry>
        <mesh filename="meshes/rotary_output.stl"/>
        <!-- <cylinder radius=".0025" length=".1" /> -->
      </geometry>
      <material name="red">
        <color rgba=".82 0.06 0.06 1"/>
      </material>
    </visual>
    <collision>
      <origin rpy="0 0 0" xyz="0 0 0.0183"/>
      <geometry>
        <cylinder length="0.033" radius="0.026"/>
      </geometry>
    </collision>
    <inertial>
      <origin rpy="0 0 0" xyz="0 0 0"/>
      <mass value="0.103"/>
      <inertia ixx="5.4796e-05" ixy="0" ixz="0" iyy="5.4796e-05" iyz="0" izz="3.4814e-05"/>
    </inertial>
  </link>
  <joint name="SA009__MoJo__OUTPUT_INTERFACE" type="fixed">
    <parent link="SA009__MoJo__OUTPUT_BODY"/>
    <child link="SA010__MoJo__INPUT_INTERFACE"/>
    <origin rpy="0 0 -1.57075" xyz="0 0 0.0273"/>
  </joint>
  <link name="SA010__MoJo__INPUT_INTERFACE">
    <visual>
      <origin rpy="1.57075 0 0" xyz="0 0 0.035"/>
      <geometry>
        <mesh filename="meshes/rotary_input.stl"/>
      </geometry>
      <material name="red">
        <color rgba=".82 0.06 0.06 1"/>
      </material>
    </visual>
    <collision>
      <origin rpy="0 0 0" xyz="0 0 0.0183"/>
      <geometry>
        <cylinder length="0.033" radius="0.026"/>
      </geometry>
    </collision>
    <inertial>
      <origin rpy="0 0 0" xyz="0 0 0.0366"/>
      <mass value="0.103"/>
      <inertia ixx="5.4796e-05" ixy="0" ixz="0" iyy="5.4796e-05" iyz="0" izz="3.4814e-05"/>
    </inertial>
  </link>
  <link name="SA010__MoJo__INPUT_INTERFACE__COLLAR">
    <visual>
      <origin rpy="0 0 0" xyz="0 0 0.005"/>
      <geometry>
        <cylinder length="0.01" radius="0.026"/>
      </geometry>
      <material name="black">
        <color rgba="0 0 0 1"/>
      </material>
    </visual>
    <inertial>
      <origin rpy="0 0 0" xyz="0 0 0"/>
      <mass value="0"/>
      <inertia ixx="0.0" ixy="0.0" ixz="0.0" iyy="0.0" iyz="0.0" izz="0.0"/>
    </inertial>
  </link> <!-- in pybullet, the inertia need to be specified even for dummy links, otherwise it will put an identity inertia and a mass of 1 by default -->
  <joint name="SA010__MoJo__INPUT_INTERFACE__COLLAR_JOINT" type="fixed">
    <parent link="SA010__MoJo__INPUT_INTERFACE"/>
    <child link="SA010__MoJo__INPUT_INTERFACE__COLLAR"/>
  </joint>
  <joint name="SA010__MoJo" type="revolute">
    <parent link="SA010__MoJo__INPUT_INTERFACE"/>
    <child link="SA010__MoJo__OUTPUT_BODY"/>
    <origin rpy="0 0 0" xyz="0 0 0.0366"/>
    <axis xyz="0 1 0"/>
    <dynamics damping=".1" friction="0.2"/>
    <limit effort="7.0" lower="-1.57" upper="1.57" velocity="2.208932"/>
  </joint>
  <transmission name="SA010__MoJo_trans">
    <type>transmission_interface/SimpleTransmission</type>
    <joint name="SA010__MoJo">
      <hardwareInterface>EffortJointInterface</hardwareInterface>
    </joint>
    <actuator name="SA010__MoJo_motor">
      <hardwareInterface>EffortJointInterface</hardwareInterface>
      <mechanicalReduction>300</mechanicalReduction>
    </actuator>
  </transmission>
  <link name="SA010__MoJo__OUTPUT_BODY">
    <visual>
      <origin rpy="1.57075 0 0" xyz="0 0 0"/>
      <geometry>
        <mesh filename="meshes/rotary_output.stl"/>
        <!-- <cylinder radius=".0025" length=".1" /> -->
      </geometry>
      <material name="red">
        <color rgba=".82 0.06 0.06 1"/>
      </material>
    </visual>
    <collision>
      <origin rpy="0 0 0" xyz="0 0 0.0183"/>
      <geometry>
        <cylinder length="0.033" radius="0.026"/>
      </geometry>
    </collision>
    <inertial>
      <origin rpy="0 0 0" xyz="0 0 0"/>
      <mass value="0.103"/>
      <inertia ixx="5.4796e-05" ixy="0" ixz="0" iyy="5.4796e-05" iyz="0" izz="3.4814e-05"/>
    </inertial>
  </link>
  <joint name="SA010__MoJo__OUTPUT_INTERFACE" type="fixed">
    <parent link="SA010__MoJo__OUTPUT_BODY"/>
    <child link="SA011__MoJo__INPUT_INTERFACE"/>
    <origin rpy="0 0 -1.57075" xyz="0 0 0.0273"/>
  </joint>
  <link name="SA011__MoJo__INPUT_INTERFACE">
    <visual>
      <origin rpy="1.57075 0 0" xyz="0 0 0.035"/>
      <geometry>
        <mesh filename="meshes/rotary_input.stl"/>
      </geometry>
      <material name="red">
        <color rgba=".82 0.06 0.06 1"/>
      </material>
    </visual>
    <collision>
      <origin rpy="0 0 0" xyz="0 0 0.0183"/>
      <geometry>
        <cylinder length="0.033" radius="0.026"/>
      </geometry>
    </collision>
    <inertial>
      <origin rpy="0 0 0" xyz="0 0 0.0366"/>
      <mass value="0.103"/>
      <inertia ixx="5.4796e-05" ixy="0" ixz="0" iyy="5.4796e-05" iyz="0" izz="3.4814e-05"/>
    </inertial>
  </link>
  <link name="SA011__MoJo__INPUT_INTERFACE__COLLAR">
    <visual>
      <origin rpy="0 0 0" xyz="0 0 0.005"/>
      <geometry>
        <cylinder length="0.01" radius="0.026"/>
      </geometry>
      <material name="black">
        <color rgba="0 0 0 1"/>
      </material>
    </visual>
    <inertial>
      <origin rpy="0 0 0" xyz="0 0 0"/>
      <mass value="0"/>
      <inertia ixx="0.0" ixy="0.0" ixz="0.0" iyy="0.0" iyz="0.0" izz="0.0"/>
    </inertial>
  </link> <!-- in pybullet, the inertia need to be specified even for dummy links, otherwise it will put an identity inertia and a mass of 1 by default -->
  <joint name="SA011__MoJo__INPUT_INTERFACE__COLLAR_JOINT" type="fixed">
    <parent link="SA011__MoJo__INPUT_INTERFACE"/>
    <child link="SA011__MoJo__INPUT_INTERFACE__COLLAR"/>
  </joint>
  <joint name="SA011__MoJo" type="revolute">
    <parent link="SA011__MoJo__INPUT_INTERFACE"/>
    <child link="SA011__MoJo__OUTPUT_BODY"/>
    <origin rpy="0 0 0" xyz="0 0 0.0366"/>
    <axis xyz="0 1 0"/>
    <dynamics damping=".1" friction="0.2"/>
    <limit effort="7.0" lower="-1.57" upper="1.57" velocity="2.208932"/>
  </joint>
  <transmission name="SA011__MoJo_trans">
    <type>transmission_interface/SimpleTransmission</type>
    <joint name="SA011__MoJo">
      <hardwareInterface>EffortJointInterface</hardwareInterface>
    </joint>
    <actuator name="SA011__MoJo_motor">
      <hardwareInterface>EffortJointInterface</hardwareInterface>
      <mechanicalReduction>300</mechanicalReduction>
    </actuator>
  </transmission>
  <link name="SA011__MoJo__OUTPUT_BODY">
    <visual>
      <origin rpy="1.57075 0 0" xyz="0 0 0"/>
      <geometry>
        <mesh filename="meshes/rotary_output.stl"/>
        <!-- <cylinder radius=".0025" length=".1" /> -->
      </geometry>
      <material name="red">
        <color rgba=".82 0.06 0.06 1"/>
      </material>
    </visual>
    <collision>
      <origin rpy="0 0 0" xyz="0 0 0.0183"/>
      <geometry>
        <cylinder length="0.033" radius="0.026"/>
      </geometry>
    </collision>
    <inertial>
      <origin rpy="0 0 0" xyz="0 0 0"/>
      <mass value="0.103"/>
      <inertia ixx="5.4796e-05" ixy="0" ixz="0" iyy="5.4796e-05" iyz="0" izz="3.4814e-05"/>
    </inertial>
  </link>
  <joint name="SA011__MoJo__OUTPUT_INTERFACE" type="fixed">
    <parent link="SA011__MoJo__OUTPUT_BODY"/>
    <child link="SA012__MoJo__INPUT_INTERFACE"/>
    <origin rpy="0 0 -1.57075" xyz="0 0 0.0273"/>
  </joint>
  <link name="SA012__MoJo__INPUT_INTERFACE">
    <visual>
      <origin rpy="1.57075 0 0" xyz="0 0 0.035"/>
      <geometry>
        <mesh filename="meshes/rotary_input.stl"/>
      </geometry>
      <material name="red">
        <color rgba=".82 0.06 0.06 1"/>
      </material>
    </visual>
    <collision>
      <origin rpy="0 0 0" xyz="0 0 0.0183"/>
      <geometry>
        <cylinder length="0.033" radius="0.026"/>
      </geometry>
    </collision>
    <inertial>
      <origin rpy="0 0 0" xyz="0 0 0.0366"/>
      <mass value="0.103"/>
      <inertia ixx="5.4796e-05" ixy="0" ixz="0" iyy="5.4796e-05" iyz="0" izz="3.4814e-05"/>
    </inertial>
  </link>
  <link name="SA012__MoJo__INPUT_INTERFACE__COLLAR">
    <visual>
      <origin rpy="0 0 0" xyz="0 0 0.005"/>
      <geometry>
        <cylinder length="0.01" radius="0.026"/>
      </geometry>
      <material name="black">
        <color rgba="0 0 0 1"/>
      </material>
    </visual>
    <inertial>
      <origin rpy="0 0 0" xyz="0 0 0"/>
      <mass value="0"/>
      <inertia ixx="0.0" ixy="0.0" ixz="0.0" iyy="0.0" iyz="0.0" izz="0.0"/>
    </inertial>
  </link> <!-- in pybullet, the inertia need to be specified even for dummy links, otherwise it will put an identity inertia and a mass of 1 by default -->
  <joint name="SA012__MoJo__INPUT_INTERFACE__COLLAR_JOINT" type="fixed">
    <parent link="SA012__MoJo__INPUT_INTERFACE"/>
    <child link="SA012__MoJo__INPUT_INTERFACE__COLLAR"/>
  </joint>
  <joint name="SA012__MoJo" type="revolute">
    <parent link="SA012__MoJo__INPUT_INTERFACE"/>
    <child link="SA012__MoJo__OUTPUT_BODY"/>
    <origin rpy="0 0 0" xyz="0 0 0.0366"/>
    <axis xyz="0 1 0"/>
    <dynamics damping=".1" friction="0.2"/>
    <limit effort="7.0" lower="-1.57" upper="1.57" velocity="2.208932"/>
  </joint>
  <transmission name="SA012__MoJo_trans">
    <type>transmission_interface/SimpleTransmission</type>
    <joint name="SA012__MoJo">
      <hardwareInterface>EffortJointInterface</hardwareInterface>
    </joint>
    <actuator name="SA012__MoJo_motor">
      <hardwareInterface>EffortJointInterface</hardwareInterface>
      <mechanicalReduction>300</mechanicalReduction>
    </actuator>
  </transmission>
  <link name="SA012__MoJo__OUTPUT_BODY">
    <visual>
      <origin rpy="1.57075 0 0" xyz="0 0 0"/>
      <geometry>
        <mesh filename="meshes/rotary_output.stl"/>
        <!-- <cylinder radius=".0025" length=".1" /> -->
      </geometry>
      <material name="red">
        <color rgba=".82 0.06 0.06 1"/>
      </material>
    </visual>
    <collision>
      <origin rpy="0 0 0" xyz="0 0 0.0183"/>
      <geometry>
        <cylinder length="0.033" radius="0.026"/>
      </geometry>
    </collision>
    <inertial>
      <origin rpy="0 0 0" xyz="0 0 0"/>
      <mass value="0.103"/>
      <inertia ixx="5.4796e-05" ixy="0" ixz="0" iyy="5.4796e-05" iyz="0" izz="3.4814e-05"/>
    </inertial>
  </link>
  <joint name="SA012__MoJo__OUTPUT_INTERFACE" type="fixed">
    <parent link="SA012__MoJo__OUTPUT_BODY"/>
    <child link="SA013__MoJo__INPUT_INTERFACE"/>
    <origin rpy="0 0 -1.57075" xyz="0 0 0.0273"/>
  </joint>
  <link name="SA013__MoJo__INPUT_INTERFACE">
    <visual>
      <origin rpy="1.57075 0 0" xyz="0 0 0.035"/>
      <geometry>
        <mesh filename="meshes/rotary_input.stl"/>
      </geometry>
      <material name="red">
        <color rgba=".82 0.06 0.06 1"/>
      </material>
    </visual>
    <collision>
      <origin rpy="0 0 0" xyz="0 0 0.0183"/>
      <geometry>
        <cylinder length="0.033" radius="0.026"/>
      </geometry>
    </collision>
    <inertial>
      <origin rpy="0 0 0" xyz="0 0 0.0366"/>
      <mass value="0.103"/>
      <inertia ixx="5.4796e-05" ixy="0" ixz="0" iyy="5.4796e-05" iyz="0" izz="3.4814e-05"/>
    </inertial>
  </link>
  <link name="SA013__MoJo__INPUT_INTERFACE__COLLAR">
    <visual>
      <origin rpy="0 0 0" xyz="0 0 0.005"/>
      <geometry>
        <cylinder length="0.01" radius="0.026"/>
      </geometry>
      <material name="black">
        <color rgba="0 0 0 1"/>
      </material>
    </visual>
    <inertial>
      <origin rpy="0 0 0" xyz="0 0 0"/>
      <mass value="0"/>
      <inertia ixx="0.0" ixy="0.0" ixz="0.0" iyy="0.0" iyz="0.0" izz="0.0"/>
    </inertial>
  </link> <!-- in pybullet, the inertia need to be specified even for dummy links, otherwise it will put an identity inertia and a mass of 1 by default -->
  <joint name="SA013__MoJo__INPUT_INTERFACE__COLLAR_JOINT" type="fixed">
    <parent link="SA013__MoJo__INPUT_INTERFACE"/>
    <child link="SA013__MoJo__INPUT_INTERFACE__COLLAR"/>
  </joint>
  <joint name="SA013__MoJo" type="revolute">
    <parent link="SA013__MoJo__INPUT_INTERFACE"/>
    <child link="SA013__MoJo__OUTPUT_BODY"/>
    <origin rpy="0 0 0" xyz="0 0 0.0366"/>
    <axis xyz="0 1 0"/>
    <dynamics damping=".1" friction="0.2"/>
    <limit effort="7.0" lower="-1.57" upper="1.57" velocity="2.208932"/>
  </joint>
  <transmission name="SA013__MoJo_trans">
    <type>transmission_interface/SimpleTransmission</type>
    <joint name="SA013__MoJo">
      <hardwareInterface>EffortJointInterface</hardwareInterface>
    </joint>
    <actuator name="SA013__MoJo_motor">
      <hardwareInterface>EffortJointInterface</hardwareInterface>
      <mechanicalReduction>300</mechanicalReduction>
    </actuator>
  </transmission>
  <link name="SA013__MoJo__OUTPUT_BODY">
    <visual>
      <origin rpy="1.57075 0 0" xyz="0 0 0"/>
      <geometry>
        <mesh filename="meshes/rotary_output.stl"/>
        <!-- <cylinder radius=".0025" length=".1" /> -->
      </geometry>
      <material name="red">
        <color rgba=".82 0.06 0.06 1"/>
      </material>
    </visual>
    <collision>
      <origin rpy="0 0 0" xyz="0 0 0.0183"/>
      <geometry>
        <cylinder length="0.033" radius="0.026"/>
      </geometry>
    </collision>
    <inertial>
      <origin rpy="0 0 0" xyz="0 0 0"/>
      <mass value="0.103"/>
      <inertia ixx="5.4796e-05" ixy="0" ixz="0" iyy="5.4796e-05" iyz="0" izz="3.4814e-05"/>
    </inertial>
  </link>
  <joint name="SA013__MoJo__OUTPUT_INTERFACE" type="fixed">
    <parent link="SA013__MoJo__OUTPUT_BODY"/>
    <child link="SA014__MoJo__INPUT_INTERFACE"/>
    <origin rpy="0 0 -1.57075" xyz="0 0 0.0273"/>
  </joint>
  <link name="SA014__MoJo__INPUT_INTERFACE">
    <visual>
      <origin rpy="1.57075 0 0" xyz="0 0 0.035"/>
      <geometry>
        <mesh filename="meshes/rotary_input.stl"/>
      </geometry>
      <material name="red">
        <color rgba=".82 0.06 0.06 1"/>
      </material>
    </visual>
    <collision>
      <origin rpy="0 0 0" xyz="0 0 0.0183"/>
      <geometry>
        <cylinder length="0.033" radius="0.026"/>
      </geometry>
    </collision>
    <inertial>
      <origin rpy="0 0 0" xyz="0 0 0.0366"/>
      <mass value="0.103"/>
      <inertia ixx="5.4796e-05" ixy="0" ixz="0" iyy="5.4796e-05" iyz="0" izz="3.4814e-05"/>
    </inertial>
  </link>
  <link name="SA014__MoJo__INPUT_INTERFACE__COLLAR">
    <visual>
      <origin rpy="0 0 0" xyz="0 0 0.005"/>
      <geometry>
        <cylinder length="0.01" radius="0.026"/>
      </geometry>
      <material name="black">
        <color rgba="0 0 0 1"/>
      </material>
    </visual>
    <inertial>
      <origin rpy="0 0 0" xyz="0 0 0"/>
      <mass value="0"/>
      <inertia ixx="0.0" ixy="0.0" ixz="0.0" iyy="0.0" iyz="0.0" izz="0.0"/>
    </inertial>
  </link> <!-- in pybullet, the inertia need to be specified even for dummy links, otherwise it will put an identity inertia and a mass of 1 by default -->
  <joint name="SA014__MoJo__INPUT_INTERFACE__COLLAR_JOINT" type="fixed">
    <parent link="SA014__MoJo__INPUT_INTERFACE"/>
    <child link="SA014__MoJo__INPUT_INTERFACE__COLLAR"/>
  </joint>
  <joint name="SA014__MoJo" type="revolute">
    <parent link="SA014__MoJo__INPUT_INTERFACE"/>
    <child link="SA014__MoJo__OUTPUT_BODY"/>
    <origin rpy="0 0 0" xyz="0 0 0.0366"/>
    <axis xyz="0 1 0"/>
    <dynamics damping=".1" friction="0.2"/>
    <limit effort="7.0" lower="-1.57" upper="1.57" velocity="2.208932"/>
  </joint>
  <transmission name="SA014__MoJo_trans">
    <type>transmission_interface/SimpleTransmission</type>
    <joint name="SA014__MoJo">
      <hardwareInterface>EffortJointInterface</hardwareInterface>
    </joint>
    <actuator name="SA014__MoJo_motor">
      <hardwareInterface>EffortJointInterface</hardwareInterface>
      <mechanicalReduction>300</mechanicalReduction>
    </actuator>
  </transmission>
  <link name="SA014__MoJo__OUTPUT_BODY">
    <visual>
      <origin rpy="1.57075 0 0" xyz="0 0 0"/>
      <geometry>
        <mesh filename="meshes/rotary_output.stl"/>
        <!-- <cylinder radius=".0025" length=".1" /> -->
      </geometry>
      <material name="red">
        <color rgba=".82 0.06 0.06 1"/>
      </material>
    </visual>
    <collision>
      <origin rpy="0 0 0" xyz="0 0 0.0183"/>
      <geometry>
        <cylinder length="0.033" radius="0.026"/>
      </geometry>
    </collision>
    <inertial>
      <origin rpy="0 0 0" xyz="0 0 0"/>
      <mass value="0.103"/>
      <inertia ixx="5.4796e-05" ixy="0" ixz="0" iyy="5.4796e-05" iyz="0" izz="3.4814e-05"/>
    </inertial>
  </link>
  <joint name="SA014__MoJo__OUTPUT_INTERFACE" type="fixed">
    <parent link="SA014__MoJo__OUTPUT_BODY"/>
    <child link="SA015__MoJo__INPUT_INTERFACE"/>
    <origin rpy="0 0 -1.57075" xyz="0 0 0.0273"/>
  </joint>
  <link name="SA015__MoJo__INPUT_INTERFACE">
    <visual>
      <origin rpy="1.57075 0 0" xyz="0 0 0.035"/>
      <geometry>
        <mesh filename="meshes/rotary_input.stl"/>
      </geometry>
      <material name="red">
        <color rgba=".82 0.06 0.06 1"/>
      </material>
    </visual>
    <collision>
      <origin rpy="0 0 0" xyz="0 0 0.0183"/>
      <geometry>
        <cylinder length="0.033" radius="0.026"/>
      </geometry>
    </collision>
    <inertial>
      <origin rpy="0 0 0" xyz="0 0 0.0366"/>
      <mass value="0.103"/>
      <inertia ixx="5.4796e-05" ixy="0" ixz="0" iyy="5.4796e-05" iyz="0" izz="3.4814e-05"/>
    </inertial>
  </link>
  <link name="SA015__MoJo__INPUT_INTERFACE__COLLAR">
    <visual>
      <origin rpy="0 0 0" xyz="0 0 0.005"/>
      <geometry>
        <cylinder length="0.01" radius="0.026"/>
      </geometry>
      <material name="black">
        <color rgba="0 0 0 1"/>
      </material>
    </visual>
    <inertial>
      <origin rpy="0 0 0" xyz="0 0 0"/>
      <mass value="0"/>
      <inertia ixx="0.0" ixy="0.0" ixz="0.0" iyy="0.0" iyz="0.0" izz="0.0"/>
    </inertial>
  </link> <!-- in pybullet, the inertia need to be specified even for dummy links, otherwise it will put an identity inertia and a mass of 1 by default -->
  <joint name="SA015__MoJo__INPUT_INTERFACE__COLLAR_JOINT" type="fixed">
    <parent link="SA015__MoJo__INPUT_INTERFACE"/>
    <child link="SA015__MoJo__INPUT_INTERFACE__COLLAR"/>
  </joint>
  <joint name="SA015__MoJo" type="revolute">
    <parent link="SA015__MoJo__INPUT_INTERFACE"/>
    <child link="SA015__MoJo__OUTPUT_BODY"/>
    <origin rpy="0 0 0" xyz="0 0 0.0366"/>
    <axis xyz="0 1 0"/>
    <dynamics damping=".1" friction="0.2"/>
    <limit effort="7.0" lower="-1.57" upper="1.57" velocity="2.208932"/>
  </joint>
  <transmission name="SA015__MoJo_trans">
    <type>transmission_interface/SimpleTransmission</type>
    <joint name="SA015__MoJo">
      <hardwareInterface>EffortJointInterface</hardwareInterface>
    </joint>
    <actuator name="SA015__MoJo_motor">
      <hardwareInterface>EffortJointInterface</hardwareInterface>
      <mechanicalReduction>300</mechanicalReduction>
    </actuator>
  </transmission>
  <link name="SA015__MoJo__OUTPUT_BODY">
    <visual>
      <origin rpy="1.57075 0 0" xyz="0 0 0"/>
      <geometry>
        <mesh filename="meshes/rotary_output.stl"/>
        <!-- <cylinder radius=".0025" length=".1" /> -->
      </geometry>
      <material name="red">
        <color rgba=".82 0.06 0.06 1"/>
      </material>
    </visual>
    <collision>
      <origin rpy="0 0 0" xyz="0 0 0.0183"/>
      <geometry>
        <cylinder length="0.033" radius="0.026"/>
      </geometry>
    </collision>
    <inertial>
      <origin rpy="0 0 0" xyz="0 0 0"/>
      <mass value="0.103"/>
      <inertia ixx="5.4796e-05" ixy="0" ixz="0" iyy="5.4796e-05" iyz="0" izz="3.4814e-05"/>
    </inertial>
  </link>
  <joint name="SA015__MoJo__OUTPUT_INTERFACE" type="fixed">
    <parent link="SA015__MoJo__OUTPUT_BODY"/>
    <child link="SA016__MoJo__INPUT_INTERFACE"/>
    <origin rpy="0 0 -1.57075" xyz="0 0 0.0273"/>
  </joint>
  <link name="SA016__MoJo__INPUT_INTERFACE">
    <visual>
      <origin rpy="1.57075 0 0" xyz="0 0 0.035"/>
      <geometry>
        <mesh filename="meshes/rotary_input.stl"/>
      </geometry>
      <material name="red">
        <color rgba=".82 0.06 0.06 1"/>
      </material>
    </visual>
    <collision>
      <origin rpy="0 0 0" xyz="0 0 0.0183"/>
      <geometry>
        <cylinder length="0.033" radius="0.026"/>
      </geometry>
    </collision>
    <inertial>
      <origin rpy="0 0 0" xyz="0 0 0.0366"/>
      <mass value="0.103"/>
      <inertia ixx="5.4796e-05" ixy="0" ixz="0" iyy="5.4796e-05" iyz="0" izz="3.4814e-05"/>
    </inertial>
  </link>
  <link name="SA016__MoJo__INPUT_INTERFACE__COLLAR">
    <visual>
      <origin rpy="0 0 0" xyz="0 0 0.005"/>
      <geometry>
        <cylinder length="0.01" radius="0.026"/>
      </geometry>
      <material name="black">
        <color rgba="0 0 0 1"/>
      </material>
    </visual>
    <inertial>
      <origin rpy="0 0 0" xyz="0 0 0"/>
      <mass value="0"/>
      <inertia ixx="0.0" ixy="0.0" ixz="0.0" iyy="0.0" iyz="0.0" izz="0.0"/>
    </inertial>
  </link> <!-- in pybullet, the inertia need to be specified even for dummy links, otherwise it will put an identity inertia and a mass of 1 by default -->
  <joint name="SA016__MoJo__INPUT_INTERFACE__COLLAR_JOINT" type="fixed">
    <parent link="SA016__MoJo__INPUT_INTERFACE"/>
    <child link="SA016__MoJo__INPUT_INTERFACE__COLLAR"/>
  </joint>
  <joint name="SA016__MoJo" type="revolute">
    <parent link="SA016__MoJo__INPUT_INTERFACE"/>
    <child link="SA016__MoJo__OUTPUT_BODY"/>
    <origin rpy="0 0 0" xyz="0 0 0.0366"/>
    <axis xyz="0 1 0"/>
    <dynamics damping=".1" friction="0.2"/>
    <limit effort="7.0" lower="-1.57" upper="1.57" velocity="2.208932"/>
  </joint>
  <transmission name="SA016__MoJo_trans">
    <type>transmission_interface/SimpleTransmission</type>
    <joint name="SA016__MoJo">
      <hardwareInterface>EffortJointInterface</hardwareInterface>
    </joint>
    <actuator name="SA016__MoJo_motor">
      <hardwareInterface>EffortJointInterface</hardwareInterface>
      <mechanicalReduction>300</mechanicalReduction>
    </actuator>
  </transmission>
  <link name="SA016__MoJo__OUTPUT_BODY">
    <visual>
      <origin rpy="1.57075 0 0" xyz="0 0 0"/>
      <geometry>
        <mesh filename="meshes/rotary_output.stl"/>
        <!-- <cylinder radius=".0025" length=".1" /> -->
      </geometry>
      <material name="red">
        <color rgba=".82 0.06 0.06 1"/>
      </material>
    </visual>
    <collision>
      <origin rpy="0 0 0" xyz="0 0 0.0183"/>
      <geometry>
        <cylinder length="0.033" radius="0.026"/>
      </geometry>
    </collision>
    <inertial>
      <origin rpy="0 0 0" xyz="0 0 0"/>
      <mass value="0.103"/>
      <inertia ixx="5.4796e-05" ixy="0" ixz="0" iyy="5.4796e-05" iyz="0" izz="3.4814e-05"/>
    </inertial>
  </link>
</robot>

