<?xml version="1.0" ?>
<!-- =================================================================================== -->
<!-- |    This document was autogenerated by xacro from jaco_robot.urdf.xacro          | -->
<!-- |    EDITING THIS FILE BY HAND IS NOT RECOMMENDED                                 | -->
<!-- =================================================================================== -->
<robot name="jaco_robot" xmlns:controller="http://playerstage.sourceforge.net/gazebo/xmlschema/#controller" xmlns:interface="http://playerstage.sourceforge.net/gazebo/xmlschema/#interface" xmlns:sensor="http://playerstage.sourceforge.net/gazebo/xmlschema/#sensor" xmlns:xacro="http://ros.org/wiki/xacro">
  <!--link name="robot_root">
  </link-->
  <!-- fake cylinder which is actually a box -->
  <!--xacro:macro name="cyl_inertia" params="mass r h ">
      <mass value="${mass}"/>
      <inertia
      ixx="${mass / 12.0 * (r*r + h*h)}" ixy="0.0" ixz="0.0"
      iyy="${mass / 12.0 * (h*h + r*r)}" iyz="0.0"
      izz="${mass / 12.0 * (r*r + r*r)}"/>
  </xacro:macro-->
  <!-- ***************** MODEL CORRECTIONS ************************* -->
  <!-- *************************************************************** -->
  <!-- from measurements, pitch is -0.2293 -->
  <!-- MODEL_FIX transforms from wrist to finger mounts -->
  <!--<xacro:property name="f_thb_m_xyz" value=" 0.037  0.001  0.106" />
  <xacro:property name="f_idx_m_xyz" value="-0.034  0.022 0.106" />
  <xacro:property name="f_pnk_m_xyz" value="-0.034 -0.022 0.106" />
  <xacro:property name="f_thb_m_rpy" value="0 -0.2658 ${M_PI-0.226892}" /> 
  <xacro:property name="f_idx_m_rpy" value="0 -0.2293 -0.191986" />
  <xacro:property name="f_pnk_m_rpy" value="0 -0.2293 0.191986" />-->
  <!--joint name="jaco_arm_joint" type="fixed">
    <origin rpy="0 0 0" xyz="0 0 0"/>
    <parent link="robot_root"/>
    <child link="jaco_0_baseA"/>
  </joint-->
  <!-- for some reason, material only applies if full name specified...
       these only seem to work in older gazebo versions -->
  <gazebo reference="jaco_ring_">
    <material>Gazebo/Grey</material>
    <implicitSpringDamper>1</implicitSpringDamper>
    <mu1>100000</mu1>
    <mu2>100000</mu2>
    <kp>100000000.0</kp>
    <kd>1.0</kd>
  </gazebo>
  <gazebo reference="_limb">
    <material>Gazebo/FlatBlack</material>
    <implicitSpringDamper>1</implicitSpringDamper>
    <mu1>100000</mu1>
    <mu2>100000</mu2>
    <kp>100000000.0</kp>
    <kd>1.0</kd>
  </gazebo>
  <gazebo reference="_finger">
    <material>Gazebo/Grey</material>
    <implicitSpringDamper>1</implicitSpringDamper>
    <mu1>100000</mu1>
    <mu2>100000</mu2>
    <kp>100000000.0</kp>
    <kd>1.0</kd>
  </gazebo>
  <!-- for some reason, material only applies if full name specified -->
  <gazebo reference="jaco_0_baseA">
    <material>Gazebo/White</material>
    <mu1>100000</mu1>
    <mu2>100000</mu2>
    <kp>100000000.0</kp>
    <kd>1.0</kd>
  </gazebo>
  <gazebo reference="jaco_0_baseB_limb">
    <material>Gazebo/FlatBlack</material>
    <mu1>100000</mu1>
    <mu2>100000</mu2>
    <kp>100000000.0</kp>
    <kd>1.0</kd>
  </gazebo>
  <gazebo reference="jaco_ring_1">
    <material>Gazebo/Grey</material>
    <mu1>100000</mu1>
    <mu2>100000</mu2>
    <kp>100000000.0</kp>
    <kd>1.0</kd>
  </gazebo>
  <gazebo reference="jaco_ring_2">
    <material>Gazebo/Grey</material>
    <mu1>100000</mu1>
    <mu2>100000</mu2>
    <kp>100000000.0</kp>
    <kd>1.0</kd>
  </gazebo>
  <gazebo reference="jaco_ring_3">
    <material>Gazebo/Grey</material>
    <mu1>100000</mu1>
    <mu2>100000</mu2>
    <kp>100000000.0</kp>
    <kd>1.0</kd>
  </gazebo>
  <gazebo reference="jaco_ring_4">
    <material>Gazebo/Grey</material>
    <mu1>100000</mu1>
    <mu2>100000</mu2>
    <kp>100000000.0</kp>
    <kd>1.0</kd>
  </gazebo>
  <gazebo reference="jaco_ring_5">
    <material>Gazebo/Grey</material>
    <mu1>100000</mu1>
    <mu2>100000</mu2>
    <kp>100000000.0</kp>
    <kd>1.0</kd>
  </gazebo>
  <gazebo reference="jaco_ring_6">
    <material>Gazebo/Grey</material>
    <mu1>100000</mu1>
    <mu2>100000</mu2>
    <kp>100000000.0</kp>
    <kd>1.0</kd>
  </gazebo>
  <gazebo reference="jaco_1_shoulder_limb">
    <material>Gazebo/FlatBlack</material>
    <mu1>100000</mu1>
    <mu2>100000</mu2>
    <kp>100000000.0</kp>
    <kd>1.0</kd>
  </gazebo>
  <gazebo reference="jaco_2_upperarm_limb">
    <material>Gazebo/FlatBlack</material>
    <mu1>100000</mu1>
    <mu2>100000</mu2>
    <kp>100000000.0</kp>
    <kd>1.0</kd>
  </gazebo>
  <gazebo reference="jaco_3_forearm_limb">
    <material>Gazebo/FlatBlack</material>
    <mu1>100000</mu1>
    <mu2>100000</mu2>
    <kp>100000000.0</kp>
    <kd>1.0</kd>
  </gazebo>
  <gazebo reference="jaco_4_upperwrist_limb">
    <material>Gazebo/FlatBlack</material>
    <mu1>100000</mu1>
    <mu2>100000</mu2>
    <kp>100000000.0</kp>
    <kd>1.0</kd>
  </gazebo>
  <gazebo reference="jaco_5_lowerwrist_limb">
    <material>Gazebo/FlatBlack</material>
    <mu1>100000</mu1>
    <mu2>100000</mu2>
    <kp>100000000.0</kp>
    <kd>1.0</kd>
  </gazebo>
  <gazebo reference="jaco_6_hand_limb">
    <material>Gazebo/FlatBlack</material>
    <mu1>100000</mu1>
    <mu2>100000</mu2>
    <kp>100000000.0</kp>
    <kd>1.0</kd>
  </gazebo>
  <gazebo reference="jaco_fingers_base_link">
    <material>Gazebo/FlatBlack</material>
    <mu1>100000</mu1>
    <mu2>100000</mu2>
    <kp>100000000.0</kp>
    <kd>1.0</kd>
  </gazebo>
  <gazebo reference="jaco_7_finger_mount_index">
    <material>Gazebo/FlatBlack</material>
    <mu1>100000</mu1>
    <mu2>100000</mu2>
    <kp>100000000.0</kp>
    <kd>1.0</kd>
  </gazebo>
  <gazebo reference="jaco_7_finger_mount_thumb">
    <material>Gazebo/FlatBlack</material>
    <mu1>100000</mu1>
    <mu2>100000</mu2>
    <kp>100000000.0</kp>
    <kd>1.0</kd>
  </gazebo>
  <gazebo reference="jaco_7_finger_mount_pinkie">
    <material>Gazebo/FlatBlack</material>
    <mu1>100000</mu1>
    <mu2>100000</mu2>
    <kp>100000000.0</kp>
    <kd>1.0</kd>
  </gazebo>
  <gazebo reference="jaco_8_finger_thumb">
    <material>Gazebo/Grey</material>
    <mu1>100000</mu1>
    <mu2>100000</mu2>
    <kp>100000000.0</kp>
    <kd>1.0</kd>
  </gazebo>
  <gazebo reference="jaco_8_finger_index">
    <material>Gazebo/Grey</material>
    <mu1>100000</mu1>
    <mu2>100000</mu2>
    <kp>100000000.0</kp>
    <kd>1.0</kd>
  </gazebo>
  <gazebo reference="jaco_8_finger_pinkie">
    <material>Gazebo/Grey</material>
    <mu1>100000</mu1>
    <mu2>100000</mu2>
    <kp>100000000.0</kp>
    <kd>1.0</kd>
  </gazebo>
  <gazebo reference="jaco_9_finger_thumb_tip">
    <material>Gazebo/Grey</material>
    <mu1>100000</mu1>
    <mu2>100000</mu2>
    <kp>100000000.0</kp>
    <kd>1.0</kd>
  </gazebo>
  <gazebo reference="jaco_9_finger_index_tip">
    <material>Gazebo/Grey</material>
    <mu1>100000</mu1>
    <mu2>100000</mu2>
    <kp>100000000.0</kp>
    <kd>1.0</kd>
  </gazebo>
  <gazebo reference="jaco_9_finger_pinkie_tip">
    <material>Gazebo/Grey</material>
    <mu1>100000</mu1>
    <mu2>100000</mu2>
    <kp>100000000.0</kp>
    <kd>1.0</kd>
  </gazebo>
  <gazebo reference="jaco_finger_joint_0">
    <provideFeedback value="true"/>
  </gazebo>
  <gazebo reference="jaco_finger_joint_2">
    <provideFeedback value="true"/>
  </gazebo>
  <gazebo reference="jaco_finger_joint_4">
    <provideFeedback value="true"/>
  </gazebo>
  <link name="jaco_0_baseA">
    <inertial>
      <origin rpy="0 0 0" xyz="0 0 0.03"/>
      <mass value="0.5688"/>
      <inertia ixx="0.000349289202838" ixy="0" ixz="0" iyy="0.000349289202838" iyz="0" izz="0.0003685824"/>
    </inertial>
    <visual>
      <origin rpy="0 0 0" xyz="0 0 0"/>
      <geometry>
        <mesh filename="meshes/0_baseA.STL" scale="0.98 0.98 0.98"/>
      </geometry>
      <material name="light_grey">
        <color rgba="0.65 0.65 0.66 1"/>
      </material>
    </visual>
    <collision>
      <origin rpy="0 0 0" xyz="0 0 0"/>
      <geometry>
        <mesh filename="meshes/0_baseA.STL"/>
      </geometry>
    </collision>
  </link>
  <!-- ...........................        -->
  <link name="jaco_0_baseB_limb">
    <inertial>
      <origin rpy="0 0 0" xyz="0 0.04725 0"/>
      <mass value="0.5152"/>
      <inertia ixx="0.000589483042058" ixy="0" ixz="0" iyy="0.000589483042058" iyz="0" izz="0.00041216"/>
    </inertial>
    <visual>
      <origin rpy="0 0 0" xyz="0 0 0"/>
      <geometry>
        <mesh filename="meshes/0_baseB_limb.STL"/>
      </geometry>
      <material name="black">
        <color rgba="0.10 0.10 0.10 1"/>
      </material>
    </visual>
    <collision>
      <origin rpy="0 0 0" xyz="0 0 0"/>
      <geometry>
        <mesh filename="meshes/0_baseB_limb.STL"/>
      </geometry>
    </collision>
  </link>
  <joint name="jaco_base_internal" type="fixed">
    <origin rpy="1.57079632679 0 0" xyz="0 0 0.049"/>
    <parent link="jaco_0_baseA"/>
    <child link="jaco_0_baseB_limb"/>
    <axis xyz="0 0 0"/>
  </joint>
  <link name="jaco_ring_1">
    <inertial>
      <origin rpy="0 0 0" xyz="-3.57503886452221E-16 -1.58125151997128E-15 -5.55111512312578E-17"/>
      <mass value="0.00872"/>
      <inertia ixx="3.778651552e-06" ixy="0" ixz="0" iyy="3.778651552e-06" iyz="0" izz="6.976e-06"/>
    </inertial>
    <visual>
      <origin rpy="0 0 0" xyz="0 0 0"/>
      <geometry>
        <mesh filename="meshes/ring_1.STL"/>
      </geometry>
      <material name="grey">
        <color rgba="0.50 0.50 0.50 1"/>
      </material>
    </visual>
    <collision>
      <origin rpy="0 0 0" xyz="0 0 0"/>
      <geometry>
        <mesh filename="meshes/ring_1.STL"/>
      </geometry>
    </collision>
  </link>
  <joint name="jaco_ring_1_joint" type="fixed">
    <origin rpy="-1.57079632679 0.211499083190217 -3.14159265359" xyz="0 0.104 0"/>
    <parent link="jaco_0_baseB_limb"/>
    <child link="jaco_ring_1"/>
    <axis xyz="0 0 0"/>
  </joint>
  <!-- ...........................        -->
  <link name="jaco_1_shoulder_limb">
    <inertial>
      <origin rpy="0 0 0" xyz="0.0120470281905243 0.0657132437750733 0"/>
      <mass value="0.4782"/>
      <inertia ixx="0.00119872305509" ixy="0" ixz="0" iyy="0.00119872305509" iyz="0" izz="0.00038256"/>
    </inertial>
    <visual>
      <origin rpy="0 0 0" xyz="0 0 0"/>
      <geometry>
        <mesh filename="meshes/1_shoulder_limb.STL"/>
      </geometry>
      <material name="black">
        <color rgba="0.10 0.10 0.10 1"/>
      </material>
    </visual>
    <!--     <visual>
      <origin xyz="0 0 0" rpy="0 0 0" />
      <geometry>
        <sphere radius="0.005"/>
      </geometry>
      <material name="">
        <color rgba="0.10 0.10 0.10 1" />
      </material>
    </visual>
-->
    <collision>
      <origin rpy="0 0 0" xyz="0 0 0"/>
      <geometry>
        <mesh filename="meshes/1_shoulder_limb.STL"/>
      </geometry>
    </collision>
  </link>
  <joint name="jaco_arm_0_joint" type="continuous">
    <limit effort="8" velocity="1.0"/>
    <dynamics damping="0.5" friction="0.5"/>
    <origin rpy="0 1.57079632679 0" xyz="0 0.104 0"/>
    <parent link="jaco_0_baseB_limb"/>
    <child link="jaco_1_shoulder_limb"/>
    <axis xyz="0 1 0"/>
  </joint>
  <!-- ...........................        -->
  <link name="jaco_ring_2">
    <inertial>
      <origin rpy="0 0 0" xyz="0 0 0"/>
      <mass value="0.00872"/>
      <inertia ixx="3.778651552e-06" ixy="0" ixz="0" iyy="3.778651552e-06" iyz="0" izz="6.976e-06"/>
    </inertial>
    <visual>
      <origin rpy="0 0 0" xyz="-0.0005 -0.003 -0.001"/>
      <geometry>
        <mesh filename="meshes/ring_2.STL"/>
      </geometry>
      <material name="grey">
        <color rgba="0.50 0.50 0.50 1"/>
      </material>
    </visual>
    <collision>
      <origin rpy="0 0 0" xyz="-0.0005 -0.003 -0.001"/>
      <geometry>
        <mesh filename="meshes/ring_2.STL"/>
      </geometry>
    </collision>
  </link>
  <joint name="jaco_ring_2_joint" type="fixed">
    <origin rpy="-1.57079632679488 -1.49007956532211 1.57079632679488" xyz="0 0.1225 0"/>
    <parent link="jaco_1_shoulder_limb"/>
    <child link="jaco_ring_2"/>
    <axis xyz="0 0 0"/>
  </joint>
  <!-- ...........................        -->
  <link name="jaco_2_upperarm_limb">
    <inertial>
      <origin rpy="0 0 0" xyz="0.206003857152394 0 -0.0343672381612413"/>
      <mass value="1.37163"/>
      <inertia ixx="0.0282672380881" ixy="0" ixz="0" iyy="0.0282672380881" iyz="0" izz="0.001646641815"/>
    </inertial>
    <visual>
      <origin rpy="0 0 0" xyz="-0.003 -0.001 -0.001"/>
      <geometry>
        <mesh filename="meshes/2_upperarm_limb.STL"/>
      </geometry>
      <material name="black">
        <color rgba="0.10 0.10 0.10 1"/>
      </material>
    </visual>
    <!--     <visual>
      <origin xyz="0 0 0" rpy="0 0 0" />
      <geometry>
        <sphere radius="0.005"/>
      </geometry>
      <material name="">
        <color rgba="0.10 0.10 0.10 1" />
      </material>
    </visual>
-->
    <collision>
      <origin rpy="0 0 0" xyz="-0.003 -0.001 -0.001"/>
      <geometry>
        <mesh filename="meshes/2_upperarm_limb.STL"/>
      </geometry>
    </collision>
  </link>
  <joint name="jaco_arm_1_joint" type="revolute">
    <dynamics damping="0.5" friction="0.5"/>
    <limit effort="8" lower="-3.943" upper="0.81" velocity="1.0"/>
    <origin rpy="3.14159265359 -1.57079632679 0" xyz="0 0.1225 0"/>
    <parent link="jaco_1_shoulder_limb"/>
    <child link="jaco_2_upperarm_limb"/>
    <axis xyz="0 0 1"/>
  </joint>
  <!-- ...........................        -->
  <link name="jaco_ring_3">
    <inertial>
      <origin rpy="0 0 0" xyz="0 0 0"/>
      <mass value="0.00872"/>
      <inertia ixx="3.778651552e-06" ixy="0" ixz="0" iyy="3.778651552e-06" iyz="0" izz="6.976e-06"/>
    </inertial>
    <visual>
      <origin rpy="0 0 0" xyz="0.001 0 0"/>
      <geometry>
        <mesh filename="meshes/ring_3.STL"/>
      </geometry>
      <material name="grey">
        <color rgba="0.5 0.5 0.5 1"/>
      </material>
    </visual>
    <collision>
      <origin rpy="0 0 0" xyz="0.001 0 0"/>
      <geometry>
        <mesh filename="meshes/ring_3.STL"/>
      </geometry>
    </collision>
  </link>
  <joint name="jaco_ring_3_joint" type="fixed">
    <origin rpy="3.14159265359 0 -3.14159265359" xyz="0.41 0 0"/>
    <parent link="jaco_2_upperarm_limb"/>
    <child link="jaco_ring_3"/>
    <axis xyz="0 0 0"/>
  </joint>
  <!-- ........................... -->
  <link name="jaco_3_forearm_limb">
    <inertial>
      <origin rpy="0 0 0" xyz="0.0857562490792731 1.94295959371482E-06 0.0203407295609686"/>
      <mass value="0.67592919"/>
      <inertia ixx="0.00340683847249" ixy="0" ixz="0" iyy="0.00340683847249" iyz="0" izz="0.000324783975795"/>
    </inertial>
    <visual>
      <origin rpy="0 0 0" xyz="0 0 0"/>
      <geometry>
        <mesh filename="meshes/3_forearm_limb.STL"/>
      </geometry>
      <material name="black">
        <color rgba="0.1 0.1 0.1 1"/>
      </material>
    </visual>
    <!--     <visual>
      <origin xyz="0 0 0" rpy="0 0 0" />
      <geometry>
        <sphere radius="0.005"/>
      </geometry>
      <material name="">
        <color rgba="0.10 0.10 0.10 1" />
      </material>
    </visual>
-->
    <collision>
      <origin rpy="0 0 0" xyz="0 0 0"/>
      <geometry>
        <mesh filename="meshes/3_forearm_limb.STL"/>
      </geometry>
    </collision>
  </link>
  <joint name="jaco_arm_2_joint" type="revolute">
    <limit effort="4" lower="-4.395" upper="1.252" velocity="1.0"/>
    <dynamics damping="0.5" friction="0.5"/>
    <origin rpy="0 0 1.57079632679489" xyz="0.41 0 0"/>
    <parent link="jaco_2_upperarm_limb"/>
    <child link="jaco_3_forearm_limb"/>
    <axis xyz="0 0 1"/>
  </joint>
  <!-- ...........................        -->
  <link name="jaco_ring_4">
    <inertial>
      <origin rpy="0 0 0" xyz="0 0 0"/>
      <mass value="0.00676534123969"/>
      <inertia ixx="2.11472445691e-06" ixy="0" ixz="0" iyy="2.11472445691e-06" iyz="0" izz="3.68372830501e-06"/>
    </inertial>
    <visual>
      <origin rpy="0 0 0" xyz="0 0 0"/>
      <geometry>
        <mesh filename="meshes/ring_4.STL"/>
      </geometry>
      <material name="grey">
        <color rgba="0.5 0.5 0.5 1"/>
      </material>
    </visual>
    <collision>
      <origin rpy="0 0 0" xyz="0 0 0"/>
      <geometry>
        <mesh filename="meshes/ring_4.STL"/>
      </geometry>
    </collision>
  </link>
  <joint name="jaco_ring_4_joint" type="fixed">
    <origin rpy="3.14159265359 -1.57079632679 0" xyz="0.2073 0 0.0098"/>
    <parent link="jaco_3_forearm_limb"/>
    <child link="jaco_ring_4"/>
    <axis xyz="-1 0 0"/>
  </joint>
  <!-- ...........................        -->
  <link name="jaco_4_upperwrist_limb">
    <inertial>
      <origin rpy="0 0 0" xyz="-0.0371070560898082 -0.00912675248782567 -2.44092722145872E-08"/>
      <mass value="0.24550336286"/>
      <inertia ixx="0.000272235953438" ixy="0" ixz="0" iyy="0.000272235953438" iyz="0" izz="0.000135301813339"/>
    </inertial>
    <visual>
      <origin rpy="0 0 0" xyz="0 0 0"/>
      <geometry>
        <mesh filename="meshes/4_upperwrist_limb.STL"/>
      </geometry>
      <material name="black">
        <color rgba="0.1 0.1 0.1 1"/>
      </material>
    </visual>
    <!--     <visual>
      <origin xyz="0 0 0" rpy="0 0 0" />
      <geometry>
        <sphere radius="0.005"/>
      </geometry>
      <material name="">
        <color rgba="0.10 0.10 0.10 1" />
      </material>
    </visual>
-->
    <collision>
      <origin rpy="0 0 0" xyz="0 0 0"/>
      <geometry>
        <mesh filename="meshes/4_upperwrist_limb.STL"/>
      </geometry>
    </collision>
  </link>
  <joint name="jaco_arm_3_joint" type="continuous">
    <limit effort="1.5" velocity="1.0"/>
    <dynamics damping="0.05" friction="0.05"/>
    <origin rpy="-1.57079632679484 0 -3.14159265358951" xyz="0.2073 0 0.0098"/>
    <parent link="jaco_3_forearm_limb"/>
    <child link="jaco_4_upperwrist_limb"/>
    <axis xyz="-1 0 0"/>
  </joint>
  <!-- ...........................        -->
  <link name="jaco_ring_5">
    <inertial>
      <origin rpy="0 0 0" xyz="-1.54831009124834E-13 4.27435864480685E-15 -2.58654209162046E-13"/>
      <mass value="0.00676534123969"/>
      <inertia ixx="2.11472445691e-06" ixy="0" ixz="0" iyy="2.11472445691e-06" iyz="0" izz="3.68372830501e-06"/>
    </inertial>
    <visual>
      <origin rpy="0 0 0" xyz="0 0 0"/>
      <geometry>
        <mesh filename="meshes/ring_5.STL"/>
      </geometry>
      <material name="grey">
        <color rgba="0.5 0.5 0.5 1"/>
      </material>
    </visual>
    <collision>
      <origin rpy="0 0 0" xyz="0 0 0"/>
      <geometry>
        <mesh filename="meshes/ring_5.STL"/>
      </geometry>
    </collision>
  </link>
  <joint name="jaco_ring_5_joint" type="fixed">
    <origin rpy="-1.57079632679506 0 -0.610865238196312" xyz="-0.06590490 -0.034307921 0"/>
    <parent link="jaco_4_upperwrist_limb"/>
    <child link="jaco_ring_5"/>
    <axis xyz="-1 0 0"/>
  </joint>
  <!-- ...........................        -->
  <link name="jaco_5_lowerwrist_limb">
    <inertial>
      <origin rpy="0 0 0" xyz="-0.0176083455436658 -0.00912672231835664 -5.99117305766228E-09"/>
      <mass value="0.2455"/>
      <inertia ixx="0.0002722322244" ixy="0" ixz="0" iyy="0.0002722322244" iyz="0" izz="0.00013529996"/>
    </inertial>
    <visual>
      <origin rpy="0 0 0" xyz="-0.01715 0 0"/>
      <geometry>
        <mesh filename="meshes/5_lowerwrist_limb.STL"/>
      </geometry>
      <material name="black">
        <color rgba="0.1 0.1 0.1 1"/>
      </material>
    </visual>
    <!--     <visual>
      <origin xyz="0 0 0" rpy="0 0 0" />
      <geometry>
        <sphere radius="0.005"/>
      </geometry>
      <material name="">
        <color rgba="0.10 0.10 0.10 1" />
      </material>
    </visual>
-->
    <collision>
      <origin rpy="0 0 0" xyz="-0.01715 0 0"/>
      <geometry>
        <mesh filename="meshes/5_lowerwrist_limb.STL"/>
      </geometry>
    </collision>
  </link>
  <joint name="jaco_arm_4_joint" type="continuous">
    <limit effort="1.0" velocity="1.0"/>
    <dynamics damping="0.05" friction="0.05"/>
    <!-- caluclated form DH-Parameter documentation. An iscoceles triangle with tip angle 55 degrees has base angles (gamma) 62.5.
       Base has length 74.3. Then sin(gamma)=y/74.3 and cos(gamma)=x/74.3, hence y=65.90590 and x=34.307921963  -->
    <origin rpy="0 0 0.959931089" xyz="-0.06590490 -0.034307921 0"/>
    <parent link="jaco_4_upperwrist_limb"/>
    <child link="jaco_5_lowerwrist_limb"/>
    <axis xyz="-1 0 0"/>
  </joint>
  <!-- ...........................        -->
  <link name="jaco_ring_6">
    <inertial>
      <origin rpy="0 0 0" xyz="2.12629684692711E-10 7.53045514834128E-10 3.03666577994299E-10"/>
      <mass value="0.00676"/>
      <inertia ixx="2.11305488108e-06" ixy="0" ixz="0" iyy="2.11305488108e-06" iyz="0" izz="3.68082e-06"/>
    </inertial>
    <visual>
      <origin rpy="0 0 0" xyz="-0.001 0 0"/>
      <geometry>
        <mesh filename="meshes/ring_6.STL"/>
      </geometry>
      <material name="grey">
        <color rgba="0.5 0.5 0.5 1"/>
      </material>
    </visual>
    <collision>
      <origin rpy="0 0 0" xyz="-0.001 0 0"/>
      <geometry>
        <mesh filename="meshes/ring_6.STL"/>
      </geometry>
    </collision>
  </link>
  <joint name="jaco_ring_6_joint" type="fixed">
    <origin rpy="1.57079632679 0 2.53072741539211 " xyz="-0.06590490 -0.034307921 0"/>
    <parent link="jaco_5_lowerwrist_limb"/>
    <child link="jaco_ring_6"/>
    <axis xyz="0 0 0"/>
  </joint>
  <!-- ...........................        -->
  <link name="jaco_6_hand_limb">
    <inertial>
      <origin rpy="0 0 0" xyz="-0.0555917045329114 -7.25586546752172E-05 -0.00317411883668722"/>
      <mass value="0.2"/>
      <inertia ixx="0.0007852635256" ixy="0" ixz="0" iyy="0.0007852635256" iyz="0" izz="0.00121"/>
    </inertial>
    <visual>
      <origin rpy="0 0 0" xyz="0 0 0"/>
      <geometry>
        <mesh filename="meshes/6_hand_limb.STL" scale="1.0 1.0 1.0"/>
      </geometry>
      <material name="black">
        <color rgba="0.1 0.1 0.1 1"/>
      </material>
    </visual>
    <!--     <visual>
      <origin xyz="0 0 0" rpy="0 0 0" />
      <geometry>
        <sphere radius="0.005"/>
      </geometry>
      <material name="">
        <color rgba="0.10 0.10 0.10 1" />
      </material>
    </visual>
-->
    <collision>
      <origin rpy="0 0 0" xyz="0 0 0"/>
      <geometry>
        <mesh filename="meshes/6_hand_limb.STL" scale="1.0 1.0 1.0"/>
      </geometry>
    </collision>
  </link>
  <joint name="jaco_arm_5_joint" type="continuous">
    <limit effort="1.0" velocity="1.0"/>
    <dynamics damping="0.05" friction="0.05"/>
    <!-- added some experimental angle changes to the arm wrist, as this was not accurate .. tried to touch the base with the hand, and it didn't look the same
    in rviz. I tuned the values so rviz would show same position. However, it's likely this can be better fine tuned -->
    <origin rpy="-1.57079632679 0 0.959931089" xyz="-0.06590490 -0.034307921 0"/>
    <parent link="jaco_5_lowerwrist_limb"/>
    <child link="jaco_6_hand_limb"/>
    <axis xyz="-1 0 0"/>
  </joint>
  <link name="jaco_fingers_base_link">
    <inertial>
      <origin rpy="0 0 0" xyz="0 0 0"/>
      <mass value="0.001"/>
      <inertia ixx="3.33332e-08" ixy="0" ixz="0" iyy="3.33332e-08" iyz="0" izz="5e-08"/>
    </inertial>
  </link>
  <!-- this joint is only to align the coordinate system with the kinova specification frame -->
  <joint name="jaco_fingers_base_joint" type="fixed">
    <origin rpy="-1.57079632679 3.14159265359 1.57079632679" xyz="0 0 0"/>
    <parent link="jaco_6_hand_limb"/>
    <child link="jaco_fingers_base_link"/>
  </joint>
  <!-- ...........................  -->
  <!--      FINGERS          -->
  <!-- ...........................  -->
  <link name="jaco_7_finger_mount_index">
    <inertial>
      <origin rpy="0 0 0" xyz="0 0.00706399246397285 -0.00176078508424846"/>
      <mass value="0.006465"/>
      <inertia ixx="7.8441686232e-07" ixy="0" ixz="0" iyy="7.8441686232e-07" iyz="0" izz="1.04733e-06"/>
    </inertial>
    <visual>
      <origin rpy="1.57079632679 0 1.57079632679" xyz="0 0 0"/>
      <geometry>
        <mesh filename="meshes/7_finger_mount_index.STL"/>
      </geometry>
      <material name="grey">
        <color rgba="0.5 0.5 0.5 1"/>
      </material>
    </visual>
    <collision>
      <origin rpy="1.57079632679 0 1.57079632679" xyz="0 0 0"/>
      <geometry>
        <mesh filename="meshes/7_finger_mount_index.STL"/>
      </geometry>
    </collision>
  </link>
  <joint name="jaco_finger_mount_index_fixed" type="fixed">
    <!--- remark 2014: damping greater than 0.1 (0.2) lead to model break downs when testing it bit by bit -->
    <!--- remark jan 2016: damping and friction higher than 0.005 required very high forces in order for the fingers
              to move at all, and then they mooved only slowly. -->
    <!--dynamics damping="0.1" friction="1.0"/-->
    <dynamics damping="0.005" friction="0.005"/>
    <origin rpy="0 -0.2293 -0.191986" xyz="-0.034  0.022 0.095"/>
    <parent link="jaco_fingers_base_link"/>
    <child link="jaco_7_finger_mount_index"/>
    <axis xyz="0 0 0"/>
  </joint>
  <!-- ...........................        -->
  <link name="jaco_8_finger_index">
    <inertial>
      <origin rpy="0 0 0" xyz="-0.0181403689626489 0 0.00272470933850985"/>
      <mass value="0.01845"/>
      <inertia ixx="6.37560262249e-06" ixy="0" ixz="0" iyy="6.37560262249e-06" iyz="0" izz="1.68125625e-06"/>
    </inertial>
    <!--     <visual>
      <origin xyz="0 0 0" rpy="0 0 0" />
      <geometry>
        <sphere radius="0.005"/>
      </geometry>
      <material name="">
        <color rgba="0.10 0.10 0.10 1" />
      </material>
    </visual>
-->
    <visual>
      <origin rpy="3.14159265359 1.1780972445 0" xyz="0 0 0"/>
      <geometry>
        <mesh filename="meshes/8_finger_index.STL"/>
      </geometry>
      <material name="grey">
        <color rgba="0.50 0.50 0.50 1"/>
      </material>
    </visual>
    <collision>
      <origin rpy="3.14159265359 1.1780972445 0" xyz="0 0 0"/>
      <geometry>
        <mesh filename="meshes/8_finger_index.STL"/>
      </geometry>
    </collision>
  </link>
  <joint name="jaco_finger_joint_0" type="revolute">
    <!--- remark 2014: damping greater than 0.1 (0.2) lead to model break downs when testing it bit by bit -->
    <!--- remark jan 2016: damping and friction higher than 0.005 required very high forces in order for the fingers
              to move at all, and then they mooved only slowly. -->
    <!--dynamics damping="0.1" friction="1.0"/-->
    <dynamics damping="0.005" friction="0.005"/>
    <origin rpy="0 -0.34 -0.191986" xyz="-0.0276  0.0204 0.11"/>
    <parent link="jaco_fingers_base_link"/>
    <child link="jaco_8_finger_index"/>
    <axis xyz="0 1 0"/>
    <limit effort="1.5" lower="-0.0045" upper="1.05" velocity="0.2"/>
  </joint>
  <!-- ...........................        -->
  <link name="jaco_9_finger_index_tip">
    <inertial>
      <origin rpy="0 0 0" xyz="-0.01340812509202 -4.52693266978291E-07 0.0118561361126153"/>
      <mass value="0.0122"/>
      <inertia ixx="2.6850059266e-06" ixy="0" ixz="0" iyy="2.6850059266e-06" iyz="0" izz="8.784e-07"/>
    </inertial>
    <!--     <visual>
      <origin xyz="0 0 0" rpy="0 0 0" />
      <geometry>
        <sphere radius="0.005"/>
      </geometry>
      <material name="">
        <color rgba="0.10 0.10 0.10 1" />
      </material>
    </visual>
-->
    <visual>
      <origin rpy="0 1.57079632679 3.14159265359" xyz="0 0 0"/>
      <geometry>
        <mesh filename="meshes/9_finger_index_tip.STL" scale="1 1 1"/>
      </geometry>
      <material name="grey">
        <color rgba="0.5 0.5 0.5 1"/>
      </material>
    </visual>
    <collision>
      <origin rpy="0 1.57079632679 3.14159265359" xyz="0 0 0"/>
      <geometry>
        <mesh filename="meshes/9_finger_index_tip.STL" scale="1 1 1"/>
      </geometry>
    </collision>
  </link>
  <joint name="jaco_finger_joint_1" type="fixed">
    <!--- remark 2014: damping greater than 0.1 (0.2) lead to model break downs when testing it bit by bit -->
    <!--- remark jan 2016: damping and friction higher than 0.005 required very high forces in order for the fingers
              to move at all, and then they mooved only slowly. -->
    <!--dynamics damping="0.1" friction="1.0"/-->
    <dynamics damping="0.005" friction="0.005"/>
    <origin rpy="0 0 0" xyz="0 0 0.0441"/>
    <parent link="jaco_8_finger_index"/>
    <child link="jaco_9_finger_index_tip"/>
  </joint>
  <!-- ...........................        -->
  <link name="jaco_7_finger_mount_thumb">
    <inertial>
      <origin rpy="0 0 0" xyz="-2.65251193937339E-07 0.00706398229186052 -0.00176078674955921"/>
      <mass value="0.006465"/>
      <inertia ixx="7.8441686232e-07" ixy="0" ixz="0" iyy="7.8441686232e-07" iyz="0" izz="1.04733e-06"/>
    </inertial>
    <visual>
      <origin rpy="1.57079632679 0 1.57079632679" xyz="0 0 0"/>
      <geometry>
        <mesh filename="meshes/7_finger_mount_thumb.STL"/>
      </geometry>
      <material name="grey">
        <color rgba="0.50 0.50 0.50 1"/>
      </material>
    </visual>
    <collision>
      <origin rpy="1.57079632679 0 1.57079632679" xyz="0 0 0"/>
      <geometry>
        <mesh filename="meshes/7_finger_mount_thumb.STL"/>
      </geometry>
    </collision>
  </link>
  <joint name="jaco_finger_mount_thumb_fixed" type="fixed">
    <!--- remark 2014: damping greater than 0.1 (0.2) lead to model break downs when testing it bit by bit -->
    <!--- remark jan 2016: damping and friction higher than 0.005 required very high forces in order for the fingers
              to move at all, and then they mooved only slowly. -->
    <!--dynamics damping="0.1" friction="1.0"/-->
    <dynamics damping="0.005" friction="0.005"/>
    <origin rpy="0 -0.2658 2.91470065359" xyz=" 0.037  0.001  0.095"/>
    <parent link="jaco_fingers_base_link"/>
    <child link="jaco_7_finger_mount_thumb"/>
  </joint>
  <!-- ...........................        -->
  <link name="jaco_8_finger_thumb">
    <inertial>
      <origin rpy="0 0 0" xyz="-0.0181403317517619 -3.13818432741766E-07 0.00272473343106584"/>
      <mass value="0.0184"/>
      <inertia ixx="6.3583245666e-06" ixy="0" ixz="0" iyy="6.3583245666e-06" iyz="0" izz="1.6767e-06"/>
    </inertial>
    <!--     <visual>
      <origin xyz="0 0 0" rpy="0 0 0" />
      <geometry>
        <sphere radius="0.005"/>
      </geometry>
      <material name="">
        <color rgba="0.10 0.10 0.10 1" />
      </material>
    </visual>
-->
    <visual>
      <origin rpy="3.14159265359 1.1780972445 0" xyz="0 0 0"/>
      <geometry>
        <mesh filename="meshes/8_finger_thumb.STL"/>
      </geometry>
      <material name="grey">
        <color rgba="0.5 0.5 0.5 1"/>
      </material>
    </visual>
    <collision>
      <origin rpy="3.14159265359 1.1780972445 0" xyz="0 0 0"/>
      <geometry>
        <mesh filename="meshes/8_finger_thumb.STL"/>
      </geometry>
    </collision>
  </link>
  <joint name="jaco_finger_joint_2" type="revolute">
    <!--- remark 2014: damping greater than 0.1 (0.2) lead to model break downs when testing it bit by bit -->
    <!--- remark jan 2016: damping and friction higher than 0.005 required very high forces in order for the fingers
              to move at all, and then they mooved only slowly. -->
    <!--dynamics damping="0.1" friction="1.0"/-->
    <dynamics damping="0.005" friction="0.005"/>
    <origin rpy="0 -0.37 2.91470065359" xyz=" 0.0319  0.003  0.11"/>
    <parent link="jaco_fingers_base_link"/>
    <child link="jaco_8_finger_thumb"/>
    <axis xyz="0 1 0"/>
    <limit effort="1.5" lower="-0.0045" upper="1.05" velocity="0.2"/>
  </joint>
  <!-- ...........................        -->
  <link name="jaco_9_finger_thumb_tip">
    <inertial>
      <origin rpy="0 0 0" xyz="-0.0134080639046228 -4.56622786070351E-07 0.0118561154422042"/>
      <mass value="0.0122"/>
      <inertia ixx="2.6850059266e-06" ixy="0" ixz="0" iyy="2.6850059266e-06" iyz="0" izz="8.784e-07"/>
    </inertial>
    <visual>
      <origin rpy="0 1.57079632679 3.14159265359" xyz="0 0 0"/>
      <geometry>
        <mesh filename="meshes/9_finger_thumb_tip.STL" scale="1 1 1"/>
      </geometry>
      <material name="grey">
        <color rgba="0.5 0.5 0.5 1"/>
      </material>
    </visual>
    <collision>
      <origin rpy="0 1.57079632679 3.14159265359" xyz="0 0 0"/>
      <geometry>
        <mesh filename="meshes/9_finger_thumb_tip.STL" scale="1 1 1"/>
      </geometry>
    </collision>
  </link>
  <joint name="jaco_finger_joint_3" type="fixed">
    <!--- remark 2014: damping greater than 0.1 (0.2) lead to model break downs when testing it bit by bit -->
    <!--- remark jan 2016: damping and friction higher than 0.005 required very high forces in order for the fingers
              to move at all, and then they mooved only slowly. -->
    <!--dynamics damping="0.1" friction="1.0"/-->
    <dynamics damping="0.005" friction="0.005"/>
    <origin rpy="0 0 0" xyz="0 0 0.0441"/>
    <parent link="jaco_8_finger_thumb"/>
    <child link="jaco_9_finger_thumb_tip"/>
  </joint>
  <!-- ...........................        -->
  <link name="jaco_7_finger_mount_pinkie">
    <inertial>
      <origin rpy="0 0 0" xyz="0 0.00706399455294665 -0.00176077690193762"/>
      <mass value="0.00646"/>
      <inertia ixx="7.8381019808e-07" ixy="0" ixz="0" iyy="7.8381019808e-07" iyz="0" izz="1.04652e-06"/>
    </inertial>
    <visual>
      <origin rpy="1.57079632679 0 1.57079632679" xyz="0 0 0"/>
      <geometry>
        <mesh filename="meshes/7_finger_mount_pinkie.STL"/>
      </geometry>
      <material name="grey">
        <color rgba="0.5 0.5 0.5 1"/>
      </material>
    </visual>
    <collision>
      <origin rpy="1.57079632679 0 1.57079632679" xyz="0 0 0"/>
      <geometry>
        <mesh filename="meshes/7_finger_mount_pinkie.STL"/>
      </geometry>
    </collision>
  </link>
  <joint name="jaco_finger_mount_pinkie_fixed" type="fixed">
    <!--- remark 2014: damping greater than 0.1 (0.2) lead to model break downs when testing it bit by bit -->
    <!--- remark jan 2016: damping and friction higher than 0.005 required very high forces in order for the fingers
              to move at all, and then they mooved only slowly. -->
    <!--dynamics damping="0.1" friction="1.0"/-->
    <dynamics damping="0.005" friction="0.005"/>
    <origin rpy="0 -0.2293 0.191986" xyz="-0.034 -0.022 0.095"/>
    <parent link="jaco_fingers_base_link"/>
    <child link="jaco_7_finger_mount_pinkie"/>
  </joint>
  <!-- ...........................        -->
  <link name="jaco_8_finger_pinkie">
    <inertial>
      <origin rpy="0 0 0" xyz="-0.0181404164708055 -2.87009015777565E-07 0.00272467774606585"/>
      <mass value="0.01845"/>
      <inertia ixx="6.37560262249e-06" ixy="0" ixz="0" iyy="6.37560262249e-06" iyz="0" izz="1.68125625e-06"/>
    </inertial>
    <!--     <visual>
      <origin xyz="0 0 0" rpy="0 0 0" />
      <geometry>
        <sphere radius="0.005"/>
      </geometry>
      <material name="">
        <color rgba="0.10 0.10 0.10 1" />
      </material>
    </visual>
-->
    <visual>
      <origin rpy="3.14159265359 1.1780972445 0" xyz="0 0 0"/>
      <geometry>
        <mesh filename="meshes/8_finger_pinkie.STL"/>
      </geometry>
      <material name="grey">
        <color rgba="0.5 0.5 0.5 1"/>
      </material>
    </visual>
    <collision>
      <origin rpy="3.14159265359 1.1780972445 0" xyz="0 0 0"/>
      <geometry>
        <mesh filename="meshes/8_finger_pinkie.STL"/>
      </geometry>
    </collision>
  </link>
  <joint name="jaco_finger_joint_4" type="revolute">
    <!--- remark 2014: damping greater than 0.1 (0.2) lead to model break downs when testing it bit by bit -->
    <!--- remark jan 2016: damping and friction higher than 0.005 required very high forces in order for the fingers
              to move at all, and then they mooved only slowly. -->
    <!--dynamics damping="0.1" friction="1.0"/-->
    <dynamics damping="0.005" friction="0.005"/>
    <origin rpy="0 -0.34 0.191986" xyz="-0.0276 -0.0204 0.11"/>
    <parent link="jaco_fingers_base_link"/>
    <child link="jaco_8_finger_pinkie"/>
    <axis xyz="0 1 0"/>
    <limit effort="1.5" lower="-0.0045" upper="1.05" velocity="0.2"/>
  </joint>
  <!-- ...........................        -->
  <link name="jaco_9_finger_pinkie_tip">
    <inertial>
      <origin rpy="0 0 0" xyz="-0.0134 0 0.01185"/>
      <mass value="0.0122"/>
      <inertia ixx="2.6850059266e-06" ixy="0" ixz="0" iyy="2.6850059266e-06" iyz="0" izz="8.784e-07"/>
    </inertial>
    <visual>
      <origin rpy="0 1.57079632679 3.14159265359" xyz="0 0 0"/>
      <geometry>
        <mesh filename="meshes/9_finger_pinkie_tip.STL" scale="1 1 1"/>
      </geometry>
      <material name="grey">
        <color rgba="0.5 0.5 0.5 1"/>
      </material>
    </visual>
    <collision>
      <origin rpy="0 1.57079632679 3.14159265359" xyz="0 0 0"/>
      <geometry>
        <mesh filename="meshes/9_finger_pinkie_tip.STL" scale="1 1 1"/>
      </geometry>
    </collision>
  </link>
  <joint name="jaco_finger_joint_5" type="fixed">
    <!--- remark 2014: damping greater than 0.1 (0.2) lead to model break downs when testing it bit by bit -->
    <!--- remark jan 2016: damping and friction higher than 0.005 required very high forces in order for the fingers
              to move at all, and then they mooved only slowly. -->
    <!--dynamics damping="0.1" friction="1.0"/-->
    <dynamics damping="0.005" friction="0.005"/>
    <origin rpy="0 0 0" xyz="0 0 0.0441"/>
    <parent link="jaco_8_finger_pinkie"/>
    <child link="jaco_9_finger_pinkie_tip"/>
  </joint>
</robot>

