<?xml version="1.0" ?>
<!-- =================================================================================== -->
<!-- |    This document was autogenerated by xacro from cogimon.urdf.xacro             | -->
<!-- |    EDITING THIS FILE BY HAND IS NOT RECOMMENDED                                 | -->
<!-- =================================================================================== -->
<robot name="cogimon" xmlns:xacro="http://ros.org/wiki/xacro">
  <!-- 
  ROS urdf definition of the COGIMON humanoid robot by Istituto Italiano di Tecnologia
  
  DO NOT INCLUDE THIS FILE DIRECTLY! USE cogimon_robot.urdf.xacro INSTEAD!

  Author: Enrico Mingo

  Inertial matrix has to be in CoM frame (URDF specs)
-->
  <material name="grey">
    <color rgba="0.5 0.5 0.5 1"/>
  </material>
  <material name="dark_grey">
    <color rgba="0.3 0.3 0.3 1"/>
  </material>
  <material name="red">
    <color rgba="1.0 0.0 0.0 1"/>
  </material>
  <material name="green">
    <color rgba="0.0 1.0 0.0 1"/>
  </material>
  <!-- Head -->
  <!-- This links are defined in order to be compliant with http://www.ros.org/reps/rep-0120.html#coordinate-frames
and to define the end effectors of the robot.
The coordinate frame called gaze defines the head position and orientation. The orientation indicates in which direction the head appears to be looking regardless of any sensors (camera for instance). -->
  <!--link name="gaze"/>

	<joint name="gaze_joint" type="fixed">
		<parent link="torso"/>
		<child link="gaze"/>
		<origin xyz="0 0 0.1" rpy="0 0 0" />
	</joint-->
  <!-- NECK -->
  <!--xacro:include filename="$(find cogimon_urdf)/urdf/parts/neck.urdf.xacro" /-->
  <!-- 
  ROS urdf definition of the COGIMON humanoid robot by Istituto Italiano di Tecnologia
  
  DO NOT INCLUDE THIS FILE DIRECTLY! USE cogimon_robot.urdf.xacro INSTEAD!

  Author: Enrico Mingo Hoffman

  Inertial matrix has to be in CoM frame (URDF specs)

-->
  <!-- This links are defined in order to be compliant with http://www.ros.org/reps/rep-0120.html#coordinate-frames
and to define the end effectors of the robot

The coordinate frame called base_link is rigidly attached to the robot root body. It is recommended to choose the robot waist as its root body. The base_link can be attached to the root in any arbitrary position or orientation; for every hardware platform there will be a different place on the base that provides an obvious point of reference. Note that REP 103 [1] specifies a preferred orientation for frames. -->
  <!--link name="base_link"/--> <!-- if you put mass/inertia to 0 for the base_link in pybullet then the robot will not be affected by gravity (i.e. it will float). Just removing the base_link fixes the problem. -->
  <link name="Waist">
    <inertial>
      <origin rpy="0.0 0.0 0.0" xyz="-0.056796324 0.00045196345 -0.038136153"/>
      <mass value="3.4599462"/>
      <inertia ixx="0.038130318" ixy="9.5451056e-05" ixz="-8.2481481e-05" iyy="0.0089760596" iyz="9.1637353e-06" izz="0.039650845"/>
    </inertial>
    <visual>
      <origin rpy="0 0 0" xyz="0 0 0"/>
      <material name="dark_grey"/>
      <geometry name="Waist_visual">
        <mesh filename="meshes/Waist.stl" scale="0.001 0.001 0.001"/>
      </geometry>
    </visual>
    <collision>
      <origin rpy="0 0 0" xyz="0 0 0"/>
      <geometry name="Waist_collision">
        <mesh filename="meshes/simple/Waist.stl" scale="0.001 0.001 0.001"/>
      </geometry>
    </collision>
  </link>
  <!--joint name="base_joint" type="fixed">
    <parent link="base_link"/>
    <child link="Waist"/>
    <origin rpy="0 0 0" xyz="0 0 0"/>
  </joint-->
  <joint name="imu_joint" type="fixed">
    <parent link="Waist"/>
    <child link="imu_link"/>
    <origin rpy="0 0 0" xyz="-0.146332 0 -0.03875"/>
  </joint>
  <link name="imu_link">
    <inertial>
      <mass value="0.01"/>
      <origin xyz="0 0 0"/>
      <inertia ixx="1.0E-6" ixy="0" ixz="0" iyy="1.0E-6" iyz="0" izz="1.0E-6"/>
    </inertial>
    <visual>
      <origin rpy="0 0 0" xyz="0 0 0"/>
      <geometry>
        <box size="0.01 0.01 0.01"/>
      </geometry>
    </visual>
  </link>
  <!-- LINKS -->
  <link name="LHipMot">
    <inertial>
      <origin rpy="0 0 0" xyz="-0.041435899 -0.00024099021 -0.067437774"/>
      <mass value="2.0936467"/>
      <inertia ixx="0.010806924" ixy="3.3743172e-05" ixz="-0.0013329083" iyy="0.011288691" iyz="5.6918305e-05" izz="0.0053916798"/>
    </inertial>
    <visual>
      <origin rpy="0 0 0." xyz="0. 0. 0."/>
      <material name="green"/>
      <geometry name="RHipMot_visual">
        <mesh filename="meshes/HipRoll.stl" scale="0.001 0.001 0.001"/>
      </geometry>
    </visual>
    <collision>
      <origin rpy="0 0 0." xyz="0.0 0. 0"/>
      <geometry name="RHipMot_collision">
        <mesh filename="meshes/simple/HipRoll.stl" scale="0.001 0.001 0.001"/>
      </geometry>
    </collision>
  </link>
  <link name="LThighUpLeg">
    <inertial>
      <origin rpy="0 0 0" xyz="0.00058688639 -0.062440385 -0.085057072"/>
      <mass value="1.6115687"/>
      <inertia ixx="0.016169151" ixy="-2.1886129e-05" ixz="6.0058109e-05" iyy="0.0144378" iyz="-0.0027173225" izz="0.0039254506"/>
    </inertial>
    <visual>
      <origin rpy="0 0 0." xyz="0. 0. 0."/>
      <material name="dark_grey"/>
      <geometry name="LThighUpLeg_visual">
        <mesh filename="meshes/HipPitch.stl" scale="0.001 0.001 0.001"/>
      </geometry>
    </visual>
    <collision>
      <origin rpy="0 0 0." xyz="0.0 0. 0"/>
      <geometry name="LThighUpLeg_collision">
        <mesh filename="meshes/simple/HipPitch.stl" scale="0.001 0.001 0.001"/>
      </geometry>
    </collision>
  </link>
  <link name="LThighLowLeg">
    <inertial>
      <origin rpy="0 0 0" xyz="-0.02113641 -0.0042862386 -0.038232267"/>
      <mass value="1.7454681"/>
      <inertia ixx="0.0059857438" ixy="-4.0155441e-05" ixz="-0.00080168603" iyy="0.0066483492" iyz="-0.00011435964" izz="0.0044665032"/>
    </inertial>
    <visual>
      <origin rpy="0 0 0." xyz="0. 0. 0."/>
      <material name="green"/>
      <geometry name="LThighLowLeg_visual">
        <mesh filename="meshes/HipYaw.stl" scale="0.001 0.001 0.001"/>
      </geometry>
    </visual>
    <collision>
      <origin rpy="0 0 0." xyz="0.0 0. 0"/>
      <geometry name="LThighLowLeg_collision">
        <mesh filename="meshes/simple/HipYaw.stl" scale="0.001 0.001 0.001"/>
      </geometry>
    </collision>
  </link>
  <link name="LLowLeg">
    <inertial>
      <origin rpy="0 0 0" xyz="0.027363015 -0.05780207 -0.19306454"/>
      <mass value="3.7014912"/>
      <inertia ixx="0.064669769" ixy="0.00036914631" ixz="0.0053710941" iyy="0.063323486" iyz="-0.0027319883" izz="0.0081842652"/>
    </inertial>
    <visual>
      <origin rpy="0 0 0." xyz="0. 0. 0."/>
      <material name="dark_grey"/>
      <geometry name="LLowLeg_visual">
        <mesh filename="meshes/KneePitch.stl" scale="0.001 0.001 0.001"/>
      </geometry>
    </visual>
    <collision>
      <origin rpy="0 0 0." xyz="0.0 0. 0"/>
      <geometry name="LLowLeg_collision">
        <mesh filename="meshes/simple/KneePitch.stl" scale="0.001 0.001 0.001"/>
      </geometry>
    </collision>
  </link>
  <link name="LFootmot">
    <inertial>
      <origin rpy="0 0 0" xyz="0.0011213007 0.00046152281 -1.144967e-06"/>
      <mass value="1.7723821e-01"/>
      <inertia ixx="2.8142035e-05" ixy="9.1715528e-08" ixz="-2.1701012e-10" iyy="9.7378402e-05" iyz="3.7303915e-10" izz="0.00011570584"/>
    </inertial>
    <visual>
      <origin rpy="0 0 0" xyz="0 0 0"/>
      <geometry name="LFootmot_visual">
        <mesh filename="meshes/AnklePitch.stl" scale="0.001 0.001 0.001"/>
      </geometry>
      <material name="dark_grey"/>
    </visual>
    <collision>
      <origin rpy="0 0 0" xyz="0 0 0"/>
      <geometry name="LFootmot_collision">
        <mesh filename="meshes/simple/AnklePitch.stl" scale="0.001 0.001 0.001"/>
      </geometry>
    </collision>
  </link>
  <link name="LFoot">
    <inertial>
      <origin rpy="0 0 0" xyz="-0.0077094563 -6.5520742e-05 -0.043453782"/>
      <mass value="2.0663292"/>
      <inertia ixx="0.0026932116" ixy="4.2852647e-06" ixz="0.00037001167" iyy="0.0071293752" iyz="-2.5956611e-06" izz="0.0086807822"/>
    </inertial>
    <visual>
      <origin rpy="0 0 0" xyz="0 0 0"/>
      <geometry name="LFoot_visual">
        <mesh filename="meshes/Foot2.stl" scale="0.001 0.001 0.001"/>
      </geometry>
      <material name="dark_grey"/>
    </visual>
    <collision>
      <origin rpy="0 0 0" xyz="0.0 0.0 -0.061"/>
      <geometry>
        <box size="0.21 0.11 0.015"/>
      </geometry>
    </collision>
  </link>
  <!-- JOINTS -->
  <joint name="LHipLat" type="revolute">
    <parent link="Waist"/>
    <child link="LHipMot"/>
    <origin rpy="0 0 0" xyz="0.01545 0.112 -0.05"/>
    <axis xyz="1 0 0"/>
    <limit effort="200" lower="-0.523598775598" upper="1.65806278939" velocity="7.4"/>
    <dynamics damping="3.0" friction="0"/>
  </joint>
  <joint name="LHipSag" type="revolute">
    <parent link="LHipMot"/>
    <child link="LThighUpLeg"/>
    <origin rpy="0 0 0" xyz="-0.059 0.07865 -0.1185"/>
    <axis xyz="0 1 0"/>
    <limit effort="200" lower="-1.91986217719" upper="1.55334303428" velocity="7.4"/>
    <dynamics damping="3.0" friction="0"/>
  </joint>
  <joint name="LHipYaw" type="revolute">
    <parent link="LThighUpLeg"/>
    <child link="LThighLowLeg"/>
    <origin rpy="0 0 0" xyz="0.0 -0.09 -0.25645"/>
    <axis xyz="0 0 1"/>
    <limit effort="120" lower="-0.558505360638" upper="1.5707963268" velocity="4.6"/>
    <dynamics damping="3.0" friction="0"/>
  </joint>
  <joint name="LKneePitch" type="revolute">
    <parent link="LThighLowLeg"/>
    <child link="LLowLeg"/>
    <origin rpy="0 0 0" xyz="-0.039 0.0641 -0.0607"/>
    <axis xyz="0 1 0"/>
    <limit effort="200" lower="0.0" upper="2.44346095279" velocity="5.5"/>
    <dynamics damping="3.0" friction="0"/>
  </joint>
  <!-- Here we do an assumption: Ankle Pitch can go -50/+40 while Ankle Roll -15/+15-->
  <joint name="LAnklePitch" type="revolute">
    <parent link="LLowLeg"/>
    <child link="LFootmot"/>
    <origin rpy="0 0 0" xyz="0.039 -0.0616 -0.425294"/>
    <axis xyz="0 1 0"/>
    <limit effort="200" lower="-0.872664625997" upper="0.698131700798" velocity="4.9"/>
    <dynamics damping="0.1" friction="0"/>
  </joint>
  <joint name="LAnkleRoll" type="revolute">
    <parent link="LFootmot"/>
    <child link="LFoot"/>
    <origin rpy="0 0 0" xyz="0 0 0"/>
    <axis xyz="1 0 0"/>
    <limit effort="60" lower="-0.261799387799" upper="0.261799387799" velocity="3.2"/>
    <dynamics damping="3.0" friction="0"/>
  </joint>
  <!-- LINKS -->
  <link name="RHipMot">
    <inertial>
      <origin rpy="0 0 0" xyz="-0.041435899 0.00024099021 -0.067437774"/>
      <mass value="2.0936467"/>
      <inertia ixx="0.010806924" ixy="-3.3743172e-05" ixz="-0.0013329083" iyy="0.011288691" iyz="-5.6918305e-05" izz="0.0053916798"/>
    </inertial>
    <visual>
      <origin rpy="0 0 0" xyz="0.0 0 0"/>
      <material name="green"/>
      <geometry name="RHipMot_visual">
        <mesh filename="meshes/HipRoll.stl" scale="0.001 -0.001 0.001"/>
      </geometry>
    </visual>
    <collision>
      <origin rpy="0 0 0." xyz="0.0 0. 0"/>
      <geometry name="RHipMot_collision">
        <mesh filename="meshes/simple/HipRoll.stl" scale="0.001 -0.001 0.001"/>
      </geometry>
    </collision>
  </link>
  <link name="RThighUpLeg">
    <inertial>
      <origin rpy="0 0 0" xyz="0.00058688639 0.062440385 -0.085057072"/>
      <mass value="1.6115687"/>
      <inertia ixx="0.016169151" ixy="2.1886129e-05" ixz="6.0058109e-05" iyy="0.0144378" iyz="0.0027173225" izz="0.0039254506"/>
    </inertial>
    <visual>
      <origin rpy="0 0 0." xyz="0. 0. 0."/>
      <material name="dark_grey"/>
      <geometry name="RThighUpLeg_visual">
        <mesh filename="meshes/HipPitch.stl" scale="0.001 -0.001 0.001"/>
      </geometry>
    </visual>
    <collision>
      <origin rpy="0 0 0." xyz="0.0 0. 0"/>
      <geometry name="RThighUpLeg_collision">
        <mesh filename="meshes/simple/HipPitch.stl" scale="0.001 -0.001 0.001"/>
      </geometry>
    </collision>
  </link>
  <link name="RThighLowLeg">
    <inertial>
      <origin rpy="0 0 0" xyz="-0.02113641 0.0042862386 -0.038232267"/>
      <mass value="1.7454681"/>
      <inertia ixx="0.0059857438" ixy="4.0155441e-05" ixz="-0.00080168603" iyy="0.0066483492" iyz="0.00011435964" izz="0.0044665032"/>
    </inertial>
    <visual>
      <origin rpy="0 0 0." xyz="0. 0. 0."/>
      <material name="green"/>
      <geometry name="RThighLowLeg_visual">
        <mesh filename="meshes/HipYaw.stl" scale="0.001 -0.001 0.001"/>
      </geometry>
    </visual>
    <collision>
      <origin rpy="0 0 0." xyz="0.0 0. 0"/>
      <geometry name="RThighLowLeg_collision">
        <mesh filename="meshes/simple/HipYaw.stl" scale="0.001 -0.001 0.001"/>
      </geometry>
    </collision>
  </link>
  <link name="RLowLeg">
    <inertial>
      <origin rpy="0 0 0" xyz="0.027363015 0.05780207 -0.19306454"/>
      <mass value="3.7014912"/>
      <inertia ixx="0.064669769" ixy="-0.00036914631" ixz="0.0053710941" iyy="0.063323486" iyz="0.0027319883" izz="0.0081842652"/>
    </inertial>
    <visual>
      <origin rpy="0 0 0." xyz="0. 0. 0."/>
      <material name="dark_grey"/>
      <geometry name="RLowLeg_visual">
        <mesh filename="meshes/KneePitch.stl" scale="0.001 -0.001 0.001"/>
      </geometry>
    </visual>
    <collision>
      <origin rpy="0 0 0." xyz="0.0 0. 0"/>
      <geometry name="RLowLeg_collision">
        <mesh filename="meshes/simple/KneePitch.stl" scale="0.001 -0.001 0.001"/>
      </geometry>
    </collision>
  </link>
  <link name="RFootmot">
    <inertial>
      <origin rpy="0 0 0" xyz="0.0011213007 0.00046152281 -1.144967e-06"/>
      <mass value="1.7723821e-01"/>
      <inertia ixx="2.8142035e-05" ixy="9.1715528e-08" ixz="-2.1701012e-10" iyy="9.7378402e-05" iyz="3.7303915e-10" izz="0.00011570584"/>
    </inertial>
    <visual>
      <origin rpy="0 0 0" xyz="0 0 0"/>
      <geometry name="RFootmot_visual">
        <mesh filename="meshes/AnklePitch.stl" scale="0.001 0.001 0.001"/>
      </geometry>
      <material name="dark_grey"/>
    </visual>
    <collision>
      <origin rpy="0 0 0" xyz="0 0 0"/>
      <geometry name="RFootmot_collision">
        <mesh filename="meshes/simple/AnklePitch.stl" scale="0.001 0.001 0.001"/>
      </geometry>
    </collision>
  </link>
  <link name="RFoot">
    <inertial>
      <origin rpy="0 0 0" xyz="-0.0077094563 -6.5520742e-05 -0.043453782"/>
      <mass value="2.0663292"/>
      <inertia ixx="0.0026932116" ixy="4.2852647e-06" ixz="0.00037001167" iyy="0.0071293752" iyz="-2.5956611e-06" izz="0.0086807822"/>
    </inertial>
    <visual>
      <origin rpy="0 0 0" xyz="0 0 0"/>
      <geometry name="LFoot_visual">
        <mesh filename="meshes/Foot2.stl" scale="0.001 0.001 0.001"/>
      </geometry>
      <material name="dark_grey"/>
    </visual>
    <collision>
      <origin rpy="0 0 0" xyz="0.0 0.0 -0.061"/>
      <geometry>
        <box size="0.21 0.11 0.015"/>
      </geometry>
    </collision>
  </link>
  <!-- JOINTS -->
  <joint name="RHipLat" type="revolute">
    <parent link="Waist"/>
    <child link="RHipMot"/>
    <origin rpy="0 0 0" xyz="0.01545 -0.112 -0.05"/>
    <axis xyz="1 0 0"/>
    <limit effort="200" lower="-1.65806278939" upper="0.523598775598" velocity="7.4"/>
    <dynamics damping="3.0" friction="0"/>
  </joint>
  <joint name="RHipSag" type="revolute">
    <parent link="RHipMot"/>
    <child link="RThighUpLeg"/>
    <origin rpy="0 0 0" xyz="-0.059 -0.07865 -0.1185"/>
    <axis xyz="0 1 0"/>
    <limit effort="200" lower="-1.91986217719" upper="1.55334303428" velocity="7.4"/>
    <dynamics damping="3.0" friction="0"/>
  </joint>
  <joint name="RHipYaw" type="revolute">
    <parent link="RThighUpLeg"/>
    <child link="RThighLowLeg"/>
    <origin rpy="0 0 0" xyz="0.0 0.09 -0.25645"/>
    <axis xyz="0 0 1"/>
    <limit effort="120" lower="-1.5707963268" upper="0.558505360638" velocity="4.9"/>
    <dynamics damping="3.0" friction="0"/>
  </joint>
  <joint name="RKneePitch" type="revolute">
    <parent link="RThighLowLeg"/>
    <child link="RLowLeg"/>
    <origin rpy="0 0 0" xyz="-0.039 -0.0641 -0.0607"/>
    <axis xyz="0 1 0"/>
    <limit effort="200" lower="0.0" upper="2.44346095279" velocity="5.5"/>
    <dynamics damping="3.0" friction="0"/>
  </joint>
  <!-- Here we do an assumption: Ankle Pitch can go -50/+40 while Ankle Roll -15/+15-->
  <joint name="RAnklePitch" type="revolute">
    <parent link="RLowLeg"/>
    <child link="RFootmot"/>
    <origin rpy="0 0 0" xyz="0.039 0.0616 -0.425294"/>
    <axis xyz="0 1 0"/>
    <limit effort="200" lower="-0.872664625997" upper="0.698131700798" velocity="4.9"/>
    <dynamics damping="0.1" friction="0"/>
  </joint>
  <joint name="RAnkleRoll" type="revolute">
    <parent link="RFootmot"/>
    <child link="RFoot"/>
    <origin rpy="0 0 0" xyz="0 0 0"/>
    <axis xyz="1 0 0"/>
    <limit effort="60" lower="-0.261799387799" upper="0.261799387799" velocity="3.2"/>
    <dynamics damping="3.0" friction="0"/>
  </joint>
  <!-- weight position -->
  <!-- LINKS -->
  <link name="DWL">
    <inertial>
      <origin rpy="0 0 0" xyz="0.039412845 0.00031221526 0.0056331027 "/>
      <mass value="7.4182685e-01"/>
      <inertia ixx="0.00094437073" ixy="4.8511769e-06" ixz="0.00010757639" iyy="0.0015988107" iyz="-1.104754e-05" izz="0.0015042997"/>
    </inertial>
    <visual>
      <origin rpy="0 0 0" xyz="0.0 0.0 0.0"/>
      <geometry name="DWL_visual">
        <mesh filename="meshes/TorsoRoll.stl" scale="0.001 0.001 0.001"/>
      </geometry>
      <material name="dark_grey"/>
    </visual>
    <collision>
      <origin rpy="0 0 0" xyz="0.0 0.0 0.0"/>
      <geometry name="DWL_collision">
        <mesh filename="meshes/simple/TorsoRoll.stl" scale="0.001 0.001 0.001"/>
      </geometry>
    </collision>
  </link>
  <link name="DWLExt">
    <inertial>
      <origin rpy="0 0 0" xyz="1.5386429e-06 5.166843e-05 0.095210134 "/>
      <mass value="9.6910635e-01"/>
      <inertia ixx="0.003041487" ixy="-2.8413688e-06" ixz="9.6851038e-05" iyy="0.0030465319" iyz="-8.8025302e-06" izz="0.0015978729"/>
    </inertial>
    <visual>
      <origin rpy="0 0 0" xyz="0.0 0.0 0.0"/>
      <geometry name="DWLExt_visual">
        <mesh filename="meshes/TorsoRollExt.stl" scale="0.001 0.001 0.001"/>
      </geometry>
      <material name="green"/>
    </visual>
    <collision>
      <origin rpy="0 0 0" xyz="0.0 0.0 0.0"/>
      <geometry name="DWLExt_collision">
        <mesh filename="meshes/simple/TorsoRollExt.stl" scale="0.001 0.001 0.001"/>
      </geometry>
    </collision>
  </link>
  <link name="DWYTorso">
    <inertial>
      <origin rpy="0 0 0" xyz="-0.059646212 0.0014305062 0.042741527"/>
      <mass value="1.2512295e+01"/>
      <inertia ixx="0.21021617" ixy="-0.00015527214" ixz="-0.050216602" iyy="0.19982996" iyz="-0.00029204792" izz="0.14025094"/>
    </inertial>
    <visual>
      <origin rpy="0 0 0" xyz="0.0 0.0 0.0"/>
      <geometry name="DWYTorso_visual">
        <mesh filename="meshes/Chest.stl" scale="0.001 0.001 0.001"/>
      </geometry>
      <material name="dark_grey"/>
    </visual>
    <collision>
      <origin rpy="0 0 0" xyz="0.0 0.0 0.0"/>
      <geometry name="DWYTorso_collision">
        <mesh filename="meshes/simple/Chest.stl" scale="0.001 0.001 0.001"/>
      </geometry>
    </collision>
  </link>
  <!-- JOINTS -->
  <joint name="WaistLat" type="revolute">
    <parent link="Waist"/>
    <child link="DWL"/>
    <origin rpy="0 0 0" xyz="0.012 0.0 0.0"/>
    <axis xyz="1 0 0"/>
    <limit effort="140" lower="-0.523598775598" upper="0.523598775598" velocity="7.4"/>
    <dynamics damping="3.0" friction="0"/>
  </joint>
  <joint name="WaistFixed" type="fixed">
    <parent link="DWL"/>
    <child link="DWLExt"/>
    <origin rpy="0 0 0" xyz="-0.0540957 0.0 0.0635"/>
  </joint>
  <joint name="WaistYaw" type="revolute">
    <parent link="DWLExt"/>
    <child link="DWYTorso"/>
    <origin rpy="0 0 0" xyz="0 0 0.16815"/>
    <axis xyz="0 0 1"/>
    <limit effort="120" lower="-1.74532925199" upper="1.74532925199" velocity="6.283"/>
    <dynamics damping="3.0" friction="0"/>
  </joint>
  <!--xacro:property name="PI" value="3.14159265359" />
<xacro:property name="mmTom" value="0.001" />
<xacro:property name="mm2Tom2" value="${0.001*0.001}" /-->
  <!-- RIGHT ARM -->
  <link name="RShp">
    <inertial>
      <origin rpy="0 0 0" xyz="-0.0074457212 -0.03410796 0.00010978102"/>
      <mass value="1.9628675"/>
      <inertia ixx="0.0053547717" ixy="-0.00036428926" ixz="1.5089568e-05" iyy="0.0033923328" iyz="-5.5692312e-05" izz="0.0068921413"/>
    </inertial>
    <visual>
      <origin rpy="0 0 0" xyz="0 0 0"/>
      <geometry name="RShp_visual">
        <mesh filename="meshes/ShoulderPitch.STL" scale="0.001 0.001 0.001"/>
      </geometry>
      <material name="green"/>
    </visual>
    <collision>
      <origin rpy="0 0 0" xyz="0 0 0"/>
      <geometry name="RShp_collision">
        <mesh filename="meshes/simple/ShoulderPitch.STL" scale="0.001 0.001 0.001"/>
      </geometry>
    </collision>
  </link>
  <link name="RShr">
    <inertial>
      <origin rpy="0 0 0" xyz="0.058142302 -5.7450803e-05 -0.077477683"/>
      <mass value="1.8595811"/>
      <inertia ixx="0.013776643" ixy="-3.7788675e-05" ixz="0.0037690171" iyy="0.015677464" iyz="9.4893549e-06" izz="0.0046317657"/>
    </inertial>
    <visual>
      <origin rpy="0 0 0" xyz="0 0 0"/>
      <geometry name="RShr_visual">
        <mesh filename="meshes/ShoulderRoll.STL" scale="0.001 0.001 0.001"/>
      </geometry>
      <material name="dark_grey"/>
    </visual>
    <collision>
      <origin rpy="0 0 0" xyz="0 0 0"/>
      <geometry name="RShr_collision">
        <mesh filename="meshes/simple/ShoulderRoll.STL" scale="0.001 0.001 0.001"/>
      </geometry>
    </collision>
  </link>
  <link name="RShy">
    <inertial>
      <origin rpy="0 0 0" xyz="0.014625194 -0.0008172672 -0.028333545"/>
      <mass value="1.6678109"/>
      <inertia ixx="0.0064480435" ixy="0.00015639093" ixz="0.0012205359" iyy="0.0073372077" iyz="-8.9941532e-05" izz="0.0036738448"/>
    </inertial>
    <visual>
      <origin rpy="0 0 0" xyz="0 0 0"/>
      <geometry name="RShy_visual">
        <mesh filename="meshes/ShoulderYaw.STL" scale="0.001 0.001 0.001"/>
      </geometry>
      <material name="green"/>
    </visual>
    <collision>
      <origin rpy="0 0 0" xyz="0 0 0"/>
      <geometry name="RShy_collision">
        <mesh filename="meshes/simple/ShoulderYaw.STL" scale="0.001 0.001 0.001"/>
      </geometry>
    </collision>
  </link>
  <link name="RElb">
    <inertial>
      <origin rpy="0 0 0" xyz="-0.0076833067 0.040302205 -0.043492779"/>
      <mass value="1.3157289"/>
      <inertia ixx="0.004330394" ixy="0.00011737391" ixz="-0.00041923199" iyy="0.0038539919" iyz="0.00079573038" izz="0.0017594689"/>
    </inertial>
    <visual>
      <origin rpy="0 0 0" xyz="0 0 0"/>
      <geometry name="RElb_visual">
        <mesh filename="meshes/Elbow.STL" scale="0.001 0.001 0.001"/>
      </geometry>
      <material name="dark_grey"/>
    </visual>
    <collision>
      <origin rpy="0 0 0" xyz="0 0 0"/>
      <geometry name="RElb_collision">
        <mesh filename="meshes/simple/Elbow.STL" scale="0.001 0.001 0.001"/>
      </geometry>
    </collision>
  </link>
  <link name="RForearm">
    <inertial>
      <origin rpy="0 0 0" xyz="-0.00011079615 -0.011590836 -0.07816026"/>
      <mass value="1.4908547"/>
      <inertia ixx="0.0085692128" ixy="-1.7856252e-05" ixz="1.9379365e-05" iyy="0.0077454159" iyz="0.00032860094" izz="0.0027441921"/>
    </inertial>
    <visual>
      <origin rpy="0 0 0" xyz="0 0 0"/>
      <geometry name="RForearm_visual">
        <mesh filename="meshes/Forearm.STL" scale="0.001 0.001 0.001"/>
      </geometry>
      <material name="green"/>
    </visual>
    <collision>
      <origin rpy="0 0 0" xyz="0 0 0"/>
      <geometry name="RForearm_collision">
        <mesh filename="meshes/simple/Forearm.STL" scale="0.001 0.001 0.001"/>
      </geometry>
    </collision>
  </link>
  <link name="RWrMot2">
    <inertial>
      <origin rpy="0 0 0" xyz="-4.6502396e-06 0.038014094 -0.069926878"/>
      <mass value="1.1263612"/>
      <inertia ixx="0.0051871784" ixy="-2.724437e-05" ixz="2.2833496e-06" iyy="0.0048037789" iyz="0.00072165653" izz="0.0012771388"/>
    </inertial>
    <visual>
      <origin rpy="0 0 0" xyz="0 0 0"/>
      <geometry name="RWrMot2_visual">
        <mesh filename="meshes/ForearmPitch.STL" scale="0.001 0.001 0.001"/>
      </geometry>
      <material name="dark_grey"/>
    </visual>
    <collision>
      <origin rpy="0 0 0" xyz="0 0 0"/>
      <geometry name="RWrMot2_collision">
        <mesh filename="meshes/simple/ForearmPitch.STL" scale="0.001 0.001 0.001"/>
      </geometry>
    </collision>
  </link>
  <link name="RWrMot3">
    <inertial>
      <origin rpy="0 0 0" xyz="0 0 0.03127057"/>
      <mass value="2.7966428e-01"/>
      <inertia ixx="0.00014415192" ixy="9.8651826e-08" ixz="0" iyy="0.0001441701" iyz="0" izz="6.0500616e-05"/>
    </inertial>
    <visual>
      <origin rpy="0 0 0" xyz="0 0 0"/>
      <geometry name="RWrMot3_visual">
        <mesh filename="meshes/ForearmYaw.STL" scale="0.001 0.001 0.001"/>
      </geometry>
      <material name="green"/>
    </visual>
    <collision>
      <origin rpy="0 0 0" xyz="0 0 0"/>
      <geometry name="RWrMot3_collision">
        <mesh filename="meshes/simple/ForearmYaw.STL" scale="0.001 0.001 0.001"/>
      </geometry>
    </collision>
  </link>
  <link name="r_wrist">
    <inertial>
      <origin rpy="0 0 0" xyz="8.2161929e-05 -0.0026334189 -0.016465877"/>
      <mass value="3.7827821e-01"/>
      <inertia ixx="0.00023321716" ixy="-2.3681435e-06" ixz="-1.8039102e-06" iyy="0.00020626291" iyz="-3.158829e-05" izz="0.00027399881"/>
    </inertial>
    <visual>
      <origin rpy="3.14159265359 0 0" xyz="0 0 0"/>
      <geometry name="RShp_visual">
        <mesh filename="meshes/Wrist.STL" scale="0.001 0.001 0.001"/>
      </geometry>
      <material name="dark_grey"/>
    </visual>
    <collision>
      <origin rpy="3.14159265359 0 0" xyz="0 0 0"/>
      <geometry name="RShp_collision">
        <mesh filename="meshes/simple/Wrist.STL" scale="0.001 0.001 0.001"/>
      </geometry>
    </collision>
  </link>
  <joint name="RShSag" type="revolute">
    <parent link="DWYTorso"/>
    <child link="RShp"/>
    <origin rpy="-0.174533 0 0.5235988" xyz="0.0457475 -0.169137 0.155126"/>
    <axis xyz="0 1 0"/>
    <limit effort="140" lower="-3.359" upper="1.606" velocity="6.283"/>
    <dynamics damping="3.0" friction="0"/>
  </joint>
  <joint name="RShLat" type="revolute">
    <parent link="RShp"/>
    <child link="RShr"/>
    <origin rpy="0.1745327 0 0" xyz="-0.09015 -0.062 0"/>
    <axis xyz="1 0 0"/>
    <limit effort="140" lower="-3.43" upper="0.0" velocity="6.283"/>
    <dynamics damping="3.0" friction="0"/>
  </joint>
  <joint name="RShYaw" type="revolute">
    <parent link="RShr"/>
    <child link="RShy"/>
    <origin rpy="0 0 0" xyz="0.09015 0 -0.21815"/>
    <axis xyz="0 0 1"/>
    <limit effort="120" lower="-2.55" upper="2.55" velocity="6.283"/>
    <dynamics damping="3.0" friction="0"/>
  </joint>
  <joint name="RElbj" type="revolute">
    <parent link="RShy"/>
    <child link="RElb"/>
    <origin rpy="0 0 0" xyz="0.045 -0.05515 -0.074"/>
    <axis xyz="0 1 0"/>
    <limit effort="120" lower="-2.488" upper="0.292" velocity="6.283"/>
    <dynamics damping="3.0" friction="0"/>
  </joint>
  <joint name="RForearmPlate" type="revolute">
    <parent link="RElb"/>
    <child link="RForearm"/>
    <origin rpy="0 0 0" xyz="-0.015 0.05515 -0.095"/>
    <axis xyz="0 0 1"/>
    <limit effort="35" lower="-2.55" upper="2.55" velocity="6.283"/>
    <dynamics damping="0.03" friction="0"/>
  </joint>
  <joint name="RWrj1" type="revolute">
    <parent link="RForearm"/>
    <child link="RWrMot2"/>
    <origin rpy="0 0 0" xyz="0 -0.049 -0.156"/>
    <axis xyz="0 1 0"/>
    <limit effort="35" lower="-1.542" upper="1.508" velocity="6.283"/>
    <dynamics damping="0.03" friction="0"/>
  </joint>
  <joint name="RWrj2" type="revolute">
    <parent link="RWrMot2"/>
    <child link="RWrMot3"/>
    <origin rpy="0 0 0" xyz="0 0.049 -0.174"/>
    <axis xyz="0 0 1"/>
    <limit effort="20" lower="-2.55" upper="2.55" velocity="6.283"/>
    <dynamics damping="0.03" friction="0"/>
  </joint>
  <joint name="r_wrist_joint" type="fixed">
    <parent link="RWrMot3"/>
    <child link="r_wrist"/>
    <origin rpy="0 0 0" xyz="0 0 0"/>
  </joint>
  <!-- LEFT ARM -->
  <link name="LShp">
    <inertial>
      <origin rpy="0 0 0" xyz="-0.0074457212 0.03410796 0.00010978102"/>
      <mass value="1.9628675"/>
      <inertia ixx="0.0053547717" ixy="0.00036428926" ixz="1.5089568e-05" iyy="0.0033923328" iyz="5.5692312e-05" izz="0.0068921413"/>
    </inertial>
    <visual>
      <origin rpy="0 0 0" xyz="0 0 0"/>
      <geometry name="LShp_visual">
        <mesh filename="meshes/ShoulderPitch.STL" scale="0.001 -0.001 0.001"/>
      </geometry>
      <material name="green"/>
    </visual>
    <collision>
      <origin rpy="0 0 0" xyz="0 0 0"/>
      <geometry name="LShp_collision">
        <mesh filename="meshes/simple/ShoulderPitch.STL" scale="0.001 -0.001 0.001"/>
      </geometry>
    </collision>
  </link>
  <link name="LShr">
    <inertial>
      <origin rpy="0 0 0" xyz="0.058142302 5.7450803e-05 -0.077477683"/>
      <mass value="1.8595811"/>
      <inertia ixx="0.013776643" ixy="3.7788675e-05" ixz="0.0037690171" iyy="0.015677464" iyz="-9.4893549e-06" izz="0.0046317657"/>
    </inertial>
    <visual>
      <origin rpy="0 0 0" xyz="0 0 0"/>
      <geometry name="LShr_visual">
        <mesh filename="meshes/ShoulderRoll.STL" scale="0.001 -0.001 0.001"/>
      </geometry>
      <material name="dark_grey"/>
    </visual>
    <collision>
      <origin rpy="0 0 0" xyz="0 0 0"/>
      <geometry name="LShr_collision">
        <mesh filename="meshes/simple/ShoulderRoll.STL" scale="0.001 -0.001 0.001"/>
      </geometry>
    </collision>
  </link>
  <link name="LShy">
    <inertial>
      <origin rpy="0 0 0" xyz="0.014625194 0.0008172672 -0.028333545"/>
      <mass value="1.6678109"/>
      <inertia ixx="0.0064480435" ixy="-0.00015639093" ixz="0.0012205359" iyy="0.0073372077" iyz="8.9941532e-05" izz="0.0036738448"/>
    </inertial>
    <visual>
      <origin rpy="0 0 0" xyz="0 0 0"/>
      <geometry name="LShy_visual">
        <mesh filename="meshes/ShoulderYaw.STL" scale="0.001 -0.001 0.001"/>
      </geometry>
      <material name="green"/>
    </visual>
    <collision>
      <origin rpy="0 0 0" xyz="0 0 0"/>
      <geometry name="LShy_collision">
        <mesh filename="meshes/simple/ShoulderYaw.STL" scale="0.001 -0.001 0.001"/>
      </geometry>
    </collision>
  </link>
  <link name="LElb">
    <inertial>
      <origin rpy="0 0 0" xyz="-0.0076833067 -0.040302205 -0.043492779"/>
      <mass value="1.3157289"/>
      <inertia ixx="0.004330394" ixy="-0.00011737391" ixz="-0.00041923199" iyy="0.0038539919" iyz="-0.00079573038" izz="0.0017594689"/>
    </inertial>
    <visual>
      <origin rpy="0 0 0" xyz="0 0 0"/>
      <geometry name="LElb_visual">
        <mesh filename="meshes/Elbow.STL" scale="0.001 -0.001 0.001"/>
      </geometry>
      <material name="dark_grey"/>
    </visual>
    <collision>
      <origin rpy="0 0 0" xyz="0 0 0"/>
      <geometry name="LElb_collision">
        <mesh filename="meshes/simple/Elbow.STL" scale="0.001 -0.001 0.001"/>
      </geometry>
    </collision>
  </link>
  <link name="LForearm">
    <inertial>
      <origin rpy="0 0 0" xyz="-0.00011079615 0.011590836 -0.07816026"/>
      <mass value="1.4908547"/>
      <inertia ixx="0.0085692128" ixy="1.7856252e-05" ixz="1.9379365e-05" iyy="0.0077454159" iyz="-0.00032860094" izz="0.0027441921"/>
    </inertial>
    <visual>
      <origin rpy="0 0 0" xyz="0 0 0"/>
      <geometry name="LForearm_visual">
        <mesh filename="meshes/Forearm.STL" scale="0.001 -0.001 0.001"/>
      </geometry>
      <material name="green"/>
    </visual>
    <collision>
      <origin rpy="0 0 0" xyz="0 0 0"/>
      <geometry name="LForearm_collision">
        <mesh filename="meshes/simple/Forearm.STL" scale="0.001 -0.001 0.001"/>
      </geometry>
    </collision>
  </link>
  <link name="LWrMot2">
    <inertial>
      <origin rpy="0 0 0" xyz="-4.6502396e-06 -0.038014094 -0.069926878"/>
      <mass value="1.1263612"/>
      <inertia ixx="0.0051871784" ixy="2.724437e-05" ixz="2.2833496e-06" iyy="0.0048037789" iyz="-0.00072165653" izz="0.0012771388"/>
    </inertial>
    <visual>
      <origin rpy="0 0 0" xyz="0 0 0"/>
      <geometry name="LWrMot2_visual">
        <mesh filename="meshes/ForearmPitch.STL" scale="0.001 -0.001 0.001"/>
      </geometry>
      <material name="dark_grey"/>
    </visual>
    <collision>
      <origin rpy="0 0 0" xyz="0 0 0"/>
      <geometry name="LWrMot2_collision">
        <mesh filename="meshes/simple/ForearmPitch.STL" scale="0.001 -0.001 0.001"/>
      </geometry>
    </collision>
  </link>
  <link name="LWrMot3">
    <inertial>
      <origin rpy="0 0 0" xyz="0 0 0.03127057"/>
      <mass value="2.7966428e-01"/>
      <inertia ixx="0.00014415192" ixy="9.8651826e-08" ixz="0" iyy="0.0001441701" iyz="0" izz="6.0500616e-05"/>
    </inertial>
    <visual>
      <origin rpy="0 0 0" xyz="0 0 0"/>
      <geometry name="LWrMot3_visual">
        <mesh filename="meshes/ForearmYaw.STL" scale="0.001 -0.001 0.001"/>
      </geometry>
      <material name="green"/>
    </visual>
    <collision>
      <origin rpy="0 0 0" xyz="0 0 0"/>
      <geometry name="LWrMot3_collision">
        <mesh filename="meshes/simple/ForearmYaw.STL" scale="0.001 -0.001 0.001"/>
      </geometry>
    </collision>
  </link>
  <link name="l_wrist">
    <inertial>
      <origin rpy="0 0 0" xyz="8.2161929e-05 0.0026334189 -0.016465877"/>
      <mass value="3.7827821e-01"/>
      <inertia ixx="0.00023321716" ixy="2.3681435e-06" ixz="-1.8039102e-06" iyy="0.00020626291" iyz="3.158829e-05" izz="0.00027399881"/>
    </inertial>
    <visual>
      <origin rpy="3.14159265359 0 0" xyz="0 0 0"/>
      <geometry name="LShp_visual">
        <mesh filename="meshes/Wrist.STL" scale="0.001 -0.001 0.001"/>
      </geometry>
      <material name="dark_grey"/>
    </visual>
    <collision>
      <origin rpy="3.14159265359 0 0" xyz="0 0 0"/>
      <geometry name="LShp_collision">
        <mesh filename="meshes/simple/Wrist.STL" scale="0.001 -0.001 0.001"/>
      </geometry>
    </collision>
  </link>
  <joint name="LShSag" type="revolute">
    <parent link="DWYTorso"/>
    <child link="LShp"/>
    <origin rpy="0.174533 0 -0.5235988" xyz="0.0457475 0.169137 0.155126"/>
    <axis xyz="0 1 0"/>
    <limit effort="140" lower="-3.352" upper="1.603" velocity="6.283"/>
    <dynamics damping="3.0" friction="0"/>
  </joint>
  <joint name="LShLat" type="revolute">
    <parent link="LShp"/>
    <child link="LShr"/>
    <origin rpy="-0.1745327 0 0" xyz="-0.09015 0.062 0"/>
    <axis xyz="1 0 0"/>
    <limit effort="140" lower="0.0" upper="3.517" velocity="6.283"/>
    <dynamics damping="3.0" friction="0"/>
  </joint>
  <joint name="LShYaw" type="revolute">
    <parent link="LShr"/>
    <child link="LShy"/>
    <origin rpy="0 0 0" xyz="0.09015 0 -0.21815"/>
    <axis xyz="0 0 1"/>
    <limit effort="120" lower="-2.55" upper="2.55" velocity="6.283"/>
    <dynamics damping="3.0" friction="0"/>
  </joint>
  <joint name="LElbj" type="revolute">
    <parent link="LShy"/>
    <child link="LElb"/>
    <origin rpy="0 0 0" xyz="0.045 0.05515 -0.074"/>
    <axis xyz="0 1 0"/>
    <limit effort="120" lower="-2.492" upper="0.298" velocity="6.283"/>
    <dynamics damping="3.0" friction="0"/>
  </joint>
  <joint name="LForearmPlate" type="revolute">
    <parent link="LElb"/>
    <child link="LForearm"/>
    <origin rpy="0 0 0" xyz="-0.015 -0.05515 -0.095"/>
    <axis xyz="0 0 1"/>
    <limit effort="35" lower="-2.55" upper="2.55" velocity="6.283"/>
    <dynamics damping="0.03" friction="0"/>
  </joint>
  <joint name="LWrj1" type="revolute">
    <parent link="LForearm"/>
    <child link="LWrMot2"/>
    <origin rpy="0 0 0" xyz="0 0.049 -0.156"/>
    <axis xyz="0 1 0"/>
    <limit effort="35" lower="-1.562" upper="1.478" velocity="6.283"/>
    <dynamics damping="0.03" friction="0"/>
  </joint>
  <joint name="LWrj2" type="revolute">
    <parent link="LWrMot2"/>
    <child link="LWrMot3"/>
    <origin rpy="0 0 0" xyz="0 -0.049 -0.174"/>
    <axis xyz="0 0 1"/>
    <limit effort="20" lower="-2.55" upper="2.55" velocity="6.283"/>
    <dynamics damping="0.03" friction="0"/>
  </joint>
  <joint name="l_wrist_joint" type="fixed">
    <parent link="LWrMot3"/>
    <child link="l_wrist"/>
    <origin rpy="0 0 0" xyz="0 0 0"/>
  </joint>
  <!-- LINKS -->
  <link name="Neck">
    <inertial>
      <origin rpy="0 0 0" xyz="0.019525578 8.7785097e-05 0.073374976 "/>
      <mass value="2.3794941e-01"/>
      <inertia ixx="0.00028460315" ixy="-5.4194691e-07" ixz="-7.3250232e-05" iyy="0.0004530875" iyz="-9.4474115e-08" izz="0.00027675534"/>
    </inertial>
    <visual>
      <origin rpy="0 0 0" xyz="0.0 0.0 0.0"/>
      <geometry name="Neck_visual">
        <mesh filename="meshes/NeckFixed.stl" scale="0.001 0.001 0.001"/>
      </geometry>
      <material name="dark_grey"/>
    </visual>
    <collision>
      <origin rpy="0 0 0" xyz="0.0 0.0 0.0"/>
      <geometry name="Neck_collision">
        <mesh filename="meshes/simple/NeckFixed.stl" scale="0.001 0.001 0.001"/>
      </geometry>
    </collision>
  </link>
  <link name="HeadHokuyo">
    <!-- TODO: CHECK THESE VALUES!!! -->
    <inertial>
      <origin rpy="0 0 0" xyz="0.055322369 0.018472201 -0.018483703 "/>
      <mass value="5.4611797e-01"/>
      <inertia ixx="0.0019756996" ixy="-0.00011287972" ixz="0.00011284571" iyy="0.0044030675" iyz="0.00049540219" izz="0.0044027914"/>
    </inertial>
    <visual>
      <origin rpy="-0.785398163398 0 0" xyz="0.0 0.0 0.0"/>
      <geometry name="Neck_visual">
        <mesh filename="meshes/HeadRoll.stl" scale="0.001 0.001 0.001"/>
      </geometry>
      <material name="dark_grey"/>
    </visual>
    <collision>
      <origin rpy="-0.785398163398 0 0" xyz="0.0 0.0 0.0"/>
      <geometry name="Neck_collision">
        <mesh filename="meshes/simple/HeadRoll.stl" scale="0.001 0.001 0.001"/>
      </geometry>
    </collision>
  </link>
  <!-- JOINTS -->
  <joint name="neck_frame" type="fixed">
    <parent link="DWYTorso"/>
    <child link="Neck"/>
    <origin rpy="0 0 0" xyz="0.016 0.0 0.1965"/>
  </joint>
  <joint name="head_roll" type="fixed">
    <parent link="Neck"/>
    <child link="HeadHokuyo"/>
    <origin rpy="0 0 0" xyz="0.0496 0.0 0.09"/>
  </joint>
  <!--xacro:property name="PI" value="3.14159265359" />
<xacro:property name="PI_2" value="1.57079632679" /-->
  <!-- LINKS -->
  <link name="RSoftHand">
    <inertial>
      <origin rpy="0 0 0" xyz="0 0 0"/>
      <mass value="0"/>
      <inertia ixx="0.0" ixy="0.0" ixz="0.0" iyy="0.0" iyz="0.0" izz="0.0"/>
    </inertial>
  </link> <!-- in pybullet, the inertia need to be specified even for dummy links, otherwise it will put an identity inertia and a mass of 1 by default -->
  <link name="TCP_R">
    <inertial>
      <origin rpy="0 0 0" xyz="0 0 0"/>
      <mass value="0"/>
      <inertia ixx="0.0" ixy="0.0" ixz="0.0" iyy="0.0" iyz="0.0" izz="0.0"/>
    </inertial>
  </link> <!-- in pybullet, the inertia need to be specified even for dummy links, otherwise it will put an identity inertia and a mass of 1 by default -->
  <link name="RSoftHandLink">
    <inertial>
      <origin rpy="0 0 0" xyz="0.0020955992 0.0043009755 -0.060792229"/>
      <mass value="1.4"/>
      <inertia ixx="0.0046340021" ixy="-5.6301252e-05" ixz="0.00021001241" iyy="0.0052222303" iyz="0.00020916976" izz="0.0013961628"/>
    </inertial>
    <visual>
      <origin rpy="0.0 0.0 0.0" xyz="0.0 0.0 0.0"/>
      <geometry name="RSoftHandLink_visual">
        <mesh filename="meshes/SoftHandOpen2.STL" scale="0.001 0.001 0.001"/>
      </geometry>
      <material name="grey"/>
    </visual>
    <collision>
      <origin rpy="0.0 0.0 0.0" xyz="0.0 0.0 0.0"/>
      <geometry name="RSoftHandLink_collision">
        <mesh filename="meshes/simple/SoftHandOpen2.STL" scale="0.001 0.001 0.001"/>
      </geometry>
    </collision>
  </link>
  <joint name="r_handj" type="fixed">
    <parent link="r_wrist"/>
    <child link="RSoftHandLink"/>
    <origin rpy="0 0 0" xyz="0 0 -0.0395"/>
  </joint>
  <joint name="r_handj2" type="fixed">
    <parent link="RSoftHandLink"/>
    <child link="RSoftHand"/>
    <origin rpy="0 0 0" xyz="0 0.041 -0.1005"/>
  </joint>
  <joint name="TCP_Rjoint" type="fixed">
    <parent link="RSoftHand"/>
    <child link="TCP_R"/>
    <origin rpy="-1.57079632679 0 0" xyz="0.0 0.0 0.0"/>
  </joint>
  <link name="LSoftHand">
    <inertial>
      <origin rpy="0 0 0" xyz="0 0 0"/>
      <mass value="0"/>
      <inertia ixx="0.0" ixy="0.0" ixz="0.0" iyy="0.0" iyz="0.0" izz="0.0"/>
    </inertial>
  </link> <!-- in pybullet, the inertia need to be specified even for dummy links, otherwise it will put an identity inertia and a mass of 1 by default -->
  <link name="TCP_L">
    <inertial>
      <origin rpy="0 0 0" xyz="0 0 0"/>
      <mass value="0"/>
      <inertia ixx="0.0" ixy="0.0" ixz="0.0" iyy="0.0" iyz="0.0" izz="0.0"/>
    </inertial>
  </link> <!-- in pybullet, the inertia need to be specified even for dummy links, otherwise it will put an identity inertia and a mass of 1 by default -->
  <link name="LSoftHandLink">
    <inertial>
      <origin rpy="0 0 0" xyz="0.0020955992 -0.0043009755 -0.060792229"/>
      <mass value="1.4"/>
      <inertia ixx="0.0046340021" ixy="5.6301252e-05" ixz="0.00021001241" iyy="0.0052222303" iyz="-0.00020916976" izz="0.0013961628"/>
    </inertial>
    <visual>
      <origin rpy="0.0 0.0 0.0" xyz="0.0 0.0 0.0"/>
      <geometry name="LSoftHandLink_visual">
        <mesh filename="meshes/SoftHandOpen2.STL" scale="0.001 -0.001 0.001"/>
      </geometry>
      <material name="grey"/>
    </visual>
    <collision>
      <origin rpy="0.0 0.0 0.0" xyz="0.0 0.0 0.0"/>
      <geometry name="LSoftHandLink_collision">
        <mesh filename="meshes/simple/SoftHandOpen2.STL" scale="0.001 -0.001 0.001"/>
      </geometry>
    </collision>
  </link>
  <!-- JOINTS -->
  <joint name="l_handj" type="fixed">
    <parent link="l_wrist"/>
    <child link="LSoftHandLink"/>
    <origin rpy="0 0 0" xyz="0 0 -0.0395"/>
  </joint>
  <joint name="l_handj2" type="fixed">
    <parent link="LSoftHandLink"/>
    <child link="LSoftHand"/>
    <origin rpy="0 0 0" xyz="0 -0.041 -0.1005"/>
  </joint>
  <joint name="TCP_Ljoint" type="fixed">
    <parent link="LSoftHand"/>
    <child link="TCP_L"/>
    <origin rpy="1.57079632679 3.14159265359 0" xyz="0.0 0.0 0.0"/>
  </joint>
  <link name="l_ankle">
    <inertial>
      <origin rpy="0 0 0" xyz="0 0 0"/>
      <mass value="0"/>
      <inertia ixx="0.0" ixy="0.0" ixz="0.0" iyy="0.0" iyz="0.0" izz="0.0"/>
    </inertial>
  </link> <!-- in pybullet, the inertia need to be specified even for dummy links, otherwise it will put an identity inertia and a mass of 1 by default -->
  <link name="l_sole">
    <inertial>
      <origin rpy="0 0 0" xyz="0 0 0"/>
      <mass value="0"/>
      <inertia ixx="0.0" ixy="0.0" ixz="0.0" iyy="0.0" iyz="0.0" izz="0.0"/>
    </inertial>
  </link> <!-- in pybullet, the inertia need to be specified even for dummy links, otherwise it will put an identity inertia and a mass of 1 by default -->
  <link name="l_toe">
    <inertial>
      <origin rpy="0 0 0" xyz="0 0 0"/>
      <mass value="0"/>
      <inertia ixx="0.0" ixy="0.0" ixz="0.0" iyy="0.0" iyz="0.0" izz="0.0"/>
    </inertial>
  </link> <!-- in pybullet, the inertia need to be specified even for dummy links, otherwise it will put an identity inertia and a mass of 1 by default -->
  <link name="l_heel">
    <inertial>
      <origin rpy="0 0 0" xyz="0 0 0"/>
      <mass value="0"/>
      <inertia ixx="0.0" ixy="0.0" ixz="0.0" iyy="0.0" iyz="0.0" izz="0.0"/>
    </inertial>
  </link> <!-- in pybullet, the inertia need to be specified even for dummy links, otherwise it will put an identity inertia and a mass of 1 by default -->
  <link name="l_leg_ft">
    <inertial>
      <origin rpy="0 0 0" xyz="0 0 0"/>
      <mass value="0"/>
      <inertia ixx="0.0" ixy="0.0" ixz="0.0" iyy="0.0" iyz="0.0" izz="0.0"/>
    </inertial>
  </link> <!-- in pybullet, the inertia need to be specified even for dummy links, otherwise it will put an identity inertia and a mass of 1 by default -->
  <joint name="l_leg_ft_joint" type="fixed">
    <origin rpy="0 0 0" xyz="0 0 -0.035"/>
    <parent link="LFoot"/>
    <child link="l_leg_ft"/>
  </joint>
  <joint name="l_ankle_joint" type="fixed">
    <origin rpy="0 0 0" xyz="0 0 0"/>
    <parent link="LFoot"/>
    <child link="l_ankle"/>
  </joint>
  <joint name="l_sole_joint" type="fixed">
    <origin rpy="0 0 0" xyz="0 0 -0.069"/>
    <parent link="l_ankle"/>
    <child link="l_sole"/>
  </joint>
  <joint name="l_toe_joint" type="fixed">
    <origin rpy="0 0 0" xyz="0.107 0 0"/>
    <parent link="l_sole"/>
    <child link="l_toe"/>
  </joint>
  <joint name="l_heel_joint" type="fixed">
    <origin rpy="0 0 0" xyz="-0.1035 0 0"/>
    <parent link="l_sole"/>
    <child link="l_heel"/>
  </joint>
  <link name="l_foot_upper_right_link">
    <inertial>
      <origin rpy="0 0 0" xyz="0 0 0"/>
      <mass value="0"/>
      <inertia ixx="0.0" ixy="0.0" ixz="0.0" iyy="0.0" iyz="0.0" izz="0.0"/>
    </inertial>
  </link> <!-- in pybullet, the inertia need to be specified even for dummy links, otherwise it will put an identity inertia and a mass of 1 by default -->
  <joint name="l_foot_upper_right_joint" type="fixed">
    <origin rpy="0 0 0" xyz="0.107 -0.055 0"/>
    <parent link="l_sole"/>
    <child link="l_foot_upper_right_link"/>
  </joint>
  <link name="l_foot_upper_left_link">
    <inertial>
      <origin rpy="0 0 0" xyz="0 0 0"/>
      <mass value="0"/>
      <inertia ixx="0.0" ixy="0.0" ixz="0.0" iyy="0.0" iyz="0.0" izz="0.0"/>
    </inertial>
  </link> <!-- in pybullet, the inertia need to be specified even for dummy links, otherwise it will put an identity inertia and a mass of 1 by default -->
  <joint name="l_foot_upper_left_joint" type="fixed">
    <origin rpy="0 0 0" xyz="0.107 0.055 0"/>
    <parent link="l_sole"/>
    <child link="l_foot_upper_left_link"/>
  </joint>
  <link name="l_foot_lower_right_link">
    <inertial>
      <origin rpy="0 0 0" xyz="0 0 0"/>
      <mass value="0"/>
      <inertia ixx="0.0" ixy="0.0" ixz="0.0" iyy="0.0" iyz="0.0" izz="0.0"/>
    </inertial>
  </link> <!-- in pybullet, the inertia need to be specified even for dummy links, otherwise it will put an identity inertia and a mass of 1 by default -->
  <joint name="l_foot_lower_right_joint" type="fixed">
    <origin rpy="0 0 0" xyz="-0.1035 -0.055 0"/>
    <parent link="l_sole"/>
    <child link="l_foot_lower_right_link"/>
  </joint>
  <link name="l_foot_lower_left_link">
    <inertial>
      <origin rpy="0 0 0" xyz="0 0 0"/>
      <mass value="0"/>
      <inertia ixx="0.0" ixy="0.0" ixz="0.0" iyy="0.0" iyz="0.0" izz="0.0"/>
    </inertial>
  </link> <!-- in pybullet, the inertia need to be specified even for dummy links, otherwise it will put an identity inertia and a mass of 1 by default -->
  <joint name="l_foot_lower_left_joint" type="fixed">
    <origin rpy="0 0 0" xyz="-0.1035 0.055 0"/>
    <parent link="l_sole"/>
    <child link="l_foot_lower_left_link"/>
  </joint>
  <link name="r_ankle">
    <inertial>
      <origin rpy="0 0 0" xyz="0 0 0"/>
      <mass value="0"/>
      <inertia ixx="0.0" ixy="0.0" ixz="0.0" iyy="0.0" iyz="0.0" izz="0.0"/>
    </inertial>
  </link> <!-- in pybullet, the inertia need to be specified even for dummy links, otherwise it will put an identity inertia and a mass of 1 by default -->
  <link name="r_sole">
    <inertial>
      <origin rpy="0 0 0" xyz="0 0 0"/>
      <mass value="0"/>
      <inertia ixx="0.0" ixy="0.0" ixz="0.0" iyy="0.0" iyz="0.0" izz="0.0"/>
    </inertial>
  </link> <!-- in pybullet, the inertia need to be specified even for dummy links, otherwise it will put an identity inertia and a mass of 1 by default -->
  <link name="r_toe">
    <inertial>
      <origin rpy="0 0 0" xyz="0 0 0"/>
      <mass value="0"/>
      <inertia ixx="0.0" ixy="0.0" ixz="0.0" iyy="0.0" iyz="0.0" izz="0.0"/>
    </inertial>
  </link> <!-- in pybullet, the inertia need to be specified even for dummy links, otherwise it will put an identity inertia and a mass of 1 by default -->
  <link name="r_heel">
    <inertial>
      <origin rpy="0 0 0" xyz="0 0 0"/>
      <mass value="0"/>
      <inertia ixx="0.0" ixy="0.0" ixz="0.0" iyy="0.0" iyz="0.0" izz="0.0"/>
    </inertial>
  </link> <!-- in pybullet, the inertia need to be specified even for dummy links, otherwise it will put an identity inertia and a mass of 1 by default -->
  <link name="r_leg_ft">
    <inertial>
      <origin rpy="0 0 0" xyz="0 0 0"/>
      <mass value="0"/>
      <inertia ixx="0.0" ixy="0.0" ixz="0.0" iyy="0.0" iyz="0.0" izz="0.0"/>
    </inertial>
  </link> <!-- in pybullet, the inertia need to be specified even for dummy links, otherwise it will put an identity inertia and a mass of 1 by default -->
  <joint name="r_leg_ft_joint" type="fixed">
    <origin rpy="0 0 0" xyz="0 0 -0.035"/>
    <parent link="RFoot"/>
    <child link="r_leg_ft"/>
  </joint>
  <joint name="r_ankle_joint" type="fixed">
    <origin rpy="0 0 0" xyz="0 0 0"/>
    <parent link="RFoot"/>
    <child link="r_ankle"/>
  </joint>
  <joint name="r_sole_joint" type="fixed">
    <origin rpy="0 0 0" xyz="0 0 -0.069"/>
    <parent link="r_ankle"/>
    <child link="r_sole"/>
  </joint>
  <joint name="r_toe_joint" type="fixed">
    <origin rpy="0 0 0" xyz="0.107 0 0"/>
    <parent link="r_sole"/>
    <child link="r_toe"/>
  </joint>
  <joint name="r_heel_joint" type="fixed">
    <origin rpy="0 0 0" xyz="-0.1035 0 0"/>
    <parent link="r_sole"/>
    <child link="r_heel"/>
  </joint>
  <link name="r_foot_upper_right_link">
    <inertial>
      <origin rpy="0 0 0" xyz="0 0 0"/>
      <mass value="0"/>
      <inertia ixx="0.0" ixy="0.0" ixz="0.0" iyy="0.0" iyz="0.0" izz="0.0"/>
    </inertial>
  </link> <!-- in pybullet, the inertia need to be specified even for dummy links, otherwise it will put an identity inertia and a mass of 1 by default -->
  <joint name="r_foot_upper_right_joint" type="fixed">
    <origin rpy="0 0 0" xyz="0.107 -0.055 0"/>
    <parent link="r_sole"/>
    <child link="r_foot_upper_right_link"/>
  </joint>
  <link name="r_foot_upper_left_link">
    <inertial>
      <origin rpy="0 0 0" xyz="0 0 0"/>
      <mass value="0"/>
      <inertia ixx="0.0" ixy="0.0" ixz="0.0" iyy="0.0" iyz="0.0" izz="0.0"/>
    </inertial>
  </link> <!-- in pybullet, the inertia need to be specified even for dummy links, otherwise it will put an identity inertia and a mass of 1 by default -->
  <joint name="r_foot_upper_left_joint" type="fixed">
    <origin rpy="0 0 0" xyz="0.107 0.055 0"/>
    <parent link="r_sole"/>
    <child link="r_foot_upper_left_link"/>
  </joint>
  <link name="r_foot_lower_right_link">
    <inertial>
      <origin rpy="0 0 0" xyz="0 0 0"/>
      <mass value="0"/>
      <inertia ixx="0.0" ixy="0.0" ixz="0.0" iyy="0.0" iyz="0.0" izz="0.0"/>
    </inertial>
  </link> <!-- in pybullet, the inertia need to be specified even for dummy links, otherwise it will put an identity inertia and a mass of 1 by default -->
  <joint name="r_foot_lower_right_joint" type="fixed">
    <origin rpy="0 0 0" xyz="-0.1035 -0.055 0"/>
    <parent link="r_sole"/>
    <child link="r_foot_lower_right_link"/>
  </joint>
  <link name="r_foot_lower_left_link">
    <inertial>
      <origin rpy="0 0 0" xyz="0 0 0"/>
      <mass value="0"/>
      <inertia ixx="0.0" ixy="0.0" ixz="0.0" iyy="0.0" iyz="0.0" izz="0.0"/>
    </inertial>
  </link> <!-- in pybullet, the inertia need to be specified even for dummy links, otherwise it will put an identity inertia and a mass of 1 by default -->
  <joint name="r_foot_lower_left_joint" type="fixed">
    <origin rpy="0 0 0" xyz="-0.1035 0.055 0"/>
    <parent link="r_sole"/>
    <child link="r_foot_lower_left_link"/>
  </joint>
  <link name="r_arm_ft">
    <inertial>
      <origin rpy="0 0 0" xyz="0 0 0"/>
      <mass value="0"/>
      <inertia ixx="0.0" ixy="0.0" ixz="0.0" iyy="0.0" iyz="0.0" izz="0.0"/>
    </inertial>
  </link> <!-- in pybullet, the inertia need to be specified even for dummy links, otherwise it will put an identity inertia and a mass of 1 by default -->
  <joint name="r_arm_ft_joint" type="fixed">
    <origin rpy="0 0 0" xyz="0 0 -0.02"/>
    <parent link="RWrMot3"/>
    <child link="r_arm_ft"/>
  </joint>
  <link name="l_arm_ft">
    <inertial>
      <origin rpy="0 0 0" xyz="0 0 0"/>
      <mass value="0"/>
      <inertia ixx="0.0" ixy="0.0" ixz="0.0" iyy="0.0" iyz="0.0" izz="0.0"/>
    </inertial>
  </link> <!-- in pybullet, the inertia need to be specified even for dummy links, otherwise it will put an identity inertia and a mass of 1 by default -->
  <joint name="l_arm_ft_joint" type="fixed">
    <origin rpy="0 0 0" xyz="0 0 -0.02"/>
    <parent link="LWrMot3"/>
    <child link="l_arm_ft"/>
  </joint>
  <!--link name="world"/>
  <joint name="reference" type="floating">
    <parent link="world"/>
    <child link="base_link"/>
  </joint-->
</robot>
