<?xml version="1.0" ?>
<!-- =================================================================================== -->
<!-- |    This document was autogenerated by xacro from cogimon.urdf.xacro             | -->
<!-- |    EDITING THIS FILE BY HAND IS NOT RECOMMENDED                                 | -->
<!-- =================================================================================== -->
<robot name="cogimon" xmlns:xacro="http://ros.org/wiki/xacro">
  <!-- 
  ROS urdf definition of the COGIMON humanoid robot by Istituto Italiano di Tecnologia
  
  DO NOT INCLUDE THIS FILE DIRECTLY! USE cogimon_robot.urdf.xacro INSTEAD!

  Author: Enrico Mingo

  Inertial matrix has to be in CoM frame (URDF specs)
-->
  <material name="grey">
    <color rgba="0.5 0.5 0.5 1"/>
  </material>
  <material name="dark_grey">
    <color rgba="0.3 0.3 0.3 1"/>
  </material>
  <material name="red">
    <color rgba="1.0 0.0 0.0 1"/>
  </material>
  <material name="green">
    <color rgba="0.0 1.0 0.0 1"/>
  </material>
  <!-- Head -->
  <!-- This links are defined in order to be compliant with http://www.ros.org/reps/rep-0120.html#coordinate-frames
and to define the end effectors of the robot.
The coordinate frame called gaze defines the head position and orientation. The orientation indicates in which direction the head appears to be looking regardless of any sensors (camera for instance). -->
  <!--link name="gaze"/>

	<joint name="gaze_joint" type="fixed">
		<parent link="torso"/>
		<child link="gaze"/>
		<origin xyz="0 0 0.1" rpy="0 0 0" />
	</joint-->
  <!-- NECK -->
  <!--xacro:include filename="$(find cogimon_urdf)/urdf/parts/neck.urdf.xacro" /-->
  <!-- 
  ROS urdf definition of the COGIMON humanoid robot by Istituto Italiano di Tecnologia
  
  DO NOT INCLUDE THIS FILE DIRECTLY! USE cogimon_robot.urdf.xacro INSTEAD!

  Author: Enrico Mingo Hoffman

  Inertial matrix has to be in CoM frame (URDF specs)

-->
  <!-- This links are defined in order to be compliant with http://www.ros.org/reps/rep-0120.html#coordinate-frames
and to define the end effectors of the robot

The coordinate frame called base_link is rigidly attached to the robot root body. It is recommended to choose the robot waist as its root body. The base_link can be attached to the root in any arbitrary position or orientation; for every hardware platform there will be a different place on the base that provides an obvious point of reference. Note that REP 103 [1] specifies a preferred orientation for frames. -->
  <!--<link name="base_link"/>-->
  <link name="Waist">
    <inertial>
      <origin rpy="0.0 0.0 0.0" xyz="-0.056796324 0.00045196345 -0.038136153"/>
      <mass value="3.4599462"/>
      <inertia ixx="0.038130318" ixy="9.5451056e-05" ixz="-8.2481481e-05" iyy="0.0089760596" iyz="9.1637353e-06" izz="0.039650845"/>
    </inertial>
    <visual>
      <origin rpy="0 0 0" xyz="0 0 0"/>
      <material name="dark_grey"/>
      <geometry name="Waist_visual">
        <mesh filename="meshes/Waist.stl" scale="0.001 0.001 0.001"/>
      </geometry>
    </visual>
    <collision>
      <origin rpy="0 0 0" xyz="0 0 0"/>
      <geometry name="Waist_collision">
        <mesh filename="meshes/simple/Waist.stl" scale="0.001 0.001 0.001"/>
      </geometry>
    </collision>
  </link>
  <!--<joint name="base_joint" type="fixed">-->
  <!--<parent link="base_link"/>-->
  <!--<child link="Waist"/>-->
  <!--<origin xyz="0 0 0" rpy="0 0 0" />-->
  <!--</joint>-->
  <!--<joint name="imu_joint" type="fixed">-->
  <!--<parent link="Waist"/>-->
  <!--<child link="imu_link"/>-->
  <!--<origin xyz="${-146.332*mmTom} 0 ${-38.75*mmTom}" rpy="0 0 0" />-->
  <!--</joint>-->
  <!--<link name="imu_link">-->
  <!--<inertial>-->
  <!--<mass value="0.01"/>-->
  <!--<origin xyz="0 0 0"/>-->
  <!--<inertia ixx="1.0E-6" ixy="0" ixz="0" iyy="1.0E-6" iyz="0" izz="1.0E-6"/>-->
  <!--</inertial>-->
  <!--<visual>-->
  <!--<origin rpy="0 0 0" xyz="0 0 0"/>-->
  <!--<geometry>-->
  <!--<box size="0.01 0.01 0.01"/>-->
  <!--</geometry>-->
  <!--</visual>-->
  <!--</link>-->
  <!-- LINKS -->
  <link name="LHipMot">
    <inertial>
      <origin rpy="0 0 0" xyz="-0.041435899 -0.00024099021 -0.067437774"/>
      <mass value="2.0936467"/>
      <inertia ixx="0.010806924" ixy="3.3743172e-05" ixz="-0.0013329083" iyy="0.011288691" iyz="5.6918305e-05" izz="0.0053916798"/>
    </inertial>
    <visual>
      <origin rpy="0 0 0." xyz="0. 0. 0."/>
      <material name="green"/>
      <geometry name="RHipMot_visual">
        <mesh filename="meshes/HipRoll.stl" scale="0.001 0.001 0.001"/>
      </geometry>
    </visual>
    <collision>
      <origin rpy="0 0 0." xyz="0.0 0. 0"/>
      <geometry name="RHipMot_collision">
        <mesh filename="meshes/simple/HipRoll.stl" scale="0.001 0.001 0.001"/>
      </geometry>
    </collision>
  </link>
  <link name="LThighUpLeg">
    <inertial>
      <origin rpy="0 0 0" xyz="0.00058688639 -0.062440385 -0.085057072"/>
      <mass value="1.6115687"/>
      <inertia ixx="0.016169151" ixy="-2.1886129e-05" ixz="6.0058109e-05" iyy="0.0144378" iyz="-0.0027173225" izz="0.0039254506"/>
    </inertial>
    <visual>
      <origin rpy="0 0 0." xyz="0. 0. 0."/>
      <material name="dark_grey"/>
      <geometry name="LThighUpLeg_visual">
        <mesh filename="meshes/HipPitch.stl" scale="0.001 0.001 0.001"/>
      </geometry>
    </visual>
    <collision>
      <origin rpy="0 0 0." xyz="0.0 0. 0"/>
      <geometry name="LThighUpLeg_collision">
        <mesh filename="meshes/simple/HipPitch.stl" scale="0.001 0.001 0.001"/>
      </geometry>
    </collision>
  </link>
  <link name="LThighLowLeg">
    <inertial>
      <origin rpy="0 0 0" xyz="-0.02113641 -0.0042862386 -0.038232267"/>
      <mass value="1.7454681"/>
      <inertia ixx="0.0059857438" ixy="-4.0155441e-05" ixz="-0.00080168603" iyy="0.0066483492" iyz="-0.00011435964" izz="0.0044665032"/>
    </inertial>
    <visual>
      <origin rpy="0 0 0." xyz="0. 0. 0."/>
      <material name="green"/>
      <geometry name="LThighLowLeg_visual">
        <mesh filename="meshes/HipYaw.stl" scale="0.001 0.001 0.001"/>
      </geometry>
    </visual>
    <collision>
      <origin rpy="0 0 0." xyz="0.0 0. 0"/>
      <geometry name="LThighLowLeg_collision">
        <mesh filename="meshes/simple/HipYaw.stl" scale="0.001 0.001 0.001"/>
      </geometry>
    </collision>
  </link>
  <link name="LLowLeg">
    <inertial>
      <origin rpy="0 0 0" xyz="0.027363015 -0.05780207 -0.19306454"/>
      <mass value="3.7014912"/>
      <inertia ixx="0.064669769" ixy="0.00036914631" ixz="0.0053710941" iyy="0.063323486" iyz="-0.0027319883" izz="0.0081842652"/>
    </inertial>
    <visual>
      <origin rpy="0 0 0." xyz="0. 0. 0."/>
      <material name="dark_grey"/>
      <geometry name="LLowLeg_visual">
        <mesh filename="meshes/KneePitch.stl" scale="0.001 0.001 0.001"/>
      </geometry>
    </visual>
    <collision>
      <origin rpy="0 0 0." xyz="0.0 0. 0"/>
      <geometry name="LLowLeg_collision">
        <mesh filename="meshes/simple/KneePitch.stl" scale="0.001 0.001 0.001"/>
      </geometry>
    </collision>
  </link>
  <link name="LFootmot">
    <inertial>
      <origin rpy="0 0 0" xyz="0.0011213007 0.00046152281 -1.144967e-06"/>
      <mass value="1.7723821e-01"/>
      <inertia ixx="2.8142035e-05" ixy="9.1715528e-08" ixz="-2.1701012e-10" iyy="9.7378402e-05" iyz="3.7303915e-10" izz="0.00011570584"/>
    </inertial>
    <visual>
      <origin rpy="0 0 0" xyz="0 0 0"/>
      <geometry name="LFootmot_visual">
        <mesh filename="meshes/AnklePitch.stl" scale="0.001 0.001 0.001"/>
      </geometry>
      <material name="dark_grey"/>
    </visual>
    <collision>
      <origin rpy="0 0 0" xyz="0 0 0"/>
      <geometry name="LFootmot_collision">
        <mesh filename="meshes/simple/AnklePitch.stl" scale="0.001 0.001 0.001"/>
      </geometry>
    </collision>
  </link>
  <link name="LFoot">
    <inertial>
      <origin rpy="0 0 0" xyz="-0.0077094563 -6.5520742e-05 -0.043453782"/>
      <mass value="2.0663292"/>
      <inertia ixx="0.0026932116" ixy="4.2852647e-06" ixz="0.00037001167" iyy="0.0071293752" iyz="-2.5956611e-06" izz="0.0086807822"/>
    </inertial>
    <visual>
      <origin rpy="0 0 0" xyz="0 0 0"/>
      <geometry name="LFoot_visual">
        <mesh filename="meshes/Foot2.stl" scale="0.001 0.001 0.001"/>
      </geometry>
      <material name="dark_grey"/>
    </visual>
    <collision>
      <origin rpy="0 0 0" xyz="0.0 0.0 -0.061"/>
      <geometry>
        <box size="0.21 0.11 0.015"/>
      </geometry>
    </collision>
  </link>
  <!-- JOINTS -->
  <joint name="LHipLat" type="continuous">
    <parent link="Waist"/>
    <child link="LHipMot"/>
    <origin rpy="0 0 0" xyz="0.01545 0.112 -0.05"/>
    <axis xyz="1 0 0"/>
    <limit effort="10000" lower="-0.523598775598" upper="1.65806278939" velocity="1000"/>
    <dynamics damping="1.0" friction="0"/>
  </joint>
  <joint name="LHipSag" type="continuous">
    <parent link="LHipMot"/>
    <child link="LThighUpLeg"/>
    <origin rpy="0 0 0" xyz="-0.059 0.07865 -0.1185"/>
    <axis xyz="0 1 0"/>
    <limit effort="10000" lower="-1.91986217719" upper="1.55334303428" velocity="1000"/>
    <dynamics damping="1.0" friction="0"/>
  </joint>
  <joint name="LHipYaw" type="continuous">
    <parent link="LThighUpLeg"/>
    <child link="LThighLowLeg"/>
    <origin rpy="0 0 0" xyz="0.0 -0.09 -0.25645"/>
    <axis xyz="0 0 1"/>
    <limit effort="10000" lower="-0.558505360638" upper="1.5707963268" velocity="1000"/>
    <dynamics damping="1.0" friction="0"/>
  </joint>
  <joint name="LKneePitch" type="continuous">
    <parent link="LThighLowLeg"/>
    <child link="LLowLeg"/>
    <origin rpy="0 0 0" xyz="-0.039 0.0641 -0.0607"/>
    <axis xyz="0 1 0"/>
    <limit effort="10000" lower="0.0" upper="2.44346095279" velocity="1000"/>
    <dynamics damping="1.0" friction="0"/>
  </joint>
  <!-- Here we do an assumption: Ankle Pitch can go -50/+40 while Ankle Roll -15/+15-->
  <joint name="LAnklePitch" type="continuous">
    <parent link="LLowLeg"/>
    <child link="LFootmot"/>
    <origin rpy="0 0 0" xyz="0.039 -0.0616 -0.425294"/>
    <axis xyz="0 1 0"/>
    <limit effort="10000" lower="-0.872664625997" upper="0.698131700798" velocity="1000"/>
    <dynamics damping="1.0" friction="0"/>
  </joint>
  <joint name="LAnkleRoll" type="continuous">
    <parent link="LFootmot"/>
    <child link="LFoot"/>
    <origin rpy="0 0 0" xyz="0 0 0"/>
    <axis xyz="1 0 0"/>
    <limit effort="10000" lower="-0.261799387799" upper="0.261799387799" velocity="1000"/>
    <dynamics damping="1.0" friction="0"/>
  </joint>
  <!-- LINKS -->
  <link name="RHipMot">
    <inertial>
      <origin rpy="0 0 0" xyz="-0.041435899 0.00024099021 -0.067437774"/>
      <mass value="2.0936467"/>
      <inertia ixx="0.010806924" ixy="-3.3743172e-05" ixz="-0.0013329083" iyy="0.011288691" iyz="-5.6918305e-05" izz="0.0053916798"/>
    </inertial>
    <visual>
      <origin rpy="0 0 0" xyz="0.0 0 0"/>
      <material name="green"/>
      <geometry name="RHipMot_visual">
        <mesh filename="meshes/HipRoll.stl" scale="0.001 -0.001 0.001"/>
      </geometry>
    </visual>
    <collision>
      <origin rpy="0 0 0." xyz="0.0 0. 0"/>
      <geometry name="RHipMot_collision">
        <mesh filename="meshes/simple/HipRoll.stl" scale="0.001 -0.001 0.001"/>
      </geometry>
    </collision>
  </link>
  <link name="RThighUpLeg">
    <inertial>
      <origin rpy="0 0 0" xyz="0.00058688639 0.062440385 -0.085057072"/>
      <mass value="1.6115687"/>
      <inertia ixx="0.016169151" ixy="2.1886129e-05" ixz="6.0058109e-05" iyy="0.0144378" iyz="0.0027173225" izz="0.0039254506"/>
    </inertial>
    <visual>
      <origin rpy="0 0 0." xyz="0. 0. 0."/>
      <material name="dark_grey"/>
      <geometry name="RThighUpLeg_visual">
        <mesh filename="meshes/HipPitch.stl" scale="0.001 -0.001 0.001"/>
      </geometry>
    </visual>
    <collision>
      <origin rpy="0 0 0." xyz="0.0 0. 0"/>
      <geometry name="RThighUpLeg_collision">
        <mesh filename="meshes/simple/HipPitch.stl" scale="0.001 -0.001 0.001"/>
      </geometry>
    </collision>
  </link>
  <link name="RThighLowLeg">
    <inertial>
      <origin rpy="0 0 0" xyz="-0.02113641 0.0042862386 -0.038232267"/>
      <mass value="1.7454681"/>
      <inertia ixx="0.0059857438" ixy="4.0155441e-05" ixz="-0.00080168603" iyy="0.0066483492" iyz="0.00011435964" izz="0.0044665032"/>
    </inertial>
    <visual>
      <origin rpy="0 0 0." xyz="0. 0. 0."/>
      <material name="green"/>
      <geometry name="RThighLowLeg_visual">
        <mesh filename="meshes/HipYaw.stl" scale="0.001 -0.001 0.001"/>
      </geometry>
    </visual>
    <collision>
      <origin rpy="0 0 0." xyz="0.0 0. 0"/>
      <geometry name="RThighLowLeg_collision">
        <mesh filename="meshes/simple/HipYaw.stl" scale="0.001 -0.001 0.001"/>
      </geometry>
    </collision>
  </link>
  <link name="RLowLeg">
    <inertial>
      <origin rpy="0 0 0" xyz="0.027363015 0.05780207 -0.19306454"/>
      <mass value="3.7014912"/>
      <inertia ixx="0.064669769" ixy="-0.00036914631" ixz="0.0053710941" iyy="0.063323486" iyz="0.0027319883" izz="0.0081842652"/>
    </inertial>
    <visual>
      <origin rpy="0 0 0." xyz="0. 0. 0."/>
      <material name="dark_grey"/>
      <geometry name="RLowLeg_visual">
        <mesh filename="meshes/KneePitch.stl" scale="0.001 -0.001 0.001"/>
      </geometry>
    </visual>
    <collision>
      <origin rpy="0 0 0." xyz="0.0 0. 0"/>
      <geometry name="RLowLeg_collision">
        <mesh filename="meshes/simple/KneePitch.stl" scale="0.001 -0.001 0.001"/>
      </geometry>
    </collision>
  </link>
  <link name="RFootmot">
    <inertial>
      <origin rpy="0 0 0" xyz="0.0011213007 0.00046152281 -1.144967e-06"/>
      <mass value="1.7723821e-01"/>
      <inertia ixx="2.8142035e-05" ixy="9.1715528e-08" ixz="-2.1701012e-10" iyy="9.7378402e-05" iyz="3.7303915e-10" izz="0.00011570584"/>
    </inertial>
    <visual>
      <origin rpy="0 0 0" xyz="0 0 0"/>
      <geometry name="RFootmot_visual">
        <mesh filename="meshes/AnklePitch.stl" scale="0.001 0.001 0.001"/>
      </geometry>
      <material name="dark_grey"/>
    </visual>
    <collision>
      <origin rpy="0 0 0" xyz="0 0 0"/>
      <geometry name="RFootmot_collision">
        <mesh filename="meshes/simple/AnklePitch.stl" scale="0.001 0.001 0.001"/>
      </geometry>
    </collision>
  </link>
  <link name="RFoot">
    <inertial>
      <origin rpy="0 0 0" xyz="-0.0077094563 -6.5520742e-05 -0.043453782"/>
      <mass value="2.0663292"/>
      <inertia ixx="0.0026932116" ixy="4.2852647e-06" ixz="0.00037001167" iyy="0.0071293752" iyz="-2.5956611e-06" izz="0.0086807822"/>
    </inertial>
    <visual>
      <origin rpy="0 0 0" xyz="0 0 0"/>
      <geometry name="LFoot_visual">
        <mesh filename="meshes/Foot2.stl" scale="0.001 0.001 0.001"/>
      </geometry>
      <material name="dark_grey"/>
    </visual>
    <collision>
      <origin rpy="0 0 0" xyz="0.0 0.0 -0.061"/>
      <geometry>
        <box size="0.21 0.11 0.015"/>
      </geometry>
    </collision>
  </link>
  <!-- JOINTS -->
  <joint name="RHipLat" type="continuous">
    <parent link="Waist"/>
    <child link="RHipMot"/>
    <origin rpy="0 0 0" xyz="0.01545 -0.112 -0.05"/>
    <axis xyz="1 0 0"/>
    <limit effort="10000" lower="-1.65806278939" upper="0.523598775598" velocity="1000"/>
    <dynamics damping="1.0" friction="0"/>
  </joint>
  <joint name="RHipSag" type="continuous">
    <parent link="RHipMot"/>
    <child link="RThighUpLeg"/>
    <origin rpy="0 0 0" xyz="-0.059 -0.07865 -0.1185"/>
    <axis xyz="0 1 0"/>
    <limit effort="10000" lower="-1.91986217719" upper="1.55334303428" velocity="1000"/>
    <dynamics damping="1.0" friction="0"/>
  </joint>
  <joint name="RHipYaw" type="continuous">
    <parent link="RThighUpLeg"/>
    <child link="RThighLowLeg"/>
    <origin rpy="0 0 0" xyz="0.0 0.09 -0.25645"/>
    <axis xyz="0 0 1"/>
    <limit effort="10000" lower="-1.5707963268" upper="0.558505360638" velocity="1000"/>
    <dynamics damping="1.0" friction="0"/>
  </joint>
  <joint name="RKneePitch" type="continuous">
    <parent link="RThighLowLeg"/>
    <child link="RLowLeg"/>
    <origin rpy="0 0 0" xyz="-0.039 -0.0641 -0.0607"/>
    <axis xyz="0 1 0"/>
    <limit effort="10000" lower="0.0" upper="2.44346095279" velocity="1000"/>
    <dynamics damping="1.0" friction="0"/>
  </joint>
  <!-- Here we do an assumption: Ankle Pitch can go -50/+40 while Ankle Roll -15/+15-->
  <joint name="RAnklePitch" type="continuous">
    <parent link="RLowLeg"/>
    <child link="RFootmot"/>
    <origin rpy="0 0 0" xyz="0.039 0.0616 -0.425294"/>
    <axis xyz="0 1 0"/>
    <limit effort="10000" lower="-0.872664625997" upper="0.698131700798" velocity="1000"/>
    <dynamics damping="1.0" friction="0"/>
  </joint>
  <joint name="RAnkleRoll" type="continuous">
    <parent link="RFootmot"/>
    <child link="RFoot"/>
    <origin rpy="0 0 0" xyz="0 0 0"/>
    <axis xyz="1 0 0"/>
    <limit effort="10000" lower="-0.261799387799" upper="0.261799387799" velocity="1000"/>
    <dynamics damping="1.0" friction="0"/>
  </joint>
  <!-- weight position -->
  <!-- LINKS -->
  <link name="DWL">
    <inertial>
      <origin rpy="0 0 0" xyz="0.039412845 0.00031221526 0.0056331027 "/>
      <mass value="7.4182685e-01"/>
      <inertia ixx="0.00094437073" ixy="4.8511769e-06" ixz="0.00010757639" iyy="0.0015988107" iyz="-1.104754e-05" izz="0.0015042997"/>
    </inertial>
    <visual>
      <origin rpy="0 0 0" xyz="0.0 0.0 0.0"/>
      <geometry name="DWL_visual">
        <mesh filename="meshes/TorsoRoll.stl" scale="0.001 0.001 0.001"/>
      </geometry>
      <material name="dark_grey"/>
    </visual>
    <collision>
      <origin rpy="0 0 0" xyz="0.0 0.0 0.0"/>
      <geometry name="DWL_collision">
        <mesh filename="meshes/simple/TorsoRoll.stl" scale="0.001 0.001 0.001"/>
      </geometry>
    </collision>
  </link>
  <link name="weight">
    <inertial>
      <origin rpy="0 0 0" xyz="0 0 0 "/>
      <mass value="30.0"/>
      <inertia ixx="0.0316875" ixy="0" ixz="0" iyy="0.0316875" iyz="0" izz="0.045375"/>
    </inertial>
    <visual>
      <origin rpy="0 0 0" xyz="0 0 0"/>
      <geometry>
        <cylinder length="0.06" radius="0.055"/>
      </geometry>
    </visual>
    <collision>
      <origin rpy="0 0 0" xyz="0 0 0"/>
      <geometry>
        <cylinder length="0.06" radius="0.055"/>
      </geometry>
    </collision>
  </link>
  <link name="pennacchio">
    <inertial>
      <origin rpy="0 0 0" xyz="-3.4081174e-06 -3.4081174e-06 0.17247336 "/>
      <mass value="2.1651618"/>
      <inertia ixx="0.045713534" ixy="1.9747985e-08" ixz="5.9794097e-07" iyy="0.045712755" iyz="-2.6722676e-07" izz="0.00060311791"/>
    </inertial>
    <visual>
      <origin rpy="0 0 0" xyz="0.0 0.0 0.0"/>
      <geometry name="pennacchio_visual">
        <mesh filename="meshes/Pennacchio.stl" scale="0.001 0.001 0.001"/>
      </geometry>
      <material name="dark_grey"/>
    </visual>
    <collision>
      <origin rpy="0 0 0" xyz="0.0 0.0 0.0"/>
      <geometry name="pennacchio_collision">
        <mesh filename="meshes/simple/Pennacchio.stl" scale="0.001 0.001 0.001"/>
      </geometry>
    </collision>
  </link>
  <joint name="WaistLat" type="fixed">
    <parent link="Waist"/>
    <child link="DWL"/>
    <origin rpy="0 0 0" xyz="0.012 0.0 0.0"/>
    <axis xyz="1 0 0"/>
    <limit effort="140" lower="-0.523598775598" upper="0.523598775598" velocity="7.4"/>
    <dynamics damping="3.0" friction="0"/>
  </joint>
  <joint name="pennacchio_frame" type="fixed">
    <parent link="DWL"/>
    <child link="pennacchio"/>
    <origin rpy="0 0 0" xyz="-0.0540957 0.0 0.0665"/>
  </joint>
  <joint name="weight_frame" type="fixed">
    <parent link="pennacchio"/>
    <child link="weight"/>
    <origin rpy="0 0 0" xyz="0. 0. 0.2"/>
  </joint>
  <!--xacro:property name="PI" value="3.14159265359" />
<xacro:property name="mmTom" value="0.001" />
<xacro:property name="mm2Tom2" value="${0.001*0.001}" /-->
  <!--xacro:property name="PI" value="3.14159265359" />
<xacro:property name="PI_2" value="1.57079632679" /-->
  <!-- ************ REF FRAMES **************** -->
  <!--<xacro:include filename="$(find cogimon_urdf)/urdf/parts/feet_reference_frames.urdf.xacro"/>-->
  <!--<xacro:include filename="$(find cogimon_urdf)/urdf/parts/arms_reference_frames.urdf.xacro"/>-->
  <!--<link name="world"/>-->
  <!--<joint name="reference" type="floating">-->
  <!--<parent link="world"/>-->
  <!--<child link="base_link"/>-->
  <!--</joint>-->
</robot>

