<?xml version="1.0"?>
<!-- created by Brian: diameter=33mm, height=34mm, the dimensions of the different parts and the mass values are
random -->
<!-- solid cylinder: i_xx = i_yy = i_zz = 1/12 * m * (3*r^2 + h^2) -->

<robot name="kilobot">

    <link name="base_link">
        <inertial>
          <origin xyz="0. 0. 0.02" />
          <mass value="0.08"/>
          <inertia ixx="3.220667e-05"  ixy="0.0"  ixz="0.0" iyy="3.220667e-05" iyz="0.0" izz="3.220667e-05" />
        </inertial>
        <visual>
            <geometry>
                <cylinder length="0.002" radius="0.0165"/>
            </geometry>
            <origin xyz="0.0 0.0 0.015"/>
            <material name="green_pcb">
                <color rgba="0.23 0.4 0.16 1.0"/>
            </material>
        </visual>
        <collision>
          <geometry>
            <cylinder length="0.002" radius="0.0165"/>
          </geometry>
          <origin xyz="0.0 0.0 0.015"/>
        </collision>
    </link>

    <link name="front_leg">
        <inertial>
          <mass value="0.001"/>
          <inertia ixx="3.220667e-05"  ixy="0.0"  ixz="0.0" iyy="3.220667e-05" iyz="0.0" izz="3.220667e-05" />
        </inertial>
        <visual>
            <geometry>
                <cylinder length="0.02" radius="0.0005"/>
            </geometry>
            <material name="gold">
                <color rgba="1.0 0.84 0.0 1.0"/>
            </material>
        </visual>
        <collision>
          <geometry>
            <cylinder length="0.02" radius="0.0005"/>
          </geometry>
        </collision>
    </link>

    <joint name="base_to_front_leg" type="fixed">
        <parent link="base_link"/>
        <child link="front_leg"/>
        <origin xyz="0.0165 0.0 0.0"/>
    </joint>

    <link name="left_leg">
        <inertial>
          <mass value="0.001"/>
          <inertia ixx="3.220667e-05"  ixy="0.0"  ixz="0.0" iyy="3.220667e-05" iyz="0.0" izz="3.220667e-05" />
        </inertial>
        <visual>
            <geometry>
                <cylinder length="0.02" radius="0.0005"/>
            </geometry>
            <material name="gold">
                <color rgba="1.0 0.84 0.0 1.0"/>
            </material>
        </visual>
        <collision>
          <geometry>
            <cylinder length="0.02" radius="0.0005"/>
          </geometry>
        </collision>
    </link>

    <joint name="base_to_left_leg" type="fixed">
        <parent link="base_link"/>
        <child link="left_leg"/>
        <origin xyz="-0.01166726 0.0116672 0.0"/>
    </joint>

    <link name="right_leg">
        <inertial>
          <mass value="0.001"/>
          <inertia ixx="3.220667e-05"  ixy="0.0"  ixz="0.0" iyy="3.220667e-05" iyz="0.0" izz="3.220667e-05" />
        </inertial>
        <visual>
            <geometry>
                <cylinder length="0.02" radius="0.0005"/>
            </geometry>
            <material name="gold">
                <color rgba="1.0 0.84 0.0 1.0"/>
            </material>
        </visual>
        <collision>
          <geometry>
            <cylinder length="0.02" radius="0.0005"/>
          </geometry>
        </collision>
    </link>

    <joint name="base_to_right_leg" type="fixed">
        <parent link="base_link"/>
        <child link="right_leg"/>
        <origin xyz="-0.01166726 -0.0116672 0.0"/>
    </joint>

    <link name="right_vibration_motor">
        <inertial>
          <origin rpy="0 1.57075 0"/>
          <mass value="0.02"/>
          <inertia ixx="2.006667e-06"  ixy="0.0"  ixz="0.0" iyy="2.006667e-06" iyz="0.0" izz="2.006667e-06" />
        </inertial>
        <visual>
            <geometry>
                <cylinder length="0.0015" radius="0.004"/>
            </geometry>
            <origin rpy="0 1.57075 0"/>
            <material name="light_grey">
                <color rgba="0.8 0.8 0.8 1"/>
            </material>
        </visual>
        <collision>
          <geometry>
            <cylinder length="0.0015" radius="0.004"/>
          </geometry>
          <origin rpy="0 1.57075 0"/>
        </collision>
    </link>

    <joint name="base_to_right_vibration_motor" type="continuous">
        <parent link="base_link"/>
        <child link="right_vibration_motor"/>
        <origin rpy="0 0 -0.7853981633974483" xyz="0.0077782 -0.0077782 0.022"/>
        <axis xyz="1 1 0"/>
    </joint>

    <link name="left_vibration_motor">
        <inertial>
          <origin rpy="0 1.57075 0"/>
          <mass value="0.02"/>
          <inertia ixx="2.006667e-06"  ixy="0.0"  ixz="0.0" iyy="2.006667e-06" iyz="0.0" izz="2.006667e-06" />
        </inertial>
        <visual>
            <geometry>
                <cylinder length="0.0015" radius="0.004"/>
            </geometry>
            <origin rpy="0 1.57075 0"/>
            <material name="light_grey">
                <color rgba="0.8 0.8 0.8 1"/>
            </material>
        </visual>
        <collision>
          <geometry>
            <cylinder length="0.0015" radius="0.004"/>
          </geometry>
          <origin rpy="0 1.57075 0"/>
        </collision>
    </link>

    <joint name="base_to_left_vibration_motor" type="continuous">
        <parent link="base_link"/>
        <child link="left_vibration_motor"/>
        <origin rpy="0 0 0.7853981633974483" xyz="0.0077782 0.0077782 0.022"/>
        <axis xyz="1 -1 0"/>
    </joint>

    <link name="body_top">
        <inertial>
          <mass value="0.03"/>
          <inertia ixx="1.02775e-5"  ixy="0.0"  ixz="0.0" iyy="1.02775e-5" iyz="0.0" izz="1.02775e-5" />
        </inertial>
        <visual>
            <geometry>
                <cylinder length="0.008" radius="0.01"/>
            </geometry>
            <material name="black">
                <color rgba="0.0 0.0 0.0 1"/>
            </material>
        </visual>
        <collision>
          <geometry>
            <cylinder length="0.008" radius="0.01"/>
          </geometry>
        </collision>
    </link>

    <joint name="base_to_body_top" type="fixed">
        <parent link="base_link"/>
        <child link="body_top"/>
        <origin xyz="0.0 0.0 0.022"/>
    </joint>

</robot>
