<?xml version="1.0" ?>
<!-- =================================================================================== -->
<!-- |    This document was autogenerated by xacro from kit_c.xacro                    | -->
<!-- |    EDITING THIS FILE BY HAND IS NOT RECOMMENDED                                 | -->
<!-- =================================================================================== -->
<robot name="quad" xmlns:xacro="http://ros.org/wiki/xacro">
  <!-- Properties -->
  <!-- "propeller" -->
  <!-- [kg] -->
  <!-- [m] -->
  <!-- [m] -->
  <!-- [kg] -->
  <!-- [m] -->
  <!-- [m] -->
  <!-- [m] -->
  <!-- [kg.m/s^2] -->
  <!-- [m] -->
  <!-- [s] -->
  <!-- [s] -->
  <!-- [rad/s] -->
  <!-- Property Blocks -->
  <!-- inertia of a single rotor, assuming it is a cuboid. Height=3mm, width=15mm -->
  <!-- Included URDF Files -->
  <!-- Main multirotor link -->
  <!-- Rotor joint and link -->
  <!-- Instantiate multirotor_base_macro once -->
  <link name="base_link">
    <inertial>
      <origin rpy="0 0 0" xyz="0 0 0"/>
      <mass value="1e-6"/>
      <inertia ixx="1e-12" ixy="0.0" ixz="0.0" iyy="1e-12" iyz="0.0" izz="1e-12"/>
    </inertial>
  </link> <!-- in pybullet, the inertia need to be specified even for dummy links, otherwise it will put an identity inertia and a mass of 1 by default -->
  <joint name="base_joint" type="fixed">
    <origin rpy="0 0 0" xyz="0 0 0"/>
    <parent link="base_link"/>
    <child link="base_link_inertia"/>
  </joint>
  <link name="base_link_inertia">
    <inertial>
      <mass value="1.4"/>
      <!-- [kg] -->
      <origin xyz="0 0 0"/>
      <inertia ixx="0.05" ixy="0.0" ixz="0.0" iyy="0.05" iyz="0.0" izz="0.24"/>
    </inertial>
    <visual>
      <origin rpy="0 0 0" xyz="0 0 0"/>
      <geometry>
        <mesh filename="meshes/hummingbird.dae" scale="1 1 1"/>
        <!-- <box size="${body_width} ${body_width} ${body_height}"/> -->
        <!-- [m] [m] [m] -->
      </geometry>
    </visual>
    <collision>
      <origin rpy="0 0 0" xyz="0 0 0"/>
      <geometry>
        <box size="0.3 0.3 0.17"/>
        <!-- [m] [m] [m] -->
      </geometry>
    </collision>
  </link>
  <!-- attach multirotor_base_plugin to the base_link -->
  <gazebo>
    <plugin filename="librotors_gazebo_multirotor_base_plugin.so" name="rosbag">
      <robotNamespace>quad</robotNamespace>
      <linkName>base_link</linkName>
      <rotorVelocitySlowdownSim>10</rotorVelocitySlowdownSim>
    </plugin>
  </gazebo>
  <gazebo reference="base_link">
    <material>Gazebo/DarkGrey</material>
  </gazebo>
  <!-- Instantiate rotors -->
  <joint name="rotor_0_joint" type="continuous">
    <origin rpy="0 0 0" xyz="0.17 0 0.01"/>
    <axis xyz="0 0 1"/>
    <!-- TODO(ff): not currently set because it's not yet supported -->
    <!-- <limit effort="2000" velocity="${max_rot_velocity}" /> -->
    <parent link="base_link"/>
    <child link="rotor_0"/>
  </joint>
  <!-- TODO(ff): not currently set because it's not yet supported -->
  <!-- <gazebo reference="rotor_${motor_number}_joint"> <axis> <xyz>0 0 1</xyz>
      <limit> <velocity> ${max_rot_velocity} </velocity> </limit> </axis> </gazebo> -->
  <link name="rotor_0">
    <inertial>
      <mass value="0.005"/>
      <!-- [kg] -->
      <inertia ixx="9.75e-07" ixy="0.0" ixz="0.0" iyy="0.000326704166667" iyz="0.0" izz="0.000327604166667"/>
    </inertial>
    <visual>
      <geometry>
        <!-- <cylinder length="0.005" radius="${radius_rotor}"/> -->
        <!-- [m] -->
        <!-- <mesh filename="meshes/propeller_${direction}.dae" -->
        <mesh filename="meshes/propeller_ccw.dae" scale=".12 .12 .12"/>
        <!-- <box size="${2*radius_rotor} 0.01 0.005"/> -->
      </geometry>
    </visual>
    <collision>
      <geometry>
        <cylinder length="0.005" radius="0.14"/>
        <!-- [m] -->
      </geometry>
    </collision>
  </link>
  <gazebo>
    <plugin filename="librotors_gazebo_motor_model.so" name="front_motor_model">
      <robotNamespace>quad</robotNamespace>
      <jointName>rotor_0_joint</jointName>
      <linkName>rotor_0</linkName>
      <turningDirection>ccw</turningDirection>
      <timeConstantUp>0.15</timeConstantUp>
      <timeConstantDown>0.15</timeConstantDown>
      <maxRotVelocity>770</maxRotVelocity>
      <motorConstant>2.39e-05</motorConstant>
      <momentConstant>0.016</momentConstant>
      <commandSubTopic>gazebo/command/motor_speed</commandSubTopic>
      <motorNumber>0</motorNumber>
      <rotorDragCoefficient>1.3858e-06</rotorDragCoefficient>
      <rollingMomentCoefficient>1e-06</rollingMomentCoefficient>
      <motorSpeedPubTopic>motor_speed/0</motorSpeedPubTopic>
      <rotorVelocitySlowdownSim>10</rotorVelocitySlowdownSim>
    </plugin>
  </gazebo>
  <gazebo reference="rotor_0">
    <material>Gazebo/Blue</material>
  </gazebo>
  <joint name="rotor_1_joint" type="continuous">
    <origin rpy="0 0 0" xyz="0 -0.17 0.01"/>
    <axis xyz="0 0 1"/>
    <!-- TODO(ff): not currently set because it's not yet supported -->
    <!-- <limit effort="2000" velocity="${max_rot_velocity}" /> -->
    <parent link="base_link"/>
    <child link="rotor_1"/>
  </joint>
  <!-- TODO(ff): not currently set because it's not yet supported -->
  <!-- <gazebo reference="rotor_${motor_number}_joint"> <axis> <xyz>0 0 1</xyz>
      <limit> <velocity> ${max_rot_velocity} </velocity> </limit> </axis> </gazebo> -->
  <link name="rotor_1">
    <inertial>
      <mass value="0.005"/>
      <!-- [kg] -->
      <inertia ixx="9.75e-07" ixy="0.0" ixz="0.0" iyy="0.000326704166667" iyz="0.0" izz="0.000327604166667"/>
    </inertial>
    <visual>
      <geometry>
        <!-- <cylinder length="0.005" radius="${radius_rotor}"/> -->
        <!-- [m] -->
        <!-- <mesh filename="meshes/propeller_${direction}.dae" -->
        <mesh filename="meshes/propeller_cw.dae" scale=".12 .12 .12"/>
        <!-- <box size="${2*radius_rotor} 0.01 0.005"/> -->
      </geometry>
    </visual>
    <collision>
      <geometry>
        <cylinder length="0.005" radius="0.14"/>
        <!-- [m] -->
      </geometry>
    </collision>
  </link>
  <gazebo>
    <plugin filename="librotors_gazebo_motor_model.so" name="right_motor_model">
      <robotNamespace>quad</robotNamespace>
      <jointName>rotor_1_joint</jointName>
      <linkName>rotor_1</linkName>
      <turningDirection>cw</turningDirection>
      <timeConstantUp>0.15</timeConstantUp>
      <timeConstantDown>0.15</timeConstantDown>
      <maxRotVelocity>770</maxRotVelocity>
      <motorConstant>2.39e-05</motorConstant>
      <momentConstant>0.016</momentConstant>
      <commandSubTopic>gazebo/command/motor_speed</commandSubTopic>
      <motorNumber>1</motorNumber>
      <rotorDragCoefficient>1.3858e-06</rotorDragCoefficient>
      <rollingMomentCoefficient>1e-06</rollingMomentCoefficient>
      <motorSpeedPubTopic>motor_speed/1</motorSpeedPubTopic>
      <rotorVelocitySlowdownSim>10</rotorVelocitySlowdownSim>
    </plugin>
  </gazebo>
  <gazebo reference="rotor_1">
    <material>Gazebo/Grey</material>
  </gazebo>
  <joint name="rotor_2_joint" type="continuous">
    <origin rpy="0 0 0" xyz="-0.17 0 0.01"/>
    <axis xyz="0 0 1"/>
    <!-- TODO(ff): not currently set because it's not yet supported -->
    <!-- <limit effort="2000" velocity="${max_rot_velocity}" /> -->
    <parent link="base_link"/>
    <child link="rotor_2"/>
  </joint>
  <!-- TODO(ff): not currently set because it's not yet supported -->
  <!-- <gazebo reference="rotor_${motor_number}_joint"> <axis> <xyz>0 0 1</xyz>
      <limit> <velocity> ${max_rot_velocity} </velocity> </limit> </axis> </gazebo> -->
  <link name="rotor_2">
    <inertial>
      <mass value="0.005"/>
      <!-- [kg] -->
      <inertia ixx="9.75e-07" ixy="0.0" ixz="0.0" iyy="0.000326704166667" iyz="0.0" izz="0.000327604166667"/>
    </inertial>
    <visual>
      <geometry>
        <!-- <cylinder length="0.005" radius="${radius_rotor}"/> -->
        <!-- [m] -->
        <!-- <mesh filename="meshes/propeller_${direction}.dae" -->
        <mesh filename="meshes/propeller_ccw.dae" scale=".12 .12 .12"/>
        <!-- <box size="${2*radius_rotor} 0.01 0.005"/> -->
      </geometry>
    </visual>
    <collision>
      <geometry>
        <cylinder length="0.005" radius="0.14"/>
        <!-- [m] -->
      </geometry>
    </collision>
  </link>
  <gazebo>
    <plugin filename="librotors_gazebo_motor_model.so" name="back_motor_model">
      <robotNamespace>quad</robotNamespace>
      <jointName>rotor_2_joint</jointName>
      <linkName>rotor_2</linkName>
      <turningDirection>ccw</turningDirection>
      <timeConstantUp>0.15</timeConstantUp>
      <timeConstantDown>0.15</timeConstantDown>
      <maxRotVelocity>770</maxRotVelocity>
      <motorConstant>2.39e-05</motorConstant>
      <momentConstant>0.016</momentConstant>
      <commandSubTopic>gazebo/command/motor_speed</commandSubTopic>
      <motorNumber>2</motorNumber>
      <rotorDragCoefficient>1.3858e-06</rotorDragCoefficient>
      <rollingMomentCoefficient>1e-06</rollingMomentCoefficient>
      <motorSpeedPubTopic>motor_speed/2</motorSpeedPubTopic>
      <rotorVelocitySlowdownSim>10</rotorVelocitySlowdownSim>
    </plugin>
  </gazebo>
  <gazebo reference="rotor_2">
    <material>Gazebo/Grey</material>
  </gazebo>
  <joint name="rotor_3_joint" type="continuous">
    <origin rpy="0 0 0" xyz="0 0.17 0.01"/>
    <axis xyz="0 0 1"/>
    <!-- TODO(ff): not currently set because it's not yet supported -->
    <!-- <limit effort="2000" velocity="${max_rot_velocity}" /> -->
    <parent link="base_link"/>
    <child link="rotor_3"/>
  </joint>
  <!-- TODO(ff): not currently set because it's not yet supported -->
  <!-- <gazebo reference="rotor_${motor_number}_joint"> <axis> <xyz>0 0 1</xyz>
      <limit> <velocity> ${max_rot_velocity} </velocity> </limit> </axis> </gazebo> -->
  <link name="rotor_3">
    <inertial>
      <mass value="0.005"/>
      <!-- [kg] -->
      <inertia ixx="9.75e-07" ixy="0.0" ixz="0.0" iyy="0.000326704166667" iyz="0.0" izz="0.000327604166667"/>
    </inertial>
    <visual>
      <geometry>
        <!-- <cylinder length="0.005" radius="${radius_rotor}"/> -->
        <!-- [m] -->
        <!-- <mesh filename="meshes/propeller_${direction}.dae" -->
        <mesh filename="meshes/propeller_cw.dae" scale=".12 .12 .12"/>
        <!-- <box size="${2*radius_rotor} 0.01 0.005"/> -->
      </geometry>
    </visual>
    <collision>
      <geometry>
        <cylinder length="0.005" radius="0.14"/>
        <!-- [m] -->
      </geometry>
    </collision>
  </link>
  <gazebo>
    <plugin filename="librotors_gazebo_motor_model.so" name="left_motor_model">
      <robotNamespace>quad</robotNamespace>
      <jointName>rotor_3_joint</jointName>
      <linkName>rotor_3</linkName>
      <turningDirection>cw</turningDirection>
      <timeConstantUp>0.15</timeConstantUp>
      <timeConstantDown>0.15</timeConstantDown>
      <maxRotVelocity>770</maxRotVelocity>
      <motorConstant>2.39e-05</motorConstant>
      <momentConstant>0.016</momentConstant>
      <commandSubTopic>gazebo/command/motor_speed</commandSubTopic>
      <motorNumber>3</motorNumber>
      <rotorDragCoefficient>1.3858e-06</rotorDragCoefficient>
      <rollingMomentCoefficient>1e-06</rollingMomentCoefficient>
      <motorSpeedPubTopic>motor_speed/3</motorSpeedPubTopic>
      <rotorVelocitySlowdownSim>10</rotorVelocitySlowdownSim>
    </plugin>
  </gazebo>
  <gazebo reference="rotor_3">
    <material>Gazebo/Grey</material>
  </gazebo>
</robot>
