<?xml version="1.0" ?>
<!-- =================================================================================== -->
<!-- |    This document was autogenerated by xacro from pepper_robot.xacro             | -->
<!-- |    EDITING THIS FILE BY HAND IS NOT RECOMMENDED                                 | -->
<!-- =================================================================================== -->
<!--******************************************************************
 ****** File automatically generated by generate_urdf.py script ******
 *********************************************************************-->
<robot name="JulietteY20MP" xmlns:xacro="http://www.ros.org/wiki/xacro">
  <material name="black">
    <color rgba="0.2 0.2 0.2 1"/>
  </material>
  <material name="white">
    <color rgba="0.9 0.9 0.9 1"/>
  </material>
  <material name="dark_gray">
    <color rgba="0.3 0.3 0.3 1"/>
  </material>
  <material name="gray">
    <color rgba="0.5 0.5 0.5 1"/>
  </material>
  <material name="light_gray">
    <color rgba="0.7 0.7 0.7 1"/>
  </material>
  <material name="pure_red">
    <color rgba="1.0 0.0 0.0 1"/>
  </material>
  <material name="red">
    <color rgba="0.5 0.1 0.2 1"/>
  </material>
  <material name="pure_green">
    <color rgba="0.0 1.0 0.0 1"/>
  </material>
  <material name="pure_blue">
    <color rgba="0.0 0.0 1.0 1"/>
  </material>
  <material name="blue">
    <color rgba="0.0 0.2 0.3 1"/>
  </material>

  <joint name="HeadYaw" type="revolute">
    <parent link="torso"/>
    <child link="Neck"/>
    <origin rpy="0 0 0" xyz="-0.038 0 0.1699"/>
    <axis xyz="0 0 1.0"/>
    <limit effort="5.428" lower="-2.08567" upper="2.08567" velocity="7.33998"/>
  </joint>
  <link name="Neck">
    <inertial>
      <mass value="0.27391"/>
      <inertia ixx="0.000343501" ixy="0" ixz="-1.88563e-05" iyy="0.000493898" iyz="2.09863e-06" izz="0.000215252"/>
      <origin rpy="0 0 0" xyz="-0.00207 0 -0.02636"/>
    </inertial>
    <visual>
      <material name="light_gray"/>
      <geometry>
        <mesh filename="meshes/1.0/HeadYaw.obj" scale="0.1 0.1 0.1"/>
      </geometry>
      <origin rpy="0 0 0" xyz="0 0 0"/>
    </visual>
    <collision>
      <geometry>
        <mesh filename="meshes/1.0/HeadYaw_0.10.stl" scale="0.1 0.1 0.1"/>
      </geometry>
      <origin rpy="0 0 0" xyz="0 0 0"/>
    </collision>
  </link>
  <joint name="HeadPitch" type="revolute">
    <parent link="Neck"/>
    <child link="Head"/>
    <origin rpy="0 0 0" xyz="0 0 0"/>
    <axis xyz="0 1.0 0"/>
    <limit effort="2.666" lower="-0.706858" upper="0.637045" velocity="9.22756"/>
  </joint>
  <link name="Head">
    <inertial>
      <mass value="1.51893"/>
      <inertia ixx="0.00597209" ixy="0" ixz="0.000125138" iyy="0.0059054" iyz="4.3428e-07" izz="0.00570374"/>
      <origin rpy="0 0 0" xyz="0.00312 0 0.11152"/>
    </inertial>
    <visual>
      <material name="white"/>
      <geometry>
        <mesh filename="meshes/1.0/HeadPitch.obj" scale="0.1 0.1 0.1"/>
      </geometry>
      <origin rpy="0 0 0" xyz="0 0 0"/>
    </visual>
    <collision>
      <geometry>
        <mesh filename="meshes/1.0/HeadPitch_0.10.stl" scale="0.1 0.1 0.1"/>
      </geometry>
      <origin rpy="0 0 0" xyz="0 0 0"/>
    </collision>
  </link>
  <joint name="HipRoll" type="revolute">
    <parent link="torso"/>
    <child link="Hip"/>
    <origin rpy="0 0 0" xyz="2e-05 0 -0.139"/>
    <axis xyz="1.0 0 0"/>
    <limit effort="10.1884" lower="-0.514872" upper="0.514872" velocity="2.27032"/>
  </joint>
  <link name="Hip">
    <inertial>
      <mass value="1.02338"/>
      <inertia ixx="0.00502422" ixy="0" ixz="-2.54911e-05" iyy="0.00640971" iyz="0.000159449" izz="0.00441082"/>
      <origin rpy="0 0 0" xyz="0.00032 0 -0.06039"/>
    </inertial>
    <visual>
      <material name="light_gray"/>
      <geometry>
        <mesh filename="meshes/1.0/HipRoll.obj" scale="0.1 0.1 0.1"/>
      </geometry>
      <origin rpy="0 0 0" xyz="0 0 0"/>
    </visual>
    <collision>
      <geometry>
        <mesh filename="meshes/1.0/HipRoll_0.10.stl" scale="0.1 0.1 0.1"/>
      </geometry>
      <origin rpy="0 0 0" xyz="0 0 0"/>
    </collision>
  </link>
  <joint name="HipPitch" type="revolute">
    <parent link="Hip"/>
    <child link="Pelvis"/>
    <origin rpy="0 0 0" xyz="0 0 -0.079"/>
    <axis xyz="0 1.0 0"/>
    <limit effort="19.787" lower="-1.03847" upper="1.03847" velocity="2.93276"/>
  </joint>
  <link name="Pelvis">
    <inertial>
      <mass value="2.45917"/>
      <inertia ixx="0.034351" ixy="0" ixz="0.000223034" iyy="0.0303122" iyz="-8.37542e-05" izz="0.0143771"/>
      <origin rpy="0 0 0" xyz="0.00237 0 -0.09654"/>
    </inertial>
    <visual>
      <material name="white"/>
      <geometry>
        <mesh filename="meshes/1.0/HipPitch.obj" scale="0.1 0.1 0.1"/>
      </geometry>
      <origin rpy="0 0 0" xyz="0 0 0"/>
    </visual>
    <collision>
      <geometry>
        <mesh filename="meshes/1.0/HipPitch_0.10.stl" scale="0.1 0.1 0.1"/>
      </geometry>
      <origin rpy="0 0 0" xyz="0 0 0"/>
    </collision>
  </link>
  <joint name="KneePitch" type="revolute">
    <parent link="Pelvis"/>
    <child link="Tibia"/>
    <origin rpy="0 0 0" xyz="0 0 -0.268"/>
    <axis xyz="0 1.0 0"/>
    <limit effort="27.702" lower="-0.514872" upper="0.514872" velocity="2.93276"/>
  </joint>
  <link name="Tibia">
    <inertial>
      <mass value="11.6015"/>
      <inertia ixx="0.129229" ixy="-0.000401943" ixz="0.00048556" iyy="0.122839" iyz="-1.01666e-08" izz="0.108168"/>
      <origin rpy="0 0 0" xyz="0.00220451 0 -0.185729"/>
    </inertial>
    <visual>
      <material name="white"/>
      <geometry>
        <mesh filename="meshes/1.0/KneePitch.obj" scale="0.1 0.1 0.1"/>
      </geometry>
      <origin rpy="0 0 0" xyz="0 0 0"/>
    </visual>
    <collision>
      <geometry>
        <mesh filename="meshes/1.0/KneePitch_0.10.stl" scale="0.1 0.1 0.1"/>
      </geometry>
      <origin rpy="0 0 0" xyz="0 0 0"/>
    </collision>
  </link>
  <joint name="base_footprint_joint" type="fixed">
    <parent link="Tibia"/>
    <child link="base_footprint"/>
    <origin rpy="0 0 0" xyz="0 0 -0.334"/>
  </joint>
  <link name="base_footprint">
    <inertial>
      <origin rpy="0 0 0" xyz="0 0 0"/>
      <mass value="0"/>
      <inertia ixx="0.0" ixy="0.0" ixz="0.0" iyy="0.0" iyz="0.0" izz="0.0"/>
    </inertial>
  </link> <!-- in pybullet, the inertia need to be specified even for dummy links, otherwise it will put an identity inertia and a mass of 1 by default -->
  <!--link name="base_link"/>
  <joint name="base_link_fixedjoint" type="fixed">
    <parent link="base_link"/>
    <child link="torso"/>
    <origin rpy="0 0 0" xyz="0 0 0"/>
    <axis xyz="0 0 0"/>
  </joint-->
  <link name="torso">
    <inertial>
      <mass value="3.99533"/>
      <inertia ixx="0.0452761" ixy="0" ixz="0.00499091" iyy="0.0432702" iyz="-0.000266886" izz="0.0258881"/>
      <origin rpy="0 0 0" xyz="0.00322 0 -0.01029"/>
    </inertial>
    <visual>
      <material name="white"/>
      <geometry>
        <mesh filename="meshes/1.0/Torso.obj" scale="0.1 0.1 0.1"/>
      </geometry>
      <origin rpy="0 0 0" xyz="0 0 0"/>
    </visual>
    <collision>
      <geometry>
        <mesh filename="meshes/1.0/Torso_0.10.stl" scale="0.1 0.1 0.1"/>
      </geometry>
      <origin rpy="0 0 0" xyz="0 0 0"/>
    </collision>
  </link>
  <joint name="LShoulderPitch" type="revolute">
    <parent link="torso"/>
    <child link="LShoulder"/>
    <origin rpy="0 0 0" xyz="-0.057 0.14974 0.08682"/>
    <axis xyz="0 1.0 0"/>
    <limit effort="5.428" lower="-2.08567" upper="2.08567" velocity="7.33998"/>
  </joint>
  <link name="LShoulder">
    <inertial>
      <mass value="0.3125"/>
      <inertia ixx="0.000361198" ixy="-1.98347e-06" ixz="6.35907e-07" iyy="0.000137229" iyz="-5.68878e-06" izz="0.000399194"/>
      <origin rpy="0 0 0" xyz="0.00018 -0.01856 0.00099"/>
    </inertial>
    <visual>
      <material name="light_gray"/>
      <geometry>
        <mesh filename="meshes/1.0/LShoulderPitch.obj" scale="0.1 0.1 0.1"/>
      </geometry>
      <origin rpy="0 0 0" xyz="0 0 0"/>
    </visual>
    <collision>
      <geometry>
        <mesh filename="meshes/1.0/LShoulderPitch_0.10.stl" scale="0.1 0.1 0.1"/>
      </geometry>
      <origin rpy="0 0 0" xyz="0 0 0"/>
    </collision>
  </link>
  <joint name="LShoulderRoll" type="revolute">
    <parent link="LShoulder"/>
    <child link="LBicep"/>
    <origin rpy="0 0 0" xyz="0 0 0"/>
    <axis xyz="0 0 1.0"/>
    <limit effort="2.666" lower="0.00872665" upper="1.56207" velocity="9.22756"/>
  </joint>
  <link name="LBicep">
    <inertial>
      <mass value="0.50527"/>
      <inertia ixx="0.000500872" ixy="-3.55918e-05" ixz="8.51263e-05" iyy="0.00126284" iyz="9.06813e-06" izz="0.00115718"/>
      <origin rpy="0 0 0" xyz="0.08151 0.01284 -0.01017"/>
    </inertial>
    <visual>
      <material name="white"/>
      <geometry>
        <mesh filename="meshes/1.0/LShoulderRoll.obj" scale="0.1 0.1 0.1"/>
      </geometry>
      <origin rpy="0 0 0" xyz="0 0 0"/>
    </visual>
    <collision>
      <geometry>
        <mesh filename="meshes/1.0/LShoulderRoll_0.10.stl" scale="0.1 0.1 0.1"/>
      </geometry>
      <origin rpy="0 0 0" xyz="0 0 0"/>
    </collision>
  </link>
  <joint name="LElbowYaw" type="revolute">
    <parent link="LBicep"/>
    <child link="LElbow"/>
    <origin rpy="0 -0.157079 0" xyz="0.1812 0.015 0.00013"/>
    <axis xyz="1.0 0 0"/>
    <limit effort="5.428" lower="-2.08567" upper="2.08567" velocity="7.33998"/>
  </joint>
  <link name="LElbow">
    <inertial>
      <mass value="0.27495"/>
      <inertia ixx="0.000122971" ixy="9.86024e-07" ixz="-2.55838e-05" iyy="0.000331766" iyz="-1.98925e-06" izz="0.000303047"/>
      <origin rpy="0 0 0" xyz="-0.02297 -0.00019 0.00119"/>
    </inertial>
    <visual>
      <material name="light_gray"/>
      <geometry>
        <mesh filename="meshes/1.0/LElbowYaw.obj" scale="0.1 0.1 0.1"/>
      </geometry>
      <origin rpy="0 0 0" xyz="0 0 0"/>
    </visual>
    <collision>
      <geometry>
        <mesh filename="meshes/1.0/LElbowYaw_0.10.stl" scale="0.1 0.1 0.1"/>
      </geometry>
      <origin rpy="0 0 0" xyz="0 0 0"/>
    </collision>
  </link>
  <joint name="LElbowRoll" type="revolute">
    <parent link="LElbow"/>
    <child link="LForeArm"/>
    <origin rpy="0 0 0" xyz="0 0 0"/>
    <axis xyz="0 0 1.0"/>
    <limit effort="2.666" lower="-1.56207" upper="-0.00872665" velocity="9.22756"/>
  </joint>
  <link name="LForeArm">
    <inertial>
      <mass value="0.16579"/>
      <inertia ixx="0.00156513" ixy="1.47517e-05" ixz="-6.05746e-05" iyy="0.00173219" iyz="-1.7619e-07" izz="0.000273081"/>
      <origin rpy="0 0 0" xyz="0.0593 0.00271 -0.01014"/>
    </inertial>
    <visual>
      <material name="white"/>
      <geometry>
        <mesh filename="meshes/1.0/LElbowRoll.obj" scale="0.1 0.1 0.1"/>
      </geometry>
      <origin rpy="0 0 0" xyz="0 0 0"/>
    </visual>
    <collision>
      <geometry>
        <mesh filename="meshes/1.0/LElbowRoll_0.10.stl" scale="0.1 0.1 0.1"/>
      </geometry>
      <origin rpy="0 0 0" xyz="0 0 0"/>
    </collision>
  </link>
  <joint name="LWristYaw" type="revolute">
    <parent link="LForeArm"/>
    <child link="l_wrist"/>
    <origin rpy="0 0 0" xyz="0.15 0 0"/>
    <axis xyz="1.0 0 0"/>
    <limit effort="0.2014" lower="-1.82387" upper="1.82387" velocity="17.3835"/>
  </joint>
  <link name="l_wrist">
    <inertial>
      <mass value="0.27555"/>
      <inertia ixx="0.000151643" ixy="1.06629e-05" ixz="2.89509e-06" iyy="0.000431099" iyz="-3.13715e-06" izz="0.000456172"/>
      <origin rpy="0 0 0" xyz="0.03536 -0.00072 -0.00207"/>
    </inertial>
    <visual>
      <material name="white"/>
      <geometry>
        <mesh filename="meshes/1.0/LWristYaw.obj" scale="0.1 0.1 0.1"/>
      </geometry>
      <origin rpy="0 0 0" xyz="0 0 0"/>
    </visual>
    <collision>
      <geometry>
        <mesh filename="meshes/1.0/LWristYaw_0.10.stl" scale="0.1 0.1 0.1"/>
      </geometry>
      <origin rpy="0 0 0" xyz="0 0 0"/>
    </collision>
  </link>
  <joint name="LHand" type="revolute">
    <parent link="l_wrist"/>
    <child link="l_gripper"/>
    <origin rpy="0 0 0" xyz="0.025 0 0"/>
    <axis xyz="1.0 0 0"/>
    <limit effort="0.144" lower="0.02" upper="0.98" velocity="12.56"/>
  </joint>
  <link name="l_gripper">
    <inertial>
      <mass value="2e-06"/>
      <inertia ixx="1.1e-09" ixy="0" ixz="0" iyy="1.1e-09" iyz="0" izz="1.1e-09"/>
    </inertial>
  </link>
  <joint name="RShoulderPitch" type="revolute">
    <parent link="torso"/>
    <child link="RShoulder"/>
    <origin rpy="0 0 0" xyz="-0.057 -0.14974 0.08682"/>
    <axis xyz="0 1.0 0"/>
    <limit effort="5.428" lower="-2.08567" upper="2.08567" velocity="7.33998"/>
  </joint>
  <link name="RShoulder">
    <inertial>
      <mass value="0.3125"/>
      <inertia ixx="0.000361198" ixy="1.98347e-06" ixz="6.35907e-07" iyy="0.000137229" iyz="5.68878e-06" izz="0.000399194"/>
      <origin rpy="0 0 0" xyz="0.00018 0.01856 0.00099"/>
    </inertial>
    <visual>
      <material name="light_gray"/>
      <geometry>
        <mesh filename="meshes/1.0/RShoulderPitch.obj" scale="0.1 0.1 0.1"/>
      </geometry>
      <origin rpy="0 0 0" xyz="0 0 0"/>
    </visual>
    <collision>
      <geometry>
        <mesh filename="meshes/1.0/RShoulderPitch_0.10.stl" scale="0.1 0.1 0.1"/>
      </geometry>
      <origin rpy="0 0 0" xyz="0 0 0"/>
    </collision>
  </link>
  <joint name="RShoulderRoll" type="revolute">
    <parent link="RShoulder"/>
    <child link="RBicep"/>
    <origin rpy="0 0 0" xyz="0 0 0"/>
    <axis xyz="0 0 1.0"/>
    <limit effort="2.666" lower="-1.56207" upper="-0.00872665" velocity="9.22756"/>
  </joint>
  <link name="RBicep">
    <inertial>
      <mass value="0.50527"/>
      <inertia ixx="0.000500872" ixy="3.55918e-05" ixz="8.51263e-05" iyy="0.00126284" iyz="-9.06813e-06" izz="0.00115718"/>
      <origin rpy="0 0 0" xyz="0.08151 -0.01284 -0.01017"/>
    </inertial>
    <visual>
      <material name="white"/>
      <geometry>
        <mesh filename="meshes/1.0/RShoulderRoll.obj" scale="0.1 0.1 0.1"/>
      </geometry>
      <origin rpy="0 0 0" xyz="0 0 0"/>
    </visual>
    <collision>
      <geometry>
        <mesh filename="meshes/1.0/RShoulderRoll_0.10.stl" scale="0.1 0.1 0.1"/>
      </geometry>
      <origin rpy="0 0 0" xyz="0 0 0"/>
    </collision>
  </link>
  <joint name="RElbowYaw" type="revolute">
    <parent link="RBicep"/>
    <child link="RElbow"/>
    <origin rpy="0 -0.157079 0" xyz="0.1812 -0.015 0.00013"/>
    <axis xyz="1.0 0 0"/>
    <limit effort="5.428" lower="-2.08567" upper="2.08567" velocity="7.33998"/>
  </joint>
  <link name="RElbow">
    <inertial>
      <mass value="0.27495"/>
      <inertia ixx="0.000122971" ixy="-9.86024e-07" ixz="-2.55838e-05" iyy="0.000331766" iyz="1.98925e-06" izz="0.000303047"/>
      <origin rpy="0 0 0" xyz="-0.02297 0.00019 0.00119"/>
    </inertial>
    <visual>
      <material name="light_gray"/>
      <geometry>
        <mesh filename="meshes/1.0/RElbowYaw.obj" scale="0.1 0.1 0.1"/>
      </geometry>
      <origin rpy="0 0 0" xyz="0 0 0"/>
    </visual>
    <collision>
      <geometry>
        <mesh filename="meshes/1.0/RElbowYaw_0.10.stl" scale="0.1 0.1 0.1"/>
      </geometry>
      <origin rpy="0 0 0" xyz="0 0 0"/>
    </collision>
  </link>
  <joint name="RElbowRoll" type="revolute">
    <parent link="RElbow"/>
    <child link="RForeArm"/>
    <origin rpy="0 0 0" xyz="0 0 0"/>
    <axis xyz="0 0 1.0"/>
    <limit effort="2.666" lower="0.00872665" upper="1.56207" velocity="9.22756"/>
  </joint>
  <link name="RForeArm">
    <inertial>
      <mass value="0.16579"/>
      <inertia ixx="0.00156513" ixy="-1.47517e-05" ixz="-6.05746e-05" iyy="0.00173219" iyz="1.7619e-07" izz="0.000273081"/>
      <origin rpy="0 0 0" xyz="0.0593 -0.00271 -0.01014"/>
    </inertial>
    <visual>
      <material name="white"/>
      <geometry>
        <mesh filename="meshes/1.0/RElbowRoll.obj" scale="0.1 0.1 0.1"/>
      </geometry>
      <origin rpy="0 0 0" xyz="0 0 0"/>
    </visual>
    <collision>
      <geometry>
        <mesh filename="meshes/1.0/RElbowRoll_0.10.stl" scale="0.1 0.1 0.1"/>
      </geometry>
      <origin rpy="0 0 0" xyz="0 0 0"/>
    </collision>
  </link>
  <joint name="RWristYaw" type="revolute">
    <parent link="RForeArm"/>
    <child link="r_wrist"/>
    <origin rpy="0 0 0" xyz="0.15 0 0"/>
    <axis xyz="1.0 0 0"/>
    <limit effort="0.2014" lower="-1.82387" upper="1.82387" velocity="17.3835"/>
  </joint>
  <link name="r_wrist">
    <inertial>
      <mass value="0.27555"/>
      <inertia ixx="0.000151643" ixy="-1.06629e-05" ixz="2.89509e-06" iyy="0.000431099" iyz="3.13715e-06" izz="0.000456172"/>
      <origin rpy="0 0 0" xyz="0.03536 0.00072 -0.00207"/>
    </inertial>
    <visual>
      <material name="white"/>
      <geometry>
        <mesh filename="meshes/1.0/RWristYaw.obj" scale="0.1 0.1 0.1"/>
      </geometry>
      <origin rpy="0 0 0" xyz="0 0 0"/>
    </visual>
    <collision>
      <geometry>
        <mesh filename="meshes/1.0/RWristYaw_0.10.stl" scale="0.1 0.1 0.1"/>
      </geometry>
      <origin rpy="0 0 0" xyz="0 0 0"/>
    </collision>
  </link>
  <joint name="RHand" type="revolute">
    <parent link="r_wrist"/>
    <child link="r_gripper"/>
    <origin rpy="0 0 0" xyz="0.025 0 0"/>
    <axis xyz="1.0 0 0"/>
    <limit effort="0.144" lower="0.02" upper="0.98" velocity="12.56"/>
  </joint>
  <link name="r_gripper">
    <inertial>
      <mass value="2e-06"/>
      <inertia ixx="1.1e-09" ixy="0" ixz="0" iyy="1.1e-09" iyz="0" izz="1.1e-09"/>
    </inertial>
  </link>
  <link name="SonarBack_frame">
    <inertial>
      <origin rpy="0 0 0" xyz="0 0 0"/>
      <mass value="0"/>
      <inertia ixx="0.0" ixy="0.0" ixz="0.0" iyy="0.0" iyz="0.0" izz="0.0"/>
    </inertial>
  </link> <!-- in pybullet, the inertia need to be specified even for dummy links, otherwise it will put an identity inertia and a mass of 1 by default -->
  <joint name="Sonar/Back_sensor_fixedjoint" type="fixed">
    <parent link="Tibia"/>
    <child link="SonarBack_frame"/>
    <origin rpy="-1.81761e-08 -0.209438 -3.14159" xyz="-0.0718 0 -0.0534"/>
    <axis xyz="0 0 0"/>
  </joint>
  <link name="CameraBottom_optical_frame">
    <inertial>
      <origin rpy="0 0 0" xyz="0 0 0"/>
      <mass value="0"/>
      <inertia ixx="0.0" ixy="0.0" ixz="0.0" iyy="0.0" iyz="0.0" izz="0.0"/>
    </inertial>
  </link> <!-- in pybullet, the inertia need to be specified even for dummy links, otherwise it will put an identity inertia and a mass of 1 by default -->
  <joint name="CameraBottom_optical_frame_fixedjoint" type="fixed">
    <parent link="CameraBottom_frame"/>
    <child link="CameraBottom_optical_frame"/>
    <origin rpy="-1.57079632679 0 -1.57079632679" xyz="0 0 0"/>
  </joint>
  <link name="CameraDepth_optical_frame">
    <inertial>
      <origin rpy="0 0 0" xyz="0 0 0"/>
      <mass value="0"/>
      <inertia ixx="0.0" ixy="0.0" ixz="0.0" iyy="0.0" iyz="0.0" izz="0.0"/>
    </inertial>
  </link> <!-- in pybullet, the inertia need to be specified even for dummy links, otherwise it will put an identity inertia and a mass of 1 by default -->
  <joint name="CameraDepth_optical_frame_fixedjoint" type="fixed">
    <parent link="CameraDepth_frame"/>
    <child link="CameraDepth_optical_frame"/>
    <origin rpy="-1.57079632679 0 -1.57079632679" xyz="0 0 0"/>
  </joint>
  <link name="LHandTouchBack_frame">
    <inertial>
      <origin rpy="0 0 0" xyz="0 0 0"/>
      <mass value="0"/>
      <inertia ixx="0.0" ixy="0.0" ixz="0.0" iyy="0.0" iyz="0.0" izz="0.0"/>
    </inertial>
  </link> <!-- in pybullet, the inertia need to be specified even for dummy links, otherwise it will put an identity inertia and a mass of 1 by default -->
  <joint name="LHand/Touch/Back_sensor_fixedjoint" type="fixed">
    <parent link="l_wrist"/>
    <child link="LHandTouchBack_frame"/>
    <origin rpy="1.5708 -1.5708 -3.14159" xyz="0.0523 0 0.0304"/>
    <axis xyz="0 0 0"/>
  </joint>
  <link name="VerticalLeftLaser_frame">
    <inertial>
      <origin rpy="0 0 0" xyz="0 0 0"/>
      <mass value="0"/>
      <inertia ixx="0.0" ixy="0.0" ixz="0.0" iyy="0.0" iyz="0.0" izz="0.0"/>
    </inertial>
  </link> <!-- in pybullet, the inertia need to be specified even for dummy links, otherwise it will put an identity inertia and a mass of 1 by default -->
  <joint name="LaserSensor/VerticalLeft_sensor_fixedjoint" type="fixed">
    <parent link="Tibia"/>
    <child link="VerticalLeftLaser_frame"/>
    <origin rpy="0 0.349066 0" xyz="0.0562 0 -0.0692"/>
    <axis xyz="0 0 0"/>
  </joint>
  <link name="SurroundingFrontLaser_device_frame">
    <inertial>
      <origin rpy="0 0 0" xyz="0 0 0"/>
      <mass value="0"/>
      <inertia ixx="0.0" ixy="0.0" ixz="0.0" iyy="0.0" iyz="0.0" izz="0.0"/>
    </inertial>
  </link> <!-- in pybullet, the inertia need to be specified even for dummy links, otherwise it will put an identity inertia and a mass of 1 by default -->
  <joint name="LaserSensor/Front_sensor_fixedjoint" type="fixed">
    <parent link="Tibia"/>
    <child link="SurroundingFrontLaser_device_frame"/>
    <origin rpy="0 0.349066 0" xyz="0.0562 0 -0.0692"/>
    <axis xyz="0 0 0"/>
  </joint>
  <link name="BumperB_frame">
    <inertial>
      <origin rpy="0 0 0" xyz="0 0 0"/>
      <mass value="0"/>
      <inertia ixx="0.0" ixy="0.0" ixz="0.0" iyy="0.0" iyz="0.0" izz="0.0"/>
    </inertial>
  </link> <!-- in pybullet, the inertia need to be specified even for dummy links, otherwise it will put an identity inertia and a mass of 1 by default -->
  <joint name="Bumper/Back_sensor_fixedjoint" type="fixed">
    <parent link="Tibia"/>
    <child link="BumperB_frame"/>
    <origin rpy="0 0 -3.14159" xyz="-0.251 0 -0.264"/>
    <axis xyz="0 0 0"/>
  </joint>
  <link name="SurroundingLeftLaser_frame">
    <inertial>
      <origin rpy="0 0 0" xyz="0 0 0"/>
      <mass value="0"/>
      <inertia ixx="0.0" ixy="0.0" ixz="0.0" iyy="0.0" iyz="0.0" izz="0.0"/>
    </inertial>
  </link> <!-- in pybullet, the inertia need to be specified even for dummy links, otherwise it will put an identity inertia and a mass of 1 by default -->
  <joint name="LaserSensor/Left_projected_sensor_fixedjoint" type="fixed">
    <parent link="Tibia"/>
    <child link="SurroundingLeftLaser_frame"/>
    <origin rpy="0 0 1.75728" xyz="-0.018 0.0899 -0.334"/>
    <axis xyz="0 0 0"/>
  </joint>
  <link name="ShovelLaser_frame">
    <inertial>
      <origin rpy="0 0 0" xyz="0 0 0"/>
      <mass value="0"/>
      <inertia ixx="0.0" ixy="0.0" ixz="0.0" iyy="0.0" iyz="0.0" izz="0.0"/>
    </inertial>
  </link> <!-- in pybullet, the inertia need to be specified even for dummy links, otherwise it will put an identity inertia and a mass of 1 by default -->
  <joint name="LaserSensor/Shovel_sensor_fixedjoint" type="fixed">
    <parent link="Tibia"/>
    <child link="ShovelLaser_frame"/>
    <origin rpy="0 0.349066 0" xyz="0.0562 0 -0.0692"/>
    <axis xyz="0 0 0"/>
  </joint>
  <link name="ImuTorsoAccelerometer_frame">
    <inertial>
      <origin rpy="0 0 0" xyz="0 0 0"/>
      <mass value="0"/>
      <inertia ixx="0.0" ixy="0.0" ixz="0.0" iyy="0.0" iyz="0.0" izz="0.0"/>
    </inertial>
  </link> <!-- in pybullet, the inertia need to be specified even for dummy links, otherwise it will put an identity inertia and a mass of 1 by default -->
  <joint name="Accelerometer_sensor_fixedjoint" type="fixed">
    <parent link="torso"/>
    <child link="ImuTorsoAccelerometer_frame"/>
    <origin rpy="0 0 0" xyz="0.00239 -0.03575 0.00626"/>
    <axis xyz="0 0 0"/>
  </joint>
  <link name="RSpeaker_frame">
    <inertial>
      <origin rpy="0 0 0" xyz="0 0 0"/>
      <mass value="0"/>
      <inertia ixx="0.0" ixy="0.0" ixz="0.0" iyy="0.0" iyz="0.0" izz="0.0"/>
    </inertial>
  </link> <!-- in pybullet, the inertia need to be specified even for dummy links, otherwise it will put an identity inertia and a mass of 1 by default -->
  <joint name="SpeakerRight_sensor_fixedjoint" type="fixed">
    <parent link="Head"/>
    <child link="RSpeaker_frame"/>
    <origin rpy="0 0 0" xyz="0 0 0"/>
    <axis xyz="0 0 0"/>
  </joint>
  <link name="SurroundingRightLaser_device_frame">
    <inertial>
      <origin rpy="0 0 0" xyz="0 0 0"/>
      <mass value="0"/>
      <inertia ixx="0.0" ixy="0.0" ixz="0.0" iyy="0.0" iyz="0.0" izz="0.0"/>
    </inertial>
  </link> <!-- in pybullet, the inertia need to be specified even for dummy links, otherwise it will put an identity inertia and a mass of 1 by default -->
  <joint name="LaserSensor/Right_sensor_fixedjoint" type="fixed">
    <parent link="Tibia"/>
    <child link="SurroundingRightLaser_device_frame"/>
    <origin rpy="0 0.349066 -1.5708" xyz="-0.018 -0.0899 -0.0759"/>
    <axis xyz="0 0 0"/>
  </joint>
  <link name="LSpeaker_frame">
    <inertial>
      <origin rpy="0 0 0" xyz="0 0 0"/>
      <mass value="0"/>
      <inertia ixx="0.0" ixy="0.0" ixz="0.0" iyy="0.0" iyz="0.0" izz="0.0"/>
    </inertial>
  </link> <!-- in pybullet, the inertia need to be specified even for dummy links, otherwise it will put an identity inertia and a mass of 1 by default -->
  <joint name="SpeakerLeft_sensor_fixedjoint" type="fixed">
    <parent link="Head"/>
    <child link="LSpeaker_frame"/>
    <origin rpy="0 0 0" xyz="0 0 0"/>
    <axis xyz="0 0 0"/>
  </joint>
  <link name="RHandTouchBack_frame">
    <inertial>
      <origin rpy="0 0 0" xyz="0 0 0"/>
      <mass value="0"/>
      <inertia ixx="0.0" ixy="0.0" ixz="0.0" iyy="0.0" iyz="0.0" izz="0.0"/>
    </inertial>
  </link> <!-- in pybullet, the inertia need to be specified even for dummy links, otherwise it will put an identity inertia and a mass of 1 by default -->
  <joint name="RHand/Touch/Back_sensor_fixedjoint" type="fixed">
    <parent link="r_wrist"/>
    <child link="RHandTouchBack_frame"/>
    <origin rpy="1.5708 -1.5708 -3.14159" xyz="0.0523 0 0.0304"/>
    <axis xyz="0 0 0"/>
  </joint>
  <link name="CameraTop_frame">
    <inertial>
      <origin rpy="0 0 0" xyz="0 0 0"/>
      <mass value="0"/>
      <inertia ixx="0.0" ixy="0.0" ixz="0.0" iyy="0.0" iyz="0.0" izz="0.0"/>
    </inertial>
  </link> <!-- in pybullet, the inertia need to be specified even for dummy links, otherwise it will put an identity inertia and a mass of 1 by default -->
  <joint name="CameraTop_sensor_fixedjoint" type="fixed">
    <parent link="Head"/>
    <child link="CameraTop_frame"/>
    <origin rpy="0 0 0" xyz="0.08601 0 0.16284"/>
    <axis xyz="0 0 0"/>
  </joint>
  <link name="SurroundingLeftLaser_device_frame">
    <inertial>
      <origin rpy="0 0 0" xyz="0 0 0"/>
      <mass value="0"/>
      <inertia ixx="0.0" ixy="0.0" ixz="0.0" iyy="0.0" iyz="0.0" izz="0.0"/>
    </inertial>
  </link> <!-- in pybullet, the inertia need to be specified even for dummy links, otherwise it will put an identity inertia and a mass of 1 by default -->
  <joint name="LaserSensor/Left_sensor_fixedjoint" type="fixed">
    <parent link="Tibia"/>
    <child link="SurroundingLeftLaser_device_frame"/>
    <origin rpy="0 0.349066 1.5708" xyz="-0.018 0.0899 -0.0759"/>
    <axis xyz="0 0 0"/>
  </joint>
  <link name="CameraDepth_frame">
    <inertial>
      <origin rpy="0 0 0" xyz="0 0 0"/>
      <mass value="0"/>
      <inertia ixx="0.0" ixy="0.0" ixz="0.0" iyy="0.0" iyz="0.0" izz="0.0"/>
    </inertial>
  </link> <!-- in pybullet, the inertia need to be specified even for dummy links, otherwise it will put an identity inertia and a mass of 1 by default -->
  <joint name="CameraDepth_sensor_fixedjoint" type="fixed">
    <parent link="Head"/>
    <child link="CameraDepth_frame"/>
    <origin rpy="0 0 0" xyz="0.05138 0.039 0.1194"/>
    <axis xyz="0 0 0"/>
  </joint>
  <link name="SurroundingRightLaser_frame">
    <inertial>
      <origin rpy="0 0 0" xyz="0 0 0"/>
      <mass value="0"/>
      <inertia ixx="0.0" ixy="0.0" ixz="0.0" iyy="0.0" iyz="0.0" izz="0.0"/>
    </inertial>
  </link> <!-- in pybullet, the inertia need to be specified even for dummy links, otherwise it will put an identity inertia and a mass of 1 by default -->
  <joint name="LaserSensor/Right_projected_sensor_fixedjoint" type="fixed">
    <parent link="Tibia"/>
    <child link="SurroundingRightLaser_frame"/>
    <origin rpy="0 0 -1.75728" xyz="-0.018 -0.0899 -0.334"/>
    <axis xyz="0 0 0"/>
  </joint>
  <link name="HeadTouchFront_frame">
    <inertial>
      <origin rpy="0 0 0" xyz="0 0 0"/>
      <mass value="0"/>
      <inertia ixx="0.0" ixy="0.0" ixz="0.0" iyy="0.0" iyz="0.0" izz="0.0"/>
    </inertial>
  </link> <!-- in pybullet, the inertia need to be specified even for dummy links, otherwise it will put an identity inertia and a mass of 1 by default -->
  <joint name="Head/Touch/Front_sensor_fixedjoint" type="fixed">
    <parent link="Head"/>
    <child link="HeadTouchFront_frame"/>
    <origin rpy="0 0.20944 0" xyz="0.028175 0 0.21267"/>
    <axis xyz="0 0 0"/>
  </joint>
  <link name="VerticalRightLaser_frame">
    <inertial>
      <origin rpy="0 0 0" xyz="0 0 0"/>
      <mass value="0"/>
      <inertia ixx="0.0" ixy="0.0" ixz="0.0" iyy="0.0" iyz="0.0" izz="0.0"/>
    </inertial>
  </link> <!-- in pybullet, the inertia need to be specified even for dummy links, otherwise it will put an identity inertia and a mass of 1 by default -->
  <joint name="LaserSensor/VerticalRight_sensor_fixedjoint" type="fixed">
    <parent link="Tibia"/>
    <child link="VerticalRightLaser_frame"/>
    <origin rpy="0 0.349066 0" xyz="0.0562 0 -0.0692"/>
    <axis xyz="0 0 0"/>
  </joint>
  <link name="SonarFront_frame">
    <inertial>
      <origin rpy="0 0 0" xyz="0 0 0"/>
      <mass value="0"/>
      <inertia ixx="0.0" ixy="0.0" ixz="0.0" iyy="0.0" iyz="0.0" izz="0.0"/>
    </inertial>
  </link> <!-- in pybullet, the inertia need to be specified even for dummy links, otherwise it will put an identity inertia and a mass of 1 by default -->
  <joint name="Sonar/Front_sensor_fixedjoint" type="fixed">
    <parent link="Tibia"/>
    <child link="SonarFront_frame"/>
    <origin rpy="0 -0.322858 0" xyz="0.0699 0 -0.1023"/>
    <axis xyz="0 0 0"/>
  </joint>
  <link name="BumperFL_frame">
    <inertial>
      <origin rpy="0 0 0" xyz="0 0 0"/>
      <mass value="0"/>
      <inertia ixx="0.0" ixy="0.0" ixz="0.0" iyy="0.0" iyz="0.0" izz="0.0"/>
    </inertial>
  </link> <!-- in pybullet, the inertia need to be specified even for dummy links, otherwise it will put an identity inertia and a mass of 1 by default -->
  <joint name="Bumper/FrontLeft_sensor_fixedjoint" type="fixed">
    <parent link="Tibia"/>
    <child link="BumperFL_frame"/>
    <origin rpy="0 0 0.48886" xyz="0.129 0.227 -0.264"/>
    <axis xyz="0 0 0"/>
  </joint>
  <link name="CameraBottom_frame">
    <inertial>
      <origin rpy="0 0 0" xyz="0 0 0"/>
      <mass value="0"/>
      <inertia ixx="0.0" ixy="0.0" ixz="0.0" iyy="0.0" iyz="0.0" izz="0.0"/>
    </inertial>
  </link> <!-- in pybullet, the inertia need to be specified even for dummy links, otherwise it will put an identity inertia and a mass of 1 by default -->
  <joint name="CameraBottom_sensor_fixedjoint" type="fixed">
    <parent link="Head"/>
    <child link="CameraBottom_frame"/>
    <origin rpy="0 0.698132 0" xyz="0.09262 0 0.06177"/>
    <axis xyz="0 0 0"/>
  </joint>
  <link name="CameraTop_optical_frame">
    <inertial>
      <origin rpy="0 0 0" xyz="0 0 0"/>
      <mass value="0"/>
      <inertia ixx="0.0" ixy="0.0" ixz="0.0" iyy="0.0" iyz="0.0" izz="0.0"/>
    </inertial>
  </link> <!-- in pybullet, the inertia need to be specified even for dummy links, otherwise it will put an identity inertia and a mass of 1 by default -->
  <joint name="CameraTop_optical_frame_fixedjoint" type="fixed">
    <parent link="CameraTop_frame"/>
    <child link="CameraTop_optical_frame"/>
    <origin rpy="-1.57079632679 0 -1.57079632679" xyz="0 0 0"/>
  </joint>
  <link name="ImuBaseAccelerometer_frame">
    <inertial>
      <origin rpy="0 0 0" xyz="0 0 0"/>
      <mass value="0"/>
      <inertia ixx="0.0" ixy="0.0" ixz="0.0" iyy="0.0" iyz="0.0" izz="0.0"/>
    </inertial>
  </link> <!-- in pybullet, the inertia need to be specified even for dummy links, otherwise it will put an identity inertia and a mass of 1 by default -->
  <joint name="AccelerometerBase_sensor_fixedjoint" type="fixed">
    <parent link="Tibia"/>
    <child link="ImuBaseAccelerometer_frame"/>
    <origin rpy="0 0 0" xyz="0.0147 -0.0017 -0.26319"/>
    <axis xyz="0 0 0"/>
  </joint>
  <link name="ImuTorsoGyrometer_frame">
    <inertial>
      <origin rpy="0 0 0" xyz="0 0 0"/>
      <mass value="0"/>
      <inertia ixx="0.0" ixy="0.0" ixz="0.0" iyy="0.0" iyz="0.0" izz="0.0"/>
    </inertial>
  </link> <!-- in pybullet, the inertia need to be specified even for dummy links, otherwise it will put an identity inertia and a mass of 1 by default -->
  <joint name="Gyrometer_sensor_fixedjoint" type="fixed">
    <parent link="torso"/>
    <child link="ImuTorsoGyrometer_frame"/>
    <origin rpy="0 0 0" xyz="0.00204 -0.03491 -0.00959"/>
    <axis xyz="0 0 0"/>
  </joint>
  <link name="Tablet_frame">
    <inertial>
      <origin rpy="0 0 0" xyz="0 0 0"/>
      <mass value="0"/>
      <inertia ixx="0.0" ixy="0.0" ixz="0.0" iyy="0.0" iyz="0.0" izz="0.0"/>
    </inertial>
  </link> <!-- in pybullet, the inertia need to be specified even for dummy links, otherwise it will put an identity inertia and a mass of 1 by default -->
  <joint name="Tablet_sensor_fixedjoint" type="fixed">
    <parent link="torso"/>
    <child link="Tablet_frame"/>
    <origin rpy="0 -0.523599 0" xyz="0.0839249 0 0.06251"/>
    <axis xyz="0 0 0"/>
  </joint>
  <link name="HeadTouchRear_frame">
    <inertial>
      <origin rpy="0 0 0" xyz="0 0 0"/>
      <mass value="0"/>
      <inertia ixx="0.0" ixy="0.0" ixz="0.0" iyy="0.0" iyz="0.0" izz="0.0"/>
    </inertial>
  </link> <!-- in pybullet, the inertia need to be specified even for dummy links, otherwise it will put an identity inertia and a mass of 1 by default -->
  <joint name="Head/Touch/Rear_sensor_fixedjoint" type="fixed">
    <parent link="Head"/>
    <child link="HeadTouchRear_frame"/>
    <origin rpy="0 -0.314159 0" xyz="-0.03376 0 0.21052"/>
    <axis xyz="0 0 0"/>
  </joint>
  <link name="BumperFR_frame">
    <inertial>
      <origin rpy="0 0 0" xyz="0 0 0"/>
      <mass value="0"/>
      <inertia ixx="0.0" ixy="0.0" ixz="0.0" iyy="0.0" iyz="0.0" izz="0.0"/>
    </inertial>
  </link> <!-- in pybullet, the inertia need to be specified even for dummy links, otherwise it will put an identity inertia and a mass of 1 by default -->
  <joint name="Bumper/FrontRight_sensor_fixedjoint" type="fixed">
    <parent link="Tibia"/>
    <child link="BumperFR_frame"/>
    <origin rpy="0 0 -0.48886" xyz="0.129 -0.227 -0.264"/>
    <axis xyz="0 0 0"/>
  </joint>
  <link name="SurroundingFrontLaser_frame">
    <inertial>
      <origin rpy="0 0 0" xyz="0 0 0"/>
      <mass value="0"/>
      <inertia ixx="0.0" ixy="0.0" ixz="0.0" iyy="0.0" iyz="0.0" izz="0.0"/>
    </inertial>
  </link> <!-- in pybullet, the inertia need to be specified even for dummy links, otherwise it will put an identity inertia and a mass of 1 by default -->
  <joint name="LaserSensor/Front_projected_sensor_fixedjoint" type="fixed">
    <parent link="Tibia"/>
    <child link="SurroundingFrontLaser_frame"/>
    <origin rpy="0 0 0" xyz="0.0562 0 -0.334"/>
    <axis xyz="0 0 0"/>
  </joint>
  <link name="ChestButton_frame">
    <inertial>
      <origin rpy="0 0 0" xyz="0 0 0"/>
      <mass value="0"/>
      <inertia ixx="0.0" ixy="0.0" ixz="0.0" iyy="0.0" iyz="0.0" izz="0.0"/>
    </inertial>
  </link> <!-- in pybullet, the inertia need to be specified even for dummy links, otherwise it will put an identity inertia and a mass of 1 by default -->
  <joint name="ChestBoard/Button_sensor_fixedjoint" type="fixed">
    <parent link="torso"/>
    <child link="ChestButton_frame"/>
    <origin rpy="0 0 0" xyz="0.049871 0.001588 0.055163"/>
    <axis xyz="0 0 0"/>
  </joint>
  <link name="HeadTouchMiddle_frame">
    <inertial>
      <origin rpy="0 0 0" xyz="0 0 0"/>
      <mass value="0"/>
      <inertia ixx="0.0" ixy="0.0" ixz="0.0" iyy="0.0" iyz="0.0" izz="0.0"/>
    </inertial>
  </link> <!-- in pybullet, the inertia need to be specified even for dummy links, otherwise it will put an identity inertia and a mass of 1 by default -->
  <joint name="Head/Touch/Middle_sensor_fixedjoint" type="fixed">
    <parent link="Head"/>
    <child link="HeadTouchMiddle_frame"/>
    <origin rpy="0 -0.0349066 0" xyz="0.0041 0 0.2159"/>
    <axis xyz="0 0 0"/>
  </joint>
  <link name="RFinger41_link">
    <inertial>
      <mass value="2e-06"/>
      <inertia ixx="1.1e-09" ixy="0" ixz="0" iyy="1.1e-09" iyz="0" izz="1.1e-09"/>
    </inertial>
    <visual>
      <material name="light_gray"/>
      <geometry>
        <mesh filename="meshes/1.0/RFinger41.obj" scale="0.1 0.1 0.1"/>
      </geometry>
      <origin rpy="0 0 0" xyz="0 0 0"/>
    </visual>
    <collision>
      <geometry>
        <mesh filename="meshes/1.0/RFinger41_0.10.stl" scale="0.1 0.1 0.1"/>
      </geometry>
      <origin rpy="0 0 0" xyz="0 0 0"/>
    </collision>
  </link>
  <joint name="RFinger41" type="revolute"> <!-- type="continuous" -->
    <parent link="r_wrist"/>
    <child link="RFinger41_link"/>
    <origin rpy="1.74402 1.04064 -0.0683394" xyz="0.074 -0.0309 0"/>
    <axis xyz="0 0 1.0"/>
    <!--mimic joint="RHand" multiplier="0.872665" offset="0"/-->
    <limit effort="3.25" lower="-1e12" upper="1e12" velocity="6.28319"/> <!-- pybullet doesn't currently accept a limit of 0 -->
  </joint>
  <link name="LFinger42_link">
    <inertial>
      <mass value="2e-06"/>
      <inertia ixx="1.1e-09" ixy="0" ixz="0" iyy="1.1e-09" iyz="0" izz="1.1e-09"/>
    </inertial>
    <visual>
      <material name="light_gray"/>
      <geometry>
        <mesh filename="meshes/1.0/LFinger42.obj" scale="0.1 0.1 0.1"/>
      </geometry>
      <origin rpy="0 0 0" xyz="0 0 0"/>
    </visual>
    <collision>
      <geometry>
        <mesh filename="meshes/1.0/LFinger42_0.10.stl" scale="0.1 0.1 0.1"/>
      </geometry>
      <origin rpy="0 0 0" xyz="0 0 0"/>
    </collision>
  </link>
  <joint name="LFinger42" type="revolute"> <!-- type="continuous" -->
    <parent link="LFinger41_link"/>
    <child link="LFinger42_link"/>
    <origin rpy="0 0 -1.0472" xyz="0.018 0 0"/>
    <axis xyz="0 0 1.0"/>
    <!--mimic joint="LHand" multiplier="0.872665" offset="0"/-->
    <limit effort="3.25" lower="-1e12" upper="1e12" velocity="6.28319"/> <!-- pybullet doesn't currently accept a limit of 0 -->
  </joint>
  <link name="RFinger12_link">
    <inertial>
      <mass value="2e-06"/>
      <inertia ixx="1.1e-09" ixy="0" ixz="0" iyy="1.1e-09" iyz="0" izz="1.1e-09"/>
    </inertial>
    <visual>
      <material name="light_gray"/>
      <geometry>
        <mesh filename="meshes/1.0/RFinger12.obj" scale="0.1 0.1 0.1"/>
      </geometry>
      <origin rpy="0 0 0" xyz="0 0 0"/>
    </visual>
    <collision>
      <geometry>
        <mesh filename="meshes/1.0/RFinger12_0.10.stl" scale="0.1 0.1 0.1"/>
      </geometry>
      <origin rpy="0 0 0" xyz="0 0 0"/>
    </collision>
  </link>
  <joint name="RFinger12" type="revolute"> <!-- type="continuous" -->
    <parent link="RFinger11_link"/>
    <child link="RFinger12_link"/>
    <origin rpy="0 0 -1.0472" xyz="0.018 0 0"/>
    <axis xyz="0 0 1.0"/>
    <!--mimic joint="RHand" multiplier="0.872665" offset="0"/-->
    <limit effort="3.25" lower="-1e12" upper="1e12" velocity="6.28319"/> <!-- pybullet doesn't currently accept a limit of 0 -->
  </joint>
  <link name="LFinger33_link">
    <inertial>
      <mass value="2e-06"/>
      <inertia ixx="1.1e-09" ixy="0" ixz="0" iyy="1.1e-09" iyz="0" izz="1.1e-09"/>
    </inertial>
    <visual>
      <material name="light_gray"/>
      <geometry>
        <mesh filename="meshes/1.0/LFinger33.obj" scale="0.1 0.1 0.1"/>
      </geometry>
      <origin rpy="0 0 0" xyz="0 0 0"/>
    </visual>
    <collision>
      <geometry>
        <mesh filename="meshes/1.0/LFinger33_0.10.stl" scale="0.1 0.1 0.1"/>
      </geometry>
      <origin rpy="0 0 0" xyz="0 0 0"/>
    </collision>
  </link>
  <joint name="LFinger33" type="revolute"> <!-- type="continuous" -->
    <parent link="LFinger32_link"/>
    <child link="LFinger33_link"/>
    <origin rpy="0 0 -1.0472" xyz="0.018 0 0"/>
    <axis xyz="0 0 1.0"/>
    <!--mimic joint="LHand" multiplier="0.872665" offset="0"/-->
    <limit effort="3.25" lower="-1e12" upper="1e12" velocity="6.28319"/> <!-- pybullet doesn't currently accept a limit of 0 -->
  </joint>
  <link name="RFinger31_link">
    <inertial>
      <mass value="2e-06"/>
      <inertia ixx="1.1e-09" ixy="0" ixz="0" iyy="1.1e-09" iyz="0" izz="1.1e-09"/>
    </inertial>
    <visual>
      <material name="light_gray"/>
      <geometry>
        <mesh filename="meshes/1.0/RFinger31.obj" scale="0.1 0.1 0.1"/>
      </geometry>
      <origin rpy="0 0 0" xyz="0 0 0"/>
    </visual>
    <collision>
      <geometry>
        <mesh filename="meshes/1.0/RFinger31_0.10.stl" scale="0.1 0.1 0.1"/>
      </geometry>
      <origin rpy="0 0 0" xyz="0 0 0"/>
    </collision>
  </link>
  <joint name="RFinger31" type="revolute"> <!-- type="continuous" -->
    <parent link="r_wrist"/>
    <child link="RFinger31_link"/>
    <origin rpy="1.67523 1.04483 0.029316" xyz="0.0833 -0.0123 0.004"/>
    <axis xyz="0 0 1.0"/>
    <!--mimic joint="RHand" multiplier="0.872665" offset="0"/-->
    <limit effort="3.25" lower="-1e12" upper="1e12" velocity="6.28319"/> <!-- pybullet doesn't currently accept a limit of 0 -->
  </joint>
  <link name="LFinger21_link">
    <inertial>
      <mass value="2e-06"/>
      <inertia ixx="1.1e-09" ixy="0" ixz="0" iyy="1.1e-09" iyz="0" izz="1.1e-09"/>
    </inertial>
    <visual>
      <material name="light_gray"/>
      <geometry>
        <mesh filename="meshes/1.0/LFinger21.obj" scale="0.1 0.1 0.1"/>
      </geometry>
      <origin rpy="0 0 0" xyz="0 0 0"/>
    </visual>
    <collision>
      <geometry>
        <mesh filename="meshes/1.0/LFinger21_0.10.stl" scale="0.1 0.1 0.1"/>
      </geometry>
      <origin rpy="0 0 0" xyz="0 0 0"/>
    </collision>
  </link>
  <joint name="LFinger21" type="revolute"> <!-- type="continuous" -->
    <parent link="l_wrist"/>
    <child link="LFinger21_link"/>
    <origin rpy="1.5708 1.0472 -0.061086" xyz="0.0873 -0.0073 0.006"/>
    <axis xyz="0 0 1.0"/>
    <!--mimic joint="LHand" multiplier="0.872665" offset="0"/-->
    <limit effort="3.25" lower="-1e12" upper="1e12" velocity="6.28319"/> <!-- pybullet doesn't currently accept a limit of 0 -->
  </joint>
  <link name="RFinger32_link">
    <inertial>
      <mass value="2e-06"/>
      <inertia ixx="1.1e-09" ixy="0" ixz="0" iyy="1.1e-09" iyz="0" izz="1.1e-09"/>
    </inertial>
    <visual>
      <material name="light_gray"/>
      <geometry>
        <mesh filename="meshes/1.0/RFinger32.obj" scale="0.1 0.1 0.1"/>
      </geometry>
      <origin rpy="0 0 0" xyz="0 0 0"/>
    </visual>
    <collision>
      <geometry>
        <mesh filename="meshes/1.0/RFinger32_0.10.stl" scale="0.1 0.1 0.1"/>
      </geometry>
      <origin rpy="0 0 0" xyz="0 0 0"/>
    </collision>
  </link>
  <joint name="RFinger32" type="revolute"> <!-- type="continuous" -->
    <parent link="RFinger31_link"/>
    <child link="RFinger32_link"/>
    <origin rpy="0 0 -1.0472" xyz="0.018 0 0"/>
    <axis xyz="0 0 1.0"/>
    <!--mimic joint="RHand" multiplier="0.872665" offset="0"/-->
    <limit effort="3.25" lower="-1e12" upper="1e12" velocity="6.28319"/> <!-- pybullet doesn't currently accept a limit of 0 -->
  </joint>
  <link name="LFinger13_link">
    <inertial>
      <mass value="2e-06"/>
      <inertia ixx="1.1e-09" ixy="0" ixz="0" iyy="1.1e-09" iyz="0" izz="1.1e-09"/>
    </inertial>
    <visual>
      <material name="light_gray"/>
      <geometry>
        <mesh filename="meshes/1.0/LFinger13.obj" scale="0.1 0.1 0.1"/>
      </geometry>
      <origin rpy="0 0 0" xyz="0 0 0"/>
    </visual>
    <collision>
      <geometry>
        <mesh filename="meshes/1.0/LFinger13_0.10.stl" scale="0.1 0.1 0.1"/>
      </geometry>
      <origin rpy="0 0 0" xyz="0 0 0"/>
    </collision>
  </link>
  <joint name="LFinger13" type="revolute"> <!-- type="continuous" -->
    <parent link="LFinger12_link"/>
    <child link="LFinger13_link"/>
    <origin rpy="0 0 -1.0472" xyz="0.018 0 0"/>
    <axis xyz="0 0 1.0"/>
    <!--mimic joint="LHand" multiplier="0.872665" offset="0"/-->
    <limit effort="3.25" lower="-1e12" upper="1e12" velocity="6.28319"/> <!-- pybullet doesn't currently accept a limit of 0 -->
  </joint>
  <link name="LFinger32_link">
    <inertial>
      <mass value="2e-06"/>
      <inertia ixx="1.1e-09" ixy="0" ixz="0" iyy="1.1e-09" iyz="0" izz="1.1e-09"/>
    </inertial>
    <visual>
      <material name="light_gray"/>
      <geometry>
        <mesh filename="meshes/1.0/LFinger32.obj" scale="0.1 0.1 0.1"/>
      </geometry>
      <origin rpy="0 0 0" xyz="0 0 0"/>
    </visual>
    <collision>
      <geometry>
        <mesh filename="meshes/1.0/LFinger32_0.10.stl" scale="0.1 0.1 0.1"/>
      </geometry>
      <origin rpy="0 0 0" xyz="0 0 0"/>
    </collision>
  </link>
  <joint name="LFinger32" type="revolute"> <!-- type="continuous" -->
    <parent link="LFinger31_link"/>
    <child link="LFinger32_link"/>
    <origin rpy="0 0 -1.0472" xyz="0.018 0 0"/>
    <axis xyz="0 0 1.0"/>
    <!--mimic joint="LHand" multiplier="0.872665" offset="0"/-->
    <limit effort="3.25" lower="-1e12" upper="1e12" velocity="6.28319"/> <!-- pybullet doesn't currently accept a limit of 0 -->
  </joint>
  <link name="LFinger11_link">
    <inertial>
      <mass value="2e-06"/>
      <inertia ixx="1.1e-09" ixy="0" ixz="0" iyy="1.1e-09" iyz="0" izz="1.1e-09"/>
    </inertial>
    <visual>
      <material name="light_gray"/>
      <geometry>
        <mesh filename="meshes/1.0/LFinger11.obj" scale="0.1 0.1 0.1"/>
      </geometry>
      <origin rpy="0 0 0" xyz="0 0 0"/>
    </visual>
    <collision>
      <geometry>
        <mesh filename="meshes/1.0/LFinger11_0.10.stl" scale="0.1 0.1 0.1"/>
      </geometry>
      <origin rpy="0 0 0" xyz="0 0 0"/>
    </collision>
  </link>
  <joint name="LFinger11" type="revolute"> <!-- type="continuous" -->
    <parent link="l_wrist"/>
    <child link="LFinger11_link"/>
    <origin rpy="1.74402 1.04064 -0.0334335" xyz="0.0821 -0.0268 0.004"/>
    <axis xyz="0 0 1.0"/>
    <!--mimic joint="LHand" multiplier="0.872665" offset="0"/-->
    <limit effort="3.25" lower="-1e12" upper="1e12" velocity="6.28319"/> <!-- pybullet doesn't currently accept a limit of 0 -->
  </joint>
  <link name="RFinger22_link">
    <inertial>
      <mass value="2e-06"/>
      <inertia ixx="1.1e-09" ixy="0" ixz="0" iyy="1.1e-09" iyz="0" izz="1.1e-09"/>
    </inertial>
    <visual>
      <material name="light_gray"/>
      <geometry>
        <mesh filename="meshes/1.0/RFinger22.obj" scale="0.1 0.1 0.1"/>
      </geometry>
      <origin rpy="0 0 0" xyz="0 0 0"/>
    </visual>
    <collision>
      <geometry>
        <mesh filename="meshes/1.0/RFinger22_0.10.stl" scale="0.1 0.1 0.1"/>
      </geometry>
      <origin rpy="0 0 0" xyz="0 0 0"/>
    </collision>
  </link>
  <joint name="RFinger22" type="revolute"> <!-- type="continuous" -->
    <parent link="RFinger21_link"/>
    <child link="RFinger22_link"/>
    <origin rpy="0 0 -1.0472" xyz="0.018 0 0"/>
    <axis xyz="0 0 1.0"/>
    <!--mimic joint="RHand" multiplier="0.872665" offset="0"/-->
    <limit effort="3.25" lower="-1e12" upper="1e12" velocity="6.28319"/> <!-- pybullet doesn't currently accept a limit of 0 -->
  </joint>
  <link name="RFinger13_link">
    <inertial>
      <mass value="2e-06"/>
      <inertia ixx="1.1e-09" ixy="0" ixz="0" iyy="1.1e-09" iyz="0" izz="1.1e-09"/>
    </inertial>
    <visual>
      <material name="light_gray"/>
      <geometry>
        <mesh filename="meshes/1.0/RFinger13.obj" scale="0.1 0.1 0.1"/>
      </geometry>
      <origin rpy="0 0 0" xyz="0 0 0"/>
    </visual>
    <collision>
      <geometry>
        <mesh filename="meshes/1.0/RFinger13_0.10.stl" scale="0.1 0.1 0.1"/>
      </geometry>
      <origin rpy="0 0 0" xyz="0 0 0"/>
    </collision>
  </link>
  <joint name="RFinger13" type="revolute"> <!-- type="continuous" -->
    <parent link="RFinger12_link"/>
    <child link="RFinger13_link"/>
    <origin rpy="0 0 -1.0472" xyz="0.018 0 0"/>
    <axis xyz="0 0 1.0"/>
    <!--mimic joint="RHand" multiplier="0.872665" offset="0"/-->
    <limit effort="3.25" lower="-1e12" upper="1e12" velocity="6.28319"/> <!-- pybullet doesn't currently accept a limit of 0 -->
  </joint>
  <link name="LFinger22_link">
    <inertial>
      <mass value="2e-06"/>
      <inertia ixx="1.1e-09" ixy="0" ixz="0" iyy="1.1e-09" iyz="0" izz="1.1e-09"/>
    </inertial>
    <visual>
      <material name="light_gray"/>
      <geometry>
        <mesh filename="meshes/1.0/LFinger22.obj" scale="0.1 0.1 0.1"/>
      </geometry>
      <origin rpy="0 0 0" xyz="0 0 0"/>
    </visual>
    <collision>
      <geometry>
        <mesh filename="meshes/1.0/LFinger22_0.10.stl" scale="0.1 0.1 0.1"/>
      </geometry>
      <origin rpy="0 0 0" xyz="0 0 0"/>
    </collision>
  </link>
  <joint name="LFinger22" type="revolute"> <!-- type="continuous" -->
    <parent link="LFinger21_link"/>
    <child link="LFinger22_link"/>
    <origin rpy="0 0 -1.0472" xyz="0.018 0 0"/>
    <axis xyz="0 0 1.0"/>
    <!--mimic joint="LHand" multiplier="0.872665" offset="0"/-->
    <limit effort="3.25" lower="-1e12" upper="1e12" velocity="6.28319"/> <!-- pybullet doesn't currently accept a limit of 0 -->
  </joint>
  <link name="RFinger21_link">
    <inertial>
      <mass value="2e-06"/>
      <inertia ixx="1.1e-09" ixy="0" ixz="0" iyy="1.1e-09" iyz="0" izz="1.1e-09"/>
    </inertial>
    <visual>
      <material name="light_gray"/>
      <geometry>
        <mesh filename="meshes/1.0/RFinger21.obj" scale="0.1 0.1 0.1"/>
      </geometry>
      <origin rpy="0 0 0" xyz="0 0 0"/>
    </visual>
    <collision>
      <geometry>
        <mesh filename="meshes/1.0/RFinger21_0.10.stl" scale="0.1 0.1 0.1"/>
      </geometry>
      <origin rpy="0 0 0" xyz="0 0 0"/>
    </collision>
  </link>
  <joint name="RFinger21" type="revolute"> <!-- type="continuous" -->
    <parent link="r_wrist"/>
    <child link="RFinger21_link"/>
    <origin rpy="1.5708 1.0472 0.061086" xyz="0.0873 0.0073 0.006"/>
    <axis xyz="0 0 1.0"/>
    <!--mimic joint="RHand" multiplier="0.872665" offset="0"/-->
    <limit effort="3.25" lower="-1e12" upper="1e12" velocity="6.28319"/> <!-- pybullet doesn't currently accept a limit of 0 -->
  </joint>
  <link name="LFinger41_link">
    <inertial>
      <mass value="2e-06"/>
      <inertia ixx="1.1e-09" ixy="0" ixz="0" iyy="1.1e-09" iyz="0" izz="1.1e-09"/>
    </inertial>
    <visual>
      <material name="light_gray"/>
      <geometry>
        <mesh filename="meshes/1.0/LFinger41.obj" scale="0.1 0.1 0.1"/>
      </geometry>
      <origin rpy="0 0 0" xyz="0 0 0"/>
    </visual>
    <collision>
      <geometry>
        <mesh filename="meshes/1.0/LFinger41_0.10.stl" scale="0.1 0.1 0.1"/>
      </geometry>
      <origin rpy="0 0 0" xyz="0 0 0"/>
    </collision>
  </link>
  <joint name="LFinger41" type="revolute"> <!-- type="continuous" -->
    <parent link="l_wrist"/>
    <child link="LFinger41_link"/>
    <origin rpy="1.39757 1.04064 0.0683394" xyz="0.074 0.0309 0"/>
    <axis xyz="0 0 1.0"/>
    <!--mimic joint="LHand" multiplier="0.872665" offset="0"/-->
    <limit effort="3.25" lower="-1e12" upper="1e12" velocity="6.28319"/> <!-- pybullet doesn't currently accept a limit of 0 -->
  </joint>
  <link name="LFinger12_link">
    <inertial>
      <mass value="2e-06"/>
      <inertia ixx="1.1e-09" ixy="0" ixz="0" iyy="1.1e-09" iyz="0" izz="1.1e-09"/>
    </inertial>
    <visual>
      <material name="light_gray"/>
      <geometry>
        <mesh filename="meshes/1.0/LFinger12.obj" scale="0.1 0.1 0.1"/>
      </geometry>
      <origin rpy="0 0 0" xyz="0 0 0"/>
    </visual>
    <collision>
      <geometry>
        <mesh filename="meshes/1.0/LFinger12_0.10.stl" scale="0.1 0.1 0.1"/>
      </geometry>
      <origin rpy="0 0 0" xyz="0 0 0"/>
    </collision>
  </link>
  <joint name="LFinger12" type="revolute"> <!-- type="continuous" -->
    <parent link="LFinger11_link"/>
    <child link="LFinger12_link"/>
    <origin rpy="0 0 -1.0472" xyz="0.018 0 0"/>
    <axis xyz="0 0 1.0"/>
    <!--mimic joint="LHand" multiplier="0.872665" offset="0"/-->
    <limit effort="3.25" lower="-1e12" upper="1e12" velocity="6.28319"/> <!-- pybullet doesn't currently accept a limit of 0 -->
  </joint>
  <link name="RFinger23_link">
    <inertial>
      <mass value="2e-06"/>
      <inertia ixx="1.1e-09" ixy="0" ixz="0" iyy="1.1e-09" iyz="0" izz="1.1e-09"/>
    </inertial>
    <visual>
      <material name="light_gray"/>
      <geometry>
        <mesh filename="meshes/1.0/RFinger23.obj" scale="0.1 0.1 0.1"/>
      </geometry>
      <origin rpy="0 0 0" xyz="0 0 0"/>
    </visual>
    <collision>
      <geometry>
        <mesh filename="meshes/1.0/RFinger23_0.10.stl" scale="0.1 0.1 0.1"/>
      </geometry>
      <origin rpy="0 0 0" xyz="0 0 0"/>
    </collision>
  </link>
  <joint name="RFinger23" type="revolute"> <!-- type="continuous" -->
    <parent link="RFinger22_link"/>
    <child link="RFinger23_link"/>
    <origin rpy="0 0 -1.0472" xyz="0.018 0 0"/>
    <axis xyz="0 0 1.0"/>
    <!--mimic joint="RHand" multiplier="0.872665" offset="0"/-->
    <limit effort="3.25" lower="-1e12" upper="1e12" velocity="6.28319"/> <!-- pybullet doesn't currently accept a limit of 0 -->
  </joint>
  <link name="RFinger11_link">
    <inertial>
      <mass value="2e-06"/>
      <inertia ixx="1.1e-09" ixy="0" ixz="0" iyy="1.1e-09" iyz="0" izz="1.1e-09"/>
    </inertial>
    <visual>
      <material name="light_gray"/>
      <geometry>
        <mesh filename="meshes/1.0/RFinger11.obj" scale="0.1 0.1 0.1"/>
      </geometry>
      <origin rpy="0 0 0" xyz="0 0 0"/>
    </visual>
    <collision>
      <geometry>
        <mesh filename="meshes/1.0/RFinger11_0.10.stl" scale="0.1 0.1 0.1"/>
      </geometry>
      <origin rpy="0 0 0" xyz="0 0 0"/>
    </collision>
  </link>
  <joint name="RFinger11" type="revolute"> <!-- type="continuous" -->
    <parent link="r_wrist"/>
    <child link="RFinger11_link"/>
    <origin rpy="1.39757 1.04064 0.0334335" xyz="0.0821 0.0268 0.004"/>
    <axis xyz="0 0 1.0"/>
    <!--mimic joint="RHand" multiplier="0.872665" offset="0"/-->
    <limit effort="3.25" lower="-1e12" upper="1e12" velocity="6.28319"/> <!-- pybullet doesn't currently accept a limit of 0 -->
  </joint>
  <link name="LFinger23_link">
    <inertial>
      <mass value="2e-06"/>
      <inertia ixx="1.1e-09" ixy="0" ixz="0" iyy="1.1e-09" iyz="0" izz="1.1e-09"/>
    </inertial>
    <visual>
      <material name="light_gray"/>
      <geometry>
        <mesh filename="meshes/1.0/LFinger23.obj" scale="0.1 0.1 0.1"/>
      </geometry>
      <origin rpy="0 0 0" xyz="0 0 0"/>
    </visual>
    <collision>
      <geometry>
        <mesh filename="meshes/1.0/LFinger23_0.10.stl" scale="0.1 0.1 0.1"/>
      </geometry>
      <origin rpy="0 0 0" xyz="0 0 0"/>
    </collision>
  </link>
  <joint name="LFinger23" type="revolute"> <!-- type="continuous" -->
    <parent link="LFinger22_link"/>
    <child link="LFinger23_link"/>
    <origin rpy="0 0 -1.0472" xyz="0.018 0 0"/>
    <axis xyz="0 0 1.0"/>
    <!--mimic joint="LHand" multiplier="0.872665" offset="0"/-->
    <limit effort="3.25" lower="-1e12" upper="1e12" velocity="6.28319"/> <!-- pybullet doesn't currently accept a limit of 0 -->
  </joint>
  <link name="LFinger43_link">
    <inertial>
      <mass value="2e-06"/>
      <inertia ixx="1.1e-09" ixy="0" ixz="0" iyy="1.1e-09" iyz="0" izz="1.1e-09"/>
    </inertial>
    <visual>
      <material name="light_gray"/>
      <geometry>
        <mesh filename="meshes/1.0/LFinger43.obj" scale="0.1 0.1 0.1"/>
      </geometry>
      <origin rpy="0 0 0" xyz="0 0 0"/>
    </visual>
    <collision>
      <geometry>
        <mesh filename="meshes/1.0/LFinger43_0.10.stl" scale="0.1 0.1 0.1"/>
      </geometry>
      <origin rpy="0 0 0" xyz="0 0 0"/>
    </collision>
  </link>
  <joint name="LFinger43" type="revolute"> <!-- type="continuous" -->
    <parent link="LFinger42_link"/>
    <child link="LFinger43_link"/>
    <origin rpy="0 0 -1.0472" xyz="0.018 0 0"/>
    <axis xyz="0 0 1.0"/>
    <!--mimic joint="LHand" multiplier="0.872665" offset="0"/-->
    <limit effort="3.25" lower="-1e12" upper="1e12" velocity="6.28319"/> <!-- pybullet doesn't currently accept a limit of 0 -->
  </joint>
  <link name="RFinger43_link">
    <inertial>
      <mass value="2e-06"/>
      <inertia ixx="1.1e-09" ixy="0" ixz="0" iyy="1.1e-09" iyz="0" izz="1.1e-09"/>
    </inertial>
    <visual>
      <material name="light_gray"/>
      <geometry>
        <mesh filename="meshes/1.0/RFinger43.obj" scale="0.1 0.1 0.1"/>
      </geometry>
      <origin rpy="0 0 0" xyz="0 0 0"/>
    </visual>
    <collision>
      <geometry>
        <mesh filename="meshes/1.0/RFinger43_0.10.stl" scale="0.1 0.1 0.1"/>
      </geometry>
      <origin rpy="0 0 0" xyz="0 0 0"/>
    </collision>
  </link>
  <joint name="RFinger43" type="revolute"> <!-- type="continuous" -->
    <parent link="RFinger42_link"/>
    <child link="RFinger43_link"/>
    <origin rpy="0 0 -1.0472" xyz="0.018 0 0"/>
    <axis xyz="0 0 1.0"/>
    <!--mimic joint="RHand" multiplier="0.872665" offset="0"/-->
    <limit effort="3.25" lower="-1e12" upper="1e12" velocity="6.28319"/> <!-- pybullet doesn't currently accept a limit of 0 -->
  </joint>
  <link name="RFinger42_link">
    <inertial>
      <mass value="2e-06"/>
      <inertia ixx="1.1e-09" ixy="0" ixz="0" iyy="1.1e-09" iyz="0" izz="1.1e-09"/>
    </inertial>
    <visual>
      <material name="light_gray"/>
      <geometry>
        <mesh filename="meshes/1.0/RFinger42.obj" scale="0.1 0.1 0.1"/>
      </geometry>
      <origin rpy="0 0 0" xyz="0 0 0"/>
    </visual>
    <collision>
      <geometry>
        <mesh filename="meshes/1.0/RFinger42_0.10.stl" scale="0.1 0.1 0.1"/>
      </geometry>
      <origin rpy="0 0 0" xyz="0 0 0"/>
    </collision>
  </link>
  <joint name="RFinger42" type="revolute"> <!-- type="continuous" -->
    <parent link="RFinger41_link"/>
    <child link="RFinger42_link"/>
    <origin rpy="0 0 -1.0472" xyz="0.018 0 0"/>
    <axis xyz="0 0 1.0"/>
    <!--mimic joint="RHand" multiplier="0.872665" offset="0"/-->
    <limit effort="3.25" lower="-1e12" upper="1e12" velocity="6.28319"/> <!-- pybullet doesn't currently accept a limit of 0 -->
  </joint>
  <link name="LFinger31_link">
    <inertial>
      <mass value="2e-06"/>
      <inertia ixx="1.1e-09" ixy="0" ixz="0" iyy="1.1e-09" iyz="0" izz="1.1e-09"/>
    </inertial>
    <visual>
      <material name="light_gray"/>
      <geometry>
        <mesh filename="meshes/1.0/LFinger31.obj" scale="0.1 0.1 0.1"/>
      </geometry>
      <origin rpy="0 0 0" xyz="0 0 0"/>
    </visual>
    <collision>
      <geometry>
        <mesh filename="meshes/1.0/LFinger31_0.10.stl" scale="0.1 0.1 0.1"/>
      </geometry>
      <origin rpy="0 0 0" xyz="0 0 0"/>
    </collision>
  </link>
  <joint name="LFinger31" type="revolute"> <!-- type="continuous" -->
    <parent link="l_wrist"/>
    <child link="LFinger31_link"/>
    <origin rpy="1.46636 1.04483 -0.029314" xyz="0.0833 0.0123 0.004"/>
    <axis xyz="0 0 1.0"/>
    <!--mimic joint="LHand" multiplier="0.872665" offset="0"/-->
    <limit effort="3.25" lower="-1e12" upper="1e12" velocity="6.28319"/> <!-- pybullet doesn't currently accept a limit of 0 -->
  </joint>
  <link name="RFinger33_link">
    <inertial>
      <mass value="2e-06"/>
      <inertia ixx="1.1e-09" ixy="0" ixz="0" iyy="1.1e-09" iyz="0" izz="1.1e-09"/>
    </inertial>
    <visual>
      <material name="light_gray"/>
      <geometry>
        <mesh filename="meshes/1.0/RFinger33.obj" scale="0.1 0.1 0.1"/>
      </geometry>
      <origin rpy="0 0 0" xyz="0 0 0"/>
    </visual>
    <collision>
      <geometry>
        <mesh filename="meshes/1.0/RFinger33_0.10.stl" scale="0.1 0.1 0.1"/>
      </geometry>
      <origin rpy="0 0 0" xyz="0 0 0"/>
    </collision>
  </link>
  <joint name="RFinger33" type="revolute"> <!-- type="continuous" -->
    <parent link="RFinger32_link"/>
    <child link="RFinger33_link"/>
    <origin rpy="0 0 -1.0472" xyz="0.018 0 0"/>
    <axis xyz="0 0 1.0"/>
    <!--mimic joint="RHand" multiplier="0.872665" offset="0"/-->
    <limit effort="3.25" lower="-1e12" upper="1e12" velocity="6.28319"/> <!-- pybullet doesn't currently accept a limit of 0 -->
  </joint>
  <link name="LThumb1_link">
    <inertial>
      <mass value="2e-06"/>
      <inertia ixx="1.1e-09" ixy="0" ixz="0" iyy="1.1e-09" iyz="0" izz="1.1e-09"/>
    </inertial>
    <visual>
      <material name="light_gray"/>
      <geometry>
        <mesh filename="meshes/1.0/LThumb1.obj" scale="0.1 0.1 0.1"/>
      </geometry>
      <origin rpy="0 0 0" xyz="0 0 0"/>
    </visual>
    <collision>
      <geometry>
        <mesh filename="meshes/1.0/LThumb1_0.10.stl" scale="0.1 0.1 0.1"/>
      </geometry>
      <origin rpy="0 0 0" xyz="0 0 0"/>
    </collision>
  </link>
  <joint name="LThumb1" type="revolute"> <!-- type="continuous" -->
    <parent link="l_wrist"/>
    <child link="LThumb1_link"/>
    <origin rpy="-1.95836 0.60626 0.533978" xyz="0.0482 -0.0357 -0.0199"/>
    <axis xyz="0 0 1.0"/>
    <!--mimic joint="LHand" multiplier="0.872665" offset="0"/-->
    <limit effort="3.25" lower="-1e12" upper="1e12" velocity="6.28319"/> <!-- pybullet doesn't currently accept a limit of 0 -->
  </joint>
  <link name="RThumb2_link">
    <inertial>
      <mass value="2e-06"/>
      <inertia ixx="1.1e-09" ixy="0" ixz="0" iyy="1.1e-09" iyz="0" izz="1.1e-09"/>
    </inertial>
    <visual>
      <material name="light_gray"/>
      <geometry>
        <mesh filename="meshes/1.0/RThumb2.obj" scale="0.1 0.1 0.1"/>
      </geometry>
      <origin rpy="0 0 0" xyz="0 0 0"/>
    </visual>
    <collision>
      <geometry>
        <mesh filename="meshes/1.0/RThumb2_0.10.stl" scale="0.1 0.1 0.1"/>
      </geometry>
      <origin rpy="0 0 0" xyz="0 0 0"/>
    </collision>
  </link>
  <joint name="RThumb2" type="revolute"> <!-- type="continuous" -->
    <parent link="RThumb1_link"/>
    <child link="RThumb2_link"/>
    <origin rpy="0 0 -1.0472" xyz="0.022 0 0"/>
    <axis xyz="0 0 1.0"/>
    <!--mimic joint="RHand" multiplier="0.872665" offset="0"/-->
    <limit effort="3.25" lower="-1e12" upper="1e12" velocity="6.28319"/> <!-- pybullet doesn't currently accept a limit of 0 -->
  </joint>
  <link name="RThumb1_link">
    <inertial>
      <mass value="2e-06"/>
      <inertia ixx="1.1e-09" ixy="0" ixz="0" iyy="1.1e-09" iyz="0" izz="1.1e-09"/>
    </inertial>
    <visual>
      <material name="light_gray"/>
      <geometry>
        <mesh filename="meshes/1.0/RThumb1.obj" scale="0.1 0.1 0.1"/>
      </geometry>
      <origin rpy="0 0 0" xyz="0 0 0"/>
    </visual>
    <collision>
      <geometry>
        <mesh filename="meshes/1.0/RThumb1_0.10.stl" scale="0.1 0.1 0.1"/>
      </geometry>
      <origin rpy="0 0 0" xyz="0 0 0"/>
    </collision>
  </link>
  <joint name="RThumb1" type="revolute"> <!-- type="continuous" -->
    <parent link="r_wrist"/>
    <child link="RThumb1_link"/>
    <origin rpy="-1.18323 0.60626 -0.533978" xyz="0.0482 0.0357 -0.0199"/>
    <axis xyz="0 0 1.0"/>
    <!--mimic joint="RHand" multiplier="0.872665" offset="0"/-->
    <limit effort="3.25" lower="-1e12" upper="1e12" velocity="6.28319"/> <!-- pybullet doesn't currently accept a limit of 0 -->
  </joint>
  <link name="LThumb2_link">
    <inertial>
      <mass value="2e-06"/>
      <inertia ixx="1.1e-09" ixy="0" ixz="0" iyy="1.1e-09" iyz="0" izz="1.1e-09"/>
    </inertial>
    <visual>
      <material name="light_gray"/>
      <geometry>
        <mesh filename="meshes/1.0/LThumb2.obj" scale="0.1 0.1 0.1"/>
      </geometry>
      <origin rpy="0 0 0" xyz="0 0 0"/>
    </visual>
    <collision>
      <geometry>
        <mesh filename="meshes/1.0/LThumb2_0.10.stl" scale="0.1 0.1 0.1"/>
      </geometry>
      <origin rpy="0 0 0" xyz="0 0 0"/>
    </collision>
  </link>
  <joint name="LThumb2" type="revolute"> <!-- type="continuous" -->
    <parent link="LThumb1_link"/>
    <child link="LThumb2_link"/>
    <origin rpy="0 0 -1.0472" xyz="0.022 0 0"/>
    <axis xyz="0 0 1.0"/>
    <!--mimic joint="LHand" multiplier="0.872665" offset="0"/-->
    <limit effort="3.25" lower="-1e12" upper="1e12" velocity="6.28319"/> <!-- pybullet doesn't currently accept a limit of 0 -->
  </joint>
  <link name="WheelFL_link">
    <inertial>
      <mass value="1.58028"/>
      <inertia ixx="0.00299756" ixy="6.3068e-07" ixz="5.56903e-06" iyy="0.00303229" iyz="-9.0408e-07" izz="0.00296585"/>
      <origin rpy="0 0 0" xyz="0 0 0"/>
    </inertial>
    <visual>
      <material name="black"/>
      <geometry>
        <mesh filename="meshes/1.0/WheelFL.obj" scale="0.1 0.1 0.1"/>
      </geometry>
      <origin rpy="0 0 0" xyz="0 0 0"/>
    </visual>
    <collision>
      <geometry>
        <mesh filename="meshes/1.0/WheelFL_0.10.stl" scale="0.1 0.1 0.1"/>
      </geometry>
      <origin rpy="0 0 0" xyz="0 0 0"/>
    </collision>
  </link>
  <joint name="WheelFL" type="revolute"> <!-- type="continuous" -->
    <parent link="Tibia"/>
    <child link="WheelFL_link"/>
    <origin rpy="0 0 1.07517" xyz="0.09 0.155 -0.264"/>
    <axis xyz="1.0 0 0"/>
    <limit effort="3.25" lower="-1e12" upper="1e12" velocity="6.28319"/> <!-- pybullet doesn't currently accept a limit of 0 -->
  </joint>
  <link name="WheelB_link">
    <inertial>
      <mass value="1.58028"/>
      <inertia ixx="0.00299756" ixy="6.3068e-07" ixz="5.56903e-06" iyy="0.00303229" iyz="-9.0408e-07" izz="0.00296585"/>
      <origin rpy="0 0 0" xyz="0 0 0"/>
    </inertial>
    <visual>
      <material name="black"/>
      <geometry>
        <mesh filename="meshes/1.0/WheelB.obj" scale="0.1 0.1 0.1"/>
      </geometry>
      <origin rpy="0 0 0" xyz="0 0 0"/>
    </visual>
    <collision>
      <geometry>
        <mesh filename="meshes/1.0/WheelB_0.10.stl" scale="0.1 0.1 0.1"/>
      </geometry>
      <origin rpy="0 0 0" xyz="0 0 0"/>
    </collision>
  </link>
  <joint name="WheelB" type="revolute"> <!-- type="continuous" -->
    <parent link="Tibia"/>
    <child link="WheelB_link"/>
    <origin rpy="0 0 -3.14159" xyz="-0.17 0 -0.264"/>
    <axis xyz="1.0 0 0"/>
    <limit effort="3.25" lower="-1e12" upper="1e12" velocity="6.28319"/> <!-- pybullet doesn't currently accept a limit of 0 -->
  </joint>
  <link name="WheelFR_link">
    <inertial>
      <mass value="1.58028"/>
      <inertia ixx="0.00299756" ixy="6.3068e-07" ixz="5.56903e-06" iyy="0.00303229" iyz="-9.0408e-07" izz="0.00296585"/>
      <origin rpy="0 0 0" xyz="0 0 0"/>
    </inertial>
    <visual>
      <material name="black"/>
      <geometry>
        <mesh filename="meshes/1.0/WheelFR.obj" scale="0.1 0.1 0.1"/>
      </geometry>
      <origin rpy="0 0 0" xyz="0 0 0"/>
    </visual>
    <collision>
      <geometry>
        <mesh filename="meshes/1.0/WheelFR_0.10.stl" scale="0.1 0.1 0.1"/>
      </geometry>
      <origin rpy="0 0 0" xyz="0 0 0"/>
    </collision>
  </link>
  <joint name="WheelFR" type="revolute"> <!-- type="continuous" -->
    <parent link="Tibia"/>
    <child link="WheelFR_link"/>
    <origin rpy="0 0 -1.07517" xyz="0.09 -0.155 -0.264"/>
    <axis xyz="1.0 0 0"/>
    <limit effort="3.25" lower="-1e12" upper="1e12" velocity="6.28319"/> <!-- pybullet doesn't currently accept a limit of 0 -->
  </joint>
  <!-- MACROS FOR DISABLE LINKS -->
  <!-- MACROS FOR MIMIC JOINTS -->
  <!-- Fingers -->
  <!-- Thumbs -->
  <!-- GAZEBO ROS CONTROL -->
  <gazebo>
    <plugin filename="libgazebo_ros_control.so" name="gazebo_ros_control">
      <robotNamespace/>
      <robotSimType>gazebo_ros_control/DefaultRobotHWSim</robotSimType>
    </plugin>
    <plugin filename="libroboticsgroup_gazebo_mimic_joint_plugin.so" name="mimic_LFinger11">
      <joint>LHand</joint>
      <mimicJoint>LFinger11</mimicJoint>
      <multiplier>-0.785398163398</multiplier>
      <offset>0.785398163398</offset>
    </plugin>
    <plugin filename="libroboticsgroup_gazebo_mimic_joint_plugin.so" name="mimic_LFinger12">
      <joint>LHand</joint>
      <mimicJoint>LFinger12</mimicJoint>
      <multiplier>-0.785398163398</multiplier>
      <offset>0.785398163398</offset>
    </plugin>
    <plugin filename="libroboticsgroup_gazebo_mimic_joint_plugin.so" name="mimic_LFinger13">
      <joint>LHand</joint>
      <mimicJoint>LFinger13</mimicJoint>
      <multiplier>-0.785398163398</multiplier>
      <offset>0.785398163398</offset>
    </plugin>
    <plugin filename="libroboticsgroup_gazebo_mimic_joint_plugin.so" name="mimic_LFinger21">
      <joint>LHand</joint>
      <mimicJoint>LFinger21</mimicJoint>
      <multiplier>-0.785398163398</multiplier>
      <offset>0.785398163398</offset>
    </plugin>
    <plugin filename="libroboticsgroup_gazebo_mimic_joint_plugin.so" name="mimic_LFinger22">
      <joint>LHand</joint>
      <mimicJoint>LFinger22</mimicJoint>
      <multiplier>-0.785398163398</multiplier>
      <offset>0.785398163398</offset>
    </plugin>
    <plugin filename="libroboticsgroup_gazebo_mimic_joint_plugin.so" name="mimic_LFinger23">
      <joint>LHand</joint>
      <mimicJoint>LFinger23</mimicJoint>
      <multiplier>-0.785398163398</multiplier>
      <offset>0.785398163398</offset>
    </plugin>
    <plugin filename="libroboticsgroup_gazebo_mimic_joint_plugin.so" name="mimic_LFinger31">
      <joint>LHand</joint>
      <mimicJoint>LFinger31</mimicJoint>
      <multiplier>-0.785398163398</multiplier>
      <offset>0.785398163398</offset>
    </plugin>
    <plugin filename="libroboticsgroup_gazebo_mimic_joint_plugin.so" name="mimic_LFinger32">
      <joint>LHand</joint>
      <mimicJoint>LFinger32</mimicJoint>
      <multiplier>-0.785398163398</multiplier>
      <offset>0.785398163398</offset>
    </plugin>
    <plugin filename="libroboticsgroup_gazebo_mimic_joint_plugin.so" name="mimic_LFinger33">
      <joint>LHand</joint>
      <mimicJoint>LFinger33</mimicJoint>
      <multiplier>-0.785398163398</multiplier>
      <offset>0.785398163398</offset>
    </plugin>
    <plugin filename="libroboticsgroup_gazebo_mimic_joint_plugin.so" name="mimic_LFinger41">
      <joint>LHand</joint>
      <mimicJoint>LFinger41</mimicJoint>
      <multiplier>-0.785398163398</multiplier>
      <offset>0.785398163398</offset>
    </plugin>
    <plugin filename="libroboticsgroup_gazebo_mimic_joint_plugin.so" name="mimic_LFinger42">
      <joint>LHand</joint>
      <mimicJoint>LFinger42</mimicJoint>
      <multiplier>-0.785398163398</multiplier>
      <offset>0.785398163398</offset>
    </plugin>
    <plugin filename="libroboticsgroup_gazebo_mimic_joint_plugin.so" name="mimic_LFinger43">
      <joint>LHand</joint>
      <mimicJoint>LFinger43</mimicJoint>
      <multiplier>-0.785398163398</multiplier>
      <offset>0.785398163398</offset>
    </plugin>
    <plugin filename="libroboticsgroup_gazebo_mimic_joint_plugin.so" name="mimic_RFinger11">
      <joint>RHand</joint>
      <mimicJoint>RFinger11</mimicJoint>
      <multiplier>-0.785398163398</multiplier>
      <offset>0.785398163398</offset>
    </plugin>
    <plugin filename="libroboticsgroup_gazebo_mimic_joint_plugin.so" name="mimic_RFinger12">
      <joint>RHand</joint>
      <mimicJoint>RFinger12</mimicJoint>
      <multiplier>-0.785398163398</multiplier>
      <offset>0.785398163398</offset>
    </plugin>
    <plugin filename="libroboticsgroup_gazebo_mimic_joint_plugin.so" name="mimic_RFinger13">
      <joint>RHand</joint>
      <mimicJoint>RFinger13</mimicJoint>
      <multiplier>-0.785398163398</multiplier>
      <offset>0.785398163398</offset>
    </plugin>
    <plugin filename="libroboticsgroup_gazebo_mimic_joint_plugin.so" name="mimic_RFinger21">
      <joint>RHand</joint>
      <mimicJoint>RFinger21</mimicJoint>
      <multiplier>-0.785398163398</multiplier>
      <offset>0.785398163398</offset>
    </plugin>
    <plugin filename="libroboticsgroup_gazebo_mimic_joint_plugin.so" name="mimic_RFinger22">
      <joint>RHand</joint>
      <mimicJoint>RFinger22</mimicJoint>
      <multiplier>-0.785398163398</multiplier>
      <offset>0.785398163398</offset>
    </plugin>
    <plugin filename="libroboticsgroup_gazebo_mimic_joint_plugin.so" name="mimic_RFinger23">
      <joint>RHand</joint>
      <mimicJoint>RFinger23</mimicJoint>
      <multiplier>-0.785398163398</multiplier>
      <offset>0.785398163398</offset>
    </plugin>
    <plugin filename="libroboticsgroup_gazebo_mimic_joint_plugin.so" name="mimic_RFinger31">
      <joint>RHand</joint>
      <mimicJoint>RFinger31</mimicJoint>
      <multiplier>-0.785398163398</multiplier>
      <offset>0.785398163398</offset>
    </plugin>
    <plugin filename="libroboticsgroup_gazebo_mimic_joint_plugin.so" name="mimic_RFinger32">
      <joint>RHand</joint>
      <mimicJoint>RFinger32</mimicJoint>
      <multiplier>-0.785398163398</multiplier>
      <offset>0.785398163398</offset>
    </plugin>
    <plugin filename="libroboticsgroup_gazebo_mimic_joint_plugin.so" name="mimic_RFinger33">
      <joint>RHand</joint>
      <mimicJoint>RFinger33</mimicJoint>
      <multiplier>-0.785398163398</multiplier>
      <offset>0.785398163398</offset>
    </plugin>
    <plugin filename="libroboticsgroup_gazebo_mimic_joint_plugin.so" name="mimic_RFinger41">
      <joint>RHand</joint>
      <mimicJoint>RFinger41</mimicJoint>
      <multiplier>-0.785398163398</multiplier>
      <offset>0.785398163398</offset>
    </plugin>
    <plugin filename="libroboticsgroup_gazebo_mimic_joint_plugin.so" name="mimic_RFinger42">
      <joint>RHand</joint>
      <mimicJoint>RFinger42</mimicJoint>
      <multiplier>-0.785398163398</multiplier>
      <offset>0.785398163398</offset>
    </plugin>
    <plugin filename="libroboticsgroup_gazebo_mimic_joint_plugin.so" name="mimic_RFinger43">
      <joint>RHand</joint>
      <mimicJoint>RFinger43</mimicJoint>
      <multiplier>-0.785398163398</multiplier>
      <offset>0.785398163398</offset>
    </plugin>
    <plugin filename="libroboticsgroup_gazebo_mimic_joint_plugin.so" name="LThumb1">
      <joint>LHand</joint>
      <mimicJoint>LThumb1</mimicJoint>
      <multiplier>-0.785398163398</multiplier>
      <offset>0.785398163398</offset>
    </plugin>
    <plugin filename="libroboticsgroup_gazebo_mimic_joint_plugin.so" name="LThumb2">
      <joint>LHand</joint>
      <mimicJoint>LThumb2</mimicJoint>
      <multiplier>-0.785398163398</multiplier>
      <offset>0.785398163398</offset>
    </plugin>
    <plugin filename="libroboticsgroup_gazebo_mimic_joint_plugin.so" name="RThumb1">
      <joint>RHand</joint>
      <mimicJoint>RThumb1</mimicJoint>
      <multiplier>-0.785398163398</multiplier>
      <offset>0.785398163398</offset>
    </plugin>
    <plugin filename="libroboticsgroup_gazebo_mimic_joint_plugin.so" name="RThumb2">
      <joint>RHand</joint>
      <mimicJoint>RThumb2</mimicJoint>
      <multiplier>-0.785398163398</multiplier>
      <offset>0.785398163398</offset>
    </plugin>
    <plugin filename="libroboticsgroup_gazebo_disable_link_plugin.so" name="LFinger11_link">
      <link>LFinger11_link</link>
    </plugin>
    <plugin filename="libroboticsgroup_gazebo_disable_link_plugin.so" name="LFinger12_link">
      <link>LFinger12_link</link>
    </plugin>
    <plugin filename="libroboticsgroup_gazebo_disable_link_plugin.so" name="LFinger13_link">
      <link>LFinger13_link</link>
    </plugin>
    <plugin filename="libroboticsgroup_gazebo_disable_link_plugin.so" name="LFinger21_link">
      <link>LFinger21_link</link>
    </plugin>
    <plugin filename="libroboticsgroup_gazebo_disable_link_plugin.so" name="LFinger22_link">
      <link>LFinger22_link</link>
    </plugin>
    <plugin filename="libroboticsgroup_gazebo_disable_link_plugin.so" name="LFinger23_link">
      <link>LFinger23_link</link>
    </plugin>
    <plugin filename="libroboticsgroup_gazebo_disable_link_plugin.so" name="LFinger31_link">
      <link>LFinger31_link</link>
    </plugin>
    <plugin filename="libroboticsgroup_gazebo_disable_link_plugin.so" name="LFinger32_link">
      <link>LFinger32_link</link>
    </plugin>
    <plugin filename="libroboticsgroup_gazebo_disable_link_plugin.so" name="LFinger33_link">
      <link>LFinger33_link</link>
    </plugin>
    <plugin filename="libroboticsgroup_gazebo_disable_link_plugin.so" name="LFinger41_link">
      <link>LFinger41_link</link>
    </plugin>
    <plugin filename="libroboticsgroup_gazebo_disable_link_plugin.so" name="LFinger42_link">
      <link>LFinger42_link</link>
    </plugin>
    <plugin filename="libroboticsgroup_gazebo_disable_link_plugin.so" name="LFinger43_link">
      <link>LFinger43_link</link>
    </plugin>
    <plugin filename="libroboticsgroup_gazebo_disable_link_plugin.so" name="LThumb1_link">
      <link>LThumb1_link</link>
    </plugin>
    <plugin filename="libroboticsgroup_gazebo_disable_link_plugin.so" name="LThumb2_link">
      <link>LThumb2_link</link>
    </plugin>
    <plugin filename="libroboticsgroup_gazebo_disable_link_plugin.so" name="l_gripper">
      <link>l_gripper</link>
    </plugin>
    <plugin filename="libroboticsgroup_gazebo_disable_link_plugin.so" name="RFinger11_link">
      <link>RFinger11_link</link>
    </plugin>
    <plugin filename="libroboticsgroup_gazebo_disable_link_plugin.so" name="RFinger12_link">
      <link>RFinger12_link</link>
    </plugin>
    <plugin filename="libroboticsgroup_gazebo_disable_link_plugin.so" name="RFinger13_link">
      <link>RFinger13_link</link>
    </plugin>
    <plugin filename="libroboticsgroup_gazebo_disable_link_plugin.so" name="RFinger21_link">
      <link>RFinger21_link</link>
    </plugin>
    <plugin filename="libroboticsgroup_gazebo_disable_link_plugin.so" name="RFinger22_link">
      <link>RFinger22_link</link>
    </plugin>
    <plugin filename="libroboticsgroup_gazebo_disable_link_plugin.so" name="RFinger23_link">
      <link>RFinger23_link</link>
    </plugin>
    <plugin filename="libroboticsgroup_gazebo_disable_link_plugin.so" name="RFinger31_link">
      <link>RFinger31_link</link>
    </plugin>
    <plugin filename="libroboticsgroup_gazebo_disable_link_plugin.so" name="RFinger32_link">
      <link>RFinger32_link</link>
    </plugin>
    <plugin filename="libroboticsgroup_gazebo_disable_link_plugin.so" name="RFinger33_link">
      <link>RFinger33_link</link>
    </plugin>
    <plugin filename="libroboticsgroup_gazebo_disable_link_plugin.so" name="RFinger41_link">
      <link>RFinger41_link</link>
    </plugin>
    <plugin filename="libroboticsgroup_gazebo_disable_link_plugin.so" name="RFinger42_link">
      <link>RFinger42_link</link>
    </plugin>
    <plugin filename="libroboticsgroup_gazebo_disable_link_plugin.so" name="RFinger43_link">
      <link>RFinger43_link</link>
    </plugin>
    <plugin filename="libroboticsgroup_gazebo_disable_link_plugin.so" name="RThumb1_link">
      <link>RThumb1_link</link>
    </plugin>
    <plugin filename="libroboticsgroup_gazebo_disable_link_plugin.so" name="RThumb2_link">
      <link>RThumb2_link</link>
    </plugin>
    <plugin filename="libroboticsgroup_gazebo_disable_link_plugin.so" name="r_gripper">
      <link>r_gripper</link>
    </plugin>
  </gazebo>
  <!-- END OF GAZEBO ROS CONTROL PLUGIN -->
  <!-- GAZEBO MATERIALS -->
  <gazebo reference="base_footprint">
    <turnGravityOff>false</turnGravityOff>
  </gazebo>
  <!--gazebo reference="base_link">
    <turnGravityOff>false</turnGravityOff>
  </gazebo-->
  <gazebo reference="torso">
    <mu1>0.5</mu1>
    <mu2>0.5</mu2>
    <selfCollide>false</selfCollide>
    <turnGravityOff>false</turnGravityOff>
  </gazebo>
  <gazebo reference="Neck">
    <mu1>0.5</mu1>
    <mu2>0.5</mu2>
    <selfCollide>false</selfCollide>
    <turnGravityOff>false</turnGravityOff>
  </gazebo>
  <gazebo reference="Head">
    <mu1>0.5</mu1>
    <mu2>0.5</mu2>
    <selfCollide>false</selfCollide>
    <turnGravityOff>false</turnGravityOff>
  </gazebo>
  <gazebo reference="gaze">
    <mu1>0.5</mu1>
    <mu2>0.5</mu2>
    <selfCollide>false</selfCollide>
    <turnGravityOff>false</turnGravityOff>
  </gazebo>
  <!-- ARMS -->
  <gazebo reference="LShoulder">
    <mu1>0.5</mu1>
    <mu2>0.5</mu2>
    <selfCollide>false</selfCollide>
    <turnGravityOff>false</turnGravityOff>
  </gazebo>
  <gazebo reference="LBicep">
    <mu1>0.5</mu1>
    <mu2>0.5</mu2>
    <selfCollide>false</selfCollide>
    <turnGravityOff>false</turnGravityOff>
  </gazebo>
  <gazebo reference="LElbow">
    <mu1>0.5</mu1>
    <mu2>0.5</mu2>
    <selfCollide>false</selfCollide>
    <turnGravityOff>false</turnGravityOff>
  </gazebo>
  <gazebo reference="LForeArm">
    <mu1>0.5</mu1>
    <mu2>0.5</mu2>
    <selfCollide>false</selfCollide>
    <turnGravityOff>false</turnGravityOff>
  </gazebo>
  <gazebo reference="l_wrist">
    <mu1>0.5</mu1>
    <mu2>0.5</mu2>
    <selfCollide>false</selfCollide>
    <turnGravityOff>false</turnGravityOff>
  </gazebo>
  <gazebo reference="l_gripper">
    <mu1>0.5</mu1>
    <mu2>0.5</mu2>
    <selfCollide>false</selfCollide>
    <turnGravityOff>true</turnGravityOff>
  </gazebo>
  <gazebo reference="RShoulder">
    <mu1>0.5</mu1>
    <mu2>0.5</mu2>
    <selfCollide>false</selfCollide>
    <turnGravityOff>false</turnGravityOff>
  </gazebo>
  <gazebo reference="RBicep">
    <mu1>0.5</mu1>
    <mu2>0.5</mu2>
    <selfCollide>false</selfCollide>
    <turnGravityOff>false</turnGravityOff>
  </gazebo>
  <gazebo reference="RElbow">
    <mu1>0.5</mu1>
    <mu2>0.5</mu2>
    <selfCollide>false</selfCollide>
    <turnGravityOff>false</turnGravityOff>
  </gazebo>
  <gazebo reference="RForeArm">
    <mu1>0.5</mu1>
    <mu2>0.5</mu2>
    <selfCollide>false</selfCollide>
    <turnGravityOff>false</turnGravityOff>
  </gazebo>
  <gazebo reference="r_wrist">
    <mu1>0.5</mu1>
    <mu2>0.5</mu2>
    <selfCollide>false</selfCollide>
    <turnGravityOff>false</turnGravityOff>
  </gazebo>
  <gazebo reference="r_gripper">
    <mu1>0.5</mu1>
    <mu2>0.5</mu2>
    <selfCollide>false</selfCollide>
    <turnGravityOff>true</turnGravityOff>
  </gazebo>
  <gazebo reference="LFinger11_link">
    <mu1>0.5</mu1>
    <mu2>0.5</mu2>
    <selfCollide>false</selfCollide>
    <turnGravityOff>true</turnGravityOff>
  </gazebo>
  <gazebo reference="LFinger12_link">
    <mu1>0.5</mu1>
    <mu2>0.5</mu2>
    <selfCollide>false</selfCollide>
    <turnGravityOff>true</turnGravityOff>
  </gazebo>
  <gazebo reference="LFinger13_link">
    <mu1>0.5</mu1>
    <mu2>0.5</mu2>
    <selfCollide>false</selfCollide>
    <turnGravityOff>true</turnGravityOff>
  </gazebo>
  <gazebo reference="LFinger21_link">
    <mu1>0.5</mu1>
    <mu2>0.5</mu2>
    <selfCollide>false</selfCollide>
    <turnGravityOff>true</turnGravityOff>
  </gazebo>
  <gazebo reference="LFinger22_link">
    <mu1>0.5</mu1>
    <mu2>0.5</mu2>
    <selfCollide>false</selfCollide>
    <turnGravityOff>true</turnGravityOff>
  </gazebo>
  <gazebo reference="LFinger23_link">
    <mu1>0.5</mu1>
    <mu2>0.5</mu2>
    <selfCollide>false</selfCollide>
    <turnGravityOff>true</turnGravityOff>
  </gazebo>
  <gazebo reference="LFinger31_link">
    <mu1>0.5</mu1>
    <mu2>0.5</mu2>
    <selfCollide>false</selfCollide>
    <turnGravityOff>true</turnGravityOff>
  </gazebo>
  <gazebo reference="LFinger32_link">
    <mu1>0.5</mu1>
    <mu2>0.5</mu2>
    <selfCollide>false</selfCollide>
    <turnGravityOff>true</turnGravityOff>
  </gazebo>
  <gazebo reference="LFinger33_link">
    <mu1>0.5</mu1>
    <mu2>0.5</mu2>
    <selfCollide>false</selfCollide>
    <turnGravityOff>true</turnGravityOff>
  </gazebo>
  <gazebo reference="LFinger41_link">
    <mu1>0.5</mu1>
    <mu2>0.5</mu2>
    <selfCollide>false</selfCollide>
    <turnGravityOff>true</turnGravityOff>
  </gazebo>
  <gazebo reference="LFinger42_link">
    <mu1>0.5</mu1>
    <mu2>0.5</mu2>
    <selfCollide>false</selfCollide>
    <turnGravityOff>true</turnGravityOff>
  </gazebo>
  <gazebo reference="LFinger43_link">
    <mu1>0.5</mu1>
    <mu2>0.5</mu2>
    <selfCollide>false</selfCollide>
    <turnGravityOff>true</turnGravityOff>
  </gazebo>
  <gazebo reference="LThumb1_link">
    <mu1>0.5</mu1>
    <mu2>0.5</mu2>
    <selfCollide>false</selfCollide>
    <turnGravityOff>true</turnGravityOff>
  </gazebo>
  <gazebo reference="LThumb2_link">
    <mu1>0.5</mu1>
    <mu2>0.5</mu2>
    <selfCollide>false</selfCollide>
    <turnGravityOff>true</turnGravityOff>
  </gazebo>
  <gazebo reference="Hip">
    <mu1>0.5</mu1>
    <mu2>0.5</mu2>
    <selfCollide>false</selfCollide>
    <turnGravityOff>false</turnGravityOff>
  </gazebo>
  <gazebo reference="Pelvis">
    <mu1>0.5</mu1>
    <mu2>0.5</mu2>
    <selfCollide>false</selfCollide>
    <turnGravityOff>false</turnGravityOff>
  </gazebo>
  <gazebo reference="Tibia">
    <mu1>0.5</mu1>
    <mu2>0.5</mu2>
    <selfCollide>false</selfCollide>
    <turnGravityOff>false</turnGravityOff>
  </gazebo>
  <gazebo reference="WheelFL_link">
    <mu1>1</mu1>
    <mu2>0</mu2>
    <kp value="10000000.0"/>
    <kd value="1.0"/>
    <fdir1 value="1 0 0"/>
    <minDepth>0.003</minDepth>
    <turnGravityOff>false</turnGravityOff>
  </gazebo>
  <gazebo reference="WheelB_link">
    <mu1>0.5</mu1>
    <mu2>0.5</mu2>
    <kp value="10000000.0"/>
    <kd value="1.0"/>
    <fdir1 value="1 0 0"/>
    <minDepth>0.003</minDepth>
    <turnGravityOff>false</turnGravityOff>
  </gazebo>
  <gazebo reference="WheelFR_link">
    <mu1>0</mu1>
    <mu2>1</mu2>
    <kp value="10000000.0"/>
    <kd value="1.0"/>
    <fdir1 value="0 1 0"/>
    <minDepth>0.003</minDepth>
    <turnGravityOff>false</turnGravityOff>
  </gazebo>
  <gazebo reference="RFinger11_link">
    <mu1>0.5</mu1>
    <mu2>0.5</mu2>
    <selfCollide>false</selfCollide>
    <turnGravityOff>true</turnGravityOff>
  </gazebo>
  <gazebo reference="RFinger12_link">
    <mu1>0.5</mu1>
    <mu2>0.5</mu2>
    <selfCollide>false</selfCollide>
    <turnGravityOff>true</turnGravityOff>
  </gazebo>
  <gazebo reference="RFinger13_link">
    <mu1>0.5</mu1>
    <mu2>0.5</mu2>
    <selfCollide>false</selfCollide>
    <turnGravityOff>true</turnGravityOff>
  </gazebo>
  <gazebo reference="RFinger21_link">
    <mu1>0.5</mu1>
    <mu2>0.5</mu2>
    <selfCollide>false</selfCollide>
    <turnGravityOff>true</turnGravityOff>
  </gazebo>
  <gazebo reference="RFinger22_link">
    <mu1>0.5</mu1>
    <mu2>0.5</mu2>
    <selfCollide>false</selfCollide>
    <turnGravityOff>true</turnGravityOff>
  </gazebo>
  <gazebo reference="RFinger23_link">
    <mu1>0.5</mu1>
    <mu2>0.5</mu2>
    <selfCollide>false</selfCollide>
    <turnGravityOff>true</turnGravityOff>
  </gazebo>
  <gazebo reference="RFinger31_link">
    <mu1>0.5</mu1>
    <mu2>0.5</mu2>
    <selfCollide>false</selfCollide>
    <turnGravityOff>true</turnGravityOff>
  </gazebo>
  <gazebo reference="RFinger32_link">
    <mu1>0.5</mu1>
    <mu2>0.5</mu2>
    <selfCollide>false</selfCollide>
    <turnGravityOff>true</turnGravityOff>
  </gazebo>
  <gazebo reference="RFinger33_link">
    <mu1>0.5</mu1>
    <mu2>0.5</mu2>
    <selfCollide>false</selfCollide>
    <turnGravityOff>true</turnGravityOff>
  </gazebo>
  <gazebo reference="RFinger41_link">
    <mu1>0.5</mu1>
    <mu2>0.5</mu2>
    <selfCollide>false</selfCollide>
    <turnGravityOff>true</turnGravityOff>
  </gazebo>
  <gazebo reference="RFinger42_link">
    <mu1>0.5</mu1>
    <mu2>0.5</mu2>
    <selfCollide>false</selfCollide>
    <turnGravityOff>true</turnGravityOff>
  </gazebo>
  <gazebo reference="RFinger43_link">
    <mu1>0.5</mu1>
    <mu2>0.5</mu2>
    <selfCollide>false</selfCollide>
    <turnGravityOff>true</turnGravityOff>
  </gazebo>
  <gazebo reference="RThumb1_link">
    <mu1>0.5</mu1>
    <mu2>0.5</mu2>
    <selfCollide>false</selfCollide>
    <turnGravityOff>true</turnGravityOff>
  </gazebo>
  <gazebo reference="RThumb2_link">
    <mu1>0.5</mu1>
    <mu2>0.5</mu2>
    <selfCollide>false</selfCollide>
    <turnGravityOff>true</turnGravityOff>
  </gazebo>
  <!--
        RGB CAMERAS:
-->
  <gazebo reference="CameraTop_frame">
    <sensor name="CameraTop" type="camera">
      <update_rate>5.0</update_rate>
      <camera name="camera_top">
        <horizontal_fov>1.0</horizontal_fov>
        <image>
          <width>640</width>
          <height>480</height>
          <format>R8G8B8</format>
        </image>
        <clip>
          <near>0.3</near>
          <far>500</far>
        </clip>
        <noise>
          <type>gaussian</type>
          <mean>0.0</mean>
          <stddev>0.007</stddev>
        </noise>
      </camera>
      <plugin filename="libgazebo_ros_camera.so" name="camera_controller">
        <robotNamespace>/pepper_robot</robotNamespace>
        <alwaysOn>true</alwaysOn>
        <updateRate>5.0</updateRate>
        <cameraName>camera/front</cameraName>
        <imageTopicName>image_raw</imageTopicName>
        <cameraInfoTopicName>camera_info</cameraInfoTopicName>
        <frameName>CameraTop_optical_frame</frameName>
        <hackBaseline>0.07</hackBaseline>
        <distortionK1>-0.0545211</distortionK1>
        <distortionK2>0.06919734</distortionK2>
        <distortionK3>-0.0241095</distortionK3>
        <distortionT1>-0.0112245</distortionT1>
        <distortionT2>0.0</distortionT2>
      </plugin>
    </sensor>
  </gazebo>
  <gazebo reference="CameraBottom_frame">
    <sensor name="CameraBottom" type="camera">
      <update_rate>5.0</update_rate>
      <camera name="camera_bottom">
        <horizontal_fov>1.0</horizontal_fov>
        <image>
          <width>640</width>
          <height>480</height>
          <format>R8G8B8</format>
        </image>
        <clip>
          <near>0.05</near>
          <far>500</far>
        </clip>
        <noise>
          <type>gaussian</type>
          <mean>0.0</mean>
          <stddev>0.007</stddev>
        </noise>
      </camera>
      <plugin filename="libgazebo_ros_camera.so" name="camera_controller">
        <robotNamespace>/pepper_robot</robotNamespace>
        <alwaysOn>true</alwaysOn>
        <updateRate>5.0</updateRate>
        <cameraName>camera/bottom</cameraName>
        <imageTopicName>image_raw</imageTopicName>
        <cameraInfoTopicName>camera_info</cameraInfoTopicName>
        <frameName>CameraBottom_optical_frame</frameName>
        <hackBaseline>0.07</hackBaseline>
        <distortionK1>-0.0648764</distortionK1>
        <distortionK2>0.06125202</distortionK2>
        <distortionK3>0.00382815</distortionK3>
        <distortionT1>-0.00551104</distortionT1>
        <distortionT2>0.0</distortionT2>
      </plugin>
    </sensor>
  </gazebo>
  <!-- 
    BUMPERS

<gazebo reference="BumperB_frame">
  <mu1>0.5</mu1>
  <mu2>0.5</mu2>
  <selfCollide>false</selfCollide>
  <turnGravityOff>false</turnGravityOff>
  <fdir1>1 0 0</fdir1>
  <maxVel>0.1</maxVel>
  <minDepth>0.003</minDepth>
  <sensor name="BumperB" type="contact">
    <always_on>1</always_on>
    <update_rate>20</update_rate>
    <visualize>false</visualize>
    <contact>
      <collision>BumperB_frame_collision</collision>
    </contact>
    <plugin filename="libgazebo_ros_bumper.so" name="gazebo_pepper_BumperB">
      <robotNamespace>pepper_robot</robotNamespace>
      <alwaysOn>true</alwaysOn>
      <bumperTopicName>Bumper/Back</bumperTopicName>
      <frameName>BumperB_frame</frameName>
    </plugin>
  </sensor>
</gazebo>

<gazebo reference="BumperFL_frame">
  <mu1>0.5</mu1>
  <mu2>0.5</mu2>
  <selfCollide>false</selfCollide>
  <turnGravityOff>false</turnGravityOff>
  <fdir1>1 0 0</fdir1>
  <maxVel>0.1</maxVel>
  <minDepth>0.003</minDepth>
  <sensor name="BumperFL" type="contact">
    <always_on>1</always_on>
    <update_rate>20</update_rate>
    <visualize>false</visualize>
    <contact>
      <collision>BumperFL_frame_collision</collision>
    </contact>
    <plugin filename="libgazebo_ros_bumper.so" name="gazebo_pepper_BumperFL">
      <robotNamespace>pepper_robot</robotNamespace>
      <alwaysOn>true</alwaysOn>
      <bumperTopicName>Bumper/FrontLeft</bumperTopicName>
      <frameName>BumperFL_frame</frameName>
    </plugin>
  </sensor>
</gazebo>

<gazebo reference="BumperFR_frame">
  <mu1>0.5</mu1>
  <mu2>0.5</mu2>
  <selfCollide>false</selfCollide>
  <turnGravityOff>false</turnGravityOff>
  <fdir1>1 0 0</fdir1>
  <maxVel>0.1</maxVel>
  <minDepth>0.003</minDepth>
  <sensor name="BumperFR" type="contact">
    <always_on>1</always_on>
    <update_rate>20</update_rate>
    <visualize>false</visualize>
    <contact>
      <collision>BumperFR_frame_collision</collision>
    </contact>
    <plugin filename="libgazebo_ros_bumper.so" name="gazebo_pepper_BumperFR">
      <robotNamespace>pepper_robot</robotNamespace>
      <alwaysOn>true</alwaysOn>
      <bumperTopicName>Bumper/FrontRight</bumperTopicName>
      <frameName>BumperFR_frame</frameName>
    </plugin>
  </sensor>
</gazebo>
-->
  <!--
    Sonars
-->
  <!--
<gazebo reference="SonarBack_frame">
  <sensor type="ray" name="SonarBack">
    <pose>0 0 0 0 0 0</pose>
    <update_rate>20</update_rate>
    <visualize>false</visualize>
    <ray>
      <scan>
        <horizontal>
          <samples>5</samples>
          <resolution>1</resolution>
          <min_angle>-0.2617993877991494</min_angle>
          <max_angle>0.2617993877991494</max_angle> 
        </horizontal>
        <vertical>
          <samples>5</samples>
          <resolution>1</resolution>
          <min_angle>-0.13</min_angle>
          <max_angle>0.13</max_angle> 
        </vertical>
      </scan>
      <range>
        <min>0.025</min>
        <max>2.55</max>
        <resolution>1</resolution>
      </range>
    </ray>
    <plugin filename="libgazebo_ros_range.so" name="gazebo_ros_range">
      <robotNamespace>pepper_robot</robotNamespace>
      <gaussianNoise>0.05</gaussianNoise>
      <alwaysOn>true</alwaysOn>
      <updateRate>20</updateRate>
      <topicName>sonar_back</topicName>
      <frameName>SonarBack_frame</frameName>
      <minRange>0.025</minRange>
      <maxRange>2.55</maxRange>
      <fov>0.5235987755982988</fov> 
      <radiation>ultrasound</radiation>
    </plugin>
  </sensor>
</gazebo> 

<gazebo reference="SonarFront_frame">
  <sensor type="ray" name="SonarFront">
    <pose>0 0 0 0 0 0</pose>
    <update_rate>20</update_rate>
    <visualize>false</visualize>
    <ray>
      <scan>
        <horizontal>
          <samples>5</samples>
          <resolution>1</resolution>
          <min_angle>-0.2617993877991494</min_angle>
          <max_angle>0.2617993877991494</max_angle> 
        </horizontal>
        <vertical>
          <samples>5</samples>
          <resolution>1</resolution>
          <min_angle>-0.13</min_angle>
          <max_angle>0.13</max_angle>
        </vertical>
      </scan>
      <range>
        <min>0.025</min>
        <max>2.55</max> 
        <resolution>1</resolution>
      </range>
    </ray>
    <plugin filename="libgazebo_ros_range.so" name="gazebo_ros_range">
      <robotNamespace>pepper_robot</robotNamespace>
      <gaussianNoise>0.05</gaussianNoise>
      <alwaysOn>true</alwaysOn>
      <updateRate>20</updateRate>
      <topicName>sonar_front</topicName>
      <frameName>SonarFront_frame</frameName>
      <minRange>0.025</minRange>
      <maxRange>2.55</maxRange>
      <fov>0.5235987755982988</fov>
      <radiation>ultrasound</radiation>
    </plugin>
  </sensor>
</gazebo> 
-->
  <gazebo>
    <plugin filename="libgazebo_ros_diff_drive.so" name="differential_drive_controller">
      <alwaysOn>true</alwaysOn>
      <updateRate>100</updateRate>
      <robotNamespace>/</robotNamespace>
      <leftJoint>WheelFL</leftJoint>
      <rightJoint>WheelFR</rightJoint>
      <wheelSeparation>0.170</wheelSeparation>
      <wheelDiameter>0.140</wheelDiameter>
      <torque>36.9</torque>
      <commandTopic>cmd_vel</commandTopic>
      <odometryTopic>odom_diffdrive</odometryTopic>
      <odometryFrame>odom</odometryFrame>
      <robotBaseFrame>base_footprint</robotBaseFrame>
    </plugin>
  </gazebo>
  <!-- HEAD -->
  <transmission name="HeadYaw_Transmission">
    <type>transmission_interface/SimpleTransmission</type>
    <joint name="HeadYaw">
      <hardwareInterface>PositionJointInterface</hardwareInterface>
    </joint>
    <actuator name="HeadYaw_Motor">
      <!-- Dummy Values -->
      <hardwareInterface>PositionJointInterface</hardwareInterface>
      <mechanicalReduction>101.3</mechanicalReduction>
    </actuator>
  </transmission>
  <transmission name="HeadPitch_Transmission">
    <type>transmission_interface/SimpleTransmission</type>
    <joint name="HeadPitch">
      <hardwareInterface>PositionJointInterface</hardwareInterface>
    </joint>
    <actuator name="HeadPitch_Motor">
      <!-- Dummy Values -->
      <hardwareInterface>PositionJointInterface</hardwareInterface>
      <mechanicalReduction>118.1</mechanicalReduction>
    </actuator>
  </transmission>
  <!-- ARMS -->
  <!-- XACRO -->
  <transmission name="LShoulderPitch_Transmission">
    <type>transmission_interface/SimpleTransmission</type>
    <joint name="LShoulderPitch">
      <hardwareInterface>PositionJointInterface</hardwareInterface>
    </joint>
    <actuator name="LShoulderPitch_Motor">
      <hardwareInterface>PositionJointInterface</hardwareInterface>
      <mechanicalReduction>101.3</mechanicalReduction>
    </actuator>
  </transmission>
  <transmission name="LShoulderRoll_Transmission">
    <type>transmission_interface/SimpleTransmission</type>
    <joint name="LShoulderRoll">
      <hardwareInterface>PositionJointInterface</hardwareInterface>
    </joint>
    <actuator name="LShoulderRoll_Motor">
      <hardwareInterface>PositionJointInterface</hardwareInterface>
      <mechanicalReduction>118.1</mechanicalReduction>
    </actuator>
  </transmission>
  <transmission name="LElbowYaw_Transmission">
    <type>transmission_interface/SimpleTransmission</type>
    <joint name="LElbowYaw">
      <hardwareInterface>PositionJointInterface</hardwareInterface>
    </joint>
    <actuator name="LElbowYaw_Motor">
      <hardwareInterface>PositionJointInterface</hardwareInterface>
      <mechanicalReduction>101.3</mechanicalReduction>
    </actuator>
  </transmission>
  <transmission name="LElbowRoll_Transmission">
    <type>transmission_interface/SimpleTransmission</type>
    <joint name="LElbowRoll">
      <hardwareInterface>PositionJointInterface</hardwareInterface>
    </joint>
    <actuator name="LElbowRoll_Motor">
      <hardwareInterface>PositionJointInterface</hardwareInterface>
      <mechanicalReduction>118.1</mechanicalReduction>
    </actuator>
  </transmission>
  <transmission name="LWristYaw_Transmission">
    <type>transmission_interface/SimpleTransmission</type>
    <joint name="LWristYaw">
      <hardwareInterface>PositionJointInterface</hardwareInterface>
    </joint>
    <actuator name="LWristYaw_Motor">
      <hardwareInterface>PositionJointInterface</hardwareInterface>
      <mechanicalReduction>118.1</mechanicalReduction>
    </actuator>
  </transmission>
  <transmission name="LHand_Transmission">
    <type>transmission_interface/SimpleTransmission</type>
    <joint name="LHand">
      <hardwareInterface>PositionJointInterface</hardwareInterface>
    </joint>
    <actuator name="LHand_Motor">
      <hardwareInterface>PositionJointInterface</hardwareInterface>
      <mechanicalReduction>36.24</mechanicalReduction>
    </actuator>
  </transmission>
  <transmission name="RShoulderPitch_Transmission">
    <type>transmission_interface/SimpleTransmission</type>
    <joint name="RShoulderPitch">
      <hardwareInterface>PositionJointInterface</hardwareInterface>
    </joint>
    <actuator name="RShoulderPitch_Motor">
      <hardwareInterface>PositionJointInterface</hardwareInterface>
      <mechanicalReduction>101.3</mechanicalReduction>
    </actuator>
  </transmission>
  <transmission name="RShoulderRoll_Transmission">
    <type>transmission_interface/SimpleTransmission</type>
    <joint name="RShoulderRoll">
      <hardwareInterface>PositionJointInterface</hardwareInterface>
    </joint>
    <actuator name="RShoulderRoll_Motor">
      <hardwareInterface>PositionJointInterface</hardwareInterface>
      <mechanicalReduction>118.1</mechanicalReduction>
    </actuator>
  </transmission>
  <transmission name="RElbowYaw_Transmission">
    <type>transmission_interface/SimpleTransmission</type>
    <joint name="RElbowYaw">
      <hardwareInterface>PositionJointInterface</hardwareInterface>
    </joint>
    <actuator name="RElbowYaw_Motor">
      <hardwareInterface>PositionJointInterface</hardwareInterface>
      <mechanicalReduction>101.3</mechanicalReduction>
    </actuator>
  </transmission>
  <transmission name="RElbowRoll_Transmission">
    <type>transmission_interface/SimpleTransmission</type>
    <joint name="RElbowRoll">
      <hardwareInterface>PositionJointInterface</hardwareInterface>
    </joint>
    <actuator name="RElbowRoll_Motor">
      <hardwareInterface>PositionJointInterface</hardwareInterface>
      <mechanicalReduction>118.1</mechanicalReduction>
    </actuator>
  </transmission>
  <transmission name="RWristYaw_Transmission">
    <type>transmission_interface/SimpleTransmission</type>
    <joint name="RWristYaw">
      <hardwareInterface>PositionJointInterface</hardwareInterface>
    </joint>
    <actuator name="RWristYaw_Motor">
      <hardwareInterface>PositionJointInterface</hardwareInterface>
      <mechanicalReduction>118.1</mechanicalReduction>
    </actuator>
  </transmission>
  <transmission name="RHand_Transmission">
    <type>transmission_interface/SimpleTransmission</type>
    <joint name="RHand">
      <hardwareInterface>PositionJointInterface</hardwareInterface>
    </joint>
    <actuator name="RHand_Motor">
      <hardwareInterface>PositionJointInterface</hardwareInterface>
      <mechanicalReduction>36.24</mechanicalReduction>
    </actuator>
  </transmission>
  <!-- LEGS -->
  <transmission name="HipRoll_Transmission">
    <type>transmission_interface/SimpleTransmission</type>
    <joint name="HipRoll">
      <hardwareInterface>PositionJointInterface</hardwareInterface>
    </joint>
    <actuator name="HipRoll_Motor">
      <!-- Dummy Values -->
      <hardwareInterface>PositionJointInterface</hardwareInterface>
      <mechanicalReduction>108.33</mechanicalReduction>
    </actuator>
  </transmission>
  <transmission name="HipPitch_Transmission">
    <type>transmission_interface/SimpleTransmission</type>
    <joint name="HipPitch">
      <hardwareInterface>PositionJointInterface</hardwareInterface>
    </joint>
    <actuator name="HipPitch_Motor">
      <!-- Dummy Values -->
      <hardwareInterface>PositionJointInterface</hardwareInterface>
      <mechanicalReduction>108.33</mechanicalReduction>
    </actuator>
  </transmission>
  <transmission name="KneePitch_Transmission">
    <type>transmission_interface/SimpleTransmission</type>
    <joint name="KneePitch">
      <hardwareInterface>PositionJointInterface</hardwareInterface>
    </joint>
    <actuator name="KneePitch_Motor">
      <!-- Dummy Values -->
      <hardwareInterface>PositionJointInterface</hardwareInterface>
      <mechanicalReduction>108.33</mechanicalReduction>
    </actuator>
  </transmission>
  <!-- XACRO -->
  <transmission name="WheelFL_Transmission">
    <type>transmission_interface/SimpleTransmission</type>
    <joint name="WheelFL">
      <hardwareInterface>EffortJointInterface</hardwareInterface>
    </joint>
    <actuator name="WheelFL_Motor">
      <!-- Dummy Values -->
      <hardwareInterface>EffortJointInterface</hardwareInterface>
      <mechanicalReduction>25.0</mechanicalReduction>
    </actuator>
  </transmission>
  <transmission name="WheelB_Transmission">
    <type>transmission_interface/SimpleTransmission</type>
    <joint name="WheelB">
      <hardwareInterface>EffortJointInterface</hardwareInterface>
    </joint>
    <actuator name="WheelB_Motor">
      <!-- Dummy Values -->
      <hardwareInterface>EffortJointInterface</hardwareInterface>
      <mechanicalReduction>25.0</mechanicalReduction>
    </actuator>
  </transmission>
  <transmission name="WheelFR_Transmission">
    <type>transmission_interface/SimpleTransmission</type>
    <joint name="WheelFR">
      <hardwareInterface>EffortJointInterface</hardwareInterface>
    </joint>
    <actuator name="WheelFR_Motor">
      <!-- Dummy Values -->
      <hardwareInterface>EffortJointInterface</hardwareInterface>
      <mechanicalReduction>25.0</mechanicalReduction>
    </actuator>
  </transmission>
</robot>
