<?xml version="1.0" ?>
<!-- =================================================================================== -->
<!-- |    This document was autogenerated by xacro from panda_arm_hand.urdf.xacro      | -->
<!-- |    EDITING THIS FILE BY HAND IS NOT RECOMMENDED                                 | -->
<!-- =================================================================================== -->
<robot name="panda" xmlns:xacro="http://www.ros.org/wiki/xacro">
  <link name="panda_link0">
    <inertial> <!-- these inertia are calculated based on the visual meshes using Meshlab, and using a density of 1kg/m^3 (http://gazebosim.org/tutorials?tut=inertia) -->
      <mass value="1"/> <!-- volume = 0.002442 -->
      <origin xyz="-0.025566 -0.000029 0.057332"/>
      <!--inertia ixx="0.000007" ixy="0.0" ixz="-0.000001" iyy="0.000009" iyz="0.0" izz="0.000009"/-->
      <inertia ixx="0.00286650" ixy="0.0" ixz="-0.0004095" iyy="0.00368550" iyz="0.0" izz="0.00368550"/> <!-- divided by the volume, just need to be multiplied by the mass -->
    </inertial>
    <visual>
      <geometry>
        <mesh filename="meshes/visual/link0.stl"/>
      </geometry>
    </visual>
    <collision>
      <geometry>
        <mesh filename="meshes/collision/link0.stl"/>
      </geometry>
    </collision>
  </link>
  <link name="panda_link1">
    <inertial> <!-- these inertia are calculated based on the visual meshes using Meshlab, and using a density of 1kg/m^3 (http://gazebosim.org/tutorials?tut=inertia) -->
      <mass value="1"/> <!-- volume = 0.002293 -->
      <origin xyz="-0.000000 -0.032496 -0.067582"/>
      <!--inertia ixx="0.000015" ixy="0.0" ixz="0.0" iyy="0.000013" iyz="0.000004" izz="0.000005"/-->
      <inertia ixx="0.00654165" ixy="0.0" ixz="0.0" iyy="0.00566943" iyz="0.00174444" izz="0.00218055"/> <!-- divided by the volume, just need to be multiplied by the mass -->
    </inertial>
    <visual>
      <geometry>
        <mesh filename="meshes/visual/link1.stl"/>
      </geometry>
    </visual>
    <collision>
      <geometry>
        <mesh filename="meshes/collision/link1.stl"/>
      </geometry>
    </collision>
  </link>
  <joint name="panda_joint1" type="revolute">
    <safety_controller k_position="100.0" k_velocity="40.0" soft_lower_limit="-2.8973" soft_upper_limit="2.8973"/>
    <origin rpy="0 0 0" xyz="0 0 0.333"/>
    <parent link="panda_link0"/>
    <child link="panda_link1"/>
    <axis xyz="0 0 1"/>
    <limit effort="87" lower="-2.9671" upper="2.9671" velocity="2.1750"/>
  </joint>
  <link name="panda_link2">
    <inertial> <!-- these inertia are calculated based on the visual meshes using Meshlab, and using a density of 1kg/m^3 (http://gazebosim.org/tutorials?tut=inertia) -->
      <mass value="1"/> <!-- volume = 0.002312 -->
      <origin xyz="0.000000 -0.068610 0.032229"/>
      <!--inertia ixx="0.000015" ixy="0.0" ixz="0.0" iyy="0.000005" iyz="0.000004" izz="0.000014"/-->
      <inertia ixx="0.00648789" ixy="0.0" ixz="0.0" iyy="0.00216263" iyz="0.0017301" izz="0.00605536"/> <!-- divided by the volume, just need to be multiplied by the mass -->
    </inertial>
    <visual>
      <geometry>
        <mesh filename="meshes/visual/link2.stl"/>
      </geometry>
    </visual>
    <collision>
      <geometry>
        <mesh filename="meshes/collision/link2.stl"/>
      </geometry>
    </collision>
  </link>
  <joint name="panda_joint2" type="revolute">
    <safety_controller k_position="100.0" k_velocity="40.0" soft_lower_limit="-1.7628" soft_upper_limit="1.7628"/>
    <origin rpy="-1.57079632679 0 0" xyz="0 0 0"/>
    <parent link="panda_link1"/>
    <child link="panda_link2"/>
    <axis xyz="0 0 1"/>
    <limit effort="87" lower="-1.8326" upper="1.8326" velocity="2.1750"/>
  </joint>
  <link name="panda_link3">
    <inertial> <!-- these inertia are calculated based on the visual meshes using Meshlab, and using a density of 1kg/m^3 (http://gazebosim.org/tutorials?tut=inertia) -->
      <mass value="1"/> <!-- volume = 0.002021 -->
      <origin xyz="0.046989 0.031637 -0.031704"/>
      <!--inertia ixx="0.000007" ixy="-0.000002" ixz="-0.000003" iyy="0.000008" iyz="-0.000002" izz="0.000007"/-->
      <inertia ixx="0.00346363" ixy="-0.0009896" ixz="-0.00148441" iyy="0.00395844" iyz="-0.0009896" izz="0.00346363"/> <!-- divided by the volume, just need to be multiplied by the mass -->
    </inertial>
    <visual>
      <geometry>
        <mesh filename="meshes/visual/link3.stl"/>
      </geometry>
    </visual>
    <collision>
      <geometry>
        <mesh filename="meshes/collision/link3.stl"/>
      </geometry>
    </collision>
  </link>
  <joint name="panda_joint3" type="revolute">
    <safety_controller k_position="100.0" k_velocity="40.0" soft_lower_limit="-2.8973" soft_upper_limit="2.8973"/>
    <origin rpy="1.57079632679 0 0" xyz="0 -0.316 0"/>
    <parent link="panda_link2"/>
    <child link="panda_link3"/>
    <axis xyz="0 0 1"/>
    <limit effort="87" lower="-2.9671" upper="2.9671" velocity="2.1750"/>
  </joint>
  <link name="panda_link4">
    <inertial> <!-- these inertia are calculated based on the visual meshes using Meshlab, and using a density of 1kg/m^3 (http://gazebosim.org/tutorials?tut=inertia) -->
      <mass value="1"/> <!-- volume = 0.002004 -->
      <origin xyz="-0.036051 0.033707 0.031902"/>
      <!--inertia ixx="0.000007" ixy="0.000003" ixz="-0.000002" iyy="0.000007" iyz="0.000002" izz="0.000009"/-->
      <inertia ixx="0.00349301" ixy="0.00149701" ixz="-0.00099800" iyy="0.00349301" iyz="0.00099800" izz="0.00449102"/> <!-- divided by the volume, just need to be multiplied by the mass -->
    </inertial>
    <visual>
      <geometry>
        <mesh filename="meshes/visual/link4.stl"/>
      </geometry>
    </visual>
    <collision>
      <geometry>
        <mesh filename="meshes/collision/link4.stl"/>
      </geometry>
    </collision>
  </link>
  <joint name="panda_joint4" type="revolute">
    <safety_controller k_position="100.0" k_velocity="40.0" soft_lower_limit="-3.0718" soft_upper_limit="-0.0698"/>
    <origin rpy="1.57079632679 0 0" xyz="0.0825 0 0"/>
    <parent link="panda_link3"/>
    <child link="panda_link4"/>
    <axis xyz="0 0 1"/>
    <limit effort="87" lower="-3.1416" upper="0.0" velocity="2.1750"/>
  </joint>
  <link name="panda_link5">
    <inertial> <!-- these inertia are calculated based on the visual meshes using Meshlab, and using a density of 1kg/m^3 (http://gazebosim.org/tutorials?tut=inertia) -->
      <mass value="1"/> <!-- volume = 0.002275 -->
      <origin xyz="-0.000006 0.061043 -0.104176"/>
      <!--inertia ixx="0.000025" ixy="0.000000" ixz="-0.000000" iyy="0.000024" iyz="-0.000006" izz="0.000004"/-->
      <inertia ixx="0.01098901" ixy="0.000000" ixz="0.000000" iyy="0.01054945" iyz="-0.00263736" izz="0.00175824"/> <!-- divided by the volume, just need to be multiplied by the mass -->
    </inertial>
    <visual>
      <geometry>
        <mesh filename="meshes/visual/link5.stl"/>
      </geometry>
    </visual>
    <collision>
      <geometry>
        <mesh filename="meshes/collision/link5.stl"/>
      </geometry>
    </collision>
  </link>
  <joint name="panda_joint5" type="revolute">
    <safety_controller k_position="100.0" k_velocity="40.0" soft_lower_limit="-2.8973" soft_upper_limit="2.8973"/>
    <origin rpy="-1.57079632679 0 0" xyz="-0.0825 0.384 0"/>
    <parent link="panda_link4"/>
    <child link="panda_link5"/>
    <axis xyz="0 0 1"/>
    <limit effort="12" lower="-2.9671" upper="2.9671" velocity="2.6100"/>
  </joint>
  <link name="panda_link6">
    <inertial> <!-- these inertia are calculated based on the visual meshes using Meshlab, and using a density of 1kg/m^3 (http://gazebosim.org/tutorials?tut=inertia) -->
      <mass value="1"/> <!-- volume = 0.001435 --> <!-- NOTE: BECAUSE MESHLAB OUTPUTED NAN FOR THE VISUAL MESH, I USED THE COLLISION MESH -->
      <origin xyz="0.051002 0.006933 0.006169"/>
      <!--inertia ixx="0.000002" ixy="0.000000" ixz="0.000000" iyy="0.000004" iyz="0.000000" izz="0.000004"/-->
      <inertia ixx="0.00139373" ixy="0.000000" ixz="0.000000" iyy="0.00278745" iyz="0.000000" izz="0.00278745"/> <!-- divided by the volume, just need to be multiplied by the mass -->
    </inertial>
    <visual>
      <geometry>
        <mesh filename="meshes/visual/link6.stl"/>
      </geometry>
    </visual>
    <collision>
      <geometry>
        <mesh filename="meshes/collision/link6.stl"/>
      </geometry>
    </collision>
  </link>
  <joint name="panda_joint6" type="revolute">
    <safety_controller k_position="100.0" k_velocity="40.0" soft_lower_limit="-0.0175" soft_upper_limit="3.7525"/>
    <origin rpy="1.57079632679 0 0" xyz="0 0 0"/>
    <parent link="panda_link5"/>
    <child link="panda_link6"/>
    <axis xyz="0 0 1"/>
    <limit effort="12" lower="-0.0873" upper="3.8223" velocity="2.6100"/>
  </joint>
  <link name="panda_link7">
    <inertial> <!-- these inertia are calculated based on the visual meshes using Meshlab, and using a density of 1kg/m^3 (http://gazebosim.org/tutorials?tut=inertia) -->
      <mass value="1"/> <!-- volume = 0.000454 -->
      <origin xyz="0.010969 0.010797 0.065041"/>
      <!--inertia ixx="0.000001" ixy="0.000000" ixz="0.000000" iyy="0.000001" iyz="0.000000" izz="0.000001"/-->
      <inertia ixx="0.00220264" ixy="0.000000" ixz="0.000000" iyy="0.00220264" iyz="0.000000" izz="0.00220264"/> <!-- divided by the volume, just need to be multiplied by the mass -->
    </inertial>
    <visual>
      <geometry>
        <mesh filename="meshes/visual/link7.stl"/>
      </geometry>
    </visual>
    <collision>
      <geometry>
        <mesh filename="meshes/collision/link7.stl"/>
      </geometry>
    </collision>
  </link>
  <joint name="panda_joint7" type="revolute">
    <safety_controller k_position="100.0" k_velocity="40.0" soft_lower_limit="-2.8973" soft_upper_limit="2.8973"/>
    <origin rpy="1.57079632679 0 0" xyz="0.088 0 0"/>
    <parent link="panda_link6"/>
    <child link="panda_link7"/>
    <axis xyz="0 0 1"/>
    <limit effort="12" lower="-2.9671" upper="2.9671" velocity="2.6100"/>
  </joint>
  <link name="panda_link8">
    <inertial>
      <origin rpy="0 0 0" xyz="0 0 0"/>
      <mass value="0"/>
      <inertia ixx="0.0" ixy="0.0" ixz="0.0" iyy="0.0" iyz="0.0" izz="0.0"/>
    </inertial>
  </link> <!-- in pybullet, the inertia need to be specified even for dummy links, otherwise it will put an identity inertia and a mass of 1 by default -->
  <joint name="panda_joint8" type="fixed">
    <origin rpy="0 0 0" xyz="0 0 0.107"/>
    <parent link="panda_link7"/>
    <child link="panda_link8"/>
    <axis xyz="0 0 0"/>
  </joint>
  <joint name="panda_hand_joint" type="fixed">
    <parent link="panda_link8"/>
    <child link="panda_hand"/>
    <origin rpy="0 0 -0.785398163397" xyz="0 0 0"/>
  </joint>
  <link name="panda_hand">
    <inertial> <!-- these inertia are calculated based on the visual meshes using Meshlab, and using a density of 1kg/m^3 (http://gazebosim.org/tutorials?tut=inertia) -->
      <mass value="1"/> <!-- volume = 0.000488 -->
      <origin xyz="-0.000007 0.001524 0.027591"/>
      <!--inertia ixx="0.000002" ixy="0.000000" ixz="0.000000" iyy="0.0000003" iyz="0.000000" izz="0.000002"/-->
      <inertia ixx="0.00409836" ixy="0.000000" ixz="0.000000" iyy="0.00061475" iyz="0.000000" izz="0.00409836"/> <!-- divided by the volume, just need to be multiplied by the mass -->
    </inertial>
    <visual>
      <geometry>
        <mesh filename="meshes/visual/hand.stl"/>
      </geometry>
    </visual>
    <collision>
      <geometry>
        <mesh filename="meshes/collision/hand.stl"/>
      </geometry>
    </collision>
  </link>
  <link name="panda_leftfinger">
    <inertial> <!-- these inertia are calculated based on the visual meshes using Meshlab, and using a density of 1kg/m^3 (http://gazebosim.org/tutorials?tut=inertia) -->
      <mass value="1"/> <!-- volume = 0.000011 -->
      <origin xyz="0.000002 0.014564 0.022794"/>
      <!--inertia ixx="0.00000000338" ixy="0.000000" ixz="0.000000" iyy="0.000000000332" iyz="0.00000000060" izz="0.00000000078"/-->
      <inertia ixx="0.00030727" ixy="0.000000" ixz="0.000000" iyy="0.00003018" iyz="0.00005455" izz="0.00007091"/> <!-- divided by the volume, just need to be multiplied by the mass -->
    </inertial>
    <visual>
      <geometry>
        <mesh filename="meshes/visual/finger.stl"/>
      </geometry>
    </visual>
    <collision>
      <geometry>
        <mesh filename="meshes/collision/finger.stl"/>
      </geometry>
    </collision>
  </link>
  <link name="panda_rightfinger">
    <inertial> <!-- these inertia are calculated based on the visual meshes using Meshlab, and using a density of 1kg/m^3 (http://gazebosim.org/tutorials?tut=inertia) -->
      <mass value="1"/> <!-- volume = 0.000011 -->
      <origin xyz="0.000002 0.014564 0.022794"/>
      <!--inertia ixx="0.00000000338" ixy="0.000000" ixz="0.000000" iyy="0.000000000332" iyz="0.00000000060" izz="0.00000000078"/-->
      <inertia ixx="0.00030727" ixy="0.000000" ixz="0.000000" iyy="0.00003018" iyz="0.00005455" izz="0.00007091"/> <!-- divided by the volume, just need to be multiplied by the mass -->
    </inertial>
    <visual>
      <origin rpy="0 0 3.14159265359" xyz="0 0 0"/>
      <geometry>
        <mesh filename="meshes/visual/finger.stl"/>
      </geometry>
    </visual>
    <collision>
      <origin rpy="0 0 3.14159265359" xyz="0 0 0"/>
      <geometry>
        <mesh filename="meshes/collision/finger.stl"/>
      </geometry>
    </collision>
  </link>
  <joint name="panda_finger_joint1" type="prismatic">
    <parent link="panda_hand"/>
    <child link="panda_leftfinger"/>
    <origin rpy="0 0 0" xyz="0 0 0.0584"/>
    <axis xyz="0 1 0"/>
    <limit effort="20" lower="0.0" upper="0.04" velocity="0.2"/>
  </joint>
  <joint name="panda_finger_joint2" type="prismatic">
    <parent link="panda_hand"/>
    <child link="panda_rightfinger"/>
    <origin rpy="0 0 0" xyz="0 0 0.0584"/>
    <axis xyz="0 -1 0"/>
    <limit effort="20" lower="0.0" upper="0.04" velocity="0.2"/>
    <mimic joint="panda_finger_joint1"/>
  </joint>
</robot>

