<?xml version="1.0" ?>
<!-- =================================================================================== -->
<!-- |    This document was autogenerated by xacro from manipulator2d.xacro            | -->
<!-- |    EDITING THIS FILE BY HAND IS NOT RECOMMENDED                                 | -->
<!-- =================================================================================== -->
<!-- Manipulator 2D robot (based on Revolute-Revolute Manipulator) -->
<robot name="manipulator2d" xmlns:xacro="http://www.ros.org/wiki/xacro">
  <!-- ros_control plugin -->
  <gazebo>
    <plugin filename="libgazebo_ros_control.so" name="gazebo_ros_control">
      <robotNamespace>/manipulator2d</robotNamespace>
      <robotSimType>gazebo_ros_control/DefaultRobotHWSim</robotSimType>
    </plugin>
  </gazebo>
  <!-- Links | Colors -->
  <gazebo reference="base_link">
    <!--<gravity>0</gravity>-->
    <material>Gazebo/Black</material>
  </gazebo>
  <gazebo reference="coupler0">
    <!--<gravity>0</gravity>-->
    <material>Gazebo/White</material>
  </gazebo>
  <gazebo reference="link1">
    <!--<gravity>0</gravity>-->
    <mu1>0.2</mu1>
    <mu2>0.2</mu2>
    <material>Gazebo/Blue</material>
  </gazebo>
  <gazebo reference="coupler1">
    <!--<gravity>0</gravity>-->
    <material>Gazebo/White</material>
  </gazebo>
  <gazebo reference="link2">
    <!--<gravity>0</gravity>-->
    <mu1>0.2</mu1>
    <mu2>0.2</mu2>
    <material>Gazebo/Blue</material>
  </gazebo>
  <gazebo reference="coupler2">
    <material>Gazebo/White</material>
  </gazebo>
  <gazebo reference="link3">
    <!--<gravity>0</gravity>-->
    <mu1>0.2</mu1>
    <mu2>0.2</mu2>
    <material>Gazebo/Blue</material>
  </gazebo>
  <gazebo reference="camera_link">
    <!--<gravity>0</gravity>-->
    <mu1>0.2</mu1>
    <mu1>0.2</mu1>
    <mu2>0.2</mu2>
    <material>Gazebo/Red</material>
  </gazebo>
  <!--&lt;!&ndash; hokuyo &ndash;&gt;-->
  <!--<gazebo reference="hokuyo_link">-->
  <!--<sensor type="gpu_ray" name="head_hokuyo_sensor">-->
  <!--<pose>0 0 0 0 0 0</pose>-->
  <!--<visualize>false</visualize>-->
  <!--<update_rate>40</update_rate>-->
  <!--<ray>-->
  <!--<scan>-->
  <!--<horizontal>-->
  <!--<samples>720</samples>-->
  <!--<resolution>1</resolution>-->
  <!--<min_angle>-1.570796</min_angle>-->
  <!--<max_angle>1.570796</max_angle>-->
  <!--</horizontal>-->
  <!--</scan>-->
  <!--<range>-->
  <!--<min>0.10</min>-->
  <!--<max>30.0</max>-->
  <!--<resolution>0.01</resolution>-->
  <!--</range>-->
  <!--<noise>-->
  <!--<type>gaussian</type>-->
  <!--&lt;!&ndash; Noise parameters based on published spec for Hokuyo laser-->
  <!--achieving "+-30mm" accuracy at range < 10m.  A mean of 0.0m and-->
  <!--stddev of 0.01m will put 99.7% of samples within 0.03m of the true-->
  <!--reading. &ndash;&gt;-->
  <!--<mean>0.0</mean>-->
  <!--<stddev>0.01</stddev>-->
  <!--</noise>-->
  <!--</ray>-->
  <!--<plugin name="gazebo_ros_head_hokuyo_controller" filename="libgazebo_ros_gpu_laser.so">-->
  <!--<topicName>/manipulator2d/laser/scan</topicName>-->
  <!--<frameName>hokuyo_link</frameName>-->
  <!--</plugin>-->
  <!--</sensor>-->
  <!--</gazebo>-->
  <!-- camera -->
  <gazebo reference="camera_link">
    <sensor name="camera1" type="camera">
      <update_rate>30.0</update_rate>
      <camera name="head">
        <horizontal_fov>1.3962634</horizontal_fov>
        <image>
          <width>800</width>
          <height>800</height>
          <format>R8G8B8</format>
        </image>
        <clip>
          <near>0.02</near>
          <far>300</far>
        </clip>
        <noise>
          <type>gaussian</type>
          <!-- Noise is sampled independently per pixel on each frame.
               That pixel's noise value is added to each of its color
               channels, which at that point lie in the range [0,1]. -->
          <mean>0.0</mean>
          <stddev>0.007</stddev>
        </noise>
      </camera>
      <plugin filename="libgazebo_ros_camera.so" name="camera_controller">
        <alwaysOn>true</alwaysOn>
        <updateRate>0.0</updateRate>
        <cameraName>manipulator2d/camera1</cameraName>
        <imageTopicName>image_raw</imageTopicName>
        <cameraInfoTopicName>camera_info</cameraInfoTopicName>
        <frameName>camera_link_optical</frameName>
        <!-- setting hackBaseline to anything but 0.0 will cause a misalignment
            between the gazebo sensor image and the frame it is supposed to
            be attached to -->
        <hackBaseline>0.0</hackBaseline>
        <distortionK1>0.0</distortionK1>
        <distortionK2>0.0</distortionK2>
        <distortionK3>0.0</distortionK3>
        <distortionT1>0.0</distortionT1>
        <distortionT2>0.0</distortionT2>
        <CxPrime>0</CxPrime>
        <Cx>0.0</Cx>
        <Cy>0.0</Cy>
        <focalLength>0.0</focalLength>
      </plugin>
    </sensor>
  </gazebo>
  <material name="black">
    <color rgba="0.0 0.0 0.0 1.0"/>
  </material>
  <material name="blue">
    <color rgba="0.0 0.0 0.8 1.0"/>
  </material>
  <material name="green">
    <color rgba="0.0 0.8 0.0 1.0"/>
  </material>
  <material name="grey">
    <color rgba="0.2 0.2 0.2 1.0"/>
  </material>
  <material name="orange">
    <color rgba="1.0 0.423529411765 0.0392156862745 1.0"/>
  </material>
  <material name="brown">
    <color rgba="0.870588235294 0.811764705882 0.764705882353 1.0"/>
  </material>
  <material name="red">
    <color rgba="0.8 0.0 0.0 1.0"/>
  </material>
  <material name="white">
    <color rgba="1.0 1.0 1.0 1.0"/>
  </material>
  <!-- Used for fixing robot to Gazebo 'base_link' -->
  <link name="world"/>
  <!--<joint name="fixed" type="fixed">-->
  <!--<parent link="world"/>-->
  <!--<child link="link1"/>-->
  <!--<origin xyz="0 0 ${base_z}" rpy="0 0 0"/>-->
  <!--</joint>-->
  <joint name="fixed" type="fixed">
    <parent link="world"/>
    <child link="base_link"/>
    <origin rpy="0 0 0" xyz="0 0 0.0"/>
  </joint>
  <link name="base_link">
    <collision>
      <origin rpy="0 0 0" xyz="0 0 0.05"/>
      <geometry>
        <cylinder length="0.1" radius="0.01"/>
      </geometry>
    </collision>
    <visual>
      <origin rpy="0 0 0" xyz="0 0 0.05"/>
      <geometry>
        <cylinder length="0.1" radius="0.01"/>
      </geometry>
      <material name="black"/>
    </visual>
    <inertial>
      <origin rpy="0 0 0" xyz="0 0 0.05"/>
      <mass value="4.93230046614"/>
      <inertia ixx="0.0042335579001" ixy="0.0" ixz="0.0" iyy="0.0042335579001" iyz="0.0" izz="0.000246615023307"/>
    </inertial>
  </link>
  <joint name="joint0" type="continuous">
    <parent link="base_link"/>
    <child link="coupler0"/>
    <origin rpy="0 0 0" xyz="0 0 0.075"/>
    <axis xyz="0 0 1"/>
    <dynamics damping="0.7"/>
  </joint>
  <link name="coupler0">
    <visual>
      <origin rpy="0 0 0" xyz="0 0 0"/>
      <geometry>
        <!--<sphere radius="${radius_axel}"/>-->
        <cylinder length="0.05" radius="0.045"/>
      </geometry>
      <material name="white"/>
    </visual>
  </link>
  <joint name="coupler_joint0" type="fixed">
    <parent link="coupler0"/>
    <child link="link1"/>
    <origin rpy="0 0 0" xyz="0 0 0"/>
  </joint>
  <!-- Base Link -->
  <link name="link1">
    <collision>
      <origin rpy="1.57079632679 0 1.57079632679" xyz="0.15 0 0"/>
      <geometry>
        <cylinder length="0.3" radius="0.025"/>
      </geometry>
    </collision>
    <visual>
      <origin rpy="1.57079632679 0 1.57079632679" xyz="0.15 0 0"/>
      <geometry>
        <cylinder length="0.3" radius="0.025"/>
      </geometry>
      <material name="blue"/>
    </visual>
    <inertial>
      <origin rpy="1.57079632679 0 1.57079632679" xyz="0.15 0 0"/>
      <mass value="1.2723450247"/>
      <inertia ixx="0.00974139159539" ixy="0.0" ixz="0.0" iyy="0.00974139159539" iyz="0.0" izz="0.00039760782022"/>
    </inertial>
  </link>
  <!--<joint name="joint1" type="continuous">-->
  <!--<parent link="link1"/>-->
  <!--<child link="link2"/>-->
  <!--<origin xyz="${height1 + axel_offset} 0 0" rpy="0 0 0"/>-->
  <!--<axis xyz="0 0 1"/>-->
  <!--<dynamics damping="0.7"/>-->
  <!--</joint>-->
  <joint name="joint1" type="continuous">
    <parent link="link1"/>
    <child link="coupler1"/>
    <origin rpy="0 0 0" xyz="0.335 0 0"/>
    <axis xyz="0 0 1"/>
    <dynamics damping="0.7"/>
  </joint>
  <link name="coupler1">
    <visual>
      <origin rpy="0 0 0" xyz="0 0 0"/>
      <geometry>
        <cylinder length="0.05" radius="0.045"/>
      </geometry>
      <material name="white"/>
    </visual>
  </link>
  <joint name="coupler_joint1" type="fixed">
    <parent link="coupler1"/>
    <child link="link2"/>
    <origin rpy="0 0 0" xyz="0.035 0 0"/>
  </joint>
  <!--Middle Link-->
  <link name="link2">
    <collision>
      <origin rpy="1.57079632679 0 1.57079632679" xyz="0.1 0 0"/>
      <geometry>
        <cylinder length="0.2" radius="0.025"/>
      </geometry>
    </collision>
    <visual>
      <origin rpy="1.57079632679 0 1.57079632679" xyz="0.1 0 0"/>
      <geometry>
        <cylinder length="0.2" radius="0.025"/>
      </geometry>
      <material name="blue"/>
    </visual>
    <inertial>
      <origin rpy="1.57079632679 0 1.57079632679" xyz="0.1 0 0"/>
      <mass value="0.848230016469"/>
      <inertia ixx="0.00437368602242" ixy="0.0" ixz="0.0" iyy="0.00437368602242" iyz="0.0" izz="0.000265071880147"/>
    </inertial>
  </link>
  <!--<joint name="joint2" type="continuous">-->
  <!--<parent link="link2"/>-->
  <!--<child link="link3"/>-->
  <!--<origin xyz="${height2 + axel_offset*2} 0.1 0.1" rpy="0 0 0"/>-->
  <!--<axis xyz="0 0 1"/>-->
  <!--<dynamics damping="0.7"/>-->
  <!--</joint>-->
  <joint name="joint2" type="continuous">
    <parent link="link2"/>
    <child link="coupler2"/>
    <origin rpy="0 0 0" xyz="0.235 0 0"/>
    <axis xyz="0 0 1"/>
    <dynamics damping="0.7"/>
  </joint>
  <link name="coupler2">
    <visual>
      <origin rpy="0 0 0" xyz="0 0 0"/>
      <geometry>
        <cylinder length="0.05" radius="0.045"/>
      </geometry>
      <material name="white"/>
    </visual>
  </link>
  <joint name="coupler_joint2" type="fixed">
    <parent link="coupler2"/>
    <child link="link3"/>
    <origin rpy="0 0 0" xyz="0.035 0 0"/>
  </joint>
  <!--Top Link-->
  <link name="link3">
    <collision>
      <origin rpy="1.57079632679 0 1.57079632679" xyz="0.05 0 0"/>
      <geometry>
        <cylinder length="0.1" radius="0.025"/>
      </geometry>
    </collision>
    <visual>
      <origin rpy="1.57079632679 0 1.57079632679" xyz="0.05 0 0"/>
      <geometry>
        <cylinder length="0.1" radius="0.025"/>
      </geometry>
      <material name="blue"/>
    </visual>
    <inertial>
      <origin rpy="1.57079632679 0 1.57079632679" xyz="0.05 0 0"/>
      <mass value="0.424115008235"/>
      <inertia ixx="0.00112655549062" ixy="0.0" ixz="0.0" iyy="0.00112655549062" iyz="0.0" izz="0.000132535940073"/>
    </inertial>
  </link>
  <joint name="gripper_joint" type="fixed">
    <parent link="link3"/>
    <child link="gripper"/>
    <origin rpy="0 0 0" xyz="0.1 0 0"/>
  </joint>
  <link name="gripper">
    <visual>
      <origin rpy="1.57079632679 0 1.57079632679" xyz="0.0075 0 0"/>
      <geometry>
        <box size="0.14 0.025 0.015"/>
      </geometry>
      <material name="white"/>
    </visual>
    <visual>
      <origin rpy="1.57079632679 0 1.57079632679" xyz="0.0575 0.06 0"/>
      <geometry>
        <box size="0.02 0.025 0.085"/>
      </geometry>
      <material name="white"/>
    </visual>
    <visual>
      <origin rpy="1.57079632679 0 1.57079632679" xyz="0.0575 -0.06 0"/>
      <geometry>
        <box size="0.02 0.025 0.085"/>
      </geometry>
      <material name="white"/>
    </visual>
    <collision>
      <origin rpy="1.57079632679 0 1.57079632679" xyz="0.0075 0 0"/>
      <geometry>
        <box size="0.14 0.025 0.015"/>
      </geometry>
      <material name="white"/>
    </collision>
    <collision>
      <origin rpy="1.57079632679 0 1.57079632679" xyz="0.0575 0.06 0"/>
      <geometry>
        <box size="0.02 0.025 0.085"/>
      </geometry>
      <material name="white"/>
    </collision>
    <collision>
      <origin rpy="1.57079632679 0 1.57079632679" xyz="0.0575 -0.06 0"/>
      <geometry>
        <box size="0.02 0.025 0.085"/>
      </geometry>
      <material name="white"/>
    </collision>
  </link>
  <!--<joint name="hokuyo_joint" type="fixed">-->
  <!--<axis xyz="0 1 0" />-->
  <!--<origin xyz="0 0 ${height3 - axel_offset/2}" rpy="0 0 0"/>-->
  <!--<parent link="link3"/>-->
  <!--<child link="hokuyo_link"/>-->
  <!--</joint>-->
  <!--&lt;!&ndash; Hokuyo Laser &ndash;&gt;-->
  <!--<link name="hokuyo_link">-->
  <!--<collision>-->
  <!--<origin xyz="0 0 0" rpy="0 0 0"/>-->
  <!--<geometry>-->
  <!--<box size="0.1 0.1 0.1"/>-->
  <!--</geometry>-->
  <!--</collision>-->
  <!--<visual>-->
  <!--<origin xyz="0 0 0" rpy="0 0 0"/>-->
  <!--<geometry>-->
  <!--<mesh filename="package://manipulator2d_description/meshes/hokuyo.dae"/>-->
  <!--</geometry>-->
  <!--</visual>-->
  <!--<inertial>-->
  <!--<mass value="1e-5" />-->
  <!--<origin xyz="0 0 0" rpy="0 0 0"/>-->
  <!--<inertia ixx="1e-6" ixy="0" ixz="0" iyy="1e-6" iyz="0" izz="1e-6" />-->
  <!--</inertial>-->
  <!--</link>-->
  <joint name="camera_joint" type="fixed">
    <axis xyz="0 1 0"/>
    <origin rpy="0 1.57079632679 1.57079632679" xyz="0.0 0.0 1.5"/>
    <parent link="base_link"/>
    <child link="camera_link"/>
  </joint>
  <!-- Camera -->
  <link name="camera_link">
    <!--<collision>-->
    <!--<origin xyz="0 0 0" rpy="0 0 0"/>-->
    <!--<geometry>-->
    <!--<box size="${camera_link} ${camera_link} ${camera_link}"/>-->
    <!--</geometry>-->
    <!--</collision>-->
    <!--<visual>-->
    <!--<origin xyz="0 0 0" rpy="0 0 0"/>-->
    <!--<geometry>-->
    <!--<box size="${camera_link} ${camera_link} ${camera_link}"/>-->
    <!--</geometry>-->
    <!--<material name="red"/>-->
    <!--</visual>-->
    <!--<inertial>-->
    <!--<mass value="1e-5" />-->
    <!--<origin xyz="0 0 0" rpy="0 0 0"/>-->
    <!--<inertia ixx="1e-6" ixy="0" ixz="0" iyy="1e-6" iyz="0" izz="1e-6" />-->
    <!--</inertial>-->
  </link>
  <!-- generate an optical frame http://www.ros.org/reps/rep-0103.html#suffix-frames
      so that ros and opencv can operate on the camera frame correctly -->
  <joint name="camera_optical_joint" type="fixed">
    <!-- these values have to be these values otherwise the gazebo camera image
        won't be aligned properly with the frame it is supposedly originating from -->
    <origin rpy="-1.57079632679 0 -1.57079632679" xyz="0 0 0"/>
    <parent link="camera_link"/>
    <child link="camera_link_optical"/>
  </joint>
  <link name="camera_link_optical">
  </link>
  <transmission name="tran0">
    <type>transmission_interface/SimpleTransmission</type>
    <joint name="joint0">
      <hardwareInterface>hardware_interface/EffortJointInterface</hardwareInterface>
    </joint>
    <actuator name="motor0">
      <hardwareInterface>hardware_interface/EffortJointInterface</hardwareInterface>
      <mechanicalReduction>1</mechanicalReduction>
    </actuator>
  </transmission>
  <transmission name="tran1">
    <type>transmission_interface/SimpleTransmission</type>
    <joint name="joint1">
      <hardwareInterface>hardware_interface/EffortJointInterface</hardwareInterface>
    </joint>
    <actuator name="motor1">
      <hardwareInterface>hardware_interface/EffortJointInterface</hardwareInterface>
      <mechanicalReduction>1</mechanicalReduction>
    </actuator>
  </transmission>
  <transmission name="tran2">
    <type>transmission_interface/SimpleTransmission</type>
    <joint name="joint2">
      <hardwareInterface>hardware_interface/EffortJointInterface</hardwareInterface>
    </joint>
    <actuator name="motor2">
      <hardwareInterface>hardware_interface/EffortJointInterface</hardwareInterface>
      <mechanicalReduction>1</mechanicalReduction>
    </actuator>
  </transmission>
</robot>

