<?xml version="1.0" ?>
<!-- =================================================================================== -->
<!-- |    This document was autogenerated by xacro from centauro.urdf.xacro            | -->
<!-- |    EDITING THIS FILE BY HAND IS NOT RECOMMENDED                                 | -->
<!-- =================================================================================== -->
<robot name="centauro" xmlns:xacro="http://www.ros.org/wiki/xacro">
  <!-- /constants -->
  <!-- Here all arguments from launch file are evaluated to the final xacro poropeties.
     Also all the parameter dependencies are resolved-->
  <!-- Here all arguments from launch file are evaluated to the final xacro poropeties.
     Also all the parameter dependencies are resolved-->
  <!-- Here all arguments from launch file are evaluated to the final xacro poropeties.
     Also all the parameter dependencies are resolved-->
  <!-- Here all arguments from launch file are evaluated to the final xacro poropeties.
     Also all the parameter dependencies are resolved-->
  <gazebo reference="j_ft_1">
    <sensor name="left_arm_ft" type="force_torque">
      <force_torque>
        <frame>parent</frame>
        <measure_direction>child_to_parent</measure_direction>
      </force_torque>
      <always_on>true</always_on>
      <visualize>true</visualize>
      <update_rate>1000</update_rate>
      <pose>0 0 0 0 0 0</pose>
    </sensor>
  </gazebo>
  <gazebo reference="j_ft_2">
    <sensor name="right_arm_ft" type="force_torque">
      <force_torque>
        <frame>parent</frame>
        <measure_direction>child_to_parent</measure_direction>
      </force_torque>
      <always_on>true</always_on>
      <visualize>true</visualize>
      <update_rate>1000</update_rate>
      <pose>0 0 0 0 0 0</pose>
    </sensor>
  </gazebo>
  <gazebo reference="j_wheel_1">
    <sensor name="fl_foot_ft" type="force_torque">
      <force_torque>
        <frame>parent</frame>
        <measure_direction>child_to_parent</measure_direction>
      </force_torque>
      <always_on>true</always_on>
      <visualize>true</visualize>
      <update_rate>1000</update_rate>
      <pose>0 0 0 0 0 0</pose>
    </sensor>
  </gazebo>
  <gazebo reference="j_wheel_2">
    <sensor name="fr_foot_ft" type="force_torque">
      <force_torque>
        <frame>parent</frame>
        <measure_direction>child_to_parent</measure_direction>
      </force_torque>
      <always_on>true</always_on>
      <visualize>true</visualize>
      <update_rate>1000</update_rate>
      <pose>0 0 0 0 0 0</pose>
    </sensor>
  </gazebo>
  <gazebo reference="j_wheel_4">
    <sensor name="hr_foot_ft" type="force_torque">
      <force_torque>
        <frame>parent</frame>
        <measure_direction>child_to_parent</measure_direction>
      </force_torque>
      <always_on>true</always_on>
      <visualize>true</visualize>
      <update_rate>1000</update_rate>
      <pose>0 0 0 0 0 0</pose>
    </sensor>
  </gazebo>
  <gazebo reference="j_wheel_3">
    <sensor name="hl_foot_ft" type="force_torque">
      <force_torque>
        <frame>parent</frame>
        <measure_direction>child_to_parent</measure_direction>
      </force_torque>
      <always_on>true</always_on>
      <visualize>true</visualize>
      <update_rate>1000</update_rate>
      <pose>0 0 0 0 0 0</pose>
    </sensor>
  </gazebo>
  <gazebo reference="wheel_1">
    <sensor name="wheel_1_contact_sensor_1" type="contact">
      <always_on>true</always_on>
      <update_rate>1000.0</update_rate>
      <contact>
        <collision>wheel_1_collision_1</collision>
      </contact>
      <plugin filename="libgazebo_ros_bumper.so" name="wheel_1_bumper">
        <bumperTopicName>centauro/contacts_wheel_1</bumperTopicName>
        <frameName>wheel_1</frameName>
      </plugin>
    </sensor>
  </gazebo>
  <gazebo reference="wheel_2">
    <sensor name="wheel_2_contact_sensor_1" type="contact">
      <always_on>true</always_on>
      <update_rate>1000.0</update_rate>
      <contact>
        <collision>wheel_2_collision_1</collision>
      </contact>
      <plugin filename="libgazebo_ros_bumper.so" name="wheel_2_bumper">
        <bumperTopicName>centauro/contacts_wheel_2</bumperTopicName>
        <frameName>wheel_2</frameName>
      </plugin>
    </sensor>
  </gazebo>
  <gazebo reference="wheel_3">
    <sensor name="wheel_3_contact_sensor_1" type="contact">
      <always_on>true</always_on>
      <update_rate>1000.0</update_rate>
      <contact>
        <collision>wheel_3_collision_1</collision>
      </contact>
      <plugin filename="libgazebo_ros_bumper.so" name="wheel_3_bumper">
        <bumperTopicName>centauro/contacts_wheel_3</bumperTopicName>
        <frameName>wheel_3</frameName>
      </plugin>
    </sensor>
  </gazebo>
  <gazebo reference="wheel_4">
    <sensor name="wheel_4_contact_sensor_1" type="contact">
      <always_on>true</always_on>
      <update_rate>1000.0</update_rate>
      <contact>
        <collision>wheel_4_collision_1</collision>
      </contact>
      <plugin filename="libgazebo_ros_bumper.so" name="wheel_4_bumper">
        <bumperTopicName>centauro/contacts_wheel_4</bumperTopicName>
        <frameName>wheel_4</frameName>
      </plugin>
    </sensor>
  </gazebo>
  <!-- Here all arguments from launch file are evaluated to the final xacro poropeties.
     Also all the parameter dependencies are resolved-->
  <gazebo reference="imu_link">
    <sensor name="imu_link" type="imu">
      <always_on>1</always_on>
      <update_rate>500</update_rate>
      <visualize>true</visualize>
      <topic>__default_topic__</topic>
      <imu>
        <!--
                <noise>
                <type>gaussian</type>
                <rate>
                    <mean>0.0</mean>
                    <stddev>2e-4</stddev>
                    <bias_mean>0.0000075</bias_mean>
                    <bias_stddev>0.0000008</bias_stddev>
                </rate>
                <accel>
                    <mean>0.0</mean>
                    <stddev>1.7e-2</stddev>
                    <bias_mean>0.1</bias_mean>
                    <bias_stddev>0.001</bias_stddev>
                </accel>
                </noise>
                -->
      </imu>
    </sensor>
  </gazebo>
  <gazebo>
    <plugin filename="libGazeboXBotPlugin.so" name="gazebo_xbot_plugin">
      <path_to_config_file>configs/ADVR_shared/centauro/configs/config_centauro.yaml</path_to_config_file>
      <!--                <path_to_config_file>configs/ADVR_shared/centauro/configs/config_centauro.yaml</path_to_config_file> -->
    </plugin>
  </gazebo>
  <!-- /CONTROLLER -->
  <!-- VISUALiZATION AND FRICTION -->
  <gazebo reference="base_link">
    <material>Gazebo/Red</material>
  </gazebo>
  <gazebo reference="pelvis">
    <material>Gazebo/OrangeTransparent</material>
    <mu1>0</mu1>
    <mu2>0</mu2>
  </gazebo>
  <gazebo reference="torso_2">
    <material>Gazebo/OrangeTransparent</material>
    <mu1>0</mu1>
    <mu2>0</mu2>
  </gazebo>
  <gazebo reference="hip1_1">
    <material>Gazebo/Lane_1</material>
    <mu1>0</mu1>
    <mu2>0</mu2>
  </gazebo>
  <gazebo reference="hip1_2">
    <material>Gazebo/Lane_1 </material>
    <mu1>0</mu1>
    <mu2>0</mu2>
  </gazebo>
  <gazebo reference="hip1_3">
    <material>Gazebo/Lane_1</material>
    <mu1>0</mu1>
    <mu2>0</mu2>
  </gazebo>
  <gazebo reference="hip1_4">
    <material>Gazebo/Lane_1</material>
    <mu1>0</mu1>
    <mu2>0</mu2>
  </gazebo>
  <gazebo reference="hip2_1">
    <material>Gazebo/OrangeTransparent </material>
    <mu1>0</mu1>
    <mu2>0</mu2>
  </gazebo>
  <gazebo reference="hip2_2">
    <material>Gazebo/OrangeTransparent</material>
    <mu1>0</mu1>
    <mu2>0</mu2>
  </gazebo>
  <gazebo reference="hip2_3">
    <material>Gazebo/OrangeTransparent </material>
    <mu1>0</mu1>
    <mu2>0</mu2>
  </gazebo>
  <gazebo reference="hip2_4">
    <material>Gazebo/OrangeTransparent </material>
    <mu1>0</mu1>
    <mu2>0</mu2>
  </gazebo>
  <gazebo reference="knee_1">
    <material>Gazebo/Lane_1 </material>
    <mu1>0</mu1>
    <mu2>0</mu2>
  </gazebo>
  <gazebo reference="knee_2">
    <material>Gazebo/Lane_1 </material>
    <mu1>0</mu1>
    <mu2>0</mu2>
  </gazebo>
  <gazebo reference="knee_3">
    <material>Gazebo/Lane_1 </material>
    <mu1>0</mu1>
    <mu2>0</mu2>
  </gazebo>
  <gazebo reference="knee_4">
    <material>Gazebo/Lane_1 </material>
    <mu1>0</mu1>
    <mu2>0</mu2>
  </gazebo>
  <gazebo reference="ankle1_1">
    <material>Gazebo/OrangeTransparent</material>
    <mu1>0</mu1>
    <mu2>0</mu2>
  </gazebo>
  <gazebo reference="ankle1_2">
    <material>Gazebo/OrangeTransparent  </material>
    <mu1>0</mu1>
    <mu2>0</mu2>
  </gazebo>
  <gazebo reference="ankle1_3">
    <material>Gazebo/OrangeTransparent </material>
    <mu1>0</mu1>
    <mu2>0</mu2>
  </gazebo>
  <gazebo reference="ankle1_4">
    <material>Gazebo/OrangeTransparent  </material>
    <mu1>0</mu1>
    <mu2>0</mu2>
  </gazebo>
  <gazebo reference="ankle2_1">
    <material> Gazebo/Lane_1 </material>
    <mu1>0</mu1>
    <mu2>0</mu2>
  </gazebo>
  <gazebo reference="ankle2_2">
    <material>Gazebo/Lane_1 </material>
    <mu1>0</mu1>
    <mu2>0</mu2>
  </gazebo>
  <gazebo reference="ankle2_3">
    <material>Gazebo/Lane_1</material>
    <mu1>0</mu1>
    <mu2>0</mu2>
  </gazebo>
  <gazebo reference="ankle2_4">
    <material>Gazebo/Lane_1</material>
    <mu1>0</mu1>
    <mu2>0</mu2>
  </gazebo>
  <gazebo reference="wheel_1">
    <material>Gazebo/Residential </material>
    <collision>
      <surface>
        <friction>
          <!--                                        <torsional>
                                                <coefficient> 0.5 </coefficient>
                                                <use_patch_radius>true</use_patch_radius>
                                                <patch_radius>0.2</patch_radius>
                                        </torsional>-->
          <ode>
            <mu>0.5</mu>
            <mu2>0.5</mu2>
          </ode>
          <bullet>
            <friction>0.5</friction>
            <friction2>0.5</friction2>
          </bullet>
        </friction>
        <contact>
          <ode>
            <!--<soft_cfm>0.0001</soft_cfm>
                                        <soft_erp>0.25</soft_erp> -->
            <kp>2100000</kp>
            <kd>1</kd>
            <max_vel>100</max_vel>
          </ode>
          <bullet>
            <soft_cfm>0.007</soft_cfm>
            <soft_erp>0.25</soft_erp>
            <kp>1000000</kp>
            <kd>5</kd>
            <split_impulse>0.01</split_impulse>
          </bullet>
        </contact>
      </surface>
    </collision>
  </gazebo>
  <gazebo reference="wheel_2">
    <material>Gazebo/Residential</material>
    <collision>
      <surface>
        <friction>
          <!--                                        <torsional>
                                                <coefficient> 0.5 </coefficient>
                                                <use_patch_radius>true</use_patch_radius>
                                                <patch_radius>0.2</patch_radius>
                                        </torsional>-->
          <ode>
            <mu>0.5</mu>
            <mu2>0.5</mu2>
          </ode>
          <bullet>
            <friction>0.5</friction>
            <friction2>0.5</friction2>
          </bullet>
        </friction>
        <contact>
          <ode>
            <!--<soft_cfm>0.0001</soft_cfm>
                                        <soft_erp>0.25</soft_erp> -->
            <kp>2100000</kp>
            <kd>1</kd>
            <max_vel>100</max_vel>
          </ode>
          <bullet>
            <soft_cfm>0.007</soft_cfm>
            <soft_erp>0.25</soft_erp>
            <kp>1000000</kp>
            <kd>5</kd>
            <split_impulse>0.01</split_impulse>
          </bullet>
        </contact>
      </surface>
    </collision>
  </gazebo>
  <gazebo reference="wheel_3">
    <material>Gazebo/Residential </material>
    <collision>
      <surface>
        <friction>
          <!--                                        <torsional>
                                                <coefficient> 0.5 </coefficient>
                                                <use_patch_radius>true</use_patch_radius>
                                                <patch_radius>0.2</patch_radius>
                                        </torsional>-->
          <ode>
            <mu>0.5</mu>
            <mu2>0.5</mu2>
          </ode>
          <bullet>
            <friction>0.5</friction>
            <friction2>0.5</friction2>
          </bullet>
        </friction>
        <contact>
          <ode>
            <!--<soft_cfm>0.0001</soft_cfm>
                                        <soft_erp>0.25</soft_erp> -->
            <kp>2100000</kp>
            <kd>1</kd>
            <max_vel>100</max_vel>
          </ode>
          <bullet>
            <soft_cfm>0.007</soft_cfm>
            <soft_erp>0.25</soft_erp>
            <kp>1000000</kp>
            <kd>5</kd>
            <split_impulse>0.01</split_impulse>
          </bullet>
        </contact>
      </surface>
    </collision>
  </gazebo>
  <gazebo reference="wheel_4">
    <material>Gazebo/Residential</material>
    <collision>
      <surface>
        <friction>
          <!--                                        <torsional>
                                                <coefficient> 0.5 </coefficient>
                                                <use_patch_radius>true</use_patch_radius>
                                                <patch_radius>0.2</patch_radius>
                                        </torsional>-->
          <ode>
            <mu>0.5</mu>
            <mu2>0.5</mu2>
          </ode>
          <bullet>
            <friction>0.5</friction>
            <friction2>0.5</friction2>
          </bullet>
        </friction>
        <contact>
          <ode>
            <!--<soft_cfm>0.0001</soft_cfm>
                                        <soft_erp>0.25</soft_erp> -->
            <kp>2100000</kp>
            <kd>1</kd>
            <max_vel>100</max_vel>
          </ode>
          <bullet>
            <soft_cfm>0.007</soft_cfm>
            <soft_erp>0.25</soft_erp>
            <kp>1000000</kp>
            <kd>5</kd>
            <split_impulse>0.01</split_impulse>
          </bullet>
        </contact>
      </surface>
    </collision>
  </gazebo>
  <gazebo reference="arm1_1">
    <material>Gazebo/Lane_1 </material>
    <mu1>0</mu1>
    <mu2>0</mu2>
  </gazebo>
  <gazebo reference="arm2_1">
    <material>Gazebo/Lane_1 </material>
    <mu1>0</mu1>
    <mu2>0</mu2>
  </gazebo>
  <gazebo reference="arm1_2">
    <material>Gazebo/OrangeTransparent </material>
    <mu1>0</mu1>
    <mu2>0</mu2>
  </gazebo>
  <gazebo reference="arm2_2">
    <material>Gazebo/OrangeTransparent</material>
    <mu1>0</mu1>
    <mu2>0</mu2>
  </gazebo>
  <gazebo reference="arm1_3">
    <material>Gazebo/Lane_1 </material>
    <mu1>0</mu1>
    <mu2>0</mu2>
  </gazebo>
  <gazebo reference="arm2_3">
    <material>Gazebo/Lane_1 </material>
    <mu1>0</mu1>
    <mu2>0</mu2>
  </gazebo>
  <gazebo reference="arm1_4">
    <material>Gazebo/OrangeTransparent </material>
    <mu1>0</mu1>
    <mu2>0</mu2>
  </gazebo>
  <gazebo reference="arm2_4">
    <material>Gazebo/OrangeTransparent </material>
    <mu1>0</mu1>
    <mu2>0</mu2>
  </gazebo>
  <gazebo reference="arm1_5">
    <material>Gazebo/Lane_1 </material>
    <mu1>0</mu1>
    <mu2>0</mu2>
  </gazebo>
  <gazebo reference="arm2_5">
    <material>Gazebo/Lane_1 </material>
    <mu1>0</mu1>
    <mu2>0</mu2>
  </gazebo>
  <gazebo reference="arm1_6">
    <material>Gazebo/OrangeTransparent </material>
    <mu1>0</mu1>
    <mu2>0</mu2>
  </gazebo>
  <gazebo reference="arm2_6">
    <material>Gazebo/OrangeTransparent </material>
    <mu1>0</mu1>
    <mu2>0</mu2>
  </gazebo>
  <gazebo reference="arm1_7">
    <material>Gazebo/Lane_1 </material>
    <mu1>0</mu1>
    <mu2>0</mu2>
  </gazebo>
  <gazebo reference="arm2_7">
    <material>Gazebo/Lane_1 </material>
    <mu1>0</mu1>
    <mu2>0</mu2>
  </gazebo>
  <gazebo reference="arm1_8">
    <material>Gazebo/OrangeTransparent </material>
    <mu1>0</mu1>
    <mu2>0</mu2>
  </gazebo>
  <gazebo reference="arm2_8">
    <material>Gazebo/OrangeTransparent </material>
    <mu1>0</mu1>
    <mu2>0</mu2>
  </gazebo>
  <material name="grey">
    <color rgba="0.5 0.5 0.5 1"/>
  </material>
  <material name="dark_grey">
    <color rgba="0.3 0.3 0.3 1"/>
  </material>
  <material name="blue">
    <color rgba="0.0 0.2 0.3 1"/>
  </material>
  <material name="red">
    <color rgba="0.5 0.1 0.2 1"/>
  </material>
  <material name="black">
    <color rgba="0.0 0.0 0.0 1"/>
  </material>
  <!-- Here all arguments from launch file are evaluated to the final xacro poropeties.
     Also all the parameter dependencies are resolved-->
  <!-- load proper collision model -->
  <!-- load proper collision model -->
  <!-- load proper collision model -->
  <!-- load proper collision model -->
  <!-- Here all arguments from launch file are evaluated to the final xacro poropeties.
     Also all the parameter dependencies are resolved-->
  <!-- load proper collision model -->
  <!-- load proper collision model -->
  <!-- load proper collision model -->
  <!-- load proper collision model -->
  <!-- /macro legs -->
  <!-- /macro arms -->
  <!-- /other files -->
  <!-- reference -->
  <!-- <link name="base_link"/>

<joint name="base_joint" type="fixed">
   <origin xyz="0 0 0"/>
   <parent link="base_link"/>
   <child link="world"/>
</joint>
-->
  <!--link name="world"/-->
  <link name="pelvis">
    <inertial>
      <origin xyz="-0.013541342 -0.0029098264 0.01400721"/>
      <mass value="24.190945"/>
      <inertia ixx="0.20021119" ixy="-0.0038421093" ixz="-0.033298849" iyy="0.51136214" iyz="0.004469847" izz="0.54401411"/>
    </inertial>
    <visual>
      <origin rpy="0.0 0.0 0.0" xyz="0.0 0 0.0"/>
      <geometry>
        <mesh filename="meshes/simplified/pelvis.stl" scale="0.001 0.001 0.001"/>
      </geometry>
    </visual>
    <collision>
      <origin rpy="0.0 0.0 0.0" xyz="0.0 0 0.0"/>
      <geometry>
        <mesh filename="meshes/convex_hull/pelvis.stl" scale="0.001 0.001 0.001"/>
      </geometry>
    </collision>
  </link>
  <link name="imu_link">
    <inertial>
      <mass value="0.0"/>
      <inertia ixx="0.0" ixy="0.0" ixz="0.0" iyy="0.0" iyz="0.0" izz="0.0"/>
    </inertial>
  </link>
  <joint name="imu_joint" type="fixed">
    <parent link="pelvis"/>
    <origin rpy="0.0 0.0 0.0" xyz="0.0 0.0 0.0"/>
    <child link="imu_link"/>
  </joint>
  <!--joint name="reference" type="floating">
    <origin xyz="0.0 0.0 0.93445"/>
    <parent link="world"/>
    <child link="pelvis"/>
  </joint-->
  <!-- /reference  -->
  <!-- torso links -->
  <link name="torso_2">
    <inertial>
      <origin xyz="0.0064454169 0.0021390093 0.14302095"/>
      <mass value="6.1886404"/>
      <inertia ixx="0.063643392" ixy="8.939e-05" ixz="-0.00086873" iyy="0.02680235" iyz="-4.657e-05" izz="0.04743015"/>
    </inertial>
    <visual>
      <origin rpy="0.0 0.0 0.0" xyz="0.0 0 0.0"/>
      <geometry>
        <mesh filename="meshes/simplified/link1.stl" scale="0.001 0.001 0.001"/>
      </geometry>
    </visual>
    <collision>
      <origin rpy="0.0 0.0 0.0" xyz="0.0 0 0.0"/>
      <geometry>
        <mesh filename="meshes/convex_hull/link1.stl" scale="0.001 0.001 0.001"/>
      </geometry>
    </collision>
  </link>
  <!-- /torso links -->
  <!-- torso joints -->
  <joint name="torso_yaw" type="revolute">
    <parent link="pelvis"/>
    <origin xyz="0.2 0.0 0.256"/>
    <child link="torso_2"/>
    <axis xyz="0 0 1"/>
    <limit effort="147" lower="-2.618" upper="2.618" velocity="5.7"/>
    <!-- TODO -->
  </joint>
  <!-- /torso joints -->
  <transmission name="t_torso_yaw">
    <type> transmission_interface/SimpleTransmission</type>
    <joint name="torso_yaw">
      <hardwareInterface>hardware_interface/EffortJointInterface</hardwareInterface>
    </joint>
    <actuator name="motor_torso_yaw">
      <hardwareInterface>hardware_interface/EffortJointInterface</hardwareInterface>
      <machanicalReduction>1</machanicalReduction>
    </actuator>
    <robotNamespace>/centauro</robotNamespace>
  </transmission>
  <!-- /torso actuators -->
  <!-- head links -->
  <link name="neck_1">
    <inertial>
      <origin xyz="0.040479674 0.021377573 -0.014595112"/>
      <mass value="0.33878686"/>
      <inertia ixx="0.0003718568" ixy="-9.42983e-05" ixz="-2.80644e-05" iyy="0.0001886879" iyz="-1.54534e-05" izz="0.0005023443"/>
    </inertial>
    <visual>
      <origin rpy="0.0 0.0 0.0" xyz="0.0 0 0.0"/>
      <geometry>
        <mesh filename="meshes/simplified/neck_yaw.stl" scale="0.001 0.001 0.001"/>
      </geometry>
    </visual>
    <collision>
      <origin rpy="0.0 0.0 0.0" xyz="0.0 0 0.0"/>
      <geometry>
        <mesh filename="meshes/convex_hull/neck_yaw.stl" scale="0.001 0.001 0.001"/>
      </geometry>
    </collision>
  </link>
  <link name="neck_2">
    <inertial>
      <origin xyz="0.048466918 -0.059852318 -0.0085314894"/>
      <mass value="0.78526942"/>
      <inertia ixx="0.0004682345" ixy="-1.05438e-05" ixz="7.24398e-05" iyy="0.0002635246" iyz="1.6904e-06" izz="0.0003763351"/>
    </inertial>
    <visual>
      <origin rpy="0.0 0.0 0.0" xyz="0.0 0 0.0"/>
      <geometry>
        <mesh filename="meshes/simplified/neck_pitch.stl" scale="0.001 0.001 0.001"/>
      </geometry>
    </visual>
    <collision>
      <origin rpy="0.0 0.0 0.0" xyz="0.0 0 0.0"/>
      <geometry>
        <mesh filename="meshes/convex_hull/neck_pitch.stl" scale="0.001 0.001 0.001"/>
      </geometry>
    </collision>
  </link>
  <link name="neck_3">
    <inertial>
      <origin xyz="0.048466918 -0.059852318 -0.0085314894"/>
      <mass value="0.78526942"/>
      <inertia ixx="0.0004682345" ixy="-1.05438e-05" ixz="7.24398e-05" iyy="0.0002635246" iyz="1.6904e-06" izz="0.0003763351"/>
    </inertial>
    <visual>
      <origin rpy="0.0 0.0 0.0" xyz="0.0 0 0.0"/>
      <geometry>
        <mesh filename="meshes/simplified/velodyne.stl" scale="0.001 0.001 0.001"/>
      </geometry>
    </visual>
    <collision>
      <origin rpy="0.0 0.0 0.0" xyz="0.0 0 0.0"/>
      <geometry>
        <mesh filename="meshes/convex_hull/velodyne.stl" scale="0.001 0.001 0.001"/>
      </geometry>
    </collision>
  </link>
  <!-- /head links -->
  <!-- sensors links -->
  <link name="camera_central">
    <inertial>
      <origin xyz="0.0 0.0 0.0"/>
      <mass value="0.1"/>
      <inertia ixx="1e-06" ixy="0.0" ixz="0.0" iyy="1e-06" iyz="0.0" izz="1e-06"/>
    </inertial>
  </link>
  <link name="camera_left">
    <inertial>
      <origin xyz="0.0 0.0 0.0"/>
      <mass value="0.1"/>
      <inertia ixx="1e-06" ixy="0.0" ixz="0.0" iyy="1e-06" iyz="0.0" izz="1e-06"/>
    </inertial>
  </link>
  <link name="camera_right">
    <inertial>
      <origin xyz="0.0 0.0 0.0"/>
      <mass value="0.1"/>
      <inertia ixx="1e-06" ixy="0.0" ixz="0.0" iyy="1e-06" iyz="0.0" izz="1e-06"/>
    </inertial>
  </link>
  <link name="kinect">
    <inertial>
      <origin xyz="0.0 0.0 0.0"/>
      <mass value="0.1"/>
      <inertia ixx="1e-06" ixy="0.0" ixz="0.0" iyy="1e-06" iyz="0.0" izz="1e-06"/>
    </inertial>
  </link>
  <link name="kinect2_rgb_optical_frame">
    <inertial>
      <origin rpy="0 0 0" xyz="0 0 0"/>
      <mass value="0"/>
      <inertia ixx="0.0" ixy="0.0" ixz="0.0" iyy="0.0" iyz="0.0" izz="0.0"/>
    </inertial>
  </link> <!-- in pybullet, the inertia need to be specified even for dummy links, otherwise it will put an identity inertia and a mass of 1 by default -->
  <link name="velodyne_mount">
    <inertial>
      <origin xyz="0.0 0.0 0.0"/>
      <mass value="0.1"/>
      <inertia ixx="1e-06" ixy="0.0" ixz="0.0" iyy="1e-06" iyz="0.0" izz="1e-06"/>
    </inertial>
  </link>
  <!-- /sensors links -->
  <!-- head joints -->
  <joint name="neck_yaw" type="revolute">
    <parent link="torso_2"/>
    <origin xyz="0.0 0.0 0.2795"/>
    <child link="neck_1"/>
    <axis xyz="0 0 1"/>
    <limit effort="35" lower="-0.78539816" upper="0.78539816" velocity="5.7"/>
    <!-- TODO -->
  </joint>
  <joint name="neck_pitch" type="revolute">
    <parent link="neck_1"/>
    <origin xyz="0.054 0.0596 -0.0124975"/>
    <child link="neck_2"/>
    <axis xyz="0 1 0"/>
    <limit effort="35" lower="-0.34906585" upper="0.78539816" velocity="5.7"/>
    <!-- TODO -->
  </joint>
  <joint name="neck_velodyne" type="continuous">
    <parent link="torso_2"/>
    <origin xyz="0.055 0.0 0.473262"/>
    <child link="neck_3"/>
    <axis xyz="0 0 1"/>
    <limit effort="35" velocity="5.7"/>
    <!-- TODO -->
  </joint>
  <!-- /head joints -->
  <!-- sensors transformations  -->
  <joint name="j_camera_central" type="fixed">
    <parent link="torso_2"/>
    <origin rpy="0.0 0.349065586018 0.0" xyz="0.0559593 5e-12 0.390626"/>
    <child link="camera_central"/>
  </joint>
  <joint name="j_camera_left" type="fixed">
    <parent link="torso_2"/>
    <origin rpy="0.0 0.349065586018 1.2217302006" xyz="0.0191392 0.0525845 0.390626"/>
    <child link="camera_left"/>
  </joint>
  <joint name="j_camera_right" type="fixed">
    <parent link="torso_2"/>
    <origin rpy="0.0 0.349065586018 -1.2217302006" xyz="0.0191392 -0.0525845 0.390626"/>
    <child link="camera_right"/>
  </joint>
  <joint name="j_kinect" type="fixed">
    <parent link="neck_2"/>
    <origin rpy="0.0 0.0 0.0" xyz="0.03 -0.0596 0.045855"/>
    <child link="kinect"/>
  </joint>
  <joint name="j_kinect_optical_frame" type="fixed">
    <parent link="kinect"/>
    <child link="kinect2_rgb_optical_frame"/>
    <origin rpy=" -1.5707963268 0 -1.5707963268" xyz="0.050 -0.110 -0.035"/>
  </joint>
  <joint name="j_velodyne" type="fixed">
    <parent link="neck_3"/>
    <origin rpy="0.0 0.0 -3.14159265359" xyz="-0.138 0.0 -0.033"/>
    <child link="velodyne_mount"/>
  </joint>
  <!-- /sensors transformations -->
  <transmission name="t_neck_yaw">
    <type> transmission_interface/SimpleTransmission</type>
    <joint name="neck_yaw">
      <hardwareInterface>hardware_interface/EffortJointInterface</hardwareInterface>
    </joint>
    <actuator name="motor_neck_yaw">
      <hardwareInterface>hardware_interface/EffortJointInterface</hardwareInterface>
      <machanicalReduction>1</machanicalReduction>
    </actuator>
    <robotNamespace>/centauro</robotNamespace>
  </transmission>
  <transmission name="t_neck_pitch">
    <type> transmission_interface/SimpleTransmission</type>
    <joint name="neck_pitch">
      <hardwareInterface>hardware_interface/EffortJointInterface</hardwareInterface>
    </joint>
    <actuator name="motor_neck_pitch">
      <hardwareInterface>hardware_interface/EffortJointInterface</hardwareInterface>
      <machanicalReduction>1</machanicalReduction>
    </actuator>
    <robotNamespace>/centauro</robotNamespace>
  </transmission>
  <transmission name="t_neck_velodyne">
    <type> transmission_interface/SimpleTransmission</type>
    <joint name="neck_velodyne">
      <hardwareInterface>hardware_interface/EffortJointInterface</hardwareInterface>
    </joint>
    <actuator name="motor_neck_velodyne">
      <hardwareInterface>hardware_interface/EffortJointInterface</hardwareInterface>
      <machanicalReduction>1</machanicalReduction>
    </actuator>
    <robotNamespace>/centauro</robotNamespace>
  </transmission>
  <!-- /torso actuators -->
  <!-- /torso -->
  <!-- LINKS -->
  <!-- shoulder yaw-roll-->
  <link name="arm1_1">
    <inertial>
      <origin xyz="-0.0031005886 0.040324584 0.007451937"/>
      <mass value="1.5583338"/>
      <inertia ixx="0.0032318636" ixy="4.24587e-05" ixz="4.91626e-05" iyy="0.00275718" iyz="-0.0002387056" izz="0.004275047"/>
    </inertial>
    <visual>
      <origin rpy="0.0 0.0 0.0" xyz="0.0 0.0 0.0"/>
      <geometry>
        <mesh filename="meshes/simplified/link2.stl" scale="0.001 -0.001 0.001"/>
      </geometry>
      <material name="dark_grey"/>
    </visual>
    <collision>
      <origin rpy="0.0 0.0 0.0" xyz="0.0 0.0 0.0"/>
      <geometry>
        <mesh filename="meshes/convex_hull/link2.stl" scale="0.001 -0.001 0.001"/>
      </geometry>
    </collision>
  </link>
  <!-- shoulder yaw-roll-->
  <!-- shoulder roll-pitch-->
  <link name="arm1_2">
    <inertial>
      <origin xyz="0.05105435 0.00011109 -0.07643596"/>
      <mass value="1.515061"/>
      <inertia ixx="0.01029558" ixy="2.846e-05" ixz="0.0036567" iyy="0.01178018" iyz="2.088e-05" izz="0.00386123"/>
    </inertial>
    <visual>
      <origin rpy="0.0 0.0 0.0" xyz="0.0 0.0 0.0"/>
      <geometry>
        <mesh filename="meshes/simplified/link3.stl" scale="0.001 -0.001 0.001"/>
      </geometry>
    </visual>
    <collision>
      <origin rpy="0.0 0.0 0.0" xyz="0.0 0.0 0.0"/>
      <geometry>
        <mesh filename="meshes/convex_hull/link3.stl" scale="0.001 -0.001 0.001"/>
      </geometry>
    </collision>
  </link>
  <!-- shoulder roll-pitch-->
  <!-- shoulder-elbow -->
  <link name="arm1_3">
    <inertial>
      <origin xyz="0.01207624 0.00322013 -0.03427312"/>
      <mass value="1.5088101"/>
      <inertia ixx="0.00469819" ixy="-0.00026547" ixz="0.00077706" iyy="0.00501755" iyz="0.00029679" izz="0.00310954"/>
    </inertial>
    <visual>
      <origin rpy="0.0 0.0 0.0" xyz="0.0 0.0 0.0"/>
      <geometry>
        <mesh filename="meshes/simplified/link4.stl" scale="0.001 -0.001 0.001"/>
      </geometry>
      <material name="dark_grey"/>
    </visual>
    <collision>
      <origin rpy="0.0 0.0 0.0" xyz="0.0 0.0 0.0"/>
      <geometry>
        <mesh filename="meshes/convex_hull/link4.stl" scale="0.001 -0.001 0.001"/>
      </geometry>
    </collision>
  </link>
  <!-- /shoulder-elbow -->
  <!-- elbow yaw-pitch -->
  <link name="arm1_4">
    <inertial>
      <origin xyz="0.010147552 -0.029928537 -0.032528288"/>
      <mass value="0.96297329"/>
      <inertia ixx="0.0026493567" ixy="5.1632e-06" ixz="0.0001292309" iyy="0.0023470955" iyz="-0.0007895755" izz="0.0012213063"/>
    </inertial>
    <visual>
      <origin rpy="0.0 0.0 0.0" xyz="0.0 0.0 0.0"/>
      <geometry>
        <mesh filename="meshes/simplified/link5.stl" scale="0.001 -0.001 0.001"/>
      </geometry>
    </visual>
    <collision>
      <origin rpy="0.0 0.0 0.0" xyz="0.0 0.0 0.0"/>
      <geometry>
        <mesh filename="meshes/convex_hull/link5.stl" scale="0.001 -0.001 0.001"/>
      </geometry>
    </collision>
  </link>
  <!-- /elbow yaw-pitch -->
  <!-- elbow-wrist -->
  <link name="arm1_5">
    <inertial>
      <origin xyz="-0.0001574443 0.0041320907 -0.10756614"/>
      <mass value="1.4703698"/>
      <inertia ixx="0.0064160453" ixy="1.96382e-05" ixz="2.49912e-05" iyy="0.0062016367" iyz="-0.0001987903" izz="0.0017091658"/>
    </inertial>
    <visual>
      <origin rpy="0.0 0.0 0.0" xyz="0.0 0.0 0.0"/>
      <geometry>
        <mesh filename="meshes/simplified/link6.stl" scale="0.001 -0.001 0.001"/>
      </geometry>
      <material name="dark_grey"/>
    </visual>
    <collision>
      <origin rpy="0.0 0.0 0.0" xyz="0.0 0.0 0.0"/>
      <geometry>
        <mesh filename="meshes/convex_hull/link6.stl" scale="0.001 -0.001 0.001"/>
      </geometry>
    </collision>
  </link>
  <!-- /elbow-wrist -->
  <!-- wrist yaw-pitch -->
  <link name="arm1_6">
    <inertial>
      <origin xyz="3.23645e-05 -0.035947237 -0.080878061"/>
      <mass value="0.94693868"/>
      <inertia ixx="0.0036896582" ixy="2.63667e-05" ixz="1.4005e-06" iyy="0.0034146283" iyz="-0.0008268103" izz="0.0010790183"/>
    </inertial>
    <visual>
      <origin rpy="0.0 0.0 0.0" xyz="0.0 0.0 0.0"/>
      <geometry>
        <mesh filename="meshes/simplified/link7.stl" scale="0.001 -0.001 0.001"/>
      </geometry>
    </visual>
    <collision>
      <origin rpy="0.0 0.0 0.0" xyz="0.0 0.0 0.0"/>
      <geometry>
        <mesh filename="meshes/convex_hull/link7.stl" scale="0.001 -0.001 0.001"/>
      </geometry>
    </collision>
  </link>
  <!-- /wrist yaw-pitch -->
  <link name="arm1_7">
    <inertial>
      <origin xyz="2.46596e-05 -0.0001467705 -0.0052993013"/>
      <mass value="0.55981036"/>
      <inertia ixx="0.0004360175" ixy="1.397e-07" ixz="-1.382e-07" iyy="0.0004299166" iyz="-1.4752e-06" izz="0.0004522224"/>
    </inertial>
    <visual>
      <origin rpy="0.0 0.0 0.0" xyz="0.0 0.0 0.0"/>
      <geometry>
        <mesh filename="meshes/simplified/link8.stl" scale="0.001 -0.001 0.001"/>
      </geometry>
      <material name="dark_grey"/>
    </visual>
    <collision>
      <origin rpy="0.0 0.0 0.0" xyz="0.0 0.0 0.0"/>
      <geometry>
        <mesh filename="meshes/convex_hull/link8.stl" scale="0.001 -0.001 0.001"/>
      </geometry>
    </collision>
  </link>
  <!-- /LINKS -->
  <!-- JOINTS -->
  <!-- shoulder yaw -->
  <joint name="j_arm1_1" type="revolute">
    <parent link="torso_2"/>
    <child link="arm1_1"/>
    <origin rpy="0.0 0.0 -0.523602668986" xyz="0.04576 0.169137 0.116626"/>
    <axis xyz="0 0.984807753012 0.173648177667"/>
    <limit effort="147" lower="-3.348" upper="1.578" velocity="5.7"/>
  </joint>
  <!-- /shoulder yaw -->
  <!-- shoulder roll -->
  <joint name="j_arm1_2" type="revolute">
    <parent link="arm1_1"/>
    <child link="arm1_2"/>
    <origin xyz="-0.09115 0.06106 0.010766"/>
    <axis xyz="-1 0 0"/>
    <limit effort="147" lower="-3.42" upper="-0.056" velocity="5.7"/>
  </joint>
  <!-- /shoulder roll -->
  <!-- shoulder pitch-->
  <joint name="j_arm1_3" type="revolute">
    <parent link="arm1_2"/>
    <child link="arm1_3"/>
    <origin xyz="0.09115 0.0 -0.21915"/>
    <axis xyz="0 0 -1"/>
    <limit effort="147" lower="-2.5556" upper="2.5424" velocity="8.2"/>
  </joint>
  <!-- /shoulder pitch -->
  <!-- elbow yaw -->
  <joint name="j_arm1_4" type="revolute">
    <parent link="arm1_3"/>
    <child link="arm1_4"/>
    <origin xyz="0.04 0.05615 -0.074"/>
    <axis xyz="0 1 0"/>
    <limit effort="147" lower="-2.4636" upper="0.2804" velocity="8.2"/>
  </joint>
  <!-- /elbow yaw -->
  <!-- elbow pitch-->
  <joint name="j_arm1_5" type="revolute">
    <parent link="arm1_4"/>
    <child link="arm1_5"/>
    <origin xyz="-0.015 -0.05615 -0.061"/>
    <axis xyz="0 0 -1"/>
    <limit effort="55" lower="-2.5406" upper="2.5534" velocity="11.6"/>
  </joint>
  <!-- /elbow pitch-->
  <!-- wrist yaw-->
  <joint name="j_arm1_6" type="revolute">
    <parent link="arm1_5"/>
    <child link="arm1_6"/>
    <origin xyz="0.0 0.049 -0.18"/>
    <axis xyz="0 1 0"/>
    <limit effort="55" lower="-1.5096" upper="1.5044" velocity="11.6"/>
  </joint>
  <!-- /wrist yaw-->
  <!-- wrist pitch-->
  <joint name="j_arm1_7" type="revolute">
    <parent link="arm1_6"/>
    <child link="arm1_7"/>
    <origin xyz="0.0 -0.049 -0.169"/>
    <axis xyz="0 0 -1"/>
    <limit effort="27" lower="-2.5376" upper="2.5554" velocity="20.3"/>
  </joint>
  <!-- wrist pitch-->
  <!-- force-troque sensor -->
  <transmission name="t_j_arm1_1">
    <type> transmission_interface/SimpleTransmission</type>
    <joint name="j_arm1_1">
      <hardwareInterface>hardware_interface/EffortJointInterface</hardwareInterface>
    </joint>
    <actuator name="motor_j_arm1_1">
      <hardwareInterface>hardware_interface/EffortJointInterface</hardwareInterface>
      <machanicalReduction>1</machanicalReduction>
    </actuator>
    <robotNamespace>/centauro</robotNamespace>
  </transmission>
  <transmission name="t_j_arm1_2">
    <type> transmission_interface/SimpleTransmission</type>
    <joint name="j_arm1_2">
      <hardwareInterface>hardware_interface/EffortJointInterface</hardwareInterface>
    </joint>
    <actuator name="motor_j_arm1_2">
      <hardwareInterface>hardware_interface/EffortJointInterface</hardwareInterface>
      <machanicalReduction>1</machanicalReduction>
    </actuator>
    <robotNamespace>/centauro</robotNamespace>
  </transmission>
  <transmission name="t_j_arm1_3">
    <type> transmission_interface/SimpleTransmission</type>
    <joint name="j_arm1_3">
      <hardwareInterface>hardware_interface/EffortJointInterface</hardwareInterface>
    </joint>
    <actuator name="motor_j_arm1_3">
      <hardwareInterface>hardware_interface/EffortJointInterface</hardwareInterface>
      <machanicalReduction>1</machanicalReduction>
    </actuator>
    <robotNamespace>/centauro</robotNamespace>
  </transmission>
  <transmission name="t_j_arm1_4">
    <type> transmission_interface/SimpleTransmission</type>
    <joint name="j_arm1_4">
      <hardwareInterface>hardware_interface/EffortJointInterface</hardwareInterface>
    </joint>
    <actuator name="motor_j_arm1_4">
      <hardwareInterface>hardware_interface/EffortJointInterface</hardwareInterface>
      <machanicalReduction>1</machanicalReduction>
    </actuator>
    <robotNamespace>/centauro</robotNamespace>
  </transmission>
  <transmission name="t_j_arm1_5">
    <type> transmission_interface/SimpleTransmission</type>
    <joint name="j_arm1_5">
      <hardwareInterface>hardware_interface/EffortJointInterface</hardwareInterface>
    </joint>
    <actuator name="motor_j_arm1_5">
      <hardwareInterface>hardware_interface/EffortJointInterface</hardwareInterface>
      <machanicalReduction>1</machanicalReduction>
    </actuator>
    <robotNamespace>/centauro</robotNamespace>
  </transmission>
  <transmission name="t_j_arm1_6">
    <type> transmission_interface/SimpleTransmission</type>
    <joint name="j_arm1_6">
      <hardwareInterface>hardware_interface/EffortJointInterface</hardwareInterface>
    </joint>
    <actuator name="motor_j_arm1_6">
      <hardwareInterface>hardware_interface/EffortJointInterface</hardwareInterface>
      <machanicalReduction>1</machanicalReduction>
    </actuator>
    <robotNamespace>/centauro</robotNamespace>
  </transmission>
  <transmission name="t_j_arm1_7">
    <type> transmission_interface/SimpleTransmission</type>
    <joint name="j_arm1_7">
      <hardwareInterface>hardware_interface/EffortJointInterface</hardwareInterface>
    </joint>
    <actuator name="motor_j_arm1_7">
      <hardwareInterface>hardware_interface/EffortJointInterface</hardwareInterface>
      <machanicalReduction>1</machanicalReduction>
    </actuator>
    <robotNamespace>/centauro</robotNamespace>
  </transmission>
  <!-- /actuators -->
  <!-- wrist pitch-->
  <joint name="j_ft_1" type="revolute">
    <parent link="arm1_7"/>
    <child link="ft_arm1"/>
    <origin rpy="0.0 3.14159265359 -3.14159265359" xyz="0.0 0.0 -0.0405"/>
    <axis xyz="0 0 1"/>
    <limit effort="0" lower="0.0" upper="0.0" velocity="0"/>
  </joint>
  <!-- wrist pitch-->
  <link name="ft_arm1">
    <inertial>
      <origin xyz="0.0 -0.0 0.0"/>
      <mass value="0.15"/>
      <inertia ixx="1e-06" ixy="-0.0" ixz="0.0" iyy="1e-06" iyz="-0.0" izz="1e-06"/>
    </inertial>
  </link>
  <transmission name="t_j_ft_1">
    <type> transmission_interface/SimpleTransmission</type>
    <joint name="j_ft_1">
      <hardwareInterface>hardware_interface/EffortJointInterface</hardwareInterface>
    </joint>
    <actuator name="motor_j_ft_1">
      <hardwareInterface>hardware_interface/EffortJointInterface</hardwareInterface>
      <machanicalReduction>1</machanicalReduction>
    </actuator>
    <robotNamespace>/centauro</robotNamespace>
  </transmission>
  <!-- links -->
  <link name="arm1_8">
    <inertial>
      <origin rpy="0 0 0" xyz="0.001 0.0 0.006"/>
      <mass value="0.15"/>
      <inertia ixx="0.0002" ixy="0.0" ixz="0.0" iyy="0.0002" iyz="0.0" izz="1e-05"/>
      <!--          <inertia ixx="0.003"  ixy="0"  ixz="0" iyy="0.0025" iyz="0" izz="0.00016900" /> -->
    </inertial>
    <visual>
      <origin rpy="0.0 0.0 0.0" xyz="0.0 0.0 0.0"/>
      <geometry>
        <mesh filename="meshes/simplified/link9.stl" scale="0.001 -0.001 -0.001"/>
      </geometry>
      <material name="dark_grey"/>
    </visual>
    <collision>
      <origin rpy="0.0 0.0 0.0" xyz="0.0 0.0 0.0"/>
      <geometry>
        <mesh filename="meshes/convex_hull/link9.stl" scale="0.001 -0.001 -0.001"/>
      </geometry>
    </collision>
  </link>
  <!-- /links -->
  <!-- joints -->
  <joint name="j_arm1_8" type="fixed">
    <parent link="ft_arm1"/>
    <origin rpy="0.0 0.0 -1.5707963268" xyz="0.0 0.0 0.0"/>
    <child link="arm1_8"/>
    <axis xyz="1 0 0"/>
  </joint>
   --&gt;

  <!-- /joints -->
  <!-- /end-effector -->
  <!-- LINKS -->
  <!-- shoulder yaw-roll-->
  <link name="arm2_1">
    <inertial>
      <origin xyz="-0.0031005886 -0.040324584 0.007451937"/>
      <mass value="1.5583338"/>
      <inertia ixx="0.0032318636" ixy="-4.24587e-05" ixz="4.91626e-05" iyy="0.00275718" iyz="0.0002387056" izz="0.004275047"/>
    </inertial>
    <visual>
      <origin rpy="0.0 0.0 0.0" xyz="0.0 0.0 0.0"/>
      <geometry>
        <mesh filename="meshes/simplified/link2.stl" scale="0.001 0.001 0.001"/>
      </geometry>
      <material name="dark_grey"/>
    </visual>
    <collision>
      <origin rpy="0.0 0.0 0.0" xyz="0.0 0.0 0.0"/>
      <geometry>
        <mesh filename="meshes/convex_hull/link2.stl" scale="0.001 0.001 0.001"/>
      </geometry>
    </collision>
  </link>
  <!-- shoulder yaw-roll-->
  <!-- shoulder roll-pitch-->
  <link name="arm2_2">
    <inertial>
      <origin xyz="0.05105435 -0.00011109 -0.07643596"/>
      <mass value="1.515061"/>
      <inertia ixx="0.01029558" ixy="-2.846e-05" ixz="0.0036567" iyy="0.01178018" iyz="-2.088e-05" izz="0.00386123"/>
    </inertial>
    <visual>
      <origin rpy="0.0 0.0 0.0" xyz="0.0 0.0 0.0"/>
      <geometry>
        <mesh filename="meshes/simplified/link3.stl" scale="0.001 0.001 0.001"/>
      </geometry>
    </visual>
    <collision>
      <origin rpy="0.0 0.0 0.0" xyz="0.0 0.0 0.0"/>
      <geometry>
        <mesh filename="meshes/convex_hull/link3.stl" scale="0.001 0.001 0.001"/>
      </geometry>
    </collision>
  </link>
  <!-- shoulder roll-pitch-->
  <!-- shoulder-elbow -->
  <link name="arm2_3">
    <inertial>
      <origin xyz="0.01207624 -0.00322013 -0.03427312"/>
      <mass value="1.5088101"/>
      <inertia ixx="0.00469819" ixy="0.00026547" ixz="0.00077706" iyy="0.00501755" iyz="-0.00029679" izz="0.00310954"/>
    </inertial>
    <visual>
      <origin rpy="0.0 0.0 0.0" xyz="0.0 0.0 0.0"/>
      <geometry>
        <mesh filename="meshes/simplified/link4.stl" scale="0.001 0.001 0.001"/>
      </geometry>
      <material name="dark_grey"/>
    </visual>
    <collision>
      <origin rpy="0.0 0.0 0.0" xyz="0.0 0.0 0.0"/>
      <geometry>
        <mesh filename="meshes/convex_hull/link4.stl" scale="0.001 0.001 0.001"/>
      </geometry>
    </collision>
  </link>
  <!-- /shoulder-elbow -->
  <!-- elbow yaw-pitch -->
  <link name="arm2_4">
    <inertial>
      <origin xyz="0.010147552 0.029928537 -0.032528288"/>
      <mass value="0.96297329"/>
      <inertia ixx="0.0026493567" ixy="-5.1632e-06" ixz="0.0001292309" iyy="0.0023470955" iyz="0.0007895755" izz="0.0012213063"/>
    </inertial>
    <visual>
      <origin rpy="0.0 0.0 0.0" xyz="0.0 0.0 0.0"/>
      <geometry>
        <mesh filename="meshes/simplified/link5.stl" scale="0.001 0.001 0.001"/>
      </geometry>
    </visual>
    <collision>
      <origin rpy="0.0 0.0 0.0" xyz="0.0 0.0 0.0"/>
      <geometry>
        <mesh filename="meshes/convex_hull/link5.stl" scale="0.001 0.001 0.001"/>
      </geometry>
    </collision>
  </link>
  <!-- /elbow yaw-pitch -->
  <!-- elbow-wrist -->
  <link name="arm2_5">
    <inertial>
      <origin xyz="-0.0001574443 -0.0041320907 -0.10756614"/>
      <mass value="1.4703698"/>
      <inertia ixx="0.0064160453" ixy="-1.96382e-05" ixz="2.49912e-05" iyy="0.0062016367" iyz="0.0001987903" izz="0.0017091658"/>
    </inertial>
    <visual>
      <origin rpy="0.0 0.0 0.0" xyz="0.0 0.0 0.0"/>
      <geometry>
        <mesh filename="meshes/simplified/link6.stl" scale="0.001 0.001 0.001"/>
      </geometry>
      <material name="dark_grey"/>
    </visual>
    <collision>
      <origin rpy="0.0 0.0 0.0" xyz="0.0 0.0 0.0"/>
      <geometry>
        <mesh filename="meshes/convex_hull/link6.stl" scale="0.001 0.001 0.001"/>
      </geometry>
    </collision>
  </link>
  <!-- /elbow-wrist -->
  <!-- wrist yaw-pitch -->
  <link name="arm2_6">
    <inertial>
      <origin xyz="3.23645e-05 0.035947237 -0.080878061"/>
      <mass value="0.94693868"/>
      <inertia ixx="0.0036896582" ixy="-2.63667e-05" ixz="1.4005e-06" iyy="0.0034146283" iyz="0.0008268103" izz="0.0010790183"/>
    </inertial>
    <visual>
      <origin rpy="0.0 0.0 0.0" xyz="0.0 0.0 0.0"/>
      <geometry>
        <mesh filename="meshes/simplified/link7.stl" scale="0.001 0.001 0.001"/>
      </geometry>
    </visual>
    <collision>
      <origin rpy="0.0 0.0 0.0" xyz="0.0 0.0 0.0"/>
      <geometry>
        <mesh filename="meshes/convex_hull/link7.stl" scale="0.001 0.001 0.001"/>
      </geometry>
    </collision>
  </link>
  <!-- /wrist yaw-pitch -->
  <link name="arm2_7">
    <inertial>
      <origin xyz="2.46596e-05 0.0001467705 -0.0052993013"/>
      <mass value="0.55981036"/>
      <inertia ixx="0.0004360175" ixy="-1.397e-07" ixz="-1.382e-07" iyy="0.0004299166" iyz="1.4752e-06" izz="0.0004522224"/>
    </inertial>
    <visual>
      <origin rpy="0.0 0.0 0.0" xyz="0.0 0.0 0.0"/>
      <geometry>
        <mesh filename="meshes/simplified/link8.stl" scale="0.001 0.001 0.001"/>
      </geometry>
      <material name="dark_grey"/>
    </visual>
    <collision>
      <origin rpy="0.0 0.0 0.0" xyz="0.0 0.0 0.0"/>
      <geometry>
        <mesh filename="meshes/convex_hull/link8.stl" scale="0.001 0.001 0.001"/>
      </geometry>
    </collision>
  </link>
  <!-- /LINKS -->
  <!-- JOINTS -->
  <!-- shoulder yaw -->
  <joint name="j_arm2_1" type="revolute">
    <parent link="torso_2"/>
    <child link="arm2_1"/>
    <origin rpy="0.0 0.0 0.523602668986" xyz="0.04576 -0.169137 0.116626"/>
    <axis xyz="0 -0.984807753012 0.173648177667"/>
    <limit effort="147" lower="-1.6102" upper="3.3138" velocity="5.7"/>
  </joint>
  <!-- /shoulder yaw -->
  <!-- shoulder roll -->
  <joint name="j_arm2_2" type="revolute">
    <parent link="arm2_1"/>
    <child link="arm2_2"/>
    <origin xyz="-0.09115 -0.06106 0.010766"/>
    <axis xyz="-1 0 0"/>
    <limit effort="147" lower="0.0578" upper="3.4288" velocity="5.7"/>
  </joint>
  <!-- /shoulder roll -->
  <!-- shoulder pitch-->
  <joint name="j_arm2_3" type="revolute">
    <parent link="arm2_2"/>
    <child link="arm2_3"/>
    <origin xyz="0.09115 0.0 -0.21915"/>
    <axis xyz="0 0 -1"/>
    <limit effort="147" lower="-2.5426" upper="2.5524" velocity="8.2"/>
  </joint>
  <!-- /shoulder pitch -->
  <!-- elbow yaw -->
  <joint name="j_arm2_4" type="revolute">
    <parent link="arm2_3"/>
    <child link="arm2_4"/>
    <origin xyz="0.04 -0.05615 -0.074"/>
    <axis xyz="0 -1 0"/>
    <limit effort="147" lower="-0.2796" upper="2.4564" velocity="8.2"/>
  </joint>
  <!-- /elbow yaw -->
  <!-- elbow pitch-->
  <joint name="j_arm2_5" type="revolute">
    <parent link="arm2_4"/>
    <child link="arm2_5"/>
    <origin xyz="-0.015 0.05615 -0.061"/>
    <axis xyz="0 0 -1"/>
    <limit effort="55" lower="-2.5626" upper="2.5464" velocity="11.6"/>
  </joint>
  <!-- /elbow pitch-->
  <!-- wrist yaw-->
  <joint name="j_arm2_6" type="revolute">
    <parent link="arm2_5"/>
    <child link="arm2_6"/>
    <origin xyz="0.0 -0.049 -0.18"/>
    <axis xyz="0 -1 0"/>
    <limit effort="55" lower="-1.4726" upper="1.5364" velocity="11.6"/>
  </joint>
  <!-- /wrist yaw-->
  <!-- wrist pitch-->
  <joint name="j_arm2_7" type="revolute">
    <parent link="arm2_6"/>
    <child link="arm2_7"/>
    <origin xyz="0.0 0.049 -0.169"/>
    <axis xyz="0 0 -1"/>
    <limit effort="27" lower="-3.0908" upper="2.0114" velocity="20.3"/>
  </joint>
  <!-- wrist pitch-->
  <!-- force-troque sensor -->
  <transmission name="t_j_arm2_1">
    <type> transmission_interface/SimpleTransmission</type>
    <joint name="j_arm2_1">
      <hardwareInterface>hardware_interface/EffortJointInterface</hardwareInterface>
    </joint>
    <actuator name="motor_j_arm2_1">
      <hardwareInterface>hardware_interface/EffortJointInterface</hardwareInterface>
      <machanicalReduction>1</machanicalReduction>
    </actuator>
    <robotNamespace>/centauro</robotNamespace>
  </transmission>
  <transmission name="t_j_arm2_2">
    <type> transmission_interface/SimpleTransmission</type>
    <joint name="j_arm2_2">
      <hardwareInterface>hardware_interface/EffortJointInterface</hardwareInterface>
    </joint>
    <actuator name="motor_j_arm2_2">
      <hardwareInterface>hardware_interface/EffortJointInterface</hardwareInterface>
      <machanicalReduction>1</machanicalReduction>
    </actuator>
    <robotNamespace>/centauro</robotNamespace>
  </transmission>
  <transmission name="t_j_arm2_3">
    <type> transmission_interface/SimpleTransmission</type>
    <joint name="j_arm2_3">
      <hardwareInterface>hardware_interface/EffortJointInterface</hardwareInterface>
    </joint>
    <actuator name="motor_j_arm2_3">
      <hardwareInterface>hardware_interface/EffortJointInterface</hardwareInterface>
      <machanicalReduction>1</machanicalReduction>
    </actuator>
    <robotNamespace>/centauro</robotNamespace>
  </transmission>
  <transmission name="t_j_arm2_4">
    <type> transmission_interface/SimpleTransmission</type>
    <joint name="j_arm2_4">
      <hardwareInterface>hardware_interface/EffortJointInterface</hardwareInterface>
    </joint>
    <actuator name="motor_j_arm2_4">
      <hardwareInterface>hardware_interface/EffortJointInterface</hardwareInterface>
      <machanicalReduction>1</machanicalReduction>
    </actuator>
    <robotNamespace>/centauro</robotNamespace>
  </transmission>
  <transmission name="t_j_arm2_5">
    <type> transmission_interface/SimpleTransmission</type>
    <joint name="j_arm2_5">
      <hardwareInterface>hardware_interface/EffortJointInterface</hardwareInterface>
    </joint>
    <actuator name="motor_j_arm2_5">
      <hardwareInterface>hardware_interface/EffortJointInterface</hardwareInterface>
      <machanicalReduction>1</machanicalReduction>
    </actuator>
    <robotNamespace>/centauro</robotNamespace>
  </transmission>
  <transmission name="t_j_arm2_6">
    <type> transmission_interface/SimpleTransmission</type>
    <joint name="j_arm2_6">
      <hardwareInterface>hardware_interface/EffortJointInterface</hardwareInterface>
    </joint>
    <actuator name="motor_j_arm2_6">
      <hardwareInterface>hardware_interface/EffortJointInterface</hardwareInterface>
      <machanicalReduction>1</machanicalReduction>
    </actuator>
    <robotNamespace>/centauro</robotNamespace>
  </transmission>
  <transmission name="t_j_arm2_7">
    <type> transmission_interface/SimpleTransmission</type>
    <joint name="j_arm2_7">
      <hardwareInterface>hardware_interface/EffortJointInterface</hardwareInterface>
    </joint>
    <actuator name="motor_j_arm2_7">
      <hardwareInterface>hardware_interface/EffortJointInterface</hardwareInterface>
      <machanicalReduction>1</machanicalReduction>
    </actuator>
    <robotNamespace>/centauro</robotNamespace>
  </transmission>
  <!-- /actuators -->
  <!-- wrist pitch-->
  <joint name="j_ft_2" type="revolute">
    <parent link="arm2_7"/>
    <child link="ft_arm2"/>
    <origin rpy="0.0 3.14159265359 -3.14159265359" xyz="0.0 0.0 -0.0405"/>
    <axis xyz="0 0 1"/>
    <limit effort="0" lower="0.0" upper="0.0" velocity="0"/>
  </joint>
  <!-- wrist pitch-->
  <link name="ft_arm2">
    <inertial>
      <origin xyz="0.0 0.0 0.0"/>
      <mass value="0.15"/>
      <inertia ixx="1e-06" ixy="0.0" ixz="0.0" iyy="1e-06" iyz="0.0" izz="1e-06"/>
    </inertial>
  </link>
  <transmission name="t_j_ft_2">
    <type> transmission_interface/SimpleTransmission</type>
    <joint name="j_ft_2">
      <hardwareInterface>hardware_interface/EffortJointInterface</hardwareInterface>
    </joint>
    <actuator name="motor_j_ft_2">
      <hardwareInterface>hardware_interface/EffortJointInterface</hardwareInterface>
      <machanicalReduction>1</machanicalReduction>
    </actuator>
    <robotNamespace>/centauro</robotNamespace>
  </transmission>
  <!-- All inertia values are dummy values, please change them with the real ones -->
  <!-- RIGHT HAND = 1, LEFT HAND = -1 -->
  <!-- BASE_LINE LINKS -->
  <link name="right_hand_camera_link">
    <inertial>
      <mass value="0.03"/>
      <inertia ixx="0.00001" ixy="0.0" ixz="0.0" iyy="0.00001" iyz="0.0" izz="0.00001"/>
    </inertial>
    <visual>
      <origin rpy="0 0 0" xyz="0 0 0"/>
      <geometry>
        <mesh filename="meshes/schunk_hand/camera_link.STL"/>
      </geometry>
    </visual>
    <collision>
      <origin rpy="0 0 0" xyz="0 0 0"/>
      <geometry>
        <mesh filename="meshes/schunk_hand/camera_link.STL"/>
      </geometry>
    </collision>
  </link>
  <joint name="right_hand_camera_joint" type="fixed">
    <origin rpy="3.14159265359 0 1.5707963268" xyz="0 0 -0.04"/>
    <parent link="arm2_7"/>
    <child link="right_hand_camera_link"/>
  </joint>
  <joint name="right_hand_base_joint" type="fixed">
    <origin rpy="0 0 -1.5707963268" xyz="0 0 0.0495"/>
    <parent link="right_hand_camera_link"/>
    <child link="right_hand_base_link"/>
  </joint>
  <link name="right_hand_base_link">
    <inertial>
      <mass value="0.03"/>
      <inertia ixx="0.00001" ixy="0.0" ixz="0.0" iyy="0.00001" iyz="0.0" izz="0.00001"/>
    </inertial>
    <origin rpy="3.14159265359 0 1.5707963268" xyz="0 0 -0.04"/>
    <visual>
      <origin rpy="0 0 0" xyz="0 0 -0.032"/>
      <geometry>
        <mesh filename="meshes/schunk_hand/base10.dae"/>
      </geometry>
    </visual>
    <collision>
      <origin rpy="0 0 0" xyz="0 0 -0.032"/>
      <geometry>
        <mesh filename="meshes/schunk_hand/base10.dae"/>
      </geometry>
    </collision>
  </link>
  <link name="right_hand_d">
    <inertial>
      <mass value="0.03"/>
      <inertia ixx="0.00001" ixy="0.0" ixz="0.0" iyy="0.00001" iyz="0.0" izz="0.00001"/>
    </inertial>
  </link>
  <link name="right_hand_h">
    <inertial>
      <mass value="0.03"/>
      <inertia ixx="0.00001" ixy="0.0" ixz="0.0" iyy="0.00001" iyz="0.0" izz="0.00001"/>
    </inertial>
  </link>
  <link name="right_hand_d2">
    <inertial>
      <mass value="0.03"/>
      <inertia ixx="0.00001" ixy="0.0" ixz="0.0" iyy="0.00001" iyz="0.0" izz="0.00001"/>
    </inertial>
  </link>
  <!-- LENGTH NOT FOUND IN DATASHEET! GUESSED!!! -->
  <link name="right_hand_e1">
    <inertial>
      <mass value="0.03"/>
      <inertia ixx="0.00001" ixy="0.0" ixz="0.0" iyy="0.00001" iyz="0.0" izz="0.00001"/>
    </inertial>
    <visual>
      <origin rpy="0 0 0" xyz="0 0.01313 0"/>
      <geometry>
        <mesh filename="meshes/schunk_hand/h10.dae" scale="1 1 1"/>
      </geometry>
    </visual>
    <collision>
      <!--origin rpy="0 0 0" xyz="0 0.01313 0" /-->
      <origin rpy="0 0 0" xyz="-0.00368 0.0 0.06"/>
      <geometry>
        <box size="0.055 0.025 0.12"/>
        <!--mesh scale="${side*(1)} 1 1" filename="meshes/schunk_hand/h10.dae" /-->
      </geometry>
    </collision>
    <!--xacro:capsule-collision e1="0.01251 0.00157842 0.0928213" e2="-0.000462897 0.0155179 0.0150623" rad="0.035205530643540185" len="0.080056609487979907" rpy="-2.96421 -0.162765 1.48449" mid="0.00602356 0.00854815 0.0539418" /-->
  </link>
  <!-- LENGTH NOT FOUND IN DATASHEET! GUESSED!!! -->
  <link name="right_hand_e2">
    <inertial>
      <mass value="0.03"/>
      <inertia ixx="0.00001" ixy="0.0" ixz="0.0" iyy="0.00001" iyz="0.0" izz="0.00001"/>
    </inertial>
    <visual>
      <origin xyz="-0.0007 0 -0.01002"/>
      <geometry>
        <mesh filename="meshes/schunk_hand/h11.dae" scale="1 1 1"/>
      </geometry>
    </visual>
    <collision>
      <origin xyz="-0.0007 0 -0.01002"/>
      <geometry>
        <mesh filename="meshes/schunk_hand/h11.dae" scale="1 1 1"/>
      </geometry>
    </collision>
    <!--xacro:capsule-collision e1="-0.0130892 -0.00943485 0.0572708" e2="-0.00918653 -0.000238213 0.0052382" rad="0.025230241520476298" len="0.052982989614211572" rpy="-2.96665 0.0737258 -0.796187" mid="-0.0111379 -0.00483653 0.0312545" /-->
  </link>
  <!-- LENGTH NOT FOUND IN DATASHEET! GUESSED!!! -->
  <link name="right_hand_e3">
    <inertial>
      <mass value="0.03"/>
      <inertia ixx="0.00001" ixy="0.0" ixz="0.0" iyy="0.00001" iyz="0.0" izz="0.00001"/>
    </inertial>
    <!-- <visual> -->
    <!-- 	<origin rpy="0 0 0" xyz="${side*(0.0175)} 0 0.015" /> -->
    <!-- 	<geometry> -->
    <!-- 	  <cylinder length="0.03" radius="${cyl_radius}" /> -->
    <!-- 	</geometry> -->
    <!-- 	<material name="green" /> -->
    <!-- </visual> -->
  </link>
  <link name="right_hand_e">
    <inertial>
      <mass value="0.03"/>
      <inertia ixx="0.00001" ixy="0.0" ixz="0.0" iyy="0.00001" iyz="0.0" izz="0.00001"/>
    </inertial>
  </link>
  <!-- LENGTH NOT FOUND IN DATASHEET! GUESSED, BUT POSITION CALCULATED: E4 = D-G-F!!! -->
  <link name="right_hand_e4">
    <inertial>
      <mass value="0.03"/>
      <inertia ixx="0.00001" ixy="0.0" ixz="0.0" iyy="0.00001" iyz="0.0" izz="0.00001"/>
    </inertial>
    <!-- <visual> -->
    <!-- 	<origin rpy="0 0 0" xyz="${side*(0.02825)} 0 0.043" /> -->
    <!-- 	<geometry> -->
    <!-- 	  <cylinder length="0.026" radius="${cyl_radius}" /> -->
    <!-- 	</geometry> -->
    <!-- 	<material name="green" /> -->
    <!-- </visual> -->
  </link>
  <!-- LENGTH NOT FOUND IN DATASHEET! GUESSED, BUT POSITION CALCULATED: E5 = D-G!!! -->
  <link name="right_hand_e5">
    <inertial>
      <mass value="0.03"/>
      <inertia ixx="0.00001" ixy="0.0" ixz="0.0" iyy="0.00001" iyz="0.0" izz="0.00001"/>
    </inertial>
    <!-- <visual> -->
    <!-- 	<origin rpy="0 0 0" xyz="${side*(0.00675)} 0 0.04775" /> -->
    <!-- 	<geometry> -->
    <!-- 	  <cylinder length="0.0355" radius="${cyl_radius}" /> -->
    <!-- 	</geometry> -->
    <!-- 	<material name="green" /> -->
    <!-- </visual> -->
  </link>
  <!-- THUMB LINKS -->
  <link name="right_hand_z">
    <inertial>
      <mass value="0.03"/>
      <inertia ixx="0.00001" ixy="0.0" ixz="0.0" iyy="0.00001" iyz="0.0" izz="0.00001"/>
    </inertial>
    <visual>
      <origin xyz="0 0 0.02442"/>
      <geometry>
        <mesh filename="meshes/schunk_hand/d10.dae" scale="1 1 1"/>
      </geometry>
    </visual>
    <collision>
      <origin rpy="2.9985 8.56161e-08 1.19461e-06" xyz="4.35903e-09 0.00135239 0.0513426"/>
      <geometry>
        <sphere radius="0.0187964403536"/>
      </geometry>
    </collision>
    <collision>
      <origin rpy="2.9985 8.56161e-08 1.19461e-06" xyz="4.8053e-09 0.000609069 0.0461834"/>
      <geometry>
        <cylinder length="0.0104248181037" radius="0.0187964403536"/>
      </geometry>
    </collision>
    <collision>
      <origin rpy="2.9985 8.56161e-08 1.19461e-06" xyz="5.25157e-09 -0.000134248 0.0410243"/>
      <geometry>
        <sphere radius="0.0187964403536"/>
      </geometry>
    </collision>
  </link>
  <link name="right_hand_virtual_a">
    <inertial>
      <mass value="0.03"/>
      <inertia ixx="0.00001" ixy="0.0" ixz="0.0" iyy="0.00001" iyz="0.0" izz="0.00001"/>
    </inertial>
  </link>
  <link name="right_hand_a">
    <inertial>
      <mass value="0.03"/>
      <inertia ixx="0.00001" ixy="0.0" ixz="0.0" iyy="0.00001" iyz="0.0" izz="0.00001"/>
    </inertial>
    <visual>
      <geometry>
        <mesh filename="meshes/schunk_hand/d11.dae" scale="1 1 1"/>
      </geometry>
    </visual>
    <collision>
      <origin rpy="-1.57079 1.53946 -1.53946" xyz="-0.000196701 -0.00148458 -1.94634e-05"/>
      <geometry>
        <sphere radius="0.0167591808589"/>
      </geometry>
    </collision>
    <collision>
      <origin rpy="-1.57079 1.53946 -1.53946" xyz="0.0234125 -0.000744623 -1.94586e-05"/>
      <geometry>
        <cylinder length="0.0472415416058" radius="0.0167591808589"/>
      </geometry>
    </collision>
    <collision>
      <origin rpy="-1.57079 1.53946 -1.53946" xyz="0.0470217 -4.66742e-06 -1.94537e-05"/>
      <geometry>
        <sphere radius="0.0167591808589"/>
      </geometry>
    </collision>
  </link>
  <link name="right_hand_b">
    <inertial>
      <mass value="0.03"/>
      <inertia ixx="0.00001" ixy="0.0" ixz="0.0" iyy="0.00001" iyz="0.0" izz="0.00001"/>
    </inertial>
    <visual>
      <geometry>
        <mesh filename="meshes/schunk_hand/d12.dae" scale="1 1 1"/>
      </geometry>
    </visual>
    <collision>
      <origin rpy="1.56836 1.57067 1.56823" xyz="1.38494e-05 -5.84793e-06 2.67358e-06"/>
      <geometry>
        <sphere radius="0.0157927296103"/>
      </geometry>
    </collision>
    <collision>
      <origin rpy="1.56836 1.57067 1.56823" xyz="0.0115211 -7.34551e-06 2.67722e-06"/>
      <geometry>
        <cylinder length="0.0230145255328" radius="0.0157927296103"/>
      </geometry>
    </collision>
    <collision>
      <origin rpy="1.56836 1.57067 1.56823" xyz="0.0230284 -8.84308e-06 2.68087e-06"/>
      <geometry>
        <sphere radius="0.0157927296103"/>
      </geometry>
    </collision>
  </link>
  <link name="right_hand_c">
    <inertial>
      <mass value="0.03"/>
      <inertia ixx="0.00001" ixy="0.0" ixz="0.0" iyy="0.00001" iyz="0.0" izz="0.00001"/>
    </inertial>
    <visual>
      <geometry>
        <mesh filename="meshes/schunk_hand/d13.dae" scale="1 1 1"/>
      </geometry>
    </visual>
    <collision>
      <origin rpy="1.5708 1.55113 1.55114" xyz="0.00205819 -0.000468129 7.76376e-10"/>
      <geometry>
        <sphere radius="0.010704766923"/>
      </geometry>
    </collision>
    <collision>
      <origin rpy="1.5708 1.55113 1.55114" xyz="0.0096433 -0.000617283 1.28171e-10"/>
      <geometry>
        <cylinder length="0.0151731409586" radius="0.010704766923"/>
      </geometry>
    </collision>
    <collision>
      <origin rpy="1.5708 1.55113 1.55114" xyz="0.0172284 -0.000766437 -5.20034e-10"/>
      <geometry>
        <sphere radius="0.010704766923"/>
      </geometry>
    </collision>
  </link>
  <link name="right_hand_thumb_tip_ee">
    <inertial>
      <origin rpy="0 0 0" xyz="0 0 0"/>
      <mass value="0"/>
      <inertia ixx="0.0" ixy="0.0" ixz="0.0" iyy="0.0" iyz="0.0" izz="0.0"/>
    </inertial>
  </link> <!-- in pybullet, the inertia need to be specified even for dummy links, otherwise it will put an identity inertia and a mass of 1 by default -->
  <joint name="right_hand_thumb_tip_joint" type="fixed">
    <parent link="right_hand_c"/>
    <child link="right_hand_thumb_tip_ee"/>
    <origin rpy="0 0 0" xyz="0.012 0.01 0.0"/>
  </joint>
  <!-- INDEX FINGER LINKS -->
  <link name="right_hand_virtual_l">
    <inertial>
      <mass value="0.03"/>
      <inertia ixx="0.00001" ixy="0.0" ixz="0.0" iyy="0.00001" iyz="0.0" izz="0.00001"/>
    </inertial>
    <visual>
      <origin xyz="0 0 0.01321"/>
      <geometry>
        <mesh filename="meshes/schunk_hand/f10.dae"/>
      </geometry>
    </visual>
    <collision>
      <origin rpy="-3.14159 -0.218902 3.14159" xyz="-9.36911e-06 2.05516e-05 0.00314503"/>
      <geometry>
        <sphere radius="0.0124183215874"/>
      </geometry>
    </collision>
    <collision>
      <origin rpy="-3.14159 -0.218902 3.14159" xyz="-0.000565219 2.05537e-05 0.000646459"/>
      <geometry>
        <cylinder length="0.00511930368187" radius="0.0124183215874"/>
      </geometry>
    </collision>
    <collision>
      <origin rpy="-3.14159 -0.218902 3.14159" xyz="-0.00112107 2.05558e-05 -0.00185211"/>
      <geometry>
        <sphere radius="0.0124183215874"/>
      </geometry>
    </collision>
  </link>
  <link name="right_hand_l">
    <inertial>
      <mass value="0.03"/>
      <inertia ixx="0.00001" ixy="0.0" ixz="0.0" iyy="0.00001" iyz="0.0" izz="0.00001"/>
    </inertial>
    <visual>
      <geometry>
        <mesh filename="meshes/schunk_hand/f11.dae"/>
      </geometry>
    </visual>
    <collision>
      <origin rpy="-1.57082 1.56946 -1.56948" xyz="0.000494844 0.000786315 2.26346e-09"/>
      <geometry>
        <sphere radius="0.0104104100979"/>
      </geometry>
    </collision>
    <collision>
      <origin rpy="-1.57082 1.56946 -1.56948" xyz="0.0239282 0.000817694 1.63176e-09"/>
      <geometry>
        <cylinder length="0.0468666682082" radius="0.0104104100979"/>
      </geometry>
    </collision>
    <collision>
      <origin rpy="-1.57082 1.56946 -1.56948" xyz="0.0473615 0.000849073 1.00007e-09"/>
      <geometry>
        <sphere radius="0.0104104100979"/>
      </geometry>
    </collision>
  </link>
  <link name="right_hand_p">
    <inertial>
      <mass value="0.05"/>
      <origin rpy="0.0 1.57 0.0" xyz="0.0127 0.0 0.0"/>
      <inertia ixx="6.23228917375e-06" ixy="0.0" ixz="0.0" iyy="6.23228917375e-06" iyz="0.0" izz="2.25625e-06"/>
    </inertial>
    <visual>
      <geometry>
        <mesh filename="meshes/schunk_hand/f12.dae"/>
      </geometry>
    </visual>
    <collision>
      <origin rpy="-1.5708 1.56914 -1.56914" xyz="-2.97253e-05 1.67438e-05 -1.68626e-18"/>
      <geometry>
        <sphere radius="0.0110292374466"/>
      </geometry>
    </collision>
    <collision>
      <origin rpy="-1.5708 1.56914 -1.56914" xyz="0.011829 3.63913e-05 5.61001e-18"/>
      <geometry>
        <cylinder length="0.0237175682775" radius="0.0110292374466"/>
      </geometry>
    </collision>
    <collision>
      <origin rpy="-1.5708 1.56914 -1.56914" xyz="0.0236878 5.60387e-05 1.29063e-17"/>
      <geometry>
        <sphere radius="0.0110292374466"/>
      </geometry>
    </collision>
  </link>
  <link name="right_hand_t">
    <!--xacro:dummy_inertial /-->
    <inertial>
      <mass value="0.03"/>
      <origin rpy="0 1.57 0" xyz="0.007 0 0"/>
      <inertia ixx="2.439999024e-06" ixy="0.0" ixz="0.0" iyy="2.439999024e-06" iyz="0.0" izz="9.6e-07"/>
    </inertial>
    <visual>
      <geometry>
        <mesh filename="meshes/schunk_hand/f13.dae"/>
      </geometry>
    </visual>
    <collision>
      <origin rpy="-1.5708 1.56702 -1.56702" xyz="0.00112397 6.55543e-05 2.56588e-17"/>
      <geometry>
        <sphere radius="0.00858501607426"/>
      </geometry>
    </collision>
    <collision>
      <origin rpy="-1.5708 1.56702 -1.56702" xyz="0.00751444 8.96663e-05 1.21518e-17"/>
      <geometry>
        <cylinder length="0.0127810419291" radius="0.00858501607426"/>
      </geometry>
    </collision>
    <collision>
      <origin rpy="-1.5708 1.56702 -1.56702" xyz="0.0139049 0.000113778 -1.35513e-18"/>
      <geometry>
        <sphere radius="0.00858501607426"/>
      </geometry>
    </collision>
  </link>
  <link name="right_hand_index_tip_ee">
    <inertial>
      <origin rpy="0 0 0" xyz="0 0 0"/>
      <mass value="0"/>
      <inertia ixx="0.0" ixy="0.0" ixz="0.0" iyy="0.0" iyz="0.0" izz="0.0"/>
    </inertial>
  </link> <!-- in pybullet, the inertia need to be specified even for dummy links, otherwise it will put an identity inertia and a mass of 1 by default -->
  <joint name="right_hand_index_tip_joint" type="fixed">
    <parent link="right_hand_t"/>
    <child link="right_hand_index_tip_ee"/>
    <origin rpy="0 0 0" xyz="0.012 0.007 0.0"/>
  </joint>
  <!-- MIDDLE FINGER LINKS -->
  <link name="right_hand_virtual_k">
    <inertial>
      <mass value="0.03"/>
      <inertia ixx="0.00001" ixy="0.0" ixz="0.0" iyy="0.00001" iyz="0.0" izz="0.00001"/>
    </inertial>
    <visual>
      <origin xyz="0 0 0.01321"/>
      <geometry>
        <mesh filename="meshes/schunk_hand/f20.dae"/>
      </geometry>
    </visual>
    <collision>
      <origin rpy="-3.14159 -0.21666 3.14158" xyz="-2.48053e-05 -8.49468e-07 0.00306843"/>
      <geometry>
        <sphere radius="0.0124149630608"/>
      </geometry>
    </collision>
    <collision>
      <origin rpy="-3.14159 -0.21666 3.14158" xyz="-0.000572389 -8.47362e-07 0.000580713"/>
      <geometry>
        <cylinder length="0.00509453184408" radius="0.0124149630608"/>
      </geometry>
    </collision>
    <collision>
      <origin rpy="-3.14159 -0.21666 3.14158" xyz="-0.00111997 -8.45255e-07 -0.001907"/>
      <geometry>
        <sphere radius="0.0124149630608"/>
      </geometry>
    </collision>
  </link>
  <link name="right_hand_k">
    <inertial>
      <mass value="0.03"/>
      <inertia ixx="0.00001" ixy="0.0" ixz="0.0" iyy="0.00001" iyz="0.0" izz="0.00001"/>
    </inertial>
    <visual>
      <geometry>
        <mesh filename="meshes/schunk_hand/f21.dae"/>
      </geometry>
    </visual>
    <collision>
      <origin rpy="-1.57078 1.56262 -1.5626" xyz="0.000329902 0.000681478 -7.15399e-09"/>
      <geometry>
        <sphere radius="0.0103423075683"/>
      </geometry>
    </collision>
    <collision>
      <origin rpy="-1.57078 1.56262 -1.5626" xyz="0.025073 0.000883872 -4.18943e-09"/>
      <geometry>
        <cylinder length="0.0494877939213" radius="0.0103423075683"/>
      </geometry>
    </collision>
    <collision>
      <origin rpy="-1.57078 1.56262 -1.5626" xyz="0.049816 0.00108627 -1.22488e-09"/>
      <geometry>
        <sphere radius="0.0103423075683"/>
      </geometry>
    </collision>
  </link>
  <link name="right_hand_o">
    <!--xacro:dummy_inertial /-->
    <inertial>
      <mass value="0.05"/>
      <origin rpy="0 1.57 0" xyz="0.016 0 0"/>
      <inertia ixx="7.79478854875e-06" ixy="0.0" ixz="0.0" iyy="7.79478854875e-06" iyz="0.0" izz="2.25625e-06"/>
    </inertial>
    <visual>
      <geometry>
        <mesh filename="meshes/schunk_hand/f22.dae"/>
      </geometry>
    </visual>
    <collision>
      <origin rpy="-1.5708 1.56927 -1.56927" xyz="-3.30221e-05 1.09516e-05 8.53407e-19"/>
      <geometry>
        <sphere radius="0.0109921488052"/>
      </geometry>
    </collision>
    <collision>
      <origin rpy="-1.5708 1.56927 -1.56927" xyz="0.0148204 3.363e-05 1.37822e-18"/>
      <geometry>
        <cylinder length="0.0297069326601" radius="0.0109921488052"/>
      </geometry>
    </collision>
    <collision>
      <origin rpy="-1.5708 1.56927 -1.56927" xyz="0.0296739 5.63084e-05 1.90304e-18"/>
      <geometry>
        <sphere radius="0.0109921488052"/>
      </geometry>
    </collision>
  </link>
  <link name="right_hand_s">
    <!--xacro:dummy_inertial /-->
    <inertial>
      <mass value="0.03"/>
      <origin rpy="0 1.57 0" xyz="0.008 0 0"/>
      <inertia ixx="2.439999024e-06" ixy="0.0" ixz="0.0" iyy="2.439999024e-06" iyz="0.0" izz="9.6e-07"/>
    </inertial>
    <visual>
      <geometry>
        <mesh filename="meshes/schunk_hand/f23.dae"/>
      </geometry>
    </visual>
    <collision>
      <origin rpy="-1.5708 1.5644 -1.5644" xyz="0.00111375 3.07691e-05 -1.75721e-18"/>
      <geometry>
        <sphere radius="0.00858541498434"/>
      </geometry>
    </collision>
    <collision>
      <origin rpy="-1.5708 1.5644 -1.5644" xyz="0.00750196 7.16119e-05 2.84644e-19"/>
      <geometry>
        <cylinder length="0.0127766757058" radius="0.00858541498434"/>
      </geometry>
    </collision>
    <collision>
      <origin rpy="-1.5708 1.5644 -1.5644" xyz="0.0138902 0.000112455 2.3265e-18"/>
      <geometry>
        <sphere radius="0.00858541498434"/>
      </geometry>
    </collision>
  </link>
  <link name="right_hand_middle_tip_ee">
    <inertial>
      <origin rpy="0 0 0" xyz="0 0 0"/>
      <mass value="0"/>
      <inertia ixx="0.0" ixy="0.0" ixz="0.0" iyy="0.0" iyz="0.0" izz="0.0"/>
    </inertial>
  </link> <!-- in pybullet, the inertia need to be specified even for dummy links, otherwise it will put an identity inertia and a mass of 1 by default -->
  <joint name="right_hand_middle_tip_joint" type="fixed">
    <parent link="right_hand_s"/>
    <child link="right_hand_middle_tip_ee"/>
    <origin rpy="0 0 0" xyz="0.012 0.007 0.0"/>
  </joint>
  <!-- RING FINGER LINKS -->
  <link name="right_hand_virtual_j">
    <inertial>
      <mass value="0.03"/>
      <inertia ixx="0.00001" ixy="0.0" ixz="0.0" iyy="0.00001" iyz="0.0" izz="0.00001"/>
    </inertial>
    <visual>
      <origin xyz="0 0 -0.01321"/>
      <geometry>
        <mesh filename="meshes/schunk_hand/f30.dae"/>
      </geometry>
    </visual>
    <collision>
      <origin rpy="5.49177e-08 -0.215196 -5.93196e-09" xyz="2.78542e-05 3.86086e-05 -0.0030288"/>
      <geometry>
        <sphere radius="0.0124140277083"/>
      </geometry>
    </collision>
    <collision>
      <origin rpy="5.49177e-08 -0.215196 -5.93196e-09" xyz="-0.000514205 3.86085e-05 -0.000548897"/>
      <geometry>
        <cylinder length="0.00507690493408" radius="0.0124140277083"/>
      </geometry>
    </collision>
    <collision>
      <origin rpy="5.49177e-08 -0.215196 -5.93196e-09" xyz="-0.00105626 3.86083e-05 0.00193101"/>
      <geometry>
        <sphere radius="0.0124140277083"/>
      </geometry>
    </collision>
  </link>
  <link name="right_hand_j">
    <inertial>
      <mass value="0.03"/>
      <inertia ixx="0.00001" ixy="0.0" ixz="0.0" iyy="0.00001" iyz="0.0" izz="0.00001"/>
    </inertial>
    <visual>
      <geometry>
        <mesh filename="meshes/schunk_hand/f31.dae"/>
      </geometry>
    </visual>
    <collision>
      <origin rpy="1.5708 1.52508 1.52508" xyz="-0.00092978 0.00119932 2.49389e-09"/>
      <geometry>
        <sphere radius="0.010523390341"/>
      </geometry>
    </collision>
    <collision>
      <origin rpy="1.5708 1.52508 1.52508" xyz="0.0239238 6.23222e-05 -2.50296e-09"/>
      <geometry>
        <cylinder length="0.0497591540656" radius="0.010523390341"/>
      </geometry>
    </collision>
    <collision>
      <origin rpy="1.5708 1.52508 1.52508" xyz="0.0487774 -0.00107468 -7.49981e-09"/>
      <geometry>
        <sphere radius="0.010523390341"/>
      </geometry>
    </collision>
  </link>
  <link name="right_hand_n">
    <inertial>
      <mass value="0.05"/>
      <origin rpy="0 1.57 0" xyz="0.016 0 0"/>
      <inertia ixx="8.47812160875e-06" ixy="0.0" ixz="0.0" iyy="8.47812160875e-06" iyz="0.0" izz="2.25625e-06"/>
    </inertial>
    <visual>
      <geometry>
        <mesh filename="meshes/schunk_hand/f32.dae"/>
      </geometry>
    </visual>
    <collision>
      <origin rpy="-1.5708 1.5692 -1.5692" xyz="-1.93421e-05 5.57259e-06 7.00794e-20"/>
      <geometry>
        <sphere radius="0.0109911462183"/>
      </geometry>
    </collision>
    <collision>
      <origin rpy="-1.5708 1.5692 -1.5692" xyz="0.014822 2.92925e-05 2.03475e-19"/>
      <geometry>
        <cylinder length="0.0296826647281" radius="0.0109911462183"/>
      </geometry>
    </collision>
    <collision>
      <origin rpy="-1.5708 1.5692 -1.5692" xyz="0.0296633 5.30125e-05 3.3687e-19"/>
      <geometry>
        <sphere radius="0.0109911462183"/>
      </geometry>
    </collision>
  </link>
  <link name="right_hand_r">
    <inertial>
      <mass value="0.03"/>
      <origin rpy="0 1.57 0" xyz="0.008 0 0"/>
      <inertia ixx="2.439999024e-06" ixy="0.0" ixz="0.0" iyy="2.439999024e-06" iyz="0.0" izz="9.6e-07"/>
    </inertial>
    <visual>
      <geometry>
        <mesh filename="meshes/schunk_hand/f33.dae"/>
      </geometry>
    </visual>
    <collision>
      <origin rpy="-1.5708 1.57043 -1.57043" xyz="0.00109315 6.51512e-05 -1.52904e-16"/>
      <geometry>
        <sphere radius="0.00856929639647"/>
      </geometry>
    </collision>
    <collision>
      <origin rpy="-1.5708 1.57043 -1.57043" xyz="0.00749768 6.74823e-05 -1.88397e-17"/>
      <geometry>
        <cylinder length="0.0128090602606" radius="0.00856929639647"/>
      </geometry>
    </collision>
    <collision>
      <origin rpy="-1.5708 1.57043 -1.57043" xyz="0.0139022 6.98134e-05 1.15224e-16"/>
      <geometry>
        <sphere radius="0.00856929639647"/>
      </geometry>
    </collision>
  </link>
  <link name="right_hand_ring_tip_ee">
    <inertial>
      <origin rpy="0 0 0" xyz="0 0 0"/>
      <mass value="0"/>
      <inertia ixx="0.0" ixy="0.0" ixz="0.0" iyy="0.0" iyz="0.0" izz="0.0"/>
    </inertial>
  </link> <!-- in pybullet, the inertia need to be specified even for dummy links, otherwise it will put an identity inertia and a mass of 1 by default -->
  <joint name="right_hand_ring_tip_joint" type="fixed">
    <parent link="right_hand_r"/>
    <child link="right_hand_ring_tip_ee"/>
    <origin rpy="0 0 0" xyz="0.012 0.007 0.0"/>
  </joint>
  <!-- LITTLE FINGER LINKS -->
  <link name="right_hand_virtual_i">
    <inertial>
      <mass value="0.03"/>
      <inertia ixx="0.00001" ixy="0.0" ixz="0.0" iyy="0.00001" iyz="0.0" izz="0.00001"/>
    </inertial>
    <visual>
      <origin xyz="0 0 -0.01321"/>
      <geometry>
        <mesh filename="meshes/schunk_hand/f40.dae"/>
      </geometry>
    </visual>
    <collision>
      <origin rpy="1.62648e-07 -0.223705 -1.82689e-08" xyz="-7.87181e-06 4.4169e-06 -0.00303052"/>
      <geometry>
        <sphere radius="0.0123918487645"/>
      </geometry>
    </collision>
    <collision>
      <origin rpy="1.62648e-07 -0.223705 -1.82689e-08" xyz="-0.000579472 4.4165e-06 -0.000518133"/>
      <geometry>
        <cylinder length="0.00515318354012" radius="0.0123918487645"/>
      </geometry>
    </collision>
    <collision>
      <origin rpy="1.62648e-07 -0.223705 -1.82689e-08" xyz="-0.00115107 4.41609e-06 0.00199426"/>
      <geometry>
        <sphere radius="0.0123918487645"/>
      </geometry>
    </collision>
  </link>
  <link name="right_hand_i">
    <inertial>
      <mass value="0.03"/>
      <inertia ixx="0.00001" ixy="0.0" ixz="0.0" iyy="0.00001" iyz="0.0" izz="0.00001"/>
    </inertial>
    <visual>
      <geometry>
        <mesh filename="meshes/schunk_hand/f41.dae"/>
      </geometry>
    </visual>
    <collision>
      <origin rpy="1.57078 1.54144 1.54142" xyz="-0.000481662 0.00135926 -6.99986e-09"/>
      <geometry>
        <sphere radius="0.0105526202063"/>
      </geometry>
    </collision>
    <collision>
      <origin rpy="1.57078 1.54144 1.54142" xyz="0.021353 0.000718 6.59159e-10"/>
      <geometry>
        <cylinder length="0.0436881600922" radius="0.0105526202063"/>
      </geometry>
    </collision>
    <collision>
      <origin rpy="1.57078 1.54144 1.54142" xyz="0.0431877 7.67402e-05 8.31818e-09"/>
      <geometry>
        <sphere radius="0.0105526202063"/>
      </geometry>
    </collision>
  </link>
  <link name="right_hand_m">
    <!--xacro:dummy_inertial /-->
    <inertial>
      <mass value="0.05"/>
      <origin rpy="0 1.57 0" xyz="0.016 0 0"/>
      <inertia ixx="5.39478950875e-06" ixy="0.0" ixz="0.0" iyy="5.39478950875e-06" iyz="0.0" izz="2.25625e-06"/>
    </inertial>
    <visual>
      <geometry>
        <mesh filename="meshes/schunk_hand/f42.dae"/>
      </geometry>
    </visual>
    <collision>
      <origin rpy="-1.5708 1.56905 -1.56905" xyz="1.74585e-06 -2.21286e-06 7.25811e-19"/>
      <geometry>
        <sphere radius="0.011141281998"/>
      </geometry>
    </collision>
    <collision>
      <origin rpy="-1.5708 1.56905 -1.56905" xyz="0.00978733 1.48637e-05 -6.73016e-18"/>
      <geometry>
        <cylinder length="0.0195712007882" radius="0.011141281998"/>
      </geometry>
    </collision>
    <collision>
      <origin rpy="-1.5708 1.56905 -1.56905" xyz="0.0195729 3.19402e-05 -1.41861e-17"/>
      <geometry>
        <sphere radius="0.011141281998"/>
      </geometry>
    </collision>
  </link>
  <link name="right_hand_q">
    <!--xacro:dummy_inertial /-->
    <inertial>
      <mass value="0.03"/>
      <origin rpy="0 1.57 0" xyz="0.008 0 0"/>
      <inertia ixx="2.439999024e-06" ixy="0.0" ixz="0.0" iyy="2.439999024e-06" iyz="0.0" izz="9.6e-07"/>
    </inertial>
    <visual>
      <geometry>
        <mesh filename="meshes/schunk_hand/f43.dae"/>
      </geometry>
    </visual>
    <collision>
      <origin rpy="-1.5708 1.57062 -1.57062" xyz="0.00111873 6.04446e-05 5.35122e-17"/>
      <geometry>
        <sphere radius="0.00857885551647"/>
      </geometry>
    </collision>
    <collision>
      <origin rpy="-1.5708 1.57062 -1.57062" xyz="0.00751342 6.15983e-05 7.63387e-18"/>
      <geometry>
        <cylinder length="0.0127893791599" radius="0.00857885551647"/>
      </geometry>
    </collision>
    <collision>
      <origin rpy="-1.5708 1.57062 -1.57062" xyz="0.0139081 6.27521e-05 -3.82445e-17"/>
      <geometry>
        <sphere radius="0.00857885551647"/>
      </geometry>
    </collision>
  </link>
  <link name="right_hand_pinky_tip_ee">
    <inertial>
      <origin rpy="0 0 0" xyz="0 0 0"/>
      <mass value="0"/>
      <inertia ixx="0.0" ixy="0.0" ixz="0.0" iyy="0.0" iyz="0.0" izz="0.0"/>
    </inertial>
  </link> <!-- in pybullet, the inertia need to be specified even for dummy links, otherwise it will put an identity inertia and a mass of 1 by default -->
  <joint name="right_hand_pinky_tip_joint" type="fixed">
    <parent link="right_hand_q"/>
    <child link="right_hand_pinky_tip_ee"/>
    <origin rpy="0 0 0" xyz="0.012 0.007 0.0"/>
  </joint>
  <joint name="right_hand_Thumb_Flexion" type="revolute">
    <parent link="right_hand_virtual_a"/>
    <child link="right_hand_a"/>
    <limit effort="1000.0" lower="0.0" upper="0.9704" velocity="1"/>
    <origin rpy="0 0 -0.9704" xyz="0 0 0"/>
    <axis xyz="0 0 1"/>
  </joint>
  <transmission name="right_hand_Thumb_Flexion_transmission">
    <type>transmission_interface/SimpleTransmission</type>
    <joint name="right_hand_Thumb_Flexion">
      <hardwareInterface>hardware_interface/EffortJointInterface</hardwareInterface>
    </joint>
    <actuator name="motor_right_hand_Thumb_Flexion">
      <mechanicalReduction>1</mechanicalReduction>
      <hardwareInterface>hardware_interface/EffortJointInterface</hardwareInterface>
    </actuator>
  </transmission>
  <!--transmission name="${name}_Thumb_Flexion_transmission">
            <type>transmission_interface/SimpleTransmission</type>
            <joint name="${name}_Thumb_Flexion">
                <hardwareInterface>hardware_interface/EffortJointInterface</hardwareInterface>
            </joint>
            <actuator name="motor_${name}_Thumb_Flexion">
                <mechanicalReduction>1</mechanicalReduction>
                <hardwareInterface>hardware_interface/EffortJointInterface</hardwareInterface>
            </actuator>
        </transmission-->
  <joint name="right_hand_Thumb_Helper" type="fixed">
    <!--limit effort="1000" upper="0" lower="0" velocity="1"/-->
    <parent link="right_hand_z"/>
    <child link="right_hand_virtual_a"/>
    <origin rpy="0 -1.5707 3.1416" xyz="0 0 0.04596"/>
  </joint>
  <!-- BASE_LINE JOINTS -->
  <joint name="right_hand_Thumb_Opposition" type="revolute">
    <parent link="right_hand_e1"/>
    <child link="right_hand_z"/>
    <limit effort="1000.0" lower="0.0" upper="0.9879" velocity="1"/>
    <origin rpy="0 0.2618 1.571" xyz="-0.0169 0.02626 0"/>
    <axis xyz="0 0 -1"/>
  </joint>
  <transmission name="right_hand_Thumb_Opposition_transmission">
    <type>transmission_interface/SimpleTransmission</type>
    <joint name="right_hand_Thumb_Opposition">
      <hardwareInterface>hardware_interface/EffortJointInterface</hardwareInterface>
    </joint>
    <actuator name="motor_right_hand_Thumb_Opposition">
      <mechanicalReduction>1</mechanicalReduction>
      <hardwareInterface>hardware_interface/EffortJointInterface</hardwareInterface>
    </actuator>
  </transmission>
  <!-- JOINT NOT FOR BASE_LINE. BUT WRITTEN DOWN HERE FOR BETTER UX -->
  <joint name="right_hand_f1" type="fixed">
    <!--limit effort="1000" upper="0" lower="0" velocity="1"/-->
    <parent link="right_hand_e1"/>
    <child link="right_hand_d"/>
    <origin rpy="0 0 0" xyz="0 0 0"/>
  </joint>
  <joint name="right_hand_f2" type="fixed">
    <!--limit effort="1000" upper="0" lower="0" velocity="1"/-->
    <parent link="right_hand_d"/>
    <child link="right_hand_h"/>
    <origin rpy="0 0 0" xyz="0 0 0"/>
  </joint>
  <joint name="right_hand_f3" type="fixed">
    <!--limit effort="1000" upper="0" lower="0" velocity="1"/-->
    <parent link="right_hand_h"/>
    <child link="right_hand_d2"/>
    <origin rpy="0 0 0" xyz="0 0 0"/>
  </joint>
  <joint name="right_hand_f4" type="fixed">
    <!--limit effort="1000" upper="0" lower="0" velocity="1"/-->
    <parent link="right_hand_base_link"/>
    <child link="right_hand_e1"/>
    <origin rpy="0 0 0" xyz="0 -0.01313 0"/>
  </joint>
  <joint name="right_hand_j5" type="revolute">
    <parent link="right_hand_e1"/>
    <child link="right_hand_e2"/>
    <limit effort="1000.0" lower="0.0" upper="0.98786" velocity="1"/>
    <origin rpy="0 0 0" xyz="0.0184 0.006 0.0375"/>
    <axis xyz="0 0 1"/>
    <mimic joint="right_hand_Thumb_Opposition" multiplier="1" offset="0"/>
  </joint>
  <transmission name="right_hand_j5_transmission">
    <type>transmission_interface/SimpleTransmission</type>
    <joint name="right_hand_j5">
      <hardwareInterface>hardware_interface/EffortJointInterface</hardwareInterface>
    </joint>
    <actuator name="motor_right_hand_j5">
      <mechanicalReduction>1</mechanicalReduction>
      <hardwareInterface>hardware_interface/EffortJointInterface</hardwareInterface>
    </actuator>
  </transmission>
  <joint name="right_hand_f5" type="fixed">
    <!--limit effort="1000" upper="0" lower="0" velocity="1"/-->
    <parent link="right_hand_e2"/>
    <child link="right_hand_e3"/>
    <origin rpy="0 0 0" xyz="0 -0.0060 0"/>
  </joint>
  <joint name="right_hand_f6" type="fixed">
    <!--limit effort="1000" upper="0" lower="0" velocity="1"/-->
    <parent link="right_hand_e3"/>
    <child link="right_hand_e"/>
    <origin rpy="0 0 0" xyz="0 0 0"/>
  </joint>
  <joint name="right_hand_f7" type="fixed">
    <!--limit effort="1000" upper="0" lower="0" velocity="1"/-->
    <parent link="right_hand_e"/>
    <child link="right_hand_e4"/>
    <origin rpy="0 0 0" xyz="0 0 0"/>
  </joint>
  <joint name="right_hand_f8" type="fixed">
    <!--limit effort="1000" upper="0" lower="0" velocity="1"/-->
    <parent link="right_hand_e"/>
    <child link="right_hand_e5"/>
    <origin rpy="0 0 0" xyz="0 0 0"/>
  </joint>
  <!-- THUMB JOINTS -->
  <joint name="right_hand_j3" type="revolute">
    <parent link="right_hand_a"/>
    <child link="right_hand_b"/>
    <limit effort="1000.0" lower="0.0" upper="0.98506" velocity="1"/>
    <origin rpy="0 0 0" xyz="0.0485 0 0"/>
    <axis xyz="0 0 1"/>
    <mimic joint="right_hand_Thumb_Flexion" multiplier="1.01511" offset="0"/>
  </joint>
  <transmission name="right_hand_j3_transmission">
    <type>transmission_interface/SimpleTransmission</type>
    <joint name="right_hand_j3">
      <hardwareInterface>hardware_interface/EffortJointInterface</hardwareInterface>
    </joint>
    <actuator name="motor_right_hand_j3">
      <mechanicalReduction>1</mechanicalReduction>
      <hardwareInterface>hardware_interface/EffortJointInterface</hardwareInterface>
    </actuator>
  </transmission>
  <joint name="right_hand_j4" type="revolute">
    <parent link="right_hand_b"/>
    <child link="right_hand_c"/>
    <limit effort="1000.0" lower="0.0" upper="1.406" velocity="1"/>
    <origin rpy="0 0 0" xyz="0.030 0 0"/>
    <axis xyz="0 0 1"/>
    <mimic joint="right_hand_Thumb_Flexion" multiplier="1.44889" offset="0"/>
  </joint>
  <transmission name="right_hand_j4_transmission">
    <type>transmission_interface/SimpleTransmission</type>
    <joint name="right_hand_j4">
      <hardwareInterface>hardware_interface/EffortJointInterface</hardwareInterface>
    </joint>
    <actuator name="motor_right_hand_j4">
      <mechanicalReduction>1</mechanicalReduction>
      <hardwareInterface>hardware_interface/EffortJointInterface</hardwareInterface>
    </actuator>
  </transmission>
  <!-- INDEX FINGER JOINTS -->
  <joint name="right_hand_Index_Finger_Distal" type="revolute">
    <parent link="right_hand_l"/>
    <child link="right_hand_p"/>
    <limit effort="1000.0" lower="0" upper="1.334" velocity="1"/>
    <origin rpy="0 0 0" xyz="0.04804 0 0"/>
    <axis xyz="0 0 1"/>
  </joint>
  <transmission name="right_hand_Index_Finger_Distal_transmission">
    <type>transmission_interface/SimpleTransmission</type>
    <joint name="right_hand_Index_Finger_Distal">
      <hardwareInterface>hardware_interface/EffortJointInterface</hardwareInterface>
    </joint>
    <actuator name="motor_right_hand_Index_Finger_Distal">
      <mechanicalReduction>1</mechanicalReduction>
      <hardwareInterface>hardware_interface/EffortJointInterface</hardwareInterface>
    </actuator>
  </transmission>
  <joint name="right_hand_Index_Finger_Proximal" type="revolute">
    <parent link="right_hand_virtual_l"/>
    <child link="right_hand_l"/>
    <limit effort="1000.0" lower="0.0" upper="0.79849" velocity="1"/>
    <origin rpy="-1.5707 0 0" xyz="0 0 0"/>
    <axis xyz="0 0 1"/>
  </joint>
  <transmission name="right_hand_Index_Finger_Proximal_transmission">
    <type>transmission_interface/SimpleTransmission</type>
    <joint name="right_hand_Index_Finger_Proximal">
      <hardwareInterface>hardware_interface/EffortJointInterface</hardwareInterface>
    </joint>
    <actuator name="motor_right_hand_Index_Finger_Proximal">
      <mechanicalReduction>1</mechanicalReduction>
      <hardwareInterface>hardware_interface/EffortJointInterface</hardwareInterface>
    </actuator>
  </transmission>
  <!-- JOINT Finger_Spread in BASE_LINE section for better UX -->
  <joint name="right_hand_j14" type="revolute">
    <parent link="right_hand_p"/>
    <child link="right_hand_t"/>
    <limit effort="1000.0" lower="0" upper="1.394" velocity="1"/>
    <origin rpy="0 0 0" xyz="0.026 0 0"/>
    <axis xyz="0 0 1"/>
    <mimic joint="right_hand_Index_Finger_Distal" multiplier="1.0450" offset="0"/>
  </joint>
  <transmission name="right_hand_j14_transmission">
    <type>transmission_interface/SimpleTransmission</type>
    <joint name="right_hand_j14">
      <hardwareInterface>hardware_interface/EffortJointInterface</hardwareInterface>
    </joint>
    <actuator name="motor_right_hand_j14">
      <mechanicalReduction>1</mechanicalReduction>
      <hardwareInterface>hardware_interface/EffortJointInterface</hardwareInterface>
    </actuator>
  </transmission>
  <!-- MIDDLE FINGER JOINTS -->
  <joint name="right_hand_Middle_Finger_Proximal" type="revolute">
    <parent link="right_hand_virtual_k"/>
    <child link="right_hand_k"/>
    <limit effort="1000.0" lower="0.0" upper="0.79849" velocity="1"/>
    <origin rpy="-1.5707 0 0" xyz="0 0 0"/>
    <axis xyz="0 0 1"/>
  </joint>
  <transmission name="right_hand_Middle_Finger_Proximal_transmission">
    <type>transmission_interface/SimpleTransmission</type>
    <joint name="right_hand_Middle_Finger_Proximal">
      <hardwareInterface>hardware_interface/EffortJointInterface</hardwareInterface>
    </joint>
    <actuator name="motor_right_hand_Middle_Finger_Proximal">
      <mechanicalReduction>1</mechanicalReduction>
      <hardwareInterface>hardware_interface/EffortJointInterface</hardwareInterface>
    </actuator>
  </transmission>
  <joint name="right_hand_Middle_Finger_Distal" type="revolute">
    <parent link="right_hand_k"/>
    <child link="right_hand_o"/>
    <limit effort="1000.0" lower="0" upper="1.334" velocity="1"/>
    <origin rpy="0 0 0" xyz="0.05004 0 0"/>
    <axis xyz="0 0 1"/>
  </joint>
  <transmission name="right_hand_Middle_Finger_Distal_transmission">
    <type>transmission_interface/SimpleTransmission</type>
    <joint name="right_hand_Middle_Finger_Distal">
      <hardwareInterface>hardware_interface/EffortJointInterface</hardwareInterface>
    </joint>
    <actuator name="motor_right_hand_Middle_Finger_Distal">
      <mechanicalReduction>1</mechanicalReduction>
      <hardwareInterface>hardware_interface/EffortJointInterface</hardwareInterface>
    </actuator>
  </transmission>
  <joint name="right_hand_j15" type="revolute">
    <parent link="right_hand_o"/>
    <child link="right_hand_s"/>
    <limit effort="1000.0" lower="0" upper="1.334" velocity="1"/>
    <origin rpy="0 0 0" xyz="0.032 0 0"/>
    <axis xyz="0 0 1"/>
    <mimic joint="right_hand_Middle_Finger_Distal" multiplier="1.0454" offset="0"/>
  </joint>
  <transmission name="right_hand_j15_transmission">
    <type>transmission_interface/SimpleTransmission</type>
    <joint name="right_hand_j15">
      <hardwareInterface>hardware_interface/EffortJointInterface</hardwareInterface>
    </joint>
    <actuator name="motor_right_hand_j15">
      <mechanicalReduction>1</mechanicalReduction>
      <hardwareInterface>hardware_interface/EffortJointInterface</hardwareInterface>
    </actuator>
  </transmission>
  <!-- RING FINGER JOINTS -->
  <joint name="right_hand_Ring_Finger" type="revolute">
    <parent link="right_hand_virtual_j"/>
    <child link="right_hand_j"/>
    <limit effort="1000.0" lower="0.0" upper="0.98175" velocity="1"/>
    <origin rpy="1.5707 0 0" xyz="0 0 0"/>
    <axis xyz="0 0 1"/>
  </joint>
  <transmission name="right_hand_Ring_Finger_transmission">
    <type>transmission_interface/SimpleTransmission</type>
    <joint name="right_hand_Ring_Finger">
      <hardwareInterface>hardware_interface/EffortJointInterface</hardwareInterface>
    </joint>
    <actuator name="motor_right_hand_Ring_Finger">
      <mechanicalReduction>1</mechanicalReduction>
      <hardwareInterface>hardware_interface/EffortJointInterface</hardwareInterface>
    </actuator>
  </transmission>
  <joint name="right_hand_j12" type="revolute">
    <parent link="right_hand_j"/>
    <child link="right_hand_n"/>
    <limit effort="1000.0" lower="0" upper="1.334" velocity="1"/>
    <origin rpy="0 0 0" xyz="0.05004 0 0"/>
    <axis xyz="0 0 1"/>
    <mimic joint="right_hand_Ring_Finger" multiplier="1.3588" offset="0"/>
  </joint>
  <transmission name="right_hand_j12_transmission">
    <type>transmission_interface/SimpleTransmission</type>
    <joint name="right_hand_j12">
      <hardwareInterface>hardware_interface/EffortJointInterface</hardwareInterface>
    </joint>
    <actuator name="motor_right_hand_j12">
      <mechanicalReduction>1</mechanicalReduction>
      <hardwareInterface>hardware_interface/EffortJointInterface</hardwareInterface>
    </actuator>
  </transmission>
  <joint name="right_hand_j16" type="revolute">
    <parent link="right_hand_n"/>
    <child link="right_hand_r"/>
    <limit effort="1000.0" lower="0" upper="1.395" velocity="1"/>
    <origin rpy="0 0 0" xyz="0.032 0 0"/>
    <axis xyz="0 0 1"/>
    <mimic joint="right_hand_Ring_Finger" multiplier="1.42093" offset="0"/>
  </joint>
  <transmission name="right_hand_j16_transmission">
    <type>transmission_interface/SimpleTransmission</type>
    <joint name="right_hand_j16">
      <hardwareInterface>hardware_interface/EffortJointInterface</hardwareInterface>
    </joint>
    <actuator name="motor_right_hand_j16">
      <mechanicalReduction>1</mechanicalReduction>
      <hardwareInterface>hardware_interface/EffortJointInterface</hardwareInterface>
    </actuator>
  </transmission>
  <!-- PINKY JOINTS -->
  <joint name="right_hand_Pinky" type="revolute">
    <parent link="right_hand_virtual_i"/>
    <child link="right_hand_i"/>
    <limit effort="1000.0" lower="0.0" upper="0.98175" velocity="1"/>
    <origin rpy="1.5707 0 0" xyz="0 0 0"/>
    <axis xyz="0 0 1"/>
  </joint>
  <transmission name="right_hand_Pinky_transmission">
    <type>transmission_interface/SimpleTransmission</type>
    <joint name="right_hand_Pinky">
      <hardwareInterface>hardware_interface/EffortJointInterface</hardwareInterface>
    </joint>
    <actuator name="motor_right_hand_Pinky">
      <mechanicalReduction>1</mechanicalReduction>
      <hardwareInterface>hardware_interface/EffortJointInterface</hardwareInterface>
    </actuator>
  </transmission>
  <joint name="right_hand_j13" type="revolute">
    <parent link="right_hand_i"/>
    <child link="right_hand_m"/>
    <limit effort="1000.0" lower="0" upper="1.334" velocity="1"/>
    <origin rpy="0 0 0" xyz="0.04454 0 0"/>
    <axis xyz="0 0 1"/>
    <mimic joint="right_hand_Pinky" multiplier="1.35880" offset="0"/>
  </joint>
  <transmission name="right_hand_j13_transmission">
    <type>transmission_interface/SimpleTransmission</type>
    <joint name="right_hand_j13">
      <hardwareInterface>hardware_interface/EffortJointInterface</hardwareInterface>
    </joint>
    <actuator name="motor_right_hand_j13">
      <mechanicalReduction>1</mechanicalReduction>
      <hardwareInterface>hardware_interface/EffortJointInterface</hardwareInterface>
    </actuator>
  </transmission>
  <joint name="right_hand_j17" type="revolute">
    <parent link="right_hand_m"/>
    <child link="right_hand_q"/>
    <limit effort="1000.0" lower="0" upper="1.3971" velocity="1"/>
    <origin rpy="0 0 0" xyz="0.022 0 0"/>
    <axis xyz="0 0 1"/>
    <mimic joint="right_hand_Pinky" multiplier="1.42307" offset="0"/>
  </joint>
  <transmission name="right_hand_j17_transmission">
    <type>transmission_interface/SimpleTransmission</type>
    <joint name="right_hand_j17">
      <hardwareInterface>hardware_interface/EffortJointInterface</hardwareInterface>
    </joint>
    <actuator name="motor_right_hand_j17">
      <mechanicalReduction>1</mechanicalReduction>
      <hardwareInterface>hardware_interface/EffortJointInterface</hardwareInterface>
    </actuator>
  </transmission>
  <joint name="right_hand_index_spread" type="revolute">
    <parent link="right_hand_d2"/>
    <child link="right_hand_virtual_l"/>
    <limit effort="1000.0" lower="0.0" upper="0.28833" velocity="1"/>
    <origin rpy="0 -1.5707 1.5707" xyz="-0.025 0 0.110"/>
    <axis xyz="0 0 1"/>
    <mimic joint="right_hand_Finger_Spread" multiplier="0.5" offset="0"/>
  </joint>
  <transmission name="right_hand_index_spread_transmission">
    <type>transmission_interface/SimpleTransmission</type>
    <joint name="right_hand_index_spread">
      <hardwareInterface>hardware_interface/EffortJointInterface</hardwareInterface>
    </joint>
    <actuator name="motor_right_hand_index_spread">
      <mechanicalReduction>1</mechanicalReduction>
      <hardwareInterface>hardware_interface/EffortJointInterface</hardwareInterface>
    </actuator>
  </transmission>
  <joint name="right_hand_middle_spread_dummy" type="fixed">
    <!--limit effort="1000" upper="0" lower="0" velocity="1"/-->
    <parent link="right_hand_d"/>
    <child link="right_hand_virtual_k"/>
    <origin rpy="0 -1.5707 1.5707" xyz="0 0 0.110"/>
  </joint>
  <joint name="right_hand_ring_spread" type="revolute">
    <parent link="right_hand_e5"/>
    <child link="right_hand_virtual_j"/>
    <limit effort="1000.0" lower="0.0" upper="0.28833" velocity="1"/>
    <origin rpy="-1.5707 -1.5707 0" xyz="0.003855 0 0.0655"/>
    <axis xyz="0 0 1"/>
    <mimic joint="right_hand_Finger_Spread" multiplier="0.5" offset="0"/>
  </joint>
  <transmission name="right_hand_ring_spread_transmission">
    <type>transmission_interface/SimpleTransmission</type>
    <joint name="right_hand_ring_spread">
      <hardwareInterface>hardware_interface/EffortJointInterface</hardwareInterface>
    </joint>
    <actuator name="motor_right_hand_ring_spread">
      <mechanicalReduction>1</mechanicalReduction>
      <hardwareInterface>hardware_interface/EffortJointInterface</hardwareInterface>
    </actuator>
  </transmission>
  <joint name="right_hand_Finger_Spread" type="revolute">
    <parent link="right_hand_e4"/>
    <child link="right_hand_virtual_i"/>
    <limit effort="1000.0" lower="0.00" upper="0.5829" velocity="1"/>
    <origin rpy="-1.5707 -1.5707 0" xyz="0.025355 0 0.056"/>
    <axis xyz="0 0 1"/>
  </joint>
  <transmission name="right_hand_Finger_Spread_transmission">
    <type>transmission_interface/SimpleTransmission</type>
    <joint name="right_hand_Finger_Spread">
      <hardwareInterface>hardware_interface/EffortJointInterface</hardwareInterface>
    </joint>
    <actuator name="motor_right_hand_Finger_Spread">
      <mechanicalReduction>1</mechanicalReduction>
      <hardwareInterface>hardware_interface/EffortJointInterface</hardwareInterface>
    </actuator>
  </transmission>
  <gazebo reference="right_hand_c">
    <!--material>Gazebo/Blue</material-->
    <mu1>70</mu1>
    <mu2>70</mu2>
    <minDepth>0.001</minDepth>
    <!--maxVel>0.1</maxVel-->
    <kp>10000000.0</kp>
    <kd>100000.0</kd>
  </gazebo>
  <gazebo reference="right_hand_b">
    <!--material>Gazebo/Blue</material-->
    <mu1>70</mu1>
    <mu2>70</mu2>
    <minDepth>0.001</minDepth>
    <!--maxVel>0.1</maxVel-->
    <kp>10000000.0</kp>
    <kd>100000.0</kd>
  </gazebo>
  <gazebo reference="right_hand_a">
    <!--material>Gazebo/Blue</material-->
    <mu1>70</mu1>
    <mu2>70</mu2>
    <minDepth>0.001</minDepth>
    <!--maxVel>0.1</maxVel-->
    <kp>10000000.0</kp>
    <kd>100000.0</kd>
  </gazebo>
  <gazebo reference="right_hand_t">
    <!--material>Gazebo/Blue</material-->
    <mu1>70</mu1>
    <mu2>70</mu2>
    <minDepth>0.001</minDepth>
    <!--maxVel>0.1</maxVel-->
    <kp>10000000.0</kp>
    <kd>100000.0</kd>
  </gazebo>
  <gazebo reference="right_hand_p">
    <!--material>Gazebo/Blue</material-->
    <mu1>70</mu1>
    <mu2>70</mu2>
    <minDepth>0.001</minDepth>
    <!--maxVel>0.1</maxVel-->
    <kp>10000000.0</kp>
    <kd>100000.0</kd>
  </gazebo>
  <gazebo reference="right_hand_l">
    <!--material>Gazebo/Blue</material-->
    <mu1>70</mu1>
    <mu2>70</mu2>
    <minDepth>0.001</minDepth>
    <!--maxVel>0.1</maxVel-->
    <kp>10000000.0</kp>
    <kd>100000.0</kd>
  </gazebo>
  <gazebo reference="right_hand_s">
    <!--material>Gazebo/Blue</material-->
    <mu1>70</mu1>
    <mu2>70</mu2>
    <minDepth>0.001</minDepth>
    <!--maxVel>0.1</maxVel-->
    <kp>10000000.0</kp>
    <kd>100000.0</kd>
  </gazebo>
  <gazebo reference="right_hand_o">
    <!--material>Gazebo/Blue</material-->
    <mu1>70</mu1>
    <mu2>70</mu2>
    <minDepth>0.001</minDepth>
    <!--maxVel>0.1</maxVel-->
    <kp>10000000.0</kp>
    <kd>100000.0</kd>
  </gazebo>
  <gazebo reference="right_hand_k">
    <!--material>Gazebo/Blue</material-->
    <mu1>70</mu1>
    <mu2>70</mu2>
    <minDepth>0.001</minDepth>
    <!--maxVel>0.1</maxVel-->
    <kp>10000000.0</kp>
    <kd>100000.0</kd>
  </gazebo>
  <gazebo reference="right_hand_r">
    <!--material>Gazebo/Blue</material-->
    <mu1>70</mu1>
    <mu2>70</mu2>
    <minDepth>0.001</minDepth>
    <!--maxVel>0.1</maxVel-->
    <kp>10000000.0</kp>
    <kd>100000.0</kd>
  </gazebo>
  <gazebo reference="right_hand_n">
    <!--material>Gazebo/Blue</material-->
    <mu1>70</mu1>
    <mu2>70</mu2>
    <minDepth>0.001</minDepth>
    <!--maxVel>0.1</maxVel-->
    <kp>10000000.0</kp>
    <kd>100000.0</kd>
  </gazebo>
  <gazebo reference="right_hand_j">
    <!--material>Gazebo/Blue</material-->
    <mu1>70</mu1>
    <mu2>70</mu2>
    <minDepth>0.001</minDepth>
    <!--maxVel>0.1</maxVel-->
    <kp>10000000.0</kp>
    <kd>100000.0</kd>
  </gazebo>
  <gazebo reference="right_hand_q">
    <!--material>Gazebo/Blue</material-->
    <mu1>70</mu1>
    <mu2>70</mu2>
    <minDepth>0.001</minDepth>
    <!--maxVel>0.1</maxVel-->
    <kp>10000000.0</kp>
    <kd>100000.0</kd>
  </gazebo>
  <gazebo reference="right_hand_m">
    <!--material>Gazebo/Blue</material-->
    <mu1>70</mu1>
    <mu2>70</mu2>
    <minDepth>0.001</minDepth>
    <!--maxVel>0.1</maxVel-->
    <kp>10000000.0</kp>
    <kd>100000.0</kd>
  </gazebo>
  <gazebo reference="right_hand_i">
    <!--material>Gazebo/Blue</material-->
    <mu1>70</mu1>
    <mu2>70</mu2>
    <minDepth>0.001</minDepth>
    <!--maxVel>0.1</maxVel-->
    <kp>10000000.0</kp>
    <kd>100000.0</kd>
  </gazebo>
  <gazebo reference="right_hand_d">
    <!--material>Gazebo/Blue</material-->
    <mu1>70</mu1>
    <mu2>70</mu2>
    <minDepth>0.001</minDepth>
    <!--maxVel>0.1</maxVel-->
    <kp>10000000.0</kp>
    <kd>100000.0</kd>
  </gazebo>
  <!-- /end-effector -->
  <!-- /arms -->
  <link name="hip1_1">
    <inertial>
      <origin xyz="0.010214199 -0.018348359 0.038090987"/>
      <mass value="1.9194403"/>
      <!-- org: 2 -->
      <inertia ixx="0.0047439572" ixy="0.0005747047" ixz="-0.0003784138" iyy="0.0040551878" iyz="0.0007407508" izz="0.0034146219"/>
      <!-- <inertia ixx="0.01" ixy="0.01" ixz="0.01" iyy="0.01" iyz="0.01" izz="0.01"/> -->
    </inertial>
    <visual>
      <origin rpy="0.0 0.0 4.06442490005" xyz="0.0 0.0 0.0"/>
      <geometry>
        <mesh filename="meshes/simplified/hip-yaw.stl" scale="0.001 0.001 0.001"/>
      </geometry>
      <material name="dark_grey"/>
    </visual>
    <collision>
      <origin rpy="0.0 0.0 4.06442490005" xyz="0.0 0.0 0.0"/>
      <geometry>
        <mesh filename="meshes/convex_hull/hip-yaw.stl" scale="0.001 0.001 0.001"/>
      </geometry>
    </collision>
  </link>
  <link name="hip2_1">
    <inertial>
      <origin xyz="2.57966e-05 0.1810266 0.085669756"/>
      <mass value="2.7264471"/>
      <!-- org: 4.5 -->
      <inertia ixx="0.04851869" ixy="-4.11894e-05" ixz="-1.68778e-05" iyy="0.004242055" iyz="0.0032243188" izz="0.04825583"/>
      <!-- <inertia ixx="0.01" ixy="0.01" ixz="0.01" iyy="0.01" iyz="0.01" izz="0.01"/> -->
    </inertial>
    <visual>
      <origin rpy="0.0 0.0 0.0" xyz="0.0 0.0 0.0"/>
      <geometry>
        <mesh filename="meshes/simplified/hip-pitch.stl" scale="0.001 0.001 0.001"/>
      </geometry>
    </visual>
    <collision>
      <origin rpy="0.0 0.0 0.0" xyz="0.0 0.0 0.0"/>
      <geometry>
        <mesh filename="meshes/convex_hull/hip-pitch.stl" scale="0.001 0.001 0.001"/>
      </geometry>
    </collision>
  </link>
  <link name="knee_1">
    <inertial>
      <origin xyz="0.10881667 0.0001089081 -0.022638996"/>
      <mass value="1.9356754"/>
      <!-- org: 3.5, foot un modeled-->
      <inertia ixx="0.0030534242" ixy="-4.22079e-05" ixz="0.0013679297" iyy="0.019603321" iyz="6.9941e-06" izz="0.019849817"/>
      <!--	<inertia ixx="0.01" ixy="0.01" ixz="0.01" iyy="0.01" iyz="0.01" izz="0.01"/>  -->
    </inertial>
    <visual>
      <origin rpy="0.0 0.0 0.0" xyz="0.0 0.0 0.0"/>
      <geometry>
        <mesh filename="meshes/simplified/knee.stl" scale="0.001 0.001 0.001"/>
      </geometry>
      <material name="dark_grey"/>
    </visual>
    <collision>
      <origin rpy="0.0 0.0 0.0" xyz="0.0 0.0 0.0"/>
      <geometry>
        <mesh filename="meshes/convex_hull/knee.stl" scale="0.001 0.001 0.001"/>
      </geometry>
    </collision>
  </link>
  <link name="ankle1_1">
    <inertial>
      <origin xyz="0.032137318 9.73572e-05 -0.0044222206"/>
      <mass value="1.2380744"/>
      <!-- org: 3.5, foot un modeled-->
      <inertia ixx="0.0015610452" ixy="3.30597e-05" ixz="-0.0001314174" iyy="0.0037423211" iyz="-2.12589e-05" izz="0.0038312442"/>
      <!--	<inertia ixx="0.01" ixy="0.01" ixz="0.01" iyy="0.01" iyz="0.01" izz="0.01"/>  -->
    </inertial>
    <visual>
      <origin rpy="0.0 0.0 0.0" xyz="0.0 0.0 0.0"/>
      <geometry>
        <mesh filename="meshes/simplified/ankle-pitch.stl" scale="0.001 0.001 0.001"/>
      </geometry>
    </visual>
    <collision>
      <origin rpy="0.0 0.0 0.0" xyz="0.0 0.0 0.0"/>
      <geometry>
        <mesh filename="meshes/convex_hull/ankle-pitch.stl" scale="0.001 0.001 0.001"/>
      </geometry>
    </collision>
  </link>
  <link name="ankle2_1">
    <inertial>
      <origin xyz="0.0004435803 0.0004389911 0.19392092"/>
      <mass value="1.1565926"/>
      <!-- org: 3.5, foot un modeled-->
      <inertia ixx="0.0049019475" ixy="4.3032e-06" ixz="3.46491e-05" iyy="0.0038724162" iyz="1.7099e-05" izz="0.0021783198"/>
    </inertial>
    <visual>
      <origin rpy="0.0 0.0 0.0" xyz="0.0 0.0 0.0"/>
      <geometry>
        <mesh filename="meshes/simplified/ankle-yaw.stl" scale="0.001 0.001 0.001"/>
      </geometry>
      <material name="dark_grey"/>
    </visual>
    <collision>
      <origin rpy="0.0 0.0 0.0" xyz="0.0 0.0 0.0"/>
      <geometry>
        <mesh filename="meshes/convex_hull/ankle-yaw.stl" scale="0.001 0.001 0.001"/>
      </geometry>
    </collision>
  </link>
  <link name="wheel_1">
    <inertial>
      <origin xyz="0.0 0.0 0.0024271906"/>
      <mass value="1.7289003"/>
      <!-- org: 3.5, foot un modeled-->
      <inertia ixx="0.0046864297" ixy="0.0" ixz="0.0" iyy="0.0046713489" iyz="0.0" izz="0.0053126029"/>
    </inertial>
    <visual>
      <origin rpy="0.0 0.0 0.0" xyz="0.0 0.0 0.0"/>
      <geometry>
        <mesh filename="meshes/simplified/wheel.stl" scale="0.001 0.001 0.001"/>
      </geometry>
      <material name="black"/>
    </visual>
    <collision>
      <origin rpy="0.0 0.0 0.0" xyz="0.0 0.0 0.0"/>
      <geometry>
        <mesh filename="meshes/convex_hull/wheel.stl" scale="0.001 0.001 0.001"/>
      </geometry>
    </collision>
  </link>
  <joint name="hip_yaw_1" type="revolute">
    <parent link="pelvis"/>
    <child link="hip1_1"/>
    <origin rpy="3.14159265359 0.0 0.461416123228" xyz="0.25 0.125 -0.0566"/>
    <axis xyz="0 0 1"/>
    <limit effort="304" lower="-0.9432" upper="2.5138" velocity="8.8"/>
  </joint>
  <joint name="hip_pitch_1" type="revolute">
    <parent link="hip1_1"/>
    <child link="hip2_1"/>
    <origin rpy="1.57079632679 0.0 0.46141612323" xyz="0.0 0.0 0.0625"/>
    <axis xyz="0 0 1"/>
    <limit effort="304" lower="-2.0226" upper="2.02748" velocity="8.8"/>
  </joint>
  <joint name="knee_pitch_1" type="revolute">
    <parent link="hip2_1"/>
    <child link="knee_1"/>
    <origin rpy="3.14159265359 0.0 1.57079632679" xyz="0.0 0.3 -0.0036"/>
    <axis xyz="0 0 1"/>
    <limit effort="304" lower="-2.4056" upper="2.3994" velocity="8.8"/>
  </joint>
  <joint name="ankle_pitch_1" type="revolute">
    <parent link="knee_1"/>
    <child link="ankle1_1"/>
    <origin rpy="3.14159265359 0.0 0.0" xyz="0.2 0.0 -0.10015"/>
    <axis xyz="0 0 1"/>
    <limit effort="147" lower="-2.4056" upper="2.3184" velocity="8.1"/>
  </joint>
  <joint name="ankle_yaw_1" type="revolute">
    <parent link="ankle1_1"/>
    <child link="ankle2_1"/>
    <origin rpy="1.57079632679 0.0 1.57079632679" xyz="0.0 0.0 0.0"/>
    <axis xyz="0 0 1"/>
    <limit effort="35" lower="-2.5626" upper="2.5384" velocity="20.0"/>
  </joint>
  <joint name="j_wheel_1" type="continuous">
    <parent link="ankle2_1"/>
    <child link="wheel_1"/>
    <origin rpy="1.57079632679 0.0 3.14159265359" xyz="0.0 0.00085 0.23735"/>
    <axis xyz="0 0 -1"/>
    <limit effort="35" velocity="20.0"/>
  </joint>
  <transmission name="t_hip_yaw_1">
    <type> transmission_interface/SimpleTransmission</type>
    <joint name="hip_yaw_1">
      <hardwareInterface>hardware_interface/EffortJointInterface</hardwareInterface>
    </joint>
    <actuator name="motor_hip_yaw_1">
      <hardwareInterface>hardware_interface/EffortJointInterface</hardwareInterface>
      <machanicalReduction>1</machanicalReduction>
    </actuator>
    <robotNamespace>/centauro</robotNamespace>
  </transmission>
  <transmission name="t_hip_pitch_1">
    <type> transmission_interface/SimpleTransmission</type>
    <joint name="hip_pitch_1">
      <hardwareInterface>hardware_interface/EffortJointInterface</hardwareInterface>
    </joint>
    <actuator name="motor_hip_pitch_1">
      <hardwareInterface>hardware_interface/EffortJointInterface</hardwareInterface>
      <machanicalReduction>1</machanicalReduction>
    </actuator>
    <robotNamespace>/centauro</robotNamespace>
  </transmission>
  <transmission name="t_knee_pitch_1">
    <type> transmission_interface/SimpleTransmission</type>
    <joint name="knee_pitch_1">
      <hardwareInterface>hardware_interface/EffortJointInterface</hardwareInterface>
    </joint>
    <actuator name="motor_knee_pitch_1">
      <hardwareInterface>hardware_interface/EffortJointInterface</hardwareInterface>
      <machanicalReduction>1</machanicalReduction>
    </actuator>
    <robotNamespace>/centauro</robotNamespace>
  </transmission>
  <transmission name="t_ankle_pitch_1">
    <type> transmission_interface/SimpleTransmission</type>
    <joint name="ankle_pitch_1">
      <hardwareInterface>hardware_interface/EffortJointInterface</hardwareInterface>
    </joint>
    <actuator name="motor_ankle_pitch_1">
      <hardwareInterface>hardware_interface/EffortJointInterface</hardwareInterface>
      <machanicalReduction>1</machanicalReduction>
    </actuator>
    <robotNamespace>/centauro</robotNamespace>
  </transmission>
  <transmission name="t_ankle_yaw_1">
    <type> transmission_interface/SimpleTransmission</type>
    <joint name="ankle_yaw_1">
      <hardwareInterface>hardware_interface/EffortJointInterface</hardwareInterface>
    </joint>
    <actuator name="motor_ankle_yaw_1">
      <hardwareInterface>hardware_interface/EffortJointInterface</hardwareInterface>
      <machanicalReduction>1</machanicalReduction>
    </actuator>
    <robotNamespace>/centauro</robotNamespace>
  </transmission>
  <transmission name="t_j_wheel_1">
    <type> transmission_interface/SimpleTransmission</type>
    <joint name="j_wheel_1">
      <hardwareInterface>hardware_interface/EffortJointInterface</hardwareInterface>
    </joint>
    <actuator name="motor_j_wheel_1">
      <hardwareInterface>hardware_interface/EffortJointInterface</hardwareInterface>
      <machanicalReduction>1</machanicalReduction>
    </actuator>
    <robotNamespace>/centauro</robotNamespace>
  </transmission>
  <!-- /actuators -->
  <link name="hip1_2">
    <inertial>
      <origin xyz="0.010214199 0.018348359 0.038090987"/>
      <mass value="1.9194403"/>
      <!-- org: 2 -->
      <inertia ixx="0.0047439572" ixy="-0.0005747047" ixz="-0.0003784138" iyy="0.0040551878" iyz="-0.0007407508" izz="0.0034146219"/>
      <!-- <inertia ixx="0.01" ixy="0.01" ixz="0.01" iyy="0.01" iyz="0.01" izz="0.01"/> -->
    </inertial>
    <visual>
      <origin rpy="0.0 0.0 0.0" xyz="0.0 0.0 0.0"/>
      <geometry>
        <mesh filename="meshes/simplified/hip-yaw.stl" scale="0.001 0.001 0.001"/>
      </geometry>
      <material name="dark_grey"/>
    </visual>
    <collision>
      <origin rpy="0.0 0.0 0.0" xyz="0.0 0.0 0.0"/>
      <geometry>
        <mesh filename="meshes/convex_hull/hip-yaw.stl" scale="0.001 0.001 0.001"/>
      </geometry>
    </collision>
  </link>
  <link name="hip2_2">
    <inertial>
      <origin xyz="2.57966e-05 0.1810266 0.085669756"/>
      <mass value="2.7264471"/>
      <!-- org: 4.5 -->
      <inertia ixx="0.04851869" ixy="-4.11894e-05" ixz="-1.68778e-05" iyy="0.004242055" iyz="0.0032243188" izz="0.04825583"/>
      <!-- <inertia ixx="0.01" ixy="0.01" ixz="0.01" iyy="0.01" iyz="0.01" izz="0.01"/> -->
    </inertial>
    <visual>
      <origin rpy="0.0 0.0 0.0" xyz="0.0 0.0 0.0"/>
      <geometry>
        <mesh filename="meshes/simplified/hip-pitch.stl" scale="0.001 0.001 0.001"/>
      </geometry>
    </visual>
    <collision>
      <origin rpy="0.0 0.0 0.0" xyz="0.0 0.0 0.0"/>
      <geometry>
        <mesh filename="meshes/convex_hull/hip-pitch.stl" scale="0.001 0.001 0.001"/>
      </geometry>
    </collision>
  </link>
  <link name="knee_2">
    <inertial>
      <origin xyz="0.10881667 0.0001089081 -0.022638996"/>
      <mass value="1.9356754"/>
      <!-- org: 3.5, foot un modeled-->
      <inertia ixx="0.0030534242" ixy="-4.22079e-05" ixz="0.0013679297" iyy="0.019603321" iyz="6.9941e-06" izz="0.019849817"/>
      <!--	<inertia ixx="0.01" ixy="0.01" ixz="0.01" iyy="0.01" iyz="0.01" izz="0.01"/>  -->
    </inertial>
    <visual>
      <origin rpy="0.0 0.0 0.0" xyz="0.0 0.0 0.0"/>
      <geometry>
        <mesh filename="meshes/simplified/knee.stl" scale="0.001 0.001 0.001"/>
      </geometry>
      <material name="dark_grey"/>
    </visual>
    <collision>
      <origin rpy="0.0 0.0 0.0" xyz="0.0 0.0 0.0"/>
      <geometry>
        <mesh filename="meshes/convex_hull/knee.stl" scale="0.001 0.001 0.001"/>
      </geometry>
    </collision>
  </link>
  <link name="ankle1_2">
    <inertial>
      <origin xyz="0.032137318 9.73572e-05 -0.0044222206"/>
      <mass value="1.2380744"/>
      <!-- org: 3.5, foot un modeled-->
      <inertia ixx="0.0015610452" ixy="3.30597e-05" ixz="-0.0001314174" iyy="0.0037423211" iyz="-2.12589e-05" izz="0.0038312442"/>
      <!--	<inertia ixx="0.01" ixy="0.01" ixz="0.01" iyy="0.01" iyz="0.01" izz="0.01"/>  -->
    </inertial>
    <visual>
      <origin rpy="0.0 0.0 0.0" xyz="0.0 0.0 0.0"/>
      <geometry>
        <mesh filename="meshes/simplified/ankle-pitch.stl" scale="0.001 0.001 0.001"/>
      </geometry>
    </visual>
    <collision>
      <origin rpy="0.0 0.0 0.0" xyz="0.0 0.0 0.0"/>
      <geometry>
        <mesh filename="meshes/convex_hull/ankle-pitch.stl" scale="0.001 0.001 0.001"/>
      </geometry>
    </collision>
  </link>
  <link name="ankle2_2">
    <inertial>
      <origin xyz="0.0004435803 0.0004389911 0.19392092"/>
      <mass value="1.1565926"/>
      <!-- org: 3.5, foot un modeled-->
      <inertia ixx="0.0049019475" ixy="4.3032e-06" ixz="3.46491e-05" iyy="0.0038724162" iyz="1.7099e-05" izz="0.0021783198"/>
    </inertial>
    <visual>
      <origin rpy="0.0 0.0 0.0" xyz="0.0 0.0 0.0"/>
      <geometry>
        <mesh filename="meshes/simplified/ankle-yaw.stl" scale="0.001 0.001 0.001"/>
      </geometry>
      <material name="dark_grey"/>
    </visual>
    <collision>
      <origin rpy="0.0 0.0 0.0" xyz="0.0 0.0 0.0"/>
      <geometry>
        <mesh filename="meshes/convex_hull/ankle-yaw.stl" scale="0.001 0.001 0.001"/>
      </geometry>
    </collision>
  </link>
  <link name="wheel_2">
    <inertial>
      <origin xyz="0.0 0.0 0.0024271906"/>
      <mass value="1.7289003"/>
      <!-- org: 3.5, foot un modeled-->
      <inertia ixx="0.0046864297" ixy="0.0" ixz="0.0" iyy="0.0046713489" iyz="0.0" izz="0.0053126029"/>
    </inertial>
    <visual>
      <origin rpy="0.0 0.0 0.0" xyz="0.0 0.0 0.0"/>
      <geometry>
        <mesh filename="meshes/simplified/wheel.stl" scale="0.001 0.001 0.001"/>
      </geometry>
      <material name="black"/>
    </visual>
    <collision>
      <origin rpy="0.0 0.0 0.0" xyz="0.0 0.0 0.0"/>
      <geometry>
        <mesh filename="meshes/convex_hull/wheel.stl" scale="0.001 0.001 0.001"/>
      </geometry>
    </collision>
  </link>
  <joint name="hip_yaw_2" type="revolute">
    <parent link="pelvis"/>
    <child link="hip1_2"/>
    <origin rpy="3.14159265359 0.0 -0.461416123228" xyz="0.25 -0.125 -0.0566"/>
    <axis xyz="0 0 1"/>
    <limit effort="304" lower="-2.511" upper="0.943" velocity="8.8"/>
  </joint>
  <joint name="hip_pitch_2" type="revolute">
    <parent link="hip1_2"/>
    <child link="hip2_2"/>
    <origin rpy="1.57079632679 0.0 2.68017653036" xyz="0.0 0.0 0.0625"/>
    <axis xyz="0 0 1"/>
    <limit effort="304" lower="-2.0156" upper="2.0354" velocity="8.8"/>
  </joint>
  <joint name="knee_pitch_2" type="revolute">
    <parent link="hip2_2"/>
    <child link="knee_2"/>
    <origin rpy="3.14159265359 0.0 1.57079632679" xyz="0.0 0.3 -0.0036"/>
    <axis xyz="0 0 1"/>
    <limit effort="304" lower="-2.4006" upper="2.4034" velocity="8.8"/>
  </joint>
  <joint name="ankle_pitch_2" type="revolute">
    <parent link="knee_2"/>
    <child link="ankle1_2"/>
    <origin rpy="3.14159265359 0.0 0.0" xyz="0.2 0.0 -0.10015"/>
    <axis xyz="0 0 1"/>
    <limit effort="147" lower="-2.3266" upper="2.3914" velocity="8.1"/>
  </joint>
  <joint name="ankle_yaw_2" type="revolute">
    <parent link="ankle1_2"/>
    <child link="ankle2_2"/>
    <origin rpy="1.57079632679 0.0 1.57079632679" xyz="0.0 0.0 0.0"/>
    <axis xyz="0 0 1"/>
    <limit effort="35" lower="-2.5546" upper="2.5484" velocity="20.0"/>
  </joint>
  <joint name="j_wheel_2" type="continuous">
    <parent link="ankle2_2"/>
    <child link="wheel_2"/>
    <origin rpy="1.57079632679 0.0 3.14159265359" xyz="0.0 0.00085 0.23735"/>
    <axis xyz="0 0 -1"/>
    <limit effort="35" velocity="20.0"/>
  </joint>
  <transmission name="t_hip_yaw_2">
    <type> transmission_interface/SimpleTransmission</type>
    <joint name="hip_yaw_2">
      <hardwareInterface>hardware_interface/EffortJointInterface</hardwareInterface>
    </joint>
    <actuator name="motor_hip_yaw_2">
      <hardwareInterface>hardware_interface/EffortJointInterface</hardwareInterface>
      <machanicalReduction>1</machanicalReduction>
    </actuator>
    <robotNamespace>/centauro</robotNamespace>
  </transmission>
  <transmission name="t_hip_pitch_2">
    <type> transmission_interface/SimpleTransmission</type>
    <joint name="hip_pitch_2">
      <hardwareInterface>hardware_interface/EffortJointInterface</hardwareInterface>
    </joint>
    <actuator name="motor_hip_pitch_2">
      <hardwareInterface>hardware_interface/EffortJointInterface</hardwareInterface>
      <machanicalReduction>1</machanicalReduction>
    </actuator>
    <robotNamespace>/centauro</robotNamespace>
  </transmission>
  <transmission name="t_knee_pitch_2">
    <type> transmission_interface/SimpleTransmission</type>
    <joint name="knee_pitch_2">
      <hardwareInterface>hardware_interface/EffortJointInterface</hardwareInterface>
    </joint>
    <actuator name="motor_knee_pitch_2">
      <hardwareInterface>hardware_interface/EffortJointInterface</hardwareInterface>
      <machanicalReduction>1</machanicalReduction>
    </actuator>
    <robotNamespace>/centauro</robotNamespace>
  </transmission>
  <transmission name="t_ankle_pitch_2">
    <type> transmission_interface/SimpleTransmission</type>
    <joint name="ankle_pitch_2">
      <hardwareInterface>hardware_interface/EffortJointInterface</hardwareInterface>
    </joint>
    <actuator name="motor_ankle_pitch_2">
      <hardwareInterface>hardware_interface/EffortJointInterface</hardwareInterface>
      <machanicalReduction>1</machanicalReduction>
    </actuator>
    <robotNamespace>/centauro</robotNamespace>
  </transmission>
  <transmission name="t_ankle_yaw_2">
    <type> transmission_interface/SimpleTransmission</type>
    <joint name="ankle_yaw_2">
      <hardwareInterface>hardware_interface/EffortJointInterface</hardwareInterface>
    </joint>
    <actuator name="motor_ankle_yaw_2">
      <hardwareInterface>hardware_interface/EffortJointInterface</hardwareInterface>
      <machanicalReduction>1</machanicalReduction>
    </actuator>
    <robotNamespace>/centauro</robotNamespace>
  </transmission>
  <transmission name="t_j_wheel_2">
    <type> transmission_interface/SimpleTransmission</type>
    <joint name="j_wheel_2">
      <hardwareInterface>hardware_interface/EffortJointInterface</hardwareInterface>
    </joint>
    <actuator name="motor_j_wheel_2">
      <hardwareInterface>hardware_interface/EffortJointInterface</hardwareInterface>
      <machanicalReduction>1</machanicalReduction>
    </actuator>
    <robotNamespace>/centauro</robotNamespace>
  </transmission>
  <!-- /actuators -->
  <link name="hip1_3">
    <inertial>
      <origin xyz="0.010214199 0.018348359 0.038090987"/>
      <mass value="1.9194403"/>
      <!-- org: 2 -->
      <inertia ixx="0.0047439572" ixy="-0.0005747047" ixz="-0.0003784138" iyy="0.0040551878" iyz="-0.0007407508" izz="0.0034146219"/>
      <!-- <inertia ixx="0.01" ixy="0.01" ixz="0.01" iyy="0.01" iyz="0.01" izz="0.01"/> -->
    </inertial>
    <visual>
      <origin rpy="0.0 0.0 0.0" xyz="0.0 0.0 0.0"/>
      <geometry>
        <mesh filename="meshes/simplified/hip-yaw.stl" scale="0.001 0.001 0.001"/>
      </geometry>
      <material name="dark_grey"/>
    </visual>
    <collision>
      <origin rpy="0.0 0.0 0.0" xyz="0.0 0.0 0.0"/>
      <geometry>
        <mesh filename="meshes/convex_hull/hip-yaw.stl" scale="0.001 0.001 0.001"/>
      </geometry>
    </collision>
  </link>
  <link name="hip2_3">
    <inertial>
      <origin xyz="2.57966e-05 0.1810266 0.085669756"/>
      <mass value="2.7264471"/>
      <!-- org: 4.5 -->
      <inertia ixx="0.04851869" ixy="-4.11894e-05" ixz="-1.68778e-05" iyy="0.004242055" iyz="0.0032243188" izz="0.04825583"/>
      <!-- <inertia ixx="0.01" ixy="0.01" ixz="0.01" iyy="0.01" iyz="0.01" izz="0.01"/> -->
    </inertial>
    <visual>
      <origin rpy="0.0 0.0 0.0" xyz="0.0 0.0 0.0"/>
      <geometry>
        <mesh filename="meshes/simplified/hip-pitch.stl" scale="0.001 0.001 0.001"/>
      </geometry>
    </visual>
    <collision>
      <origin rpy="0.0 0.0 0.0" xyz="0.0 0.0 0.0"/>
      <geometry>
        <mesh filename="meshes/convex_hull/hip-pitch.stl" scale="0.001 0.001 0.001"/>
      </geometry>
    </collision>
  </link>
  <link name="knee_3">
    <inertial>
      <origin xyz="0.10881667 0.0001089081 -0.022638996"/>
      <mass value="1.9356754"/>
      <!-- org: 3.5, foot un modeled-->
      <inertia ixx="0.0030534242" ixy="-4.22079e-05" ixz="0.0013679297" iyy="0.019603321" iyz="6.9941e-06" izz="0.019849817"/>
      <!--	<inertia ixx="0.01" ixy="0.01" ixz="0.01" iyy="0.01" iyz="0.01" izz="0.01"/>  -->
    </inertial>
    <visual>
      <origin rpy="0.0 0.0 0.0" xyz="0.0 0.0 0.0"/>
      <geometry>
        <mesh filename="meshes/simplified/knee.stl" scale="0.001 0.001 0.001"/>
      </geometry>
      <material name="dark_grey"/>
    </visual>
    <collision>
      <origin rpy="0.0 0.0 0.0" xyz="0.0 0.0 0.0"/>
      <geometry>
        <mesh filename="meshes/convex_hull/knee.stl" scale="0.001 0.001 0.001"/>
      </geometry>
    </collision>
  </link>
  <link name="ankle1_3">
    <inertial>
      <origin xyz="0.032137318 9.73572e-05 -0.0044222206"/>
      <mass value="1.2380744"/>
      <!-- org: 3.5, foot un modeled-->
      <inertia ixx="0.0015610452" ixy="3.30597e-05" ixz="-0.0001314174" iyy="0.0037423211" iyz="-2.12589e-05" izz="0.0038312442"/>
      <!--	<inertia ixx="0.01" ixy="0.01" ixz="0.01" iyy="0.01" iyz="0.01" izz="0.01"/>  -->
    </inertial>
    <visual>
      <origin rpy="0.0 0.0 0.0" xyz="0.0 0.0 0.0"/>
      <geometry>
        <mesh filename="meshes/simplified/ankle-pitch.stl" scale="0.001 0.001 0.001"/>
      </geometry>
    </visual>
    <collision>
      <origin rpy="0.0 0.0 0.0" xyz="0.0 0.0 0.0"/>
      <geometry>
        <mesh filename="meshes/convex_hull/ankle-pitch.stl" scale="0.001 0.001 0.001"/>
      </geometry>
    </collision>
  </link>
  <link name="ankle2_3">
    <inertial>
      <origin xyz="0.0004435803 0.0004389911 0.19392092"/>
      <mass value="1.1565926"/>
      <!-- org: 3.5, foot un modeled-->
      <inertia ixx="0.0049019475" ixy="4.3032e-06" ixz="3.46491e-05" iyy="0.0038724162" iyz="1.7099e-05" izz="0.0021783198"/>
    </inertial>
    <visual>
      <origin rpy="0.0 0.0 0.0" xyz="0.0 0.0 0.0"/>
      <geometry>
        <mesh filename="meshes/simplified/ankle-yaw.stl" scale="0.001 0.001 0.001"/>
      </geometry>
      <material name="dark_grey"/>
    </visual>
    <collision>
      <origin rpy="0.0 0.0 0.0" xyz="0.0 0.0 0.0"/>
      <geometry>
        <mesh filename="meshes/convex_hull/ankle-yaw.stl" scale="0.001 0.001 0.001"/>
      </geometry>
    </collision>
  </link>
  <link name="wheel_3">
    <inertial>
      <origin xyz="0.0 0.0 0.0024271906"/>
      <mass value="1.7289003"/>
      <!-- org: 3.5, foot un modeled-->
      <inertia ixx="0.0046864297" ixy="0.0" ixz="0.0" iyy="0.0046713489" iyz="0.0" izz="0.0053126029"/>
    </inertial>
    <visual>
      <origin rpy="0.0 0.0 0.0" xyz="0.0 0.0 0.0"/>
      <geometry>
        <mesh filename="meshes/simplified/wheel.stl" scale="0.001 0.001 0.001"/>
      </geometry>
      <material name="black"/>
    </visual>
    <collision>
      <origin rpy="0.0 0.0 0.0" xyz="0.0 0.0 0.0"/>
      <geometry>
        <mesh filename="meshes/convex_hull/wheel.stl" scale="0.001 0.001 0.001"/>
      </geometry>
    </collision>
  </link>
  <joint name="hip_yaw_3" type="revolute">
    <parent link="pelvis"/>
    <child link="hip1_3"/>
    <origin rpy="3.14159265359 0.0 2.68017653036" xyz="-0.25 0.125 -0.0566"/>
    <axis xyz="0 0 1"/>
    <limit effort="304" lower="-2.51" upper="0.943" velocity="8.8"/>
  </joint>
  <joint name="hip_pitch_3" type="revolute">
    <parent link="hip1_3"/>
    <child link="hip2_3"/>
    <origin rpy="1.57079632679 0.0 2.68017653036" xyz="0.0 0.0 0.0625"/>
    <axis xyz="0 0 1"/>
    <limit effort="304" lower="-2.0126" upper="2.0384" velocity="8.8"/>
  </joint>
  <joint name="knee_pitch_3" type="revolute">
    <parent link="hip2_3"/>
    <child link="knee_3"/>
    <origin rpy="3.14159265359 0.0 1.57079632679" xyz="0.0 0.3 -0.0036"/>
    <axis xyz="0 0 1"/>
    <limit effort="304" lower="-2.4056" upper="2.4064" velocity="8.8"/>
  </joint>
  <joint name="ankle_pitch_3" type="revolute">
    <parent link="knee_3"/>
    <child link="ankle1_3"/>
    <origin rpy="3.14159265359 0.0 0.0" xyz="0.2 0.0 -0.10015"/>
    <axis xyz="0 0 1"/>
    <limit effort="147" lower="-2.4696" upper="2.4464" velocity="8.1"/>
  </joint>
  <joint name="ankle_yaw_3" type="revolute">
    <parent link="ankle1_3"/>
    <child link="ankle2_3"/>
    <origin rpy="1.57079632679 0.0 1.57079632679" xyz="0.0 0.0 0.0"/>
    <axis xyz="0 0 1"/>
    <limit effort="35" lower="-2.5606" upper="2.5454" velocity="20.0"/>
  </joint>
  <joint name="j_wheel_3" type="continuous">
    <parent link="ankle2_3"/>
    <child link="wheel_3"/>
    <origin rpy="1.57079632679 0.0 3.14159265359" xyz="0.0 0.00085 0.23735"/>
    <axis xyz="0 0 -1"/>
    <limit effort="35" velocity="20.0"/>
  </joint>
  <transmission name="t_hip_yaw_3">
    <type> transmission_interface/SimpleTransmission</type>
    <joint name="hip_yaw_3">
      <hardwareInterface>hardware_interface/EffortJointInterface</hardwareInterface>
    </joint>
    <actuator name="motor_hip_yaw_3">
      <hardwareInterface>hardware_interface/EffortJointInterface</hardwareInterface>
      <machanicalReduction>1</machanicalReduction>
    </actuator>
    <robotNamespace>/centauro</robotNamespace>
  </transmission>
  <transmission name="t_hip_pitch_3">
    <type> transmission_interface/SimpleTransmission</type>
    <joint name="hip_pitch_3">
      <hardwareInterface>hardware_interface/EffortJointInterface</hardwareInterface>
    </joint>
    <actuator name="motor_hip_pitch_3">
      <hardwareInterface>hardware_interface/EffortJointInterface</hardwareInterface>
      <machanicalReduction>1</machanicalReduction>
    </actuator>
    <robotNamespace>/centauro</robotNamespace>
  </transmission>
  <transmission name="t_knee_pitch_3">
    <type> transmission_interface/SimpleTransmission</type>
    <joint name="knee_pitch_3">
      <hardwareInterface>hardware_interface/EffortJointInterface</hardwareInterface>
    </joint>
    <actuator name="motor_knee_pitch_3">
      <hardwareInterface>hardware_interface/EffortJointInterface</hardwareInterface>
      <machanicalReduction>1</machanicalReduction>
    </actuator>
    <robotNamespace>/centauro</robotNamespace>
  </transmission>
  <transmission name="t_ankle_pitch_3">
    <type> transmission_interface/SimpleTransmission</type>
    <joint name="ankle_pitch_3">
      <hardwareInterface>hardware_interface/EffortJointInterface</hardwareInterface>
    </joint>
    <actuator name="motor_ankle_pitch_3">
      <hardwareInterface>hardware_interface/EffortJointInterface</hardwareInterface>
      <machanicalReduction>1</machanicalReduction>
    </actuator>
    <robotNamespace>/centauro</robotNamespace>
  </transmission>
  <transmission name="t_ankle_yaw_3">
    <type> transmission_interface/SimpleTransmission</type>
    <joint name="ankle_yaw_3">
      <hardwareInterface>hardware_interface/EffortJointInterface</hardwareInterface>
    </joint>
    <actuator name="motor_ankle_yaw_3">
      <hardwareInterface>hardware_interface/EffortJointInterface</hardwareInterface>
      <machanicalReduction>1</machanicalReduction>
    </actuator>
    <robotNamespace>/centauro</robotNamespace>
  </transmission>
  <transmission name="t_j_wheel_3">
    <type> transmission_interface/SimpleTransmission</type>
    <joint name="j_wheel_3">
      <hardwareInterface>hardware_interface/EffortJointInterface</hardwareInterface>
    </joint>
    <actuator name="motor_j_wheel_3">
      <hardwareInterface>hardware_interface/EffortJointInterface</hardwareInterface>
      <machanicalReduction>1</machanicalReduction>
    </actuator>
    <robotNamespace>/centauro</robotNamespace>
  </transmission>
  <!-- /actuators -->
  <link name="hip1_4">
    <inertial>
      <origin xyz="0.010214199 -0.018348359 0.038090987"/>
      <mass value="1.9194403"/>
      <!-- org: 2 -->
      <inertia ixx="0.0047439572" ixy="0.0005747047" ixz="-0.0003784138" iyy="0.0040551878" iyz="0.0007407508" izz="0.0034146219"/>
      <!-- <inertia ixx="0.01" ixy="0.01" ixz="0.01" iyy="0.01" iyz="0.01" izz="0.01"/> -->
    </inertial>
    <visual>
      <origin rpy="0.0 0.0 4.06442490005" xyz="0.0 0.0 0.0"/>
      <geometry>
        <mesh filename="meshes/simplified/hip-yaw.stl" scale="0.001 0.001 0.001"/>
      </geometry>
      <material name="dark_grey"/>
    </visual>
    <collision>
      <origin rpy="0.0 0.0 4.06442490005" xyz="0.0 0.0 0.0"/>
      <geometry>
        <mesh filename="meshes/convex_hull/hip-yaw.stl" scale="0.001 0.001 0.001"/>
      </geometry>
    </collision>
  </link>
  <link name="hip2_4">
    <inertial>
      <origin xyz="2.57966e-05 0.1810266 0.085669756"/>
      <mass value="2.7264471"/>
      <!-- org: 4.5 -->
      <inertia ixx="0.04851869" ixy="-4.11894e-05" ixz="-1.68778e-05" iyy="0.004242055" iyz="0.0032243188" izz="0.04825583"/>
      <!-- <inertia ixx="0.01" ixy="0.01" ixz="0.01" iyy="0.01" iyz="0.01" izz="0.01"/> -->
    </inertial>
    <visual>
      <origin rpy="0.0 0.0 0.0" xyz="0.0 0.0 0.0"/>
      <geometry>
        <mesh filename="meshes/simplified/hip-pitch.stl" scale="0.001 0.001 0.001"/>
      </geometry>
    </visual>
    <collision>
      <origin rpy="0.0 0.0 0.0" xyz="0.0 0.0 0.0"/>
      <geometry>
        <mesh filename="meshes/convex_hull/hip-pitch.stl" scale="0.001 0.001 0.001"/>
      </geometry>
    </collision>
  </link>
  <link name="knee_4">
    <inertial>
      <origin xyz="0.10881667 0.0001089081 -0.022638996"/>
      <mass value="1.9356754"/>
      <!-- org: 3.5, foot un modeled-->
      <inertia ixx="0.0030534242" ixy="-4.22079e-05" ixz="0.0013679297" iyy="0.019603321" iyz="6.9941e-06" izz="0.019849817"/>
      <!--	<inertia ixx="0.01" ixy="0.01" ixz="0.01" iyy="0.01" iyz="0.01" izz="0.01"/>  -->
    </inertial>
    <visual>
      <origin rpy="0.0 0.0 0.0" xyz="0.0 0.0 0.0"/>
      <geometry>
        <mesh filename="meshes/simplified/knee.stl" scale="0.001 0.001 0.001"/>
      </geometry>
      <material name="dark_grey"/>
    </visual>
    <collision>
      <origin rpy="0.0 0.0 0.0" xyz="0.0 0.0 0.0"/>
      <geometry>
        <mesh filename="meshes/convex_hull/knee.stl" scale="0.001 0.001 0.001"/>
      </geometry>
    </collision>
  </link>
  <link name="ankle1_4">
    <inertial>
      <origin xyz="0.032137318 9.73572e-05 -0.0044222206"/>
      <mass value="1.2380744"/>
      <!-- org: 3.5, foot un modeled-->
      <inertia ixx="0.0015610452" ixy="3.30597e-05" ixz="-0.0001314174" iyy="0.0037423211" iyz="-2.12589e-05" izz="0.0038312442"/>
      <!--	<inertia ixx="0.01" ixy="0.01" ixz="0.01" iyy="0.01" iyz="0.01" izz="0.01"/>  -->
    </inertial>
    <visual>
      <origin rpy="0.0 0.0 0.0" xyz="0.0 0.0 0.0"/>
      <geometry>
        <mesh filename="meshes/simplified/ankle-pitch.stl" scale="0.001 0.001 0.001"/>
      </geometry>
    </visual>
    <collision>
      <origin rpy="0.0 0.0 0.0" xyz="0.0 0.0 0.0"/>
      <geometry>
        <mesh filename="meshes/convex_hull/ankle-pitch.stl" scale="0.001 0.001 0.001"/>
      </geometry>
    </collision>
  </link>
  <link name="ankle2_4">
    <inertial>
      <origin xyz="0.0004435803 0.0004389911 0.19392092"/>
      <mass value="1.1565926"/>
      <!-- org: 3.5, foot un modeled-->
      <inertia ixx="0.0049019475" ixy="4.3032e-06" ixz="3.46491e-05" iyy="0.0038724162" iyz="1.7099e-05" izz="0.0021783198"/>
    </inertial>
    <visual>
      <origin rpy="0.0 0.0 0.0" xyz="0.0 0.0 0.0"/>
      <geometry>
        <mesh filename="meshes/simplified/ankle-yaw.stl" scale="0.001 0.001 0.001"/>
      </geometry>
      <material name="dark_grey"/>
    </visual>
    <collision>
      <origin rpy="0.0 0.0 0.0" xyz="0.0 0.0 0.0"/>
      <geometry>
        <mesh filename="meshes/convex_hull/ankle-yaw.stl" scale="0.001 0.001 0.001"/>
      </geometry>
    </collision>
  </link>
  <link name="wheel_4">
    <inertial>
      <origin xyz="0.0 0.0 0.0024271906"/>
      <mass value="1.7289003"/>
      <!-- org: 3.5, foot un modeled-->
      <inertia ixx="0.0046864297" ixy="0.0" ixz="0.0" iyy="0.0046713489" iyz="0.0" izz="0.0053126029"/>
    </inertial>
    <visual>
      <origin rpy="0.0 0.0 0.0" xyz="0.0 0.0 0.0"/>
      <geometry>
        <mesh filename="meshes/simplified/wheel.stl" scale="0.001 0.001 0.001"/>
      </geometry>
      <material name="black"/>
    </visual>
    <collision>
      <origin rpy="0.0 0.0 0.0" xyz="0.0 0.0 0.0"/>
      <geometry>
        <mesh filename="meshes/convex_hull/wheel.stl" scale="0.001 0.001 0.001"/>
      </geometry>
    </collision>
  </link>
  <joint name="hip_yaw_4" type="revolute">
    <parent link="pelvis"/>
    <child link="hip1_4"/>
    <origin rpy="3.14159265359 0.0 3.60300877682" xyz="-0.25 -0.125 -0.0566"/>
    <axis xyz="0 0 1"/>
    <limit effort="304" lower="-0.9412" upper="2.5138" velocity="8.8"/>
  </joint>
  <joint name="hip_pitch_4" type="revolute">
    <parent link="hip1_4"/>
    <child link="hip2_4"/>
    <origin rpy="1.57079632679 0.0 0.46141612323" xyz="0.0 0.0 0.0625"/>
    <axis xyz="0 0 1"/>
    <limit effort="304" lower="-2.0326" upper="2.0524" velocity="8.8"/>
  </joint>
  <joint name="knee_pitch_4" type="revolute">
    <parent link="hip2_4"/>
    <child link="knee_4"/>
    <origin rpy="3.14159265359 0.0 1.57079632679" xyz="0.0 0.3 -0.0036"/>
    <axis xyz="0 0 1"/>
    <limit effort="304" lower="-2.4176" upper="2.3884" velocity="8.8"/>
  </joint>
  <joint name="ankle_pitch_4" type="revolute">
    <parent link="knee_4"/>
    <child link="ankle1_4"/>
    <origin rpy="3.14159265359 0.0 0.0" xyz="0.2 0.0 -0.10015"/>
    <axis xyz="0 0 1"/>
    <limit effort="147" lower="-2.3426" upper="2.3934" velocity="8.1"/>
  </joint>
  <joint name="ankle_yaw_4" type="revolute">
    <parent link="ankle1_4"/>
    <child link="ankle2_4"/>
    <origin rpy="1.57079632679 0.0 1.57079632679" xyz="0.0 0.0 0.0"/>
    <axis xyz="0 0 1"/>
    <limit effort="35" lower="-2.6046" upper="2.5514" velocity="20.0"/>
  </joint>
  <joint name="j_wheel_4" type="continuous">
    <parent link="ankle2_4"/>
    <child link="wheel_4"/>
    <origin rpy="1.57079632679 0.0 3.14159265359" xyz="0.0 0.00085 0.23735"/>
    <axis xyz="0 0 -1"/>
    <limit effort="35" velocity="20.0"/>
  </joint>
  <transmission name="t_hip_yaw_4">
    <type> transmission_interface/SimpleTransmission</type>
    <joint name="hip_yaw_4">
      <hardwareInterface>hardware_interface/EffortJointInterface</hardwareInterface>
    </joint>
    <actuator name="motor_hip_yaw_4">
      <hardwareInterface>hardware_interface/EffortJointInterface</hardwareInterface>
      <machanicalReduction>1</machanicalReduction>
    </actuator>
    <robotNamespace>/centauro</robotNamespace>
  </transmission>
  <transmission name="t_hip_pitch_4">
    <type> transmission_interface/SimpleTransmission</type>
    <joint name="hip_pitch_4">
      <hardwareInterface>hardware_interface/EffortJointInterface</hardwareInterface>
    </joint>
    <actuator name="motor_hip_pitch_4">
      <hardwareInterface>hardware_interface/EffortJointInterface</hardwareInterface>
      <machanicalReduction>1</machanicalReduction>
    </actuator>
    <robotNamespace>/centauro</robotNamespace>
  </transmission>
  <transmission name="t_knee_pitch_4">
    <type> transmission_interface/SimpleTransmission</type>
    <joint name="knee_pitch_4">
      <hardwareInterface>hardware_interface/EffortJointInterface</hardwareInterface>
    </joint>
    <actuator name="motor_knee_pitch_4">
      <hardwareInterface>hardware_interface/EffortJointInterface</hardwareInterface>
      <machanicalReduction>1</machanicalReduction>
    </actuator>
    <robotNamespace>/centauro</robotNamespace>
  </transmission>
  <transmission name="t_ankle_pitch_4">
    <type> transmission_interface/SimpleTransmission</type>
    <joint name="ankle_pitch_4">
      <hardwareInterface>hardware_interface/EffortJointInterface</hardwareInterface>
    </joint>
    <actuator name="motor_ankle_pitch_4">
      <hardwareInterface>hardware_interface/EffortJointInterface</hardwareInterface>
      <machanicalReduction>1</machanicalReduction>
    </actuator>
    <robotNamespace>/centauro</robotNamespace>
  </transmission>
  <transmission name="t_ankle_yaw_4">
    <type> transmission_interface/SimpleTransmission</type>
    <joint name="ankle_yaw_4">
      <hardwareInterface>hardware_interface/EffortJointInterface</hardwareInterface>
    </joint>
    <actuator name="motor_ankle_yaw_4">
      <hardwareInterface>hardware_interface/EffortJointInterface</hardwareInterface>
      <machanicalReduction>1</machanicalReduction>
    </actuator>
    <robotNamespace>/centauro</robotNamespace>
  </transmission>
  <transmission name="t_j_wheel_4">
    <type> transmission_interface/SimpleTransmission</type>
    <joint name="j_wheel_4">
      <hardwareInterface>hardware_interface/EffortJointInterface</hardwareInterface>
    </joint>
    <actuator name="motor_j_wheel_4">
      <hardwareInterface>hardware_interface/EffortJointInterface</hardwareInterface>
      <machanicalReduction>1</machanicalReduction>
    </actuator>
    <robotNamespace>/centauro</robotNamespace>
  </transmission>
  <!-- /actuators -->
  <!-- /legs -->
</robot>

