<?xml version="1.0" ?>
<!-- =================================================================================== -->
<!-- |    This document was autogenerated by xacro from centauro.urdf.xacro            | -->
<!-- |    EDITING THIS FILE BY HAND IS NOT RECOMMENDED                                 | -->
<!-- =================================================================================== -->
<robot name="schunk_hand" xmlns:xacro="http://www.ros.org/wiki/xacro">
  <!-- /constants -->
  <!-- Here all arguments from launch file are evaluated to the final xacro poropeties.
     Also all the parameter dependencies are resolved-->
  <!-- Here all arguments from launch file are evaluated to the final xacro poropeties.
     Also all the parameter dependencies are resolved-->
  <!-- Here all arguments from launch file are evaluated to the final xacro poropeties.
     Also all the parameter dependencies are resolved-->
  <!-- Here all arguments from launch file are evaluated to the final xacro poropeties.
     Also all the parameter dependencies are resolved-->

  <!-- All inertia values are dummy values, please change them with the real ones -->
  <!-- RIGHT HAND = 1, LEFT HAND = -1 -->
  <!-- BASE_LINE LINKS -->
  <link name="right_hand_camera_link">
    <inertial>
      <mass value="0.03"/>
      <inertia ixx="0.00001" ixy="0.0" ixz="0.0" iyy="0.00001" iyz="0.0" izz="0.00001"/>
    </inertial>
    <visual>
      <origin rpy="0 0 0" xyz="0 0 0"/>
      <geometry>
        <mesh filename="meshes/schunk_hand/camera_link.STL"/>
      </geometry>
    </visual>
    <collision>
      <origin rpy="0 0 0" xyz="0 0 0"/>
      <geometry>
        <mesh filename="meshes/schunk_hand/camera_link.STL"/>
      </geometry>
    </collision>
  </link>
  <!--joint name="right_hand_camera_joint" type="fixed">
    <origin rpy="3.14159265359 0 1.5707963268" xyz="0 0 -0.04"/>
    <parent link="arm2_7"/>
    <child link="right_hand_camera_link"/>
  </joint-->
  <joint name="right_hand_base_joint" type="fixed">
    <origin rpy="0 0 -1.5707963268" xyz="0 0 0.0495"/>
    <parent link="right_hand_camera_link"/>
    <child link="right_hand_base_link"/>
  </joint>
  <link name="right_hand_base_link">
    <inertial>
      <mass value="0.03"/>
      <inertia ixx="0.00001" ixy="0.0" ixz="0.0" iyy="0.00001" iyz="0.0" izz="0.00001"/>
    </inertial>
    <origin rpy="3.14159265359 0 1.5707963268" xyz="0 0 -0.04"/>
    <visual>
      <origin rpy="0 0 0" xyz="0 0 -0.032"/>
      <geometry>
        <mesh filename="meshes/schunk_hand/base10.dae"/>
      </geometry>
    </visual>
    <collision>
      <origin rpy="0 0 0" xyz="0 0 -0.032"/>
      <geometry>
        <mesh filename="meshes/schunk_hand/base10.dae"/>
      </geometry>
    </collision>
  </link>
  <link name="right_hand_d">
    <inertial>
      <mass value="0.03"/>
      <inertia ixx="0.00001" ixy="0.0" ixz="0.0" iyy="0.00001" iyz="0.0" izz="0.00001"/>
    </inertial>
  </link>
  <link name="right_hand_h">
    <inertial>
      <mass value="0.03"/>
      <inertia ixx="0.00001" ixy="0.0" ixz="0.0" iyy="0.00001" iyz="0.0" izz="0.00001"/>
    </inertial>
  </link>
  <link name="right_hand_d2">
    <inertial>
      <mass value="0.03"/>
      <inertia ixx="0.00001" ixy="0.0" ixz="0.0" iyy="0.00001" iyz="0.0" izz="0.00001"/>
    </inertial>
  </link>
  <!-- LENGTH NOT FOUND IN DATASHEET! GUESSED!!! -->
  <link name="right_hand_e1">
    <inertial>
      <mass value="0.03"/>
      <inertia ixx="0.00001" ixy="0.0" ixz="0.0" iyy="0.00001" iyz="0.0" izz="0.00001"/>
    </inertial>
    <visual>
      <origin rpy="0 0 0" xyz="0 0.01313 0"/>
      <geometry>
        <mesh filename="meshes/schunk_hand/h10.dae" scale="1 1 1"/>
      </geometry>
    </visual>
    <collision>
      <!--origin rpy="0 0 0" xyz="0 0.01313 0" /-->
      <origin rpy="0 0 0" xyz="-0.00368 0.0 0.06"/>
      <geometry>
        <box size="0.055 0.025 0.12"/>
        <!--mesh scale="${side*(1)} 1 1" filename="meshes/schunk_hand/h10.dae" /-->
      </geometry>
    </collision>
    <!--xacro:capsule-collision e1="0.01251 0.00157842 0.0928213" e2="-0.000462897 0.0155179 0.0150623" rad="0.035205530643540185" len="0.080056609487979907" rpy="-2.96421 -0.162765 1.48449" mid="0.00602356 0.00854815 0.0539418" /-->
  </link>
  <!-- LENGTH NOT FOUND IN DATASHEET! GUESSED!!! -->
  <link name="right_hand_e2">
    <inertial>
      <mass value="0.03"/>
      <inertia ixx="0.00001" ixy="0.0" ixz="0.0" iyy="0.00001" iyz="0.0" izz="0.00001"/>
    </inertial>
    <visual>
      <origin xyz="-0.0007 0 -0.01002"/>
      <geometry>
        <mesh filename="meshes/schunk_hand/h11.dae" scale="1 1 1"/>
      </geometry>
    </visual>
    <collision>
      <origin xyz="-0.0007 0 -0.01002"/>
      <geometry>
        <mesh filename="meshes/schunk_hand/h11.dae" scale="1 1 1"/>
      </geometry>
    </collision>
    <!--xacro:capsule-collision e1="-0.0130892 -0.00943485 0.0572708" e2="-0.00918653 -0.000238213 0.0052382" rad="0.025230241520476298" len="0.052982989614211572" rpy="-2.96665 0.0737258 -0.796187" mid="-0.0111379 -0.00483653 0.0312545" /-->
  </link>
  <!-- LENGTH NOT FOUND IN DATASHEET! GUESSED!!! -->
  <link name="right_hand_e3">
    <inertial>
      <mass value="0.03"/>
      <inertia ixx="0.00001" ixy="0.0" ixz="0.0" iyy="0.00001" iyz="0.0" izz="0.00001"/>
    </inertial>
    <!-- <visual> -->
    <!-- 	<origin rpy="0 0 0" xyz="${side*(0.0175)} 0 0.015" /> -->
    <!-- 	<geometry> -->
    <!-- 	  <cylinder length="0.03" radius="${cyl_radius}" /> -->
    <!-- 	</geometry> -->
    <!-- 	<material name="green" /> -->
    <!-- </visual> -->
  </link>
  <link name="right_hand_e">
    <inertial>
      <mass value="0.03"/>
      <inertia ixx="0.00001" ixy="0.0" ixz="0.0" iyy="0.00001" iyz="0.0" izz="0.00001"/>
    </inertial>
  </link>
  <!-- LENGTH NOT FOUND IN DATASHEET! GUESSED, BUT POSITION CALCULATED: E4 = D-G-F!!! -->
  <link name="right_hand_e4">
    <inertial>
      <mass value="0.03"/>
      <inertia ixx="0.00001" ixy="0.0" ixz="0.0" iyy="0.00001" iyz="0.0" izz="0.00001"/>
    </inertial>
    <!-- <visual> -->
    <!-- 	<origin rpy="0 0 0" xyz="${side*(0.02825)} 0 0.043" /> -->
    <!-- 	<geometry> -->
    <!-- 	  <cylinder length="0.026" radius="${cyl_radius}" /> -->
    <!-- 	</geometry> -->
    <!-- 	<material name="green" /> -->
    <!-- </visual> -->
  </link>
  <!-- LENGTH NOT FOUND IN DATASHEET! GUESSED, BUT POSITION CALCULATED: E5 = D-G!!! -->
  <link name="right_hand_e5">
    <inertial>
      <mass value="0.03"/>
      <inertia ixx="0.00001" ixy="0.0" ixz="0.0" iyy="0.00001" iyz="0.0" izz="0.00001"/>
    </inertial>
    <!-- <visual> -->
    <!-- 	<origin rpy="0 0 0" xyz="${side*(0.00675)} 0 0.04775" /> -->
    <!-- 	<geometry> -->
    <!-- 	  <cylinder length="0.0355" radius="${cyl_radius}" /> -->
    <!-- 	</geometry> -->
    <!-- 	<material name="green" /> -->
    <!-- </visual> -->
  </link>
  <!-- THUMB LINKS -->
  <link name="right_hand_z">
    <inertial>
      <mass value="0.03"/>
      <inertia ixx="0.00001" ixy="0.0" ixz="0.0" iyy="0.00001" iyz="0.0" izz="0.00001"/>
    </inertial>
    <visual>
      <origin xyz="0 0 0.02442"/>
      <geometry>
        <mesh filename="meshes/schunk_hand/d10.dae" scale="1 1 1"/>
      </geometry>
    </visual>
    <collision>
      <origin rpy="2.9985 8.56161e-08 1.19461e-06" xyz="4.35903e-09 0.00135239 0.0513426"/>
      <geometry>
        <sphere radius="0.0187964403536"/>
      </geometry>
    </collision>
    <collision>
      <origin rpy="2.9985 8.56161e-08 1.19461e-06" xyz="4.8053e-09 0.000609069 0.0461834"/>
      <geometry>
        <cylinder length="0.0104248181037" radius="0.0187964403536"/>
      </geometry>
    </collision>
    <collision>
      <origin rpy="2.9985 8.56161e-08 1.19461e-06" xyz="5.25157e-09 -0.000134248 0.0410243"/>
      <geometry>
        <sphere radius="0.0187964403536"/>
      </geometry>
    </collision>
  </link>
  <link name="right_hand_virtual_a">
    <inertial>
      <mass value="0.03"/>
      <inertia ixx="0.00001" ixy="0.0" ixz="0.0" iyy="0.00001" iyz="0.0" izz="0.00001"/>
    </inertial>
  </link>
  <link name="right_hand_a">
    <inertial>
      <mass value="0.03"/>
      <inertia ixx="0.00001" ixy="0.0" ixz="0.0" iyy="0.00001" iyz="0.0" izz="0.00001"/>
    </inertial>
    <visual>
      <geometry>
        <mesh filename="meshes/schunk_hand/d11.dae" scale="1 1 1"/>
      </geometry>
    </visual>
    <collision>
      <origin rpy="-1.57079 1.53946 -1.53946" xyz="-0.000196701 -0.00148458 -1.94634e-05"/>
      <geometry>
        <sphere radius="0.0167591808589"/>
      </geometry>
    </collision>
    <collision>
      <origin rpy="-1.57079 1.53946 -1.53946" xyz="0.0234125 -0.000744623 -1.94586e-05"/>
      <geometry>
        <cylinder length="0.0472415416058" radius="0.0167591808589"/>
      </geometry>
    </collision>
    <collision>
      <origin rpy="-1.57079 1.53946 -1.53946" xyz="0.0470217 -4.66742e-06 -1.94537e-05"/>
      <geometry>
        <sphere radius="0.0167591808589"/>
      </geometry>
    </collision>
  </link>
  <link name="right_hand_b">
    <inertial>
      <mass value="0.03"/>
      <inertia ixx="0.00001" ixy="0.0" ixz="0.0" iyy="0.00001" iyz="0.0" izz="0.00001"/>
    </inertial>
    <visual>
      <geometry>
        <mesh filename="meshes/schunk_hand/d12.dae" scale="1 1 1"/>
      </geometry>
    </visual>
    <collision>
      <origin rpy="1.56836 1.57067 1.56823" xyz="1.38494e-05 -5.84793e-06 2.67358e-06"/>
      <geometry>
        <sphere radius="0.0157927296103"/>
      </geometry>
    </collision>
    <collision>
      <origin rpy="1.56836 1.57067 1.56823" xyz="0.0115211 -7.34551e-06 2.67722e-06"/>
      <geometry>
        <cylinder length="0.0230145255328" radius="0.0157927296103"/>
      </geometry>
    </collision>
    <collision>
      <origin rpy="1.56836 1.57067 1.56823" xyz="0.0230284 -8.84308e-06 2.68087e-06"/>
      <geometry>
        <sphere radius="0.0157927296103"/>
      </geometry>
    </collision>
  </link>
  <link name="right_hand_c">
    <inertial>
      <mass value="0.03"/>
      <inertia ixx="0.00001" ixy="0.0" ixz="0.0" iyy="0.00001" iyz="0.0" izz="0.00001"/>
    </inertial>
    <visual>
      <geometry>
        <mesh filename="meshes/schunk_hand/d13.dae" scale="1 1 1"/>
      </geometry>
    </visual>
    <collision>
      <origin rpy="1.5708 1.55113 1.55114" xyz="0.00205819 -0.000468129 7.76376e-10"/>
      <geometry>
        <sphere radius="0.010704766923"/>
      </geometry>
    </collision>
    <collision>
      <origin rpy="1.5708 1.55113 1.55114" xyz="0.0096433 -0.000617283 1.28171e-10"/>
      <geometry>
        <cylinder length="0.0151731409586" radius="0.010704766923"/>
      </geometry>
    </collision>
    <collision>
      <origin rpy="1.5708 1.55113 1.55114" xyz="0.0172284 -0.000766437 -5.20034e-10"/>
      <geometry>
        <sphere radius="0.010704766923"/>
      </geometry>
    </collision>
  </link>
  <link name="right_hand_thumb_tip_ee">
    <inertial>
      <origin rpy="0 0 0" xyz="0 0 0"/>
      <mass value="0"/>
      <inertia ixx="0.0" ixy="0.0" ixz="0.0" iyy="0.0" iyz="0.0" izz="0.0"/>
    </inertial>
  </link> <!-- in pybullet, the inertia need to be specified even for dummy links, otherwise it will put an identity inertia and a mass of 1 by default -->
  <joint name="right_hand_thumb_tip_joint" type="fixed">
    <parent link="right_hand_c"/>
    <child link="right_hand_thumb_tip_ee"/>
    <origin rpy="0 0 0" xyz="0.012 0.01 0.0"/>
  </joint>
  <!-- INDEX FINGER LINKS -->
  <link name="right_hand_virtual_l">
    <inertial>
      <mass value="0.03"/>
      <inertia ixx="0.00001" ixy="0.0" ixz="0.0" iyy="0.00001" iyz="0.0" izz="0.00001"/>
    </inertial>
    <visual>
      <origin xyz="0 0 0.01321"/>
      <geometry>
        <mesh filename="meshes/schunk_hand/f10.dae"/>
      </geometry>
    </visual>
    <collision>
      <origin rpy="-3.14159 -0.218902 3.14159" xyz="-9.36911e-06 2.05516e-05 0.00314503"/>
      <geometry>
        <sphere radius="0.0124183215874"/>
      </geometry>
    </collision>
    <collision>
      <origin rpy="-3.14159 -0.218902 3.14159" xyz="-0.000565219 2.05537e-05 0.000646459"/>
      <geometry>
        <cylinder length="0.00511930368187" radius="0.0124183215874"/>
      </geometry>
    </collision>
    <collision>
      <origin rpy="-3.14159 -0.218902 3.14159" xyz="-0.00112107 2.05558e-05 -0.00185211"/>
      <geometry>
        <sphere radius="0.0124183215874"/>
      </geometry>
    </collision>
  </link>
  <link name="right_hand_l">
    <inertial>
      <mass value="0.03"/>
      <inertia ixx="0.00001" ixy="0.0" ixz="0.0" iyy="0.00001" iyz="0.0" izz="0.00001"/>
    </inertial>
    <visual>
      <geometry>
        <mesh filename="meshes/schunk_hand/f11.dae"/>
      </geometry>
    </visual>
    <collision>
      <origin rpy="-1.57082 1.56946 -1.56948" xyz="0.000494844 0.000786315 2.26346e-09"/>
      <geometry>
        <sphere radius="0.0104104100979"/>
      </geometry>
    </collision>
    <collision>
      <origin rpy="-1.57082 1.56946 -1.56948" xyz="0.0239282 0.000817694 1.63176e-09"/>
      <geometry>
        <cylinder length="0.0468666682082" radius="0.0104104100979"/>
      </geometry>
    </collision>
    <collision>
      <origin rpy="-1.57082 1.56946 -1.56948" xyz="0.0473615 0.000849073 1.00007e-09"/>
      <geometry>
        <sphere radius="0.0104104100979"/>
      </geometry>
    </collision>
  </link>
  <link name="right_hand_p">
    <inertial>
      <mass value="0.05"/>
      <origin rpy="0.0 1.57 0.0" xyz="0.0127 0.0 0.0"/>
      <inertia ixx="6.23228917375e-06" ixy="0.0" ixz="0.0" iyy="6.23228917375e-06" iyz="0.0" izz="2.25625e-06"/>
    </inertial>
    <visual>
      <geometry>
        <mesh filename="meshes/schunk_hand/f12.dae"/>
      </geometry>
    </visual>
    <collision>
      <origin rpy="-1.5708 1.56914 -1.56914" xyz="-2.97253e-05 1.67438e-05 -1.68626e-18"/>
      <geometry>
        <sphere radius="0.0110292374466"/>
      </geometry>
    </collision>
    <collision>
      <origin rpy="-1.5708 1.56914 -1.56914" xyz="0.011829 3.63913e-05 5.61001e-18"/>
      <geometry>
        <cylinder length="0.0237175682775" radius="0.0110292374466"/>
      </geometry>
    </collision>
    <collision>
      <origin rpy="-1.5708 1.56914 -1.56914" xyz="0.0236878 5.60387e-05 1.29063e-17"/>
      <geometry>
        <sphere radius="0.0110292374466"/>
      </geometry>
    </collision>
  </link>
  <link name="right_hand_t">
    <!--xacro:dummy_inertial /-->
    <inertial>
      <mass value="0.03"/>
      <origin rpy="0 1.57 0" xyz="0.007 0 0"/>
      <inertia ixx="2.439999024e-06" ixy="0.0" ixz="0.0" iyy="2.439999024e-06" iyz="0.0" izz="9.6e-07"/>
    </inertial>
    <visual>
      <geometry>
        <mesh filename="meshes/schunk_hand/f13.dae"/>
      </geometry>
    </visual>
    <collision>
      <origin rpy="-1.5708 1.56702 -1.56702" xyz="0.00112397 6.55543e-05 2.56588e-17"/>
      <geometry>
        <sphere radius="0.00858501607426"/>
      </geometry>
    </collision>
    <collision>
      <origin rpy="-1.5708 1.56702 -1.56702" xyz="0.00751444 8.96663e-05 1.21518e-17"/>
      <geometry>
        <cylinder length="0.0127810419291" radius="0.00858501607426"/>
      </geometry>
    </collision>
    <collision>
      <origin rpy="-1.5708 1.56702 -1.56702" xyz="0.0139049 0.000113778 -1.35513e-18"/>
      <geometry>
        <sphere radius="0.00858501607426"/>
      </geometry>
    </collision>
  </link>
  <link name="right_hand_index_tip_ee">
    <inertial>
      <origin rpy="0 0 0" xyz="0 0 0"/>
      <mass value="0"/>
      <inertia ixx="0.0" ixy="0.0" ixz="0.0" iyy="0.0" iyz="0.0" izz="0.0"/>
    </inertial>
  </link> <!-- in pybullet, the inertia need to be specified even for dummy links, otherwise it will put an identity inertia and a mass of 1 by default -->
  <joint name="right_hand_index_tip_joint" type="fixed">
    <parent link="right_hand_t"/>
    <child link="right_hand_index_tip_ee"/>
    <origin rpy="0 0 0" xyz="0.012 0.007 0.0"/>
  </joint>
  <!-- MIDDLE FINGER LINKS -->
  <link name="right_hand_virtual_k">
    <inertial>
      <mass value="0.03"/>
      <inertia ixx="0.00001" ixy="0.0" ixz="0.0" iyy="0.00001" iyz="0.0" izz="0.00001"/>
    </inertial>
    <visual>
      <origin xyz="0 0 0.01321"/>
      <geometry>
        <mesh filename="meshes/schunk_hand/f20.dae"/>
      </geometry>
    </visual>
    <collision>
      <origin rpy="-3.14159 -0.21666 3.14158" xyz="-2.48053e-05 -8.49468e-07 0.00306843"/>
      <geometry>
        <sphere radius="0.0124149630608"/>
      </geometry>
    </collision>
    <collision>
      <origin rpy="-3.14159 -0.21666 3.14158" xyz="-0.000572389 -8.47362e-07 0.000580713"/>
      <geometry>
        <cylinder length="0.00509453184408" radius="0.0124149630608"/>
      </geometry>
    </collision>
    <collision>
      <origin rpy="-3.14159 -0.21666 3.14158" xyz="-0.00111997 -8.45255e-07 -0.001907"/>
      <geometry>
        <sphere radius="0.0124149630608"/>
      </geometry>
    </collision>
  </link>
  <link name="right_hand_k">
    <inertial>
      <mass value="0.03"/>
      <inertia ixx="0.00001" ixy="0.0" ixz="0.0" iyy="0.00001" iyz="0.0" izz="0.00001"/>
    </inertial>
    <visual>
      <geometry>
        <mesh filename="meshes/schunk_hand/f21.dae"/>
      </geometry>
    </visual>
    <collision>
      <origin rpy="-1.57078 1.56262 -1.5626" xyz="0.000329902 0.000681478 -7.15399e-09"/>
      <geometry>
        <sphere radius="0.0103423075683"/>
      </geometry>
    </collision>
    <collision>
      <origin rpy="-1.57078 1.56262 -1.5626" xyz="0.025073 0.000883872 -4.18943e-09"/>
      <geometry>
        <cylinder length="0.0494877939213" radius="0.0103423075683"/>
      </geometry>
    </collision>
    <collision>
      <origin rpy="-1.57078 1.56262 -1.5626" xyz="0.049816 0.00108627 -1.22488e-09"/>
      <geometry>
        <sphere radius="0.0103423075683"/>
      </geometry>
    </collision>
  </link>
  <link name="right_hand_o">
    <!--xacro:dummy_inertial /-->
    <inertial>
      <mass value="0.05"/>
      <origin rpy="0 1.57 0" xyz="0.016 0 0"/>
      <inertia ixx="7.79478854875e-06" ixy="0.0" ixz="0.0" iyy="7.79478854875e-06" iyz="0.0" izz="2.25625e-06"/>
    </inertial>
    <visual>
      <geometry>
        <mesh filename="meshes/schunk_hand/f22.dae"/>
      </geometry>
    </visual>
    <collision>
      <origin rpy="-1.5708 1.56927 -1.56927" xyz="-3.30221e-05 1.09516e-05 8.53407e-19"/>
      <geometry>
        <sphere radius="0.0109921488052"/>
      </geometry>
    </collision>
    <collision>
      <origin rpy="-1.5708 1.56927 -1.56927" xyz="0.0148204 3.363e-05 1.37822e-18"/>
      <geometry>
        <cylinder length="0.0297069326601" radius="0.0109921488052"/>
      </geometry>
    </collision>
    <collision>
      <origin rpy="-1.5708 1.56927 -1.56927" xyz="0.0296739 5.63084e-05 1.90304e-18"/>
      <geometry>
        <sphere radius="0.0109921488052"/>
      </geometry>
    </collision>
  </link>
  <link name="right_hand_s">
    <!--xacro:dummy_inertial /-->
    <inertial>
      <mass value="0.03"/>
      <origin rpy="0 1.57 0" xyz="0.008 0 0"/>
      <inertia ixx="2.439999024e-06" ixy="0.0" ixz="0.0" iyy="2.439999024e-06" iyz="0.0" izz="9.6e-07"/>
    </inertial>
    <visual>
      <geometry>
        <mesh filename="meshes/schunk_hand/f23.dae"/>
      </geometry>
    </visual>
    <collision>
      <origin rpy="-1.5708 1.5644 -1.5644" xyz="0.00111375 3.07691e-05 -1.75721e-18"/>
      <geometry>
        <sphere radius="0.00858541498434"/>
      </geometry>
    </collision>
    <collision>
      <origin rpy="-1.5708 1.5644 -1.5644" xyz="0.00750196 7.16119e-05 2.84644e-19"/>
      <geometry>
        <cylinder length="0.0127766757058" radius="0.00858541498434"/>
      </geometry>
    </collision>
    <collision>
      <origin rpy="-1.5708 1.5644 -1.5644" xyz="0.0138902 0.000112455 2.3265e-18"/>
      <geometry>
        <sphere radius="0.00858541498434"/>
      </geometry>
    </collision>
  </link>
  <link name="right_hand_middle_tip_ee">
    <inertial>
      <origin rpy="0 0 0" xyz="0 0 0"/>
      <mass value="0"/>
      <inertia ixx="0.0" ixy="0.0" ixz="0.0" iyy="0.0" iyz="0.0" izz="0.0"/>
    </inertial>
  </link> <!-- in pybullet, the inertia need to be specified even for dummy links, otherwise it will put an identity inertia and a mass of 1 by default -->
  <joint name="right_hand_middle_tip_joint" type="fixed">
    <parent link="right_hand_s"/>
    <child link="right_hand_middle_tip_ee"/>
    <origin rpy="0 0 0" xyz="0.012 0.007 0.0"/>
  </joint>
  <!-- RING FINGER LINKS -->
  <link name="right_hand_virtual_j">
    <inertial>
      <mass value="0.03"/>
      <inertia ixx="0.00001" ixy="0.0" ixz="0.0" iyy="0.00001" iyz="0.0" izz="0.00001"/>
    </inertial>
    <visual>
      <origin xyz="0 0 -0.01321"/>
      <geometry>
        <mesh filename="meshes/schunk_hand/f30.dae"/>
      </geometry>
    </visual>
    <collision>
      <origin rpy="5.49177e-08 -0.215196 -5.93196e-09" xyz="2.78542e-05 3.86086e-05 -0.0030288"/>
      <geometry>
        <sphere radius="0.0124140277083"/>
      </geometry>
    </collision>
    <collision>
      <origin rpy="5.49177e-08 -0.215196 -5.93196e-09" xyz="-0.000514205 3.86085e-05 -0.000548897"/>
      <geometry>
        <cylinder length="0.00507690493408" radius="0.0124140277083"/>
      </geometry>
    </collision>
    <collision>
      <origin rpy="5.49177e-08 -0.215196 -5.93196e-09" xyz="-0.00105626 3.86083e-05 0.00193101"/>
      <geometry>
        <sphere radius="0.0124140277083"/>
      </geometry>
    </collision>
  </link>
  <link name="right_hand_j">
    <inertial>
      <mass value="0.03"/>
      <inertia ixx="0.00001" ixy="0.0" ixz="0.0" iyy="0.00001" iyz="0.0" izz="0.00001"/>
    </inertial>
    <visual>
      <geometry>
        <mesh filename="meshes/schunk_hand/f31.dae"/>
      </geometry>
    </visual>
    <collision>
      <origin rpy="1.5708 1.52508 1.52508" xyz="-0.00092978 0.00119932 2.49389e-09"/>
      <geometry>
        <sphere radius="0.010523390341"/>
      </geometry>
    </collision>
    <collision>
      <origin rpy="1.5708 1.52508 1.52508" xyz="0.0239238 6.23222e-05 -2.50296e-09"/>
      <geometry>
        <cylinder length="0.0497591540656" radius="0.010523390341"/>
      </geometry>
    </collision>
    <collision>
      <origin rpy="1.5708 1.52508 1.52508" xyz="0.0487774 -0.00107468 -7.49981e-09"/>
      <geometry>
        <sphere radius="0.010523390341"/>
      </geometry>
    </collision>
  </link>
  <link name="right_hand_n">
    <inertial>
      <mass value="0.05"/>
      <origin rpy="0 1.57 0" xyz="0.016 0 0"/>
      <inertia ixx="8.47812160875e-06" ixy="0.0" ixz="0.0" iyy="8.47812160875e-06" iyz="0.0" izz="2.25625e-06"/>
    </inertial>
    <visual>
      <geometry>
        <mesh filename="meshes/schunk_hand/f32.dae"/>
      </geometry>
    </visual>
    <collision>
      <origin rpy="-1.5708 1.5692 -1.5692" xyz="-1.93421e-05 5.57259e-06 7.00794e-20"/>
      <geometry>
        <sphere radius="0.0109911462183"/>
      </geometry>
    </collision>
    <collision>
      <origin rpy="-1.5708 1.5692 -1.5692" xyz="0.014822 2.92925e-05 2.03475e-19"/>
      <geometry>
        <cylinder length="0.0296826647281" radius="0.0109911462183"/>
      </geometry>
    </collision>
    <collision>
      <origin rpy="-1.5708 1.5692 -1.5692" xyz="0.0296633 5.30125e-05 3.3687e-19"/>
      <geometry>
        <sphere radius="0.0109911462183"/>
      </geometry>
    </collision>
  </link>
  <link name="right_hand_r">
    <inertial>
      <mass value="0.03"/>
      <origin rpy="0 1.57 0" xyz="0.008 0 0"/>
      <inertia ixx="2.439999024e-06" ixy="0.0" ixz="0.0" iyy="2.439999024e-06" iyz="0.0" izz="9.6e-07"/>
    </inertial>
    <visual>
      <geometry>
        <mesh filename="meshes/schunk_hand/f33.dae"/>
      </geometry>
    </visual>
    <collision>
      <origin rpy="-1.5708 1.57043 -1.57043" xyz="0.00109315 6.51512e-05 -1.52904e-16"/>
      <geometry>
        <sphere radius="0.00856929639647"/>
      </geometry>
    </collision>
    <collision>
      <origin rpy="-1.5708 1.57043 -1.57043" xyz="0.00749768 6.74823e-05 -1.88397e-17"/>
      <geometry>
        <cylinder length="0.0128090602606" radius="0.00856929639647"/>
      </geometry>
    </collision>
    <collision>
      <origin rpy="-1.5708 1.57043 -1.57043" xyz="0.0139022 6.98134e-05 1.15224e-16"/>
      <geometry>
        <sphere radius="0.00856929639647"/>
      </geometry>
    </collision>
  </link>
  <link name="right_hand_ring_tip_ee">
    <inertial>
      <origin rpy="0 0 0" xyz="0 0 0"/>
      <mass value="0"/>
      <inertia ixx="0.0" ixy="0.0" ixz="0.0" iyy="0.0" iyz="0.0" izz="0.0"/>
    </inertial>
  </link> <!-- in pybullet, the inertia need to be specified even for dummy links, otherwise it will put an identity inertia and a mass of 1 by default -->
  <joint name="right_hand_ring_tip_joint" type="fixed">
    <parent link="right_hand_r"/>
    <child link="right_hand_ring_tip_ee"/>
    <origin rpy="0 0 0" xyz="0.012 0.007 0.0"/>
  </joint>
  <!-- LITTLE FINGER LINKS -->
  <link name="right_hand_virtual_i">
    <inertial>
      <mass value="0.03"/>
      <inertia ixx="0.00001" ixy="0.0" ixz="0.0" iyy="0.00001" iyz="0.0" izz="0.00001"/>
    </inertial>
    <visual>
      <origin xyz="0 0 -0.01321"/>
      <geometry>
        <mesh filename="meshes/schunk_hand/f40.dae"/>
      </geometry>
    </visual>
    <collision>
      <origin rpy="1.62648e-07 -0.223705 -1.82689e-08" xyz="-7.87181e-06 4.4169e-06 -0.00303052"/>
      <geometry>
        <sphere radius="0.0123918487645"/>
      </geometry>
    </collision>
    <collision>
      <origin rpy="1.62648e-07 -0.223705 -1.82689e-08" xyz="-0.000579472 4.4165e-06 -0.000518133"/>
      <geometry>
        <cylinder length="0.00515318354012" radius="0.0123918487645"/>
      </geometry>
    </collision>
    <collision>
      <origin rpy="1.62648e-07 -0.223705 -1.82689e-08" xyz="-0.00115107 4.41609e-06 0.00199426"/>
      <geometry>
        <sphere radius="0.0123918487645"/>
      </geometry>
    </collision>
  </link>
  <link name="right_hand_i">
    <inertial>
      <mass value="0.03"/>
      <inertia ixx="0.00001" ixy="0.0" ixz="0.0" iyy="0.00001" iyz="0.0" izz="0.00001"/>
    </inertial>
    <visual>
      <geometry>
        <mesh filename="meshes/schunk_hand/f41.dae"/>
      </geometry>
    </visual>
    <collision>
      <origin rpy="1.57078 1.54144 1.54142" xyz="-0.000481662 0.00135926 -6.99986e-09"/>
      <geometry>
        <sphere radius="0.0105526202063"/>
      </geometry>
    </collision>
    <collision>
      <origin rpy="1.57078 1.54144 1.54142" xyz="0.021353 0.000718 6.59159e-10"/>
      <geometry>
        <cylinder length="0.0436881600922" radius="0.0105526202063"/>
      </geometry>
    </collision>
    <collision>
      <origin rpy="1.57078 1.54144 1.54142" xyz="0.0431877 7.67402e-05 8.31818e-09"/>
      <geometry>
        <sphere radius="0.0105526202063"/>
      </geometry>
    </collision>
  </link>
  <link name="right_hand_m">
    <!--xacro:dummy_inertial /-->
    <inertial>
      <mass value="0.05"/>
      <origin rpy="0 1.57 0" xyz="0.016 0 0"/>
      <inertia ixx="5.39478950875e-06" ixy="0.0" ixz="0.0" iyy="5.39478950875e-06" iyz="0.0" izz="2.25625e-06"/>
    </inertial>
    <visual>
      <geometry>
        <mesh filename="meshes/schunk_hand/f42.dae"/>
      </geometry>
    </visual>
    <collision>
      <origin rpy="-1.5708 1.56905 -1.56905" xyz="1.74585e-06 -2.21286e-06 7.25811e-19"/>
      <geometry>
        <sphere radius="0.011141281998"/>
      </geometry>
    </collision>
    <collision>
      <origin rpy="-1.5708 1.56905 -1.56905" xyz="0.00978733 1.48637e-05 -6.73016e-18"/>
      <geometry>
        <cylinder length="0.0195712007882" radius="0.011141281998"/>
      </geometry>
    </collision>
    <collision>
      <origin rpy="-1.5708 1.56905 -1.56905" xyz="0.0195729 3.19402e-05 -1.41861e-17"/>
      <geometry>
        <sphere radius="0.011141281998"/>
      </geometry>
    </collision>
  </link>
  <link name="right_hand_q">
    <!--xacro:dummy_inertial /-->
    <inertial>
      <mass value="0.03"/>
      <origin rpy="0 1.57 0" xyz="0.008 0 0"/>
      <inertia ixx="2.439999024e-06" ixy="0.0" ixz="0.0" iyy="2.439999024e-06" iyz="0.0" izz="9.6e-07"/>
    </inertial>
    <visual>
      <geometry>
        <mesh filename="meshes/schunk_hand/f43.dae"/>
      </geometry>
    </visual>
    <collision>
      <origin rpy="-1.5708 1.57062 -1.57062" xyz="0.00111873 6.04446e-05 5.35122e-17"/>
      <geometry>
        <sphere radius="0.00857885551647"/>
      </geometry>
    </collision>
    <collision>
      <origin rpy="-1.5708 1.57062 -1.57062" xyz="0.00751342 6.15983e-05 7.63387e-18"/>
      <geometry>
        <cylinder length="0.0127893791599" radius="0.00857885551647"/>
      </geometry>
    </collision>
    <collision>
      <origin rpy="-1.5708 1.57062 -1.57062" xyz="0.0139081 6.27521e-05 -3.82445e-17"/>
      <geometry>
        <sphere radius="0.00857885551647"/>
      </geometry>
    </collision>
  </link>
  <link name="right_hand_pinky_tip_ee">
    <inertial>
      <origin rpy="0 0 0" xyz="0 0 0"/>
      <mass value="0"/>
      <inertia ixx="0.0" ixy="0.0" ixz="0.0" iyy="0.0" iyz="0.0" izz="0.0"/>
    </inertial>
  </link> <!-- in pybullet, the inertia need to be specified even for dummy links, otherwise it will put an identity inertia and a mass of 1 by default -->
  <joint name="right_hand_pinky_tip_joint" type="fixed">
    <parent link="right_hand_q"/>
    <child link="right_hand_pinky_tip_ee"/>
    <origin rpy="0 0 0" xyz="0.012 0.007 0.0"/>
  </joint>
  <joint name="right_hand_Thumb_Flexion" type="revolute">
    <parent link="right_hand_virtual_a"/>
    <child link="right_hand_a"/>
    <limit effort="1000.0" lower="0.0" upper="0.9704" velocity="1"/>
    <origin rpy="0 0 -0.9704" xyz="0 0 0"/>
    <axis xyz="0 0 1"/>
  </joint>
  <transmission name="right_hand_Thumb_Flexion_transmission">
    <type>transmission_interface/SimpleTransmission</type>
    <joint name="right_hand_Thumb_Flexion">
      <hardwareInterface>hardware_interface/EffortJointInterface</hardwareInterface>
    </joint>
    <actuator name="motor_right_hand_Thumb_Flexion">
      <mechanicalReduction>1</mechanicalReduction>
      <hardwareInterface>hardware_interface/EffortJointInterface</hardwareInterface>
    </actuator>
  </transmission>
  <!--transmission name="${name}_Thumb_Flexion_transmission">
            <type>transmission_interface/SimpleTransmission</type>
            <joint name="${name}_Thumb_Flexion">
                <hardwareInterface>hardware_interface/EffortJointInterface</hardwareInterface>
            </joint>
            <actuator name="motor_${name}_Thumb_Flexion">
                <mechanicalReduction>1</mechanicalReduction>
                <hardwareInterface>hardware_interface/EffortJointInterface</hardwareInterface>
            </actuator>
        </transmission-->
  <joint name="right_hand_Thumb_Helper" type="fixed">
    <!--limit effort="1000" upper="0" lower="0" velocity="1"/-->
    <parent link="right_hand_z"/>
    <child link="right_hand_virtual_a"/>
    <origin rpy="0 -1.5707 3.1416" xyz="0 0 0.04596"/>
  </joint>
  <!-- BASE_LINE JOINTS -->
  <joint name="right_hand_Thumb_Opposition" type="revolute">
    <parent link="right_hand_e1"/>
    <child link="right_hand_z"/>
    <limit effort="1000.0" lower="0.0" upper="0.9879" velocity="1"/>
    <origin rpy="0 0.2618 1.571" xyz="-0.0169 0.02626 0"/>
    <axis xyz="0 0 -1"/>
  </joint>
  <transmission name="right_hand_Thumb_Opposition_transmission">
    <type>transmission_interface/SimpleTransmission</type>
    <joint name="right_hand_Thumb_Opposition">
      <hardwareInterface>hardware_interface/EffortJointInterface</hardwareInterface>
    </joint>
    <actuator name="motor_right_hand_Thumb_Opposition">
      <mechanicalReduction>1</mechanicalReduction>
      <hardwareInterface>hardware_interface/EffortJointInterface</hardwareInterface>
    </actuator>
  </transmission>
  <!-- JOINT NOT FOR BASE_LINE. BUT WRITTEN DOWN HERE FOR BETTER UX -->
  <joint name="right_hand_f1" type="fixed">
    <!--limit effort="1000" upper="0" lower="0" velocity="1"/-->
    <parent link="right_hand_e1"/>
    <child link="right_hand_d"/>
    <origin rpy="0 0 0" xyz="0 0 0"/>
  </joint>
  <joint name="right_hand_f2" type="fixed">
    <!--limit effort="1000" upper="0" lower="0" velocity="1"/-->
    <parent link="right_hand_d"/>
    <child link="right_hand_h"/>
    <origin rpy="0 0 0" xyz="0 0 0"/>
  </joint>
  <joint name="right_hand_f3" type="fixed">
    <!--limit effort="1000" upper="0" lower="0" velocity="1"/-->
    <parent link="right_hand_h"/>
    <child link="right_hand_d2"/>
    <origin rpy="0 0 0" xyz="0 0 0"/>
  </joint>
  <joint name="right_hand_f4" type="fixed">
    <!--limit effort="1000" upper="0" lower="0" velocity="1"/-->
    <parent link="right_hand_base_link"/>
    <child link="right_hand_e1"/>
    <origin rpy="0 0 0" xyz="0 -0.01313 0"/>
  </joint>
  <joint name="right_hand_j5" type="revolute">
    <parent link="right_hand_e1"/>
    <child link="right_hand_e2"/>
    <limit effort="1000.0" lower="0.0" upper="0.98786" velocity="1"/>
    <origin rpy="0 0 0" xyz="0.0184 0.006 0.0375"/>
    <axis xyz="0 0 1"/>
    <mimic joint="right_hand_Thumb_Opposition" multiplier="1" offset="0"/>
  </joint>
  <transmission name="right_hand_j5_transmission">
    <type>transmission_interface/SimpleTransmission</type>
    <joint name="right_hand_j5">
      <hardwareInterface>hardware_interface/EffortJointInterface</hardwareInterface>
    </joint>
    <actuator name="motor_right_hand_j5">
      <mechanicalReduction>1</mechanicalReduction>
      <hardwareInterface>hardware_interface/EffortJointInterface</hardwareInterface>
    </actuator>
  </transmission>
  <joint name="right_hand_f5" type="fixed">
    <!--limit effort="1000" upper="0" lower="0" velocity="1"/-->
    <parent link="right_hand_e2"/>
    <child link="right_hand_e3"/>
    <origin rpy="0 0 0" xyz="0 -0.0060 0"/>
  </joint>
  <joint name="right_hand_f6" type="fixed">
    <!--limit effort="1000" upper="0" lower="0" velocity="1"/-->
    <parent link="right_hand_e3"/>
    <child link="right_hand_e"/>
    <origin rpy="0 0 0" xyz="0 0 0"/>
  </joint>
  <joint name="right_hand_f7" type="fixed">
    <!--limit effort="1000" upper="0" lower="0" velocity="1"/-->
    <parent link="right_hand_e"/>
    <child link="right_hand_e4"/>
    <origin rpy="0 0 0" xyz="0 0 0"/>
  </joint>
  <joint name="right_hand_f8" type="fixed">
    <!--limit effort="1000" upper="0" lower="0" velocity="1"/-->
    <parent link="right_hand_e"/>
    <child link="right_hand_e5"/>
    <origin rpy="0 0 0" xyz="0 0 0"/>
  </joint>
  <!-- THUMB JOINTS -->
  <joint name="right_hand_j3" type="revolute">
    <parent link="right_hand_a"/>
    <child link="right_hand_b"/>
    <limit effort="1000.0" lower="0.0" upper="0.98506" velocity="1"/>
    <origin rpy="0 0 0" xyz="0.0485 0 0"/>
    <axis xyz="0 0 1"/>
    <mimic joint="right_hand_Thumb_Flexion" multiplier="1.01511" offset="0"/>
  </joint>
  <transmission name="right_hand_j3_transmission">
    <type>transmission_interface/SimpleTransmission</type>
    <joint name="right_hand_j3">
      <hardwareInterface>hardware_interface/EffortJointInterface</hardwareInterface>
    </joint>
    <actuator name="motor_right_hand_j3">
      <mechanicalReduction>1</mechanicalReduction>
      <hardwareInterface>hardware_interface/EffortJointInterface</hardwareInterface>
    </actuator>
  </transmission>
  <joint name="right_hand_j4" type="revolute">
    <parent link="right_hand_b"/>
    <child link="right_hand_c"/>
    <limit effort="1000.0" lower="0.0" upper="1.406" velocity="1"/>
    <origin rpy="0 0 0" xyz="0.030 0 0"/>
    <axis xyz="0 0 1"/>
    <mimic joint="right_hand_Thumb_Flexion" multiplier="1.44889" offset="0"/>
  </joint>
  <transmission name="right_hand_j4_transmission">
    <type>transmission_interface/SimpleTransmission</type>
    <joint name="right_hand_j4">
      <hardwareInterface>hardware_interface/EffortJointInterface</hardwareInterface>
    </joint>
    <actuator name="motor_right_hand_j4">
      <mechanicalReduction>1</mechanicalReduction>
      <hardwareInterface>hardware_interface/EffortJointInterface</hardwareInterface>
    </actuator>
  </transmission>
  <!-- INDEX FINGER JOINTS -->
  <joint name="right_hand_Index_Finger_Distal" type="revolute">
    <parent link="right_hand_l"/>
    <child link="right_hand_p"/>
    <limit effort="1000.0" lower="0" upper="1.334" velocity="1"/>
    <origin rpy="0 0 0" xyz="0.04804 0 0"/>
    <axis xyz="0 0 1"/>
  </joint>
  <transmission name="right_hand_Index_Finger_Distal_transmission">
    <type>transmission_interface/SimpleTransmission</type>
    <joint name="right_hand_Index_Finger_Distal">
      <hardwareInterface>hardware_interface/EffortJointInterface</hardwareInterface>
    </joint>
    <actuator name="motor_right_hand_Index_Finger_Distal">
      <mechanicalReduction>1</mechanicalReduction>
      <hardwareInterface>hardware_interface/EffortJointInterface</hardwareInterface>
    </actuator>
  </transmission>
  <joint name="right_hand_Index_Finger_Proximal" type="revolute">
    <parent link="right_hand_virtual_l"/>
    <child link="right_hand_l"/>
    <limit effort="1000.0" lower="0.0" upper="0.79849" velocity="1"/>
    <origin rpy="-1.5707 0 0" xyz="0 0 0"/>
    <axis xyz="0 0 1"/>
  </joint>
  <transmission name="right_hand_Index_Finger_Proximal_transmission">
    <type>transmission_interface/SimpleTransmission</type>
    <joint name="right_hand_Index_Finger_Proximal">
      <hardwareInterface>hardware_interface/EffortJointInterface</hardwareInterface>
    </joint>
    <actuator name="motor_right_hand_Index_Finger_Proximal">
      <mechanicalReduction>1</mechanicalReduction>
      <hardwareInterface>hardware_interface/EffortJointInterface</hardwareInterface>
    </actuator>
  </transmission>
  <!-- JOINT Finger_Spread in BASE_LINE section for better UX -->
  <joint name="right_hand_j14" type="revolute">
    <parent link="right_hand_p"/>
    <child link="right_hand_t"/>
    <limit effort="1000.0" lower="0" upper="1.394" velocity="1"/>
    <origin rpy="0 0 0" xyz="0.026 0 0"/>
    <axis xyz="0 0 1"/>
    <mimic joint="right_hand_Index_Finger_Distal" multiplier="1.0450" offset="0"/>
  </joint>
  <transmission name="right_hand_j14_transmission">
    <type>transmission_interface/SimpleTransmission</type>
    <joint name="right_hand_j14">
      <hardwareInterface>hardware_interface/EffortJointInterface</hardwareInterface>
    </joint>
    <actuator name="motor_right_hand_j14">
      <mechanicalReduction>1</mechanicalReduction>
      <hardwareInterface>hardware_interface/EffortJointInterface</hardwareInterface>
    </actuator>
  </transmission>
  <!-- MIDDLE FINGER JOINTS -->
  <joint name="right_hand_Middle_Finger_Proximal" type="revolute">
    <parent link="right_hand_virtual_k"/>
    <child link="right_hand_k"/>
    <limit effort="1000.0" lower="0.0" upper="0.79849" velocity="1"/>
    <origin rpy="-1.5707 0 0" xyz="0 0 0"/>
    <axis xyz="0 0 1"/>
  </joint>
  <transmission name="right_hand_Middle_Finger_Proximal_transmission">
    <type>transmission_interface/SimpleTransmission</type>
    <joint name="right_hand_Middle_Finger_Proximal">
      <hardwareInterface>hardware_interface/EffortJointInterface</hardwareInterface>
    </joint>
    <actuator name="motor_right_hand_Middle_Finger_Proximal">
      <mechanicalReduction>1</mechanicalReduction>
      <hardwareInterface>hardware_interface/EffortJointInterface</hardwareInterface>
    </actuator>
  </transmission>
  <joint name="right_hand_Middle_Finger_Distal" type="revolute">
    <parent link="right_hand_k"/>
    <child link="right_hand_o"/>
    <limit effort="1000.0" lower="0" upper="1.334" velocity="1"/>
    <origin rpy="0 0 0" xyz="0.05004 0 0"/>
    <axis xyz="0 0 1"/>
  </joint>
  <transmission name="right_hand_Middle_Finger_Distal_transmission">
    <type>transmission_interface/SimpleTransmission</type>
    <joint name="right_hand_Middle_Finger_Distal">
      <hardwareInterface>hardware_interface/EffortJointInterface</hardwareInterface>
    </joint>
    <actuator name="motor_right_hand_Middle_Finger_Distal">
      <mechanicalReduction>1</mechanicalReduction>
      <hardwareInterface>hardware_interface/EffortJointInterface</hardwareInterface>
    </actuator>
  </transmission>
  <joint name="right_hand_j15" type="revolute">
    <parent link="right_hand_o"/>
    <child link="right_hand_s"/>
    <limit effort="1000.0" lower="0" upper="1.334" velocity="1"/>
    <origin rpy="0 0 0" xyz="0.032 0 0"/>
    <axis xyz="0 0 1"/>
    <mimic joint="right_hand_Middle_Finger_Distal" multiplier="1.0454" offset="0"/>
  </joint>
  <transmission name="right_hand_j15_transmission">
    <type>transmission_interface/SimpleTransmission</type>
    <joint name="right_hand_j15">
      <hardwareInterface>hardware_interface/EffortJointInterface</hardwareInterface>
    </joint>
    <actuator name="motor_right_hand_j15">
      <mechanicalReduction>1</mechanicalReduction>
      <hardwareInterface>hardware_interface/EffortJointInterface</hardwareInterface>
    </actuator>
  </transmission>
  <!-- RING FINGER JOINTS -->
  <joint name="right_hand_Ring_Finger" type="revolute">
    <parent link="right_hand_virtual_j"/>
    <child link="right_hand_j"/>
    <limit effort="1000.0" lower="0.0" upper="0.98175" velocity="1"/>
    <origin rpy="1.5707 0 0" xyz="0 0 0"/>
    <axis xyz="0 0 1"/>
  </joint>
  <transmission name="right_hand_Ring_Finger_transmission">
    <type>transmission_interface/SimpleTransmission</type>
    <joint name="right_hand_Ring_Finger">
      <hardwareInterface>hardware_interface/EffortJointInterface</hardwareInterface>
    </joint>
    <actuator name="motor_right_hand_Ring_Finger">
      <mechanicalReduction>1</mechanicalReduction>
      <hardwareInterface>hardware_interface/EffortJointInterface</hardwareInterface>
    </actuator>
  </transmission>
  <joint name="right_hand_j12" type="revolute">
    <parent link="right_hand_j"/>
    <child link="right_hand_n"/>
    <limit effort="1000.0" lower="0" upper="1.334" velocity="1"/>
    <origin rpy="0 0 0" xyz="0.05004 0 0"/>
    <axis xyz="0 0 1"/>
    <mimic joint="right_hand_Ring_Finger" multiplier="1.3588" offset="0"/>
  </joint>
  <transmission name="right_hand_j12_transmission">
    <type>transmission_interface/SimpleTransmission</type>
    <joint name="right_hand_j12">
      <hardwareInterface>hardware_interface/EffortJointInterface</hardwareInterface>
    </joint>
    <actuator name="motor_right_hand_j12">
      <mechanicalReduction>1</mechanicalReduction>
      <hardwareInterface>hardware_interface/EffortJointInterface</hardwareInterface>
    </actuator>
  </transmission>
  <joint name="right_hand_j16" type="revolute">
    <parent link="right_hand_n"/>
    <child link="right_hand_r"/>
    <limit effort="1000.0" lower="0" upper="1.395" velocity="1"/>
    <origin rpy="0 0 0" xyz="0.032 0 0"/>
    <axis xyz="0 0 1"/>
    <mimic joint="right_hand_Ring_Finger" multiplier="1.42093" offset="0"/>
  </joint>
  <transmission name="right_hand_j16_transmission">
    <type>transmission_interface/SimpleTransmission</type>
    <joint name="right_hand_j16">
      <hardwareInterface>hardware_interface/EffortJointInterface</hardwareInterface>
    </joint>
    <actuator name="motor_right_hand_j16">
      <mechanicalReduction>1</mechanicalReduction>
      <hardwareInterface>hardware_interface/EffortJointInterface</hardwareInterface>
    </actuator>
  </transmission>
  <!-- PINKY JOINTS -->
  <joint name="right_hand_Pinky" type="revolute">
    <parent link="right_hand_virtual_i"/>
    <child link="right_hand_i"/>
    <limit effort="1000.0" lower="0.0" upper="0.98175" velocity="1"/>
    <origin rpy="1.5707 0 0" xyz="0 0 0"/>
    <axis xyz="0 0 1"/>
  </joint>
  <transmission name="right_hand_Pinky_transmission">
    <type>transmission_interface/SimpleTransmission</type>
    <joint name="right_hand_Pinky">
      <hardwareInterface>hardware_interface/EffortJointInterface</hardwareInterface>
    </joint>
    <actuator name="motor_right_hand_Pinky">
      <mechanicalReduction>1</mechanicalReduction>
      <hardwareInterface>hardware_interface/EffortJointInterface</hardwareInterface>
    </actuator>
  </transmission>
  <joint name="right_hand_j13" type="revolute">
    <parent link="right_hand_i"/>
    <child link="right_hand_m"/>
    <limit effort="1000.0" lower="0" upper="1.334" velocity="1"/>
    <origin rpy="0 0 0" xyz="0.04454 0 0"/>
    <axis xyz="0 0 1"/>
    <mimic joint="right_hand_Pinky" multiplier="1.35880" offset="0"/>
  </joint>
  <transmission name="right_hand_j13_transmission">
    <type>transmission_interface/SimpleTransmission</type>
    <joint name="right_hand_j13">
      <hardwareInterface>hardware_interface/EffortJointInterface</hardwareInterface>
    </joint>
    <actuator name="motor_right_hand_j13">
      <mechanicalReduction>1</mechanicalReduction>
      <hardwareInterface>hardware_interface/EffortJointInterface</hardwareInterface>
    </actuator>
  </transmission>
  <joint name="right_hand_j17" type="revolute">
    <parent link="right_hand_m"/>
    <child link="right_hand_q"/>
    <limit effort="1000.0" lower="0" upper="1.3971" velocity="1"/>
    <origin rpy="0 0 0" xyz="0.022 0 0"/>
    <axis xyz="0 0 1"/>
    <mimic joint="right_hand_Pinky" multiplier="1.42307" offset="0"/>
  </joint>
  <transmission name="right_hand_j17_transmission">
    <type>transmission_interface/SimpleTransmission</type>
    <joint name="right_hand_j17">
      <hardwareInterface>hardware_interface/EffortJointInterface</hardwareInterface>
    </joint>
    <actuator name="motor_right_hand_j17">
      <mechanicalReduction>1</mechanicalReduction>
      <hardwareInterface>hardware_interface/EffortJointInterface</hardwareInterface>
    </actuator>
  </transmission>
  <joint name="right_hand_index_spread" type="revolute">
    <parent link="right_hand_d2"/>
    <child link="right_hand_virtual_l"/>
    <limit effort="1000.0" lower="0.0" upper="0.28833" velocity="1"/>
    <origin rpy="0 -1.5707 1.5707" xyz="-0.025 0 0.110"/>
    <axis xyz="0 0 1"/>
    <mimic joint="right_hand_Finger_Spread" multiplier="0.5" offset="0"/>
  </joint>
  <transmission name="right_hand_index_spread_transmission">
    <type>transmission_interface/SimpleTransmission</type>
    <joint name="right_hand_index_spread">
      <hardwareInterface>hardware_interface/EffortJointInterface</hardwareInterface>
    </joint>
    <actuator name="motor_right_hand_index_spread">
      <mechanicalReduction>1</mechanicalReduction>
      <hardwareInterface>hardware_interface/EffortJointInterface</hardwareInterface>
    </actuator>
  </transmission>
  <joint name="right_hand_middle_spread_dummy" type="fixed">
    <!--limit effort="1000" upper="0" lower="0" velocity="1"/-->
    <parent link="right_hand_d"/>
    <child link="right_hand_virtual_k"/>
    <origin rpy="0 -1.5707 1.5707" xyz="0 0 0.110"/>
  </joint>
  <joint name="right_hand_ring_spread" type="revolute">
    <parent link="right_hand_e5"/>
    <child link="right_hand_virtual_j"/>
    <limit effort="1000.0" lower="0.0" upper="0.28833" velocity="1"/>
    <origin rpy="-1.5707 -1.5707 0" xyz="0.003855 0 0.0655"/>
    <axis xyz="0 0 1"/>
    <mimic joint="right_hand_Finger_Spread" multiplier="0.5" offset="0"/>
  </joint>
  <transmission name="right_hand_ring_spread_transmission">
    <type>transmission_interface/SimpleTransmission</type>
    <joint name="right_hand_ring_spread">
      <hardwareInterface>hardware_interface/EffortJointInterface</hardwareInterface>
    </joint>
    <actuator name="motor_right_hand_ring_spread">
      <mechanicalReduction>1</mechanicalReduction>
      <hardwareInterface>hardware_interface/EffortJointInterface</hardwareInterface>
    </actuator>
  </transmission>
  <joint name="right_hand_Finger_Spread" type="revolute">
    <parent link="right_hand_e4"/>
    <child link="right_hand_virtual_i"/>
    <limit effort="1000.0" lower="0.00" upper="0.5829" velocity="1"/>
    <origin rpy="-1.5707 -1.5707 0" xyz="0.025355 0 0.056"/>
    <axis xyz="0 0 1"/>
  </joint>
  <transmission name="right_hand_Finger_Spread_transmission">
    <type>transmission_interface/SimpleTransmission</type>
    <joint name="right_hand_Finger_Spread">
      <hardwareInterface>hardware_interface/EffortJointInterface</hardwareInterface>
    </joint>
    <actuator name="motor_right_hand_Finger_Spread">
      <mechanicalReduction>1</mechanicalReduction>
      <hardwareInterface>hardware_interface/EffortJointInterface</hardwareInterface>
    </actuator>
  </transmission>
  <gazebo reference="right_hand_c">
    <!--material>Gazebo/Blue</material-->
    <mu1>70</mu1>
    <mu2>70</mu2>
    <minDepth>0.001</minDepth>
    <!--maxVel>0.1</maxVel-->
    <kp>10000000.0</kp>
    <kd>100000.0</kd>
  </gazebo>
  <gazebo reference="right_hand_b">
    <!--material>Gazebo/Blue</material-->
    <mu1>70</mu1>
    <mu2>70</mu2>
    <minDepth>0.001</minDepth>
    <!--maxVel>0.1</maxVel-->
    <kp>10000000.0</kp>
    <kd>100000.0</kd>
  </gazebo>
  <gazebo reference="right_hand_a">
    <!--material>Gazebo/Blue</material-->
    <mu1>70</mu1>
    <mu2>70</mu2>
    <minDepth>0.001</minDepth>
    <!--maxVel>0.1</maxVel-->
    <kp>10000000.0</kp>
    <kd>100000.0</kd>
  </gazebo>
  <gazebo reference="right_hand_t">
    <!--material>Gazebo/Blue</material-->
    <mu1>70</mu1>
    <mu2>70</mu2>
    <minDepth>0.001</minDepth>
    <!--maxVel>0.1</maxVel-->
    <kp>10000000.0</kp>
    <kd>100000.0</kd>
  </gazebo>
  <gazebo reference="right_hand_p">
    <!--material>Gazebo/Blue</material-->
    <mu1>70</mu1>
    <mu2>70</mu2>
    <minDepth>0.001</minDepth>
    <!--maxVel>0.1</maxVel-->
    <kp>10000000.0</kp>
    <kd>100000.0</kd>
  </gazebo>
  <gazebo reference="right_hand_l">
    <!--material>Gazebo/Blue</material-->
    <mu1>70</mu1>
    <mu2>70</mu2>
    <minDepth>0.001</minDepth>
    <!--maxVel>0.1</maxVel-->
    <kp>10000000.0</kp>
    <kd>100000.0</kd>
  </gazebo>
  <gazebo reference="right_hand_s">
    <!--material>Gazebo/Blue</material-->
    <mu1>70</mu1>
    <mu2>70</mu2>
    <minDepth>0.001</minDepth>
    <!--maxVel>0.1</maxVel-->
    <kp>10000000.0</kp>
    <kd>100000.0</kd>
  </gazebo>
  <gazebo reference="right_hand_o">
    <!--material>Gazebo/Blue</material-->
    <mu1>70</mu1>
    <mu2>70</mu2>
    <minDepth>0.001</minDepth>
    <!--maxVel>0.1</maxVel-->
    <kp>10000000.0</kp>
    <kd>100000.0</kd>
  </gazebo>
  <gazebo reference="right_hand_k">
    <!--material>Gazebo/Blue</material-->
    <mu1>70</mu1>
    <mu2>70</mu2>
    <minDepth>0.001</minDepth>
    <!--maxVel>0.1</maxVel-->
    <kp>10000000.0</kp>
    <kd>100000.0</kd>
  </gazebo>
  <gazebo reference="right_hand_r">
    <!--material>Gazebo/Blue</material-->
    <mu1>70</mu1>
    <mu2>70</mu2>
    <minDepth>0.001</minDepth>
    <!--maxVel>0.1</maxVel-->
    <kp>10000000.0</kp>
    <kd>100000.0</kd>
  </gazebo>
  <gazebo reference="right_hand_n">
    <!--material>Gazebo/Blue</material-->
    <mu1>70</mu1>
    <mu2>70</mu2>
    <minDepth>0.001</minDepth>
    <!--maxVel>0.1</maxVel-->
    <kp>10000000.0</kp>
    <kd>100000.0</kd>
  </gazebo>
  <gazebo reference="right_hand_j">
    <!--material>Gazebo/Blue</material-->
    <mu1>70</mu1>
    <mu2>70</mu2>
    <minDepth>0.001</minDepth>
    <!--maxVel>0.1</maxVel-->
    <kp>10000000.0</kp>
    <kd>100000.0</kd>
  </gazebo>
  <gazebo reference="right_hand_q">
    <!--material>Gazebo/Blue</material-->
    <mu1>70</mu1>
    <mu2>70</mu2>
    <minDepth>0.001</minDepth>
    <!--maxVel>0.1</maxVel-->
    <kp>10000000.0</kp>
    <kd>100000.0</kd>
  </gazebo>
  <gazebo reference="right_hand_m">
    <!--material>Gazebo/Blue</material-->
    <mu1>70</mu1>
    <mu2>70</mu2>
    <minDepth>0.001</minDepth>
    <!--maxVel>0.1</maxVel-->
    <kp>10000000.0</kp>
    <kd>100000.0</kd>
  </gazebo>
  <gazebo reference="right_hand_i">
    <!--material>Gazebo/Blue</material-->
    <mu1>70</mu1>
    <mu2>70</mu2>
    <minDepth>0.001</minDepth>
    <!--maxVel>0.1</maxVel-->
    <kp>10000000.0</kp>
    <kd>100000.0</kd>
  </gazebo>
  <gazebo reference="right_hand_d">
    <!--material>Gazebo/Blue</material-->
    <mu1>70</mu1>
    <mu2>70</mu2>
    <minDepth>0.001</minDepth>
    <!--maxVel>0.1</maxVel-->
    <kp>10000000.0</kp>
    <kd>100000.0</kd>
  </gazebo>
  
</robot>

