<?xml version="1.0" ?>
<!-- =================================================================================== -->
<!-- |    This document was autogenerated by xacro from /home/brian/catkin_baxter/src/baxter_common/baxter_description/urdf/baxter.urdf.xacro | -->
<!-- |    EDITING THIS FILE BY HAND IS NOT RECOMMENDED                                 | -->
<!-- =================================================================================== -->
<robot name="baxter_gripper" xmlns:xacro="http://www.ros.org/wiki/xacro">
  
  <link name="right_wrist">
    <visual>
      <origin rpy="0 0 0" xyz="0 0 0"/>
      <geometry>
        <mesh filename="meshes/wrist/W2.STL"/>
      </geometry>
      <material name="lightgrey">
        <color rgba=".1 .1 .1 1"/>
      </material>
    </visual>
    <collision>
      <origin rpy="0 0 0" xyz="0 0 0.06"/>
      <geometry>
        <cylinder length="0.0165" radius="0.06"/>
      </geometry>
    </collision>
    <inertial>
      <origin rpy="0 0 0" xyz="0.00198 0.00125 0.01855"/>
      <mass value="0.35093"/>
      <inertia ixx="0.00025289155" ixy="0.00000575311" ixz="-0.00000159345" iyy="0.0002688601" iyz="-0.00000519818" izz="0.0003074118"/>
    </inertial>
  </link>
  <link name="right_hand">
    <collision>
      <origin rpy="0 0 0" xyz="0 0 -0.0232"/>
      <geometry>
        <cylinder length="0.0464" radius="0.04"/>
      </geometry>
    </collision>
    <inertial>
      <origin rpy="0 0 0" xyz="0.01093 0.00042 -0.01532"/>
      <mass value="0.19125"/>
      <inertia ixx="0.00017588" ixy="0.00000147073" ixz="0.0000243633" iyy="0.00021166377" iyz="0.00000172689" izz="0.00023745397"/>
    </inertial>
  </link>
  <link name="right_hand_camera">
    <visual>
      <origin rpy="0 0 0" xyz="0 0 0"/>
      <geometry>
        <cylinder length="0.01" radius="0.02"/>
      </geometry>
      <material name="blue">
        <color rgba="0 0 1 0.8"/>
      </material>
    </visual>
    <inertial>
      <origin rpy="0 0 0" xyz="0 0 0"/>
      <mass value="0.0001"/>
      <inertia ixx="1e-08" ixy="0" ixz="0" iyy="1e-08" iyz="0" izz="1e-08"/>
    </inertial>
  </link>
  <link name="right_hand_camera_axis">
    <inertial>
      <origin rpy="0 0 0" xyz="0 0 0"/>
      <mass value="0.0001"/>
      <inertia ixx="1e-08" ixy="0" ixz="0" iyy="1e-08" iyz="0" izz="1e-08"/>
    </inertial>
  </link>
  <link name="right_hand_range">
    <visual>
      <origin rpy="0 0 0" xyz="0 0 0"/>
      <geometry>
        <box size="0.005 .02 .005"/>
      </geometry>
      <material name="blue">
        <color rgba="0 0 1 0.8"/>
      </material>
    </visual>
    <inertial>
      <origin rpy="0 0 0" xyz="0 0 0"/>
      <mass value="0.0001"/>
      <inertia ixx="1e-08" ixy="0" ixz="0" iyy="1e-08" iyz="0" izz="1e-08"/>
    </inertial>
  </link>
  <link name="right_hand_accelerometer">
    <visual>
      <origin rpy="0 0 0" xyz="0 0 0"/>
      <geometry>
        <box size="0.01 0.01 0.01"/>
      </geometry>
      <material name="black">
        <color rgba="0 0 0 1"/>
      </material>
    </visual>
    <inertial>
      <origin rpy="0 0 0" xyz="0.000000 0.000000 0.000000"/>
      <mass value="0.0001"/>
      <inertia ixx="1e-08" ixy="0" ixz="0" iyy="1e-08" iyz="0" izz="1e-08"/>
    </inertial>
  </link>

  <joint name="right_hand" type="fixed">
    <origin rpy="0 0 0" xyz="0 0 0.11355"/>
    <axis xyz="0 0 1"/>
    <parent link="right_wrist"/>
    <child link="right_hand"/>
  </joint>
  <joint name="right_hand_camera" type="fixed">
    <origin rpy="0 0 -1.57079633" xyz="0.03825 0.012 0.015355"/>
    <parent link="right_hand"/>
    <child link="right_hand_camera"/>
  </joint>
  <joint name="right_hand_camera_axis" type="fixed">
    <origin rpy="0 0 0" xyz="0.03825 0.012 0.015355"/>
    <parent link="right_hand"/>
    <child link="right_hand_camera_axis"/>
  </joint>
  <joint name="right_hand_range" type="fixed">
    <origin rpy="0 -1.57079632679 -1.57079632679" xyz="0.032 -0.020245 0.0288"/>
    <parent link="right_hand"/>
    <child link="right_hand_range"/>
  </joint>
  <joint name="right_hand_accelerometer" type="fixed">
    <origin rpy="0 0 0" xyz="0.00198 0.000133 -0.0146"/>
    <parent link="right_hand"/>
    <child link="right_hand_accelerometer"/>
  </joint>

  <!-- Base of end effector -->
  <link name="right_gripper_base">
    <visual>
      <origin rpy="-1.57079632679 3.14159265359 0" xyz="0 0 0"/>
      <geometry>
        <mesh filename="meshes/electric_gripper/electric_gripper_base.STL"/>
      </geometry>
    </visual>
    <collision>
      <origin rpy="-1.57079632679 3.14159265359 0" xyz="0.0 0.0 0"/>
      <geometry>
        <cylinder length="0.1" radius="0.029"/>
      </geometry>
      <material name="darkred">
        <color rgba=".5 .1 .1 1"/>
      </material>
    </collision>
    <inertial>
      <origin rpy="-1.57079632679 3.14159265359 0" xyz="0.0 0.0 0.0"/>
      <mass value="0.3"/>
      <inertia ixx="2e-08" ixy="0" ixz="0" iyy="3e-08" iyz="0" izz="2e-08"/>
    </inertial>
  </link>
  <link name="r_gripper_l_finger">
    <visual>
      <origin rpy="0 0 -3.14159265359" xyz="0 0 0"/>
      <geometry>
        <mesh filename="meshes/electric_gripper/fingers/extended_narrow.STL"/>
      </geometry>
    </visual>
    <collision>
      <origin rpy="0 0 -3.14159265359" xyz="0 0.01725 0.0615"/>
      <geometry>
        <box size="0.01 0.0135 0.1127"/>
      </geometry>
    </collision>
    <collision>
      <origin rpy="0 0 -3.14159265359" xyz="-0.005 -0.003 0.0083"/>
      <geometry>
        <box size="0.01 0.05 0.017"/>
      </geometry>
    </collision>
    <inertial>
      <origin rpy="0 0 -3.14159265359" xyz="0 0 0"/>
      <mass value="0.02"/>
      <inertia ixx="0.01" ixy="0" ixz="0" iyy="0.01" iyz="0" izz="0.01"/>
    </inertial>
  </link>
  <gazebo reference="r_gripper_l_finger">
    <mu1>1000</mu1>
    <mu2>1000</mu2>
    <fdir1>0.0 0.0 1.0</fdir1>
    <kp>1e5</kp>
    <kd>1.0</kd>
  </gazebo>
  <link name="r_gripper_l_finger_tip">
    <visual>
      <origin rpy="0 0 3.14159265359" xyz="0 0 0"/>
      <geometry>
        <mesh filename="meshes/electric_gripper/fingers/half_round_tip.STL"/>
      </geometry>
    </visual>
    <collision>
      <origin rpy="0 0 3.14159265359" xyz="0 -0.0045 -0.015"/>
      <geometry>
        <cylinder length="0.037" radius="0.008"/>
      </geometry>
    </collision>
    <inertial>
      <origin rpy="0 0 3.14159265359" xyz="0 0 0"/>
      <mass value="0.01"/>
      <inertia ixx="0.01" ixy="0" ixz="0" iyy="0.01" iyz="0" izz="0.01"/>
    </inertial>
  </link>
  <joint name="r_gripper_l_finger_tip_joint" type="fixed">
    <origin rpy="0 0 0" xyz="0.0 0.01725 0.1127"/>
    <parent link="r_gripper_l_finger"/>
    <child link="r_gripper_l_finger_tip"/>
  </joint>
  <link name="r_gripper_r_finger">
    <visual>
      <origin rpy="0 0 -0.0" xyz="0 0 0"/>
      <geometry>
        <mesh filename="meshes/electric_gripper/fingers/extended_narrow.STL"/>
      </geometry>
    </visual>
    <collision>
      <origin rpy="0 0 -0.0" xyz="0 -0.01725 0.0615"/>
      <geometry>
        <box size="0.01 0.0135 0.1127"/>
      </geometry>
    </collision>
    <collision>
      <origin rpy="0 0 -0.0" xyz="0.005 0.003 0.0083"/>
      <geometry>
        <box size="0.01 0.05 0.017"/>
      </geometry>
    </collision>
    <inertial>
      <origin rpy="0 0 -0.0" xyz="0 0 0"/>
      <mass value="0.02"/>
      <inertia ixx="0.01" ixy="0" ixz="0" iyy="0.01" iyz="0" izz="0.01"/>
    </inertial>
  </link>
  <gazebo reference="r_gripper_r_finger">
    <mu1>1000</mu1>
    <mu2>1000</mu2>
    <fdir1>0.0 0.0 1.0</fdir1>
    <kp>1e5</kp>
    <kd>1.0</kd>
  </gazebo>
  <link name="r_gripper_r_finger_tip">
    <visual>
      <origin rpy="0 0 0.0" xyz="0 0 0"/>
      <geometry>
        <mesh filename="meshes/electric_gripper/fingers/half_round_tip.STL"/>
      </geometry>
    </visual>
    <collision>
      <origin rpy="0 0 0.0" xyz="0 0.0045 -0.015"/>
      <geometry>
        <cylinder length="0.037" radius="0.008"/>
      </geometry>
    </collision>
    <inertial>
      <origin rpy="0 0 0.0" xyz="0 0 0"/>
      <mass value="0.01"/>
      <inertia ixx="0.01" ixy="0" ixz="0" iyy="0.01" iyz="0" izz="0.01"/>
    </inertial>
  </link>
  <joint name="r_gripper_r_finger_tip_joint" type="fixed">
    <origin rpy="0 0 0" xyz="0.0 -0.01725 0.1127"/>
    <parent link="r_gripper_r_finger"/>
    <child link="r_gripper_r_finger_tip"/>
  </joint>
  <!-- Electric Gripper Base Joint -->
  <joint name="right_gripper_base" type="fixed">
    <origin rpy="0 0 0" xyz="0 0 0.025"/>
    <parent link="right_hand"/>
    <child link="right_gripper_base"/>
  </joint>
  <!-- Electric Gripper Tip joint -->
  <joint name="right_endpoint" type="fixed">
    <origin rpy="0 0 0" xyz="0 0 0.1327"/>
    <parent link="right_gripper_base"/>
    <child link="right_gripper"/>
  </joint>
  <!-- Electric Gripper Tip link -->
  <link name="right_gripper">
    <inertial>
      <origin rpy="0 0 0" xyz="0 0 0"/>
      <mass value="0.0001"/>
      <inertia ixx="0" ixy="0" ixz="0" iyy="0" iyz="0" izz="0.0"/>
    </inertial>
  </link>
  <joint name="r_gripper_l_finger_joint" type="prismatic">
    <origin rpy="0 0 0" xyz="0.0 -0.0015 0.02"/>
    <axis xyz="0 1 0"/>
    <parent link="right_gripper_base"/>
    <child link="r_gripper_l_finger"/>
    <limit effort="20.0" lower="0.0" upper="0.020833" velocity="5.0"/>
    <dynamics damping="0.7" friction="0.0"/>
  </joint>
  <joint name="r_gripper_r_finger_joint" type="prismatic">
    <origin rpy="0 0 0" xyz="0.0 0.0015 0.02"/>
    <axis xyz="0 1 0"/>
    <parent link="right_gripper_base"/>
    <child link="r_gripper_r_finger"/>
    <limit effort="20.0" lower="-0.020833" upper="0.0" velocity="5.0"/>
    <mimic joint="r_gripper_l_finger_joint" multiplier="-1.0"/>
    <dynamics damping="0.7" friction="0.0"/>
  </joint>
  <transmission name="gripper_right1">
    <type>transmission_interface/SimpleTransmission</type>
    <joint name="r_gripper_r_finger_joint">
      <hardwareInterface>EffortJointInterface</hardwareInterface>
    </joint>
    <actuator name="gripper_r1_motor1">
      <hardwareInterface>EffortJointInterface</hardwareInterface>
      <mechanicalReduction>1</mechanicalReduction>
    </actuator>
  </transmission>
  <transmission name="gripper_right2">
    <type>transmission_interface/SimpleTransmission</type>
    <joint name="r_gripper_l_finger_joint">
      <hardwareInterface>EffortJointInterface</hardwareInterface>
    </joint>
    <actuator name="gripper_r1_motor2">
      <hardwareInterface>EffortJointInterface</hardwareInterface>
      <mechanicalReduction>1</mechanicalReduction>
    </actuator>
  </transmission>
  <gazebo reference="r_gripper_r_finger_joint">
    <implicitSpringDamper>1</implicitSpringDamper>
  </gazebo>
  <gazebo reference="r_gripper_l_finger_joint">
    <implicitSpringDamper>1</implicitSpringDamper>
  </gazebo>

</robot>

