<?xml version="1.0" ?>
<!-- =================================================================================== -->
<!-- |    This document was autogenerated by xacro from /home/brian/catkin_softhand/src/pisa-iit-soft-hand/soft_hand_description/model/soft_hand_example.urdf.xacro | -->
<!-- |    EDITING THIS FILE BY HAND IS NOT RECOMMENDED                                 | -->
<!-- =================================================================================== -->
<robot name="soft_hand" xmlns:xacro="http://www.ros.org/wiki/xacro">
  <material name="SoftHand/LightGrey">
    <color rgba="0.7 0.7 0.7 1.0"/>
  </material>
  <material name="SoftHand/DarkGrey">
    <color rgba="0.4 0.4 0.4 1.0"/>
  </material>
  <material name="SoftHand/Black">
    <color rgba="0.0 0.0 0.0 1.0"/>
  </material>
  <material name="SoftHand/DarkGolden">
    <color rgba="0.4 0.4 0.3 1.0"/>
  </material>
  <material name="SoftHand/Blue">
    <color rgba="0.0 0.0 0.8 0.9"/>
  </material>
  <material name="SoftHand/LightBlue">
    <color rgba="0.0 0.4 1.0 0.5"/>
  </material>
  <!-- <xacro:insert_block name="gazebo_friction_properties"/> -->
  <!-- <xacro:insert_block name="gazebo_other_properties"/> -->
  <!-- NOTE: inertia values are approximated using meshlab and only using the significant elements -->
  <!-- from http://answers.ros.org/question/11350/is-there-any-way-to-calculate-inertial-property-of-a-robot-to-simulate-it-in-gazebo/s
    One general rule of thumb I use for checking my inertia tensors is: If total mass of the rigid body is m, and the dimension of the corresponding body is d, then check to see if ixx, iyy, izz are near m*(d/2)^2.

    This is by no means correct, but a sanity check to make sure the moment of inertia are the right order of magnitudes, so the model behaves somewhat physically realistically.
    -->
  <!-- PACMAN VERION ALREADY INCLUDES THE COUPLER, CLAMP AND BASE -->
  <!--joint name="box_left_hand_kuka_coupler_joint" type="fixed">
    <origin rpy="0 0 0" xyz="0.0 0.0 0.0"/>
    <parent link="box"/>
    <child link="left_hand_kuka_coupler_bottom"/>
  </joint-->
  <link name="left_hand_kuka_coupler_bottom">
    <inertial>
      <origin rpy="0 0 0" xyz="0 0 0"/>
      <mass value="0"/>
      <inertia ixx="0.0" ixy="0.0" ixz="0.0" iyy="0.0" iyz="0.0" izz="0.0"/>
    </inertial> <!-- in pybullet, the inertia need to be specified even for dummy links, otherwise it will put an identity inertia and a mass of 1 by default -->
    <visual>
      <origin rpy="0 0 0" xyz="0 0 0.0115"/>
      <geometry>
        <!-- mesh filename="meshes/accesories/kuka_coupler.stl"/-->
        <cylinder length="0.023" radius="0.033"/>
      </geometry>
      <material name="SoftHand/Blue"/>
    </visual>
    <collision>
      <origin rpy="0 0 0" xyz="0 0 0.031"/>
      <geometry>
        <cylinder length="0.023" radius="0.033"/>
      </geometry>
    </collision>
  </link>
  <joint name="box_left_hand_kuka_coupler_base_joint" type="fixed">
    <origin rpy="0 0 0" xyz="0 0 0.023"/>
    <parent link="left_hand_kuka_coupler_bottom"/>
    <child link="left_hand_kuka_coupler"/>
  </joint>
  <link name="left_hand_kuka_coupler">
    <inertial>
      <origin rpy="0 0 0" xyz="0 0 0"/>
      <mass value="0"/>
      <inertia ixx="0.0" ixy="0.0" ixz="0.0" iyy="0.0" iyz="0.0" izz="0.0"/>
    </inertial> <!-- in pybullet, the inertia need to be specified even for dummy links, otherwise it will put an identity inertia and a mass of 1 by default -->
  </link>
  <joint name="left_hand_kuka_coupler_left_hand_clamp_joint" type="fixed">
    <origin rpy="0 0 0" xyz="0 0 0.01"/>
    <parent link="left_hand_kuka_coupler"/>
    <child link="left_hand_clamp"/>
  </joint>
  <link name="left_hand_clamp">
    <inertial>
      <origin rpy="0 0 0" xyz="0 0 0"/>
      <mass value="0"/>
      <inertia ixx="0.0" ixy="0.0" ixz="0.0" iyy="0.0" iyz="0.0" izz="0.0"/>
    </inertial> <!-- in pybullet, the inertia need to be specified even for dummy links, otherwise it will put an identity inertia and a mass of 1 by default -->
    <visual>
      <origin rpy="0 0 0" xyz="0 0 0"/>
      <geometry>
        <mesh filename="meshes/accesories/clamp.stl"/>
      </geometry>
      <material name="SoftHand/Blue"/>
    </visual>
    <collision>
      <origin rpy="0 0 0" xyz="0 0 0"/>
      <geometry>
        <box size="0.066 0.0725 0.0256"/>
      </geometry>
    </collision>
  </link>
  <joint name="left_hand_clamp_left_hand_softhand_base_joint" type="fixed">
    <origin rpy="0 0 0" xyz="0 0 0.004"/>
    <parent link="left_hand_clamp"/>
    <child link="left_hand_softhand_base"/>
  </joint>
  <link name="left_hand_softhand_base">
    <inertial>
      <origin rpy="0 0 0" xyz="0 0 0"/>
      <mass value="0"/>
      <inertia ixx="0.0" ixy="0.0" ixz="0.0" iyy="0.0" iyz="0.0" izz="0.0"/>
    </inertial> <!-- in pybullet, the inertia need to be specified even for dummy links, otherwise it will put an identity inertia and a mass of 1 by default -->
    <visual>
      <origin rpy="0 0 0" xyz="0 0 0"/>
      <geometry>
        <mesh filename="meshes/accesories/softhand_base_left.stl"/>
      </geometry>
      <material name="SoftHand/Blue"/>
    </visual>
    <collision>
      <origin rpy="0 0 0" xyz="0 0 0.031"/>
      <geometry>
        <box size="0.066 0.066 0.062"/>
      </geometry>
    </collision>
  </link>
  <!-- PALM -->
  <joint name="left_hand_palm_joint" type="fixed">
    <origin rpy="0 0 0" xyz="0.002 -0.00695 0.0535"/>
    <parent link="left_hand_softhand_base"/>
    <child link="left_hand_palm_link"/>
  </joint>
  <link name="left_hand_palm_link">
    <inertial>
      <origin xyz="-0.004568758 -0.006808116 0.027653328"/>
      <mass value="2.28"/>
      <inertia ixx="1.6302" ixy="0.0228" ixz="0.0228" iyy="0.9462" iyz="0.0456" izz="1.1058"/>
    </inertial>
    <visual>
      <geometry>
        <mesh filename="meshes/palm_left.stl" scale=" .001 .001 .001"/>
      </geometry>
      <material name="SoftHand/DarkGrey"/>
    </visual>
    <collision>
      <geometry>
        <mesh filename="meshes/palm_left_collision.stl" scale=" .001 .001 .001"/>
      </geometry>
    </collision>
  </link>
  <!-- MOTOR JOINT -->
  <joint name="left_hand_synergy_joint" type="revolute">
    <parent link="left_hand_palm_link"/>
    <child link="left_hand_invisible_wire_link"/>
    <axis xyz="0 0 1"/>
    <limit effort="100" lower="0.0" upper="1.0" velocity="100000"/>
    <dynamics damping="0.0" friction="0.0"/>
  </joint>
  <link name="left_hand_invisible_wire_link">
    <inertial>
      <origin xyz="0 0 0"/>
      <mass value="0.1"/>
      <inertia ixx="0.001" ixy="0.0" ixz="0.0" iyy="0.001" iyz="0.0" izz="0.001"/>
    </inertial>
  </link>
  <!-- KNUCKLE -->
  <joint name="left_hand_thumb_abd_joint" type="revolute">
    <origin rpy="0.0 -0.38397275793662144 -1.5707963267948966" xyz="0.005669722 -0.029616 0.055314"/>
    <parent link="left_hand_palm_link"/>
    <child link="left_hand_thumb_knuckle_link"/>
    <axis xyz="0 0 1"/>
    <limit effort="100" lower="0.0" upper="1.57079632679" velocity="100"/>
    <dynamics damping="0.0" friction="0.0"/>
  </joint>
  <link name="left_hand_thumb_knuckle_link">
    <inertial>
      <origin xyz="0.013608098 -0.000532174 -0.000216691"/>
      <mass value="0.09"/>
      <inertia ixx="0.00315" ixy="0.00027" ixz="-0.00054" iyy="0.009" iyz="0.00018" izz="0.009"/>
    </inertial>
    <visual>
      <geometry>
        <mesh filename="meshes/thumb_knuckle_left.stl" scale=" .001 .001 .001"/>
      </geometry>
      <material name="SoftHand/DarkGrey"/>
    </visual>
    <collision>
      <geometry>
        <mesh filename="meshes/thumb_knuckle_left_collision.stl" scale=" .001 .001 .001"/>
      </geometry>
    </collision>
  </link>
  <!-- PROXIMAL PHALANGE -->
  <joint name="left_hand_thumb_inner_joint" type="revolute">
    <origin rpy="-0.426627741408745 0 0.0" xyz="0.022500000 0.003300000 0.0"/>
    <parent link="left_hand_thumb_knuckle_link"/>
    <child link="left_hand_thumb_fake_link1"/>
    <axis xyz="0 -1 0"/>
    <limit effort="100" lower="0.0" upper="0.785398163397" velocity="100"/>
    <dynamics damping="0.0" friction="0.0"/>
  </joint>
  <link name="left_hand_thumb_fake_link1">
    <inertial>
      <origin xyz="0 0 0"/>
      <mass value="0.1"/>
      <inertia ixx="0.001" ixy="0.0" ixz="0.0" iyy="0.001" iyz="0.0" izz="0.001"/>
    </inertial>
  </link>
  <joint name="left_hand_thumb_inner_joint_mimic" type="revolute">
    <origin rpy="0 0 0" xyz="0.013 0 0"/>
    <parent link="left_hand_thumb_fake_link1"/>
    <child link="left_hand_thumb_proximal_link"/>
    <axis xyz="0 -1 0"/>
    <limit effort="100" lower="0.0" upper="0.785398163397" velocity="100"/>
    <dynamics damping="0.0" friction="0.0"/>
  </joint>
  <link name="left_hand_thumb_proximal_link">
    <inertial>
      <origin xyz="0.005074337 -4.524e-06 -0.000262953"/>
      <mass value="0.05"/>
      <inertia ixx="0.00175" ixy="0.0" ixz="0.0001" iyy="0.00275" iyz="0.0" izz="0.00275"/>
    </inertial>
    <visual>
      <geometry>
        <mesh filename="meshes/phalanx.stl" scale=" .001 .001 .001"/>
      </geometry>
      <material name="SoftHand/DarkGrey"/>
    </visual>
    <collision>
      <geometry>
        <mesh filename="meshes/phalanx_collision.stl" scale=" .001 .001 .001"/>
      </geometry>
    </collision>
  </link>
  <!-- DISTAL PHALANGE -->
  <joint name="left_hand_thumb_outer_joint" type="revolute">
    <origin rpy="0 0 0" xyz="0.009 0 0.0"/>
    <parent link="left_hand_thumb_proximal_link"/>
    <child link="left_hand_thumb_fake_link3"/>
    <axis xyz="0 -1 0"/>
    <limit effort="100" lower="0.0" upper="0.785398163397" velocity="100"/>
    <dynamics damping="0.0" friction="0.0"/>
  </joint>
  <link name="left_hand_thumb_fake_link3">
    <inertial>
      <origin xyz="0 0 0"/>
      <mass value="0.1"/>
      <inertia ixx="0.001" ixy="0.0" ixz="0.0" iyy="0.001" iyz="0.0" izz="0.001"/>
    </inertial>
  </link>
  <joint name="left_hand_thumb_outer_joint_mimic" type="revolute">
    <origin rpy="0 0 0" xyz="0.013 0 0"/>
    <parent link="left_hand_thumb_fake_link3"/>
    <child link="left_hand_thumb_distal_link"/>
    <axis xyz="0 -1 0"/>
    <limit effort="100" lower="0.0" upper="0.785398163397" velocity="100"/>
    <dynamics damping="0.0" friction="0.0"/>
  </joint>
  <link name="left_hand_thumb_distal_link">
    <inertial>
      <origin xyz="0.009849094 5.6e-07 0.000820286"/>
      <mass value="0.1"/>
      <inertia ixx="0.0035" ixy="0.0" ixz="0.0002" iyy="0.008" iyz="0.0" izz="0.0076"/>
    </inertial>
    <visual>
      <geometry>
        <mesh filename="meshes/fingertip.stl" scale=" .001 .001 .001"/>
      </geometry>
      <material name="SoftHand/DarkGrey"/>
    </visual>
    <collision>
      <geometry>
        <mesh filename="meshes/fingertip_collision.stl" scale=" .001 .001 .001"/>
      </geometry>
    </collision>
  </link>
  <!-- KNUCKLE -->
  <joint name="left_hand_index_abd_joint" type="revolute">
    <origin rpy="-1.5707963267948966 -1.4835299330931884 -1.5707963267948966" xyz="-0.0033 -0.0195 0.0936994"/>
    <parent link="left_hand_palm_link"/>
    <child link="left_hand_index_knuckle_link"/>
    <axis xyz="0 0 -1"/>
    <limit effort="100" lower="-0.523598775598" upper="0.523598775598" velocity="100"/>
    <dynamics damping="0.0" friction="0.0"/>
  </joint>
  <link name="left_hand_index_knuckle_link">
    <inertial>
      <origin xyz="0.001285644 -9.58e-07 0.000425011"/>
      <mass value="0.09"/>
      <inertia ixx="0.00405" ixy="0.0" ixz="0.00045" iyy="0.0081" iyz="0.0" izz="0.0063"/>
    </inertial>
    <visual>
      <geometry>
        <mesh filename="meshes/knuckle.stl" scale=" .001 .001 .001"/>
      </geometry>
      <material name="SoftHand/DarkGrey"/>
    </visual>
    <collision>
      <geometry>
        <mesh filename="meshes/knuckle_collision.stl" scale=" .001 .001 .001"/>
      </geometry>
    </collision>
  </link>
  <!-- PROXIMAL PHALANGE -->
  <joint name="left_hand_index_inner_joint" type="revolute">
    <origin rpy="0 0 0" xyz="0.009 0 0"/>
    <parent link="left_hand_index_knuckle_link"/>
    <child link="left_hand_index_fake_link1"/>
    <axis xyz="0 -1 0"/>
    <limit effort="100" lower="0.0" upper="0.785398163397" velocity="100"/>
    <dynamics damping="0.0" friction="0.0"/>
  </joint>
  <link name="left_hand_index_fake_link1">
    <inertial>
      <origin xyz="0 0 0"/>
      <mass value="0.1"/>
      <inertia ixx="0.001" ixy="0.0" ixz="0.0" iyy="0.001" iyz="0.0" izz="0.001"/>
    </inertial>
  </link>
  <joint name="left_hand_index_inner_joint_mimic" type="revolute">
    <origin rpy="0 0 0" xyz="0.013 0 0"/>
    <parent link="left_hand_index_fake_link1"/>
    <child link="left_hand_index_proximal_link"/>
    <axis xyz="0 -1 0"/>
    <limit effort="100" lower="0.0" upper="0.785398163397" velocity="100"/>
    <dynamics damping="0.0" friction="0.0"/>
  </joint>
  <link name="left_hand_index_proximal_link">
    <inertial>
      <origin xyz="0.005074337 -4.524e-06 -0.000262953"/>
      <mass value="0.05"/>
      <inertia ixx="0.00175" ixy="0.0" ixz="0.0001" iyy="0.00275" iyz="0.0" izz="0.00275"/>
    </inertial>
    <visual>
      <geometry>
        <mesh filename="meshes/phalanx.stl" scale=" .001 .001 .001"/>
      </geometry>
      <material name="SoftHand/DarkGrey"/>
    </visual>
    <collision>
      <geometry>
        <mesh filename="meshes/phalanx_collision.stl" scale=" .001 .001 .001"/>
      </geometry>
    </collision>
  </link>
  <!-- MIDDLE PHALANGE -->
  <joint name="left_hand_index_middle_joint" type="revolute">
    <origin rpy="0 0 0" xyz="0.009 0 0"/>
    <parent link="left_hand_index_proximal_link"/>
    <child link="left_hand_index_fake_link2"/>
    <axis xyz="0 -1 0"/>
    <limit effort="100" lower="0.0" upper="0.785398163397" velocity="100"/>
    <dynamics damping="0.0" friction="0.0"/>
  </joint>
  <link name="left_hand_index_fake_link2">
    <inertial>
      <origin xyz="0 0 0"/>
      <mass value="0.1"/>
      <inertia ixx="0.001" ixy="0.0" ixz="0.0" iyy="0.001" iyz="0.0" izz="0.001"/>
    </inertial>
  </link>
  <joint name="left_hand_index_middle_joint_mimic" type="revolute">
    <origin rpy="0 0 0" xyz="0.013 0 0"/>
    <parent link="left_hand_index_fake_link2"/>
    <child link="left_hand_index_middle_link"/>
    <axis xyz="0 -1 0"/>
    <limit effort="100" lower="0.0" upper="0.785398163397" velocity="100"/>
    <dynamics damping="0.0" friction="0.0"/>
  </joint>
  <link name="left_hand_index_middle_link">
    <inertial>
      <origin xyz="0.005074337 -4.524e-06 -0.000262953"/>
      <mass value="0.05"/>
      <inertia ixx="0.00175" ixy="0.0" ixz="0.0001" iyy="0.00275" iyz="0.0" izz="0.00275"/>
    </inertial>
    <visual>
      <geometry>
        <mesh filename="meshes/phalanx.stl" scale=" .001 .001 .001"/>
      </geometry>
      <material name="SoftHand/DarkGrey"/>
    </visual>
    <collision>
      <geometry>
        <mesh filename="meshes/phalanx_collision.stl" scale=" .001 .001 .001"/>
      </geometry>
    </collision>
  </link>
  <!-- DISTAL PHALANGE -->
  <joint name="left_hand_index_outer_joint" type="revolute">
    <origin rpy="0 0 0" xyz="0.009 0 0"/>
    <parent link="left_hand_index_middle_link"/>
    <child link="left_hand_index_fake_link3"/>
    <axis xyz="0 -1 0"/>
    <limit effort="100" lower="0.0" upper="0.785398163397" velocity="100"/>
    <dynamics damping="0.0" friction="0.0"/>
  </joint>
  <link name="left_hand_index_fake_link3">
    <inertial>
      <origin xyz="0 0 0"/>
      <mass value="0.1"/>
      <inertia ixx="0.001" ixy="0.0" ixz="0.0" iyy="0.001" iyz="0.0" izz="0.001"/>
    </inertial>
  </link>
  <joint name="left_hand_index_outer_joint_mimic" type="revolute">
    <origin rpy="0 0 0" xyz="0.013 0 0"/>
    <parent link="left_hand_index_fake_link3"/>
    <child link="left_hand_index_distal_link"/>
    <axis xyz="0 -1 0"/>
    <limit effort="100" lower="0.0" upper="0.785398163397" velocity="100"/>
    <dynamics damping="0.0" friction="0.0"/>
  </joint>
  <link name="left_hand_index_distal_link">
    <inertial>
      <origin xyz="0.009849094 5.6e-07 0.000820286"/>
      <mass value="0.1"/>
      <inertia ixx="0.0035" ixy="0.0" ixz="0.0002" iyy="0.008" iyz="0.0" izz="0.0076"/>
    </inertial>
    <visual>
      <geometry>
        <mesh filename="meshes/fingertip.stl" scale=" .001 .001 .001"/>
      </geometry>
      <material name="SoftHand/DarkGrey"/>
    </visual>
    <collision>
      <geometry>
        <mesh filename="meshes/fingertip_collision.stl" scale=" .001 .001 .001"/>
      </geometry>
    </collision>
  </link>
  <!-- KNUCKLE -->
  <joint name="left_hand_middle_abd_joint" type="revolute">
    <origin rpy="3.1415 -1.5707963267948966 0.0" xyz="-0.0033 0.0 0.100699"/>
    <parent link="left_hand_palm_link"/>
    <child link="left_hand_middle_knuckle_link"/>
    <axis xyz="0 0 -1"/>
    <limit effort="100" lower="-0.523598775598" upper="0.523598775598" velocity="100"/>
    <dynamics damping="0.0" friction="0.0"/>
  </joint>
  <link name="left_hand_middle_knuckle_link">
    <inertial>
      <origin xyz="0.001285644 -9.58e-07 0.000425011"/>
      <mass value="0.09"/>
      <inertia ixx="0.00405" ixy="0.0" ixz="0.00045" iyy="0.0081" iyz="0.0" izz="0.0063"/>
    </inertial>
    <visual>
      <geometry>
        <mesh filename="meshes/knuckle.stl" scale=" .001 .001 .001"/>
      </geometry>
      <material name="SoftHand/DarkGrey"/>
    </visual>
    <collision>
      <geometry>
        <mesh filename="meshes/knuckle_collision.stl" scale=" .001 .001 .001"/>
      </geometry>
    </collision>
  </link>
  <!-- PROXIMAL PHALANGE -->
  <joint name="left_hand_middle_inner_joint" type="revolute">
    <origin rpy="0 0 0" xyz="0.009 0 0"/>
    <parent link="left_hand_middle_knuckle_link"/>
    <child link="left_hand_middle_fake_link1"/>
    <axis xyz="0 -1 0"/>
    <limit effort="100" lower="0.0" upper="0.785398163397" velocity="100"/>
    <dynamics damping="0.0" friction="0.0"/>
  </joint>
  <link name="left_hand_middle_fake_link1">
    <inertial>
      <origin xyz="0 0 0"/>
      <mass value="0.1"/>
      <inertia ixx="0.001" ixy="0.0" ixz="0.0" iyy="0.001" iyz="0.0" izz="0.001"/>
    </inertial>
  </link>
  <joint name="left_hand_middle_inner_joint_mimic" type="revolute">
    <origin rpy="0 0 0" xyz="0.013 0 0"/>
    <parent link="left_hand_middle_fake_link1"/>
    <child link="left_hand_middle_proximal_link"/>
    <axis xyz="0 -1 0"/>
    <limit effort="100" lower="0.0" upper="0.785398163397" velocity="100"/>
    <dynamics damping="0.0" friction="0.0"/>
  </joint>
  <link name="left_hand_middle_proximal_link">
    <inertial>
      <origin xyz="0.005074337 -4.524e-06 -0.000262953"/>
      <mass value="0.05"/>
      <inertia ixx="0.00175" ixy="0.0" ixz="0.0001" iyy="0.00275" iyz="0.0" izz="0.00275"/>
    </inertial>
    <visual>
      <geometry>
        <mesh filename="meshes/phalanx.stl" scale=" .001 .001 .001"/>
      </geometry>
      <material name="SoftHand/DarkGrey"/>
    </visual>
    <collision>
      <geometry>
        <mesh filename="meshes/phalanx_collision.stl" scale=" .001 .001 .001"/>
      </geometry>
    </collision>
  </link>
  <!-- MIDDLE PHALANGE -->
  <joint name="left_hand_middle_middle_joint" type="revolute">
    <origin rpy="0 0 0" xyz="0.009 0 0"/>
    <parent link="left_hand_middle_proximal_link"/>
    <child link="left_hand_middle_fake_link2"/>
    <axis xyz="0 -1 0"/>
    <limit effort="100" lower="0.0" upper="0.785398163397" velocity="100"/>
    <dynamics damping="0.0" friction="0.0"/>
  </joint>
  <link name="left_hand_middle_fake_link2">
    <inertial>
      <origin xyz="0 0 0"/>
      <mass value="0.1"/>
      <inertia ixx="0.001" ixy="0.0" ixz="0.0" iyy="0.001" iyz="0.0" izz="0.001"/>
    </inertial>
  </link>
  <joint name="left_hand_middle_middle_joint_mimic" type="revolute">
    <origin rpy="0 0 0" xyz="0.013 0 0"/>
    <parent link="left_hand_middle_fake_link2"/>
    <child link="left_hand_middle_middle_link"/>
    <axis xyz="0 -1 0"/>
    <limit effort="100" lower="0.0" upper="0.785398163397" velocity="100"/>
    <dynamics damping="0.0" friction="0.0"/>
  </joint>
  <link name="left_hand_middle_middle_link">
    <inertial>
      <origin xyz="0.005074337 -4.524e-06 -0.000262953"/>
      <mass value="0.05"/>
      <inertia ixx="0.00175" ixy="0.0" ixz="0.0001" iyy="0.00275" iyz="0.0" izz="0.00275"/>
    </inertial>
    <visual>
      <geometry>
        <mesh filename="meshes/phalanx.stl" scale=" .001 .001 .001"/>
      </geometry>
      <material name="SoftHand/DarkGrey"/>
    </visual>
    <collision>
      <geometry>
        <mesh filename="meshes/phalanx_collision.stl" scale=" .001 .001 .001"/>
      </geometry>
    </collision>
  </link>
  <!-- DISTAL PHALANGE -->
  <joint name="left_hand_middle_outer_joint" type="revolute">
    <origin rpy="0 0 0" xyz="0.009 0 0"/>
    <parent link="left_hand_middle_middle_link"/>
    <child link="left_hand_middle_fake_link3"/>
    <axis xyz="0 -1 0"/>
    <limit effort="100" lower="0.0" upper="0.785398163397" velocity="100"/>
    <dynamics damping="0.0" friction="0.0"/>
  </joint>
  <link name="left_hand_middle_fake_link3">
    <inertial>
      <origin xyz="0 0 0"/>
      <mass value="0.1"/>
      <inertia ixx="0.001" ixy="0.0" ixz="0.0" iyy="0.001" iyz="0.0" izz="0.001"/>
    </inertial>
  </link>
  <joint name="left_hand_middle_outer_joint_mimic" type="revolute">
    <origin rpy="0 0 0" xyz="0.013 0 0"/>
    <parent link="left_hand_middle_fake_link3"/>
    <child link="left_hand_middle_distal_link"/>
    <axis xyz="0 -1 0"/>
    <limit effort="100" lower="0.0" upper="0.785398163397" velocity="100"/>
    <dynamics damping="0.0" friction="0.0"/>
  </joint>
  <link name="left_hand_middle_distal_link">
    <inertial>
      <origin xyz="0.009849094 5.6e-07 0.000820286"/>
      <mass value="0.1"/>
      <inertia ixx="0.0035" ixy="0.0" ixz="0.0002" iyy="0.008" iyz="0.0" izz="0.0076"/>
    </inertial>
    <visual>
      <geometry>
        <mesh filename="meshes/fingertip.stl" scale=" .001 .001 .001"/>
      </geometry>
      <material name="SoftHand/DarkGrey"/>
    </visual>
    <collision>
      <geometry>
        <mesh filename="meshes/fingertip_collision.stl" scale=" .001 .001 .001"/>
      </geometry>
    </collision>
  </link>
  <!-- KNUCKLE -->
  <joint name="left_hand_ring_abd_joint" type="revolute">
    <origin rpy="1.5707963267948966 -1.5184364298870514 1.5707963267948966" xyz="-0.0033 0.0195 0.0936994"/>
    <parent link="left_hand_palm_link"/>
    <child link="left_hand_ring_knuckle_link"/>
    <axis xyz="0 0 -1"/>
    <limit effort="100" lower="-0.523598775598" upper="0.523598775598" velocity="100"/>
    <dynamics damping="0.0" friction="0.0"/>
  </joint>
  <link name="left_hand_ring_knuckle_link">
    <inertial>
      <origin xyz="0.001285644 -9.58e-07 0.000425011"/>
      <mass value="0.09"/>
      <inertia ixx="0.00405" ixy="0.0" ixz="0.00045" iyy="0.0081" iyz="0.0" izz="0.0063"/>
    </inertial>
    <visual>
      <geometry>
        <mesh filename="meshes/knuckle.stl" scale=" .001 .001 .001"/>
      </geometry>
      <material name="SoftHand/DarkGrey"/>
    </visual>
    <collision>
      <geometry>
        <mesh filename="meshes/knuckle_collision.stl" scale=" .001 .001 .001"/>
      </geometry>
    </collision>
  </link>
  <!-- PROXIMAL PHALANGE -->
  <joint name="left_hand_ring_inner_joint" type="revolute">
    <origin rpy="0 0 0" xyz="0.009 0 0"/>
    <parent link="left_hand_ring_knuckle_link"/>
    <child link="left_hand_ring_fake_link1"/>
    <axis xyz="0 -1 0"/>
    <limit effort="100" lower="0.0" upper="0.785398163397" velocity="100"/>
    <dynamics damping="0.0" friction="0.0"/>
  </joint>
  <link name="left_hand_ring_fake_link1">
    <inertial>
      <origin xyz="0 0 0"/>
      <mass value="0.1"/>
      <inertia ixx="0.001" ixy="0.0" ixz="0.0" iyy="0.001" iyz="0.0" izz="0.001"/>
    </inertial>
  </link>
  <joint name="left_hand_ring_inner_joint_mimic" type="revolute">
    <origin rpy="0 0 0" xyz="0.013 0 0"/>
    <parent link="left_hand_ring_fake_link1"/>
    <child link="left_hand_ring_proximal_link"/>
    <axis xyz="0 -1 0"/>
    <limit effort="100" lower="0.0" upper="0.785398163397" velocity="100"/>
    <dynamics damping="0.0" friction="0.0"/>
  </joint>
  <link name="left_hand_ring_proximal_link">
    <inertial>
      <origin xyz="0.005074337 -4.524e-06 -0.000262953"/>
      <mass value="0.05"/>
      <inertia ixx="0.00175" ixy="0.0" ixz="0.0001" iyy="0.00275" iyz="0.0" izz="0.00275"/>
    </inertial>
    <visual>
      <geometry>
        <mesh filename="meshes/phalanx.stl" scale=" .001 .001 .001"/>
      </geometry>
      <material name="SoftHand/DarkGrey"/>
    </visual>
    <collision>
      <geometry>
        <mesh filename="meshes/phalanx_collision.stl" scale=" .001 .001 .001"/>
      </geometry>
    </collision>
  </link>
  <!-- MIDDLE PHALANGE -->
  <joint name="left_hand_ring_middle_joint" type="revolute">
    <origin rpy="0 0 0" xyz="0.009 0 0"/>
    <parent link="left_hand_ring_proximal_link"/>
    <child link="left_hand_ring_fake_link2"/>
    <axis xyz="0 -1 0"/>
    <limit effort="100" lower="0.0" upper="0.785398163397" velocity="100"/>
    <dynamics damping="0.0" friction="0.0"/>
  </joint>
  <link name="left_hand_ring_fake_link2">
    <inertial>
      <origin xyz="0 0 0"/>
      <mass value="0.1"/>
      <inertia ixx="0.001" ixy="0.0" ixz="0.0" iyy="0.001" iyz="0.0" izz="0.001"/>
    </inertial>
  </link>
  <joint name="left_hand_ring_middle_joint_mimic" type="revolute">
    <origin rpy="0 0 0" xyz="0.013 0 0"/>
    <parent link="left_hand_ring_fake_link2"/>
    <child link="left_hand_ring_middle_link"/>
    <axis xyz="0 -1 0"/>
    <limit effort="100" lower="0.0" upper="0.785398163397" velocity="100"/>
    <dynamics damping="0.0" friction="0.0"/>
  </joint>
  <link name="left_hand_ring_middle_link">
    <inertial>
      <origin xyz="0.005074337 -4.524e-06 -0.000262953"/>
      <mass value="0.05"/>
      <inertia ixx="0.00175" ixy="0.0" ixz="0.0001" iyy="0.00275" iyz="0.0" izz="0.00275"/>
    </inertial>
    <visual>
      <geometry>
        <mesh filename="meshes/phalanx.stl" scale=" .001 .001 .001"/>
      </geometry>
      <material name="SoftHand/DarkGrey"/>
    </visual>
    <collision>
      <geometry>
        <mesh filename="meshes/phalanx_collision.stl" scale=" .001 .001 .001"/>
      </geometry>
    </collision>
  </link>
  <!-- DISTAL PHALANGE -->
  <joint name="left_hand_ring_outer_joint" type="revolute">
    <origin rpy="0 0 0" xyz="0.009 0 0"/>
    <parent link="left_hand_ring_middle_link"/>
    <child link="left_hand_ring_fake_link3"/>
    <axis xyz="0 -1 0"/>
    <limit effort="100" lower="0.0" upper="0.785398163397" velocity="100"/>
    <dynamics damping="0.0" friction="0.0"/>
  </joint>
  <link name="left_hand_ring_fake_link3">
    <inertial>
      <origin xyz="0 0 0"/>
      <mass value="0.1"/>
      <inertia ixx="0.001" ixy="0.0" ixz="0.0" iyy="0.001" iyz="0.0" izz="0.001"/>
    </inertial>
  </link>
  <joint name="left_hand_ring_outer_joint_mimic" type="revolute">
    <origin rpy="0 0 0" xyz="0.013 0 0"/>
    <parent link="left_hand_ring_fake_link3"/>
    <child link="left_hand_ring_distal_link"/>
    <axis xyz="0 -1 0"/>
    <limit effort="100" lower="0.0" upper="0.785398163397" velocity="100"/>
    <dynamics damping="0.0" friction="0.0"/>
  </joint>
  <link name="left_hand_ring_distal_link">
    <inertial>
      <origin xyz="0.009849094 5.6e-07 0.000820286"/>
      <mass value="0.1"/>
      <inertia ixx="0.0035" ixy="0.0" ixz="0.0002" iyy="0.008" iyz="0.0" izz="0.0076"/>
    </inertial>
    <visual>
      <geometry>
        <mesh filename="meshes/fingertip.stl" scale=" .001 .001 .001"/>
      </geometry>
      <material name="SoftHand/DarkGrey"/>
    </visual>
    <collision>
      <geometry>
        <mesh filename="meshes/fingertip_collision.stl" scale=" .001 .001 .001"/>
      </geometry>
    </collision>
  </link>
  <!-- KNUCKLE -->
  <joint name="left_hand_little_abd_joint" type="revolute">
    <origin rpy="1.5707963267948966 -1.4835299330931884 1.5707963267948966" xyz="-0.0033 0.039 0.0836994"/>
    <parent link="left_hand_palm_link"/>
    <child link="left_hand_little_knuckle_link"/>
    <axis xyz="0 0 -1"/>
    <limit effort="100" lower="-0.523598775598" upper="0.523598775598" velocity="100"/>
    <dynamics damping="0.0" friction="0.0"/>
  </joint>
  <link name="left_hand_little_knuckle_link">
    <inertial>
      <origin xyz="0.001285644 -9.58e-07 0.000425011"/>
      <mass value="0.09"/>
      <inertia ixx="0.00405" ixy="0.0" ixz="0.00045" iyy="0.0081" iyz="0.0" izz="0.0063"/>
    </inertial>
    <visual>
      <geometry>
        <mesh filename="meshes/knuckle.stl" scale=" .001 .001 .001"/>
      </geometry>
      <material name="SoftHand/DarkGrey"/>
    </visual>
    <collision>
      <geometry>
        <mesh filename="meshes/knuckle_collision.stl" scale=" .001 .001 .001"/>
      </geometry>
    </collision>
  </link>
  <!-- PROXIMAL PHALANGE -->
  <joint name="left_hand_little_inner_joint" type="revolute">
    <origin rpy="0 0 0" xyz="0.009 0 0"/>
    <parent link="left_hand_little_knuckle_link"/>
    <child link="left_hand_little_fake_link1"/>
    <axis xyz="0 -1 0"/>
    <limit effort="100" lower="0.0" upper="0.785398163397" velocity="100"/>
    <dynamics damping="0.0" friction="0.0"/>
  </joint>
  <link name="left_hand_little_fake_link1">
    <inertial>
      <origin xyz="0 0 0"/>
      <mass value="0.1"/>
      <inertia ixx="0.001" ixy="0.0" ixz="0.0" iyy="0.001" iyz="0.0" izz="0.001"/>
    </inertial>
  </link>
  <joint name="left_hand_little_inner_joint_mimic" type="revolute">
    <origin rpy="0 0 0" xyz="0.013 0 0"/>
    <parent link="left_hand_little_fake_link1"/>
    <child link="left_hand_little_proximal_link"/>
    <axis xyz="0 -1 0"/>
    <limit effort="100" lower="0.0" upper="0.785398163397" velocity="100"/>
    <dynamics damping="0.0" friction="0.0"/>
  </joint>
  <link name="left_hand_little_proximal_link">
    <inertial>
      <origin xyz="0.005074337 -4.524e-06 -0.000262953"/>
      <mass value="0.05"/>
      <inertia ixx="0.00175" ixy="0.0" ixz="0.0001" iyy="0.00275" iyz="0.0" izz="0.00275"/>
    </inertial>
    <visual>
      <geometry>
        <mesh filename="meshes/phalanx.stl" scale=" .001 .001 .001"/>
      </geometry>
      <material name="SoftHand/DarkGrey"/>
    </visual>
    <collision>
      <geometry>
        <mesh filename="meshes/phalanx_collision.stl" scale=" .001 .001 .001"/>
      </geometry>
    </collision>
  </link>
  <!-- MIDDLE PHALANGE -->
  <joint name="left_hand_little_middle_joint" type="revolute">
    <origin rpy="0 0 0" xyz="0.009 0 0"/>
    <parent link="left_hand_little_proximal_link"/>
    <child link="left_hand_little_fake_link2"/>
    <axis xyz="0 -1 0"/>
    <limit effort="100" lower="0.0" upper="0.785398163397" velocity="100"/>
    <dynamics damping="0.0" friction="0.0"/>
  </joint>
  <link name="left_hand_little_fake_link2">
    <inertial>
      <origin xyz="0 0 0"/>
      <mass value="0.1"/>
      <inertia ixx="0.001" ixy="0.0" ixz="0.0" iyy="0.001" iyz="0.0" izz="0.001"/>
    </inertial>
  </link>
  <joint name="left_hand_little_middle_joint_mimic" type="revolute">
    <origin rpy="0 0 0" xyz="0.013 0 0"/>
    <parent link="left_hand_little_fake_link2"/>
    <child link="left_hand_little_middle_link"/>
    <axis xyz="0 -1 0"/>
    <limit effort="100" lower="0.0" upper="0.785398163397" velocity="100"/>
    <dynamics damping="0.0" friction="0.0"/>
  </joint>
  <link name="left_hand_little_middle_link">
    <inertial>
      <origin xyz="0.005074337 -4.524e-06 -0.000262953"/>
      <mass value="0.05"/>
      <inertia ixx="0.00175" ixy="0.0" ixz="0.0001" iyy="0.00275" iyz="0.0" izz="0.00275"/>
    </inertial>
    <visual>
      <geometry>
        <mesh filename="meshes/phalanx.stl" scale=" .001 .001 .001"/>
      </geometry>
      <material name="SoftHand/DarkGrey"/>
    </visual>
    <collision>
      <geometry>
        <mesh filename="meshes/phalanx_collision.stl" scale=" .001 .001 .001"/>
      </geometry>
    </collision>
  </link>
  <!-- DISTAL PHALANGE -->
  <joint name="left_hand_little_outer_joint" type="revolute">
    <origin rpy="0 0 0" xyz="0.009 0 0"/>
    <parent link="left_hand_little_middle_link"/>
    <child link="left_hand_little_fake_link3"/>
    <axis xyz="0 -1 0"/>
    <limit effort="100" lower="0.0" upper="0.785398163397" velocity="100"/>
    <dynamics damping="0.0" friction="0.0"/>
  </joint>
  <link name="left_hand_little_fake_link3">
    <inertial>
      <origin xyz="0 0 0"/>
      <mass value="0.1"/>
      <inertia ixx="0.001" ixy="0.0" ixz="0.0" iyy="0.001" iyz="0.0" izz="0.001"/>
    </inertial>
  </link>
  <joint name="left_hand_little_outer_joint_mimic" type="revolute">
    <origin rpy="0 0 0" xyz="0.013 0 0"/>
    <parent link="left_hand_little_fake_link3"/>
    <child link="left_hand_little_distal_link"/>
    <axis xyz="0 -1 0"/>
    <limit effort="100" lower="0.0" upper="0.785398163397" velocity="100"/>
    <dynamics damping="0.0" friction="0.0"/>
  </joint>
  <link name="left_hand_little_distal_link">
    <inertial>
      <origin xyz="0.009849094 5.6e-07 0.000820286"/>
      <mass value="0.1"/>
      <inertia ixx="0.0035" ixy="0.0" ixz="0.0002" iyy="0.008" iyz="0.0" izz="0.0076"/>
    </inertial>
    <visual>
      <geometry>
        <mesh filename="meshes/fingertip.stl" scale=" .001 .001 .001"/>
      </geometry>
      <material name="SoftHand/DarkGrey"/>
    </visual>
    <collision>
      <geometry>
        <mesh filename="meshes/fingertip_collision.stl" scale=" .001 .001 .001"/>
      </geometry>
    </collision>
  </link>
  <transmission name="left_hand_thumb_abd_trans">
    <robotNamespace>left_hand</robotNamespace>
    <type>transmission_interface/SimpleTransmission</type>
    <joint name="left_hand_thumb_abd_joint">
      <hardwareInterface>EffortJointInterface</hardwareInterface>
    </joint>
    <actuator name="left_hand_thumb_abd_motor">
      <mechanicalReduction>1.0</mechanicalReduction>
    </actuator>
  </transmission>
  <transmission name="left_hand_thumb_inner_trans">
    <robotNamespace>left_hand</robotNamespace>
    <type>transmission_interface/SimpleTransmission</type>
    <joint name="left_hand_thumb_inner_joint">
      <hardwareInterface>EffortJointInterface</hardwareInterface>
    </joint>
    <actuator name="left_hand_thumb_inner_motor">
      <mechanicalReduction>1.0</mechanicalReduction>
    </actuator>
  </transmission>
  <transmission name="left_hand_thumb_inner_mimic_trans">
    <robotNamespace>left_hand</robotNamespace>
    <type>transmission_interface/SimpleTransmission</type>
    <joint name="left_hand_thumb_inner_joint_mimic">
      <hardwareInterface>EffortJointInterface</hardwareInterface>
    </joint>
    <actuator name="left_hand_thumb_inner_motor">
      <mechanicalReduction>1.0</mechanicalReduction>
    </actuator>
  </transmission>
  <transmission name="left_hand_thumb_outer_trans">
    <robotNamespace>left_hand</robotNamespace>
    <type>transmission_interface/SimpleTransmission</type>
    <joint name="left_hand_thumb_outer_joint">
      <hardwareInterface>EffortJointInterface</hardwareInterface>
    </joint>
    <actuator name="left_hand_thumb_outer_motor">
      <mechanicalReduction>1.0</mechanicalReduction>
    </actuator>
  </transmission>
  <transmission name="left_hand_thumb_outer_mimic_trans">
    <robotNamespace>left_hand</robotNamespace>
    <type>transmission_interface/SimpleTransmission</type>
    <joint name="left_hand_thumb_outer_joint_mimic">
      <hardwareInterface>EffortJointInterface</hardwareInterface>
    </joint>
    <actuator name="left_hand_thumb_outer_motor">
      <mechanicalReduction>1.0</mechanicalReduction>
    </actuator>
  </transmission>
  <transmission name="left_hand_index_abd_trans">
    <robotNamespace>left_hand</robotNamespace>
    <type>transmission_interface/SimpleTransmission</type>
    <joint name="left_hand_index_abd_joint">
      <hardwareInterface>EffortJointInterface</hardwareInterface>
    </joint>
    <actuator name="left_hand_index_abd_motor">
      <mechanicalReduction>1.0</mechanicalReduction>
    </actuator>
  </transmission>
  <transmission name="left_hand_index_inner_trans">
    <robotNamespace>left_hand</robotNamespace>
    <type>transmission_interface/SimpleTransmission</type>
    <joint name="left_hand_index_inner_joint">
      <hardwareInterface>EffortJointInterface</hardwareInterface>
    </joint>
    <actuator name="left_hand_index_inner_motor">
      <mechanicalReduction>1.0</mechanicalReduction>
    </actuator>
  </transmission>
  <transmission name="left_hand_index_inner_mimic_trans">
    <robotNamespace>left_hand</robotNamespace>
    <type>transmission_interface/SimpleTransmission</type>
    <joint name="left_hand_index_inner_joint_mimic">
      <hardwareInterface>EffortJointInterface</hardwareInterface>
    </joint>
    <actuator name="left_hand_index_inner_motor">
      <mechanicalReduction>1.0</mechanicalReduction>
    </actuator>
  </transmission>
  <transmission name="left_hand_index_middle_trans">
    <robotNamespace>left_hand</robotNamespace>
    <type>transmission_interface/SimpleTransmission</type>
    <joint name="left_hand_index_middle_joint">
      <hardwareInterface>EffortJointInterface</hardwareInterface>
    </joint>
    <actuator name="left_hand_index_middle_motor">
      <mechanicalReduction>1.0</mechanicalReduction>
    </actuator>
  </transmission>
  <transmission name="left_hand_index_middle_mimic_trans">
    <robotNamespace>left_hand</robotNamespace>
    <type>transmission_interface/SimpleTransmission</type>
    <joint name="left_hand_index_middle_joint_mimic">
      <hardwareInterface>EffortJointInterface</hardwareInterface>
    </joint>
    <actuator name="left_hand_index_middle_motor">
      <mechanicalReduction>1.0</mechanicalReduction>
    </actuator>
  </transmission>
  <transmission name="left_hand_index_outer_trans">
    <robotNamespace>left_hand</robotNamespace>
    <type>transmission_interface/SimpleTransmission</type>
    <joint name="left_hand_index_outer_joint">
      <hardwareInterface>EffortJointInterface</hardwareInterface>
    </joint>
    <actuator name="left_hand_index_outer_motor">
      <mechanicalReduction>1.0</mechanicalReduction>
    </actuator>
  </transmission>
  <transmission name="left_hand_index_outer_mimic_trans">
    <robotNamespace>left_hand</robotNamespace>
    <type>transmission_interface/SimpleTransmission</type>
    <joint name="left_hand_index_outer_joint_mimic">
      <hardwareInterface>EffortJointInterface</hardwareInterface>
    </joint>
    <actuator name="left_hand_index_outer_motor">
      <mechanicalReduction>1.0</mechanicalReduction>
    </actuator>
  </transmission>
  <transmission name="left_hand_middle_abd_trans">
    <robotNamespace>left_hand</robotNamespace>
    <type>transmission_interface/SimpleTransmission</type>
    <joint name="left_hand_middle_abd_joint">
      <hardwareInterface>EffortJointInterface</hardwareInterface>
    </joint>
    <actuator name="left_hand_middle_abd_motor">
      <mechanicalReduction>1.0</mechanicalReduction>
    </actuator>
  </transmission>
  <transmission name="left_hand_middle_inner_trans">
    <robotNamespace>left_hand</robotNamespace>
    <type>transmission_interface/SimpleTransmission</type>
    <joint name="left_hand_middle_inner_joint">
      <hardwareInterface>EffortJointInterface</hardwareInterface>
    </joint>
    <actuator name="left_hand_middle_inner_motor">
      <mechanicalReduction>1.0</mechanicalReduction>
    </actuator>
  </transmission>
  <transmission name="left_hand_middle_inner_mimic_trans">
    <robotNamespace>left_hand</robotNamespace>
    <type>transmission_interface/SimpleTransmission</type>
    <joint name="left_hand_middle_inner_joint_mimic">
      <hardwareInterface>EffortJointInterface</hardwareInterface>
    </joint>
    <actuator name="left_hand_middle_inner_motor">
      <mechanicalReduction>1.0</mechanicalReduction>
    </actuator>
  </transmission>
  <transmission name="left_hand_middle_middle_trans">
    <robotNamespace>left_hand</robotNamespace>
    <type>transmission_interface/SimpleTransmission</type>
    <joint name="left_hand_middle_middle_joint">
      <hardwareInterface>EffortJointInterface</hardwareInterface>
    </joint>
    <actuator name="left_hand_middle_middle_motor">
      <mechanicalReduction>1.0</mechanicalReduction>
    </actuator>
  </transmission>
  <transmission name="left_hand_middle_middle_mimic_trans">
    <robotNamespace>left_hand</robotNamespace>
    <type>transmission_interface/SimpleTransmission</type>
    <joint name="left_hand_middle_middle_joint_mimic">
      <hardwareInterface>EffortJointInterface</hardwareInterface>
    </joint>
    <actuator name="left_hand_middle_middle_motor">
      <mechanicalReduction>1.0</mechanicalReduction>
    </actuator>
  </transmission>
  <transmission name="left_hand_middle_outer_trans">
    <robotNamespace>left_hand</robotNamespace>
    <type>transmission_interface/SimpleTransmission</type>
    <joint name="left_hand_middle_outer_joint">
      <hardwareInterface>EffortJointInterface</hardwareInterface>
    </joint>
    <actuator name="left_hand_middle_outer_motor">
      <mechanicalReduction>1.0</mechanicalReduction>
    </actuator>
  </transmission>
  <transmission name="left_hand_middle_outer_mimic_trans">
    <robotNamespace>left_hand</robotNamespace>
    <type>transmission_interface/SimpleTransmission</type>
    <joint name="left_hand_middle_outer_joint_mimic">
      <hardwareInterface>EffortJointInterface</hardwareInterface>
    </joint>
    <actuator name="left_hand_middle_outer_motor">
      <mechanicalReduction>1.0</mechanicalReduction>
    </actuator>
  </transmission>
  <transmission name="left_hand_ring_abd_trans">
    <robotNamespace>left_hand</robotNamespace>
    <type>transmission_interface/SimpleTransmission</type>
    <joint name="left_hand_ring_abd_joint">
      <hardwareInterface>EffortJointInterface</hardwareInterface>
    </joint>
    <actuator name="left_hand_ring_abd_motor">
      <mechanicalReduction>1.0</mechanicalReduction>
    </actuator>
  </transmission>
  <transmission name="left_hand_ring_inner_trans">
    <robotNamespace>left_hand</robotNamespace>
    <type>transmission_interface/SimpleTransmission</type>
    <joint name="left_hand_ring_inner_joint">
      <hardwareInterface>EffortJointInterface</hardwareInterface>
    </joint>
    <actuator name="left_hand_ring_inner_motor">
      <mechanicalReduction>1.0</mechanicalReduction>
    </actuator>
  </transmission>
  <transmission name="left_hand_ring_inner_mimic_trans">
    <robotNamespace>left_hand</robotNamespace>
    <type>transmission_interface/SimpleTransmission</type>
    <joint name="left_hand_ring_inner_joint_mimic">
      <hardwareInterface>EffortJointInterface</hardwareInterface>
    </joint>
    <actuator name="left_hand_ring_inner_motor">
      <mechanicalReduction>1.0</mechanicalReduction>
    </actuator>
  </transmission>
  <transmission name="left_hand_ring_middle_trans">
    <robotNamespace>left_hand</robotNamespace>
    <type>transmission_interface/SimpleTransmission</type>
    <joint name="left_hand_ring_middle_joint">
      <hardwareInterface>EffortJointInterface</hardwareInterface>
    </joint>
    <actuator name="left_hand_ring_middle_motor">
      <mechanicalReduction>1.0</mechanicalReduction>
    </actuator>
  </transmission>
  <transmission name="left_hand_ring_middle_mimic_trans">
    <robotNamespace>left_hand</robotNamespace>
    <type>transmission_interface/SimpleTransmission</type>
    <joint name="left_hand_ring_middle_joint_mimic">
      <hardwareInterface>EffortJointInterface</hardwareInterface>
    </joint>
    <actuator name="left_hand_ring_middle_motor">
      <mechanicalReduction>1.0</mechanicalReduction>
    </actuator>
  </transmission>
  <transmission name="left_hand_ring_outer_trans">
    <robotNamespace>left_hand</robotNamespace>
    <type>transmission_interface/SimpleTransmission</type>
    <joint name="left_hand_ring_outer_joint">
      <hardwareInterface>EffortJointInterface</hardwareInterface>
    </joint>
    <actuator name="left_hand_ring_outer_motor">
      <mechanicalReduction>1.0</mechanicalReduction>
    </actuator>
  </transmission>
  <transmission name="left_hand_ring_outer_mimic_trans">
    <robotNamespace>left_hand</robotNamespace>
    <type>transmission_interface/SimpleTransmission</type>
    <joint name="left_hand_ring_outer_joint_mimic">
      <hardwareInterface>EffortJointInterface</hardwareInterface>
    </joint>
    <actuator name="left_hand_ring_outer_motor">
      <mechanicalReduction>1.0</mechanicalReduction>
    </actuator>
  </transmission>
  <transmission name="left_hand_little_abd_trans">
    <robotNamespace>left_hand</robotNamespace>
    <type>transmission_interface/SimpleTransmission</type>
    <joint name="left_hand_little_abd_joint">
      <hardwareInterface>EffortJointInterface</hardwareInterface>
    </joint>
    <actuator name="left_hand_little_abd_motor">
      <mechanicalReduction>1.0</mechanicalReduction>
    </actuator>
  </transmission>
  <transmission name="left_hand_little_inner_trans">
    <robotNamespace>left_hand</robotNamespace>
    <type>transmission_interface/SimpleTransmission</type>
    <joint name="left_hand_little_inner_joint">
      <hardwareInterface>EffortJointInterface</hardwareInterface>
    </joint>
    <actuator name="left_hand_little_inner_motor">
      <mechanicalReduction>1.0</mechanicalReduction>
    </actuator>
  </transmission>
  <transmission name="left_hand_little_inner_mimic_trans">
    <robotNamespace>left_hand</robotNamespace>
    <type>transmission_interface/SimpleTransmission</type>
    <joint name="left_hand_little_inner_joint_mimic">
      <hardwareInterface>EffortJointInterface</hardwareInterface>
    </joint>
    <actuator name="left_hand_little_inner_motor">
      <mechanicalReduction>1.0</mechanicalReduction>
    </actuator>
  </transmission>
  <transmission name="left_hand_little_middle_trans">
    <robotNamespace>left_hand</robotNamespace>
    <type>transmission_interface/SimpleTransmission</type>
    <joint name="left_hand_little_middle_joint">
      <hardwareInterface>EffortJointInterface</hardwareInterface>
    </joint>
    <actuator name="left_hand_little_middle_motor">
      <mechanicalReduction>1.0</mechanicalReduction>
    </actuator>
  </transmission>
  <transmission name="left_hand_little_middle_mimic_trans">
    <robotNamespace>left_hand</robotNamespace>
    <type>transmission_interface/SimpleTransmission</type>
    <joint name="left_hand_little_middle_joint_mimic">
      <hardwareInterface>EffortJointInterface</hardwareInterface>
    </joint>
    <actuator name="left_hand_little_middle_motor">
      <mechanicalReduction>1.0</mechanicalReduction>
    </actuator>
  </transmission>
  <transmission name="left_hand_little_outer_trans">
    <robotNamespace>left_hand</robotNamespace>
    <type>transmission_interface/SimpleTransmission</type>
    <joint name="left_hand_little_outer_joint">
      <hardwareInterface>EffortJointInterface</hardwareInterface>
    </joint>
    <actuator name="left_hand_little_outer_motor">
      <mechanicalReduction>1.0</mechanicalReduction>
    </actuator>
  </transmission>
  <transmission name="left_hand_little_outer_mimic_trans">
    <robotNamespace>left_hand</robotNamespace>
    <type>transmission_interface/SimpleTransmission</type>
    <joint name="left_hand_little_outer_joint_mimic">
      <hardwareInterface>EffortJointInterface</hardwareInterface>
    </joint>
    <actuator name="left_hand_little_outer_motor">
      <mechanicalReduction>1.0</mechanicalReduction>
    </actuator>
  </transmission>
  <gazebo>
    <plugin filename="libgazebo_ros_control.so" name="gazebo_ros_control">
      <robotNamespace>left_hand</robotNamespace>
    </plugin>
  </gazebo>
  <!-- LINKS -->
  <gazebo reference="left_hand_palm_link">
    <sensor name="left_hand_palm_link_contact" type="contact">
      <!-- the gazebo contact sensor -->
      <always_on>1</always_on>
      <update_rate>1000.0</update_rate>
      <contact>
        <collision>left_hand_palm_link_collision</collision>
        <topic>left_hand_palm_link_collision</topic>
      </contact>
      <!-- to publish a ros message with contact information -->
      <plugin filename="libgazebo_ros_bumper.so" name="left_hand_palm_link_gazebo_ros_bumper_plugin">
        <alwaysOn>true</alwaysOn>
        <frameName>left_hand_palm_link</frameName>
        <updateRate>100.0</updateRate>
        <bumperTopicName>/contacts/left_hand_palm_link</bumperTopicName>
      </plugin>
    </sensor>
    <gravity>true</gravity>
    <mu1>500.0</mu1>
    <mu2>500.0</mu2>
    <kp>1000000.0</kp>
    <kd>100.0</kd>
    <!-- <fdir1>string</fdir1> -->
    <!-- <dampingFactor>double</dampingFactor> -->
    <!-- <maxVel>double</maxVel> -->
    <!-- <minDepth>double</minDepth> -->
    <!-- <maxContacts>int</maxContacts> -->
  </gazebo>
  <gazebo reference="left_hand_thumb_knuckle_link">
    <sensor name="left_hand_thumb_knuckle_link_contact" type="contact">
      <!-- the gazebo contact sensor -->
      <always_on>1</always_on>
      <update_rate>1000.0</update_rate>
      <contact>
        <collision>left_hand_thumb_knuckle_link_collision</collision>
        <topic>left_hand_thumb_knuckle_link_collision</topic>
      </contact>
      <!-- to publish a ros message with contact information -->
      <plugin filename="libgazebo_ros_bumper.so" name="left_hand_thumb_knuckle_link_gazebo_ros_bumper_plugin">
        <alwaysOn>true</alwaysOn>
        <frameName>left_hand_thumb_knuckle_link</frameName>
        <updateRate>100.0</updateRate>
        <bumperTopicName>/contacts/left_hand_thumb_knuckle_link</bumperTopicName>
      </plugin>
    </sensor>
    <gravity>true</gravity>
    <mu1>500.0</mu1>
    <mu2>500.0</mu2>
    <kp>1000000.0</kp>
    <kd>100.0</kd>
    <!-- <fdir1>string</fdir1> -->
    <!-- <dampingFactor>double</dampingFactor> -->
    <!-- <maxVel>double</maxVel> -->
    <!-- <minDepth>double</minDepth> -->
    <!-- <maxContacts>int</maxContacts> -->
  </gazebo>
  <gazebo reference="left_hand_thumb_proximal_link">
    <sensor name="left_hand_thumb_proximal_link_contact" type="contact">
      <!-- the gazebo contact sensor -->
      <always_on>1</always_on>
      <update_rate>1000.0</update_rate>
      <contact>
        <collision>left_hand_thumb_proximal_link_collision</collision>
        <topic>left_hand_thumb_proximal_link_collision</topic>
      </contact>
      <!-- to publish a ros message with contact information -->
      <plugin filename="libgazebo_ros_bumper.so" name="left_hand_thumb_proximal_link_gazebo_ros_bumper_plugin">
        <alwaysOn>true</alwaysOn>
        <frameName>left_hand_thumb_proximal_link</frameName>
        <updateRate>100.0</updateRate>
        <bumperTopicName>/contacts/left_hand_thumb_proximal_link</bumperTopicName>
      </plugin>
    </sensor>
    <gravity>true</gravity>
    <mu1>500.0</mu1>
    <mu2>500.0</mu2>
    <kp>1000000.0</kp>
    <kd>100.0</kd>
    <!-- <fdir1>string</fdir1> -->
    <!-- <dampingFactor>double</dampingFactor> -->
    <!-- <maxVel>double</maxVel> -->
    <!-- <minDepth>double</minDepth> -->
    <!-- <maxContacts>int</maxContacts> -->
  </gazebo>
  <gazebo reference="left_hand_thumb_distal_link">
    <sensor name="left_hand_thumb_distal_link_contact" type="contact">
      <!-- the gazebo contact sensor -->
      <always_on>1</always_on>
      <update_rate>1000.0</update_rate>
      <contact>
        <collision>left_hand_thumb_distal_link_collision</collision>
        <topic>left_hand_thumb_distal_link_collision</topic>
      </contact>
      <!-- to publish a ros message with contact information -->
      <plugin filename="libgazebo_ros_bumper.so" name="left_hand_thumb_distal_link_gazebo_ros_bumper_plugin">
        <alwaysOn>true</alwaysOn>
        <frameName>left_hand_thumb_distal_link</frameName>
        <updateRate>100.0</updateRate>
        <bumperTopicName>/contacts/left_hand_thumb_distal_link</bumperTopicName>
      </plugin>
    </sensor>
    <gravity>true</gravity>
    <mu1>500.0</mu1>
    <mu2>500.0</mu2>
    <kp>1000000.0</kp>
    <kd>100.0</kd>
    <!-- <fdir1>string</fdir1> -->
    <!-- <dampingFactor>double</dampingFactor> -->
    <!-- <maxVel>double</maxVel> -->
    <!-- <minDepth>double</minDepth> -->
    <!-- <maxContacts>int</maxContacts> -->
  </gazebo>
  <gazebo reference="left_hand_index_knuckle_link">
    <sensor name="left_hand_index_knuckle_link_contact" type="contact">
      <!-- the gazebo contact sensor -->
      <always_on>1</always_on>
      <update_rate>1000.0</update_rate>
      <contact>
        <collision>left_hand_index_knuckle_link_collision</collision>
        <topic>left_hand_index_knuckle_link_collision</topic>
      </contact>
      <!-- to publish a ros message with contact information -->
      <plugin filename="libgazebo_ros_bumper.so" name="left_hand_index_knuckle_link_gazebo_ros_bumper_plugin">
        <alwaysOn>true</alwaysOn>
        <frameName>left_hand_index_knuckle_link</frameName>
        <updateRate>100.0</updateRate>
        <bumperTopicName>/contacts/left_hand_index_knuckle_link</bumperTopicName>
      </plugin>
    </sensor>
    <gravity>true</gravity>
    <mu1>500.0</mu1>
    <mu2>500.0</mu2>
    <kp>1000000.0</kp>
    <kd>100.0</kd>
    <!-- <fdir1>string</fdir1> -->
    <!-- <dampingFactor>double</dampingFactor> -->
    <!-- <maxVel>double</maxVel> -->
    <!-- <minDepth>double</minDepth> -->
    <!-- <maxContacts>int</maxContacts> -->
  </gazebo>
  <gazebo reference="left_hand_index_proximal_link">
    <sensor name="left_hand_index_proximal_link_contact" type="contact">
      <!-- the gazebo contact sensor -->
      <always_on>1</always_on>
      <update_rate>1000.0</update_rate>
      <contact>
        <collision>left_hand_index_proximal_link_collision</collision>
        <topic>left_hand_index_proximal_link_collision</topic>
      </contact>
      <!-- to publish a ros message with contact information -->
      <plugin filename="libgazebo_ros_bumper.so" name="left_hand_index_proximal_link_gazebo_ros_bumper_plugin">
        <alwaysOn>true</alwaysOn>
        <frameName>left_hand_index_proximal_link</frameName>
        <updateRate>100.0</updateRate>
        <bumperTopicName>/contacts/left_hand_index_proximal_link</bumperTopicName>
      </plugin>
    </sensor>
    <gravity>true</gravity>
    <mu1>500.0</mu1>
    <mu2>500.0</mu2>
    <kp>1000000.0</kp>
    <kd>100.0</kd>
    <!-- <fdir1>string</fdir1> -->
    <!-- <dampingFactor>double</dampingFactor> -->
    <!-- <maxVel>double</maxVel> -->
    <!-- <minDepth>double</minDepth> -->
    <!-- <maxContacts>int</maxContacts> -->
  </gazebo>
  <gazebo reference="left_hand_index_middle_link">
    <sensor name="left_hand_index_middle_link_contact" type="contact">
      <!-- the gazebo contact sensor -->
      <always_on>1</always_on>
      <update_rate>1000.0</update_rate>
      <contact>
        <collision>left_hand_index_middle_link_collision</collision>
        <topic>left_hand_index_middle_link_collision</topic>
      </contact>
      <!-- to publish a ros message with contact information -->
      <plugin filename="libgazebo_ros_bumper.so" name="left_hand_index_middle_link_gazebo_ros_bumper_plugin">
        <alwaysOn>true</alwaysOn>
        <frameName>left_hand_index_middle_link</frameName>
        <updateRate>100.0</updateRate>
        <bumperTopicName>/contacts/left_hand_index_middle_link</bumperTopicName>
      </plugin>
    </sensor>
    <gravity>true</gravity>
    <mu1>500.0</mu1>
    <mu2>500.0</mu2>
    <kp>1000000.0</kp>
    <kd>100.0</kd>
    <!-- <fdir1>string</fdir1> -->
    <!-- <dampingFactor>double</dampingFactor> -->
    <!-- <maxVel>double</maxVel> -->
    <!-- <minDepth>double</minDepth> -->
    <!-- <maxContacts>int</maxContacts> -->
  </gazebo>
  <gazebo reference="left_hand_index_distal_link">
    <sensor name="left_hand_index_distal_link_contact" type="contact">
      <!-- the gazebo contact sensor -->
      <always_on>1</always_on>
      <update_rate>1000.0</update_rate>
      <contact>
        <collision>left_hand_index_distal_link_collision</collision>
        <topic>left_hand_index_distal_link_collision</topic>
      </contact>
      <!-- to publish a ros message with contact information -->
      <plugin filename="libgazebo_ros_bumper.so" name="left_hand_index_distal_link_gazebo_ros_bumper_plugin">
        <alwaysOn>true</alwaysOn>
        <frameName>left_hand_index_distal_link</frameName>
        <updateRate>100.0</updateRate>
        <bumperTopicName>/contacts/left_hand_index_distal_link</bumperTopicName>
      </plugin>
    </sensor>
    <gravity>true</gravity>
    <mu1>500.0</mu1>
    <mu2>500.0</mu2>
    <kp>1000000.0</kp>
    <kd>100.0</kd>
    <!-- <fdir1>string</fdir1> -->
    <!-- <dampingFactor>double</dampingFactor> -->
    <!-- <maxVel>double</maxVel> -->
    <!-- <minDepth>double</minDepth> -->
    <!-- <maxContacts>int</maxContacts> -->
  </gazebo>
  <gazebo reference="left_hand_middle_knuckle_link">
    <sensor name="left_hand_middle_knuckle_link_contact" type="contact">
      <!-- the gazebo contact sensor -->
      <always_on>1</always_on>
      <update_rate>1000.0</update_rate>
      <contact>
        <collision>left_hand_middle_knuckle_link_collision</collision>
        <topic>left_hand_middle_knuckle_link_collision</topic>
      </contact>
      <!-- to publish a ros message with contact information -->
      <plugin filename="libgazebo_ros_bumper.so" name="left_hand_middle_knuckle_link_gazebo_ros_bumper_plugin">
        <alwaysOn>true</alwaysOn>
        <frameName>left_hand_middle_knuckle_link</frameName>
        <updateRate>100.0</updateRate>
        <bumperTopicName>/contacts/left_hand_middle_knuckle_link</bumperTopicName>
      </plugin>
    </sensor>
    <gravity>true</gravity>
    <mu1>500.0</mu1>
    <mu2>500.0</mu2>
    <kp>1000000.0</kp>
    <kd>100.0</kd>
    <!-- <fdir1>string</fdir1> -->
    <!-- <dampingFactor>double</dampingFactor> -->
    <!-- <maxVel>double</maxVel> -->
    <!-- <minDepth>double</minDepth> -->
    <!-- <maxContacts>int</maxContacts> -->
  </gazebo>
  <gazebo reference="left_hand_middle_proximal_link">
    <sensor name="left_hand_middle_proximal_link_contact" type="contact">
      <!-- the gazebo contact sensor -->
      <always_on>1</always_on>
      <update_rate>1000.0</update_rate>
      <contact>
        <collision>left_hand_middle_proximal_link_collision</collision>
        <topic>left_hand_middle_proximal_link_collision</topic>
      </contact>
      <!-- to publish a ros message with contact information -->
      <plugin filename="libgazebo_ros_bumper.so" name="left_hand_middle_proximal_link_gazebo_ros_bumper_plugin">
        <alwaysOn>true</alwaysOn>
        <frameName>left_hand_middle_proximal_link</frameName>
        <updateRate>100.0</updateRate>
        <bumperTopicName>/contacts/left_hand_middle_proximal_link</bumperTopicName>
      </plugin>
    </sensor>
    <gravity>true</gravity>
    <mu1>500.0</mu1>
    <mu2>500.0</mu2>
    <kp>1000000.0</kp>
    <kd>100.0</kd>
    <!-- <fdir1>string</fdir1> -->
    <!-- <dampingFactor>double</dampingFactor> -->
    <!-- <maxVel>double</maxVel> -->
    <!-- <minDepth>double</minDepth> -->
    <!-- <maxContacts>int</maxContacts> -->
  </gazebo>
  <gazebo reference="left_hand_middle_middle_link">
    <sensor name="left_hand_middle_middle_link_contact" type="contact">
      <!-- the gazebo contact sensor -->
      <always_on>1</always_on>
      <update_rate>1000.0</update_rate>
      <contact>
        <collision>left_hand_middle_middle_link_collision</collision>
        <topic>left_hand_middle_middle_link_collision</topic>
      </contact>
      <!-- to publish a ros message with contact information -->
      <plugin filename="libgazebo_ros_bumper.so" name="left_hand_middle_middle_link_gazebo_ros_bumper_plugin">
        <alwaysOn>true</alwaysOn>
        <frameName>left_hand_middle_middle_link</frameName>
        <updateRate>100.0</updateRate>
        <bumperTopicName>/contacts/left_hand_middle_middle_link</bumperTopicName>
      </plugin>
    </sensor>
    <gravity>true</gravity>
    <mu1>500.0</mu1>
    <mu2>500.0</mu2>
    <kp>1000000.0</kp>
    <kd>100.0</kd>
    <!-- <fdir1>string</fdir1> -->
    <!-- <dampingFactor>double</dampingFactor> -->
    <!-- <maxVel>double</maxVel> -->
    <!-- <minDepth>double</minDepth> -->
    <!-- <maxContacts>int</maxContacts> -->
  </gazebo>
  <gazebo reference="left_hand_middle_distal_link">
    <sensor name="left_hand_middle_distal_link_contact" type="contact">
      <!-- the gazebo contact sensor -->
      <always_on>1</always_on>
      <update_rate>1000.0</update_rate>
      <contact>
        <collision>left_hand_middle_distal_link_collision</collision>
        <topic>left_hand_middle_distal_link_collision</topic>
      </contact>
      <!-- to publish a ros message with contact information -->
      <plugin filename="libgazebo_ros_bumper.so" name="left_hand_middle_distal_link_gazebo_ros_bumper_plugin">
        <alwaysOn>true</alwaysOn>
        <frameName>left_hand_middle_distal_link</frameName>
        <updateRate>100.0</updateRate>
        <bumperTopicName>/contacts/left_hand_middle_distal_link</bumperTopicName>
      </plugin>
    </sensor>
    <gravity>true</gravity>
    <mu1>500.0</mu1>
    <mu2>500.0</mu2>
    <kp>1000000.0</kp>
    <kd>100.0</kd>
    <!-- <fdir1>string</fdir1> -->
    <!-- <dampingFactor>double</dampingFactor> -->
    <!-- <maxVel>double</maxVel> -->
    <!-- <minDepth>double</minDepth> -->
    <!-- <maxContacts>int</maxContacts> -->
  </gazebo>
  <gazebo reference="left_hand_ring_knuckle_link">
    <sensor name="left_hand_ring_knuckle_link_contact" type="contact">
      <!-- the gazebo contact sensor -->
      <always_on>1</always_on>
      <update_rate>1000.0</update_rate>
      <contact>
        <collision>left_hand_ring_knuckle_link_collision</collision>
        <topic>left_hand_ring_knuckle_link_collision</topic>
      </contact>
      <!-- to publish a ros message with contact information -->
      <plugin filename="libgazebo_ros_bumper.so" name="left_hand_ring_knuckle_link_gazebo_ros_bumper_plugin">
        <alwaysOn>true</alwaysOn>
        <frameName>left_hand_ring_knuckle_link</frameName>
        <updateRate>100.0</updateRate>
        <bumperTopicName>/contacts/left_hand_ring_knuckle_link</bumperTopicName>
      </plugin>
    </sensor>
    <gravity>true</gravity>
    <mu1>500.0</mu1>
    <mu2>500.0</mu2>
    <kp>1000000.0</kp>
    <kd>100.0</kd>
    <!-- <fdir1>string</fdir1> -->
    <!-- <dampingFactor>double</dampingFactor> -->
    <!-- <maxVel>double</maxVel> -->
    <!-- <minDepth>double</minDepth> -->
    <!-- <maxContacts>int</maxContacts> -->
  </gazebo>
  <gazebo reference="left_hand_ring_proximal_link">
    <sensor name="left_hand_ring_proximal_link_contact" type="contact">
      <!-- the gazebo contact sensor -->
      <always_on>1</always_on>
      <update_rate>1000.0</update_rate>
      <contact>
        <collision>left_hand_ring_proximal_link_collision</collision>
        <topic>left_hand_ring_proximal_link_collision</topic>
      </contact>
      <!-- to publish a ros message with contact information -->
      <plugin filename="libgazebo_ros_bumper.so" name="left_hand_ring_proximal_link_gazebo_ros_bumper_plugin">
        <alwaysOn>true</alwaysOn>
        <frameName>left_hand_ring_proximal_link</frameName>
        <updateRate>100.0</updateRate>
        <bumperTopicName>/contacts/left_hand_ring_proximal_link</bumperTopicName>
      </plugin>
    </sensor>
    <gravity>true</gravity>
    <mu1>500.0</mu1>
    <mu2>500.0</mu2>
    <kp>1000000.0</kp>
    <kd>100.0</kd>
    <!-- <fdir1>string</fdir1> -->
    <!-- <dampingFactor>double</dampingFactor> -->
    <!-- <maxVel>double</maxVel> -->
    <!-- <minDepth>double</minDepth> -->
    <!-- <maxContacts>int</maxContacts> -->
  </gazebo>
  <gazebo reference="left_hand_ring_middle_link">
    <sensor name="left_hand_ring_middle_link_contact" type="contact">
      <!-- the gazebo contact sensor -->
      <always_on>1</always_on>
      <update_rate>1000.0</update_rate>
      <contact>
        <collision>left_hand_ring_middle_link_collision</collision>
        <topic>left_hand_ring_middle_link_collision</topic>
      </contact>
      <!-- to publish a ros message with contact information -->
      <plugin filename="libgazebo_ros_bumper.so" name="left_hand_ring_middle_link_gazebo_ros_bumper_plugin">
        <alwaysOn>true</alwaysOn>
        <frameName>left_hand_ring_middle_link</frameName>
        <updateRate>100.0</updateRate>
        <bumperTopicName>/contacts/left_hand_ring_middle_link</bumperTopicName>
      </plugin>
    </sensor>
    <gravity>true</gravity>
    <mu1>500.0</mu1>
    <mu2>500.0</mu2>
    <kp>1000000.0</kp>
    <kd>100.0</kd>
    <!-- <fdir1>string</fdir1> -->
    <!-- <dampingFactor>double</dampingFactor> -->
    <!-- <maxVel>double</maxVel> -->
    <!-- <minDepth>double</minDepth> -->
    <!-- <maxContacts>int</maxContacts> -->
  </gazebo>
  <gazebo reference="left_hand_ring_distal_link">
    <sensor name="left_hand_ring_distal_link_contact" type="contact">
      <!-- the gazebo contact sensor -->
      <always_on>1</always_on>
      <update_rate>1000.0</update_rate>
      <contact>
        <collision>left_hand_ring_distal_link_collision</collision>
        <topic>left_hand_ring_distal_link_collision</topic>
      </contact>
      <!-- to publish a ros message with contact information -->
      <plugin filename="libgazebo_ros_bumper.so" name="left_hand_ring_distal_link_gazebo_ros_bumper_plugin">
        <alwaysOn>true</alwaysOn>
        <frameName>left_hand_ring_distal_link</frameName>
        <updateRate>100.0</updateRate>
        <bumperTopicName>/contacts/left_hand_ring_distal_link</bumperTopicName>
      </plugin>
    </sensor>
    <gravity>true</gravity>
    <mu1>500.0</mu1>
    <mu2>500.0</mu2>
    <kp>1000000.0</kp>
    <kd>100.0</kd>
    <!-- <fdir1>string</fdir1> -->
    <!-- <dampingFactor>double</dampingFactor> -->
    <!-- <maxVel>double</maxVel> -->
    <!-- <minDepth>double</minDepth> -->
    <!-- <maxContacts>int</maxContacts> -->
  </gazebo>
  <gazebo reference="left_hand_little_knuckle_link">
    <sensor name="left_hand_little_knuckle_link_contact" type="contact">
      <!-- the gazebo contact sensor -->
      <always_on>1</always_on>
      <update_rate>1000.0</update_rate>
      <contact>
        <collision>left_hand_little_knuckle_link_collision</collision>
        <topic>left_hand_little_knuckle_link_collision</topic>
      </contact>
      <!-- to publish a ros message with contact information -->
      <plugin filename="libgazebo_ros_bumper.so" name="left_hand_little_knuckle_link_gazebo_ros_bumper_plugin">
        <alwaysOn>true</alwaysOn>
        <frameName>left_hand_little_knuckle_link</frameName>
        <updateRate>100.0</updateRate>
        <bumperTopicName>/contacts/left_hand_little_knuckle_link</bumperTopicName>
      </plugin>
    </sensor>
    <gravity>true</gravity>
    <mu1>500.0</mu1>
    <mu2>500.0</mu2>
    <kp>1000000.0</kp>
    <kd>100.0</kd>
    <!-- <fdir1>string</fdir1> -->
    <!-- <dampingFactor>double</dampingFactor> -->
    <!-- <maxVel>double</maxVel> -->
    <!-- <minDepth>double</minDepth> -->
    <!-- <maxContacts>int</maxContacts> -->
  </gazebo>
  <gazebo reference="left_hand_little_proximal_link">
    <sensor name="left_hand_little_proximal_link_contact" type="contact">
      <!-- the gazebo contact sensor -->
      <always_on>1</always_on>
      <update_rate>1000.0</update_rate>
      <contact>
        <collision>left_hand_little_proximal_link_collision</collision>
        <topic>left_hand_little_proximal_link_collision</topic>
      </contact>
      <!-- to publish a ros message with contact information -->
      <plugin filename="libgazebo_ros_bumper.so" name="left_hand_little_proximal_link_gazebo_ros_bumper_plugin">
        <alwaysOn>true</alwaysOn>
        <frameName>left_hand_little_proximal_link</frameName>
        <updateRate>100.0</updateRate>
        <bumperTopicName>/contacts/left_hand_little_proximal_link</bumperTopicName>
      </plugin>
    </sensor>
    <gravity>true</gravity>
    <mu1>500.0</mu1>
    <mu2>500.0</mu2>
    <kp>1000000.0</kp>
    <kd>100.0</kd>
    <!-- <fdir1>string</fdir1> -->
    <!-- <dampingFactor>double</dampingFactor> -->
    <!-- <maxVel>double</maxVel> -->
    <!-- <minDepth>double</minDepth> -->
    <!-- <maxContacts>int</maxContacts> -->
  </gazebo>
  <gazebo reference="left_hand_little_middle_link">
    <sensor name="left_hand_little_middle_link_contact" type="contact">
      <!-- the gazebo contact sensor -->
      <always_on>1</always_on>
      <update_rate>1000.0</update_rate>
      <contact>
        <collision>left_hand_little_middle_link_collision</collision>
        <topic>left_hand_little_middle_link_collision</topic>
      </contact>
      <!-- to publish a ros message with contact information -->
      <plugin filename="libgazebo_ros_bumper.so" name="left_hand_little_middle_link_gazebo_ros_bumper_plugin">
        <alwaysOn>true</alwaysOn>
        <frameName>left_hand_little_middle_link</frameName>
        <updateRate>100.0</updateRate>
        <bumperTopicName>/contacts/left_hand_little_middle_link</bumperTopicName>
      </plugin>
    </sensor>
    <gravity>true</gravity>
    <mu1>500.0</mu1>
    <mu2>500.0</mu2>
    <kp>1000000.0</kp>
    <kd>100.0</kd>
    <!-- <fdir1>string</fdir1> -->
    <!-- <dampingFactor>double</dampingFactor> -->
    <!-- <maxVel>double</maxVel> -->
    <!-- <minDepth>double</minDepth> -->
    <!-- <maxContacts>int</maxContacts> -->
  </gazebo>
  <gazebo reference="left_hand_little_distal_link">
    <sensor name="left_hand_little_distal_link_contact" type="contact">
      <!-- the gazebo contact sensor -->
      <always_on>1</always_on>
      <update_rate>1000.0</update_rate>
      <contact>
        <collision>left_hand_little_distal_link_collision</collision>
        <topic>left_hand_little_distal_link_collision</topic>
      </contact>
      <!-- to publish a ros message with contact information -->
      <plugin filename="libgazebo_ros_bumper.so" name="left_hand_little_distal_link_gazebo_ros_bumper_plugin">
        <alwaysOn>true</alwaysOn>
        <frameName>left_hand_little_distal_link</frameName>
        <updateRate>100.0</updateRate>
        <bumperTopicName>/contacts/left_hand_little_distal_link</bumperTopicName>
      </plugin>
    </sensor>
    <gravity>true</gravity>
    <mu1>500.0</mu1>
    <mu2>500.0</mu2>
    <kp>1000000.0</kp>
    <kd>100.0</kd>
    <!-- <fdir1>string</fdir1> -->
    <!-- <dampingFactor>double</dampingFactor> -->
    <!-- <maxVel>double</maxVel> -->
    <!-- <minDepth>double</minDepth> -->
    <!-- <maxContacts>int</maxContacts> -->
  </gazebo>
  <!-- JOINTS -->
  <gazebo reference="left_hand_thumb_abd_joint">
    <provideFeedback>True</provideFeedback>
    <!--
		<kp> </kp>
		<kd> 1.0 </kd>
		<stopCfm> </stopCfm>
		<stopErp> </stopErp>
		<cfmDamping> </cfmDamping>
		<fudgeFactor> </fudgeFactor>
		-->
  </gazebo>
  <gazebo reference="left_hand_thumb_inner_joint">
    <provideFeedback>True</provideFeedback>
    <!--
		<kp> </kp>
		<kd> 1.0 </kd>
		<stopCfm> </stopCfm>
		<stopErp> </stopErp>
		<cfmDamping> </cfmDamping>
		<fudgeFactor> </fudgeFactor>
		-->
  </gazebo>
  <gazebo reference="left_hand_thumb_outer_joint">
    <provideFeedback>True</provideFeedback>
    <!--
		<kp> </kp>
		<kd> 1.0 </kd>
		<stopCfm> </stopCfm>
		<stopErp> </stopErp>
		<cfmDamping> </cfmDamping>
		<fudgeFactor> </fudgeFactor>
		-->
  </gazebo>
  <gazebo reference="left_hand_index_abd_joint">
    <provideFeedback>True</provideFeedback>
    <!--
		<kp> </kp>
		<kd> 1.0 </kd>
		<stopCfm> </stopCfm>
		<stopErp> </stopErp>
		<cfmDamping> </cfmDamping>
		<fudgeFactor> </fudgeFactor>
		-->
  </gazebo>
  <gazebo reference="left_hand_index_inner_joint">
    <provideFeedback>True</provideFeedback>
    <!--
		<kp> </kp>
		<kd> 1.0 </kd>
		<stopCfm> </stopCfm>
		<stopErp> </stopErp>
		<cfmDamping> </cfmDamping>
		<fudgeFactor> </fudgeFactor>
		-->
  </gazebo>
  <gazebo reference="left_hand_index_middle_joint">
    <provideFeedback>True</provideFeedback>
    <!--
		<kp> </kp>
		<kd> 1.0 </kd>
		<stopCfm> </stopCfm>
		<stopErp> </stopErp>
		<cfmDamping> </cfmDamping>
		<fudgeFactor> </fudgeFactor>
		-->
  </gazebo>
  <gazebo reference="left_hand_index_outer_joint">
    <provideFeedback>True</provideFeedback>
    <!--
		<kp> </kp>
		<kd> 1.0 </kd>
		<stopCfm> </stopCfm>
		<stopErp> </stopErp>
		<cfmDamping> </cfmDamping>
		<fudgeFactor> </fudgeFactor>
		-->
  </gazebo>
  <gazebo reference="left_hand_middle_abd_joint">
    <provideFeedback>True</provideFeedback>
    <!--
		<kp> </kp>
		<kd> 1.0 </kd>
		<stopCfm> </stopCfm>
		<stopErp> </stopErp>
		<cfmDamping> </cfmDamping>
		<fudgeFactor> </fudgeFactor>
		-->
  </gazebo>
  <gazebo reference="left_hand_middle_inner_joint">
    <provideFeedback>True</provideFeedback>
    <!--
		<kp> </kp>
		<kd> 1.0 </kd>
		<stopCfm> </stopCfm>
		<stopErp> </stopErp>
		<cfmDamping> </cfmDamping>
		<fudgeFactor> </fudgeFactor>
		-->
  </gazebo>
  <gazebo reference="left_hand_middle_middle_joint">
    <provideFeedback>True</provideFeedback>
    <!--
		<kp> </kp>
		<kd> 1.0 </kd>
		<stopCfm> </stopCfm>
		<stopErp> </stopErp>
		<cfmDamping> </cfmDamping>
		<fudgeFactor> </fudgeFactor>
		-->
  </gazebo>
  <gazebo reference="left_hand_middle_outer_joint">
    <provideFeedback>True</provideFeedback>
    <!--
		<kp> </kp>
		<kd> 1.0 </kd>
		<stopCfm> </stopCfm>
		<stopErp> </stopErp>
		<cfmDamping> </cfmDamping>
		<fudgeFactor> </fudgeFactor>
		-->
  </gazebo>
  <gazebo reference="left_hand_ring_abd_joint">
    <provideFeedback>True</provideFeedback>
    <!--
		<kp> </kp>
		<kd> 1.0 </kd>
		<stopCfm> </stopCfm>
		<stopErp> </stopErp>
		<cfmDamping> </cfmDamping>
		<fudgeFactor> </fudgeFactor>
		-->
  </gazebo>
  <gazebo reference="left_hand_ring_inner_joint">
    <provideFeedback>True</provideFeedback>
    <!--
		<kp> </kp>
		<kd> 1.0 </kd>
		<stopCfm> </stopCfm>
		<stopErp> </stopErp>
		<cfmDamping> </cfmDamping>
		<fudgeFactor> </fudgeFactor>
		-->
  </gazebo>
  <gazebo reference="left_hand_ring_middle_joint">
    <provideFeedback>True</provideFeedback>
    <!--
		<kp> </kp>
		<kd> 1.0 </kd>
		<stopCfm> </stopCfm>
		<stopErp> </stopErp>
		<cfmDamping> </cfmDamping>
		<fudgeFactor> </fudgeFactor>
		-->
  </gazebo>
  <gazebo reference="left_hand_ring_outer_joint">
    <provideFeedback>True</provideFeedback>
    <!--
		<kp> </kp>
		<kd> 1.0 </kd>
		<stopCfm> </stopCfm>
		<stopErp> </stopErp>
		<cfmDamping> </cfmDamping>
		<fudgeFactor> </fudgeFactor>
		-->
  </gazebo>
  <gazebo reference="left_hand_little_abd_joint">
    <provideFeedback>True</provideFeedback>
    <!--
		<kp> </kp>
		<kd> 1.0 </kd>
		<stopCfm> </stopCfm>
		<stopErp> </stopErp>
		<cfmDamping> </cfmDamping>
		<fudgeFactor> </fudgeFactor>
		-->
  </gazebo>
  <gazebo reference="left_hand_little_inner_joint">
    <provideFeedback>True</provideFeedback>
    <!--
		<kp> </kp>
		<kd> 1.0 </kd>
		<stopCfm> </stopCfm>
		<stopErp> </stopErp>
		<cfmDamping> </cfmDamping>
		<fudgeFactor> </fudgeFactor>
		-->
  </gazebo>
  <gazebo reference="left_hand_little_middle_joint">
    <provideFeedback>True</provideFeedback>
    <!--
		<kp> </kp>
		<kd> 1.0 </kd>
		<stopCfm> </stopCfm>
		<stopErp> </stopErp>
		<cfmDamping> </cfmDamping>
		<fudgeFactor> </fudgeFactor>
		-->
  </gazebo>
  <gazebo reference="left_hand_little_outer_joint">
    <provideFeedback>True</provideFeedback>
    <!--
		<kp> </kp>
		<kd> 1.0 </kd>
		<stopCfm> </stopCfm>
		<stopErp> </stopErp>
		<cfmDamping> </cfmDamping>
		<fudgeFactor> </fudgeFactor>
		-->
  </gazebo>
  <!-- mimic joints -->
  <gazebo reference="left_hand_thumb_inner_joint_mimic">
    <provideFeedback>True</provideFeedback>
    <!--
		<kp> </kp>
		<kd> 1.0 </kd>
		<stopCfm> </stopCfm>
		<stopErp> </stopErp>
		<cfmDamping> </cfmDamping>
		<fudgeFactor> </fudgeFactor>
		-->
  </gazebo>
  <gazebo reference="left_hand_thumb_outer_joint_mimic">
    <provideFeedback>True</provideFeedback>
    <!--
		<kp> </kp>
		<kd> 1.0 </kd>
		<stopCfm> </stopCfm>
		<stopErp> </stopErp>
		<cfmDamping> </cfmDamping>
		<fudgeFactor> </fudgeFactor>
		-->
  </gazebo>
  <gazebo reference="left_hand_index_inner_joint_mimic">
    <provideFeedback>True</provideFeedback>
    <!--
		<kp> </kp>
		<kd> 1.0 </kd>
		<stopCfm> </stopCfm>
		<stopErp> </stopErp>
		<cfmDamping> </cfmDamping>
		<fudgeFactor> </fudgeFactor>
		-->
  </gazebo>
  <gazebo reference="left_hand_index_middle_joint_mimic">
    <provideFeedback>True</provideFeedback>
    <!--
		<kp> </kp>
		<kd> 1.0 </kd>
		<stopCfm> </stopCfm>
		<stopErp> </stopErp>
		<cfmDamping> </cfmDamping>
		<fudgeFactor> </fudgeFactor>
		-->
  </gazebo>
  <gazebo reference="left_hand_index_outer_joint_mimic">
    <provideFeedback>True</provideFeedback>
    <!--
		<kp> </kp>
		<kd> 1.0 </kd>
		<stopCfm> </stopCfm>
		<stopErp> </stopErp>
		<cfmDamping> </cfmDamping>
		<fudgeFactor> </fudgeFactor>
		-->
  </gazebo>
  <gazebo reference="left_hand_middle_inner_joint_mimic">
    <provideFeedback>True</provideFeedback>
    <!--
		<kp> </kp>
		<kd> 1.0 </kd>
		<stopCfm> </stopCfm>
		<stopErp> </stopErp>
		<cfmDamping> </cfmDamping>
		<fudgeFactor> </fudgeFactor>
		-->
  </gazebo>
  <gazebo reference="left_hand_middle_middle_joint_mimic">
    <provideFeedback>True</provideFeedback>
    <!--
		<kp> </kp>
		<kd> 1.0 </kd>
		<stopCfm> </stopCfm>
		<stopErp> </stopErp>
		<cfmDamping> </cfmDamping>
		<fudgeFactor> </fudgeFactor>
		-->
  </gazebo>
  <gazebo reference="left_hand_middle_outer_joint_mimic">
    <provideFeedback>True</provideFeedback>
    <!--
		<kp> </kp>
		<kd> 1.0 </kd>
		<stopCfm> </stopCfm>
		<stopErp> </stopErp>
		<cfmDamping> </cfmDamping>
		<fudgeFactor> </fudgeFactor>
		-->
  </gazebo>
  <gazebo reference="left_hand_ring_inner_joint_mimic">
    <provideFeedback>True</provideFeedback>
    <!--
		<kp> </kp>
		<kd> 1.0 </kd>
		<stopCfm> </stopCfm>
		<stopErp> </stopErp>
		<cfmDamping> </cfmDamping>
		<fudgeFactor> </fudgeFactor>
		-->
  </gazebo>
  <gazebo reference="left_hand_ring_middle_joint_mimic">
    <provideFeedback>True</provideFeedback>
    <!--
		<kp> </kp>
		<kd> 1.0 </kd>
		<stopCfm> </stopCfm>
		<stopErp> </stopErp>
		<cfmDamping> </cfmDamping>
		<fudgeFactor> </fudgeFactor>
		-->
  </gazebo>
  <gazebo reference="left_hand_ring_outer_joint_mimic">
    <provideFeedback>True</provideFeedback>
    <!--
		<kp> </kp>
		<kd> 1.0 </kd>
		<stopCfm> </stopCfm>
		<stopErp> </stopErp>
		<cfmDamping> </cfmDamping>
		<fudgeFactor> </fudgeFactor>
		-->
  </gazebo>
  <gazebo reference="left_hand_little_inner_joint_mimic">
    <provideFeedback>True</provideFeedback>
    <!--
		<kp> </kp>
		<kd> 1.0 </kd>
		<stopCfm> </stopCfm>
		<stopErp> </stopErp>
		<cfmDamping> </cfmDamping>
		<fudgeFactor> </fudgeFactor>
		-->
  </gazebo>
  <gazebo reference="left_hand_little_middle_joint_mimic">
    <provideFeedback>True</provideFeedback>
    <!--
		<kp> </kp>
		<kd> 1.0 </kd>
		<stopCfm> </stopCfm>
		<stopErp> </stopErp>
		<cfmDamping> </cfmDamping>
		<fudgeFactor> </fudgeFactor>
		-->
  </gazebo>
  <gazebo reference="left_hand_little_outer_joint_mimic">
    <provideFeedback>True</provideFeedback>
    <!--
		<kp> </kp>
		<kd> 1.0 </kd>
		<stopCfm> </stopCfm>
		<stopErp> </stopErp>
		<cfmDamping> </cfmDamping>
		<fudgeFactor> </fudgeFactor>
		-->
  </gazebo>
</robot>

