<?xml version="1.0" ?>
<!-- =================================================================================== -->
<!-- |    This document was autogenerated by xacro from allegro_hand_description_right.xacro | -->
<!-- |    EDITING THIS FILE BY HAND IS NOT RECOMMENDED                                 | -->
<!-- =================================================================================== -->
<robot name="allegro_hand_right" xmlns:xacro="http://www.ros.org/wiki/xacro">
  <!--
rosrun xacro xacro.py allegro_hand_description_right.urdf.xacro > allegro_hand_description_right.urdf
roslaunch launchers/fuerte/allegro_hand_jgui_right_virtual.launch 
-->
  <!-- ======================== BASE PARAMS ========================= -->
  <!-- ======================== FINGER PARAMS ======================== -->
  <!-- full height from joint to tip. when used,
the radius of the finger tip sphere will be subtracted
and one fixed link will be added for the tip. -->
  <!--0.0435,   0.044981-->
  <!--0.002298-->
  <!--0.002298-->
  <!-- ========================= THUMB PARAMS ========================= -->
  <!-- ========================= LIMITS ========================= -->
  <!-- ============================================================================= -->
  <!-- ============================================================================= -->
  <!-- ============================================================================= -->
  <!-- BASE -->
  <!-- <link name="box_link">
    <collision>
      <origin rpy="0 0 0" xyz="0 0 0"/>
      <geometry>
        <box size="0.05 0.05 0.1"/>
      </geometry>
    </collision>
    <visual>
      <origin rpy="0 0 0" xyz="0 0 0"/>
      <geometry>
        <box size="0.05 0.05 0.1"/>
      </geometry>
      <material name="orange"/>
    </visual>
    <inertial>
      <origin rpy="0 0 0" xyz="0 0 0.05"/>
      <mass value="1"/>
      <inertia ixx="0.001" ixy="0.0" ixz="0.0" iyy="0.001" iyz="0.0" izz="4.1667e-04"/>
    </inertial>
  </link>

  <joint name="box_to_base" type="fixed">
    <parent link="box_link"/>
    <child link="base_link"/>
    <origin xyz="0 0 0.145"/>
  </joint> -->

  <link name="base_link">
    <visual>
      <geometry>
        <mesh filename="meshes/base_link.STL"/>
      </geometry>
      <!-- LEFT -->
      <!-- <origin rpy="${-90*DEG2RAD} 0 0" xyz="0 0 0 "/> -->
      <!-- RIGHT -->
      <origin rpy="0 0 0" xyz="0 0 0 "/>
      <material name="black">
        <color rgba="0.2 0.2 0.2 1"/>
      </material>
    </visual>
    <collision>
      <origin rpy="0 0 0" xyz="-0.009300 0 -0.0475"/>
      <geometry>
        <box size="0.0408 0.1130 0.095"/>
      </geometry>
    </collision>
    <inertial>
      <origin rpy="0 0 0" xyz="-0.0093624 -0.0008545 -0.0382263"/>
      <mass value="0.4154"/>
      <inertia ixx="0.7501e-3" ixy="-0.0003e-3" ixz="0.0025e-3" iyy="0.4533e-3" iyz="-0.0377e-3" izz="0.4457e-3"/>
    </inertial>
  </link>

  <gazebo reference="base_link">
    <kp>1000000.0</kp>
    <kd>1.0</kd>
    <mu1>1</mu1>
    <mu2>1</mu2>
    <maxVel>0.0</maxVel>
    <minDepth>0.001</minDepth>
  </gazebo>



  <!-- ============================================================================= -->
  <!-- FINGERS -->
  <!-- RIGHT HAND due to which finger is number 0 -->
  <!-- for LEFT HAND switch the sign of the **offset_origin_y** and **finger_angle_r** parameters-->


  <!-- FINGER 1 -->

  <link name="link_0">
    <visual>
      <geometry>
        <mesh filename="meshes/link_0.STL"/>
      </geometry>
      <material name="black"/>
    </visual>
    <collision>
      <geometry>
        <box size="0.0196 0.0275 0.0164"/>
      </geometry>
      <origin rpy="0 0 0" xyz="0 0 0.0082"/>
    </collision>
    <inertial>
      <mass value="0.0119"/>
      <origin rpy="0 0 0" xyz="-0.0004731 0.0002400 0.0059633"/>
      <inertia ixx="0.1531e-5" ixy="0.0" ixz="0.0070e-5" iyy="0.0765e-5" iyz="-0.0035e-5" izz="0.1496e-5"/>
    </inertial>
  </link>

  <joint name="joint_0" type="revolute">
    <axis xyz="0 0 1"/>
    <limit effort="0" lower="-0.47" upper="0.47" velocity="0"/>
    <parent link="base_link"/>
    <child link="link_0"/>
    <origin rpy="-0.08726646255 0 0" xyz="0 0.0435 -0.001542"/>
    <!--dynamics damping="3" friction="10"/--> <!-- this causes problems in pybullet -->
  </joint>

  <gazebo reference="link_0">
    <kp>1000000.0</kp>
    <kd>1.0</kd>
    <mu1>0.8</mu1>
    <mu2>0.8</mu2>
    <maxVel>0.0</maxVel>
    <minDepth>0.001</minDepth>
  </gazebo>
  <transmission name="transmission_0">
    <type>transmission_interface/SimpleTransmission</type>
    <joint name="joint_0">
      <hardwareInterface>hardware_interface/PositionJointInterface</hardwareInterface>
    </joint>
    <actuator name="actuator_0">
      <hardwareInterface>hardware_interface/PositionJointInterface</hardwareInterface>
      <mechanicalReduction>1</mechanicalReduction>
      <motorTorqueConstant>1</motorTorqueConstant>
    </actuator>
  </transmission>

  <link name="link_1">
    <visual>
      <geometry>
        <mesh filename="meshes/link_1.STL"/>
      </geometry>
      <material name="black"/>
    </visual>
    <collision>
      <geometry>
        <box size="0.0196 0.0275 0.054"/>
      </geometry>
      <origin rpy="0 0 0" xyz="0 0 0.027"/>
    </collision>
    <inertial>
      <mass value="0.065"/>
      <origin rpy="0 0 0" xyz="0.000000 -0.0000417 0.0270000"/>
      <inertia ixx="0.2837e-4" ixy="0.0" ixz="0.0" iyy="0.2698e-4" iyz="0.0" izz="0.0539e-4"/>
    </inertial>
  </link>

  <joint name="joint_1" type="revolute">
    <limit effort="0" lower="-0.196" upper="1.61" velocity="0"/>
    <axis xyz="0 1 0"/>
    <parent link="link_0"/>
    <child link="link_1"/>
    <origin xyz="0 0 0.0164"/>
    <!--dynamics damping="3" friction="5"/--> <!-- this causes problems in pybullet -->
  </joint>

  <gazebo reference="link_1">
    <kp>1000000.0</kp>
    <kd>1.0</kd>
    <mu1>0.8</mu1>
    <mu2>0.8</mu2>
    <maxVel>0.0</maxVel>
    <minDepth>0.001</minDepth>
  </gazebo>
  <transmission name="transmission_1">
    <type>transmission_interface/SimpleTransmission</type>
    <joint name="joint_1">
      <hardwareInterface>hardware_interface/PositionJointInterface</hardwareInterface>
    </joint>
    <actuator name="actuator_1">
      <hardwareInterface>hardware_interface/PositionJointInterface</hardwareInterface>
      <mechanicalReduction>1</mechanicalReduction>
      <motorTorqueConstant>1</motorTorqueConstant>
    </actuator>
  </transmission>

  <link name="link_2">
    <visual>
      <geometry>
        <mesh filename="meshes/link_2.STL"/>
      </geometry>
      <material name="black"/>
    </visual>
    <collision>
      <geometry>
        <box size="0.0196 0.0275 0.0384"/>
      </geometry>
      <origin rpy="0 0 0" xyz="0 0 0.0192"/>
    </collision>
    <inertial>
      <mass value="0.0355"/>
      <origin rpy="0 0 0" xyz="-0.0000612 -0.0000191 0.0263513"/>
      <inertia ixx="0.7038e-5" ixy="0.0" ixz="-0.0058e-5" iyy="0.6007e-5" iyz="0.0019e-5" izz="0.3208e-5"/>
    </inertial>
  </link>

  <joint name="joint_2" type="revolute">
    <axis xyz="0 1 0"/>
    <limit effort="0" lower="-0.174" upper="1.709" velocity="0"/>
    <parent link="link_1"/>
    <child link="link_2"/>
    <origin xyz="0 0 0.054"/>
    <!--dynamics damping="8" friction="10"/--> <!-- this causes problems in pybullet -->
  </joint>

  <gazebo reference="link_2">
    <kp>1000000.0</kp>
    <kd>1.0</kd>
    <mu1>0.8</mu1>
    <mu2>0.8</mu2>
    <maxVel>0.0</maxVel>
    <minDepth>0.001</minDepth>
  </gazebo>
  <transmission name="transmission_2">
    <type>transmission_interface/SimpleTransmission</type>
    <joint name="joint_2">
      <hardwareInterface>hardware_interface/PositionJointInterface</hardwareInterface>
    </joint>
    <actuator name="actuator_2">
      <hardwareInterface>hardware_interface/PositionJointInterface</hardwareInterface>
      <mechanicalReduction>1</mechanicalReduction>
      <motorTorqueConstant>1</motorTorqueConstant>
    </actuator>
  </transmission>

  <link name="link_3">
    <visual>
      <geometry>
        <mesh filename="meshes/link_3.STL"/>
      </geometry>
      <material name="black"/>
    </visual>
    <collision>
      <geometry>
        <box size="0.0196 0.0275 0.0267"/>
      </geometry>
      <origin rpy="0 0 0" xyz="0 0 0.01335"/>
    </collision>
    <inertial>
      <mass value="0.0096"/>
      <origin rpy="0 0 0" xyz="-0.0003075 0.0001172 0.0096734"/>
      <inertia ixx="0.1246e-5" ixy="0.0" ixz="-0.0027e-5" iyy="0.0610e-5" iyz="0.0" izz="0.1193e-5"/>
    </inertial>
  </link>

  <joint name="joint_3" type="revolute">
    <axis xyz="0 1 0"/>
    <limit effort="0" lower="-0.227" upper="1.618" velocity="0"/>
    <parent link="link_2"/>
    <child link="link_3"/>
    <origin xyz="0 0 0.0384"/>
    <!--dynamics damping="10" friction="12"/--> <!-- this causes problems in pybullet -->
  </joint>

  <gazebo reference="link_3">
    <kp>1000000.0</kp>
    <kd>1.0</kd>
    <mu1>0.8</mu1>
    <mu2>0.8</mu2>
    <maxVel>0.0</maxVel>
    <minDepth>0.001</minDepth>
  </gazebo>
  <transmission name="transmission_3">
    <type>transmission_interface/SimpleTransmission</type>
    <joint name="joint_3">
      <hardwareInterface>hardware_interface/PositionJointInterface</hardwareInterface>
    </joint>
    <actuator name="actuator_3">
      <hardwareInterface>hardware_interface/PositionJointInterface</hardwareInterface>
      <mechanicalReduction>1</mechanicalReduction>
      <motorTorqueConstant>1</motorTorqueConstant>
    </actuator>
  </transmission>

  <link name="link_3_tip">
    <visual>
      <geometry>
        <mesh filename="meshes/link_3_tip.STL"/>
      </geometry>
      <material name="white">
        <color rgba=".9 .9 .9 1"/>
      </material>
    </visual>
    <collision>
      <geometry>
        <sphere radius="0.012"/>
      </geometry>
    </collision>
    <inertial>
      <mass value="0.0168"/>
      <origin rpy="0 0 0" xyz="-0.000000 -0.0000001 -0.0012972"/>
      <inertia ixx="0.1119e-5" ixy="0.0" ixz="0.0" iyy="0.1119e-5" iyz="0.0" izz="0.1100e-5"/>
    </inertial>
  </link>

  <joint name="joint_3_tip" type="fixed">
    <parent link="link_3"/>
    <child link="link_3_tip"/>
    <origin rpy="0 0 0" xyz="0 0 0.0267"/>
  </joint>

  <gazebo reference="link_3_tip">
    <kp>1000000.0</kp>
    <kd>1.0</kd>
    <mu1>0.8</mu1>
    <mu2>0.8</mu2>
    <maxVel>0.0</maxVel>
    <minDepth>0.001</minDepth>
  </gazebo>


  <!-- FINGER 2 -->

  <link name="link_4">
    <visual>
      <geometry>
        <mesh filename="meshes/link_0.STL"/>
      </geometry>
      <material name="black"/>
    </visual>
    <collision>
      <geometry>
        <box size="0.0196 0.0275 0.0164"/>
      </geometry>
      <origin rpy="0 0 0" xyz="0 0 0.0082"/>
    </collision>
    <inertial>
      <mass value="0.0119"/>
      <origin rpy="0 0 0" xyz="-0.0004731 0.0002400 0.0059633"/>
      <inertia ixx="0.1531e-5" ixy="0.0" ixz="0.0070e-5" iyy="0.0765e-5" iyz="-0.0035e-5" izz="0.1496e-5"/>
    </inertial>
  </link>

  <joint name="joint_4" type="revolute">
    <axis xyz="0 0 1"/>
    <limit effort="0" lower="-0.47" upper="0.47" velocity="0"/>
    <parent link="base_link"/>
    <child link="link_4"/>
    <origin rpy="0.0 0 0" xyz="0 0 0.0007"/>
    <!--dynamics damping="3" friction="10"/--> <!-- this causes problems in pybullet -->
  </joint>

  <gazebo reference="link_4">
    <kp>1000000.0</kp>
    <kd>1.0</kd>
    <mu1>0.8</mu1>
    <mu2>0.8</mu2>
    <maxVel>0.0</maxVel>
    <minDepth>0.001</minDepth>
  </gazebo>
  <transmission name="transmission_4">
    <type>transmission_interface/SimpleTransmission</type>
    <joint name="joint_4">
      <hardwareInterface>hardware_interface/PositionJointInterface</hardwareInterface>
    </joint>
    <actuator name="actuator_4">
      <hardwareInterface>hardware_interface/PositionJointInterface</hardwareInterface>
      <mechanicalReduction>1</mechanicalReduction>
      <motorTorqueConstant>1</motorTorqueConstant>
    </actuator>
  </transmission>

  <link name="link_5">
    <visual>
      <geometry>
        <mesh filename="meshes/link_1.STL"/>
      </geometry>
      <material name="black"/>
    </visual>
    <collision>
      <geometry>
        <box size="0.0196 0.0275 0.054"/>
      </geometry>
      <origin rpy="0 0 0" xyz="0 0 0.027"/>
    </collision>
    <inertial>
      <mass value="0.065"/>
      <origin rpy="0 0 0" xyz="0.000000 -0.0000417 0.0270000"/>
      <inertia ixx="0.2837e-4" ixy="0.0" ixz="0.0" iyy="0.2698e-4" iyz="0.0" izz="0.0539e-4"/>
    </inertial>
  </link>

  <joint name="joint_5" type="revolute">
    <limit effort="0" lower="-0.196" upper="1.61" velocity="0"/>
    <axis xyz="0 1 0"/>
    <parent link="link_4"/>
    <child link="link_5"/>
    <origin xyz="0 0 0.0164"/>
    <!--dynamics damping="3" friction="5"/--> <!-- this causes problems in pybullet -->
  </joint>

  <gazebo reference="link_5">
    <kp>1000000.0</kp>
    <kd>1.0</kd>
    <mu1>0.8</mu1>
    <mu2>0.8</mu2>
    <maxVel>0.0</maxVel>
    <minDepth>0.001</minDepth>
  </gazebo>
  <transmission name="transmission_5">
    <type>transmission_interface/SimpleTransmission</type>
    <joint name="joint_5">
      <hardwareInterface>hardware_interface/PositionJointInterface</hardwareInterface>
    </joint>
    <actuator name="actuator_5">
      <hardwareInterface>hardware_interface/PositionJointInterface</hardwareInterface>
      <mechanicalReduction>1</mechanicalReduction>
      <motorTorqueConstant>1</motorTorqueConstant>
    </actuator>
  </transmission>

  <link name="link_6">
    <visual>
      <geometry>
        <mesh filename="meshes/link_2.STL"/>
      </geometry>
      <material name="black"/>
    </visual>
    <collision>
      <geometry>
        <box size="0.0196 0.0275 0.0384"/>
      </geometry>
      <origin rpy="0 0 0" xyz="0 0 0.0192"/>
    </collision>
    <inertial>
      <mass value="0.0355"/>
      <origin rpy="0 0 0" xyz="-0.0000612 -0.0000191 0.0263513"/>
      <inertia ixx="0.7038e-5" ixy="0.0" ixz="-0.0058e-5" iyy="0.6007e-5" iyz="0.0019e-5" izz="0.3208e-5"/>
    </inertial>
  </link>

  <joint name="joint_6" type="revolute">
    <axis xyz="0 1 0"/>
    <limit effort="0" lower="-0.174" upper="1.709" velocity="0"/>
    <parent link="link_5"/>
    <child link="link_6"/>
    <origin xyz="0 0 0.054"/>
    <!--dynamics damping="8" friction="10"/--> <!-- this causes problems in pybullet -->
  </joint>

  <gazebo reference="link_6">
    <kp>1000000.0</kp>
    <kd>1.0</kd>
    <mu1>0.8</mu1>
    <mu2>0.8</mu2>
    <maxVel>0.0</maxVel>
    <minDepth>0.001</minDepth>
  </gazebo>
  <transmission name="transmission_6">
    <type>transmission_interface/SimpleTransmission</type>
    <joint name="joint_6">
      <hardwareInterface>hardware_interface/PositionJointInterface</hardwareInterface>
    </joint>
    <actuator name="actuator_6">
      <hardwareInterface>hardware_interface/PositionJointInterface</hardwareInterface>
      <mechanicalReduction>1</mechanicalReduction>
      <motorTorqueConstant>1</motorTorqueConstant>
    </actuator>
  </transmission>

  <link name="link_7">
    <visual>
      <geometry>
        <mesh filename="meshes/link_3.STL"/>
      </geometry>
      <material name="black"/>
    </visual>
    <collision>
      <geometry>
        <box size="0.0196 0.0275 0.0267"/>
      </geometry>
      <origin rpy="0 0 0" xyz="0 0 0.01335"/>
    </collision>
    <inertial>
      <mass value="0.0096"/>
      <origin rpy="0 0 0" xyz="-0.0003075 0.0001172 0.0096734"/>
      <inertia ixx="0.1246e-5" ixy="0.0" ixz="-0.0027e-5" iyy="0.0610e-5" iyz="0.0" izz="0.1193e-5"/>
    </inertial>
  </link>

  <joint name="joint_7" type="revolute">
    <axis xyz="0 1 0"/>
    <limit effort="0" lower="-0.227" upper="1.618" velocity="0"/>
    <parent link="link_6"/>
    <child link="link_7"/>
    <origin xyz="0 0 0.0384"/>
    <!--dynamics damping="10" friction="12"/--> <!-- this causes problems in pybullet -->
  </joint>

  <gazebo reference="link_7">
    <kp>1000000.0</kp>
    <kd>1.0</kd>
    <mu1>0.8</mu1>
    <mu2>0.8</mu2>
    <maxVel>0.0</maxVel>
    <minDepth>0.001</minDepth>
  </gazebo>
  <transmission name="transmission_7">
    <type>transmission_interface/SimpleTransmission</type>
    <joint name="joint_7">
      <hardwareInterface>hardware_interface/PositionJointInterface</hardwareInterface>
    </joint>
    <actuator name="actuator_7">
      <hardwareInterface>hardware_interface/PositionJointInterface</hardwareInterface>
      <mechanicalReduction>1</mechanicalReduction>
      <motorTorqueConstant>1</motorTorqueConstant>
    </actuator>
  </transmission>

  <link name="link_7_tip">
    <visual>
      <geometry>
        <mesh filename="meshes/link_3_tip.STL"/>
      </geometry>
      <material name="white">
        <color rgba=".9 .9 .9 1"/>
      </material>
    </visual>
    <collision>
      <geometry>
        <sphere radius="0.012"/>
      </geometry>
    </collision>
    <inertial>
      <mass value="0.0168"/>
      <origin rpy="0 0 0" xyz="-0.000000 -0.0000001 -0.0012972"/>
      <inertia ixx="0.1119e-5" ixy="0.0" ixz="0.0" iyy="0.1119e-5" iyz="0.0" izz="0.1100e-5"/>
    </inertial>
  </link>

  <joint name="joint_7_tip" type="fixed">
    <parent link="link_7"/>
    <child link="link_7_tip"/>
    <origin rpy="0 0 0" xyz="0 0 0.0267"/>
  </joint>

  <gazebo reference="link_7_tip">
    <kp>1000000.0</kp>
    <kd>1.0</kd>
    <mu1>0.8</mu1>
    <mu2>0.8</mu2>
    <maxVel>0.0</maxVel>
    <minDepth>0.001</minDepth>
  </gazebo>


  <!-- FINGER 3 -->

  <link name="link_8">
    <visual>
      <geometry>
        <mesh filename="meshes/link_0.STL"/>
      </geometry>
      <material name="black"/>
    </visual>
    <collision>
      <geometry>
        <box size="0.0196 0.0275 0.0164"/>
      </geometry>
      <origin rpy="0 0 0" xyz="0 0 0.0082"/>
    </collision>
    <inertial>
      <mass value="0.0119"/>
      <origin rpy="0 0 0" xyz="-0.0004731 0.0002400 0.0059633"/>
      <inertia ixx="0.1531e-5" ixy="0.0" ixz="0.0070e-5" iyy="0.0765e-5" iyz="-0.0035e-5" izz="0.1496e-5"/>
    </inertial>
  </link>

  <joint name="joint_8" type="revolute">
    <axis xyz="0 0 1"/>
    <limit effort="0" lower="-0.47" upper="0.47" velocity="0"/>
    <parent link="base_link"/>
    <child link="link_8"/>
    <origin rpy="0.08726646255 0 0" xyz="0 -0.0435 -0.001542"/>
    <!--dynamics damping="3" friction="10"/--> <!-- this causes problems in pybullet -->
  </joint>

  <gazebo reference="link_8">
    <kp>1000000.0</kp>
    <kd>1.0</kd>
    <mu1>0.8</mu1>
    <mu2>0.8</mu2>
    <maxVel>0.0</maxVel>
    <minDepth>0.001</minDepth>
  </gazebo>
  <transmission name="transmission_8">
    <type>transmission_interface/SimpleTransmission</type>
    <joint name="joint_8">
      <hardwareInterface>hardware_interface/PositionJointInterface</hardwareInterface>
    </joint>
    <actuator name="actuator_8">
      <hardwareInterface>hardware_interface/PositionJointInterface</hardwareInterface>
      <mechanicalReduction>1</mechanicalReduction>
      <motorTorqueConstant>1</motorTorqueConstant>
    </actuator>
  </transmission>

  <link name="link_9">
    <visual>
      <geometry>
        <mesh filename="meshes/link_1.STL"/>
      </geometry>
      <material name="black"/>
    </visual>
    <collision>
      <geometry>
        <box size="0.0196 0.0275 0.054"/>
      </geometry>
      <origin rpy="0 0 0" xyz="0 0 0.027"/>
    </collision>
    <inertial>
      <mass value="0.065"/>
      <origin rpy="0 0 0" xyz="0.000000 -0.0000417 0.0270000"/>
      <inertia ixx="0.2837e-4" ixy="0.0" ixz="0.0" iyy="0.2698e-4" iyz="0.0" izz="0.0539e-4"/>
    </inertial>
  </link>

  <joint name="joint_9" type="revolute">
    <limit effort="0" lower="-0.196" upper="1.61" velocity="0"/>
    <axis xyz="0 1 0"/>
    <parent link="link_8"/>
    <child link="link_9"/>
    <origin xyz="0 0 0.0164"/>
    <!--dynamics damping="3" friction="5"/--> <!-- this causes problems in pybullet -->
  </joint>

  <gazebo reference="link_9">
    <kp>1000000.0</kp>
    <kd>1.0</kd>
    <mu1>0.8</mu1>
    <mu2>0.8</mu2>
    <maxVel>0.0</maxVel>
    <minDepth>0.001</minDepth>
  </gazebo>
  <transmission name="transmission_9">
    <type>transmission_interface/SimpleTransmission</type>
    <joint name="joint_9">
      <hardwareInterface>hardware_interface/PositionJointInterface</hardwareInterface>
    </joint>
    <actuator name="actuator_9">
      <hardwareInterface>hardware_interface/PositionJointInterface</hardwareInterface>
      <mechanicalReduction>1</mechanicalReduction>
      <motorTorqueConstant>1</motorTorqueConstant>
    </actuator>
  </transmission>

  <link name="link_10">
    <visual>
      <geometry>
        <mesh filename="meshes/link_2.STL"/>
      </geometry>
      <material name="black"/>
    </visual>
    <collision>
      <geometry>
        <box size="0.0196 0.0275 0.0384"/>
      </geometry>
      <origin rpy="0 0 0" xyz="0 0 0.0192"/>
    </collision>
    <inertial>
      <mass value="0.0355"/>
      <origin rpy="0 0 0" xyz="-0.0000612 -0.0000191 0.0263513"/>
      <inertia ixx="0.7038e-5" ixy="0.0" ixz="-0.0058e-5" iyy="0.6007e-5" iyz="0.0019e-5" izz="0.3208e-5"/>
    </inertial>
  </link>

  <joint name="joint_10" type="revolute">
    <axis xyz="0 1 0"/>
    <limit effort="0" lower="-0.174" upper="1.709" velocity="0"/>
    <parent link="link_9"/>
    <child link="link_10"/>
    <origin xyz="0 0 0.054"/>
    <!--dynamics damping="8" friction="10"/--> <!-- this causes problems in pybullet -->
  </joint>

  <gazebo reference="link_10">
    <kp>1000000.0</kp>
    <kd>1.0</kd>
    <mu1>0.8</mu1>
    <mu2>0.8</mu2>
    <maxVel>0.0</maxVel>
    <minDepth>0.001</minDepth>
  </gazebo>
  <transmission name="transmission_10">
    <type>transmission_interface/SimpleTransmission</type>
    <joint name="joint_10">
      <hardwareInterface>hardware_interface/PositionJointInterface</hardwareInterface>
    </joint>
    <actuator name="actuator_10">
      <hardwareInterface>hardware_interface/PositionJointInterface</hardwareInterface>
      <mechanicalReduction>1</mechanicalReduction>
      <motorTorqueConstant>1</motorTorqueConstant>
    </actuator>
  </transmission>

  <link name="link_11">
    <visual>
      <geometry>
        <mesh filename="meshes/link_3.STL"/>
      </geometry>
      <material name="black"/>
    </visual>
    <collision>
      <geometry>
        <box size="0.0196 0.0275 0.0267"/>
      </geometry>
      <origin rpy="0 0 0" xyz="0 0 0.01335"/>
    </collision>
    <inertial>
      <mass value="0.0096"/>
      <origin rpy="0 0 0" xyz="-0.0003075 0.0001172 0.0096734"/>
      <inertia ixx="0.1246e-5" ixy="0.0" ixz="-0.0027e-5" iyy="0.0610e-5" iyz="0.0" izz="0.1193e-5"/>
    </inertial>
  </link>

  <joint name="joint_11" type="revolute">
    <axis xyz="0 1 0"/>
    <limit effort="0" lower="-0.227" upper="1.618" velocity="0"/>
    <parent link="link_10"/>
    <child link="link_11"/>
    <origin xyz="0 0 0.0384"/>
    <!--dynamics damping="10" friction="12"/--> <!-- this causes problems in pybullet -->
  </joint>

  <gazebo reference="link_11">
    <kp>1000000.0</kp>
    <kd>1.0</kd>
    <mu1>0.8</mu1>
    <mu2>0.8</mu2>
    <maxVel>0.0</maxVel>
    <minDepth>0.001</minDepth>
  </gazebo>
  <transmission name="transmission_11">
    <type>transmission_interface/SimpleTransmission</type>
    <joint name="joint_11">
      <hardwareInterface>hardware_interface/PositionJointInterface</hardwareInterface>
    </joint>
    <actuator name="actuator_11">
      <hardwareInterface>hardware_interface/PositionJointInterface</hardwareInterface>
      <mechanicalReduction>1</mechanicalReduction>
      <motorTorqueConstant>1</motorTorqueConstant>
    </actuator>
  </transmission>

  <link name="link_11_tip">
    <visual>
      <geometry>
        <mesh filename="meshes/link_3_tip.STL"/>
      </geometry>
      <material name="white">
        <color rgba=".9 .9 .9 1"/>
      </material>
    </visual>
    <collision>
      <geometry>
        <sphere radius="0.012"/>
      </geometry>
    </collision>
    <inertial>
      <mass value="0.0168"/>
      <origin rpy="0 0 0" xyz="-0.000000 -0.0000001 -0.0012972"/>
      <inertia ixx="0.1119e-5" ixy="0.0" ixz="0.0" iyy="0.1119e-5" iyz="0.0" izz="0.1100e-5"/>
    </inertial>
  </link>

  <joint name="joint_11_tip" type="fixed">
    <parent link="link_11"/>
    <child link="link_11_tip"/>
    <origin rpy="0 0 0" xyz="0 0 0.0267"/>
  </joint>

  <gazebo reference="link_11_tip">
    <kp>1000000.0</kp>
    <kd>1.0</kd>
    <mu1>0.8</mu1>
    <mu2>0.8</mu2>
    <maxVel>0.0</maxVel>
    <minDepth>0.001</minDepth>
  </gazebo>


  <!-- THUMB -->

  <link name="link_12">
    <visual>
      <geometry>
        <!-- RIGHT -->
        <mesh filename="meshes/link_12_right.STL"/>
        <!-- LEFT -->
        <!-- <mesh filename="meshes/link_12_left.STL" /> -->
      </geometry>
      <material name="black">
        <color rgba=".2 .2 .2 1"/>
      </material>
    </visual>
    <collision>
      <geometry>
        <box size="0.0358 0.034 0.0455"/>
      </geometry>
      <!-- RIGHT -->
      <origin rpy="0 0 0" xyz="-0.0179 0.009 0.0145"/>
      <!-- LEFT -->
      <!-- <origin rpy="0 0 0" xyz="${-0.0358/2+0.0} ${-.018/2} ${.029/2}"/> -->
    </collision>
    <inertial>
      <mass value="0.0176"/>
      <origin rpy="0 0 0" xyz="-0.0177647 0.0081365 0.0123890"/>
      <inertia ixx="0.4271e-5" ixy="0.0008e-5" ixz="0.0027e-5" iyy="0.4886e-5" iyz="0.0311e-5" izz="0.3296e-5"/>
    </inertial>
  </link>

  <joint name="joint_12" type="revolute">
    <axis xyz="-1 0 0"/>
    <limit effort="0" lower="0.263" upper="1.396" velocity="0"/>
    <parent link="base_link"/>
    <child link="link_12"/>
    <origin rpy="0 -1.65806278845 -1.5707963259" xyz="-0.0182 0.019333 -0.045987"/>
    <!--dynamics damping="3" friction="10"/--> <!-- this causes problems in pybullet -->
  </joint>

  <gazebo reference="link_12">
    <kp>1000000.0</kp>
    <kd>1.0</kd>
    <mu1>0.8</mu1>
    <mu2>0.8</mu2>
    <maxVel>0.0</maxVel>
    <minDepth>0.001</minDepth>
  </gazebo>
  <transmission name="transmission_12">
    <type>transmission_interface/SimpleTransmission</type>
    <joint name="joint_12">
      <hardwareInterface>hardware_interface/PositionJointInterface</hardwareInterface>
    </joint>
    <actuator name="actuator_12">
      <hardwareInterface>hardware_interface/PositionJointInterface</hardwareInterface>
      <mechanicalReduction>1</mechanicalReduction>
      <motorTorqueConstant>1</motorTorqueConstant>
    </actuator>
  </transmission>

  <link name="link_13">
    <visual>
      <geometry>
        <mesh filename="meshes/link_13.STL"/>
      </geometry>
      <material name="black">
        <color rgba=".2 .2 .2 1"/>
      </material>
    </visual>
    <collision>
      <geometry>
        <box size="0.0196 0.0275 0.0177"/>
      </geometry>
      <origin rpy="0 0 0" xyz="0 0 0.00885"/>
    </collision>
    <inertial>
      <mass value="0.0119"/>
      <origin rpy="0 0 0" xyz="-0.0004748 0.0002393 0.0057834"/>
      <inertia ixx="0.1532e-5" ixy="0.0" ixz="0.0070e-5" iyy="0.0766e-5" iyz="-0.0035e-5" izz="0.1497e-5"/>
    </inertial>
  </link>

  <joint name="joint_13" type="revolute">
    <axis xyz="0 0 1"/>
    <limit effort="0" lower="-0.105" upper="1.163" velocity="0"/>
    <parent link="link_12"/>
    <child link="link_13"/>
    <!-- RIGHT -->
    <origin xyz="-0.027 0.005 0.0399"/>
    <!-- LEFT -->
    <!-- <origin xyz="-0.027 -0.005 0.0399"/> -->
    <!--dynamics damping="3" friction="5"/--> <!-- this causes problems in pybullet -->
  </joint>

  <gazebo reference="link_13">
    <kp>1000000.0</kp>
    <kd>1.0</kd>
    <mu1>0.8</mu1>
    <mu2>0.8</mu2>
    <maxVel>0.0</maxVel>
    <minDepth>0.001</minDepth>
  </gazebo>
  <transmission name="transmission_13">
    <type>transmission_interface/SimpleTransmission</type>
    <joint name="joint_13">
      <hardwareInterface>hardware_interface/PositionJointInterface</hardwareInterface>
    </joint>
    <actuator name="actuator_13">
      <hardwareInterface>hardware_interface/PositionJointInterface</hardwareInterface>
      <mechanicalReduction>1</mechanicalReduction>
      <motorTorqueConstant>1</motorTorqueConstant>
    </actuator>
  </transmission>

  <link name="link_14">
    <visual>
      <geometry>
        <mesh filename="meshes/link_14.STL"/>
      </geometry>
      <material name="black">
		  	</material>
    </visual>
    <collision>
      <geometry>
        <box size="0.0196 0.0275 0.0514"/>
      </geometry>
      <origin rpy="0 0 0" xyz="0 0 0.0257"/>
    </collision>
    <inertial>
      <mass value="0.038"/>
      <origin rpy="0 0 0" xyz="-0.0000581 0.0001095 0.0141403"/>
      <inertia ixx="0.1032e-4" ixy="0.0" ixz="0.0008e-4" iyy="0.0902e-4" iyz="-0.0006e-4" izz="0.0364e-4"/>
    </inertial>
  </link>

  <joint name="joint_14" type="revolute">
    <axis xyz="0 1 0"/>
    <limit effort="0" lower="-0.189" upper="1.644" velocity="0"/>
    <parent link="link_13"/>
    <child link="link_14"/>
    <origin xyz="0 0 0.0177"/>
    <!--dynamics damping="3" friction="10"/--> <!-- this causes problems in pybullet -->
  </joint>

  <gazebo reference="link_14">
    <kp>1000000.0</kp>
    <kd>1.0</kd>
    <mu1>0.8</mu1>
    <mu2>0.8</mu2>
    <maxVel>0.0</maxVel>
    <minDepth>0.001</minDepth>
  </gazebo>
  <transmission name="transmission_14">
    <type>transmission_interface/SimpleTransmission</type>
    <joint name="joint_14">
      <hardwareInterface>hardware_interface/PositionJointInterface</hardwareInterface>
    </joint>
    <actuator name="actuator_14">
      <hardwareInterface>hardware_interface/PositionJointInterface</hardwareInterface>
      <mechanicalReduction>1</mechanicalReduction>
      <motorTorqueConstant>1</motorTorqueConstant>
    </actuator>
  </transmission>

  <link name="link_15">
    <visual>
      <geometry>
        <mesh filename="meshes/link_15.STL"/>
      </geometry>
      <material name="black">
    	</material>
    </visual>
    <collision>
      <geometry>
        <box size="0.0196 0.0275 0.0423"/>
      </geometry>
      <origin rpy="0 0 0" xyz="0 0 0.02115"/>
    </collision>
    <inertial>
      <mass value="0.0388"/>
      <origin rpy="0 0 0" xyz="0.000000 0.0000572 0.0124330"/>
      <inertia ixx="0.7004e-5" ixy="0.0" ixz="0.0" iyy="0.6154e-5" iyz="0.0" izz="0.3259e-5"/>
    </inertial>
  </link>

  <joint name="joint_15" type="revolute">
    <axis xyz="0 1 0"/>
    <limit effort="0" lower="-0.162" upper="1.719" velocity="0"/>
    <parent link="link_14"/>
    <child link="link_15"/>
    <origin xyz="0 0 0.0514"/>
    <!--dynamics damping="3" friction="12"/--> <!-- this causes problems in pybullet -->
  </joint>

  <gazebo reference="link_15">
    <kp>1000000.0</kp>
    <kd>1.0</kd>
    <mu1>0.8</mu1>
    <mu2>0.8</mu2>
    <maxVel>0.0</maxVel>
    <minDepth>0.001</minDepth>
  </gazebo>
  <transmission name="transmission_15">
    <type>transmission_interface/SimpleTransmission</type>
    <joint name="joint_15">
      <hardwareInterface>hardware_interface/PositionJointInterface</hardwareInterface>
    </joint>
    <actuator name="actuator_15">
      <hardwareInterface>hardware_interface/PositionJointInterface</hardwareInterface>
      <mechanicalReduction>1</mechanicalReduction>
      <motorTorqueConstant>1</motorTorqueConstant>
    </actuator>
  </transmission>

  <link name="link_15_tip">
    <visual>
      <geometry>
        <mesh filename="meshes/link_15_tip.STL"/>
      </geometry>
      <material name="white">
        <color rgba=".9 .9 .9 1"/>
      </material>
    </visual>
    <collision>
      <geometry>
        <sphere radius="0.012"/>
      </geometry>
      <origin rpy="0 0 0" xyz="0 0 0"/>
    </collision>
    <inertial>
      <mass value="0.0168"/>
      <origin rpy="0 0 0" xyz="-0.000000 -0.0000001 -0.0012972"/>
      <inertia ixx="0.1119e-5" ixy="0.0" ixz="0.0" iyy="0.1119e-5" iyz="0.0" izz="0.1100e-5"/>
    </inertial>
  </link>

  <joint name="joint_15_tip" type="fixed">
    <parent link="link_15"/>
    <child link="link_15_tip"/>
    <origin rpy="0 0 0" xyz="0 0 0.0423"/>
    <!--0.0267000000000005-->
  </joint>

  <gazebo reference="link_15_tip">
    <kp>1000000.0</kp>
    <kd>1.0</kd>
    <mu1>0.8</mu1>
    <mu2>0.8</mu2>
    <maxVel>0.0</maxVel>
    <minDepth>0.001</minDepth>
  </gazebo>

  <!--
<xacro:thumb_left 
	finger_num=			"3" 
	offset_origin_x=	"-0.0182"	
	offset_origin_y=	"-0.019333" 
	offset_origin_z=	"-0.045987" 
	
	
	finger_angle_r=		"${90*DEG2RAD}"
	finger_angle_p=		"-${95*DEG2RAD}"	
	finger_angle_y=		"${90*DEG2RAD}"
/>
-->
  <!-- ============================================================================= -->
  <!-- ============================================================================= -->
  <!-- ============================================================================= -->
  <!-- THUMB MACRO -->
  <!-- END THUMB MACRO -->
  <!-- THREE FINGER MACRO -->
  <!-- [[END]] THREE FINGER MACRO -->

  <!-- Link ROS and Gazebo -->
  <gazebo>
    <plugin filename="libgazebo_ros_control.so" name="gazebo_ros_control">
      <robotNamespace>/</robotNamespace>
    </plugin>
  </gazebo>
</robot>
