<?xml version="1.0" ?>
<!-- =================================================================================== -->
<!-- |    This document was autogenerated by xacro from techpod.xacro                  | -->
<!-- |    EDITING THIS FILE BY HAND IS NOT RECOMMENDED                                 | -->
<!-- =================================================================================== -->
<!--
  Copyright 2016 Pavel Vechersky, ASL, ETH Zurich, Switzerland

  Licensed under the Apache License, Version 2.0 (the "License");
  you may not use this file except in compliance with the License.
  You may obtain a copy of the License at

  http://www.apache.org/licenses/LICENSE-2.0

  Unless required by applicable law or agreed to in writing, software
  distributed under the License is distributed on an "AS IS" BASIS,
  WITHOUT WARRANTIES OR CONDITIONS OF ANY KIND, either express or implied.
  See the License for the specific language governing permissions and
  limitations under the License.
-->
<robot name="techpod" xmlns:xacro="http://ros.org/wiki/xacro">
  <material name="black">
    <color rgba="0.2 0.2 0.2 1"/>
  </material>
  <material name="white">
    <color rgba="0.9 0.9 0.9 1"/>
  </material>
  <material name="dark_gray">
    <color rgba="0.3 0.3 0.3 1"/>
  </material>
  <material name="gray">
    <color rgba="0.5 0.5 0.5 1"/>
  </material>
  <material name="light_gray">
    <color rgba="0.7 0.7 0.7 1"/>
  </material>
  <material name="pure_red">
    <color rgba="1.0 0.0 0.0 1"/>
  </material>
  <material name="red">
    <color rgba="0.8 0.1 0.1 1"/>
  </material>
  <material name="pure_green">
    <color rgba="0.0 1.0 0.0 1"/>
  </material>
  <material name="pure_blue">
    <color rgba="0.0 0.0 1.0 1"/>
  </material>
  <material name="blue">
    <color rgba="0.0 0.2 0.8 1"/>
  </material>

  <!-- [kg] -->
  <link name="ns/base_link">
    <inertial>
      <origin rpy="0 0 0" xyz="0 0 0"/>
      <mass value="1e-6"/>
      <inertia ixx="1e-12" ixy="0.0" ixz="0.0" iyy="1e-12" iyz="0.0" izz="1e-12"/>
    </inertial>
  </link> <!-- in pybullet, the inertia need to be specified even for dummy links, otherwise it will put an identity inertia and a mass of 1 by default -->
  <joint name="ns/base_joint" type="fixed">
    <origin rpy="0 0 0" xyz="0 0 0"/>
    <parent link="ns/base_link"/>
    <child link="ns/base_link_inertia"/>
  </joint>
  <link name="ns/base_link_inertia">
    <inertial>
      <mass value="2.05"/>
      <origin rpy="0 0 0" xyz="0 0 0"/>
      <inertia ixx="0.16632" ixy="0.0" ixz="0.0755" iyy="0.3899" iyz="0.0" izz="0.5243"/>
    </inertial>
    <visual>
      <material name="white"/>
      <origin rpy="0 0 0" xyz="0 0 0"/>
      <geometry>
        <mesh filename="meshes/techpod/techpod_body.dae" scale="1 1 1"/>
      </geometry>
    </visual>
    <collision>
      <origin rpy="0 0 0" xyz="0 0 0"/>
      <geometry>
        <box size="1.088 2.591 0.303"/>
      </geometry>
    </collision>
  </link>
  <gazebo reference="ns/base_link">
    <material>Gazebo/Gray</material>
  </gazebo>
  <!-- Attach fw_dynamics to the base_link -->
  <gazebo>
    <plugin filename="librotors_gazebo_fw_dynamics_plugin.so" name="fw_dynamics_plugin">
      <robotNamespace>ns</robotNamespace>
      <linkName>ns/base_link</linkName>
      <aeroParamsYAML>aero_params</aeroParamsYAML>
      <vehicleParamsYAML>vehicle_params</vehicleParamsYAML>
      <isInputJoystick>true</isInputJoystick>
    </plugin>
  </gazebo>
  <joint name="ns/aileron_left_joint" type="revolute">
    <origin rpy="0 0 0" xyz="0.1095 0.99245 0.115"/>
    <axis xyz="0 -1 0"/>
    <parent link="ns/base_link"/>
    <child link="ns/aileron_left"/>
    <limit effort="0" lower="0" upper="0" velocity="0"/>
  </joint>
  <link name="ns/aileron_left">
    <inertial>
      <origin rpy="0 0 0" xyz="0 0 0"/>
      <mass value="0.1"/>
      <inertia ixx="0.0010164162601" ixy="0.0" ixz="0.0" iyy="2.481665674e-05" iyz="0.0" izz="0.0010384162513"/>
    </inertial>
    <visual>
      <material name="red"/>
      <origin rpy="0 0 0" xyz="0 0 0"/>
      <geometry>
        <mesh filename="meshes/techpod/techpod_aileron_left.dae" scale="1 1 1"/>
      </geometry>
    </visual>
    <collision>
      <origin rpy="0 0 0" xyz="0 0 0"/>
      <geometry>
        <mesh filename="meshes/techpod/techpod_aileron_left.dae" scale="1 1 1"/>
      </geometry>
    </collision>
  </link>
  <gazebo reference="ns/aileron_left">
    <material>Gazebo/Red</material>
  </gazebo>
  <joint name="ns/aileron_right_joint" type="revolute">
    <origin rpy="0 0 0" xyz="0.1095 -0.99245 0.115"/>
    <axis xyz="0 1 0"/>
    <parent link="ns/base_link"/>
    <child link="ns/aileron_right"/>
    <limit effort="0" lower="0" upper="0" velocity="0"/>
  </joint>
  <link name="ns/aileron_right">
    <inertial>
      <origin rpy="0 0 0" xyz="0 0 0"/>
      <mass value="0.1"/>
      <inertia ixx="0.0010164162601" ixy="0.0" ixz="0.0" iyy="2.481665674e-05" iyz="0.0" izz="0.0010384162513"/>
    </inertial>
    <visual>
      <material name="blue"/>
      <origin rpy="0 0 0" xyz="0 0 0"/>
      <geometry>
        <mesh filename="meshes/techpod/techpod_aileron_right.dae" scale="1 1 1"/>
      </geometry>
    </visual>
    <collision>
      <origin rpy="0 0 0" xyz="0 0 0"/>
      <geometry>
        <mesh filename="meshes/techpod/techpod_aileron_right.dae" scale="1 1 1"/>
      </geometry>
    </collision>
  </link>
  <gazebo reference="ns/aileron_right">
    <material>Gazebo/Red</material>
  </gazebo>
  <joint name="ns/elevator_joint" type="revolute">
    <origin rpy="0 0 0" xyz="-0.555 0 0.26"/>
    <axis xyz="0 -1 0"/>
    <parent link="ns/base_link"/>
    <child link="ns/elevator"/>
    <limit effort="0" lower="0" upper="0" velocity="0"/>
  </joint>
  <link name="ns/elevator">
    <inertial>
      <origin rpy="0 0 0" xyz="0 0 0"/>
      <mass value="0.1"/>
      <inertia ixx="0.00174160763669" ixy="0.0" ixz="0.0" iyy="2.287499085e-05" iyz="0.0" izz="0.0017620826285"/>
    </inertial>
    <visual>
      <origin rpy="0 0 0" xyz="0 0 0"/>
      <geometry>
        <mesh filename="meshes/techpod/techpod_elevator.dae" scale="1 1 1"/>
      </geometry>
    </visual>
    <collision>
      <origin rpy="0 0 0" xyz="0 0 0"/>
      <geometry>
        <mesh filename="meshes/techpod/techpod_elevator.dae" scale="1 1 1"/>
      </geometry>
    </collision>
  </link>
  <gazebo reference="ns/elevator">
    <material>Gazebo/Blue</material>
  </gazebo>
  <joint name="ns/flap_left_joint" type="revolute">
    <origin rpy="0 0 0" xyz="0.101 0.382 0.1185"/>
    <axis xyz="0 -1 0"/>
    <parent link="ns/base_link"/>
    <child link="ns/flap_left"/>
    <limit effort="0" lower="0" upper="0" velocity="0"/>
  </joint>
  <link name="ns/flap_left">
    <inertial>
      <origin rpy="0 0 0" xyz="0 0 0"/>
      <mass value="0.1"/>
      <inertia ixx="0.00175780763021" ixy="0.0" ixz="0.0" iyy="5.026664656e-05" iyz="0.0" izz="0.00180380761181"/>
    </inertial>
    <visual>
      <material name="red"/>
      <origin rpy="0 0 0" xyz="0 0 0"/>
      <geometry>
        <mesh filename="meshes/techpod/techpod_flap_left.dae" scale="1 1 1"/>
      </geometry>
    </visual>
    <collision>
      <origin rpy="0 0 0" xyz="0 0 0"/>
      <geometry>
        <mesh filename="meshes/techpod/techpod_flap_left.dae" scale="1 1 1"/>
      </geometry>
    </collision>
  </link>
  <gazebo reference="ns/flap_left">
    <material>Gazebo/Yellow</material>
  </gazebo>
  <joint name="ns/flap_right_joint" type="revolute">
    <origin rpy="0 0 0" xyz="0.101 -0.382 0.1185"/>
    <axis xyz="0 1 0"/>
    <parent link="ns/base_link"/>
    <child link="ns/flap_right"/>
    <limit effort="0" lower="0" upper="0" velocity="0"/>
  </joint>
  <link name="ns/flap_right">
    <inertial>
      <origin rpy="0 0 0" xyz="0 0 0"/>
      <mass value="0.1"/>
      <inertia ixx="0.00175780763021" ixy="0.0" ixz="0.0" iyy="5.026664656e-05" iyz="0.0" izz="0.00180380761181"/>
    </inertial>
    <visual>
      <material name="blue"/>
      <origin rpy="0 0 0" xyz="0 0 0"/>
      <geometry>
        <mesh filename="meshes/techpod/techpod_flap_right.dae" scale="1 1 1"/>
      </geometry>
    </visual>
    <collision>
      <origin rpy="0 0 0" xyz="0 0 0"/>
      <geometry>
        <mesh filename="meshes/techpod/techpod_flap_right.dae" scale="1 1 1"/>
      </geometry>
    </collision>
  </link>
  <gazebo reference="ns/flap_right">
    <material>Gazebo/Yellow</material>
  </gazebo>
  <joint name="ns/rudder_joint" type="revolute">
    <origin rpy="0 -0.25 0" xyz="-0.428 0 0"/>
    <axis xyz="0 0 1"/>
    <parent link="ns/base_link"/>
    <child link="ns/rudder"/>
    <limit effort="0" lower="0" upper="0" velocity="0"/>
  </joint>
  <link name="ns/rudder">
    <inertial>
      <origin rpy="0 0.25 0" xyz="0 0 0"/>
      <mass value="0.1"/>
      <inertia ixx="0.00048670813865" ixy="0.0" ixz="0.0" iyy="0.00062268308426" iyz="0.0" izz="0.00014137494345"/>
    </inertial>
    <visual>
      <origin rpy="0 0.25 0" xyz="0 0 0"/>
      <geometry>
        <mesh filename="meshes/techpod/techpod_rudder.dae" scale="1 1 1"/>
      </geometry>
    </visual>
    <collision>
      <origin rpy="0 0.25 0" xyz="0 0 0"/>
      <geometry>
        <mesh filename="meshes/techpod/techpod_rudder.dae" scale="1 1 1"/>
      </geometry>
    </collision>
  </link>
  <gazebo reference="ns/rudder">
    <material>Gazebo/Orange</material>
  </gazebo>
  <joint name="ns/propeller_{suffix}_joint" type="continuous">
    <origin rpy="0 -1.57079632679 0" xyz="-0.025 0 0.15"/>
    <axis xyz="0 0 1"/>
    <parent link="ns/base_link"/>
    <child link="ns/propeller_"/>
  </joint>
  <link name="ns/propeller_">
    <inertial>
      <mass value="0.1"/>
      <inertia ixx="0.0025007489997" ixy="0.0" ixz="0.0" iyy="0.0025007489997" iyz="0.0" izz="0.005"/>
    </inertial>
    <visual>
      <geometry>
        <mesh filename="meshes/propeller_cw.dae" scale="0.1 0.1 0.1"/>
      </geometry>
    </visual>
    <collision>
      <geometry>
        <mesh filename="meshes/propeller_cw.dae" scale="0.1 0.1 0.1"/>
      </geometry>
    </collision>
  </link>
  <gazebo reference="ns/propeller_">
    <material>Gazebo/Gray</material>
  </gazebo>
</robot>

