<?xml version="1.0" ?>
<!-- =================================================================================== -->
<!-- |    This document was autogenerated by xacro from mkz.urdf.xacro                 | -->
<!-- |    EDITING THIS FILE BY HAND IS NOT RECOMMENDED                                 | -->
<!-- =================================================================================== -->
<robot name="mkz" xmlns:xacro="http://www.ros.org/wiki/xacro">
  <!-- <link name="base_footprint">
    </link> -->
  <link name="base_link">
    <inertial>
      <origin rpy="0 0 0" xyz="1.4225 0 0.25"/>
      <mass value="1500.0"/>
      <inertia ixx="1000.0" ixy="0" ixz="0" iyy="1000.0" iyz="0" izz="1000.0"/>
    </inertial>
    <visual name="chassis">
      <origin rpy="0 0 1.570796" xyz="1.3641 0 -0.33"/>
      <geometry>
        <mesh filename="meshes/mkz_13/body.dae" scale="0.38 0.394 0.394"/>
      </geometry>
      <material name="black.001"/>
    </visual>
    <collision name="chassis_collision">
      <origin rpy="1.570796 0 -3.141593" xyz="1.51 -0.03046 0.350609"/>
      <geometry>
        <mesh filename="meshes/body_collision.stl" scale="0.001 0.001 0.001"/>
      </geometry>
    </collision>
  </link>
  <link name="steer_fl">
    <inertial>
      <origin rpy="0 0 0" xyz="-0.013054 -0.0295 0"/>
      <mass value="1.0"/>
      <inertia ixx="0.037227" ixy="0" ixz="0" iyy="0.04" iyz="0" izz="0.06"/>
    </inertial>
  </link>
  <link name="steer_fr">
    <inertial>
      <origin rpy="0 0 0" xyz="-0.01305 0.0275 0"/>
      <mass value="1.0"/>
      <inertia ixx="0.037227" ixy="0" ixz="0" iyy="0.04" iyz="0" izz="0.06"/>
    </inertial>
  </link>
  <link name="wheel_fl">
    <inertial>
      <origin rpy="0 -3.141593 0" xyz="0 0 0"/>
      <mass value="10.0"/>
      <inertia ixx="0.305583" ixy="0" ixz="0" iyy="0.305583" iyz="0" izz="0.5445"/>
    </inertial>
    <visual name="wheel_fl_visual">
      <origin rpy="-1.570796 -1.570796 0" xyz="0 0 0.0385"/>
      <geometry>
        <mesh filename="meshes/mkz_13/wheel.dae" scale="0.01 0.01 0.01"/>
      </geometry>
      <material name="carpaint_002"/>
    </visual>
    <collision name="wheel_fl_collision">
      <origin rpy="0 -3.141593 0" xyz="0 0 0"/>
      <geometry>
        <cylinder length="0.2" radius="0.33"/>
      </geometry>
    </collision>
  </link>
  <link name="wheel_fr">
    <inertial>
      <origin rpy="0 3.141593 0" xyz="0 0 0"/>
      <mass value="10.0"/>
      <inertia ixx="0.305583" ixy="0" ixz="0" iyy="0.305583" iyz="0" izz="0.5445"/>
    </inertial>
    <visual name="wheel_fr_visual">
      <origin rpy="-1.570796 1.570796 0" xyz="0 0 -0.043777"/>
      <geometry>
        <mesh filename="meshes/mkz_13/wheel.dae" scale="0.01 0.01 0.01"/>
      </geometry>
      <material name="carpaint_002.001"/>
    </visual>
    <collision name="wheel_fr_collision">
      <origin rpy="0 3.141593 0" xyz="0 0 -0.0035"/>
      <geometry>
        <cylinder length="0.2" radius="0.33"/>
      </geometry>
    </collision>
  </link>
  <link name="wheel_rl">
    <inertial>
      <origin rpy="0 3.141593 0" xyz="0 0 0"/>
      <mass value="10.0"/>
      <inertia ixx="0.305583" ixy="0" ixz="0" iyy="0.305583" iyz="0" izz="0.5445"/>
    </inertial>
    <visual name="wheel_rl_visual">
      <origin rpy="-1.570796 -1.570796 0" xyz="0 0 0.017382"/>
      <geometry>
        <mesh filename="meshes/mkz_13/wheel.dae" scale="0.01 0.01 0.01"/>
      </geometry>
      <material name="carpaint_002.003"/>
    </visual>
    <collision name="wheel_rl_collision">
      <origin rpy="0 3.141593 0" xyz="0 0 -0.021118"/>
      <geometry>
        <cylinder length="0.2" radius="0.33"/>
      </geometry>
    </collision>
  </link>
  <link name="wheel_rr">
    <inertial>
      <origin rpy="0 3.141593 0" xyz="0 0 0"/>
      <mass value="10.0"/>
      <inertia ixx="0.305583" ixy="0" ixz="0" iyy="0.305583" iyz="0" izz="0.5445"/>
    </inertial>
    <visual name="wheel_rr_visual">
      <origin rpy="-1.570796 1.570796 0" xyz="0 0 -0.019214"/>
      <geometry>
        <mesh filename="meshes/mkz_13/wheel.dae" scale="0.01 0.01 0.01"/>
      </geometry>
      <material name="carpaint_002.002"/>
    </visual>
    <collision name="wheel_rr_collision">
      <origin rpy="0 3.141593 0" xyz="0 0 0.0205"/>
      <geometry>
        <cylinder length="0.2" radius="0.33"/>
      </geometry>
    </collision>
  </link>
  <!-- <joint name="base_link" type="fixed">
    <origin rpy="0 0 0" xyz="0 0 0.33"/>
    <parent link="base_footprint"/>
    <child link="base_link"/>
  </joint> -->
  <joint name="steer_fl" type="revolute">
    <origin rpy="0 0 0" xyz="2.85 0.79121 0.0"/>
    <parent link="base_link"/>
    <child link="steer_fl"/>
    <axis xyz="0 0 1.0"/>
    <limit effort="0" lower="-0.6" upper="0.6" velocity="0"/>
  </joint>
  <joint name="steer_fr" type="revolute">
    <origin rpy="0 0 0" xyz="2.85 -0.79121 0.0"/>
    <parent link="base_link"/>
    <child link="steer_fr"/>
    <axis xyz="0 0 1.0"/>
    <limit effort="0" lower="-0.6" upper="0.6" velocity="0"/>
  </joint>
  <joint name="wheel_fl" type="continuous">
    <origin rpy="1.570796 0 -3.141593" xyz="0 0 0"/>
    <parent link="steer_fl"/>
    <child link="wheel_fl"/>
    <axis xyz="0 0 1.0"/>
    <limit effort="0" velocity="22.0"/>
  </joint>
  <joint name="wheel_fr" type="continuous">
    <origin rpy="1.570796 0 -3.141593" xyz="0 0 0"/>
    <parent link="steer_fr"/>
    <child link="wheel_fr"/>
    <axis xyz="0 0 1.0"/>
    <limit effort="0" velocity="22.0"/>
  </joint>
  <joint name="wheel_rl" type="continuous">
    <origin rpy="1.570796 0 -3.141593" xyz="0 0.7874 0"/>
    <parent link="base_link"/>
    <child link="wheel_rl"/>
    <axis xyz="0 0 1.0"/>
    <limit effort="5000.0" velocity="22.0"/>
  </joint>
  <joint name="wheel_rr" type="continuous">
    <origin rpy="1.570796 0 -3.141593" xyz="0 -0.7874 0"/>
    <parent link="base_link"/>
    <child link="wheel_rr"/>
    <axis xyz="0 0 1.0"/>
    <limit effort="5000.0" velocity="22.0"/>
  </joint>
  <material name="black.001">
    <color rgba="0 0 0 1.0"/>
  </material>
  <material name="carpaint_002">
    <color rgba="0.941177 0.941177 0.941177 1.0"/>
  </material>
  <material name="carpaint_002.001">
    <color rgba="0.941177 0.941177 0.941177 1.0"/>
  </material>
  <material name="carpaint_002.002">
    <color rgba="0.941177 0.941177 0.941177 1.0"/>
  </material>
  <material name="carpaint_002.003">
    <color rgba="0.941177 0.941177 0.941177 1.0"/>
  </material>
</robot>

